Workbook

Sheet 2229
G2: MUEBLES SANTA FE SPA
G3: VENTAS POR MENOR DE MUEBLES
G4: RUT: 77.054.606-0
G5: SEPTIMA AVENIDA 1631, SAN MIGUEL
G6: FONO 22521 6502 | O6: 10077 SF PORTLAND MAPLE
G7: E-MAIL: ventas@topmobili.cl
B8: P R E S U P U E S T O | D8: 10518
B10: CLIENTE: | C10: LYA MUEBLES | G10: FECHA: | H10: 45324
B11: RUT: | G11: PLAZO ENTREGA: | H11: 10 DIAS HABILES | R11: MT2 PUERTAS
B12: GIRO: | G12: SERVICIO EXPRESS | H12: NO
B13: CONTACTO: | C13: ANDREA NUÑEZ
B14: CORREO: | G14: CORTADA A LA MEDIDA | H14: NO | R14: ML CUBIERTAS
B15: FONO: | C15: +56 9 6191 4275 | G15: DESPACHO: | H15: NO
B16: DIRECCION: | G16: FORMA DE PAGO: | H16: ABONO 50% SALDO C/E
B17: CIUDAD: | C17: SANTIAGO | G17: DURACION COTIZACION: 5 DIAS FERNANDO DONOSO
B19: , | M19: 0.05 | P19: TOTAL | Q19: VALOR X MT2 | R19: ENCHAPE | S19: MT/L
B20: UNIDAD | C20: TIPO | D20: LARGO | E20: ANCHO | F20: SECTOR | G20: COLOR | H20: VALOR | I20: TOTAL | L20: =B20 -> UNIDAD | M20: ALTO | N20: =E20 -> ANCHO | O20: MT | P20: MT2 | Q20: =O44 -> 52230.586 | R20: 3000 | T20: m/l
B21: 2 | C21: CUBIERTA CON RESPALDO FRENTE 90° R8 | D21: 3 | E21: 0.6 | F21: MB04 | G21: BLANCO OPACO | H21: 98582 | I21: =H21*B21 -> 197164 | L21: =B21 -> 2 | M21: =D21+M$19 -> 3.05 | N21: =E21 -> 0.6 | O21: =M21*N21 -> 1.83 | P21: =O21*L21 -> 3.66 | Q21: =Q$20*O21 -> 95581.972 | R21: =Q21+R$20 -> 98581.972 | S21: =L21*M21 -> 6.1
B22: 2 | C22: CUBIERTA CON RESPALDO FRENTE 90° R8 | D22: 1.81 | E22: 0.6 | F22: MB04 | G22: BLANCO OPACO | H22: 61289 | I22: =H22*B22 -> 122578 | L22: =B22 -> 2 | M22: =D22+M$19 -> 1.86 | N22: =E22 -> 0.6 | O22: =M22*N22 -> 1.116 | P22: =O22*L22 -> 2.232 | Q22: =Q$20*O22 -> 58289.333 | R22: =Q22+R$20 -> 61289.333 | S22: =L22*M22 -> 3.72
B23: 2 | C23: CUBIERTA CON RESPALDO FRENTE 90° R8 | D23: 2.73 | E23: 0.6 | F23: MB05 | G23: BLANCO OPACO | H23: 90121 | I23: =H23*B23 -> 180242 | L23: =B23 -> 2 | M23: =D23+M$19 -> 2.78 | N23: =E23 -> 0.6 | O23: =M23*N23 -> 1.668 | P23: =O23*L23 -> 3.336 | Q23: =Q$20*O23 -> 87120.617 | R23: =Q23+R$20 -> 90120.617 | S23: =L23*M23 -> 5.56
B24: 2 | C24: CUBIERTA CON RESPALDO FRENTE 90° R8 | D24: 2.81 | E24: 0.6 | F24: MB05 | G24: BLANCO OPACO | H24: 92628 | I24: =H24*B24 -> 185256 | L24: =B24 -> 2 | M24: =D24+M$19 -> 2.86 | N24: =E24 -> 0.6 | O24: =M24*N24 -> 1.716 | P24: =O24*L24 -> 3.432 | Q24: =Q$20*O24 -> 89627.685 | R24: =Q24+R$20 -> 92627.685 | S24: =L24*M24 -> 5.72
B25: 2 | C25: CUBIERTA CON RESPALDO FRENTE 90° R8 | D25: 2.4 | E25: 0.6 | F25: MB01 | G25: BLANCO OPACO | H25: 79779 | I25: =H25*B25 -> 159558 | L25: =B25 -> 2 | M25: =D25+M$19 -> 2.45 | N25: =E25 -> 0.6 | O25: =M25*N25 -> 1.47 | P25: =O25*L25 -> 2.94 | Q25: =Q$20*O25 -> 76778.961 | R25: =Q25+R$20 -> 79778.961 | S25: =L25*M25 -> 4.9
B26: 1 | C26: CUBIERTA CON RESPALDO FRENTE 90° R8 | D26: 1.87 | E26: 0.6 | F26: MBO2 | G26: BLANCO OPACO | H26: 63170 | I26: =H26*B26 -> 63170 | L26: =B26 -> 1 | M26: =D26+M$19 -> 1.92 | N26: =E26 -> 0.6 | O26: =M26*N26 -> 1.152 | P26: =O26*L26 -> 1.152 | Q26: =Q$20*O26 -> 60169.635 | R26: =Q26+R$20 -> 63169.635 | S26: =L26*M26 -> 1.92
B27: 2 | C27: CUBIERTA CON RESPALDO FRENTE 90° R8 | D27: 2.1 | E27: 0.6 | F27: MB03 | G27: BLANCO OPACO | H27: 70377 | I27: =H27*B27 -> 140754 | L27: =B27 -> 2 | M27: =D27+M$19 -> 2.15 | N27: =E27 -> 0.6 | O27: =M27*N27 -> 1.29 | P27: =O27*L27 -> 2.58 | Q27: =Q$20*O27 -> 67377.455 | R27: =Q27+R$20 -> 70377.455 | S27: =L27*M27 -> 4.3
H30: NETO | I30: =SUM(I21:I29) -> 1048722
H31: IVA | I31: =I30*19% -> 199257.18 | P31: =SUM(P21:P27) -> 19.332
H32: TOTAL | I32: =I30+I31 -> 1247979.2 | P32: =P31 -> 19.332 | S32: =SUM(S21:S31) -> 32.22
P33: =P32*20% -> 3.8664 | Q33: 20% PERDIDA
P34: =P32+P33 -> 23.1984 | S34: 40
M36: =P34*1 -> 23.1984 | N36: 3500 | O36: =M36*N36 -> 81194.4 | P36: ADHESIVO | Q36: TRASCARA ENCHAPADA, ES POR 2 | X36: O
M37: 5.2 | N37: 25000 | O37: =M37*N37 -> 130000 | P37: MDF18MM
M38: 6 | N38: 33240 | O38: =M38*N38 -> 199440 | P38: LAMINA 153 X 366 | V38: 33390
B39: CUENTA CORRIENTE BANCO SANTANDER Nº 87316181 A NOMBRE DE MUEBLES SANTA FE SPA | N39: 20940 | O39: =M39*N39 -> 0 | P39: LAMINA 122X244 | V39: =V38/1.19 -> 28058.824
B40: RUT : 77.054.606-0 VENTAS@TOPMOBILI.CL | N40: 800 | P40: ZACALO | R40: 1.52
B41: VISITANOS Y DESCUBRE NUESTROS PRODUCTOS EN | G41: WWW.TOPMOBILICHILE.CL | M41: 32.22 | N41: 1500 | O41: =M41*N41 -> 48330 | P41: MEDIA CAÑA | R41: 2.44 | T41: 1500
O42: =SUM(O36:O41) -> 458964.4 | P42: COSTO | R42: =R40*R41 -> 3.7088 | T42: =S34*T41 -> 60000
M43: PRECIO VENTA | O43: =O42*2.2 -> 1009721.7 | P43: FACTOR 2,3 PARA 90° | R43: =P32/R42 -> 5.2124676 | T43: =T42/#REF! -> #REF!
O44: =O43/P32 -> 52230.586 | P44: VALOR M2 | W44: 2300
K45: 54510 | O45: =O43/O42 -> 2.2
K46: =K45/1.19 -> 45806.723
...

Sheet COSTOS
B2: CENTRO DE COSTOS POSTFORMADOS
B5: FECHA: | C5: ='2229'!H10 -> 45324
B6: CLIENTE: | C6: ='2229'!C10 -> LYA MUEBLES | N6: Ventas Equilibrio = | P6: Costos Fijos Totales
B7: DIRECCION: | C7: ='2229'!#REF! -> #REF! | H7: COSTOS INDIRECTOS DE FABRICA VARIABLES | O7: 1 - | P7: Costos Variables Totales
B8: PRESUPUESTO: | C8: ='2229'!D8 -> 10518 | H8: Q/HRS | I8: $ | J8: DETALLE | K8: TOTAL | L8: TOTAL | P8: Total Venta | X8: =SUM(Q11:Q16) -> 6
H9: CANTIDAD | I9: PRECIO | J9: MATERIA PRIMA INDIRECTA | L9: =SUM(K10:K23) -> 2550 | S9: DETALLE | X9: =(E15-D11)/X8 -> #REF!
D10: NETO | E10: IVA | F10: TOTAL | H10: 3 | I10: 350 | J10: RESPALDO | K10: =I10*H10 -> 1050 | Q10: UNIDAD | R10: TIPO | S10: LARGO | T10: ANCHO | U10: COLOR | V10: VALOR | W10: TOTAL
C11: MONTO A COBRAR | D11: ='2229'!#REF! -> #REF! | E11: =D11*0.19 -> #REF! | F11: =E11+D11 -> #REF! | H11: 3 | I11: 500 | J11: MEDIA CAÑA | K11: =I11*H11 -> 1500 | Q11: 1 | R11: CUB C/R R8 | S11: 2.8 | T11: 0.62 | U11: MADERA X DEFINIR | V11: 105990 | W11: =V11*Q11 -> 105990 | X11: =V11+$X$9 -> #REF! | Y11: 108990
C12: COSTO TOTAL | D12: =SUM(M43:M45) -> 440468.49 | H12: 0 | I12: 7500 | J12: DUROLAC | K12: =I12*H12 -> 0 | Q12: 1 | R12: CUB C/R R8 | S12: 2.3 | T12: 0.62 | U12: MADERA X DEFINIR | V12: 87990 | W12: =V12*Q12 -> 87990 | X12: =V12+$X$9 -> #REF! | Y12: 89990
C13: % UTILIDAD | D13: =D11-D12 -> #REF! | E13: =(D11/D12)-1 -> #REF! | H13: 0 | I13: 50 | J13: TAPACANTO PVC | K13: =I13*H13 -> 0 | Q13: 1 | R13: CUB C/R R8 | S13: 2.03 | T13: 0.62 | U13: MADERA X DEFINIR | V13: 78990 | W13: =V13*Q13 -> 78990 | X13: =V13+$X$9 -> #REF! | Y13: 81990
D14: % utilidad | E14: NETO | F14: UTILIDAD | H14: 0 | I14: 50 | J14: SOBERBIOS | K14: =I14*H14 -> 0 | Q14: 1 | R14: CUB C/R R8 | S14: 1.08 | T14: 0.62 | U14: MADERA X DEFINIR | V14: 39990 | W14: =V14*Q14 -> 39990 | X14: =V14+$X$9 -> #REF! | Y14: 39990
C15: PROYECCION | D15: 0.65 | E15: =(100%+D15)*D12 -> 726773.01 | F15: =E15-D12 -> 286304.52 | H15: 0 | I15: 10 | J15: SOPORTE REPISA | K15: =I15*H15 -> 0 | Q15: 1 | R15: CUB C/R R8 | S15: 1.08 | T15: 0.62 | U15: MADERA X DEFINIR | V15: 39990 | W15: =V15*Q15 -> 39990 | X15: =V15+$X$9 -> #REF! | Y15: 39990
H16: 1 | J16: PUNTAS | K16: =I16*H16 -> 0 | Q16: 1 | R16: CUB C/R R8 | S16: 2.06 | T16: 0.62 | U16: MADERA X DEFINIR | V16: 79990 | W16: =V16*Q16 -> 79990 | X16: =V16+$X$9 -> #REF! | Y16: 83990
B17: M. PRIMA | C17: MATERIAL | D17: NETO | E17: IVA | F17: TOTAL | H17: 1 | J17: TORNILLOS | K17: =I17*H17 -> 0 | Q17: 6 | R17: CORTES 45° | V17: 5000 | W17: =V17*Q17 -> 30000
C18: LAMINA | D18: ='2229'!O38 -> 199440 | E18: =D18*0.19 -> 37893.6 | F18: =SUM(D18:E18) -> 237333.6 | H18: 1 | J18: COLAFRIA | K18: =I18*H18 -> 0 | Q18: 1 | R18: PERFORACION LAVAPLATOS | V18: 10000 | W18: =V18*Q18 -> 10000
C19: MDF 18MM | D19: ='2229'!O37 -> 130000 | E19: =D19*0.19 -> 24700 | F19: =SUM(D19:E19) -> 154700 | H19: 1 | J19: LIJAS | K19: =I19*H19 -> 0 | V19: NETO | W19: =SUM(W11:W18) -> 472940 | Y19: =SUM(Y11:Y16)+SUM(W17:W18) -> 484940
C20: ADHESIVO | D20: ='2229'!O36 -> 81194.4 | E20: =D20*0.19 -> 15426.936 | F20: =SUM(D20:E20) -> 96621.336 | H20: 1 | J20: CARTON | K20: =I20*H20 -> 0 | V20: I.V.A. | W20: =W19*19% -> 89858.6 | Y20: =Y19*0.19 -> 92138.6
A21: =450000*1.2 -> 540000 | C21: TOTAL | D21: =SUM(D18:D20) -> 410634.4 | E21: =SUM(E18:E20) -> 78020.536 | F21: =SUM(F18:F20) -> 488654.94 | H21: 1 | J21: GUAIPE | K21: =I21*H21 -> 0 | M21: =B32/9 -> 2318.8406 | Q21: PLAZO DE ENTREGA : 8 DIAS HABILES | V21: TOTAL | W21: =W19+W20 -> 562798.6 | Y21: =SUM(Y19:Y20) -> 577078.6
A22: =450000*1.2 -> 540000 | B22: M. DE OBRA | C22: PROCESO | D22: COSTO x Hr. | E22: Q Hrs. | F22: TOTAL | H22: 1 | J22: DILUYENTE | K22: =I22*H22 -> 0 | Q22: FORMA DE PAGO: 50% CONTADO, SALDO C/E
A23: =800000*1.2 -> 960000 | B23: =A21/23 -> 23478.261 | C23: CORTE | D23: =B23/9 -> 2608.6957 | E23: 0.5 | F23: =D23*E23 -> 1304.3478 | H23: 1 | J23: CINTA EMBALAJE | K23: =I23*H23 -> 0 | Q23: VALIDEZ COTIZACIÓN: 5 DIAS
A24: 450000 | B24: =A22/23 -> 23478.261 | C24: CORTE LAMINA | D24: =B24/9 -> 2608.6957 | E24: 0.5 | F24: =D24*E24 -> 1304.3478 | H24: Q/HRS | I24: PRECIO | J24: MANO DE OBRA INDIRECTA | K24: VALOR | L24: =SUM(K25:K35) -> 0
A25: 450000 | B25: =A23/23 -> 41739.13 | C25: REBAJE LAMINA | D25: =B25/9 -> 4637.6812 | F25: =D25*E25 -> 0 | H25: 0 | I25: =((480000/23)/9) -> 2318.8406 | J25: FLETERO (HRS) | K25: =H25*I25 -> 0
B26: =A24/23 -> 19565.217 | C26: TUPIZADO | D26: =B26/9 -> 2173.913 | E26: 0.5 | F26: =D26*E26 -> 1086.9565 | H26: 0 | J26: BENCINA | K26: =H26*I26 -> 0
A27: 350000 | B27: =A25/23 -> 19565.217 | C27: ARMADO | D27: =B27/9 -> 2173.913 | E27: 0.5 | F27: =D27*E27 -> 1086.9565 | H27: 0 | J27: TAG | K27: =H27*I27 -> 0
A28: 500000 | B28: =A27/23 -> 15217.391 | C28: PEGADO | D28: =B28/9 -> 1690.8213 | E28: 0.7 | F28: =D28*E28 -> 1183.5749 | H28: 0 | J28: RECTIFICACION | K28: =H28*I28 -> 0
B29: =A28/23 -> 21739.13 | C29: POSTFORMADO | D29: =B29/9 -> 2415.4589 | E29: 0.7 | F29: =D29*E29 -> 1690.8213 | H29: 0 | I29: =((550000*1.2)/23)/9 -> 3188.4058 | J29: HR. TRAB. JUAN | K29: =H29*I29 -> 0
A30: 450000 | C30: MEDIA CAÑA | D30: 2415 | F30: =D30*E30 -> 0 | H30: 0 | I30: =((450000*1.2)/23)/9 -> 2608.6957 | J30: HR. TRAB. JULIO | K30: =H30*I30 -> 0
A31: 350000 | B31: =A30/23 -> 19565.217 | C31: CORTE-ENCHAPE | D31: =B31/9 -> 2173.913 | E31: 0 | F31: =D31*E31 -> 0 | H31: 0 | I31: =((450000*1.2)/23)/9 -> 2608.6957 | J31: HR. TRAB. EUGE | K31: =H31*I31 -> 0
A32: =A21+A24+A27+A28+A30 -> 2290000 | B32: =480000/23 -> 20869.565 | C32: CONTROL CALIDAD | D32: =B32/9 -> 2318.8406 | E32: 0.5 | F32: =D32*E32 -> 1159.4203 | H32: 0 | J32: COLACION | K32: =H32*I32 -> 0
C33: TOTAL | D33: =SUM(D23:D32) -> 25216.932 | E33: =SUM(E23:E32) -> 3.9 | F33: =SUM(F23:F32) -> 8816.4251 | H33: 0 | J33: BONO | K33: =H33*I33 -> 0
B34: CIF | C34: M. PRIMA INDIREC. | D34: =L9 -> 2550 | H34: 1 | J34: PERFORACION | K34: =H34*I34 -> 0
C35: M. OBRA INDIRECTA | D35: =L24 -> 0 | H35: 6 | J35: CORTE 45 | K35: =H35*I35 -> 0
C36: GASTOS DE FABRICA | D36: =L36 -> 18467.666 | H36: CANTIDAD | I36: PRECIO | J36: GASTOS DE FABRICACION | K36: VALOR | L36: =SUM(K37:K39) -> 18467.666
C37: DEPRECIACIONES | H37: =$E$33 -> 3.9 | I37: =32609.69/9 -> 3623.2989 | J37: ARRIENDO x HORA | K37: =I37*H37 -> 14130.866
C38: TOTAL | D38: =SUM(D34:D37) -> 21017.666 | H38: =$E$33 -> 3.9 | I38: 967 | J38: AGUA x HORA | K38: =I38*H38 -> 3771.3
H39: =$E$33 -> 3.9 | I39: 145 | J39: LUZ x HORA | K39: =I39*H39 -> 565.5
B40: PROVISIONAR | C40: IVA | D40: =E11-E21 -> #REF!
H41: ESTADO DE RESULTADOS
B42: TOTAL HRS TRABAJADAS | D42: =E33 -> 3.9 | H42: INGRESOS | I42: + TOTAL VENTA | M42: =D11 -> #REF!
H43: COSTOS | I43: - MATERIA PRIMA DIRECTA | M43: =D21 -> 410634.4
...
