Workbook

Sheet 2229
H2: MUEBLES SANTA FE SPA
H3: VENTAS POR MENOR DE MUEBLES
H4: RUT: 77.054.606-0
H5: SEPTIMA AVENIDA 1631, SAN MIGUEL
H6: FONO 22521 6502 | P6: 10077 SF PORTLAND MAPLE
H7: E-MAIL: ventas@topmobili.cl
B8: P R E S U P U E S T O | D8: 10544
B10: CLIENTE: | C10: JOSE MIGUEL RIOCA | H10: FECHA: | I10: 45310
B11: RUT: | H11: PLAZO ENTREGA: | I11: 45317 | N11: 225990 | S11: MT2 PUERTAS
B12: GIRO: | H12: SERVICIO EXPRESS | I12: SI
B13: CONTACTO:
B14: CORREO: | H14: CORTADA A LA MEDIDA | I14: SI | S14: ML CUBIERTAS
B15: FONO: | C15: +5697449 5259 | H15: DESPACHO: | I15: NO
B16: DIRECCION: | H16: FORMA DE PAGO: | I16: CONTADO
B17: CIUDAD: | C17: SANTIAGO | H17: DURACION COTIZACION: 5 DIAS FERNANDO DONOSO | L17: 142784
L18: 85767
B19: , | N19: 0.05 | Q19: TOTAL | R19: VALOR X MT2 | S19: ENCHAPE | T19: MT/L
B20: UNIDAD | C20: TIPO | D20: LARGO | E20: ANCHO | F20: FRENTE | G20: FONDO | H20: COLOR | I20: VALOR | J20: TOTAL | M20: =B20 -> UNIDAD | N20: ALTO | O20: =E20 -> ANCHO | P20: MT | Q20: MT2 | R20: =P48 -> 103887.98 | S20: 5000 | U20: m/l
B21: 1 | C21: CUBIERTA MESON ATENCION | D21: 1.81 | E21: 0.4 | F21: 0.2 | G21: 0.15 | H21: BLANCO BRILLO | I21: 150334 | J21: =I21*B21 -> 150334 | M21: =B21 -> 1 | N21: =D21+N$19 -> 1.86 | O21: =E21+F21+G21 -> 0.75 | P21: =N21*O21 -> 1.395 | Q21: =P21*M21 -> 1.395 | R21: =R$20*P21 -> 144923.73 | S21: =R21+S$20 -> 149923.73 | T21: =M21*N21 -> 1.86
B22: 1 | C22: CUBIERTA MESON ATENCION | D22: 1.77 | E22: 0.4 | F22: 0.2 | G22: 0.15 | H22: BLANCO BRILLO | I22: 147208 | J22: =I22*B22 -> 147208 | M22: =B22 -> 1 | N22: =D22+N$19 -> 1.82 | O22: =E22+F22+G22 -> 0.75 | P22: =N22*O22 -> 1.365 | Q22: =P22*M22 -> 1.365 | R22: =R$20*P22 -> 141807.09 | S22: =R22+S$20 -> 146807.09 | T22: =M22*N22 -> 1.82
B23: 1 | C23: CUBIERTA MESON ATENCION | D23: 0.835 | E23: 0.4 | F23: 0.2 | G23: 0.15 | H23: BLANCO BRILLO | I23: 74151 | J23: =I23*B23 -> 74151 | M23: =B23 -> 1 | N23: =D23+N$19 -> 0.885 | O23: =E23+F23+G23 -> 0.75 | P23: =N23*O23 -> 0.66375 | Q23: =P23*M23 -> 0.66375 | R23: =R$20*P23 -> 68955.645 | S23: =R23+S$20 -> 73955.645 | T23: =M23*N23 -> 0.885
B24: 2 | C24: CUBIERTA MESON ATENCION | D24: 1.57 | E24: 0.4 | F24: 0.2 | G24: 0.15 | H24: BLANCO BRILLO | I24: 131581 | J24: =I24*B24 -> 263162 | M24: =B24 -> 2 | N24: =D24+N$19 -> 1.62 | O24: =E24+F24+G24 -> 0.75 | P24: =N24*O24 -> 1.215 | Q24: =P24*M24 -> 2.43 | R24: =R$20*P24 -> 126223.89 | S24: =R24+S$20 -> 131223.89 | T24: =M24*N24 -> 3.24
B25: 1 | C25: CUBIERTA MESON ATENCION | D25: 1 | E25: 0.4 | F25: 0.2 | G25: 0.15 | H25: BLANCO BRILLO | I25: 87043 | J25: =I25*B25 -> 87043 | M25: =B25 -> 1 | N25: =D25+N$19 -> 1.05 | O25: =E25+F25+G25 -> 0.75 | P25: =N25*O25 -> 0.7875 | Q25: =P25*M25 -> 0.7875 | R25: =R$20*P25 -> 81811.782 | S25: =R25+S$20 -> 86811.782 | T25: =M25*N25 -> 1.05
B26: 2 | C26: CUBIERTA MESON ATENCION | D26: 1.57 | E26: 0.4 | F26: 0.2 | G26: 0.15 | H26: BLANCO BRILLO | I26: 131581 | J26: =I26*B26 -> 263162 | M26: =B26 -> 2 | N26: =D26+N$19 -> 1.62 | O26: =E26+F26+G26 -> 0.75 | P26: =N26*O26 -> 1.215 | Q26: =P26*M26 -> 2.43 | R26: =R$20*P26 -> 126223.89 | S26: =R26+S$20 -> 131223.89 | T26: =M26*N26 -> 3.24
B27: 2 | C27: CUBIERTA MESON ATENCION | D27: 1.57 | E27: 0.4 | F27: 0.2 | G27: 0.15 | H27: BLANCO BRILLO | I27: 131581 | J27: =I27*B27 -> 263162 | M27: =B27 -> 2 | N27: =D27+N$19 -> 1.62 | O27: =E27+F27+G27 -> 0.75 | P27: =N27*O27 -> 1.215 | Q27: =P27*M27 -> 2.43 | R27: =R$20*P27 -> 126223.89 | S27: =R27+S$20 -> 131223.89 | T27: =M27*N27 -> 3.24
B28: 2 | C28: CUBIERTA MESON ATENCION | D28: 1.57 | E28: 0.4 | F28: 0.2 | G28: 0.15 | H28: BLANCO BRILLO | I28: 131581 | J28: =I28*B28 -> 263162 | M28: =B28 -> 2 | N28: =D28+N$19 -> 1.62 | O28: =E28+F28+G28 -> 0.75 | P28: =N28*O28 -> 1.215 | Q28: =P28*M28 -> 2.43 | R28: =R$20*P28 -> 126223.89 | S28: =R28+S$20 -> 131223.89 | T28: =M28*N28 -> 3.24
B29: 12 | C29: CORTE CUBIERTAS | I29: 10000 | J29: =I29*B29 -> 120000 | M29: =B29 -> 12
H30: SERVICIO EXPRESS | I30: RECARGO 5% | J30: 75569 | L30: =J32*5% -> 85347.65
I32: NETO | J32: =SUM(J21:J31) -> 1706953
I33: IVA | J33: =J32*19% -> 324321.07
I34: TOTAL | J34: =J32+J33 -> 2031274.1 | N34: =N21+#REF! -> #REF!
L35: 103577 | Q35: =SUM(Q21:Q33) -> 13.93125
Q36: =Q35 -> 13.93125 | T36: =SUM(T21:T35) -> 18.575
Q37: =Q36*20% -> 2.78625 | R37: 20% PERDIDA
Q38: =Q36+Q37 -> 16.7175 | T38: 40
N40: =Q38*1 -> 16.7175 | O40: 3500 | P40: =N40*O40 -> 58511.25 | Q40: ADHESIVO | R40: TRASCARA ENCHAPADA, ES POR 2 | Y40: O
N41: 5 | O41: 27000 | P41: =N41*O41 -> 135000 | Q41: MDF18MM
O42: 50000 | P42: =N42*O42 -> 0 | Q42: LAMINA 153 X 366 | W42: 33390
B43: CUENTA CORRIENTE BANCO SANTANDER Nº 87316181 A NOMBRE DE MUEBLES SANTA FE SPA | N43: 10 | O43: 22000 | P43: =N43*O43 -> 220000 | Q43: LAMINA 122X244 | W43: =W42/1.19 -> 28058.824
B44: RUT : 77.054.606-0 VENTAS@TOPMOBILI.CL | O44: 800 | Q44: ZACALO | S44: 1.52
...

Sheet COSTOS
B2: CENTRO DE COSTOS POSTFORMADOS
B5: FECHA: | C5: ='2229'!I10 -> 45310
B6: CLIENTE: | C6: ='2229'!C10 -> JOSE MIGUEL RIOCA | N6: Ventas Equilibrio = | P6: Costos Fijos Totales
B7: DIRECCION: | C7: ='2229'!#REF! -> #REF! | H7: COSTOS INDIRECTOS DE FABRICA VARIABLES | O7: 1 - | P7: Costos Variables Totales
B8: PRESUPUESTO: | C8: ='2229'!D8 -> 10544 | H8: Q/HRS | I8: $ | J8: DETALLE | K8: TOTAL | L8: TOTAL | P8: Total Venta | X8: =SUM(Q11:Q16) -> 6
H9: CANTIDAD | I9: PRECIO | J9: MATERIA PRIMA INDIRECTA | L9: =SUM(K10:K23) -> 2550 | S9: DETALLE | X9: =(E15-D11)/X8 -> -277125.71
D10: NETO | E10: IVA | F10: TOTAL | H10: 3 | I10: 350 | J10: RESPALDO | K10: =I10*H10 -> 1050 | Q10: UNIDAD | R10: TIPO | S10: LARGO | T10: ANCHO | U10: COLOR | V10: VALOR | W10: TOTAL
C11: MONTO A COBRAR | D11: ='2229'!J34 -> 2031274.1 | E11: =D11*0.19 -> 385942.07 | F11: =E11+D11 -> 2417216.1 | H11: 3 | I11: 500 | J11: MEDIA CAÑA | K11: =I11*H11 -> 1500 | Q11: 1 | R11: CUB C/R R8 | S11: 2.8 | T11: 0.62 | U11: MADERA X DEFINIR | V11: 105990 | W11: =V11*Q11 -> 105990 | X11: =V11+$X$9 -> -171135.71 | Y11: 108990
C12: COSTO TOTAL | D12: =SUM(M43:M45) -> 223345.34 | H12: 0 | I12: 7500 | J12: DUROLAC | K12: =I12*H12 -> 0 | Q12: 1 | R12: CUB C/R R8 | S12: 2.3 | T12: 0.62 | U12: MADERA X DEFINIR | V12: 87990 | W12: =V12*Q12 -> 87990 | X12: =V12+$X$9 -> -189135.71 | Y12: 89990
C13: % UTILIDAD | D13: =D11-D12 -> 1807928.7 | E13: =(D11/D12)-1 -> 8.0947681 | H13: 0 | I13: 50 | J13: TAPACANTO PVC | K13: =I13*H13 -> 0 | Q13: 1 | R13: CUB C/R R8 | S13: 2.03 | T13: 0.62 | U13: MADERA X DEFINIR | V13: 78990 | W13: =V13*Q13 -> 78990 | X13: =V13+$X$9 -> -198135.71 | Y13: 81990
D14: % utilidad | E14: NETO | F14: UTILIDAD | H14: 0 | I14: 50 | J14: SOBERBIOS | K14: =I14*H14 -> 0 | Q14: 1 | R14: CUB C/R R8 | S14: 1.08 | T14: 0.62 | U14: MADERA X DEFINIR | V14: 39990 | W14: =V14*Q14 -> 39990 | X14: =V14+$X$9 -> -237135.71 | Y14: 39990
C15: PROYECCION | D15: 0.65 | E15: =(100%+D15)*D12 -> 368519.81 | F15: =E15-D12 -> 145174.47 | H15: 0 | I15: 10 | J15: SOPORTE REPISA | K15: =I15*H15 -> 0 | Q15: 1 | R15: CUB C/R R8 | S15: 1.08 | T15: 0.62 | U15: MADERA X DEFINIR | V15: 39990 | W15: =V15*Q15 -> 39990 | X15: =V15+$X$9 -> -237135.71 | Y15: 39990
H16: 1 | J16: PUNTAS | K16: =I16*H16 -> 0 | Q16: 1 | R16: CUB C/R R8 | S16: 2.06 | T16: 0.62 | U16: MADERA X DEFINIR | V16: 79990 | W16: =V16*Q16 -> 79990 | X16: =V16+$X$9 -> -197135.71 | Y16: 83990
B17: M. PRIMA | C17: MATERIAL | D17: NETO | E17: IVA | F17: TOTAL | H17: 1 | J17: TORNILLOS | K17: =I17*H17 -> 0 | Q17: 6 | R17: CORTES 45° | V17: 5000 | W17: =V17*Q17 -> 30000
C18: LAMINA | D18: ='2229'!P42 -> 0 | E18: =D18*0.19 -> 0 | F18: =SUM(D18:E18) -> 0 | H18: 1 | J18: COLAFRIA | K18: =I18*H18 -> 0 | Q18: 1 | R18: PERFORACION LAVAPLATOS | V18: 10000 | W18: =V18*Q18 -> 10000
C19: MDF 18MM | D19: ='2229'!P41 -> 135000 | E19: =D19*0.19 -> 25650 | F19: =SUM(D19:E19) -> 160650 | H19: 1 | J19: LIJAS | K19: =I19*H19 -> 0 | V19: NETO | W19: =SUM(W11:W18) -> 472940 | Y19: =SUM(Y11:Y16)+SUM(W17:W18) -> 484940
C20: ADHESIVO | D20: ='2229'!P40 -> 58511.25 | E20: =D20*0.19 -> 11117.138 | F20: =SUM(D20:E20) -> 69628.388 | H20: 1 | J20: CARTON | K20: =I20*H20 -> 0 | V20: I.V.A. | W20: =W19*19% -> 89858.6 | Y20: =Y19*0.19 -> 92138.6
A21: =450000*1.2 -> 540000 | C21: TOTAL | D21: =SUM(D18:D20) -> 193511.25 | E21: =SUM(E18:E20) -> 36767.137 | F21: =SUM(F18:F20) -> 230278.39 | H21: 1 | J21: GUAIPE | K21: =I21*H21 -> 0 | M21: =B32/9 -> 2318.8406 | Q21: PLAZO DE ENTREGA : 8 DIAS HABILES | V21: TOTAL | W21: =W19+W20 -> 562798.6 | Y21: =SUM(Y19:Y20) -> 577078.6
A22: =450000*1.2 -> 540000 | B22: M. DE OBRA | C22: PROCESO | D22: COSTO x Hr. | E22: Q Hrs. | F22: TOTAL | H22: 1 | J22: DILUYENTE | K22: =I22*H22 -> 0 | Q22: FORMA DE PAGO: 50% CONTADO, SALDO C/E
A23: =800000*1.2 -> 960000 | B23: =A21/23 -> 23478.261 | C23: CORTE | D23: =B23/9 -> 2608.6957 | E23: 0.5 | F23: =D23*E23 -> 1304.3478 | H23: 1 | J23: CINTA EMBALAJE | K23: =I23*H23 -> 0 | Q23: VALIDEZ COTIZACIÓN: 5 DIAS
A24: 450000 | B24: =A22/23 -> 23478.261 | C24: CORTE LAMINA | D24: =B24/9 -> 2608.6957 | E24: 0.5 | F24: =D24*E24 -> 1304.3478 | H24: Q/HRS | I24: PRECIO | J24: MANO DE OBRA INDIRECTA | K24: VALOR | L24: =SUM(K25:K35) -> 0
A25: 450000 | B25: =A23/23 -> 41739.13 | C25: REBAJE LAMINA | D25: =B25/9 -> 4637.6812 | F25: =D25*E25 -> 0 | H25: 0 | I25: =((480000/23)/9) -> 2318.8406 | J25: FLETERO (HRS) | K25: =H25*I25 -> 0
B26: =A24/23 -> 19565.217 | C26: TUPIZADO | D26: =B26/9 -> 2173.913 | E26: 0.5 | F26: =D26*E26 -> 1086.9565 | H26: 0 | J26: BENCINA | K26: =H26*I26 -> 0
A27: 350000 | B27: =A25/23 -> 19565.217 | C27: ARMADO | D27: =B27/9 -> 2173.913 | E27: 0.5 | F27: =D27*E27 -> 1086.9565 | H27: 0 | J27: TAG | K27: =H27*I27 -> 0
A28: 500000 | B28: =A27/23 -> 15217.391 | C28: PEGADO | D28: =B28/9 -> 1690.8213 | E28: 0.7 | F28: =D28*E28 -> 1183.5749 | H28: 0 | J28: RECTIFICACION | K28: =H28*I28 -> 0
B29: =A28/23 -> 21739.13 | C29: POSTFORMADO | D29: =B29/9 -> 2415.4589 | E29: 0.7 | F29: =D29*E29 -> 1690.8213 | H29: 0 | I29: =((550000*1.2)/23)/9 -> 3188.4058 | J29: HR. TRAB. JUAN | K29: =H29*I29 -> 0
A30: 450000 | C30: MEDIA CAÑA | D30: 2415 | F30: =D30*E30 -> 0 | H30: 0 | I30: =((450000*1.2)/23)/9 -> 2608.6957 | J30: HR. TRAB. JULIO | K30: =H30*I30 -> 0
A31: 350000 | B31: =A30/23 -> 19565.217 | C31: CORTE-ENCHAPE | D31: =B31/9 -> 2173.913 | E31: 0 | F31: =D31*E31 -> 0 | H31: 0 | I31: =((450000*1.2)/23)/9 -> 2608.6957 | J31: HR. TRAB. EUGE | K31: =H31*I31 -> 0
A32: =A21+A24+A27+A28+A30 -> 2290000 | B32: =480000/23 -> 20869.565 | C32: CONTROL CALIDAD | D32: =B32/9 -> 2318.8406 | E32: 0.5 | F32: =D32*E32 -> 1159.4203 | H32: 0 | J32: COLACION | K32: =H32*I32 -> 0
C33: TOTAL | D33: =SUM(D23:D32) -> 25216.932 | E33: =SUM(E23:E32) -> 3.9 | F33: =SUM(F23:F32) -> 8816.4251 | H33: 0 | J33: BONO | K33: =H33*I33 -> 0
B34: CIF | C34: M. PRIMA INDIREC. | D34: =L9 -> 2550 | H34: 1 | J34: PERFORACION | K34: =H34*I34 -> 0
C35: M. OBRA INDIRECTA | D35: =L24 -> 0 | H35: 6 | J35: CORTE 45 | K35: =H35*I35 -> 0
C36: GASTOS DE FABRICA | D36: =L36 -> 18467.666 | H36: CANTIDAD | I36: PRECIO | J36: GASTOS DE FABRICACION | K36: VALOR | L36: =SUM(K37:K39) -> 18467.666
C37: DEPRECIACIONES | H37: =$E$33 -> 3.9 | I37: =32609.69/9 -> 3623.2989 | J37: ARRIENDO x HORA | K37: =I37*H37 -> 14130.866
C38: TOTAL | D38: =SUM(D34:D37) -> 21017.666 | H38: =$E$33 -> 3.9 | I38: 967 | J38: AGUA x HORA | K38: =I38*H38 -> 3771.3
H39: =$E$33 -> 3.9 | I39: 145 | J39: LUZ x HORA | K39: =I39*H39 -> 565.5
B40: PROVISIONAR | C40: IVA | D40: =E11-E21 -> 349174.94
H41: ESTADO DE RESULTADOS
B42: TOTAL HRS TRABAJADAS | D42: =E33 -> 3.9 | H42: INGRESOS | I42: + TOTAL VENTA | M42: =D11 -> 2031274.1
H43: COSTOS | I43: - MATERIA PRIMA DIRECTA | M43: =D21 -> 193511.25
...
