Workbook

Sheet 2229
I2: MUEBLES SANTA FE SPA
I3: VENTAS POR MENOR DE MUEBLES
I4: RUT: 77.054.606-0
I5: SEPTIMA AVENIDA 1631, SAN MIGUEL
I6: FONO +569 2032 3382 | S6: 10077 SF PORTLAND MAPLE
I7: E-MAIL: ventas@topmobili.cl
B8: P R E S U P U E S T O | D8: N° 12021
B10: NOMBRE: | C10: SISTEMA MUEBLES | I10: FECHA | K10: 45725
B11: RUT: | C11: 77.091.475-2 | I11: PLAZO ENTREGA | K11: 15 DIAS HABILES | V11: MT2 PUERTAS
B12: GIRO: | I12: SERVICIO EXPRESS | K12: NO
B13: CONTACTO: | I13: CORTADA A LA MEDIDA | K13: NO
B14: CORREO: | I14: DESPACHO | K14: NO | V14: ML CUBIERTAS
B15: FONO: | C15: +569 | I15: INSTALACIÓN | K15: NO
B16: DIRECCION: | I16: FORMA DE PAGO: | K16: ABONO 50% SALDO C/ENTREGA
B17: CIUDAD: | C17: SANTIAGO | I17: Duración cotización 5 días hábiles | K17: Cotizado por: Franco Donoso
B19: DETALLE | Q19: 0.08 | T19: TOTAL | U19: VALOR X MT2 | V19: ENCHAPE | W19: MT/L
B20: UNIDAD | C20: TIPO | D20: LARGO | E20: ANCHO | F20: SUSTRATO | G20: TIPO | H20: NV | I20: COLOR | J20: TRASCARA | K20: VALOR | L20: TOTAL | M20: formato grande | N20: estándar | P20: =B20 -> UNIDAD | Q20: ALTO | R20: =E20 -> ANCHO | S20: MT | T20: MT2 | U20: =S53 -> 181220.05 | V20: 3000 | X20: m/l
B21: 1 | C21: CUBIERTA SIN RESPALDO FRENTE 180° | D21: 1.046 | E21: 0.49 | F21: MDF25MM | G21: C1 | H21: 2802-3 | I21: GLACIAL WHITE 22191 SF | J21: MISMA LAMINA | K21: 49816 | L21: =K21*B21 -> 49816 | M21: despunte | Q21: =D21+Q$19 -> 1.126 | R21: =E21+$R$19 -> 0.49 | S21: =Q21*R21 -> 0.55174 | T21: =S21*P21 -> 0 | U21: =U$20*S21 -> 99986.352 | W21: =Q21*P21 -> 0 | X21: =R21*2*P21*2 -> 0
B22: 7 | C22: CUB MESA FRENTE 180° 2 LADOS | D22: 1.05 | E22: 0.387 | F22: MDF25MM | G22: C3 | H22: 2802-3 | I22: GLACIAL WHITE 22191 SF | J22: MISMA LAMINA | K22: 40107 | L22: =K22*B22 -> 280749 | Q22: =D22+Q$19 -> 1.13 | R22: =E22+$R$19 -> 0.387 | S22: =Q22*R22 -> 0.43731 | T22: =S22*P22 -> 0 | U22: =U$20*S22 -> 79249.341 | W22: =Q22*P22 -> 0
B23: 7 | C23: CORNISA FRENTE 90° R8 1 LADO | D23: 1.05 | E23: 0.18 | F23: MDF18MM | G23: C4 | H23: 2802-3 | I23: GLACIAL WHITE 22191 SF | J23: BALANCE | K23: 23370 | L23: =K23*B23 -> 163590 | N23: 1 + 1 balance | O23: 18mm | Q23: =D23+Q$19 -> 1.13 | R23: =E23+$R$19 -> 0.18 | S23: =Q23*R23 -> 0.2034 | T23: =S23*P23 -> 0 | U23: =U$20*S23 -> 36860.159 | V23: =U23+V$20 -> 39860.159 | W23: =V23*P23 -> 0
B24: 7 | C24: CORNISA FRENTE 180° R8 1 LADO | D24: 1.05 | E24: 0.155 | F24: MDF30MM | G24: C5 | H24: 2802-3 | I24: GLACIAL WHITE 22191 SF | J24: MISMA LAMINA | K24: 32390 | L24: =K24*B24 -> 226730 | O24: 30mm | P24: =B24 -> 7 | Q24: =D24+Q$19 -> 1.13 | R24: =E24+$R$19 -> 0.155 | S24: =Q24*R24 -> 0.17515 | T24: =S24*P24 -> 1.22605 | U24: =U$20*S24 -> 31740.692 | V24: =U24+V$20 -> 34740.692 | W24: =Q24*P24 -> 7.91
B25: 1 | C25: CUB MESA FRENTE 180° 2 LADOS | D25: 1.05 | E25: 1.063 | F25: MDF25MM | G25: C6 | H25: 2802-3 | I25: GLACIAL WHITE 22191 SF | J25: BALANCE | K25: 104923 | L25: =K25*B25 -> 104923 | N25: 1 | Q25: =D25+Q$19 -> 1.13 | R25: =E25+$R$19 -> 1.063 | S25: =Q25*R25 -> 1.20119 | T25: =S25*P25 -> 0 | U25: =U$20*S25 -> 217679.71 | W25: =Q25*P25 -> 0
B26: 6 | C26: CUBIERTA SIN RESPALDO FRENTE 180° | D26: 1.05 | E26: 0.7 | F26: MDF25MM | G26: C7 | H26: 2802-3 | I26: GLACIAL WHITE 22191 SF | J26: BALANCE | K26: 70118 | L26: =K26*B26 -> 420708 | M26: 1 | Q26: =D26+Q$19 -> 1.13 | R26: =E26+$R$19 -> 0.7 | S26: =Q26*R26 -> 0.791 | T26: =S26*P26 -> 0 | U26: =U$20*S26 -> 143345.06 | W26: =Q26*P26 -> 0
B27: 1 | C27: CUB MESA FRENTE 180° 2 LADOS | D27: 1.05 | E27: 1.063 | F27: MDF25MM | G27: C6 | H27: 2802-4 | I27: GLACIAL WHITE 22191 SF | J27: BALANCE | K27: 104923 | L27: =K27*B27 -> 104923 | Q27: =D27+Q$19 -> 1.13 | R27: =E27+$R$19 -> 1.063 | S27: =Q27*R27 -> 1.20119 | T27: =S27*P27 -> 0 | U27: =U$20*S27 -> 217679.71 | W27: =Q27*P27 -> 0
B28: 1 | C28: CORNISA FRENTE 90° R8 1 LADO | D28: 2.89 | E28: 0.18 | F28: MDF18MM | G28: C4 | H28: 2802-4 | I28: GLACIAL WHITE 22191 SF | J28: BALANCE | K28: 51283 | L28: =K28*B28 -> 51283 | N28: 1 + 1 balance | O28: 18mm | Q28: =D28+Q$19 -> 2.97 | R28: =E28+$R$19 -> 0.18 | S28: =Q28*R28 -> 0.5346 | T28: =S28*P28 -> 0 | U28: =U$20*S28 -> 96880.24 | V28: =U28+V$20 -> 99880.24 | W28: =V28*P28 -> 0
B29: 2 | C29: CENEFA 90° 2 LADOS R8 | D29: 1.65 | E29: 0.387 | F29: MDF25MM | G29: C11 | H29: 2802-4 | I29: GLACIAL WHITE 22191 SF | J29: MISMA LAMINA | K29: 59809 | L29: =K29*B29 -> 119618 | M29: 0.5 | Q29: =D29+Q$19 -> 1.73 | R29: =E29+$R$19 -> 0.387 | S29: =Q29*R29 -> 0.66951 | T29: =S29*P29 -> 0 | U29: =U$20*S29 -> 121328.64 | W29: =Q29*P29 -> 0
B30: 1 | C30: CUBIERTA SIN RESPALDO FRENTE 180° | D30: 2.89 | E30: 0.8 | F30: MDF25MM | G30: C12 | H30: 2802-4 | I30: GLACIAL WHITE 22191 SF | J30: BALANCE | K30: 204608 | L30: =K30*B30 -> 204608 | N30: 1 | Q30: =D30+Q$19 -> 2.97 | R30: =E30+$R$19 -> 0.8 | S30: =Q30*R30 -> 2.376 | T30: =S30*P30 -> 0 | U30: =U$20*S30 -> 430578.84 | W30: =Q30*P30 -> 0
B31: 1 | C31: CUB MESA FRENTE 180° 2 LADOS | D31: 1.575 | E31: 1.063 | F31: MDF25MM | G31: C13 | H31: 2802-5 | I31: GLACIAL WHITE 22191 SF | J31: BALANCE | K31: 152277 | L31: =K31*B31 -> 152277 | M31: 1 | Q31: =D31+Q$19 -> 1.655 | R31: =E31+$R$19 -> 1.063 | S31: =Q31*R31 -> 1.759265 | T31: =S31*P31 -> 0 | U31: =U$20*S31 -> 318814.1 | W31: =Q31*P31 -> 0
B32: 1 | C32: CUB MESA FRENTE 180° 2 LADOS | D32: 1.475 | E32: 1.063 | F32: MDF25MM | G32: C14 | H32: 2802-5 | I32: GLACIAL WHITE 22191 SF | J32: BALANCE | K32: 143257 | L32: =K32*B32 -> 143257 | Q32: =D32+Q$19 -> 1.555 | R32: =E32+$R$19 -> 1.063 | S32: =Q32*R32 -> 1.652965 | T32: =S32*P32 -> 0 | U32: =U$20*S32 -> 299550.4 | W32: =Q32*P32 -> 0
B33: 4 | C33: CENEFA 90° 2 LADOS R8 | D33: 1.575 | E33: 0.4 | F33: MDF25MM | G33: C15 | H33: 2802-5 | I33: GLACIAL WHITE 22191 SF | J33: MISMA LAMINA | K33: 59172 | L33: =K33*B33 -> 236688 | M33: 1.5 | Q33: =D33+Q$19 -> 1.655 | R33: =E33+$R$19 -> 0.4 | S33: =Q33*R33 -> 0.662 | T33: =S33*P33 -> 0 | U33: =U$20*S33 -> 119967.67 | W33: =Q33*P33 -> 0
B34: 5 | C34: CENEFA 90° 2 LADOS R8 | D34: 1.475 | E34: 0.4 | F34: MDF25MM | G34: C16 | H34: 2802-5 | I34: GLACIAL WHITE 22191 SF | J34: MISMA LAMINA | K34: 55778 | L34: =K34*B34 -> 278890 | M34: 1 | Q34: =D34+Q$19 -> 1.555 | R34: =E34+$R$19 -> 0.4 | S34: =Q34*R34 -> 0.622 | T34: =S34*P34 -> 0 | U34: =U$20*S34 -> 112718.87 | W34: =Q34*P34 -> 0
B35: 4 | C35: CUBIERTA SIN RESPALDO FRENTE 180° | D35: 1.575 | E35: 0.79 | F35: MDF25MM | G35: C17 | H35: 2802-5 | I35: GLACIAL WHITE 22191 SF | J35: BALANCE | K35: 113940 | L35: =K35*B35 -> 455760 | M35: 4.5 | Q35: =D35+Q$19 -> 1.655 | R35: =E35+$R$19 -> 0.79 | S35: =Q35*R35 -> 1.30745 | T35: =S35*P35 -> 0 | U35: =U$20*S35 -> 236936.16 | W35: =Q35*P35 -> 0
B36: 5 | C36: CUBIERTA SIN RESPALDO FRENTE 180° | D36: 1.475 | E36: 0.79 | F36: MDF25MM | G36: C18 | H36: 2802-5 | I36: GLACIAL WHITE 22191 SF | J36: BALANCE | K36: 107236 | L36: =K36*B36 -> 536180 | Q36: =D36+Q$19 -> 1.555 | R36: =E36+$R$19 -> 0.79 | S36: =Q36*R36 -> 1.22845 | T36: =S36*P36 -> 0 | U36: =U$20*S36 -> 222619.77 | W36: =Q36*P36 -> 0
K39: NETO | L39: =SUM(L21:L36) -> 3530000 | N39: 2258362 | X39: =SUM(X21:X21) -> 0
K40: IVA | L40: =L39*19% -> 670700 | Q40: =SUM(Q21:Q39) -> 25.206 | T40: =SUM(T21:T37) -> 1.22605 | V40: =SUM(V22:V39) -> 174481.09 | W40: =SUM(W23:W39) -> 7.91
K41: TOTAL | L41: =L39+L40 -> 4200700 | T41: =T40 -> 1.22605
T42: =T41*20% -> 0.24521 | U42: 20% PERDIDA | W42: =W41+X39 -> 0
T43: =T41+T42 -> 1.47126 | W43: =W42*20% -> 0
N44: laminas | O44: laminas | P44: laminas | W44: =W42+W43 -> 0 | Y44: ADHESIVO | Z44: 58.000.- | AA44: 44971
N45: 30mm | O45: 25mm | P45: 18mm | Q45: =T43*2 -> 2.94252 | R45: 3500 | S45: =Q45*R45 -> 10298.82 | T45: ADHESIVO | Y45: LATA 16 LTS | Z45: 3625 | AA45: LITRO
...

Sheet COSTOS
B2: CENTRO DE COSTOS POSTFORMADOS
B5: FECHA: | C5: ='2229'!K10 -> 45725
B6: CLIENTE: | C6: ='2229'!C10 -> SISTEMA MUEBLES | N6: Ventas Equilibrio = | P6: Costos Fijos Totales
B7: DIRECCION: | C7: ='2229'!#REF! -> #REF! | H7: COSTOS INDIRECTOS DE FABRICA VARIABLES | O7: 1 - | P7: Costos Variables Totales
B8: PRESUPUESTO: | C8: ='2229'!D8 -> N° 12021 | H8: Q/HRS | I8: $ | J8: DETALLE | K8: TOTAL | L8: TOTAL | P8: Total Venta | X8: =SUM(Q11:Q16) -> 6
H9: CANTIDAD | I9: PRECIO | J9: MATERIA PRIMA INDIRECTA | L9: =SUM(K10:K23) -> 2550 | S9: DETALLE | X9: =(E15-D11)/X8 -> -565334.28
D10: NETO | E10: IVA | F10: TOTAL | H10: 3 | I10: 350 | J10: RESPALDO | K10: =I10*H10 -> 1050 | Q10: UNIDAD | R10: TIPO | S10: LARGO | T10: ANCHO | U10: COLOR | V10: VALOR | W10: TOTAL
C11: MONTO A COBRAR | D11: ='2229'!L39 -> 3530000 | E11: =D11*0.19 -> 670700 | F11: =E11+D11 -> 4200700 | H11: 3 | I11: 500 | J11: MEDIA CAÑA | K11: =I11*H11 -> 1500 | Q11: 1 | R11: CUB C/R R8 | S11: 2.8 | T11: 0.62 | U11: MADERA X DEFINIR | V11: 105990 | W11: =V11*Q11 -> 105990 | X11: =V11+$X$9 -> -459344.28 | Y11: 108990
C12: COSTO TOTAL | D12: =SUM(M43:M45) -> 83632.911 | H12: 0 | I12: 7500 | J12: DUROLAC | K12: =I12*H12 -> 0 | Q12: 1 | R12: CUB C/R R8 | S12: 2.3 | T12: 0.62 | U12: MADERA X DEFINIR | V12: 87990 | W12: =V12*Q12 -> 87990 | X12: =V12+$X$9 -> -477344.28 | Y12: 89990
C13: % UTILIDAD | D13: =D11-D12 -> 3446367.1 | E13: =(D11/D12)-1 -> 41.208264 | H13: 0 | I13: 50 | J13: TAPACANTO PVC | K13: =I13*H13 -> 0 | Q13: 1 | R13: CUB C/R R8 | S13: 2.03 | T13: 0.62 | U13: MADERA X DEFINIR | V13: 78990 | W13: =V13*Q13 -> 78990 | X13: =V13+$X$9 -> -486344.28 | Y13: 81990
D14: % utilidad | E14: NETO | F14: UTILIDAD | H14: 0 | I14: 50 | J14: SOBERBIOS | K14: =I14*H14 -> 0 | Q14: 1 | R14: CUB C/R R8 | S14: 1.08 | T14: 0.62 | U14: MADERA X DEFINIR | V14: 39990 | W14: =V14*Q14 -> 39990 | X14: =V14+$X$9 -> -525344.28 | Y14: 39990
C15: PROYECCION | D15: 0.65 | E15: =(100%+D15)*D12 -> 137994.3 | F15: =E15-D12 -> 54361.392 | H15: 0 | I15: 10 | J15: SOPORTE REPISA | K15: =I15*H15 -> 0 | Q15: 1 | R15: CUB C/R R8 | S15: 1.08 | T15: 0.62 | U15: MADERA X DEFINIR | V15: 39990 | W15: =V15*Q15 -> 39990 | X15: =V15+$X$9 -> -525344.28 | Y15: 39990
H16: 1 | J16: PUNTAS | K16: =I16*H16 -> 0 | Q16: 1 | R16: CUB C/R R8 | S16: 2.06 | T16: 0.62 | U16: MADERA X DEFINIR | V16: 79990 | W16: =V16*Q16 -> 79990 | X16: =V16+$X$9 -> -485344.28 | Y16: 83990
B17: M. PRIMA | C17: MATERIAL | D17: NETO | E17: IVA | F17: TOTAL | H17: 1 | J17: TORNILLOS | K17: =I17*H17 -> 0 | Q17: 6 | R17: CORTES 45° | V17: 5000 | W17: =V17*Q17 -> 30000
C18: LAMINA | D18: ='2229'!S47 -> 0 | E18: =D18*0.19 -> 0 | F18: =SUM(D18:E18) -> 0 | H18: 1 | J18: COLAFRIA | K18: =I18*H18 -> 0 | Q18: 1 | R18: PERFORACION LAVAPLATOS | V18: 10000 | W18: =V18*Q18 -> 10000
C19: MDF 18MM | D19: ='2229'!S46 -> 43500 | E19: =D19*0.19 -> 8265 | F19: =SUM(D19:E19) -> 51765 | H19: 1 | J19: LIJAS | K19: =I19*H19 -> 0 | V19: NETO | W19: =SUM(W11:W18) -> 472940 | Y19: =SUM(Y11:Y16)+SUM(W17:W18) -> 484940
C20: ADHESIVO | D20: ='2229'!S45 -> 10298.82 | E20: =D20*0.19 -> 1956.7758 | F20: =SUM(D20:E20) -> 12255.596 | H20: 1 | J20: CARTON | K20: =I20*H20 -> 0 | V20: I.V.A. | W20: =W19*19% -> 89858.6 | Y20: =Y19*0.19 -> 92138.6
A21: =450000*1.2 -> 540000 | C21: TOTAL | D21: =SUM(D18:D20) -> 53798.82 | E21: =SUM(E18:E20) -> 10221.776 | F21: =SUM(F18:F20) -> 64020.596 | H21: 1 | J21: GUAIPE | K21: =I21*H21 -> 0 | M21: =B32/9 -> 2318.8406 | Q21: PLAZO DE ENTREGA : 8 DIAS HABILES | V21: TOTAL | W21: =W19+W20 -> 562798.6 | Y21: =SUM(Y19:Y20) -> 577078.6
A22: =450000*1.2 -> 540000 | B22: M. DE OBRA | C22: PROCESO | D22: COSTO x Hr. | E22: Q Hrs. | F22: TOTAL | H22: 1 | J22: DILUYENTE | K22: =I22*H22 -> 0 | Q22: FORMA DE PAGO: 50% CONTADO, SALDO C/E
A23: =800000*1.2 -> 960000 | B23: =A21/23 -> 23478.261 | C23: CORTE | D23: =B23/9 -> 2608.6957 | E23: 0.5 | F23: =D23*E23 -> 1304.3478 | H23: 1 | J23: CINTA EMBALAJE | K23: =I23*H23 -> 0 | Q23: VALIDEZ COTIZACIÓN: 5 DIAS
A24: 450000 | B24: =A22/23 -> 23478.261 | C24: CORTE LAMINA | D24: =B24/9 -> 2608.6957 | E24: 0.5 | F24: =D24*E24 -> 1304.3478 | H24: Q/HRS | I24: PRECIO | J24: MANO DE OBRA INDIRECTA | K24: VALOR | L24: =SUM(K25:K35) -> 0
A25: 450000 | B25: =A23/23 -> 41739.13 | C25: REBAJE LAMINA | D25: =B25/9 -> 4637.6812 | F25: =D25*E25 -> 0 | H25: 0 | I25: =((480000/23)/9) -> 2318.8406 | J25: FLETERO (HRS) | K25: =H25*I25 -> 0
B26: =A24/23 -> 19565.217 | C26: TUPIZADO | D26: =B26/9 -> 2173.913 | E26: 0.5 | F26: =D26*E26 -> 1086.9565 | H26: 0 | J26: BENCINA | K26: =H26*I26 -> 0
A27: 350000 | B27: =A25/23 -> 19565.217 | C27: ARMADO | D27: =B27/9 -> 2173.913 | E27: 0.5 | F27: =D27*E27 -> 1086.9565 | H27: 0 | J27: TAG | K27: =H27*I27 -> 0
A28: 500000 | B28: =A27/23 -> 15217.391 | C28: PEGADO | D28: =B28/9 -> 1690.8213 | E28: 0.7 | F28: =D28*E28 -> 1183.5749 | H28: 0 | J28: RECTIFICACION | K28: =H28*I28 -> 0
B29: =A28/23 -> 21739.13 | C29: POSTFORMADO | D29: =B29/9 -> 2415.4589 | E29: 0.7 | F29: =D29*E29 -> 1690.8213 | H29: 0 | I29: =((550000*1.2)/23)/9 -> 3188.4058 | J29: HR. TRAB. JUAN | K29: =H29*I29 -> 0
A30: 450000 | C30: MEDIA CAÑA | D30: 2415 | F30: =D30*E30 -> 0 | H30: 0 | I30: =((450000*1.2)/23)/9 -> 2608.6957 | J30: HR. TRAB. JULIO | K30: =H30*I30 -> 0
A31: 350000 | B31: =A30/23 -> 19565.217 | C31: CORTE-ENCHAPE | D31: =B31/9 -> 2173.913 | E31: 0 | F31: =D31*E31 -> 0 | H31: 0 | I31: =((450000*1.2)/23)/9 -> 2608.6957 | J31: HR. TRAB. EUGE | K31: =H31*I31 -> 0
A32: =A21+A24+A27+A28+A30 -> 2290000 | B32: =480000/23 -> 20869.565 | C32: CONTROL CALIDAD | D32: =B32/9 -> 2318.8406 | E32: 0.5 | F32: =D32*E32 -> 1159.4203 | H32: 0 | J32: COLACION | K32: =H32*I32 -> 0
C33: TOTAL | D33: =SUM(D23:D32) -> 25216.932 | E33: =SUM(E23:E32) -> 3.9 | F33: =SUM(F23:F32) -> 8816.4251 | H33: 0 | J33: BONO | K33: =H33*I33 -> 0
B34: CIF | C34: M. PRIMA INDIREC. | D34: =L9 -> 2550 | H34: 1 | J34: PERFORACION | K34: =H34*I34 -> 0
C35: M. OBRA INDIRECTA | D35: =L24 -> 0 | H35: 6 | J35: CORTE 45 | K35: =H35*I35 -> 0
C36: GASTOS DE FABRICA | D36: =L36 -> 18467.666 | H36: CANTIDAD | I36: PRECIO | J36: GASTOS DE FABRICACION | K36: VALOR | L36: =SUM(K37:K39) -> 18467.666
C37: DEPRECIACIONES | H37: =$E$33 -> 3.9 | I37: =32609.69/9 -> 3623.2989 | J37: ARRIENDO x HORA | K37: =I37*H37 -> 14130.866
C38: TOTAL | D38: =SUM(D34:D37) -> 21017.666 | H38: =$E$33 -> 3.9 | I38: 967 | J38: AGUA x HORA | K38: =I38*H38 -> 3771.3
H39: =$E$33 -> 3.9 | I39: 145 | J39: LUZ x HORA | K39: =I39*H39 -> 565.5
B40: PROVISIONAR | C40: IVA | D40: =E11-E21 -> 660478.22
H41: ESTADO DE RESULTADOS
B42: TOTAL HRS TRABAJADAS | D42: =E33 -> 3.9 | H42: INGRESOS | I42: + TOTAL VENTA | M42: =D11 -> 3530000
H43: COSTOS | I43: - MATERIA PRIMA DIRECTA | M43: =D21 -> 53798.82
...

Sheet NOTA DE VENTA
F2: MUEBLES SANTA FE SPA
F3: VENTAS POR MENOR DE MUEBLES
F4: RUT: 77.054.606-0
F5: SEPTIMA AVENIDA 1631, SAN MIGUEL
F6: CELULAR: 963868755
F7: E-MAIL: fdonoso@topmobili.cl
B8: P R E S U P U E S T O | D8: ='2229'!D8 -> N° 12021 | F8: NOTA DE VENTA :
B10: CLIENTE: | C10: =IF('2229'!C10="","",'2229'!C10) -> SISTEMA MUEBLES | F10: FECHA : | G10: ='2229'!K10 -> 45725
B11: RUT: | C11: =IF('2229'!C11="","",'2229'!C11) -> 77.091.475-2 | F11: FECHA LIMITE : | G11: =WORKDAY(G10,5) -> 45730
B12: GIRO: | C12: =IF('2229'!C12="","",'2229'!C12) | F12: DESPACHO: | G12: ='2229'!K14 -> NO
B13: CONTACTO: | C13: =IF('2229'!C13="","",'2229'!C13) | F13: ORDEN DE COMPRA:
B14: CORREO: | C14: =IF('2229'!C14="","",'2229'!C14) | F14: HECHO POR: | G14: FERNANDO DONOSO
B15: FONO: | C15: =IF('2229'!C15="","",'2229'!C15) -> +569 | F15: SERVICIO EXPRESS: | G15: ='2229'!K12 -> NO
B16: DIRECCION: | C16: =IF('2229'!C16="","",'2229'!C16) | F16: FORMA DE PAGO : | G16: ='2229'!K16 -> ABONO 50% SALDO C/ENTREGA
B17: CIUDAD: | C17: =IF('2229'!C17="","",'2229'!C17) -> SANTIAGO | F17: VALIDEZ COTIZACIÓN: 5 DÍAS
B20: D E T A L L E
B21: UNIDAD | C21: TIPO | D21: LARGO | E21: ANCHO | F21: COLOR | G21: VALOR | H21: TOTAL
B22: ='2229'!B21 -> 1 | C22: CUB C/R R8 | D22: ='2229'!D21*1000 -> 1046 | E22: ='2229'!E21*1000 -> 490 | F22: ='2229'!I21 -> GLACIAL WHITE 22191 SF | G22: ='2229'!K21 -> 49816 | H22: =G22*B22 -> 49816
G25: NETO | H25: =SUM(H22:H24) -> 49816
G26: I.V.A. | H26: =H25*19% -> 9465.04
G27: TOTAL | H27: =H25+H26 -> 59281.04
B30: CUENTA VISTA DEL BANCO ESTADO N° 35571389078 A NOMBRE DE
B31: "MUEBLES SANTA FE SPA." - RUT : 77.054.606-0, VENTAS@TOPMOBILI.CL
B32: VISITANOS Y DESCUBRE NUESTROS PRODUCTOS EN | E32: WWW.TOPMOBILICHILE.CL

Sheet REGLAS
B2: DETALLE CORTE LAMINA | G2: DETALLE CORTE SUSTRATO | P2: DETALLE CORTE MERA
B3: ALTO | C3: ANCHO | D3: TIPO | G3: ALTO | H3: ANCHO | I3: TIPO | P3: ALTO | Q3: ANCHO | R3: TIPO
B4: 40 | C4: 60 | D4: CEN 1V | E4: A1 | G4: 50 | H4: 100 | I4: CEN 1V | J4: REGLA SIEMPRE LLEVAR MEDIDA MINIMO A 100 | P4: 50 | Q4: -30 | R4: CUB C/R
B5: 40 | C5: 90 | D5: CEN 2V | E5: A2 | G5: 50 | I5: CEN 2V | J5: REGLA SIEMPRE LLEVAR MEDIDA MINIMO A 101 | P5: 50 | Q5: -30 | R5: CUB C/R
B6: 40 | C6: 100 | D6: CORNISA FRENTE ESPAÑOL 1 LADO | E6: A3 | G6: 50 | H6: 100 | I6: CORNISA FRENTE ESPAÑOL 1 LADO | P6: 50 | Q6: -30 | R6: CUB C/R 180°
B7: 40 | C7: 150 | D7: CORNISA FRENTE ESPAÑOL 2 LADO | E7: A4 | G7: 50 | I7: CORNISA FRENTE ESPAÑOL 2 LADO | P7: 50 | Q7: -30 | R7: CUB C/R FRENTE ESPAÑOL
B8: 40 | C8: 100 | D8: CORNISA 180° 1LADO | E8: A5 | G8: 50 | H8: 100 | I8: CORNISA 180° 1LADO | L8: DETALLE CORTE MERA | P8: 50 | Q8: -30 | R8: CUB C/R PUNTA 1 LADO
B9: 40 | C9: 50 | D9: CORNISA PUNTA TIBURON 1 LADO | E9: B | G9: 50 | H9: 100 | I9: CORNISA 1LADO | L9: ALTO | M9: ANCHO | N9: TIPO | P9: 50 | Q9: 0 | R9: CUB S/R FRENTE ESPAÑOL
B10: 40 | C10: 80 | D10: CORNISA PUNTA TIBURON 2 LADOS | E10: C | G10: 50 | I10: CORNISA 2 LADOS | L10: 50 | M10: -30 | N10: CUB C/R | P10: 50 | Q10: 0 | R10: CUB S/R
B11: 40 | C11: 60 | D11: CORNISA R8 1LADO | E11: D | G11: 50 | H11: 100 | I11: CORNISA PUNTA TIBURON 1 LADO | L11: 50 | M11: 0 | N11: CUB S/R y CUB MESA | P11: 50 | Q11: 0 | R11: CUB MESA 180° 2 LADOS
B12: 40 | C12: 100 | D12: CORNISA R8 2 LADOS | E12: E | G12: 50 | I12: CORNISA PUNTA TIBURON 2 LADOS | L12: 50 | M12: -2 | N12: PR | P12: 50 | Q12: 0 | R12: CUB MESA 180° 3 LADOS
B13: 40 | C13: 130 | D13: CUB C/R R6 | E13: F | G13: 50 | H13: -30 | I13: CUB C/R | P13: 50 | Q13: 0 | R13: CUB MESA 180° 4 LADOS
B14: 40 | C14: 150 | D14: CUB C/R 180° | G14: 50 | H14: -30 | I14: CUB C/R 180°
B15: 40 | C15: 150 | D15: CUB C/R FRENTE ESPAÑOL | E15: G | G15: 50 | H15: -30 | I15: CUB C/R FRENTE ESPAÑOL | P15: 50 | Q15: 0 | R15: CUB MESA 4 LADOS
B16: 40 | C16: 130 | D16: CUB C/R R2 | E16: H | G16: 50 | H16: -30 | I16: CUB C/R PUNTA TIBURON 1 LADO | P16: 50 | Q16: 0 | R16: CUB MESA FRENTE ESPAÑOL 2 LADOS
B17: 40 | C17: 150 | D17: CUB MESA 180° 2 LADOS | E17: I | G17: 50 | I17: CUB MESA 180° 2 LADOS | P17: 50 | Q17: 0 | R17: CUB MESA FRENTE ESPAÑOL 3 LADOS
B18: 140 | C18: 150 | D18: CUB MESA 180° 3 LADOS | E18: J | G18: 50 | I18: CUB MESA 180° 3 LADOS | P18: 50 | Q18: 0 | R18: CUB MESA FRENTE ESPAÑOL 4 LADOS
B19: 150 | C19: 150 | D19: CUB MESA 180° 4 LADOS | E19: K | G19: 50 | I19: CUB MESA 180° 4 LADOS | P19: 50 | Q19: 0 | R19: CUB MESA PUNTA TIBURON 2 LADOS
B20: 40 | C20: 100 | D20: CUB MESA 2L | E20: L | G20: 50 | H20: 0 | I20: CUB MESA 2L | J20: ES IGUAL A LO PEDIDO NO SE DEBE SUMAR NI RESTAR | P20: 50 | Q20: 0 | R20: CUB MESA PUNTA TIBURON 3 LADOS
B21: 100 | C21: 100 | D21: CUB MESA 3L | E21: M | G21: 50 | H21: 0 | I21: CUB MESA 3L | P21: 50 | Q21: 0 | R21: CUB MESA PUNTA TIBURON 4 LADOS
B22: 100 | C22: 100 | D22: CUB MESA 4 LADOS | E22: N | I22: CUB MESA 4 LADOS | P22: 50 | Q22: 0 | R22: CUB PUNTA TIBURON 1 LADO
B23: 40 | C23: 150 | D23: CUB MESA FRENTE ESPAÑOL 2 LADOS | E23: O | G23: 50 | I23: CUB MESA FRENTE ESPAÑOL 2 LADOS | R23: CENEFA 1 LADO
B24: 140 | C24: 150 | D24: CUB MESA FRENTE ESPAÑOL 3 LADOS | E24: P | G24: 50 | I24: CUB MESA FRENTE ESPAÑOL 3 LADOS | R24: CENEFA 2 LADOS
B25: 150 | C25: 150 | D25: CUB MESA FRENTE ESPAÑOL 4 LADOS | E25: Q | G25: 50 | I25: CUB MESA FRENTE ESPAÑOL 4 LADOS | R25: CORNISA FRENTE ESPAÑOL 1 LADO
B26: 40 | C26: 77 | D26: CUB MESA PUNTA TIBURON 2 LADOS | E26: R | G26: 50 | I26: CUB MESA PUNTA TIBURON 2 LADOS | R26: CORNISA FRENTE ESPAÑOL 2 LADO
B27: 110 | C27: 77 | D27: CUB MESA PUNTA TIBURON 3 LADOS | E27: S | G27: 50 | I27: CUB MESA PUNTA TIBURON 3 LADOS | R27: CORNISA 180° 1LADO
B28: 120 | C28: 77 | D28: CUB MESA PUNTA TIBURON 4 LADOS | E28: T | G28: 50 | I28: CUB MESA PUNTA TIBURON 4 LADOS | R28: CORNISA 1LADO
B29: 40 | C29: 50 | D29: CUB PUNTA TIBURON 1 LADO | E29: U | G29: 50 | I29: CUB PUNTA TIBURON 1 LADO | R29: CORNISA 2 LADOS
B30: 40 | C30: 60 | D30: CUB S/R | E30: V | G30: 50 | I30: CUB S/R | R30: CORNISA PUNTA TIBURON 1 LADO
B31: 40 | C31: 100 | D31: CUB S/R FRENTE ESPAÑOL | E31: W | G31: 50 | I31: CUB S/R FRENTE ESPAÑOL | R31: CORNISA PUNTA TIBURON 2 LADOS
B32: 40 | C32: 60 | D32: CUB S/R R2 | E32: X | G32: 50 | I32: CUB S/R R2 | R32: PR2
B33: 40 | C33: 90 | D33: PR12 | E33: Y | G33: 50 | H33: -2 | I33: PR12 | R33: PR6
B34: 40 | C34: 90 | D34: PR19 | G34: 50 | H34: -2 | I34: PR19
B35: 40 | C35: 90 | D35: PR2 | E35: Z | G35: 50 | H35: -2 | I35: PR2 | R35: PR8
B36: 40 | C36: 90 | D36: PR6 | G36: 50 | H36: -2 | I36: PR6 | R36: PR12
B37: 40 | C37: 90 | D37: PR8 | G37: 50 | H37: -2 | I37: PR8 | R37: PR19
B48: 40 | C48: 150

Sheet PRODUCCION
K2: NO BORRAR REGLAS!!!!! SI NO LAS SABEN USAR NO BORREN ESTO POR FAVOR!!!!!
K3: SUSTRATO | M3: LAMINADO
C4: NOTA DE VENTA : | D4: =IF('NOTA DE VENTA'!$G$8="","",'NOTA DE VENTA'!$G$8) | K4: ALTO | L4: ANCHO | M4: ALTO | N4: ANCHO
C5: CLIENTE : | D5: ='NOTA DE VENTA'!$C$10 -> SISTEMA MUEBLES | K5: =LOOKUP(F14,REGLAS!$I$4:$I$37,REGLAS!$G$4:$G$37)+J14 -> 2070 | L5: =LOOKUP(F14,REGLAS!$I$4:$I$37,REGLAS!$H$4:$H$37)+K14 -> 460 | M5: =LOOKUP(F14,REGLAS!$D$4:$D$37,REGLAS!$B$4:$B$37)+J21 -> 2060 | N5: =H10 -> 0
C7: ='NOTA DE VENTA'!$F$10 -> FECHA : | D7: ='NOTA DE VENTA'!$G$10 -> 45725
C8: FECHA ENTREGA: | D8: ='NOTA DE VENTA'!$G$11 -> 45730
A10: SUSTRATO
D12: ALTO | E12: ANCHO
A13: MATERIAL | B13: CANTIDAD | C13: CORTE | D13: 80 | E13: -30 | F13: DESCRIPCIÓN | J13: ALTO | K13: ANCHO
A14: MDF 18MM | B14: =I14 -> 1 | D14: =LOOKUP(F14,REGLAS!$I$4:$I$37,REGLAS!$G$4:$G$37)+J14 -> 2070 | E14: =LOOKUP(F14,REGLAS!$I$4:$I$37,REGLAS!$H$4:$H$37)+K14 -> 460 | F14: =C27 -> CUB C/R R8 | I14: =I21 -> 1 | J14: =D27 -> 2020 | K14: =E27 -> 490
A17: LAMINADO
D19: ALTO | E19: ANCHO
A20: MATERIAL | B20: CANTIDAD | C20: CORTE | D20: 40 | E20: 130 | F20: DESCRIPCIÓN | J20: ALTO | K20: ANCHO
A21: MDF 18MM | B21: =I21 -> 1 | D21: =LOOKUP(F14,REGLAS!$D$4:$D$37,REGLAS!$B$4:$B$37)+J21 -> 2060 | E21: =LOOKUP(F14,REGLAS!$D$4:$D$37,REGLAS!$C$4:$C$37)+K21 -> 620 | F21: =C27 -> CUB C/R R8 | I21: =B27 -> 1 | J21: =D27 -> 2020 | K21: =E27 -> 490
B24: MEDIDAS ORIGINALES
A26: MATERIAL | B26: CANTIDAD | C26: DESCRIPCIÓN | D26: ALTO | E26: ANCHO | F26: COLOR
A27: MDF 18MM | B27: ='[1]4637'!B21 -> 1 | C27: =C49 -> CUB C/R R8 | D27: =D49 -> 2020 | E27: =E49 -> 490 | F27: =F49 -> GLACIAL WHITE 22191 SF
C39: NOTA DE VENTA : | D39: ='[1]4637'!G8 -> 7332
C40: CLIENTE : | D40: ='[1]4637'!C10 -> FMR MAKING SPA
C42: ='[1]4637'!F11 -> FECHA LIMITE : | D42: ='[1]4637'!G11 -> 45996
A45: PRODUCCIÓN
B47: DETALLE
B48: CANTIDAD | C48: CORTE | D48: ALTO | E48: ANCHO | F48: DESCRIPCION
A49: MDF18MM | B49: ='[1]4637'!B21 -> 1 | C49: ='NOTA DE VENTA'!$C22 -> CUB C/R R8 | D49: 2020 | E49: ='NOTA DE VENTA'!E22 -> 490 | F49: ='NOTA DE VENTA'!F22 -> GLACIAL WHITE 22191 SF

Sheet SEGUIMIENTO
A1: NV | B1: N° COTIZA | C1: FECHA | D1: ENTREGA | E1: NOMBRE | F1: DETALLE | G1: COLOR | H1: NETO | I1: IVA | J1: TOTAL | K1: ABONO | L1: SALDO | M1: ESTADO
A2: ='NOTA DE VENTA'!$G$8 -> 0 | B2: ='NOTA DE VENTA'!$D$8 -> N° 12021 | C2: ='NOTA DE VENTA'!$G$10 -> 45725 | D2: ='NOTA DE VENTA'!$G$11 -> 45730 | E2: ='NOTA DE VENTA'!$C$10 -> SISTEMA MUEBLES | F2: ='NOTA DE VENTA'!$C$22 -> CUB C/R R8 | G2: ='NOTA DE VENTA'!$F$22 -> GLACIAL WHITE 22191 SF | H2: ='NOTA DE VENTA'!$H$25 -> 49816 | I2: =H2*0.19 -> 9465.04 | J2: =I2+H2 -> 59281.04 | L2: =J2-K2 -> 59281.04
