Workbook

Sheet 2229
F2: MUEBLES SANTA FE SPA
F3: VENTAS POR MENOR DE MUEBLES
F4: RUT: 77.054.606-0
F5: SEPTIMA AVENIDA 1631, SAN MIGUEL
F6: FONO +569 2032 3382 | O6: 10077 SF PORTLAND MAPLE
F7: E-MAIL: ventas@topmobili.cl
B8: P R E S U P U E S T O | D8: N° 12038
B10: NOMBRE: | C10: MARITZA BELMAR | F10: FECHA | G10: 46092
B11: RUT: | F11: PLAZO ENTREGA | G11: 5 DIAS HABILES | R11: MT2 PUERTAS
B12: GIRO: | F12: SERVICIO EXPRESS | G12: NO | M12: 1.22
B13: CONTACTO: | F13: ORDEN DE COMPRA: | M13: 3.05
B14: CORREO: | F14: CORTADA A LA MEDIDA | G14: NO | M14: =M12*M13 -> 3.721 | R14: ML CUBIERTAS
B15: FONO: | C15: +569 6656 1332 | F15: DESPACHO | G15: NO | M15: 27
B16: DIRECCION: | F16: FORMA DE PAGO: | G16: ABONO 50% SALDO C/ENTREGA | M16: =M15/M14 -> 7.2561139
B17: CIUDAD: | C17: SANTIAGO | F17: DURACION COTIZACION: 5 DIAS FRANCO DONOSO
B19: DETALLE | M19: 0.08 | P19: TOTAL | Q19: VALOR X MT2 | R19: ENCHAPE | S19: MT/L
B20: UNIDAD | C20: TIPO | D20: ALTO | E20: ANCHO | F20: COLOR | G20: VALOR | H20: TOTAL | L20: =B20 -> UNIDAD | M20: ALTO | N20: =E20 -> ANCHO | O20: MT | P20: MT2 | Q20: =O38 -> 84785.774 | R20: 2000 | T20: m/l
B21: 1 | C21: CUB CON RESPALDO FTE 90° R8 | D21: 1.6 | E21: 0.5 | F21: MEDITERRANEO MT | G21: =Q21 -> 71220.05 | H21: =G21*B21 -> 71220.05 | L21: =B21 -> 1 | M21: =D21+M$19 -> 1.68 | N21: =E21+$N$19 -> 0.5 | O21: =M21*N21 -> 0.84 | P21: =O21*L21 -> 0.84 | Q21: =Q$20*O21 -> 71220.05 | R21: =Q21+R$20 -> 73220.05 | S21: =M21*L21 -> 1.68 | T21: =N21*2*L21*2 -> 2
B22: 1 | C22: CUB MESA 4 LADOS | D22: 1 | E22: 0.6 | F22: MEDITERRANEO MT | G22: 60669 | H22: =G22*B22 -> 60669 | L22: =B22 -> 1 | M22: =D22+M$19 -> 1.08 | N22: =E22+$N$19 -> 0.6 | O22: =M22*N22 -> 0.648 | P22: =O22*L22 -> 0.648 | Q22: =Q$20*O22 -> 54941.181 | R22: =Q22+R$20 -> 56941.181 | S22: =M22*L22 -> 1.08
K23: 50390
G24: NETO | H24: =SUM(H21:H23) -> 131889.05 | K24: =K23/1.19 -> 42344.538 | T24: =SUM(T21:T23) -> 2
G25: IVA | H25: =H24*0.19 -> 25058.919 | M25: =SUM(M21:M22) -> 2.76 | P25: =SUM(P21:P23) -> 1.488 | S25: =SUM(S21:S24) -> 2.76
G26: TOTAL | H26: =H25+H24 -> 156947.97 | P26: =P25 -> 1.488
P27: =P26*20% -> 0.2976 | Q27: 20% PERDIDA
P28: =P26+P27 -> 1.7856
U29: ADHESIVO | V29: 58.000.- | W29: 44971
M30: =P28 -> 1.7856 | N30: 3500 | O30: =M30*N30 -> 6249.6 | P30: ADHESIVO | U30: LATA 16 LTS | V30: 3625 | W30: LITRO
M31: 0.5 | N31: 23500 | O31: =M31*N31 -> 11750 | P31: MDF 18MM | V31: 906.25 | W31: MT2 (4)
B32: CUENTA CORRIENTE BANCO SANTANDER Nº 87316181 A NOMBRE DE MUEBLES SANTA FE SPA | N32: 68800 | O32: =M32*N32 -> 0 | P32: LAMINA 153 X 366 | V32: =V31*20% -> 181.25 | W32: PERDIDA 20%
B33: RUT : 77.054.606-0 CORREO: FRANCODONOSO@TOPMOBILI.CL | M33: 1 | N33: =39000/1.19 -> 32773.109 | O33: =M33*N33 -> 32773.109 | P33: LAMINA 122X244 | V33: =V31+V32 -> 1087.5 | W33: MINIMO A COTIZAR
B34: VISITANOS Y DESCUBRE NUESTROS PRODUCTOS EN | F34: WWW.TOPMOBILICHILE.CL | M34: 1.7 | N34: 900 | O34: =M34*N34 -> 1530 | P34: RESPALDO | R34: 1.52
M35: 1.7 | N35: 1500 | O35: =M35*N35 -> 2550 | P35: MEDIA CAÑA | R35: 2.44
O36: =SUM(O30:O35) -> 54852.709 | P36: COSTO | R36: =R34*R35 -> 3.7088
M37: PRECIO VENTA | O37: =O36*2.3 -> 126161.23 | P37: FACTOR 2,3 PARA 90° | R37: =P28/R36 -> 0.48144953
O38: =O37/P26 -> 84785.774 | P38: VALOR M2 | U38: MDF30MM | V38: 43650
O39: =O37/O36 -> 2.3 | U39: 46 UNIDADES | V39: 948.91 | W39: 2.4
U40: METRO LINEAL | V40: 395.37
U41: PERDIDA 20% | V41: 474.45
O48: 40935 | P48: MT2 | Q48: TERMO WOOD
C73: ,,,,,,,,,,,,,,,,,,,,,,,,,,,,,,,,,,,,,,,,,,,,,,,,,,,,,,,,,,,,,,,,,,,,,,,,,,,,,,,,,,,,,,,,,,,,,,,,,,,,,,,,,,,,,,,,,,,,,,,,,,,,,,,,,,,,,,,,,,,,,,,,,,,,,,,,,,,,,,,,,,,,,,,,,,,,,,,,,,,,,,,,,,,,,,,,,,,,,,,,,,,,,,,,,,,,,,,,,,,,,,,,,,,,,,,,,,,,,,,,,,,,,,,,,,,,,,,,,,,,,
...

Sheet COSTOS
B2: CENTRO DE COSTOS POSTFORMADOS
B5: FECHA: | C5: ='2229'!G10 -> 46092
B6: CLIENTE: | C6: ='2229'!C10 -> MARITZA BELMAR | N6: Ventas Equilibrio = | P6: Costos Fijos Totales
B7: DIRECCION: | C7: ='2229'!#REF! -> #REF! | H7: COSTOS INDIRECTOS DE FABRICA VARIABLES | O7: 1 - | P7: Costos Variables Totales
B8: PRESUPUESTO: | C8: ='2229'!D8 -> N° 12038 | H8: Q/HRS | I8: $ | J8: DETALLE | K8: TOTAL | L8: TOTAL | P8: Total Venta | X8: =SUM(Q11:Q16) -> 6
H9: CANTIDAD | I9: PRECIO | J9: MATERIA PRIMA INDIRECTA | L9: =SUM(K10:K25) -> 41495 | S9: DETALLE | X9: =(E15-D11)/X8 -> #REF!
D10: NETO | E10: IVA | F10: TOTAL | H10: 0 | I10: 350 | J10: RESPALDO | K10: =I10*H10 -> 0 | Q10: UNIDAD | R10: TIPO | S10: LARGO | T10: ANCHO | U10: COLOR | V10: VALOR | W10: TOTAL
C11: MONTO A COBRAR | D11: ='2229'!#REF! -> #REF! | E11: =D11*0.19 -> #REF! | F11: =E11+D11 -> #REF! | H11: 0 | I11: 500 | J11: MEDIA CAÑA | K11: =I11*H11 -> 0 | Q11: 1 | R11: CUB C/R R8 | S11: 2.8 | T11: 0.62 | U11: MADERA X DEFINIR | V11: 105990 | W11: =V11*Q11 -> 105990 | X11: =V11+$X$9 -> #REF! | Y11: 108990
C12: COSTO TOTAL | D12: =SUM(M45:M47) -> 2309114.2 | H12: 0 | I12: 7500 | J12: DUROLAC | K12: =I12*H12 -> 0 | Q12: 1 | R12: CUB C/R R8 | S12: 2.3 | T12: 0.62 | U12: MADERA X DEFINIR | V12: 87990 | W12: =V12*Q12 -> 87990 | X12: =V12+$X$9 -> #REF! | Y12: 89990
C13: % UTILIDAD | D13: =D11-D12 -> #REF! | E13: =(D11/D12)-1 -> #REF! | H13: 0 | I13: 50 | J13: TAPACANTO PVC | K13: =I13*H13 -> 0 | Q13: 1 | R13: CUB C/R R8 | S13: 2.03 | T13: 0.62 | U13: MADERA X DEFINIR | V13: 78990 | W13: =V13*Q13 -> 78990 | X13: =V13+$X$9 -> #REF! | Y13: 81990
D14: % utilidad | E14: NETO | F14: UTILIDAD | H14: 0 | I14: 50 | J14: SOBERBIOS | K14: =I14*H14 -> 0 | Q14: 1 | R14: CUB C/R R8 | S14: 1.08 | T14: 0.62 | U14: MADERA X DEFINIR | V14: 39990 | W14: =V14*Q14 -> 39990 | X14: =V14+$X$9 -> #REF! | Y14: 39990
A15: =E15*1.19 -> 4753773.4 | C15: PROYECCION | D15: 0.73 | E15: =(100%+D15)*D12 -> 3994767.6 | F15: =E15-D12 -> 1685653.4 | H15: 0 | I15: 10 | J15: SOPORTE REPISA | K15: =I15*H15 -> 0 | Q15: 1 | R15: CUB C/R R8 | S15: 1.08 | T15: 0.62 | U15: MADERA X DEFINIR | V15: 39990 | W15: =V15*Q15 -> 39990 | X15: =V15+$X$9 -> #REF! | Y15: 39990
H16: 1 | J16: PUNTAS | K16: =I16*H16 -> 0 | N16: =3*46 -> 138 | Q16: 1 | R16: CUB C/R R8 | S16: 2.06 | T16: 0.62 | U16: MADERA X DEFINIR | V16: 79990 | W16: =V16*Q16 -> 79990 | X16: =V16+$X$9 -> #REF! | Y16: 83990
B17: M. PRIMA | C17: MATERIAL | D17: NETO | E17: IVA | F17: TOTAL | H17: 6 | I17: 1103 | J17: TORNILLOS 3,5X50 (100U) | K17: =I17*H17 -> 6618 | Q17: 6 | R17: CORTES 45° | V17: 5000 | W17: =V17*Q17 -> 30000
C18: LAMINA GRANDE | D18: ='2229'!O32 -> 0 | E18: =D18*0.19 -> 0 | F18: =SUM(D18:E18) -> 0 | H18: 6 | I18: 543 | J18: TORNILLOS 3,5X30 (100U) | K18: =I18*H18 -> 3258 | N18: 5 | O18: 283 | Q18: 1 | R18: PERFORACION LAVAPLATOS | V18: 10000 | W18: =V18*Q18 -> 10000
C19: LAMINA | D19: ='2229'!O33 -> 32773.109 | E19: =D19*0.19 -> 6226.8908 | F19: =SUM(D19:E19) -> 39000 | J19: TORNILLOS 3,5X15 | V19: NETO | W19: =SUM(W11:W18) -> 472940 | Y19: =SUM(Y11:Y16)+SUM(W17:W18) -> 484940
C20: MDF 18MM | D20: ='2229'!O31 -> 11750 | E20: =D20*0.19 -> 2232.5 | F20: =SUM(D20:E20) -> 13982.5 | H20: 4 | I20: 1572 | J20: COLAFRIA | K20: =I20*H20 -> 6288 | O20: =O18*N18 -> 1415 | V20: I.V.A. | W20: =W19*19% -> 89858.6 | Y20: =Y19*0.19 -> 92138.6
A21: =1300000*1.2 -> 1560000 | C21: ADHESIVO | D21: ='2229'!O30 -> 6249.6 | E21: =D21*0.19 -> 1187.424 | F21: =SUM(D21:E21) -> 7437.024 | H21: 1 | J21: LIJAS | K21: =I21*H21 -> 0 | O21: =O20/60 -> 23.583333 | Q21: PLAZO DE ENTREGA : 8 DIAS HABILES | V21: TOTAL | W21: =W19+W20 -> 562798.6 | Y21: =SUM(Y19:Y20) -> 577078.6
A22: =1300000*1.2 -> 1560000 | B22: M. DE OBRA | C22: TOTAL | D22: =SUM(D18:D21) -> 50772.709 | E22: =SUM(E18:E21) -> 9646.8148 | F22: =SUM(F18:F21) -> 60419.524 | H22: 1 | J22: CARTON | K22: =I22*H22 -> 0 | Q22: FORMA DE PAGO: 50% CONTADO, SALDO C/E
A23: =950000*1.2 -> 1140000 | B23: =A21/23 -> 67826.087 | C23: PROCESO | D23: COSTO x Hr. | E23: Q Hrs. | F23: TOTAL | H23: 3 | I23: 3535 | J23: HUAIPE | K23: =I23*H23 -> 10605 | M23: =B32/9 -> 2318.8406 | Q23: VALIDEZ COTIZACIÓN: 5 DIAS
A24: 450000 | B24: =A22/23 -> 67826.087 | C24: CORTE | D24: =B23/8 -> 8478.2609 | E24: 23.6 | F24: =D24*E24 -> 200086.96 | H24: 2 | I24: 7363 | J24: DILUYENTE | K24: =I24*H24 -> 14726
A25: 450000 | B25: =A23/23 -> 49565.217 | C25: CORTE LAMINA | D25: =B24/8 -> 8478.2609 | E25: 23.6 | F25: =D25*E25 -> 200086.96 | H25: 1 | J25: CINTA EMBALAJE | K25: =I25*H25 -> 0
B26: =A24/23 -> 19565.217 | C26: REBAJE LAMINA | D26: =B25/8 -> 6195.6522 | F26: =D26*E26 -> 0 | H26: Q/HRS | I26: PRECIO | J26: MANO DE OBRA INDIRECTA | K26: VALOR | L26: =SUM(K27:K37) -> 39086.957
A27: 350000 | B27: =A25/23 -> 19565.217 | C27: TUPIZADO | D27: =B26/8 -> 2445.6522 | E27: 9.5 | F27: =D27*E27 -> 23233.696 | H27: 10 | I27: =((480000/23)/8) -> 2608.6957 | J27: FLETERO (HRS) | K27: =H27*I27 -> 26086.957
A28: 500000 | B28: =A28/23 -> 21739.13 | C28: ARMADO | D28: =B27/8 -> 2445.6522 | F28: =D28*E28 -> 0 | H28: 10 | I28: 1300 | J28: BENCINA | K28: =H28*I28 -> 13000
B29: =A28/23 -> 21739.13 | C29: PEGADO | D29: =B28/8 -> 2717.3913 | E29: 47.2 | F29: =D29*E29 -> 128260.87 | H29: 0 | J29: TAG | K29: =H29*I29 -> 0
A30: 450000 | C30: POSTFORMADO | D30: =B29/8 -> 2717.3913 | E30: 38 | F30: =D30*E30 -> 103260.87 | H30: 0 | J30: RECTIFICACION | K30: =H30*I30 -> 0
A31: 350000 | B31: =A30/23 -> 19565.217 | C31: MEDIA CAÑA | D31: =B26/8 -> 2445.6522 | E31: 24 | F31: =D31*E31 -> 58695.652 | H31: 0 | I31: =((550000*1.2)/23)/9 -> 3188.4058 | J31: HR. TRAB. JUAN | K31: =H31*I31 -> 0
A32: =A21+A24+A27+A28+A30 -> 3310000 | B32: =480000/23 -> 20869.565 | C32: CORTE-ENCHAPE | D32: =B31/8 -> 2445.6522 | E32: 0 | F32: =D32*E32 -> 0 | H32: 0 | I32: =((450000*1.2)/23)/9 -> 2608.6957 | J32: HR. TRAB. JULIO | K32: =H32*I32 -> 0
C33: CONTROL CALIDAD | D33: =B32/8 -> 2608.6957 | E33: 24 | F33: =D33*E33 -> 62608.696 | H33: 0 | I33: =((450000*1.2)/23)/9 -> 2608.6957 | J33: HR. TRAB. EUGE | K33: =H33*I33 -> 0
B34: CIF | C34: TOTAL | D34: =SUM(D24:D33) -> 40978.261 | E34: =SUM(E24:E33) -> 189.9 | F34: =SUM(F24:F33) -> 776233.7 | H34: 0 | J34: COLACION | K34: =H34*I34 -> 0
C35: M. PRIMA INDIREC. | D35: =L9 -> 41495 | H35: 0 | J35: BONO | K35: =H35*I35 -> 0
C36: M. OBRA INDIRECTA | D36: =L26 -> 39086.957 | H36: 1 | J36: PERFORACION | K36: =H36*I36 -> 0
C37: GASTOS DE FABRICA | D37: =L38 -> 1401525.9 | H37: 6 | J37: CORTE 45 | K37: =H37*I37 -> 0
C38: DEPRECIACIONES | H38: CANTIDAD | I38: PRECIO | J38: GASTOS DE FABRICACION | K38: VALOR | L38: =SUM(K39:K41) -> 1401525.9
C39: TOTAL | D39: =SUM(D35:D38) -> 1482107.8 | H39: =$E$34 -> 189.9 | I39: =39130.69/8 -> 4891.3363 | J39: ARRIENDO x HORA | K39: =I39*H39 -> 928864.75
B40: PROVISIONAR | C40: IVA | D40: =E11-E22 -> #REF! | H40: =$E$34 -> 189.9 | I40: 967 | J40: AGUA x HORA | K40: =I40*H40 -> 183633.3
H41: =$E$34 -> 189.9 | I41: 1522 | J41: LUZ x HORA | K41: =I41*H41 -> 289027.8
B42: TOTAL HRS TRABAJADAS | D42: =E34 -> 189.9
H43: ESTADO DE RESULTADOS
...
