Workbook

Sheet MESA REUNIONES
F2: MUEBLES SANTA FE SPA
F3: VENTAS POR MENOR DE MUEBLES
F4: RUT: 77.054.606-0
F5: SEPTIMA AVENIDA 1631, SAN MIGUEL
F6: FONO +569 2032 3382
F7: E-MAIL: ventas@topmobili.cl
B8: P R E S U P U E S T O | D8: N° 12032
B10: NOMBRE: | C10: CONSTRUCTORA DEL ROSAL SPA | F10: FECHA | G10: 46091
B11: RUT: | F11: PLAZO ENTREGA | G11: 8 DIAS HABILES | R11: MT2 PUERTAS
B12: GIRO: | F12: SERVICIO EXPRESS | G12: NO
B13: CONTACTO: | C13: SEBASTIAN DEL FIERRO | F13: ORDEN DE COMPRA:
B14: CORREO: | F14: CORTADA A LA MEDIDA | G14: NO | R14: ML CUBIERTAS
B15: FONO: | F15: DESPACHO | G15: NO
B16: DIRECCION: | F16: FORMA DE PAGO: | G16: ABONO 50% SALDO C/ENTREGA
B17: CIUDAD: | C17: SANTIAGO | F17: DURACION COTIZACION: 5 DIAS FRANCO DONOSO
B19: DETALLE | M19: 0.08 | P19: TOTAL | Q19: VALOR X MT2 | R19: ENCHAPE | S19: MT/L
B20: UNIDAD | C20: TIPO | D20: ALTO | E20: ANCHO | F20: COLOR | G20: VALOR | H20: TOTAL | L20: =B20 -> UNIDAD | M20: ALTO | N20: =E20 -> ANCHO | O20: MT | P20: MT2 | Q20: =O38 -> 138820 | R20: 2000 | T20: m/l
B21: 1 | C21: ENCHAPE RECTO 2 CARAS MDF 30MM | D21: 2 | E21: 1 | F21: GRIS NUBE TRASCARA BALANCE | G21: =R21 -> 290745.6 | H21: =G21*B21 -> 290745.6 | K21: =L21/4 -> 0.25 | L21: =B21 -> 1 | M21: =D21+M$19 -> 2.08 | N21: =E21+$N$19 -> 1 | O21: =M21*N21 -> 2.08 | P21: =O21*L21 -> 2.08 | Q21: =Q$20*O21 -> 288745.6 | R21: =Q21+R$20 -> 290745.6 | S21: =M21*L21*2 -> 4.16 | T21: =N21*L21*2 -> 2 | U21: =S21+T21 -> 6.16 | V21: =U21*20% -> 1.232 | W21: =U21+V21 -> 7.392
K22: 50390 | W22: =#REF!+#REF! -> #REF!
G23: NETO | H23: =SUM(H21:H22) -> 290745.6 | I23: =H23/15 -> 19383.04 | K23: =K22/1.19 -> 42344.538 | T23: =SUM(T21:T22) -> 2
G24: IVA | H24: =H23*0.19 -> 55241.664 | M24: =SUM(M21:M21) -> 2.08 | P24: =SUM(P21:P22) -> 2.08 | S24: =SUM(S21:S23) -> 4.16
G25: TOTAL | H25: =H24+H23 -> 345987.26 | P25: =P24 -> 2.08 | S25: =S24+T23 -> 6.16
P26: =P25*20% -> 0.416 | Q26: 20% PERDIDA | S26: =S25*20% -> 1.232
P27: =P25+P26 -> 2.496 | S27: =S25+S26 -> 7.392
I28: M | U28: ADHESIVO | V28: 58.000.- | W28: 44971
M29: =P27*2 -> 4.992 | N29: 3500 | O29: =M29*N29 -> 17472 | P29: ADHESIVO | U29: LATA 16 LTS | V29: 3625 | W29: LITRO
F30: 0 | N30: 23500 | O30: =M30*N30 -> 0 | P30: MDF 18MM | V30: 906.25 | W30: MT2 (4)
B31: CUENTA CORRIENTE BANCO SANTANDER Nº 87316181 A NOMBRE DE MUEBLES SANTA FE SPA | M31: 1 | N31: 43500 | O31: =M31*N31 -> 43500 | P31: LAMINA 153 X 366 | V31: =V30*20% -> 181.25 | W31: PERDIDA 20%
B32: RUT : 77.054.606-0 CORREO: FRANCODONOSO@TOPMOBILI.CL | M32: 1 | N32: 21630 | O32: =M32*N32 -> 21630 | P32: LAMINA 122X244 | V32: =V30+V31 -> 1087.5 | W32: MINIMO A COTIZAR
B33: VISITANOS Y DESCUBRE NUESTROS PRODUCTOS EN | F33: WWW.TOPMOBILICHILE.CL | J33: 25 MTS PVC 22X1,5MM HUMO | M33: 1 | N33: 15041 | O33: =M33*N33 -> 15041 | P33: BALANCE | R33: 1.52
J34: 29750 | N34: 25000 | O34: =M34*N34 -> 0 | P34: TAPACANTO PVC 22X1,5 | R34: 2.44
J35: =J34/1.19 -> 25000 | M35: 1 | N35: 33605 | O35: =M35*N35 -> 33605 | P35: TAPACANTO PVC 29X2 | R35: =R33*R34 -> 3.7088
J36: 25 MTS PVC 22X2MM HUMO | O36: =SUM(O29:O35) -> 131248 | P36: COSTO | R36: =P27/R35 -> 0.67299396
J37: 39990 | M37: PRECIO VENTA | O37: =O36*2.2 -> 288745.6 | P37: FACTOR 2,3 PARA 90° | U37: MDF30MM | V37: 43650
J38: =J37/1.19 -> 33605.042 | O38: =O37/P25 -> 138820 | P38: VALOR M2 | U38: 46 UNIDADES | V38: 948.91 | W38: 2.4
O39: =O37/O36 -> 2.2 | U39: METRO LINEAL | V39: 395.37
U40: PERDIDA 20% | V40: 474.45
O47: 40935 | P47: MT2 | Q47: TERMO WOOD
C72: ,,,,,,,,,,,,,,,,,,,,,,,,,,,,,,,,,,,,,,,,,,,,,,,,,,,,,,,,,,,,,,,,,,,,,,,,,,,,,,,,,,,,,,,,,,,,,,,,,,,,,,,,,,,,,,,,,,,,,,,,,,,,,,,,,,,,,,,,,,,,,,,,,,,,,,,,,,,,,,,,,,,,,,,,,,,,,,,,,,,,,,,,,,,,,,,,,,,,,,,,,,,,,,,,,,,,,,,,,,,,,,,,,,,,,,,,,,,,,,,,,,,,,,,,,,,,,,,,,,,,,
C73: ,
...

Sheet ESCRITORIOS
F2: MUEBLES SANTA FE SPA
F3: VENTAS POR MENOR DE MUEBLES
F4: RUT: 77.054.606-0
F5: SEPTIMA AVENIDA 1631, SAN MIGUEL
F6: FONO +569 2032 3382
F7: E-MAIL: ventas@topmobili.cl
B8: P R E S U P U E S T O | D8: N° 12032
B10: NOMBRE: | C10: CONSTRUCTORA DEL ROSAL SPA | F10: FECHA | G10: 46091
B11: RUT: | F11: PLAZO ENTREGA | G11: 8 DIAS HABILES | R11: MT2 PUERTAS
B12: GIRO: | F12: SERVICIO EXPRESS | G12: NO
B13: CONTACTO: | C13: SEBASTIAN DEL FIERRO | F13: ORDEN DE COMPRA:
B14: CORREO: | F14: CORTADA A LA MEDIDA | G14: NO | R14: ML CUBIERTAS
B15: FONO: | F15: DESPACHO | G15: NO
B16: DIRECCION: | F16: FORMA DE PAGO: | G16: ABONO 50% SALDO C/ENTREGA
B17: CIUDAD: | C17: SANTIAGO | F17: DURACION COTIZACION: 5 DIAS FRANCO DONOSO
B19: DETALLE | M19: 0.08 | P19: TOTAL | Q19: VALOR X MT2 | R19: ENCHAPE | S19: MT/L
B20: UNIDAD | C20: TIPO | D20: ALTO | E20: ANCHO | F20: COLOR | G20: VALOR | H20: TOTAL | L20: =B20 -> UNIDAD | M20: ALTO | N20: =E20 -> ANCHO | O20: MT | P20: MT2 | Q20: =O40 -> 86114.221 | R20: 2000 | T20: m/l
B21: 15 | C21: ENCHAPE RECTO 2 CARAS MDF 25MM | D21: 1.2 | E21: 0.6 | F21: GRIS NUBE TRASCARA BALANCE | G21: =R21 -> 68135.722 | H21: =G21*B21 -> 1022035.8 | K21: =L21/4 -> 3.75 | L21: =B21 -> 15 | M21: =D21+M$19 -> 1.28 | N21: =E21+$N$19 -> 0.6 | O21: =M21*N21 -> 0.768 | P21: =O21*L21 -> 11.52 | Q21: =Q$20*O21 -> 66135.722 | R21: =Q21+R$20 -> 68135.722 | S21: =M21*L21*2 -> 38.4 | T21: =N21*L21*2 -> 18 | U21: =S21+T21 -> 56.4 | V21: =U21*20% -> 11.28 | W21: =U21+V21 -> 67.68
B22: 30 | C22: COSTADOS RECTOS 2 CARAS MDF 18MM | D22: 0.7 | E22: 0.6 | F22: GRIS NUBE 2189 MT | G22: =R22 -> 42301.455 | H22: =G22*B22 -> 1269043.7 | J22: 60 | K22: =J22/8 -> 7.5 | L22: =B22 -> 30 | M22: =D22+M$19 -> 0.78 | N22: =E22+$N$19 -> 0.6 | O22: =M22*N22 -> 0.468 | P22: =O22*L22 -> 14.04 | Q22: =Q$20*O22 -> 40301.455 | R22: =Q22+R$20 -> 42301.455 | S22: =L22*M22*2 -> 46.8 | U22: =S22 -> 46.8 | V22: =U22*20% -> 9.36 | W22: =U22+V22 -> 56.16
B23: 30 | C23: APOYO | D23: 0.7 | E23: 0.15 | F23: GRIS NUBE 2189 MT | G23: =R23 -> 12075.364 | H23: =G23*B23 -> 362260.92 | L23: =B23 -> 30 | M23: =D23+M$19 -> 0.78 | N23: =E23+$N$19 -> 0.15 | O23: =M23*N23 -> 0.117 | P23: =O23*L23 -> 3.51 | Q23: =Q$20*O23 -> 10075.364 | R23: =Q23+R$20 -> 12075.364 | S23: =L23*M23*2 -> 46.8 | U23: =S23 -> 46.8 | V23: =U23*20% -> 9.36 | W23: =U23+V23 -> 56.16
K24: 50390 | W24: =W22+W23 -> 112.32
G25: NETO | H25: =SUM(H21:H24) -> 2653340.4 | I25: =H25/15 -> 176889.36 | K25: =K24/1.19 -> 42344.538 | T25: =SUM(T21:T24) -> 18
G26: IVA | H26: =H25*0.19 -> 504134.68 | M26: =SUM(M21:M22) -> 2.06 | P26: =SUM(P21:P24) -> 29.07 | S26: =SUM(S21:S25) -> 132
G27: TOTAL | H27: =H26+H25 -> 3157475.1 | P27: =P26 -> 29.07 | S27: =S26+T25 -> 150
P28: =P27*20% -> 5.814 | Q28: 20% PERDIDA | S28: =S27*20% -> 30
P29: =P27+P28 -> 34.884 | S29: =S27+S28 -> 180
U30: ADHESIVO | V30: 58.000.- | W30: 44971
M31: =P29*2 -> 69.768 | N31: 3500 | O31: =M31*N31 -> 244188 | P31: ADHESIVO | U31: LATA 16 LTS | V31: 3625 | W31: LITRO
F32: 0 | M32: 7 | N32: 23500 | O32: =M32*N32 -> 164500 | P32: MDF 18MM | V32: 906.25 | W32: MT2 (4)
B33: CUENTA CORRIENTE BANCO SANTANDER Nº 87316181 A NOMBRE DE MUEBLES SANTA FE SPA | M33: 4 | N33: 43500 | O33: =M33*N33 -> 174000 | P33: LAMINA 153 X 366 | V33: =V32*20% -> 181.25 | W33: PERDIDA 20%
B34: RUT : 77.054.606-0 CORREO: FRANCODONOSO@TOPMOBILI.CL | M34: 14 | N34: 21630 | O34: =M34*N34 -> 302820 | P34: LAMINA 122X244 | V34: =V32+V33 -> 1087.5 | W34: MINIMO A COTIZAR
B35: VISITANOS Y DESCUBRE NUESTROS PRODUCTOS EN | F35: WWW.TOPMOBILICHILE.CL | J35: 25 MTS PVC 22X1,5MM HUMO | M35: 4 | N35: 15041 | O35: =M35*N35 -> 60164 | P35: BALANCE | R35: 1.52
J36: 29750 | M36: 5 | N36: 25000 | O36: =M36*N36 -> 125000 | P36: TAPACANTO PVC 22X1,5 | R36: 2.44
J37: =J36/1.19 -> 25000 | M37: 2 | N37: 33605 | O37: =M37*N37 -> 67210 | P37: TAPACANTO PVC 29X2 | R37: =R35*R36 -> 3.7088
J38: 25 MTS PVC 22X2MM HUMO | O38: =SUM(O31:O37) -> 1137882 | P38: COSTO | R38: =P29/R37 -> 9.4057377
J39: 39990 | M39: PRECIO VENTA | O39: =O38*2.2 -> 2503340.4 | P39: FACTOR 2,3 PARA 90° | U39: MDF30MM | V39: 43650
J40: =J39/1.19 -> 33605.042 | O40: =O39/P27 -> 86114.221 | P40: VALOR M2 | U40: 46 UNIDADES | V40: 948.91 | W40: 2.4
O41: =O39/O38 -> 2.2 | U41: METRO LINEAL | V41: 395.37
U42: PERDIDA 20% | V42: 474.45
O49: 40935 | P49: MT2 | Q49: TERMO WOOD
...

Sheet COSTOS
B2: CENTRO DE COSTOS POSTFORMADOS
B5: FECHA: | C5: =ESCRITORIOS!G10 -> 46091
B6: CLIENTE: | C6: =ESCRITORIOS!C10 -> CONSTRUCTORA DEL ROSAL SPA | N6: Ventas Equilibrio = | P6: Costos Fijos Totales
B7: DIRECCION: | C7: =ESCRITORIOS!#REF! -> #REF! | H7: COSTOS INDIRECTOS DE FABRICA VARIABLES | O7: 1 - | P7: Costos Variables Totales
B8: PRESUPUESTO: | C8: =ESCRITORIOS!D8 -> N° 12032 | H8: Q/HRS | I8: $ | J8: DETALLE | K8: TOTAL | L8: TOTAL | P8: Total Venta | X8: =SUM(Q11:Q16) -> 6
H9: CANTIDAD | I9: PRECIO | J9: MATERIA PRIMA INDIRECTA | L9: =SUM(K10:K25) -> 41495 | S9: DETALLE | X9: =(E15-D11)/X8 -> #REF!
D10: NETO | E10: IVA | F10: TOTAL | H10: 0 | I10: 350 | J10: RESPALDO | K10: =I10*H10 -> 0 | Q10: UNIDAD | R10: TIPO | S10: LARGO | T10: ANCHO | U10: COLOR | V10: VALOR | W10: TOTAL
C11: MONTO A COBRAR | D11: =ESCRITORIOS!#REF! -> #REF! | E11: =D11*0.19 -> #REF! | F11: =E11+D11 -> #REF! | H11: 0 | I11: 500 | J11: MEDIA CAÑA | K11: =I11*H11 -> 0 | Q11: 1 | R11: CUB C/R R8 | S11: 2.8 | T11: 0.62 | U11: MADERA X DEFINIR | V11: 105990 | W11: =V11*Q11 -> 105990 | X11: =V11+$X$9 -> #REF! | Y11: 108990
C12: COSTO TOTAL | D12: =SUM(M45:M47) -> 3143849.5 | H12: 0 | I12: 7500 | J12: DUROLAC | K12: =I12*H12 -> 0 | Q12: 1 | R12: CUB C/R R8 | S12: 2.3 | T12: 0.62 | U12: MADERA X DEFINIR | V12: 87990 | W12: =V12*Q12 -> 87990 | X12: =V12+$X$9 -> #REF! | Y12: 89990
C13: % UTILIDAD | D13: =D11-D12 -> #REF! | E13: =(D11/D12)-1 -> #REF! | H13: 0 | I13: 50 | J13: TAPACANTO PVC | K13: =I13*H13 -> 0 | Q13: 1 | R13: CUB C/R R8 | S13: 2.03 | T13: 0.62 | U13: MADERA X DEFINIR | V13: 78990 | W13: =V13*Q13 -> 78990 | X13: =V13+$X$9 -> #REF! | Y13: 81990
D14: % utilidad | E14: NETO | F14: UTILIDAD | H14: 0 | I14: 50 | J14: SOBERBIOS | K14: =I14*H14 -> 0 | Q14: 1 | R14: CUB C/R R8 | S14: 1.08 | T14: 0.62 | U14: MADERA X DEFINIR | V14: 39990 | W14: =V14*Q14 -> 39990 | X14: =V14+$X$9 -> #REF! | Y14: 39990
A15: =E15*1.19 -> 6472243 | C15: PROYECCION | D15: 0.73 | E15: =(100%+D15)*D12 -> 5438859.6 | F15: =E15-D12 -> 2295010.1 | H15: 0 | I15: 10 | J15: SOPORTE REPISA | K15: =I15*H15 -> 0 | Q15: 1 | R15: CUB C/R R8 | S15: 1.08 | T15: 0.62 | U15: MADERA X DEFINIR | V15: 39990 | W15: =V15*Q15 -> 39990 | X15: =V15+$X$9 -> #REF! | Y15: 39990
H16: 1 | J16: PUNTAS | K16: =I16*H16 -> 0 | N16: =3*46 -> 138 | Q16: 1 | R16: CUB C/R R8 | S16: 2.06 | T16: 0.62 | U16: MADERA X DEFINIR | V16: 79990 | W16: =V16*Q16 -> 79990 | X16: =V16+$X$9 -> #REF! | Y16: 83990
B17: M. PRIMA | C17: MATERIAL | D17: NETO | E17: IVA | F17: TOTAL | H17: 6 | I17: 1103 | J17: TORNILLOS 3,5X50 (100U) | K17: =I17*H17 -> 6618 | Q17: 6 | R17: CORTES 45° | V17: 5000 | W17: =V17*Q17 -> 30000
C18: LAMINA GRANDE | D18: =ESCRITORIOS!O33 -> 174000 | E18: =D18*0.19 -> 33060 | F18: =SUM(D18:E18) -> 207060 | H18: 6 | I18: 543 | J18: TORNILLOS 3,5X30 (100U) | K18: =I18*H18 -> 3258 | N18: 5 | O18: 283 | Q18: 1 | R18: PERFORACION LAVAPLATOS | V18: 10000 | W18: =V18*Q18 -> 10000
C19: LAMINA | D19: =ESCRITORIOS!O34 -> 302820 | E19: =D19*0.19 -> 57535.8 | F19: =SUM(D19:E19) -> 360355.8 | J19: TORNILLOS 3,5X15 | V19: NETO | W19: =SUM(W11:W18) -> 472940 | Y19: =SUM(Y11:Y16)+SUM(W17:W18) -> 484940
C20: MDF 18MM | D20: =ESCRITORIOS!O32 -> 164500 | E20: =D20*0.19 -> 31255 | F20: =SUM(D20:E20) -> 195755 | H20: 4 | I20: 1572 | J20: COLAFRIA | K20: =I20*H20 -> 6288 | O20: =O18*N18 -> 1415 | V20: I.V.A. | W20: =W19*19% -> 89858.6 | Y20: =Y19*0.19 -> 92138.6
A21: =1300000*1.2 -> 1560000 | C21: ADHESIVO | D21: =ESCRITORIOS!O31 -> 244188 | E21: =D21*0.19 -> 46395.72 | F21: =SUM(D21:E21) -> 290583.72 | H21: 1 | J21: LIJAS | K21: =I21*H21 -> 0 | O21: =O20/60 -> 23.583333 | Q21: PLAZO DE ENTREGA : 8 DIAS HABILES | V21: TOTAL | W21: =W19+W20 -> 562798.6 | Y21: =SUM(Y19:Y20) -> 577078.6
A22: =1300000*1.2 -> 1560000 | B22: M. DE OBRA | C22: TOTAL | D22: =SUM(D18:D21) -> 885508 | E22: =SUM(E18:E21) -> 168246.52 | F22: =SUM(F18:F21) -> 1053754.5 | H22: 1 | J22: CARTON | K22: =I22*H22 -> 0 | Q22: FORMA DE PAGO: 50% CONTADO, SALDO C/E
A23: =950000*1.2 -> 1140000 | B23: =A21/23 -> 67826.087 | C23: PROCESO | D23: COSTO x Hr. | E23: Q Hrs. | F23: TOTAL | H23: 3 | I23: 3535 | J23: HUAIPE | K23: =I23*H23 -> 10605 | M23: =B32/9 -> 2318.8406 | Q23: VALIDEZ COTIZACIÓN: 5 DIAS
A24: 450000 | B24: =A22/23 -> 67826.087 | C24: CORTE | D24: =B23/8 -> 8478.2609 | E24: 23.6 | F24: =D24*E24 -> 200086.96 | H24: 2 | I24: 7363 | J24: DILUYENTE | K24: =I24*H24 -> 14726
A25: 450000 | B25: =A23/23 -> 49565.217 | C25: CORTE LAMINA | D25: =B24/8 -> 8478.2609 | E25: 23.6 | F25: =D25*E25 -> 200086.96 | H25: 1 | J25: CINTA EMBALAJE | K25: =I25*H25 -> 0
B26: =A24/23 -> 19565.217 | C26: REBAJE LAMINA | D26: =B25/8 -> 6195.6522 | F26: =D26*E26 -> 0 | H26: Q/HRS | I26: PRECIO | J26: MANO DE OBRA INDIRECTA | K26: VALOR | L26: =SUM(K27:K37) -> 39086.957
A27: 350000 | B27: =A25/23 -> 19565.217 | C27: TUPIZADO | D27: =B26/8 -> 2445.6522 | E27: 9.5 | F27: =D27*E27 -> 23233.696 | H27: 10 | I27: =((480000/23)/8) -> 2608.6957 | J27: FLETERO (HRS) | K27: =H27*I27 -> 26086.957
A28: 500000 | B28: =A28/23 -> 21739.13 | C28: ARMADO | D28: =B27/8 -> 2445.6522 | F28: =D28*E28 -> 0 | H28: 10 | I28: 1300 | J28: BENCINA | K28: =H28*I28 -> 13000
B29: =A28/23 -> 21739.13 | C29: PEGADO | D29: =B28/8 -> 2717.3913 | E29: 47.2 | F29: =D29*E29 -> 128260.87 | H29: 0 | J29: TAG | K29: =H29*I29 -> 0
A30: 450000 | C30: POSTFORMADO | D30: =B29/8 -> 2717.3913 | E30: 38 | F30: =D30*E30 -> 103260.87 | H30: 0 | J30: RECTIFICACION | K30: =H30*I30 -> 0
A31: 350000 | B31: =A30/23 -> 19565.217 | C31: MEDIA CAÑA | D31: =B26/8 -> 2445.6522 | E31: 24 | F31: =D31*E31 -> 58695.652 | H31: 0 | I31: =((550000*1.2)/23)/9 -> 3188.4058 | J31: HR. TRAB. JUAN | K31: =H31*I31 -> 0
A32: =A21+A24+A27+A28+A30 -> 3310000 | B32: =480000/23 -> 20869.565 | C32: CORTE-ENCHAPE | D32: =B31/8 -> 2445.6522 | E32: 0 | F32: =D32*E32 -> 0 | H32: 0 | I32: =((450000*1.2)/23)/9 -> 2608.6957 | J32: HR. TRAB. JULIO | K32: =H32*I32 -> 0
C33: CONTROL CALIDAD | D33: =B32/8 -> 2608.6957 | E33: 24 | F33: =D33*E33 -> 62608.696 | H33: 0 | I33: =((450000*1.2)/23)/9 -> 2608.6957 | J33: HR. TRAB. EUGE | K33: =H33*I33 -> 0
B34: CIF | C34: TOTAL | D34: =SUM(D24:D33) -> 40978.261 | E34: =SUM(E24:E33) -> 189.9 | F34: =SUM(F24:F33) -> 776233.7 | H34: 0 | J34: COLACION | K34: =H34*I34 -> 0
C35: M. PRIMA INDIREC. | D35: =L9 -> 41495 | H35: 0 | J35: BONO | K35: =H35*I35 -> 0
C36: M. OBRA INDIRECTA | D36: =L26 -> 39086.957 | H36: 1 | J36: PERFORACION | K36: =H36*I36 -> 0
C37: GASTOS DE FABRICA | D37: =L38 -> 1401525.9 | H37: 6 | J37: CORTE 45 | K37: =H37*I37 -> 0
C38: DEPRECIACIONES | H38: CANTIDAD | I38: PRECIO | J38: GASTOS DE FABRICACION | K38: VALOR | L38: =SUM(K39:K41) -> 1401525.9
C39: TOTAL | D39: =SUM(D35:D38) -> 1482107.8 | H39: =$E$34 -> 189.9 | I39: =39130.69/8 -> 4891.3363 | J39: ARRIENDO x HORA | K39: =I39*H39 -> 928864.75
B40: PROVISIONAR | C40: IVA | D40: =E11-E22 -> #REF! | H40: =$E$34 -> 189.9 | I40: 967 | J40: AGUA x HORA | K40: =I40*H40 -> 183633.3
H41: =$E$34 -> 189.9 | I41: 1522 | J41: LUZ x HORA | K41: =I41*H41 -> 289027.8
B42: TOTAL HRS TRABAJADAS | D42: =E34 -> 189.9
H43: ESTADO DE RESULTADOS
...
