Workbook

Sheet 2229 (2)
F2: MUEBLES SANTA FE SPA
F3: VENTAS POR MENOR DE MUEBLES
F4: RUT: 77.054.606-0
F5: SEPTIMA AVENIDA 1631, SAN MIGUEL
F6: FONO +569 2032 3382 | O6: 10077 SF PORTLAND MAPLE
F7: E-MAIL: ventas@topmobili.cl
B8: P R E S U P U E S T O | D8: N° 12056
B10: NOMBRE: | C10: MUEBLERIA VALENTINA | F10: FECHA | G10: 46118
B11: RUT: | F11: PLAZO ENTREGA | G11: 10 DIAS HABILES | R11: MT2 PUERTAS
B12: GIRO: | F12: SERVICIO EXPRESS | G12: NO
B13: CONTACTO: | C13: SAMI | F13: CORTADA A LA MEDIDA | G13: SI
B14: CORREO: | F14: DESPACHO | G14: NO | R14: ML CUBIERTAS
B15: FONO: | C15: +569 7220 1095 | F15: INSTALACIÓN | G15: NO
B16: DIRECCION: | F16: FORMA DE PAGO: | G16: ABONO 50% SALDO C/ENTREGA
B17: CIUDAD: | C17: RANCAGUA | F17: Duración cotización 5 días hábiles | G17: Cotizado por: Franco Donoso
B19: DETALLE | M19: 0.05 | P19: TOTAL | Q19: VALOR X MT2 | R19: ENCHAPE | S19: MT/L
B20: UNIDAD | C20: TIPO | D20: LARGO | E20: ANCHO | F20: COLOR | G20: VALOR | H20: TOTAL | L20: =B20 -> UNIDAD | M20: ALTO | N20: =E20 -> ANCHO | O20: MT | P20: MT2 | Q20: =O65 -> 134903.42 | R20: 3000 | T20: m/l
B21: 2 | C21: PR8 2 CARAS | D21: 0.5 | E21: 0.48 | F21: NEUTRAL OAK 1498 MT | G21: 35395 | H21: =G21*B21 -> 70790 | L21: =B21 -> 2 | M21: =D21+M$19 -> 0.55 | N21: =E21+$N$19 -> 0.48 | O21: =M21*N21 -> 0.264 | P21: =O21*L21 -> 0.528 | Q21: =Q$20*O21 -> 35614.502 | R21: =Q21+R$20 -> 38614.502 | S21: =M21*L21 -> 1.1 | T21: =N21*2*L21*2 -> 3.84
B22: 1 | C22: PR8 2 CARAS | D22: 0.76 | E22: 0.427 | F22: NEUTRAL OAK 1498 MT | G22: 45441 | H22: =G22*B22 -> 45441 | L22: =B22 -> 1 | M22: =D22+M$19 -> 0.81 | N22: =E22+$N$19 -> 0.427 | O22: =M22*N22 -> 0.34587 | P22: =O22*L22 -> 0.34587 | Q22: =Q$20*O22 -> 46659.045 | R22: =Q22+R$20 -> 49659.045 | S22: =M22*L22 -> 0.81
B23: 1 | C23: PR8 2 CARAS | D23: 0.76 | E23: 0.715 | F23: NEUTRAL OAK 1498 MT | G23: 74066 | H23: =G23*B23 -> 74066 | L23: =B23 -> 1 | M23: =D23+M$19 -> 0.81 | N23: =E23+$N$19 -> 0.715 | O23: =M23*N23 -> 0.57915 | P23: =O23*L23 -> 0.57915 | Q23: =Q$20*O23 -> 78129.314 | R23: =Q23+R$20 -> 81129.314 | S23: =M23*L23 -> 0.81
B24: 1 | C24: PR8 2 CARAS | D24: 0.76 | E24: 0.27 | F24: NEUTRAL OAK 1498 MT | G24: 29836 | H24: =G24*B24 -> 29836 | L24: =B24 -> 1 | M24: =D24+M$19 -> 0.81 | N24: =E24+$N$19 -> 0.27 | O24: =M24*N24 -> 0.2187 | P24: =O24*L24 -> 0.2187 | Q24: =Q$20*O24 -> 29503.377 | R24: =Q24+R$20 -> 32503.377 | S24: =M24*L24 -> 0.81
B25: 3 | C25: PR8 2 CARAS | D25: 0.76 | E25: 0.477 | F25: NEUTRAL OAK 1498 MT | G25: 50411 | H25: =G25*B25 -> 151233 | L25: =B25 -> 3 | M25: =D25+M$19 -> 0.81 | N25: =E25+$N$19 -> 0.477 | O25: =M25*N25 -> 0.38637 | P25: =O25*L25 -> 1.15911 | Q25: =Q$20*O25 -> 52122.633 | R25: =Q25+R$20 -> 55122.633 | S25: =M25*L25 -> 2.43
B26: 2 | C26: PR8 2 CARAS | D26: 0.76 | E26: 0.472 | F26: NEUTRAL OAK 1498 MT | G26: 49914 | H26: =G26*B26 -> 99828 | L26: =B26 -> 2 | M26: =D26+M$19 -> 0.81 | N26: =E26+$N$19 -> 0.472 | O26: =M26*N26 -> 0.38232 | P26: =O26*L26 -> 0.76464 | Q26: =Q$20*O26 -> 51576.274 | R26: =Q26+R$20 -> 54576.274 | S26: =M26*L26 -> 1.62
B27: 2 | C27: PR8 2 CARAS | D27: 0.76 | E27: 0.446 | F27: NEUTRAL OAK 1498 MT | G27: 47329 | H27: =G27*B27 -> 94658 | L27: =B27 -> 2 | M27: =D27+M$19 -> 0.81 | N27: =E27+$N$19 -> 0.446 | O27: =M27*N27 -> 0.36126 | P27: =O27*L27 -> 0.72252 | Q27: =Q$20*O27 -> 48735.208 | R27: =Q27+R$20 -> 51735.208 | S27: =M27*L27 -> 1.62
B28: 1 | C28: PR8 2 CARAS | D28: 0.76 | E28: 0.595 | F28: NEUTRAL OAK 1498 MT | G28: 62139 | H28: =G28*B28 -> 62139 | L28: =B28 -> 1 | M28: =D28+M$19 -> 0.81 | N28: =E28+$N$19 -> 0.595 | O28: =M28*N28 -> 0.48195 | P28: =O28*L28 -> 0.48195 | Q28: =Q$20*O28 -> 65016.702 | R28: =Q28+R$20 -> 68016.702 | S28: =M28*L28 -> 0.81
B29: 1 | C29: PR8 2 CARAS | D29: 0.76 | E29: 0.62 | F29: NEUTRAL OAK 1498 MT | G29: 64624 | H29: =G29*B29 -> 64624 | L29: =B29 -> 1 | M29: =D29+M$19 -> 0.81 | N29: =E29+$N$19 -> 0.62 | O29: =M29*N29 -> 0.5022 | P29: =O29*L29 -> 0.5022 | Q29: =Q$20*O29 -> 67748.496 | R29: =Q29+R$20 -> 70748.496 | S29: =M29*L29 -> 0.81
B30: 2 | C30: PR8 | D30: 1.12 | E30: 0.319 | F30: VAINILLA 2109 BR | G30: 29071 | H30: =G30*B30 -> 58142 | K30: 1 | M30: =D30+M$19 -> 1.17 | N30: =E30+$N$19 -> 0.319 | O30: =M30*N30 -> 0.37323 | P30: =O30*L30 -> 0 | Q30: =Q$20*O30 -> 50350.002 | R30: =Q30+R$20 -> 53350.002 | S30: =M30*L30 -> 0
B31: 2 | C31: PR8 | D31: 0.63 | E31: 0.321 | F31: VAINILLA 2109 BR | G31: 18247 | H31: =G31*B31 -> 36494 | M31: =D31+M$19 -> 0.68 | N31: =E31+$N$19 -> 0.321 | O31: =M31*N31 -> 0.21828 | P31: =O31*L31 -> 0 | Q31: =Q$20*O31 -> 29446.718 | R31: =Q31+R$20 -> 32446.718 | S31: =M31*L31 -> 0
B32: 1 | C32: PR8 | D32: 0.6 | E32: 0.64 | F32: VAINILLA 2109 BR | G32: 32058 | H32: =G32*B32 -> 32058 | M32: =D32+M$19 -> 0.65 | N32: =E32+$N$19 -> 0.64 | O32: =M32*N32 -> 0.416 | P32: =O32*L32 -> 0 | Q32: =Q$20*O32 -> 56119.821 | R32: =Q32+R$20 -> 59119.821 | S32: =M32*L32 -> 0
B33: 2 | C33: PR8 | D33: 0.84 | E33: 0.447 | F33: VAINILLA 2109 BR | G33: 30789 | H33: =G33*B33 -> 61578 | K33: 1 | M33: =D33+M$19 -> 0.89 | N33: =E33+$N$19 -> 0.447 | O33: =M33*N33 -> 0.39783 | P33: =O33*L33 -> 0 | Q33: =Q$20*O33 -> 53668.626 | R33: =Q33+R$20 -> 56668.626 | S33: =M33*L33 -> 0
B34: 1 | C34: PR8 | D34: 0.84 | E34: 0.62 | F34: VAINILLA 2109 BR | G34: 41544 | H34: =G34*B34 -> 41544 | M34: =D34+M$19 -> 0.89 | N34: =E34+$N$19 -> 0.62 | O34: =M34*N34 -> 0.5518 | P34: =O34*L34 -> 0 | Q34: =Q$20*O34 -> 74439.705 | R34: =Q34+R$20 -> 77439.705 | S34: =M34*L34 -> 0
B35: 4 | C35: PR8 | D35: 0.84 | E35: 0.447 | F35: VAINILLA 2109 BR | G35: 30789 | H35: =G35*B35 -> 123156 | M35: =D35+M$19 -> 0.89 | N35: =E35+$N$19 -> 0.447 | O35: =M35*N35 -> 0.39783 | P35: =O35*L35 -> 0 | Q35: =Q$20*O35 -> 53668.626 | R35: =Q35+R$20 -> 56668.626 | S35: =M35*L35 -> 0
B36: 1 | C36: PR8 | D36: 0.84 | E36: 0.62 | F36: VAINILLA 2109 BR | G36: 41544 | H36: =G36*B36 -> 41544 | M36: =D36+M$19 -> 0.89 | N36: =E36+$N$19 -> 0.62 | O36: =M36*N36 -> 0.5518 | P36: =O36*L36 -> 0 | Q36: =Q$20*O36 -> 74439.705 | R36: =Q36+R$20 -> 77439.705 | S36: =M36*L36 -> 0
B37: 4 | C37: PR8 | D37: 0.84 | E37: 0.447 | F37: VAINILLA 2109 BR | G37: 30789 | H37: =G37*B37 -> 123156 | K37: 1 | M37: =D37+M$19 -> 0.89 | N37: =E37+$N$19 -> 0.447 | O37: =M37*N37 -> 0.39783 | P37: =O37*L37 -> 0 | Q37: =Q$20*O37 -> 53668.626 | R37: =Q37+R$20 -> 56668.626 | S37: =M37*L37 -> 0
B38: 1 | C38: PR8 | D38: 0.88 | E38: 0.64 | F38: VAINILLA 2109 BR | G38: 44576 | H38: =G38*B38 -> 44576 | M38: =D38+M$19 -> 0.93 | N38: =E38+$N$19 -> 0.64 | O38: =M38*N38 -> 0.5952 | P38: =O38*L38 -> 0 | Q38: =Q$20*O38 -> 80294.513 | R38: =Q38+R$20 -> 83294.513 | S38: =M38*L38 -> 0
B39: 2 | C39: PR8 | D39: 2.23 | E39: 0.495 | F39: VAINILLA 2109 BR | G39: 81835 | H39: =G39*B39 -> 163670 | K39: 1 | M39: =D39+M$19 -> 2.28 | N39: =E39+$N$19 -> 0.495 | O39: =M39*N39 -> 1.1286 | P39: =O39*L39 -> 0 | Q39: =Q$20*O39 -> 152252 | R39: =Q39+R$20 -> 155252 | S39: =M39*L39 -> 0
B40: 2 | C40: PR8 | D40: 0.76 | E40: 0.372 | F40: VAINILLA 2109 BR | G40: 24048 | H40: =G40*B40 -> 48096 | M40: =D40+M$19 -> 0.81 | N40: =E40+$N$19 -> 0.372 | O40: =M40*N40 -> 0.30132 | P40: =O40*L40 -> 0 | Q40: =Q$20*O40 -> 40649.097 | R40: =Q40+R$20 -> 43649.097 | S40: =M40*L40 -> 0
B41: 1 | C41: PR8 | D41: 0.76 | E41: 0.505 | F41: VAINILLA 2109 BR | G41: 31573 | H41: =G41*B41 -> 31573 | M41: =D41+M$19 -> 0.81 | N41: =E41+$N$19 -> 0.505 | O41: =M41*N41 -> 0.40905 | P41: =O41*L41 -> 0 | Q41: =Q$20*O41 -> 55182.242 | R41: =Q41+R$20 -> 58182.242 | S41: =M41*L41 -> 0
B42: 1 | C42: PR8 | D42: 0.76 | E42: 0.52 | F42: VAINILLA 2109 BR | G42: 32422 | H42: =G42*B42 -> 32422 | M42: =D42+M$19 -> 0.81 | N42: =E42+$N$19 -> 0.52 | O42: =M42*N42 -> 0.4212 | P42: =O42*L42 -> 0 | Q42: =Q$20*O42 -> 56821.319 | R42: =Q42+R$20 -> 59821.319 | S42: =M42*L42 -> 0
B43: 2 | C43: PR8 | D43: 0.76 | E43: 0.302 | F43: VAINILLA 2109 BR | G43: 20087 | H43: =G43*B43 -> 40174 | K43: 1 | M43: =D43+M$19 -> 0.81 | N43: =E43+$N$19 -> 0.302 | O43: =M43*N43 -> 0.24462 | P43: =O43*L43 -> 0 | Q43: =Q$20*O43 -> 33000.074 | R43: =Q43+R$20 -> 36000.074 | S43: =M43*L43 -> 0
...

Sheet 2229
F2: MUEBLES SANTA FE SPA
F3: VENTAS POR MENOR DE MUEBLES
F4: RUT: 77.054.606-0
F5: SEPTIMA AVENIDA 1631, SAN MIGUEL
F6: FONO +569 2032 3382 | O6: 10077 SF PORTLAND MAPLE
F7: E-MAIL: ventas@topmobili.cl
B8: P R E S U P U E S T O | D8: N° 12056
B10: NOMBRE: | C10: MUEBLERIA VALENTINA | F10: FECHA | G10: 46118
B11: RUT: | F11: PLAZO ENTREGA | G11: 10 DIAS HABILES | R11: MT2 PUERTAS
B12: GIRO: | F12: SERVICIO EXPRESS | G12: NO
B13: CONTACTO: | C13: SAMI | F13: CORTADA A LA MEDIDA | G13: SI
B14: CORREO: | F14: DESPACHO | G14: NO | R14: ML CUBIERTAS
B15: FONO: | C15: +569 7220 1095 | F15: INSTALACIÓN | G15: NO
B16: DIRECCION: | F16: FORMA DE PAGO: | G16: ABONO 50% SALDO C/ENTREGA
B17: CIUDAD: | C17: RANCAGUA | F17: Duración cotización 5 días hábiles | G17: Cotizado por: Franco Donoso
B19: DETALLE | M19: 0.05 | P19: TOTAL | Q19: VALOR X MT2 | R19: ENCHAPE | S19: MT/L
B20: UNIDAD | C20: TIPO | D20: LARGO | E20: ANCHO | F20: COLOR | G20: VALOR | H20: TOTAL | L20: =B20 -> UNIDAD | M20: ALTO | N20: =E20 -> ANCHO | O20: MT | P20: MT2 | Q20: =O65 -> 69852.046 | R20: 3000 | T20: m/l
B21: 2 | C21: PR6 2 CARAS | D21: 0.5 | E21: 0.48 | F21: NEUTRAL OAK 1498 MT | G21: 35395 | H21: =G21*B21 -> 70790 | M21: =D21+M$19 -> 0.55 | N21: =E21+$N$19 -> 0.48 | O21: =M21*N21 -> 0.264 | P21: =O21*L21 -> 0 | Q21: =Q$20*O21 -> 18440.94 | R21: =Q21+R$20 -> 21440.94 | S21: =M21*L21 -> 0 | T21: =N21*2*L21*2 -> 0
B22: 1 | C22: PR6 2 CARAS | D22: 0.76 | E22: 0.427 | F22: NEUTRAL OAK 1498 MT | G22: 45441 | H22: =G22*B22 -> 45441 | M22: =D22+M$19 -> 0.81 | N22: =E22+$N$19 -> 0.427 | O22: =M22*N22 -> 0.34587 | P22: =O22*L22 -> 0 | Q22: =Q$20*O22 -> 24159.727 | R22: =Q22+R$20 -> 27159.727 | S22: =M22*L22 -> 0
B23: 1 | C23: PR6 2 CARAS | D23: 0.76 | E23: 0.715 | F23: NEUTRAL OAK 1498 MT | G23: 74066 | H23: =G23*B23 -> 74066 | M23: =D23+M$19 -> 0.81 | N23: =E23+$N$19 -> 0.715 | O23: =M23*N23 -> 0.57915 | P23: =O23*L23 -> 0 | Q23: =Q$20*O23 -> 40454.813 | R23: =Q23+R$20 -> 43454.813 | S23: =M23*L23 -> 0
B24: 1 | C24: PR6 2 CARAS | D24: 0.76 | E24: 0.27 | F24: NEUTRAL OAK 1498 MT | G24: 29836 | H24: =G24*B24 -> 29836 | M24: =D24+M$19 -> 0.81 | N24: =E24+$N$19 -> 0.27 | O24: =M24*N24 -> 0.2187 | P24: =O24*L24 -> 0 | Q24: =Q$20*O24 -> 15276.643 | R24: =Q24+R$20 -> 18276.643 | S24: =M24*L24 -> 0
B25: 3 | C25: PR6 2 CARAS | D25: 0.76 | E25: 0.477 | F25: NEUTRAL OAK 1498 MT | G25: 50411 | H25: =G25*B25 -> 151233 | M25: =D25+M$19 -> 0.81 | N25: =E25+$N$19 -> 0.477 | O25: =M25*N25 -> 0.38637 | P25: =O25*L25 -> 0 | Q25: =Q$20*O25 -> 26988.735 | R25: =Q25+R$20 -> 29988.735 | S25: =M25*L25 -> 0
B26: 2 | C26: PR6 2 CARAS | D26: 0.76 | E26: 0.472 | F26: NEUTRAL OAK 1498 MT | G26: 49914 | H26: =G26*B26 -> 99828 | M26: =D26+M$19 -> 0.81 | N26: =E26+$N$19 -> 0.472 | O26: =M26*N26 -> 0.38232 | P26: =O26*L26 -> 0 | Q26: =Q$20*O26 -> 26705.834 | R26: =Q26+R$20 -> 29705.834 | S26: =M26*L26 -> 0
B27: 2 | C27: PR6 2 CARAS | D27: 0.76 | E27: 0.446 | F27: NEUTRAL OAK 1498 MT | G27: 47329 | H27: =G27*B27 -> 94658 | M27: =D27+M$19 -> 0.81 | N27: =E27+$N$19 -> 0.446 | O27: =M27*N27 -> 0.36126 | P27: =O27*L27 -> 0 | Q27: =Q$20*O27 -> 25234.75 | R27: =Q27+R$20 -> 28234.75 | S27: =M27*L27 -> 0
B28: 1 | C28: PR6 2 CARAS | D28: 0.76 | E28: 0.595 | F28: NEUTRAL OAK 1498 MT | G28: 62139 | H28: =G28*B28 -> 62139 | M28: =D28+M$19 -> 0.81 | N28: =E28+$N$19 -> 0.595 | O28: =M28*N28 -> 0.48195 | P28: =O28*L28 -> 0 | Q28: =Q$20*O28 -> 33665.194 | R28: =Q28+R$20 -> 36665.194 | S28: =M28*L28 -> 0
B29: 1 | C29: PR6 2 CARAS | D29: 0.76 | E29: 0.62 | F29: NEUTRAL OAK 1498 MT | G29: 64624 | H29: =G29*B29 -> 64624 | M29: =D29+M$19 -> 0.81 | N29: =E29+$N$19 -> 0.62 | O29: =M29*N29 -> 0.5022 | P29: =O29*L29 -> 0 | Q29: =Q$20*O29 -> 35079.698 | R29: =Q29+R$20 -> 38079.698 | S29: =M29*L29 -> 0
B30: 2 | C30: PR6 | D30: 1.12 | E30: 0.319 | F30: SHELL WHITE | G30: 25180 | H30: =G30*B30 -> 50360 | I30: 29071 | K30: 1 | L30: =B30 -> 2 | M30: =D30+M$19 -> 1.17 | N30: =E30+$N$19 -> 0.319 | O30: =M30*N30 -> 0.37323 | P30: =O30*L30 -> 0.74646 | Q30: =Q$20*O30 -> 26070.879 | R30: =Q30+R$20 -> 29070.879 | S30: =M30*L30 -> 2.34
B31: 2 | C31: PR6 | D31: 0.63 | E31: 0.321 | F31: GLACIAL WHITE 22191 SF | G31: 15972 | H31: =G31*B31 -> 31944 | I31: 18247 | L31: =B31 -> 2 | M31: =D31+M$19 -> 0.68 | N31: =E31+$N$19 -> 0.321 | O31: =M31*N31 -> 0.21828 | P31: =O31*L31 -> 0.43656 | Q31: =Q$20*O31 -> 15247.305 | R31: =Q31+R$20 -> 18247.305 | S31: =M31*L31 -> 1.36
B32: 1 | C32: PR6 | D32: 0.6 | E32: 0.64 | F32: GLACIAL WHITE 22191 SF | G32: 27722 | H32: =G32*B32 -> 27722 | I32: 32058 | L32: =B32 -> 1 | M32: =D32+M$19 -> 0.65 | N32: =E32+$N$19 -> 0.64 | O32: =M32*N32 -> 0.416 | P32: =O32*L32 -> 0.416 | Q32: =Q$20*O32 -> 29058.451 | R32: =Q32+R$20 -> 32058.451 | S32: =M32*L32 -> 0.65
B33: 2 | C33: PR6 | D33: 0.84 | E33: 0.447 | F33: GLACIAL WHITE 22191 SF | G33: 26642 | H33: =G33*B33 -> 53284 | I33: 30789 | K33: 1 | L33: =B33 -> 2 | M33: =D33+M$19 -> 0.89 | N33: =E33+$N$19 -> 0.447 | O33: =M33*N33 -> 0.39783 | P33: =O33*L33 -> 0.79566 | Q33: =Q$20*O33 -> 27789.24 | R33: =Q33+R$20 -> 30789.24 | S33: =M33*L33 -> 1.78
B34: 1 | C34: PR6 | D34: 0.84 | E34: 0.62 | F34: GLACIAL WHITE 22191 SF | G34: 35792 | H34: =G34*B34 -> 35792 | I34: 41544 | L34: =B34 -> 1 | M34: =D34+M$19 -> 0.89 | N34: =E34+$N$19 -> 0.62 | O34: =M34*N34 -> 0.5518 | P34: =O34*L34 -> 0.5518 | Q34: =Q$20*O34 -> 38544.359 | R34: =Q34+R$20 -> 41544.359 | S34: =M34*L34 -> 0.89
B35: 4 | C35: PR6 | D35: 0.84 | E35: 0.447 | F35: GLACIAL WHITE 22191 SF | G35: 26642 | H35: =G35*B35 -> 106568 | I35: 30789 | L35: =B35 -> 4 | M35: =D35+M$19 -> 0.89 | N35: =E35+$N$19 -> 0.447 | O35: =M35*N35 -> 0.39783 | P35: =O35*L35 -> 1.59132 | Q35: =Q$20*O35 -> 27789.24 | R35: =Q35+R$20 -> 30789.24 | S35: =M35*L35 -> 3.56
B36: 1 | C36: PR6 | D36: 0.84 | E36: 0.62 | F36: GLACIAL WHITE 22191 SF | G36: 35792 | H36: =G36*B36 -> 35792 | I36: 41544 | L36: =B36 -> 1 | M36: =D36+M$19 -> 0.89 | N36: =E36+$N$19 -> 0.62 | O36: =M36*N36 -> 0.5518 | P36: =O36*L36 -> 0.5518 | Q36: =Q$20*O36 -> 38544.359 | R36: =Q36+R$20 -> 41544.359 | S36: =M36*L36 -> 0.89
B37: 4 | C37: PR6 | D37: 0.84 | E37: 0.447 | F37: GLACIAL WHITE 22191 SF | G37: 26642 | H37: =G37*B37 -> 106568 | I37: 30789 | K37: 1 | L37: =B37 -> 4 | M37: =D37+M$19 -> 0.89 | N37: =E37+$N$19 -> 0.447 | O37: =M37*N37 -> 0.39783 | P37: =O37*L37 -> 1.59132 | Q37: =Q$20*O37 -> 27789.24 | R37: =Q37+R$20 -> 30789.24 | S37: =M37*L37 -> 3.56
B38: 1 | C38: PR6 | D38: 0.88 | E38: 0.64 | F38: GLACIAL WHITE 22191 SF | G38: 38371 | H38: =G38*B38 -> 38371 | I38: 44576 | L38: =B38 -> 1 | M38: =D38+M$19 -> 0.93 | N38: =E38+$N$19 -> 0.64 | O38: =M38*N38 -> 0.5952 | P38: =O38*L38 -> 0.5952 | Q38: =Q$20*O38 -> 41575.938 | R38: =Q38+R$20 -> 44575.938 | S38: =M38*L38 -> 0.93
B39: 2 | C39: PR6 | D39: 2.23 | E39: 0.495 | F39: GLACIAL WHITE 22191 SF | G39: 70070 | H39: =G39*B39 -> 140140 | I39: 81835 | K39: 1 | L39: =B39 -> 2 | M39: =D39+M$19 -> 2.28 | N39: =E39+$N$19 -> 0.495 | O39: =M39*N39 -> 1.1286 | P39: =O39*L39 -> 2.2572 | Q39: =Q$20*O39 -> 78835.019 | R39: =Q39+R$20 -> 81835.019 | S39: =M39*L39 -> 4.56
B40: 2 | C40: PR6 | D40: 0.76 | E40: 0.372 | F40: GLACIAL WHITE 22191 SF | G40: 20907 | H40: =G40*B40 -> 41814 | I40: 24048 | L40: =B40 -> 2 | M40: =D40+M$19 -> 0.81 | N40: =E40+$N$19 -> 0.372 | O40: =M40*N40 -> 0.30132 | P40: =O40*L40 -> 0.60264 | Q40: =Q$20*O40 -> 21047.819 | R40: =Q40+R$20 -> 24047.819 | S40: =M40*L40 -> 1.62
B41: 1 | C41: PR6 | D41: 0.76 | E41: 0.505 | F41: GLACIAL WHITE 22191 SF | G41: 27309 | H41: =G41*B41 -> 27309 | I41: 31573 | L41: =B41 -> 1 | M41: =D41+M$19 -> 0.81 | N41: =E41+$N$19 -> 0.505 | O41: =M41*N41 -> 0.40905 | P41: =O41*L41 -> 0.40905 | Q41: =Q$20*O41 -> 28572.98 | R41: =Q41+R$20 -> 31572.98 | S41: =M41*L41 -> 0.81
B42: 1 | C42: PR6 | D42: 0.76 | E42: 0.52 | F42: GLACIAL WHITE 22191 SF | G42: 28031 | H42: =G42*B42 -> 28031 | I42: 32422 | L42: =B42 -> 1 | M42: =D42+M$19 -> 0.81 | N42: =E42+$N$19 -> 0.52 | O42: =M42*N42 -> 0.4212 | P42: =O42*L42 -> 0.4212 | Q42: =Q$20*O42 -> 29421.682 | R42: =Q42+R$20 -> 32421.682 | S42: =M42*L42 -> 0.81
B43: 2 | C43: PR6 | D43: 0.76 | E43: 0.302 | F43: GLACIAL WHITE 22191 SF | G43: 17537 | H43: =G43*B43 -> 35074 | I43: 20087 | K43: 1 | L43: =B43 -> 2 | M43: =D43+M$19 -> 0.81 | N43: =E43+$N$19 -> 0.302 | O43: =M43*N43 -> 0.24462 | P43: =O43*L43 -> 0.48924 | Q43: =Q$20*O43 -> 17087.208 | R43: =Q43+R$20 -> 20087.208 | S43: =M43*L43 -> 1.62
...

Sheet COSTOS
B2: CENTRO DE COSTOS POSTFORMADOS
B5: FECHA: | C5: ='2229'!G10 -> 46118
B6: CLIENTE: | C6: ='2229'!C10 -> MUEBLERIA VALENTINA | N6: Ventas Equilibrio = | P6: Costos Fijos Totales
B7: DIRECCION: | C7: ='2229'!#REF! -> #REF! | H7: COSTOS INDIRECTOS DE FABRICA VARIABLES | O7: 1 - | P7: Costos Variables Totales
B8: PRESUPUESTO: | C8: ='2229'!D8 -> N° 12056 | H8: Q/HRS | I8: $ | J8: DETALLE | K8: TOTAL | L8: TOTAL | P8: Total Venta | X8: =SUM(Q11:Q16) -> 6
H9: CANTIDAD | I9: PRECIO | J9: MATERIA PRIMA INDIRECTA | L9: =SUM(K10:K23) -> 2550 | S9: DETALLE | X9: =(E15-D11)/X8 -> -200126.69
D10: NETO | E10: IVA | F10: TOTAL | H10: 3 | I10: 350 | J10: RESPALDO | K10: =I10*H10 -> 1050 | Q10: UNIDAD | R10: TIPO | S10: LARGO | T10: ANCHO | U10: COLOR | V10: VALOR | W10: TOTAL
C11: MONTO A COBRAR | D11: ='2229'!H51 -> 1924051 | E11: =D11*0.19 -> 365569.69 | F11: =E11+D11 -> 2289620.7 | H11: 3 | I11: 500 | J11: MEDIA CAÑA | K11: =I11*H11 -> 1500 | Q11: 1 | R11: CUB C/R R8 | S11: 2.8 | T11: 0.62 | U11: MADERA X DEFINIR | V11: 105990 | W11: =V11*Q11 -> 105990 | X11: =V11+$X$9 -> -94136.691 | Y11: 108990
C12: COSTO TOTAL | D12: =SUM(M43:M45) -> 438358.09 | H12: 0 | I12: 7500 | J12: DUROLAC | K12: =I12*H12 -> 0 | Q12: 1 | R12: CUB C/R R8 | S12: 2.3 | T12: 0.62 | U12: MADERA X DEFINIR | V12: 87990 | W12: =V12*Q12 -> 87990 | X12: =V12+$X$9 -> -112136.69 | Y12: 89990
C13: % UTILIDAD | D13: =D11-D12 -> 1485692.9 | E13: =(D11/D12)-1 -> 3.389222 | H13: 0 | I13: 50 | J13: TAPACANTO PVC | K13: =I13*H13 -> 0 | Q13: 1 | R13: CUB C/R R8 | S13: 2.03 | T13: 0.62 | U13: MADERA X DEFINIR | V13: 78990 | W13: =V13*Q13 -> 78990 | X13: =V13+$X$9 -> -121136.69 | Y13: 81990
D14: % utilidad | E14: NETO | F14: UTILIDAD | H14: 0 | I14: 50 | J14: SOBERBIOS | K14: =I14*H14 -> 0 | Q14: 1 | R14: CUB C/R R8 | S14: 1.08 | T14: 0.62 | U14: MADERA X DEFINIR | V14: 39990 | W14: =V14*Q14 -> 39990 | X14: =V14+$X$9 -> -160136.69 | Y14: 39990
C15: PROYECCION | D15: 0.65 | E15: =(100%+D15)*D12 -> 723290.86 | F15: =E15-D12 -> 284932.76 | H15: 0 | I15: 10 | J15: SOPORTE REPISA | K15: =I15*H15 -> 0 | Q15: 1 | R15: CUB C/R R8 | S15: 1.08 | T15: 0.62 | U15: MADERA X DEFINIR | V15: 39990 | W15: =V15*Q15 -> 39990 | X15: =V15+$X$9 -> -160136.69 | Y15: 39990
H16: 1 | J16: PUNTAS | K16: =I16*H16 -> 0 | Q16: 1 | R16: CUB C/R R8 | S16: 2.06 | T16: 0.62 | U16: MADERA X DEFINIR | V16: 79990 | W16: =V16*Q16 -> 79990 | X16: =V16+$X$9 -> -120136.69 | Y16: 83990
B17: M. PRIMA | C17: MATERIAL | D17: NETO | E17: IVA | F17: TOTAL | H17: 1 | J17: TORNILLOS | K17: =I17*H17 -> 0 | Q17: 6 | R17: CORTES 45° | V17: 5000 | W17: =V17*Q17 -> 30000
C18: LAMINA | D18: ='2229'!O59 -> 0 | E18: =D18*0.19 -> 0 | F18: =SUM(D18:E18) -> 0 | H18: 1 | J18: COLAFRIA | K18: =I18*H18 -> 0 | Q18: 1 | R18: PERFORACION LAVAPLATOS | V18: 10000 | W18: =V18*Q18 -> 10000
C19: MDF 18MM | D19: ='2229'!O58 -> 250152 | E19: =D19*0.19 -> 47528.88 | F19: =SUM(D19:E19) -> 297680.88 | H19: 1 | J19: LIJAS | K19: =I19*H19 -> 0 | V19: NETO | W19: =SUM(W11:W18) -> 472940 | Y19: =SUM(Y11:Y16)+SUM(W17:W18) -> 484940
C20: ADHESIVO | D20: ='2229'!O57 -> 158372 | E20: =D20*0.19 -> 30090.681 | F20: =SUM(D20:E20) -> 188462.68 | H20: 1 | J20: CARTON | K20: =I20*H20 -> 0 | V20: I.V.A. | W20: =W19*19% -> 89858.6 | Y20: =Y19*0.19 -> 92138.6
A21: =450000*1.2 -> 540000 | C21: TOTAL | D21: =SUM(D18:D20) -> 408524 | E21: =SUM(E18:E20) -> 77619.561 | F21: =SUM(F18:F20) -> 486143.56 | H21: 1 | J21: GUAIPE | K21: =I21*H21 -> 0 | M21: =B32/9 -> 2318.8406 | Q21: PLAZO DE ENTREGA : 8 DIAS HABILES | V21: TOTAL | W21: =W19+W20 -> 562798.6 | Y21: =SUM(Y19:Y20) -> 577078.6
A22: =450000*1.2 -> 540000 | B22: M. DE OBRA | C22: PROCESO | D22: COSTO x Hr. | E22: Q Hrs. | F22: TOTAL | H22: 1 | J22: DILUYENTE | K22: =I22*H22 -> 0 | Q22: FORMA DE PAGO: 50% CONTADO, SALDO C/E
A23: =800000*1.2 -> 960000 | B23: =A21/23 -> 23478.261 | C23: CORTE | D23: =B23/9 -> 2608.6957 | E23: 0.5 | F23: =D23*E23 -> 1304.3478 | H23: 1 | J23: CINTA EMBALAJE | K23: =I23*H23 -> 0 | Q23: VALIDEZ COTIZACIÓN: 5 DIAS
A24: 450000 | B24: =A22/23 -> 23478.261 | C24: CORTE LAMINA | D24: =B24/9 -> 2608.6957 | E24: 0.5 | F24: =D24*E24 -> 1304.3478 | H24: Q/HRS | I24: PRECIO | J24: MANO DE OBRA INDIRECTA | K24: VALOR | L24: =SUM(K25:K35) -> 0
A25: 450000 | B25: =A23/23 -> 41739.13 | C25: REBAJE LAMINA | D25: =B25/9 -> 4637.6812 | F25: =D25*E25 -> 0 | H25: 0 | I25: =((480000/23)/9) -> 2318.8406 | J25: FLETERO (HRS) | K25: =H25*I25 -> 0
B26: =A24/23 -> 19565.217 | C26: TUPIZADO | D26: =B26/9 -> 2173.913 | E26: 0.5 | F26: =D26*E26 -> 1086.9565 | H26: 0 | J26: BENCINA | K26: =H26*I26 -> 0
A27: 350000 | B27: =A25/23 -> 19565.217 | C27: ARMADO | D27: =B27/9 -> 2173.913 | E27: 0.5 | F27: =D27*E27 -> 1086.9565 | H27: 0 | J27: TAG | K27: =H27*I27 -> 0
A28: 500000 | B28: =A27/23 -> 15217.391 | C28: PEGADO | D28: =B28/9 -> 1690.8213 | E28: 0.7 | F28: =D28*E28 -> 1183.5749 | H28: 0 | J28: RECTIFICACION | K28: =H28*I28 -> 0
B29: =A28/23 -> 21739.13 | C29: POSTFORMADO | D29: =B29/9 -> 2415.4589 | E29: 0.7 | F29: =D29*E29 -> 1690.8213 | H29: 0 | I29: =((550000*1.2)/23)/9 -> 3188.4058 | J29: HR. TRAB. JUAN | K29: =H29*I29 -> 0
A30: 450000 | C30: MEDIA CAÑA | D30: 2415 | F30: =D30*E30 -> 0 | H30: 0 | I30: =((450000*1.2)/23)/9 -> 2608.6957 | J30: HR. TRAB. JULIO | K30: =H30*I30 -> 0
A31: 350000 | B31: =A30/23 -> 19565.217 | C31: CORTE-ENCHAPE | D31: =B31/9 -> 2173.913 | E31: 0 | F31: =D31*E31 -> 0 | H31: 0 | I31: =((450000*1.2)/23)/9 -> 2608.6957 | J31: HR. TRAB. EUGE | K31: =H31*I31 -> 0
A32: =A21+A24+A27+A28+A30 -> 2290000 | B32: =480000/23 -> 20869.565 | C32: CONTROL CALIDAD | D32: =B32/9 -> 2318.8406 | E32: 0.5 | F32: =D32*E32 -> 1159.4203 | H32: 0 | J32: COLACION | K32: =H32*I32 -> 0
C33: TOTAL | D33: =SUM(D23:D32) -> 25216.932 | E33: =SUM(E23:E32) -> 3.9 | F33: =SUM(F23:F32) -> 8816.4251 | H33: 0 | J33: BONO | K33: =H33*I33 -> 0
B34: CIF | C34: M. PRIMA INDIREC. | D34: =L9 -> 2550 | H34: 1 | J34: PERFORACION | K34: =H34*I34 -> 0
C35: M. OBRA INDIRECTA | D35: =L24 -> 0 | H35: 6 | J35: CORTE 45 | K35: =H35*I35 -> 0
C36: GASTOS DE FABRICA | D36: =L36 -> 18467.666 | H36: CANTIDAD | I36: PRECIO | J36: GASTOS DE FABRICACION | K36: VALOR | L36: =SUM(K37:K39) -> 18467.666
C37: DEPRECIACIONES | H37: =$E$33 -> 3.9 | I37: =32609.69/9 -> 3623.2989 | J37: ARRIENDO x HORA | K37: =I37*H37 -> 14130.866
C38: TOTAL | D38: =SUM(D34:D37) -> 21017.666 | H38: =$E$33 -> 3.9 | I38: 967 | J38: AGUA x HORA | K38: =I38*H38 -> 3771.3
H39: =$E$33 -> 3.9 | I39: 145 | J39: LUZ x HORA | K39: =I39*H39 -> 565.5
B40: PROVISIONAR | C40: IVA | D40: =E11-E21 -> 287950.13
H41: ESTADO DE RESULTADOS
B42: TOTAL HRS TRABAJADAS | D42: =E33 -> 3.9 | H42: INGRESOS | I42: + TOTAL VENTA | M42: =D11 -> 1924051
H43: COSTOS | I43: - MATERIA PRIMA DIRECTA | M43: =D21 -> 408524
...

Sheet NOTA DE VENTA
F2: MUEBLES SANTA FE SPA
F3: VENTAS POR MENOR DE MUEBLES
F4: RUT: 77.054.606-0
F5: SEPTIMA AVENIDA 1631, SAN MIGUEL
F6: CELULAR: 963868755
F7: E-MAIL: fdonoso@topmobili.cl
B8: P R E S U P U E S T O | D8: ='2229'!D8 -> N° 12056 | F8: NOTA DE VENTA :
B10: CLIENTE: | C10: =IF('2229'!C10="","",'2229'!C10) -> MUEBLERIA VALENTINA | F10: FECHA : | G10: ='2229'!G10 -> 46118
B11: RUT: | C11: =IF('2229'!C11="","",'2229'!C11) | F11: FECHA LIMITE : | G11: =WORKDAY(G10,5) -> 46125
B12: GIRO: | C12: =IF('2229'!C12="","",'2229'!C12) | F12: DESPACHO: | G12: ='2229'!G14 -> NO
B13: CONTACTO: | C13: =IF('2229'!C13="","",'2229'!C13) -> SAMI | F13: ORDEN DE COMPRA:
B14: CORREO: | C14: =IF('2229'!C14="","",'2229'!C14) | F14: HECHO POR: | G14: FERNANDO DONOSO
B15: FONO: | C15: =IF('2229'!C15="","",'2229'!C15) -> +569 7220 1095 | F15: SERVICIO EXPRESS: | G15: ='2229'!G12 -> NO
B16: DIRECCION: | C16: =IF('2229'!C16="","",'2229'!C16) | F16: FORMA DE PAGO : | G16: ='2229'!G16 -> ABONO 50% SALDO C/ENTREGA
B17: CIUDAD: | C17: =IF('2229'!C17="","",'2229'!C17) -> RANCAGUA | F17: VALIDEZ COTIZACIÓN: 5 DÍAS
B20: D E T A L L E
B21: UNIDAD | C21: TIPO | D21: LARGO | E21: ANCHO | F21: COLOR | G21: VALOR | H21: TOTAL
B22: ='2229'!B21 -> 2 | C22: CUB C/R R8 | D22: ='2229'!D21*1000 -> 500 | E22: ='2229'!E21*1000 -> 480 | F22: ='2229'!F21 -> NEUTRAL OAK 1498 MT | G22: ='2229'!G21 -> 35395 | H22: =G22*B22 -> 70790
G25: NETO | H25: =SUM(H22:H24) -> 70790
G26: I.V.A. | H26: =H25*19% -> 13450.1
G27: TOTAL | H27: =H25+H26 -> 84240.1
B30: CUENTA VISTA DEL BANCO ESTADO N° 35571389078 A NOMBRE DE
B31: "MUEBLES SANTA FE SPA." - RUT : 77.054.606-0, VENTAS@TOPMOBILI.CL
B32: VISITANOS Y DESCUBRE NUESTROS PRODUCTOS EN | E32: WWW.TOPMOBILICHILE.CL

Sheet REGLAS
B2: DETALLE CORTE LAMINA | G2: DETALLE CORTE SUSTRATO | P2: DETALLE CORTE MERA
B3: ALTO | C3: ANCHO | D3: TIPO | G3: ALTO | H3: ANCHO | I3: TIPO | P3: ALTO | Q3: ANCHO | R3: TIPO
B4: 40 | C4: 60 | D4: CEN 1V | E4: A1 | G4: 50 | H4: 100 | I4: CEN 1V | J4: REGLA SIEMPRE LLEVAR MEDIDA MINIMO A 100 | P4: 50 | Q4: -30 | R4: CUB C/R
B5: 40 | C5: 90 | D5: CEN 2V | E5: A2 | G5: 50 | I5: CEN 2V | J5: REGLA SIEMPRE LLEVAR MEDIDA MINIMO A 101 | P5: 50 | Q5: -30 | R5: CUB C/R
B6: 40 | C6: 100 | D6: CORNISA FRENTE ESPAÑOL 1 LADO | E6: A3 | G6: 50 | H6: 100 | I6: CORNISA FRENTE ESPAÑOL 1 LADO | P6: 50 | Q6: -30 | R6: CUB C/R 180°
B7: 40 | C7: 150 | D7: CORNISA FRENTE ESPAÑOL 2 LADO | E7: A4 | G7: 50 | I7: CORNISA FRENTE ESPAÑOL 2 LADO | P7: 50 | Q7: -30 | R7: CUB C/R FRENTE ESPAÑOL
B8: 40 | C8: 100 | D8: CORNISA 180° 1LADO | E8: A5 | G8: 50 | H8: 100 | I8: CORNISA 180° 1LADO | L8: DETALLE CORTE MERA | P8: 50 | Q8: -30 | R8: CUB C/R PUNTA 1 LADO
B9: 40 | C9: 50 | D9: CORNISA PUNTA TIBURON 1 LADO | E9: B | G9: 50 | H9: 100 | I9: CORNISA 1LADO | L9: ALTO | M9: ANCHO | N9: TIPO | P9: 50 | Q9: 0 | R9: CUB S/R FRENTE ESPAÑOL
B10: 40 | C10: 80 | D10: CORNISA PUNTA TIBURON 2 LADOS | E10: C | G10: 50 | I10: CORNISA 2 LADOS | L10: 50 | M10: -30 | N10: CUB C/R | P10: 50 | Q10: 0 | R10: CUB S/R
B11: 40 | C11: 60 | D11: CORNISA R8 1LADO | E11: D | G11: 50 | H11: 100 | I11: CORNISA PUNTA TIBURON 1 LADO | L11: 50 | M11: 0 | N11: CUB S/R y CUB MESA | P11: 50 | Q11: 0 | R11: CUB MESA 180° 2 LADOS
B12: 40 | C12: 100 | D12: CORNISA R8 2 LADOS | E12: E | G12: 50 | I12: CORNISA PUNTA TIBURON 2 LADOS | L12: 50 | M12: -2 | N12: PR | P12: 50 | Q12: 0 | R12: CUB MESA 180° 3 LADOS
B13: 40 | C13: 130 | D13: CUB C/R R6 | E13: F | G13: 50 | H13: -30 | I13: CUB C/R | P13: 50 | Q13: 0 | R13: CUB MESA 180° 4 LADOS
B14: 40 | C14: 150 | D14: CUB C/R 180° | G14: 50 | H14: -30 | I14: CUB C/R 180°
B15: 40 | C15: 150 | D15: CUB C/R FRENTE ESPAÑOL | E15: G | G15: 50 | H15: -30 | I15: CUB C/R FRENTE ESPAÑOL | P15: 50 | Q15: 0 | R15: CUB MESA 4 LADOS
B16: 40 | C16: 130 | D16: CUB C/R R2 | E16: H | G16: 50 | H16: -30 | I16: CUB C/R PUNTA TIBURON 1 LADO | P16: 50 | Q16: 0 | R16: CUB MESA FRENTE ESPAÑOL 2 LADOS
B17: 40 | C17: 150 | D17: CUB MESA 180° 2 LADOS | E17: I | G17: 50 | I17: CUB MESA 180° 2 LADOS | P17: 50 | Q17: 0 | R17: CUB MESA FRENTE ESPAÑOL 3 LADOS
B18: 140 | C18: 150 | D18: CUB MESA 180° 3 LADOS | E18: J | G18: 50 | I18: CUB MESA 180° 3 LADOS | P18: 50 | Q18: 0 | R18: CUB MESA FRENTE ESPAÑOL 4 LADOS
B19: 150 | C19: 150 | D19: CUB MESA 180° 4 LADOS | E19: K | G19: 50 | I19: CUB MESA 180° 4 LADOS | P19: 50 | Q19: 0 | R19: CUB MESA PUNTA TIBURON 2 LADOS
B20: 40 | C20: 100 | D20: CUB MESA 2L | E20: L | G20: 50 | H20: 0 | I20: CUB MESA 2L | J20: ES IGUAL A LO PEDIDO NO SE DEBE SUMAR NI RESTAR | P20: 50 | Q20: 0 | R20: CUB MESA PUNTA TIBURON 3 LADOS
B21: 100 | C21: 100 | D21: CUB MESA 3L | E21: M | G21: 50 | H21: 0 | I21: CUB MESA 3L | P21: 50 | Q21: 0 | R21: CUB MESA PUNTA TIBURON 4 LADOS
B22: 100 | C22: 100 | D22: CUB MESA 4 LADOS | E22: N | I22: CUB MESA 4 LADOS | P22: 50 | Q22: 0 | R22: CUB PUNTA TIBURON 1 LADO
B23: 40 | C23: 150 | D23: CUB MESA FRENTE ESPAÑOL 2 LADOS | E23: O | G23: 50 | I23: CUB MESA FRENTE ESPAÑOL 2 LADOS | R23: CENEFA 1 LADO
B24: 140 | C24: 150 | D24: CUB MESA FRENTE ESPAÑOL 3 LADOS | E24: P | G24: 50 | I24: CUB MESA FRENTE ESPAÑOL 3 LADOS | R24: CENEFA 2 LADOS
B25: 150 | C25: 150 | D25: CUB MESA FRENTE ESPAÑOL 4 LADOS | E25: Q | G25: 50 | I25: CUB MESA FRENTE ESPAÑOL 4 LADOS | R25: CORNISA FRENTE ESPAÑOL 1 LADO
B26: 40 | C26: 77 | D26: CUB MESA PUNTA TIBURON 2 LADOS | E26: R | G26: 50 | I26: CUB MESA PUNTA TIBURON 2 LADOS | R26: CORNISA FRENTE ESPAÑOL 2 LADO
B27: 110 | C27: 77 | D27: CUB MESA PUNTA TIBURON 3 LADOS | E27: S | G27: 50 | I27: CUB MESA PUNTA TIBURON 3 LADOS | R27: CORNISA 180° 1LADO
B28: 120 | C28: 77 | D28: CUB MESA PUNTA TIBURON 4 LADOS | E28: T | G28: 50 | I28: CUB MESA PUNTA TIBURON 4 LADOS | R28: CORNISA 1LADO
B29: 40 | C29: 50 | D29: CUB PUNTA TIBURON 1 LADO | E29: U | G29: 50 | I29: CUB PUNTA TIBURON 1 LADO | R29: CORNISA 2 LADOS
B30: 40 | C30: 60 | D30: CUB S/R | E30: V | G30: 50 | I30: CUB S/R | R30: CORNISA PUNTA TIBURON 1 LADO
B31: 40 | C31: 100 | D31: CUB S/R FRENTE ESPAÑOL | E31: W | G31: 50 | I31: CUB S/R FRENTE ESPAÑOL | R31: CORNISA PUNTA TIBURON 2 LADOS
B32: 40 | C32: 60 | D32: CUB S/R R2 | E32: X | G32: 50 | I32: CUB S/R R2 | R32: PR2
B33: 40 | C33: 90 | D33: PR12 | E33: Y | G33: 50 | H33: -2 | I33: PR12 | R33: PR6
B34: 40 | C34: 90 | D34: PR19 | G34: 50 | H34: -2 | I34: PR19
B35: 40 | C35: 90 | D35: PR2 | E35: Z | G35: 50 | H35: -2 | I35: PR2 | R35: PR8
B36: 40 | C36: 90 | D36: PR6 | G36: 50 | H36: -2 | I36: PR6 | R36: PR12
B37: 40 | C37: 90 | D37: PR8 | G37: 50 | H37: -2 | I37: PR8 | R37: PR19
B48: 40 | C48: 150

Sheet PRODUCCION
K2: NO BORRAR REGLAS!!!!! SI NO LAS SABEN USAR NO BORREN ESTO POR FAVOR!!!!!
K3: SUSTRATO | M3: LAMINADO
C4: NOTA DE VENTA : | D4: =IF('NOTA DE VENTA'!$G$8="","",'NOTA DE VENTA'!$G$8) | K4: ALTO | L4: ANCHO | M4: ALTO | N4: ANCHO
C5: CLIENTE : | D5: ='NOTA DE VENTA'!$C$10 -> MUEBLERIA VALENTINA | K5: =LOOKUP(F14,REGLAS!$I$4:$I$37,REGLAS!$G$4:$G$37)+J14 -> 2070 | L5: =LOOKUP(F14,REGLAS!$I$4:$I$37,REGLAS!$H$4:$H$37)+K14 -> 450 | M5: =LOOKUP(F14,REGLAS!$D$4:$D$37,REGLAS!$B$4:$B$37)+J21 -> 2060 | N5: =H10 -> 0
C7: ='NOTA DE VENTA'!$F$10 -> FECHA : | D7: ='NOTA DE VENTA'!$G$10 -> 46118
C8: FECHA ENTREGA: | D8: ='NOTA DE VENTA'!$G$11 -> 46125
A10: SUSTRATO
D12: ALTO | E12: ANCHO
A13: MATERIAL | B13: CANTIDAD | C13: CORTE | D13: 80 | E13: -30 | F13: DESCRIPCIÓN | J13: ALTO | K13: ANCHO
A14: MDF 18MM | B14: =I14 -> 1 | D14: =LOOKUP(F14,REGLAS!$I$4:$I$37,REGLAS!$G$4:$G$37)+J14 -> 2070 | E14: =LOOKUP(F14,REGLAS!$I$4:$I$37,REGLAS!$H$4:$H$37)+K14 -> 450 | F14: =C27 -> CUB C/R R8 | I14: =I21 -> 1 | J14: =D27 -> 2020 | K14: =E27 -> 480
A17: LAMINADO
D19: ALTO | E19: ANCHO
A20: MATERIAL | B20: CANTIDAD | C20: CORTE | D20: 40 | E20: 130 | F20: DESCRIPCIÓN | J20: ALTO | K20: ANCHO
A21: MDF 18MM | B21: =I21 -> 1 | D21: =LOOKUP(F14,REGLAS!$D$4:$D$37,REGLAS!$B$4:$B$37)+J21 -> 2060 | E21: =LOOKUP(F14,REGLAS!$D$4:$D$37,REGLAS!$C$4:$C$37)+K21 -> 610 | F21: =C27 -> CUB C/R R8 | I21: =B27 -> 1 | J21: =D27 -> 2020 | K21: =E27 -> 480
B24: MEDIDAS ORIGINALES
A26: MATERIAL | B26: CANTIDAD | C26: DESCRIPCIÓN | D26: ALTO | E26: ANCHO | F26: COLOR
A27: MDF 18MM | B27: ='[1]4637'!B21 -> 1 | C27: =C49 -> CUB C/R R8 | D27: =D49 -> 2020 | E27: =E49 -> 480 | F27: =F49 -> NEUTRAL OAK 1498 MT
C39: NOTA DE VENTA : | D39: ='[1]4637'!G8 -> 7332
C40: CLIENTE : | D40: ='[1]4637'!C10 -> FMR MAKING SPA
C42: ='[1]4637'!F11 -> FECHA LIMITE : | D42: ='[1]4637'!G11 -> 45996
A45: PRODUCCIÓN
B47: DETALLE
B48: CANTIDAD | C48: CORTE | D48: ALTO | E48: ANCHO | F48: DESCRIPCION
A49: MDF18MM | B49: ='[1]4637'!B21 -> 1 | C49: ='NOTA DE VENTA'!$C22 -> CUB C/R R8 | D49: 2020 | E49: ='NOTA DE VENTA'!E22 -> 480 | F49: ='NOTA DE VENTA'!F22 -> NEUTRAL OAK 1498 MT

Sheet SEGUIMIENTO
A1: NV | B1: N° COTIZA | C1: FECHA | D1: ENTREGA | E1: NOMBRE | F1: DETALLE | G1: COLOR | H1: NETO | I1: IVA | J1: TOTAL | K1: ABONO | L1: SALDO | M1: ESTADO
A2: ='NOTA DE VENTA'!$G$8 -> 0 | B2: ='NOTA DE VENTA'!$D$8 -> N° 12056 | C2: ='NOTA DE VENTA'!$G$10 -> 46118 | D2: ='NOTA DE VENTA'!$G$11 -> 46125 | E2: ='NOTA DE VENTA'!$C$10 -> MUEBLERIA VALENTINA | F2: ='NOTA DE VENTA'!$C$22 -> CUB C/R R8 | G2: ='NOTA DE VENTA'!$F$22 -> NEUTRAL OAK 1498 MT | H2: ='NOTA DE VENTA'!$H$25 -> 70790 | I2: =H2*0.19 -> 13450.1 | J2: =I2+H2 -> 84240.1 | L2: =J2-K2 -> 84240.1
