Workbook

Sheet 2229
G2: MUEBLES SANTA FE SPA
G3: VENTAS POR MENOR DE MUEBLES
G4: RUT: 77.054.606-0
G5: SEPTIMA AVENIDA 1631, SAN MIGUEL
G6: FONO +569 2032 3382 | P6: 10077 SF PORTLAND MAPLE
G7: E-MAIL: ventas@topmobili.cl
B8: P R E S U P U E S T O | D8: N° 12061
B10: NOMBRE: | C10: MUEBLES ASENJO | G10: FECHA: | H10: 46105
B11: RUT: | G11: PLAZO ENTREGA: | H11: URGENTE | S11: MT2 PUERTAS
B12: GIRO: | G12: SERVICIO EXPRESS | H12: NO
B13: CONTACTO: | C13: MIGUEL ASENJO | G13: ORDEN DE COMPRA
B14: CORREO: | G14: CORTADA A LA MEDIDA | H14: NO | S14: ML CUBIERTAS
B15: FONO: | G15: DESPACHO: | H15: SI
B16: DIRECCION: | G16: FORMA DE PAGO: | H16: ABONO 50% SALDO C/ENTREGA
B17: CIUDAD: | C17: SANTIAGO | G17: DURACION COTIZACION: 5 DIAS FRANCO DONOSO
B19: DETALLE | N19: 0.08 | Q19: TOTAL | R19: VALOR X MT2 | S19: ENCHAPE | T19: MT/L
B20: UNIDAD | C20: TIPO | D20: LARGO | E20: ANCHO | F20: N/V | G20: COLOR | H20: VALOR | I20: TOTAL | M20: =B20 -> UNIDAD | N20: ALTO | O20: =E20 -> ANCHO | P20: MT | Q20: MT2 | R20: =P42 -> 57309.942 | S20: 3000 | U20: m/l
B21: 1 | C21: CUB C/R 90° R8 | D21: 3 | E21: 0.71 | F21: 28212 | G21: GLACIAL WHITE 22191 SF | H21: 125325 | I21: =H21*B21 -> 125325 | M21: =B21 -> 1 | N21: =D21+N$19 -> 3.08 | O21: =E21+$O$19 -> 0.71 | P21: =N21*O21 -> 2.1868 | Q21: =P21*M21 -> 2.1868 | R21: =R$20*P21 -> 125325.38 | S21: =R21+S$20 -> 128325.38 | T21: =M21*N21 -> 3.08
B22: 1 | C22: CUB C/R 90° R8 | D22: 1 | E22: 0.71 | F22: 28212 | G22: GLACIAL WHITE 22191 SF | H22: 43945 | I22: =H22*B22 -> 43945 | M22: =B22 -> 1 | N22: =D22+N$19 -> 1.08 | O22: =E22+$O$19 -> 0.71 | P22: =N22*O22 -> 0.7668 | Q22: =P22*M22 -> 0.7668 | R22: =R$20*P22 -> 43945.264 | S22: =R22+S$20 -> 46945.264 | T22: =M22*N22 -> 1.08
B23: 1 | C23: CUB S/R R8 | D23: 3.5 | E23: 0.5 | F23: 28212 | G23: GLACIAL WHITE 22191 SF | H23: 102585 | I23: =H23*B23 -> 102585 | M23: =B23 -> 1 | N23: =D23+N$19 -> 3.58 | O23: =E23+$O$19 -> 0.5 | P23: =N23*O23 -> 1.79 | Q23: =P23*M23 -> 1.79 | R23: =R$20*P23 -> 102584.8 | S23: =R23+S$20 -> 105584.8
B24: 1 | C24: CUB C/R 90° R8 | D24: 2.1 | E24: 0.6 | F24: 28211 | G24: GLACIAL WHITE 22191 SF | H24: 74961 | I24: =H24*B24 -> 74961 | M24: =B24 -> 1 | N24: =D24+N$19 -> 2.18 | O24: =E24+$O$19 -> 0.6 | P24: =N24*O24 -> 1.308 | Q24: =P24*M24 -> 1.308 | R24: =R$20*P24 -> 74961.405 | S24: =R24+S$20 -> 77961.405 | T24: =M24*N24 -> 2.18
B25: 1 | C25: CUB C/R 90° R8 | D25: 2.25 | E25: 0.6 | F25: 28294 | G25: GLACIAL WHITE 22191 SF | H25: 80119 | I25: =H25*B25 -> 80119 | M25: =B25 -> 1 | N25: =D25+N$19 -> 2.33 | O25: =E25+$O$19 -> 0.6 | P25: =N25*O25 -> 1.398 | Q25: =P25*M25 -> 1.398 | R25: =R$20*P25 -> 80119.3 | S25: =R25+S$20 -> 83119.3 | T25: =M25*N25 -> 2.33
B26: 1 | C26: CUB C/R 90° R8 | D26: 2.8 | E26: 0.6 | F26: 28294 | G26: GLACIAL WHITE 22191 SF | H26: 99032 | I26: =H26*B26 -> 99032 | M26: =B26 -> 1 | N26: =D26+N$19 -> 2.88 | O26: =E26+$O$19 -> 0.6 | P26: =N26*O26 -> 1.728 | Q26: =P26*M26 -> 1.728 | R26: =R$20*P26 -> 99031.581 | S26: =R26+S$20 -> 102031.58 | T26: =M26*N26 -> 2.88
I28: =SUM(I21:I27) -> 525967 | U28: =SUM(U21:U26) -> 0
H29: IVA | I29: =I28*19% -> 99933.73 | N29: =SUM(N21:N28) -> 15.13 | Q29: =SUM(Q21:Q26) -> 9.1776
H30: TOTAL | I30: =I28+I29 -> 625900.73 | Q30: =Q29 -> 9.1776 | T30: =SUM(T21:T29) -> 11.55
Q31: =Q30*20% -> 1.83552 | R31: 20% PERDIDA | T31: =T30+U28 -> 11.55
Q32: =Q30+Q31 -> 11.01312 | T32: =T31*20% -> 2.31
T33: =T31+T32 -> 13.86 | V33: ADHESIVO | W33: 58.000.- | X33: 44971
N34: =Q32 -> 11.01312 | O34: 2000 | P34: =N34*O34 -> 22026.24 | Q34: ADHESIVO | V34: LATA 16 LTS | W34: 3625 | X34: LITRO
N35: 3 | O35: 23500 | P35: =N35*O35 -> 70500 | Q35: MDF 18MM | W35: 906.25 | X35: MT2 (4)
B36: CUENTA CORRIENTE BANCO SANTANDER Nº 87316181 A NOMBRE DE MUEBLES SANTA FE SPA | L36: 1220 | O36: 45146 | P36: =N36*O36 -> 0 | Q36: LAMINA 153 X 366 | W36: =W35*20% -> 181.25 | X36: PERDIDA 20%
B37: RUT : 77.054.606-0 VENTAS@TOPMOBILI.CL | K37: 32859 | L37: 230 | N37: 6 | O37: 22500 | P37: =N37*O37 -> 135000 | Q37: LAMINA 122X306 | W37: =W35+W36 -> 1087.5 | X37: MINIMO A COTIZAR
B38: VISITANOS Y DESCUBRE NUESTROS PRODUCTOS EN | G38: WWW.TOPMOBILICHILE.CL | L38: =L36/L37 -> 5.3043478 | O38: 15700 | P38: =N38*O38 -> 0 | Q38: RESPALDO | S38: 1.83
L39: =#REF!/L38 -> #REF! | N39: 11.55 | O39: 1000 | P39: =N39*O39 -> 11550 | Q39: MEDIA CAÑA | S39: 2.5
P40: =SUM(P34:P39) -> 239076.24 | Q40: COSTO | S40: =S38*S39 -> 4.575
N41: PRECIO VENTA | P41: =P40*2.2 -> 525967.73 | Q41: FACTOR 2,3 PARA 90° | S41: =Q32/S40 -> 2.4072393
K42: 22475 | L42: 40000 | P42: =P41/Q30 -> 57309.942 | Q42: VALOR M2 | V42: MDF30MM | W42: 43650
K43: 6 | L43: =L42/1.19 -> 33613.445 | P43: =P41/P40 -> 2.2 | V43: 46 UNIDADES | W43: 948.91 | X43: 2.4
K44: =K42*K43 -> 134850 | V44: METRO LINEAL | W44: 395.37
...

Sheet COSTOS
B2: CENTRO DE COSTOS POSTFORMADOS
B5: FECHA: | C5: ='2229'!H10 -> 46105
B6: CLIENTE: | C6: ='2229'!C10 -> MUEBLES ASENJO | N6: Ventas Equilibrio = | P6: Costos Fijos Totales
B7: DIRECCION: | C7: ='2229'!#REF! -> #REF! | H7: COSTOS INDIRECTOS DE FABRICA VARIABLES | O7: 1 - | P7: Costos Variables Totales
B8: PRESUPUESTO: | C8: ='2229'!D8 -> N° 12061 | H8: Q/HRS | I8: $ | J8: DETALLE | K8: TOTAL | L8: TOTAL | P8: Total Venta | X8: =SUM(Q11:Q16) -> 6
H9: CANTIDAD | I9: PRECIO | J9: MATERIA PRIMA INDIRECTA | L9: =SUM(K10:K24) -> 2550 | S9: DETALLE | X9: =(E15-D11)/X8 -> #REF!
D10: NETO | E10: IVA | F10: TOTAL | H10: 3 | I10: 350 | J10: RESPALDO | K10: =I10*H10 -> 1050 | Q10: UNIDAD | R10: TIPO | S10: LARGO | T10: ANCHO | U10: COLOR | V10: VALOR | W10: TOTAL
C11: MONTO A COBRAR | D11: ='2229'!#REF! -> #REF! | E11: =D11*0.19 -> #REF! | F11: =E11+D11 -> #REF! | H11: 3 | I11: 500 | J11: MEDIA CAÑA | K11: =I11*H11 -> 1500 | Q11: 1 | R11: CUB C/R R8 | S11: 2.8 | T11: 0.62 | U11: MADERA X DEFINIR | V11: 105990 | W11: =V11*Q11 -> 105990 | X11: =V11+$X$9 -> #REF! | Y11: 108990
C12: COSTO TOTAL | D12: =SUM(M44:M46) -> 257360.33 | H12: 0 | I12: 7500 | J12: DUROLAC | K12: =I12*H12 -> 0 | Q12: 1 | R12: CUB C/R R8 | S12: 2.3 | T12: 0.62 | U12: MADERA X DEFINIR | V12: 87990 | W12: =V12*Q12 -> 87990 | X12: =V12+$X$9 -> #REF! | Y12: 89990
C13: % UTILIDAD | D13: =D11-D12 -> #REF! | E13: =(D11/D12)-1 -> #REF! | H13: 0 | I13: 50 | J13: TAPACANTO PVC | K13: =I13*H13 -> 0 | Q13: 1 | R13: CUB C/R R8 | S13: 2.03 | T13: 0.62 | U13: MADERA X DEFINIR | V13: 78990 | W13: =V13*Q13 -> 78990 | X13: =V13+$X$9 -> #REF! | Y13: 81990
D14: % utilidad | E14: NETO | F14: UTILIDAD | H14: 0 | I14: 50 | J14: SOBERBIOS | K14: =I14*H14 -> 0 | Q14: 1 | R14: CUB C/R R8 | S14: 1.08 | T14: 0.62 | U14: MADERA X DEFINIR | V14: 39990 | W14: =V14*Q14 -> 39990 | X14: =V14+$X$9 -> #REF! | Y14: 39990
C15: PROYECCION | D15: 0.65 | E15: =(100%+D15)*D12 -> 424644.55 | F15: =E15-D12 -> 167284.22 | H15: 0 | I15: 10 | J15: SOPORTE REPISA | K15: =I15*H15 -> 0 | Q15: 1 | R15: CUB C/R R8 | S15: 1.08 | T15: 0.62 | U15: MADERA X DEFINIR | V15: 39990 | W15: =V15*Q15 -> 39990 | X15: =V15+$X$9 -> #REF! | Y15: 39990
H16: 1 | J16: PUNTAS | K16: =I16*H16 -> 0 | Q16: 1 | R16: CUB C/R R8 | S16: 2.06 | T16: 0.62 | U16: MADERA X DEFINIR | V16: 79990 | W16: =V16*Q16 -> 79990 | X16: =V16+$X$9 -> #REF! | Y16: 83990
B17: M. PRIMA | C17: MATERIAL | D17: NETO | E17: IVA | F17: TOTAL | H17: 1 | J17: TORNILLOS | K17: =I17*H17 -> 0 | Q17: 6 | R17: CORTES 45° | V17: 5000 | W17: =V17*Q17 -> 30000
C18: LAMINA | D18: ='2229'!P36 -> 0 | E18: =D18*0.19 -> 0 | F18: =SUM(D18:E18) -> 0 | H18: 1 | J18: COLAFRIA | K18: =I18*H18 -> 0 | Q18: 1 | R18: PERFORACION LAVAPLATOS | V18: 10000 | W18: =V18*Q18 -> 10000
C19: LAMINA CHICA | D19: ='2229'!P37 -> 135000 | E19: =D19*0.19 -> 25650 | F19: =SUM(D19:E19) -> 160650
C20: MDF 18MM | D20: ='2229'!P35 -> 70500 | E20: =D20*0.19 -> 13395 | F20: =SUM(D20:E20) -> 83895 | H20: 1 | J20: LIJAS | K20: =I20*H20 -> 0 | V20: NETO | W20: =SUM(W11:W18) -> 472940 | Y20: =SUM(Y11:Y16)+SUM(W17:W18) -> 484940
C21: ADHESIVO | D21: ='2229'!P34 -> 22026.24 | E21: =D21*0.19 -> 4184.9856 | F21: =SUM(D21:E21) -> 26211.226 | H21: 1 | J21: CARTON | K21: =I21*H21 -> 0 | V21: I.V.A. | W21: =W20*19% -> 89858.6 | Y21: =Y20*0.19 -> 92138.6
A22: =450000*1.2 -> 540000 | C22: TOTAL | D22: =SUM(D18:D21) -> 227526.24 | E22: =SUM(E18:E21) -> 43229.986 | F22: =SUM(F18:F21) -> 270756.23 | H22: 1 | J22: GUAIPE | K22: =I22*H22 -> 0 | M22: =B33/9 -> 2318.8406 | Q22: PLAZO DE ENTREGA : 8 DIAS HABILES | V22: TOTAL | W22: =W20+W21 -> 562798.6 | Y22: =SUM(Y20:Y21) -> 577078.6
A23: =450000*1.2 -> 540000 | B23: M. DE OBRA | C23: PROCESO | D23: COSTO x Hr. | E23: Q Hrs. | F23: TOTAL | H23: 1 | J23: DILUYENTE | K23: =I23*H23 -> 0 | Q23: FORMA DE PAGO: 50% CONTADO, SALDO C/E
A24: =800000*1.2 -> 960000 | B24: =A22/23 -> 23478.261 | C24: CORTE | D24: =B24/9 -> 2608.6957 | E24: 0.5 | F24: =D24*E24 -> 1304.3478 | H24: 1 | J24: CINTA EMBALAJE | K24: =I24*H24 -> 0 | Q24: VALIDEZ COTIZACIÓN: 5 DIAS
A25: 450000 | B25: =A23/23 -> 23478.261 | C25: CORTE LAMINA | D25: =B25/9 -> 2608.6957 | E25: 0.5 | F25: =D25*E25 -> 1304.3478 | H25: Q/HRS | I25: PRECIO | J25: MANO DE OBRA INDIRECTA | K25: VALOR | L25: =SUM(K26:K36) -> 0
A26: 450000 | B26: =A24/23 -> 41739.13 | C26: REBAJE LAMINA | D26: =B26/9 -> 4637.6812 | F26: =D26*E26 -> 0 | H26: 0 | I26: =((480000/23)/9) -> 2318.8406 | J26: FLETERO (HRS) | K26: =H26*I26 -> 0
B27: =A25/23 -> 19565.217 | C27: TUPIZADO | D27: =B27/9 -> 2173.913 | E27: 0.5 | F27: =D27*E27 -> 1086.9565 | H27: 0 | J27: BENCINA | K27: =H27*I27 -> 0
A28: 350000 | B28: =A26/23 -> 19565.217 | C28: ARMADO | D28: =B28/9 -> 2173.913 | E28: 0.5 | F28: =D28*E28 -> 1086.9565 | H28: 0 | J28: TAG | K28: =H28*I28 -> 0
A29: 500000 | B29: =A28/23 -> 15217.391 | C29: PEGADO | D29: =B29/9 -> 1690.8213 | E29: 0.7 | F29: =D29*E29 -> 1183.5749 | H29: 0 | J29: RECTIFICACION | K29: =H29*I29 -> 0
B30: =A29/23 -> 21739.13 | C30: POSTFORMADO | D30: =B30/9 -> 2415.4589 | E30: 0.7 | F30: =D30*E30 -> 1690.8213 | H30: 0 | I30: =((550000*1.2)/23)/9 -> 3188.4058 | J30: HR. TRAB. JUAN | K30: =H30*I30 -> 0
A31: 450000 | C31: MEDIA CAÑA | D31: 2415 | F31: =D31*E31 -> 0 | H31: 0 | I31: =((450000*1.2)/23)/9 -> 2608.6957 | J31: HR. TRAB. JULIO | K31: =H31*I31 -> 0
A32: 350000 | B32: =A31/23 -> 19565.217 | C32: CORTE-ENCHAPE | D32: =B32/9 -> 2173.913 | E32: 0 | F32: =D32*E32 -> 0 | H32: 0 | I32: =((450000*1.2)/23)/9 -> 2608.6957 | J32: HR. TRAB. EUGE | K32: =H32*I32 -> 0
A33: =A22+A25+A28+A29+A31 -> 2290000 | B33: =480000/23 -> 20869.565 | C33: CONTROL CALIDAD | D33: =B33/9 -> 2318.8406 | E33: 0.5 | F33: =D33*E33 -> 1159.4203 | H33: 0 | J33: COLACION | K33: =H33*I33 -> 0
C34: TOTAL | D34: =SUM(D24:D33) -> 25216.932 | E34: =SUM(E24:E33) -> 3.9 | F34: =SUM(F24:F33) -> 8816.4251 | H34: 0 | J34: BONO | K34: =H34*I34 -> 0
B35: CIF | C35: M. PRIMA INDIREC. | D35: =L9 -> 2550 | H35: 1 | J35: PERFORACION | K35: =H35*I35 -> 0
C36: M. OBRA INDIRECTA | D36: =L25 -> 0 | H36: 6 | J36: CORTE 45 | K36: =H36*I36 -> 0
C37: GASTOS DE FABRICA | D37: =L37 -> 18467.666 | H37: CANTIDAD | I37: PRECIO | J37: GASTOS DE FABRICACION | K37: VALOR | L37: =SUM(K38:K40) -> 18467.666
C38: DEPRECIACIONES | H38: =$E$34 -> 3.9 | I38: =32609.69/9 -> 3623.2989 | J38: ARRIENDO x HORA | K38: =I38*H38 -> 14130.866
C39: TOTAL | D39: =SUM(D35:D38) -> 21017.666 | H39: =$E$34 -> 3.9 | I39: 967 | J39: AGUA x HORA | K39: =I39*H39 -> 3771.3
H40: =$E$34 -> 3.9 | I40: 145 | J40: LUZ x HORA | K40: =I40*H40 -> 565.5
B41: PROVISIONAR | C41: IVA | D41: =E11-E22 -> #REF!
H42: ESTADO DE RESULTADOS
B43: TOTAL HRS TRABAJADAS | D43: =E34 -> 3.9 | H43: INGRESOS | I43: + TOTAL VENTA | M43: =D11 -> #REF!
...
