Workbook

Sheet 4637
G2: MUEBLES SANTA FE SPA
G3: VENTAS POR MENOR DE MUEBLES
G4: RUT: 77.054.606-0
G5: SEPTIMA AVENIDA 1631, SAN MIGUEL
G6: FONO 22521 6502
G7: E-MAIL: ventas@topmobili.cl
B8: P R E S U P U E S T O | D8: N° 11758 | G8: NOTA DE VENTA : | H8: 7329
B10: CLIENTE: | C10: CONSTRUCTORA HALTRA | G10: FECHA : | H10: 45987
B11: RUT: | C11: 77.641.901-3 | G11: FECHA LIMITE : | H11: 45996
B12: GIRO: | C12: FABRICACION DE MUEBLES | G12: ORDEN DE COMPRA:
B13: CONTACTO: | C13: CRISTIAN SUAZO | G13: HECHO POR:
B14: CORREO: | G14: OBRA:
B15: FONO: | C15: +569 9230 4650 | G15: SERVICIO EXPRESS:
B16: DIRECCION: | G16: FORMA DE PAGO : | H16: CONTADO
B17: CIUDAD: | C17: SANTIAGO | G17: VALIDEZ COTIZACIÓN: 5 DÍAS
B20: D E T A L L E
B21: UNIDAD | C21: TIPO | D21: LARGO | E21: ANCHO | F21: CANTOS PVC | G21: COLOR | H21: VALOR | I21: TOTAL
B22: 3 | C22: E/R 2 CARAS MDF 30MM FRONTAL | D22: 1500 | E22: 800 | F22: 2L 1A | G22: SILVER LEGNO OAK 10879 SF | H22: 123982 | I22: =H22*B22 -> 371946
B23: 2 | C23: E/R 2 CARAS MDF 30MM FRONTAL | D23: 1500 | E23: 1100 | F23: 2L 1A | G23: SILVER LEGNO OAK 10879 SF
B24: 13 | C24: E/R 1 CARA MDF 30MM COSTADOS | D24: 750 | E24: 460 | F24: 1L | G24: SILVER LEGNO OAK 10879 SF | J24: 11
B25: 4 | C25: E/R 1 CARA MDF 30MM COSTADOS | D25: 700 | E25: 520 | F25: 1L | G25: SILVER LEGNO OAK 10879 SF
B26: 1 | C26: CUB FRENTE RECTO 2 LADOS | D26: 1430 | E26: 700 | F26: 2L | G26: FASHION GREY 21371 SF
B27: 1 | C27: CUB FRENTE RECTO 2 LADOS | D27: 1460 | E27: 700 | F27: 2L | G27: FASHION GREY 21371 SF
B28: 2 | C28: CUB FRENTE RECTO 2 LADOS | D28: 620 | E28: 500 | F28: 1A | G28: FASHION GREY 21371 SF
B29: 2 | C29: CUB FRENTE RECTO 2 LADOS | D29: 1280 | E29: 700 | F29: 2L | G29: FASHION GREY 21371 SF
B30: 1 | C30: CUB FRENTE RECTO 2 LADOS | D30: 1310 | E30: 700 | F30: 2L | G30: FASHION GREY 21371 SF
B31: 1 | C31: CUB FRENTE RECTO 2 LADOS | D31: 1860 | E31: 700 | F31: 2L | G31: FASHION GREY 21371 SF
B32: 2 | C32: CUB FRENTE RECTO 2 LADOS | D32: 1580 | E32: 700 | F32: 2L | G32: FASHION GREY 21371 SF
B33: 1 | C33: CUB FRENTE RECTO 2 LADOS | D33: 1670 | E33: 700 | F33: 2L | G33: FASHION GREY 21371 SF
B34: 1 | C34: E/R 1 CARA MDF 18MM FALDON | D34: 1430 | E34: 700 | G34: FASHION GREY 21371 SF
B35: 1 | C35: E/R 1 CARA MDF 18MM FALDON | D35: 1460 | E35: 700 | G35: FASHION GREY 21371 SF
B36: 2 | C36: E/R 1 CARA MDF 18MM FALDON | D36: 620 | E36: 350 | F36: 1L | G36: FASHION GREY 21371 SF
B37: 2 | C37: E/R 1 CARA MDF 18MM FALDON | D37: 1280 | E37: 700 | G37: FASHION GREY 21371 SF
B38: 1 | C38: E/R 1 CARA MDF 18MM FALDON | D38: 1310 | E38: 700 | G38: FASHION GREY 21371 SF
B39: 1 | C39: E/R 1 CARA MDF 18MM FALDON | D39: 1860 | E39: 700 | G39: FASHION GREY 21371 SF
B40: 2 | C40: E/R 1 CARA MDF 18MM FALDON | D40: 1580 | E40: 700 | G40: FASHION GREY 21371 SF
B41: 1 | C41: E/R 1 CARA MDF 18MM FALDON | D41: 1670 | E41: 700 | G41: FASHION GREY 21371 SF
B42: 9 | C42: PR6 | D42: 550 | E42: 398 | F42: FRENTES | G42: FASHION GREY 21371 SF
H46: NETO
H47: I.V.A.
...

Sheet REGLAS
B2: DETALLE CORTE LAMINA | G2: DETALLE CORTE SUSTRATO | P2: DETALLE CORTE MERA
B3: ALTO | C3: ANCHO | D3: TIPO | G3: ALTO | H3: ANCHO | I3: TIPO | P3: ALTO | Q3: ANCHO | R3: TIPO
B4: 40 | C4: 60 | D4: CEN 1V | E4: A1 | G4: 50 | H4: 100 | I4: CEN 1V | J4: REGLA SIEMPRE LLEVAR MEDIDA MINIMO A 100 | P4: 50 | Q4: -30 | R4: CUB C/R
B5: 40 | C5: 90 | D5: CEN 2V | E5: A2 | G5: 50 | I5: CEN 2V | J5: REGLA SIEMPRE LLEVAR MEDIDA MINIMO A 101 | P5: 50 | Q5: -30 | R5: CUB C/R
B6: 40 | C6: 100 | D6: CORNISA FRENTE ESPAÑOL 1 LADO | E6: A3 | G6: 50 | H6: 100 | I6: CORNISA FRENTE ESPAÑOL 1 LADO | P6: 50 | Q6: -30 | R6: CUB C/R 180°
B7: 40 | C7: 150 | D7: CORNISA FRENTE ESPAÑOL 2 LADO | E7: A4 | G7: 50 | I7: CORNISA FRENTE ESPAÑOL 2 LADO | P7: 50 | Q7: -30 | R7: CUB C/R FRENTE ESPAÑOL
B8: 40 | C8: 100 | D8: CORNISA 180° 1LADO | E8: A5 | G8: 50 | H8: 100 | I8: CORNISA 180° 1LADO | L8: DETALLE CORTE MERA | P8: 50 | Q8: -30 | R8: CUB C/R PUNTA 1 LADO
B9: 40 | C9: 50 | D9: CORNISA PUNTA TIBURON 1 LADO | E9: B | G9: 50 | H9: 100 | I9: CORNISA 1LADO | L9: ALTO | M9: ANCHO | N9: TIPO | P9: 50 | Q9: 0 | R9: CUB S/R FRENTE ESPAÑOL
B10: 40 | C10: 80 | D10: CORNISA PUNTA TIBURON 2 LADOS | E10: C | G10: 50 | I10: CORNISA 2 LADOS | L10: 50 | M10: -30 | N10: CUB C/R | P10: 50 | Q10: 0 | R10: CUB S/R
B11: 40 | C11: 60 | D11: CORNISA R8 1LADO | E11: D | G11: 50 | H11: 100 | I11: CORNISA PUNTA TIBURON 1 LADO | L11: 50 | M11: 0 | N11: CUB S/R y CUB MESA | P11: 50 | Q11: 0 | R11: CUB MESA 180° 2 LADOS
B12: 40 | C12: 100 | D12: CORNISA R8 2 LADOS | E12: E | G12: 50 | I12: CORNISA PUNTA TIBURON 2 LADOS | L12: 50 | M12: -2 | N12: PR | P12: 50 | Q12: 0 | R12: CUB MESA 180° 3 LADOS
B13: 40 | C13: 130 | D13: CUB C/R R6 | E13: F | G13: 50 | H13: -30 | I13: CUB C/R | P13: 50 | Q13: 0 | R13: CUB MESA 180° 4 LADOS
B14: 40 | C14: 150 | D14: CUB C/R 180° | G14: 50 | H14: -30 | I14: CUB C/R 180°
B15: 40 | C15: 150 | D15: CUB C/R FRENTE ESPAÑOL | E15: G | G15: 50 | H15: -30 | I15: CUB C/R FRENTE ESPAÑOL | P15: 50 | Q15: 0 | R15: CUB MESA 4 LADOS
B16: 40 | C16: 130 | D16: CUB C/R R2 | E16: H | G16: 50 | H16: -30 | I16: CUB C/R PUNTA TIBURON 1 LADO | P16: 50 | Q16: 0 | R16: CUB MESA FRENTE ESPAÑOL 2 LADOS
B17: 40 | C17: 150 | D17: CUB MESA 180° 2 LADOS | E17: I | G17: 50 | I17: CUB MESA 180° 2 LADOS | P17: 50 | Q17: 0 | R17: CUB MESA FRENTE ESPAÑOL 3 LADOS
B18: 140 | C18: 150 | D18: CUB MESA 180° 3 LADOS | E18: J | G18: 50 | I18: CUB MESA 180° 3 LADOS | P18: 50 | Q18: 0 | R18: CUB MESA FRENTE ESPAÑOL 4 LADOS
B19: 150 | C19: 150 | D19: CUB MESA 180° 4 LADOS | E19: K | G19: 50 | I19: CUB MESA 180° 4 LADOS | P19: 50 | Q19: 0 | R19: CUB MESA PUNTA TIBURON 2 LADOS
B20: 40 | C20: 100 | D20: CUB MESA 2L | E20: L | G20: 50 | H20: 0 | I20: CUB MESA 2L | J20: ES IGUAL A LO PEDIDO NO SE DEBE SUMAR NI RESTAR | P20: 50 | Q20: 0 | R20: CUB MESA PUNTA TIBURON 3 LADOS
B21: 100 | C21: 100 | D21: CUB MESA 3L | E21: M | G21: 50 | H21: 0 | I21: CUB MESA 3L | P21: 50 | Q21: 0 | R21: CUB MESA PUNTA TIBURON 4 LADOS
B22: 100 | C22: 100 | D22: CUB MESA 4 LADOS | E22: N | I22: CUB MESA 4 LADOS | P22: 50 | Q22: 0 | R22: CUB PUNTA TIBURON 1 LADO
B23: 40 | C23: 150 | D23: CUB MESA FRENTE ESPAÑOL 2 LADOS | E23: O | G23: 50 | I23: CUB MESA FRENTE ESPAÑOL 2 LADOS | R23: CENEFA 1 LADO
B24: 140 | C24: 150 | D24: CUB MESA FRENTE ESPAÑOL 3 LADOS | E24: P | G24: 50 | I24: CUB MESA FRENTE ESPAÑOL 3 LADOS | R24: CENEFA 2 LADOS
B25: 150 | C25: 150 | D25: CUB MESA FRENTE ESPAÑOL 4 LADOS | E25: Q | G25: 50 | I25: CUB MESA FRENTE ESPAÑOL 4 LADOS | R25: CORNISA FRENTE ESPAÑOL 1 LADO
B26: 40 | C26: 77 | D26: CUB MESA PUNTA TIBURON 2 LADOS | E26: R | G26: 50 | I26: CUB MESA PUNTA TIBURON 2 LADOS | R26: CORNISA FRENTE ESPAÑOL 2 LADO
B27: 110 | C27: 77 | D27: CUB MESA PUNTA TIBURON 3 LADOS | E27: S | G27: 50 | I27: CUB MESA PUNTA TIBURON 3 LADOS | R27: CORNISA 180° 1LADO
B28: 120 | C28: 77 | D28: CUB MESA PUNTA TIBURON 4 LADOS | E28: T | G28: 50 | I28: CUB MESA PUNTA TIBURON 4 LADOS | R28: CORNISA 1LADO
B29: 40 | C29: 50 | D29: CUB PUNTA TIBURON 1 LADO | E29: U | G29: 50 | I29: CUB PUNTA TIBURON 1 LADO | R29: CORNISA 2 LADOS
B30: 40 | C30: 60 | D30: CUB S/R | E30: V | G30: 50 | I30: CUB S/R | R30: CORNISA PUNTA TIBURON 1 LADO
B31: 40 | C31: 100 | D31: CUB S/R FRENTE ESPAÑOL | E31: W | G31: 50 | I31: CUB S/R FRENTE ESPAÑOL | R31: CORNISA PUNTA TIBURON 2 LADOS
B32: 40 | C32: 60 | D32: CUB S/R R2 | E32: X | G32: 50 | I32: CUB S/R R2 | R32: PR2
B33: 40 | C33: 90 | D33: PR12 | E33: Y | G33: 50 | H33: -2 | I33: PR12 | R33: PR6
B34: 40 | C34: 90 | D34: PR19 | G34: 50 | H34: -2 | I34: PR19
B35: 40 | C35: 90 | D35: PR2 | E35: Z | G35: 50 | H35: -2 | I35: PR2 | R35: PR8
B36: 40 | C36: 90 | D36: PR6 | G36: 50 | H36: -2 | I36: PR6 | R36: PR12
B37: 40 | C37: 90 | D37: PR8 | G37: 50 | H37: -2 | I37: PR8 | R37: PR19
B48: 40 | C48: 150

Sheet CUBIERTA
L2: NO BORRAR REGLAS!!!!! SI NO LAS SABEN USAR NO BORREN ESTO POR FAVOR!!!!!
L3: SUSTRATO | N3: LAMINADO
C4: NOTA DE VENTA : | D4: ='4637'!H8 -> 7329 | L4: ALTO | M4: ANCHO | N4: ALTO | O4: ANCHO
C5: CLIENTE : | D5: ='4637'!C10 -> CONSTRUCTORA HALTRA | L5: =LOOKUP(#REF!,REGLAS!$I$4:$I$37,REGLAS!$G$4:$G$37)+#REF! -> #REF! | M5: =LOOKUP(#REF!,REGLAS!$I$4:$I$37,REGLAS!$H$4:$H$37)+#REF! -> #REF! | N5: =LOOKUP(#REF!,REGLAS!$D$4:$D$37,REGLAS!$B$4:$B$37)+#REF! -> #REF! | O5: =LOOKUP(#REF!,REGLAS!$D$4:$D$37,REGLAS!$C$4:$C$37)+#REF! -> #REF!
C7: ='4637'!G11 -> FECHA LIMITE : | D7: ='4637'!H11 -> 45996
C8: FECHA ENTREGA:
A10: SUSTRATO
D12: ALTO | E12: ANCHO
A13: MATERIAL | B13: CANTIDAD | C13: CORTE | G13: DESCRIPCIÓN | K13: ALTO | L13: ANCHO
A14: MDF30MM | B14: =J14 -> 3 | D14: =K14+D$13 -> 1500 | E14: 810 | G14: =C68 -> E/R 2 CARAS MDF 30MM FRONTAL | J14: 3 | K14: =K43 -> 1500 | L14: =E68 -> 800
B15: =J15 -> 2 | D15: =K15+D$13 -> 1500 | E15: =L15+E$13 -> 1100 | G15: =C69 -> E/R 2 CARAS MDF 30MM FRONTAL | J15: 2 | K15: =K44 -> 1500 | L15: =E69 -> 1100
B16: =J16 -> 13 | D16: 770 | E16: 480 | G16: =C70 -> E/R 1 CARA MDF 30MM COSTADOS | J16: =J45 -> 13 | K16: =K45 -> 750 | L16: =E70 -> 460
A17: MATERIAL | B17: CANTIDAD | C17: CORTE | D17: 20 | E17: 20 | G17: DESCRIPCIÓN
A18: MDF18MM | B18: =J18 -> 1 | D18: =K18+D$17 -> 1450 | E18: =L18+E$17 -> 720 | G18: =C71 -> CUB FRENTE RECTO 2 LADOS | J18: =J46 -> 1 | K18: =K46 -> 1430 | L18: =E71 -> 700
B19: =J19 -> 1 | D19: =K19+D$17 -> 1480 | E19: =L19+E$17 -> 720 | G19: =C72 -> CUB FRENTE RECTO 2 LADOS | J19: =J47 -> 1 | K19: =K47 -> 1460 | L19: =E72 -> 700
B20: =J20 -> 2 | D20: =K20+D$17 -> 640 | E20: =L20+E$17 -> 520 | G20: =C73 -> CUB FRENTE RECTO 2 LADOS | J20: =J48 -> 2 | K20: =K48 -> 620 | L20: =E73 -> 500
B21: =J21 -> 2 | D21: =K21+D$17 -> 1300 | E21: =L21+E$17 -> 720 | G21: =C74 -> CUB FRENTE RECTO 2 LADOS | J21: =J49 -> 2 | K21: =K49 -> 1280 | L21: =E74 -> 700
B22: =J22 -> 1 | D22: =K22+D$17 -> 1330 | E22: =L22+E$17 -> 720 | G22: =C75 -> CUB FRENTE RECTO 2 LADOS | J22: =J50 -> 1 | K22: =K50 -> 1310 | L22: =E75 -> 700
B23: =J23 -> 1 | D23: =K23+D$17 -> 1880 | E23: =L23+E$17 -> 720 | G23: =C76 -> CUB FRENTE RECTO 2 LADOS | J23: =J51 -> 1 | K23: =K51 -> 1860 | L23: =E76 -> 700
B24: =J24 -> 2 | D24: =K24+D$17 -> 1600 | E24: =L24+E$17 -> 720 | G24: =C77 -> CUB FRENTE RECTO 2 LADOS | J24: =J52 -> 2 | K24: =K52 -> 1580 | L24: =E77 -> 700
B25: =J25 -> 1 | D25: =K25+D$17 -> 1690 | E25: =L25+E$17 -> 720 | G25: =C78 -> CUB FRENTE RECTO 2 LADOS | J25: =J53 -> 1 | K25: =K53 -> 1670 | L25: =E78 -> 700
B26: =J26 -> 1 | D26: =K26+D$17 -> 1450 | E26: =L26+E$17 -> 720 | G26: =C79 -> E/R 1 CARA MDF 18MM FALDON | J26: =J54 -> 1 | K26: =K54 -> 1430 | L26: =E79 -> 700
B27: =J27 -> 1 | D27: =K27+D$17 -> 1480 | E27: =L27+E$17 -> 720 | G27: =C80 -> E/R 1 CARA MDF 18MM FALDON | J27: =J55 -> 1 | K27: =K55 -> 1460 | L27: =E80 -> 700
B28: =J28 -> 2 | C28: FALDON | D28: =K28+D$17 -> 640 | E28: =L28+E$17 -> 370 | G28: =C81 -> E/R 1 CARA MDF 18MM FALDON | J28: =J56 -> 2 | K28: =K56 -> 620 | L28: =E81 -> 350
B29: =J29 -> 2 | D29: =K29+D$17 -> 1300 | E29: =L29+E$17 -> 720 | G29: =C82 -> E/R 1 CARA MDF 18MM FALDON | J29: =J57 -> 2 | K29: =K57 -> 1280 | L29: =E82 -> 700
B30: =J30 -> 1 | D30: =K30+D$17 -> 1330 | E30: =L30+E$17 -> 720 | G30: =C83 -> E/R 1 CARA MDF 18MM FALDON | J30: =J58 -> 1 | K30: =K58 -> 1310 | L30: =E83 -> 700
B31: =J31 -> 1 | D31: =K31+D$17 -> 1880 | E31: =L31+E$17 -> 720 | G31: =C84 -> E/R 1 CARA MDF 18MM FALDON | J31: =J59 -> 1 | K31: =K59 -> 1860 | L31: =E84 -> 700
B32: =J32 -> 2 | D32: =K32+D$17 -> 1600 | E32: =L32+E$17 -> 720 | G32: =C85 -> E/R 1 CARA MDF 18MM FALDON | J32: =J60 -> 2 | K32: =K60 -> 1580 | L32: =E85 -> 700
B33: =J33 -> 1 | D33: =K33+D$17 -> 1690 | E33: =L33+E$17 -> 720 | G33: =C86 -> E/R 1 CARA MDF 18MM FALDON | J33: =J61 -> 1 | K33: =K61 -> 1670 | L33: =E86 -> 700
A34: MATERIAL | B34: CANTIDAD | C34: CORTE | D34: 50 | E34: -2 | G34: DESCRIPCIÓN
A35: MELAMIL 18MM | B35: =J35 -> 9 | D35: =K35+D34 -> 600 | E35: =L35+E34 -> 396 | G35: =C87 -> PR6 | J35: =J62 -> 9 | K35: =K62 -> 550 | L35: =E87 -> 398
A39: LAMINADO
D41: ALTO | E41: ANCHO
A42: MATERIAL | B42: CANTIDAD | C42: CORTE | D42: 20 | E42: 20 | G42: DESCRIPCIÓN | K42: ALTO | L42: ANCHO
B43: =J43 -> 6 | D43: =K43+D$42 -> 1520 | E43: 810 | G43: =C68 -> E/R 2 CARAS MDF 30MM FRONTAL | J43: 6 | K43: =D68 -> 1500 | L43: =E68 -> 800 | N43: 185
B44: =J44 -> 4 | D44: =K44+D$42 -> 1520 | E44: =L44+E$42 -> 1120 | G44: =C69 -> E/R 2 CARAS MDF 30MM FRONTAL | J44: 4 | K44: =D69 -> 1500 | L44: =E69 -> 1100
B45: =J45 -> 13 | D45: 760 | E45: 480 | G45: =C70 -> E/R 1 CARA MDF 30MM COSTADOS | J45: =B70 -> 13 | K45: =D70 -> 750 | L45: =E70 -> 460
B46: =J46 -> 1 | C46: REGRUESO DE MELAMINA BLANCA | D46: =K46+D$42 -> 1450 | E46: =L46+E$42 -> 720 | G46: =C71 -> CUB FRENTE RECTO 2 LADOS | J46: =B71 -> 1 | K46: =D71 -> 1430 | L46: =E71 -> 700
B47: =J47 -> 1 | C47: REGRUESO DE MELAMINA BLANCA | D47: =K47+D$42 -> 1480 | E47: =L47+E$42 -> 720 | G47: =C72 -> CUB FRENTE RECTO 2 LADOS | J47: =B72 -> 1 | K47: =D72 -> 1460 | L47: =E72 -> 700
B48: =J48 -> 2 | C48: REGRUESO DE MELAMINA BLANCA | D48: =K48+D$42 -> 640 | E48: =L48+E$42 -> 520 | G48: =C73 -> CUB FRENTE RECTO 2 LADOS | J48: =B73 -> 2 | K48: =D73 -> 620 | L48: =E73 -> 500
...
