Workbook

Sheet RECEPCION
G2: MUEBLES SANTA FE SPA
G3: VENTAS POR MENOR DE MUEBLES
G4: RUT: 77.054.606-0
G5: SEPTIMA AVENIDA 1631, SAN MIGUEL
G6: FONO 22521 6502 | P6: 10077 SF PORTLAND MAPLE
G7: E-MAIL: ventas@topmobili.cl
B8: P R E S U P U E S T O | D8: N° 10779
B10: CLIENTE: | C10: CONSTRUCTORA BIECSA LTDA | G10: FECHA: | H10: 45376
B11: RUT: | C11: 76.110.601-5 | G11: PLAZO ENTREGA: | H11: 10 DIAS HABILES | S11: MT2 PUERTAS
B12: GIRO: | G12: SERVICIO EXPRESS | H12: NO
B13: CONTACTO: | C13: FRANCISCO ZURITA | M13: 32.98 | N13: MT2
B14: CORREO: | G14: CORTADA A LA MEDIDA | H14: NO | S14: ML CUBIERTAS
B15: FONO: | C15: +56956629251 | G15: DESPACHO: | H15: NO | L15: =I26/M13 -> 20349.879
B16: DIRECCION: | G16: FORMA DE PAGO: | H16: ABONO 50%, SALDO C/E
B17: CIUDAD: | C17: SANTIAGO | G17: DURACION COTIZACION: 5 DIAS FERNANDO DONOSO
O18: LAMINADO
B19: , | M19: 0.02 | N19: 0.02 | O19: 0.13 | Q19: TOTAL | R19: VALOR X MT2 | S19: DESFONDADOS | T19: MT/L
B20: UNIDAD | C20: TIPO | D20: LARGO | E20: ANCHO | F20: MUEBLE | G20: COLOR | H20: VALOR | I20: TOTAL | L20: =B20 -> UNIDAD | M20: ALTO | N20: =E20 -> ANCHO | P20: MT | Q20: MT2 | R20: =P40 -> 162658.02 | S20: 20000 | T20: ALTO | U20: ANCHO
B21: 1 | C21: E/R 2 CARAS | D21: 2.3 | E21: 0.6 | F21: M2 | G21: VAINILLA 2109 MT | H21: 253967 | I21: =H21*B21 -> 253967 | L21: =B21 -> 1 | M21: =D21+M$19 -> 2.32 | N21: =E21+N$19 -> 0.62 | O21: =E21+O$19 -> 0.73 | P21: =M21*N21 -> 1.4384 | Q21: =P21*L21 -> 1.4384 | R21: =R$20*P21 -> 233967.29 | S21: =R21+S$20 -> 253967.29 | T21: =M21*L21*2 -> 4.64 | U21: =N21*L21*2 -> 1.24
B22: 1 | C22: E/R 2 CARAS | D22: 2.5 | E22: 0.6 | F22: M2 | G22: GREY 27199 ANTIHUELLAS | H22: 274137 | I22: =H22*B22 -> 274137 | L22: =B22 -> 1 | M22: =D22+M$19 -> 2.52 | N22: =E22+N$19 -> 0.62 | O22: =E22+O$19 -> 0.73 | P22: =M22*N22 -> 1.5624 | Q22: =P22*L22 -> 1.5624 | R22: =R$20*P22 -> 254136.89 | S22: =R22+S$20 -> 274136.89 | T22: =M22*L22*2 -> 5.04 | U22: =N22*L22*2 -> 1.24
B23: 1 | C23: E/R 2 CARAS | D23: 1.2 | E23: 0.6 | F23: M2 | G23: GREY 27199 ANTIHUELLAS | H23: 143035 | I23: =H23*B23 -> 143035 | L23: =B23 -> 1 | M23: =D23+M$19 -> 1.22 | N23: =E23+N$19 -> 0.62 | O23: =E23+O$19 -> 0.73 | P23: =M23*N23 -> 0.7564 | Q23: =P23*L23 -> 0.7564 | R23: =R$20*P23 -> 123034.52 | S23: =R23+S$20 -> 143034.52 | T23: =M23*L23*2 -> 2.44 | U23: =N23*L23*2 -> 1.24
S24: =SUM(S21:S23) -> 671138.7 | T24: =SUM(T21:T23) -> 12.12 | U24: =SUM(U21:U23) -> 3.72
T25: =T24+U24 -> 15.84
H26: NETO | I26: =SUM(I21:I25) -> 671139 | T26: =T25*20% -> 3.168
H27: IVA | I27: =I26*0.19 -> 127516.41 | Q27: =SUM(Q21:Q23) -> 3.7572 | T27: =T25+T26 -> 19.008
H28: TOTAL | I28: =I26+I27 -> 798655.41 | Q28: =Q27 -> 3.7572
Q29: =Q28*20% -> 0.75144 | R29: 20% PERDIDA
Q30: =Q28+Q29 -> 4.50864 | T30: 40
M32: =Q30*2 -> 9.01728 | N32: 3500 | P32: =M32*N32 -> 31560.48 | Q32: ADHESIVO | R32: TRASCARA ENCHAPADA, ES POR 2
M33: 2 | N33: 45000 | P33: =M33*N33 -> 90000 | Q33: MDF18MM
M34: 2 | N34: 19000 | P34: =M34*N34 -> 38000 | Q34: BALANCE
B35: CUENTA CORRIENTE BANCO SANTANDER Nº 87316181 A NOMBRE DE MUEBLES SANTA FE SPA | M35: 2 | N35: 33076 | P35: =M35*N35 -> 66152 | Q35: LAMINA 122X244
B36: RUT : 77.054.606-0 VENTAS@TOPMOBILI.CL | M36: 20 | N36: 2000 | P36: =M36*N36 -> 40000 | Q36: TAPACANTO PVC REGRUESO | S36: 1.22 | U36: 3.05
B37: VISITANOS Y DESCUBRE NUESTROS PRODUCTOS EN | G37: WWW.TOPMOBILICHILE.CL | N37: 1500 | P37: =M37*N37 -> 0 | Q37: MEDIA CAÑA | S37: 2.44 | U37: 1.23
P38: =SUM(P32:P37) -> 265712.48 | Q38: COSTO | S38: =S36*S37 -> 2.9768 | U38: =U36*U37 -> 3.7515
K39: 39360 | M39: PRECIO VENTA | P39: =P38*2.3 -> 611138.7 | Q39: FACTOR 2,3 PARA 90° | S39: =Q28/S38 -> 1.2621607 | U39: =Q28/U38 -> 1.0015194
K40: =K39/1.19 -> 33075.63 | P40: =P39/Q28 -> 162658.02 | Q40: VALOR M2
P41: =P39/P38 -> 2.3
N43: PRECIO | P43: LAMINAS | Q43: MDF | R43: ADHESIVO | S43: TAPACANTO | T43: PRECIO
M44: MINT | N44: 50890 | P44: 6 | Q44: 3 | R44: 15.661 | S44: 70 | T44: 1399760
...

Sheet escritorio
G2: MUEBLES SANTA FE SPA
G3: VENTAS POR MENOR DE MUEBLES
G4: RUT: 77.054.606-0
G5: SEPTIMA AVENIDA 1631, SAN MIGUEL
G6: FONO 22521 6502 | P6: 10077 SF PORTLAND MAPLE
G7: E-MAIL: ventas@topmobili.cl
B8: P R E S U P U E S T O | D8: N° 10779
B10: CLIENTE: | C10: CONSTRUCTORA BIECSA LTDA | G10: FECHA: | H10: 45376
B11: RUT: | C11: 76.110.601-5 | G11: PLAZO ENTREGA: | H11: 10 DIAS HABILES | S11: MT2 PUERTAS
B12: GIRO: | G12: SERVICIO EXPRESS | H12: NO
B13: CONTACTO: | C13: FRANCISCO ZURITA | M13: 32.98 | N13: MT2
B14: CORREO: | G14: CORTADA A LA MEDIDA | H14: NO | S14: ML CUBIERTAS
B15: FONO: | C15: +56956629251 | G15: DESPACHO: | H15: NO | L15: =I27/M13 -> 20989.357
B16: DIRECCION: | G16: FORMA DE PAGO: | H16: ABONO 50%, SALDO C/E
B17: CIUDAD: | C17: SANTIAGO | G17: DURACION COTIZACION: 5 DIAS FERNANDO DONOSO
O18: LAMINADO
B19: , | M19: 0.02 | N19: 0.02 | O19: 0.13 | Q19: TOTAL | R19: VALOR X MT2 | S19: DESFONDADOS | T19: MT/L
B20: UNIDAD | C20: TIPO | D20: LARGO | E20: ANCHO | F20: MUEBLE | G20: COLOR | H20: VALOR | I20: TOTAL | L20: =B20 -> UNIDAD | M20: ALTO | N20: =E20 -> ANCHO | P20: MT | Q20: MT2 | R20: =P41 -> 231799.18 | S20: 20000 | T20: ALTO | U20: ANCHO
B21: 1 | C21: E/R 2 CARAS | D21: 0.73 | E21: 0.6 | F21: E1 | G21: GREY 27199 ANTIHUELLAS | H21: 127787 | I21: =H21*B21 -> 127787 | L21: =B21 -> 1 | M21: =D21+M$19 -> 0.75 | N21: =E21+N$19 -> 0.62 | O21: =E21+O$19 -> 0.73 | P21: =M21*N21 -> 0.465 | Q21: =P21*L21 -> 0.465 | R21: =R$20*P21 -> 107786.62 | S21: =R21+S$20 -> 127786.62 | T21: =M21*L21*2 -> 1.5 | U21: =N21*L21*2 -> 1.24
B22: 1 | C22: E/R 2 CARAS | D22: 1.4 | E22: 0.6 | F22: E1 | G22: GREY 27199 ANTIHUELLAS | H22: 224076 | I22: =H22*B22 -> 224076 | L22: =B22 -> 1 | M22: =D22+M$19 -> 1.42 | N22: =E22+N$19 -> 0.62 | O22: =E22+O$19 -> 0.73 | P22: =M22*N22 -> 0.8804 | Q22: =P22*L22 -> 0.8804 | R22: =R$20*P22 -> 204075.99 | S22: =R22+S$20 -> 224075.99 | T22: =M22*L22*2 -> 2.84 | U22: =N22*L22*2 -> 1.24
B23: 1 | C23: E/R 2 CARAS | D23: 0.8 | E23: 0.6 | F23: E1 | G23: GREY 27199 ANTIHUELLAS | H23: 137847 | I23: =H23*B23 -> 137847 | L23: =B23 -> 1 | M23: =D23+M$19 -> 0.82 | N23: =E23+N$19 -> 0.62 | O23: =E23+O$19 -> 0.73 | P23: =M23*N23 -> 0.5084 | Q23: =P23*L23 -> 0.5084 | R23: =R$20*P23 -> 117846.7 | S23: =R23+S$20 -> 137846.7 | T23: =M23*L23*2 -> 1.64 | U23: =N23*L23*2 -> 1.24
B24: 1 | C24: E/R 2 CARAS | D24: 1.25 | E24: 0.6 | F24: E1 | G24: GREY 27199 ANTIHUELLAS | H24: 202519 | I24: =H24*B24 -> 202519 | L24: =B24 -> 1 | M24: =D24+M$19 -> 1.27 | N24: =E24+N$19 -> 0.62 | O24: =E24+O$19 -> 0.73 | P24: =M24*N24 -> 0.7874 | Q24: =P24*L24 -> 0.7874 | R24: =R$20*P24 -> 182518.67 | S24: =R24+S$20 -> 202518.67 | T24: =M24*L24*2 -> 2.54 | U24: =N24*L24*2 -> 1.24
S25: =SUM(S21:S24) -> 692227.98 | T25: =SUM(T21:T24) -> 8.52 | U25: =SUM(U21:U24) -> 4.96
T26: =T25+U25 -> 13.48
H27: NETO | I27: =SUM(I21:I26) -> 692229 | T27: =T26*20% -> 2.696
H28: IVA | I28: =I27*0.19 -> 131523.51 | Q28: =SUM(Q21:Q24) -> 2.6412 | T28: =T26+T27 -> 16.176
H29: TOTAL | I29: =I27+I28 -> 823752.51 | Q29: =Q28 -> 2.6412
Q30: =Q29*20% -> 0.52824 | R30: 20% PERDIDA
Q31: =Q29+Q30 -> 3.16944 | T31: 40
M33: =Q31*2 -> 6.33888 | N33: 3500 | P33: =M33*N33 -> 22186.08 | Q33: ADHESIVO | R33: TRASCARA ENCHAPADA, ES POR 2
M34: 1 | N34: 45000 | P34: =M34*N34 -> 45000 | Q34: MDF18MM
M35: 1 | N35: 19000 | P35: =M35*N35 -> 19000 | Q35: BALANCE
B36: CUENTA CORRIENTE BANCO SANTANDER Nº 87316181 A NOMBRE DE MUEBLES SANTA FE SPA | M36: 1 | N36: 140000 | P36: =M36*N36 -> 140000 | Q36: LAMINA 122X244
B37: RUT : 77.054.606-0 VENTAS@TOPMOBILI.CL | M37: 20 | N37: 2000 | P37: =M37*N37 -> 40000 | Q37: TAPACANTO PVC REGRUESO | S37: 1.22 | U37: 3.05
B38: VISITANOS Y DESCUBRE NUESTROS PRODUCTOS EN | G38: WWW.TOPMOBILICHILE.CL | N38: 1500 | P38: =M38*N38 -> 0 | Q38: MEDIA CAÑA | S38: 2.44 | U38: 1.23
P39: =SUM(P33:P38) -> 266186.08 | Q39: COSTO | S39: =S37*S38 -> 2.9768 | U39: =U37*U38 -> 3.7515
K40: 39360 | M40: PRECIO VENTA | P40: =P39*2.3 -> 612227.98 | Q40: FACTOR 2,3 PARA 90° | S40: =Q29/S39 -> 0.88726149 | U40: =Q29/U39 -> 0.70403838
K41: =K40/1.19 -> 33075.63 | P41: =P40/Q29 -> 231799.18 | Q41: VALOR M2
P42: =P40/P39 -> 2.3
N44: PRECIO | P44: LAMINAS | Q44: MDF | R44: ADHESIVO | S44: TAPACANTO | T44: PRECIO
...

Sheet cubiertas
G2: MUEBLES SANTA FE SPA
G3: VENTAS POR MENOR DE MUEBLES
G4: RUT: 77.054.606-0
G5: SEPTIMA AVENIDA 1631, SAN MIGUEL
G6: FONO 22521 6502 | P6: 10077 SF PORTLAND MAPLE
G7: E-MAIL: ventas@topmobili.cl
B8: P R E S U P U E S T O | D8: N° 10779
B10: CLIENTE: | C10: CONSTRUCTORA BIECSA LTDA | G10: FECHA: | H10: 45376
B11: RUT: | C11: 76.110.601-5 | G11: PLAZO ENTREGA: | H11: 10 DIAS HABILES | S11: MT2 PUERTAS
B12: GIRO: | G12: SERVICIO EXPRESS | H12: NO
B13: CONTACTO: | C13: FRANCISCO ZURITA | M13: 32.98 | N13: MT2
B14: CORREO: | G14: CORTADA A LA MEDIDA | H14: NO | S14: ML CUBIERTAS
B15: FONO: | C15: +56956629251 | G15: DESPACHO: | H15: NO | L15: =I26/M13 -> 6988.963
B16: DIRECCION: | G16: FORMA DE PAGO: | H16: ABONO 50%, SALDO C/E
B17: CIUDAD: | C17: SANTIAGO | G17: DURACION COTIZACION: 5 DIAS FERNANDO DONOSO
O18: LAMINADO
B19: , | M19: 0.05 | O19: 0.13 | Q19: TOTAL | R19: VALOR X MT2 | S19: DESFONDADOS | T19: MT/L
B20: UNIDAD | C20: TIPO | D20: LARGO | E20: ANCHO | F20: MUEBLE | G20: COLOR | H20: VALOR | I20: TOTAL | L20: =B20 -> UNIDAD | M20: ALTO | N20: =E20 -> ANCHO | P20: MT | Q20: MT2 | R20: =P40 -> 142083.63 | S20: 20000 | T20: ALTO | U20: ANCHO
B21: 1 | C21: CUB C/R R6 | D21: 1.65 | E21: 0.6 | F21: M4 | G21: VAINILLA 2109 MT | H21: 230496 | I21: =H21*B21 -> 230496 | L21: =B21 -> 1 | M21: =D21+M$19 -> 1.7 | N21: =E21+N$19 -> 0.6 | O21: =E21+O$19 -> 0.73 | P21: =M21*N21 -> 1.02 | Q21: =P21*L21 -> 1.02 | R21: =R$20*P21 -> 144925.3 | S21: =R21+S$20 -> 164925.3 | T21: =M21*L21*2 -> 3.4 | U21: =N21*L21*2 -> 1.2
C22: CUB C/R R7 | D22: 5 | E22: 0.6 | F22: M5 | G22: VAINILLA 2109 MT | H22: 230497 | I22: =H22*B22 -> 0 | L22: =B22 -> 0 | M22: =D22+M$19 -> 5.05 | N22: =E22+N$19 -> 0.6 | O22: =E22+O$19 -> 0.73 | P22: =M22*N22 -> 3.03 | Q22: =P22*L22 -> 0 | R22: =R$20*P22 -> 430513.39 | S22: =R22+S$20 -> 450513.39 | T22: =M22*L22*2 -> 0
M23: =SUM(M21:M22) -> 6.75 | T23: =SUM(T21:T22) -> 3.4 | U23: =SUM(U21:U22) -> 1.2
S24: =SUM(S21:S23) -> 615438.69 | T24: =T23+U23 -> 4.6
T25: =T24*20% -> 0.92
H26: NETO | I26: =SUM(I21:I25) -> 230496 | T26: =T24+T25 -> 5.52
H27: IVA | I27: =I26*0.19 -> 43794.24 | Q27: =SUM(Q21:Q22) -> 1.02
H28: TOTAL | I28: =I26+I27 -> 274290.24 | Q28: =Q27 -> 1.02
R29: 20% PERDIDA
Q30: =Q28+Q29 -> 1.02 | T30: 40
M32: =Q30 -> 1.02 | N32: 3500 | P32: =M32*N32 -> 3570 | Q32: ADHESIVO | R32: TRASCARA ENCHAPADA, ES POR 2
M33: 0.5 | N33: 45000 | P33: =M33*N33 -> 22500 | Q33: MDF18MM
N34: 50580 | P34: =M34*N34 -> 0 | Q34: LAMINA 153X366
B35: CUENTA CORRIENTE BANCO SANTANDER Nº 87316181 A NOMBRE DE MUEBLES SANTA FE SPA | M35: 1 | N35: 33100 | P35: =M35*N35 -> 33100 | Q35: LAMINA 122X244
B36: RUT : 77.054.606-0 VENTAS@TOPMOBILI.CL | M36: 1.67 | N36: 800 | P36: =M36*N36 -> 1336 | Q36: TAPACANTO PVC REGRUESO | S36: 1.22 | U36: 3.05
B37: VISITANOS Y DESCUBRE NUESTROS PRODUCTOS EN | G37: WWW.TOPMOBILICHILE.CL | M37: 1.67 | N37: 1500 | P37: =M37*N37 -> 2505 | Q37: MEDIA CAÑA | S37: 2.44 | U37: 1.23
P38: =SUM(P32:P37) -> 63011 | Q38: COSTO | S38: =S36*S37 -> 2.9768 | U38: =U36*U37 -> 3.7515
K39: 39360 | M39: PRECIO VENTA | P39: =P38*2.3 -> 144925.3 | Q39: FACTOR 2,3 PARA 90° | S39: =Q28/S38 -> 0.34264983 | U39: =Q28/U38 -> 0.27189124
K40: =K39/1.19 -> 33075.63 | P40: =P39/Q28 -> 142083.63 | Q40: VALOR M2
P41: =P39/P38 -> 2.3
N43: PRECIO | P43: LAMINAS | Q43: MDF | R43: ADHESIVO | S43: TAPACANTO | T43: PRECIO
M44: MINT | N44: 50890 | P44: 6 | Q44: 3 | R44: 15.661 | S44: 70 | T44: 1399760
...

Sheet puertas
G2: MUEBLES SANTA FE SPA
G3: VENTAS POR MENOR DE MUEBLES
G4: RUT: 77.054.606-0
G5: SEPTIMA AVENIDA 1631, SAN MIGUEL
G6: FONO 22521 6502 | O6: 10077 SF PORTLAND MAPLE
G7: E-MAIL: ventas@topmobili.cl
B8: P R E S U P U E S T O | D8: N° 10779
B10: CLIENTE: | C10: CONSTRUCTORA BIECSA LTDA | G10: FECHA: | H10: 45376
B11: RUT: | C11: 76.110.601-5 | G11: PLAZO ENTREGA: | H11: 10 DIAS HABILES | R11: MT2 PUERTAS
B12: GIRO: | G12: SERVICIO EXPRESS | H12: NO
B13: CONTACTO: | C13: FRANCISCO ZURITA | M13: 32.98 | N13: MT2
B14: CORREO: | G14: CORTADA A LA MEDIDA | H14: NO | R14: ML CUBIERTAS
B15: FONO: | C15: +56956629251 | G15: DESPACHO: | H15: NO | L15: =I94/M13 -> 296373.32
B16: DIRECCION: | G16: FORMA DE PAGO: | H16: ABONO 50%, SALDO C/E
B17: CIUDAD: | C17: SANTIAGO | G17: DURACION COTIZACION: 5 DIAS FERNANDO DONOSO
B19: , | M19: 0.02 | N19: 0.02 | P19: TOTAL | Q19: VALOR X MT2 | R19: ENCHAPE | S19: MT/L
B20: UNIDAD | C20: TIPO | D20: LARGO | E20: ANCHO | F20: MUEBLE | G20: COLOR | H20: VALOR | I20: TOTAL | L20: =B20 -> UNIDAD | M20: ALTO | N20: =E20 -> ANCHO | O20: MT | P20: MT2 | Q20: =O108 -> 118349.22 | R20: 5000 | S20: ALTO | T20: ANCHO
B21: 7 | C21: ENCHAPE RECTO 2 CARAS | D21: 0.95 | E21: 0.369 | F21: M4 | G21: VAINILLA 2109 MT | H21: 38000 | I21: =H21*B21 -> 266000 | K21: 7 | M21: =D21+M$19 -> 0.97 | N21: =E21+N$19 -> 0.389 | O21: =M21*N21 -> 0.37733 | P21: =O21*L21 -> 0 | Q21: =Q$20*O21 -> 44656.713 | R21: =Q21+R$20 -> 49656.713 | S21: =M21*L21*2 -> 0 | T21: =N21*L21*2 -> 0
B22: 7 | C22: ENCHAPE RECTO 2 CARAS | D22: 0.56 | E22: 0.369 | F22: M4 | G22: VAINILLA 2109 MT | H22: 24732 | I22: =H22*B22 -> 173124 | K22: 7 | M22: =D22+M$19 -> 0.58 | N22: =E22+N$19 -> 0.389 | O22: =M22*N22 -> 0.22562 | P22: =O22*L22 -> 0 | Q22: =Q$20*O22 -> 26701.952 | R22: =Q22+R$20 -> 31701.952 | S22: =M22*L22*2 -> 0 | T22: =N22*L22*2 -> 0
B23: 2 | C23: ENCHAPE RECTO 2 CARAS | D23: 0.95 | E23: 0.369 | F23: M4 | G23: MINT 2236 MT | H23: 51528 | I23: =H23*B23 -> 103056 | K23: 2 | M23: =D23+M$19 -> 0.97 | N23: =E23+N$19 -> 0.389 | O23: =M23*N23 -> 0.37733 | P23: =O23*L23 -> 0 | Q23: =Q$20*O23 -> 44656.713 | R23: =Q23+R$20 -> 49656.713 | S23: =M23*L23*2 -> 0 | T23: =N23*L23*2 -> 0
B24: 2 | C24: ENCHAPE RECTO 2 CARAS | D24: 0.56 | E24: 0.369 | F24: M4 | G24: BLEEN 2224 MT | H24: 32308 | I24: =H24*B24 -> 64616 | K24: 2 | M24: =D24+M$19 -> 0.58 | N24: =E24+N$19 -> 0.389 | O24: =M24*N24 -> 0.22562 | P24: =O24*L24 -> 0 | Q24: =Q$20*O24 -> 26701.952 | R24: =Q24+R$20 -> 31701.952 | S24: =M24*L24*2 -> 0 | T24: =N24*L24*2 -> 0
B25: 2 | C25: ENCHAPE RECTO 2 CARAS | D25: 0.56 | E25: 0.375 | F25: M3 | G25: BLEEN 2224 MT | H25: 32729 | I25: =H25*B25 -> 65458 | K25: 2 | M25: =D25+M$19 -> 0.58 | N25: =E25+N$19 -> 0.395 | O25: =M25*N25 -> 0.2291 | P25: =O25*L25 -> 0 | Q25: =Q$20*O25 -> 27113.807 | R25: =Q25+R$20 -> 32113.807 | S25: =M25*L25*2 -> 0 | T25: =N25*L25*2 -> 0
B26: 6 | C26: ENCHAPE RECTO 2 CARAS | D26: 0.56 | E26: 0.375 | F26: M3 | G26: VAINILLA 2109 MT | H26: 25036 | I26: =H26*B26 -> 150216 | K26: 6 | M26: =D26+M$19 -> 0.58 | N26: =E26+N$19 -> 0.395 | O26: =M26*N26 -> 0.2291 | P26: =O26*L26 -> 0 | Q26: =Q$20*O26 -> 27113.807 | R26: =Q26+R$20 -> 32113.807 | S26: =M26*L26*2 -> 0 | T26: =N26*L26*2 -> 0
B27: 3 | C27: ENCHAPE RECTO 2 CARAS | D27: 0.7 | E27: 0.46 | F27: M2 | G27: VAINILLA 2109 MT | H27: 35225 | I27: =H27*B27 -> 105675 | K27: 3 | M27: =D27+M$19 -> 0.72 | N27: =E27+N$19 -> 0.48 | O27: =M27*N27 -> 0.3456 | P27: =O27*L27 -> 0 | Q27: =Q$20*O27 -> 40901.492 | R27: =Q27+R$20 -> 45901.492 | S27: =M27*L27*2 -> 0 | T27: =N27*L27*2 -> 0
B28: 10 | C28: ENCHAPE RECTO 2 CARAS | D28: 0.88 | E28: 0.31 | F28: M6 | G28: VAINILLA 2109 MT | H28: 30975 | I28: =H28*B28 -> 309750 | K28: 10 | M28: =D28+M$19 -> 0.9 | N28: =E28+N$19 -> 0.33 | O28: =M28*N28 -> 0.297 | P28: =O28*L28 -> 0 | Q28: =Q$20*O28 -> 35149.72 | R28: =Q28+R$20 -> 40149.72 | S28: =M28*L28*2 -> 0 | T28: =N28*L28*2 -> 0
B29: 2 | C29: ENCHAPE RECTO 2 CARAS | D29: 0.88 | E29: 0.31 | F29: M6 | G29: BLEEN 2224 MT | H29: 40948 | I29: =H29*B29 -> 81896 | K29: 2 | M29: =D29+M$19 -> 0.9 | N29: =E29+N$19 -> 0.33 | O29: =M29*N29 -> 0.297 | P29: =O29*L29 -> 0 | Q29: =Q$20*O29 -> 35149.72 | R29: =Q29+R$20 -> 40149.72 | S29: =M29*L29*2 -> 0 | T29: =N29*L29*2 -> 0
B30: 2 | C30: ENCHAPE RECTO 2 CARAS | D30: 0.88 | E30: 0.31 | F30: M6 | G30: MINT 2236 MT | H30: 41623 | I30: =H30*B30 -> 83246 | K30: 2 | M30: =D30+M$19 -> 0.9 | N30: =E30+N$19 -> 0.33 | O30: =M30*N30 -> 0.297 | P30: =O30*L30 -> 0 | Q30: =Q$20*O30 -> 35149.72 | R30: =Q30+R$20 -> 40149.72 | S30: =M30*L30*2 -> 0 | T30: =N30*L30*2 -> 0
B31: 2 | C31: ENCHAPE RECTO 2 CARAS | D31: 0.95 | E31: 0.364 | F31: M11 | G31: MINT 2236 MT | H31: 50930 | I31: =H31*B31 -> 101860 | K31: 2 | M31: =D31+M$19 -> 0.97 | N31: =E31+N$19 -> 0.384 | O31: =M31*N31 -> 0.37248 | P31: =O31*L31 -> 0 | Q31: =Q$20*O31 -> 44082.719 | R31: =Q31+R$20 -> 49082.719 | S31: =M31*L31*2 -> 0 | T31: =N31*L31*2 -> 0
B32: 2 | C32: ENCHAPE RECTO 2 CARAS | D32: 0.95 | E32: 0.364 | F32: M11 | G32: VAINILLA 2109 MT | H32: 37576 | I32: =H32*B32 -> 75152 | K32: 2 | M32: =D32+M$19 -> 0.97 | N32: =E32+N$19 -> 0.384 | O32: =M32*N32 -> 0.37248 | P32: =O32*L32 -> 0 | Q32: =Q$20*O32 -> 44082.719 | R32: =Q32+R$20 -> 49082.719 | S32: =M32*L32*2 -> 0 | T32: =N32*L32*2 -> 0
... B40: 2 | C40: ENCHAPE RECTO 2 CARAS | D40: 0.56 | E40: 0.366 | F40: M12 | G40: BLEEN 2224 MT | H40: 32097 | I40: =H40*B40 -> 64194 | K40: 2 | M40: =D40+M$19 -> 0.58 | N40: =E40+N$19 -> 0.386 | O40: =M40*N40 -> 0.22388 | P40: =O40*L40 -> 0 | Q40: =Q$20*O40 -> 26496.024 | R40: =Q40+R$20 -> 31496.024 | S40: =M40*L40*2 -> 0 | T40: =N40*L40*2 -> 0
B41: 1 | C41: ENCHAPE RECTO 2 CARAS | D41: 1.35 | E41: 0.6 | F41: M12 | G41: CARBON 2192 MT | H41: 105526 | I41: =H41*B41 -> 105526 | K41: 1 | L41: 1 | M41: =D41+M$19 -> 1.37 | N41: =E41+N$19 -> 0.62 | O41: =M41*N41 -> 0.8494 | P41: =O41*L41 -> 0.8494 | Q41: =Q$20*O41 -> 100525.83 | R41: =Q41+R$20 -> 105525.83 | S41: =M41*L41*2 -> 2.74 | T41: =N41*L41*2 -> 1.24
B42: 2 | C42: ENCHAPE RECTO 2 CARAS | D42: 2.5 | E42: 0.58 | F42: M12 | G42: CARBON 2192 MT | H42: 183944 | I42: =H42*B42 -> 367888 | K42: 2 | L42: 2 | M42: =D42+M$19 -> 2.52 | N42: =E42+N$19 -> 0.6 | O42: =M42*N42 -> 1.512 | P42: =O42*L42 -> 3.024 | Q42: =Q$20*O42 -> 178944.03 | R42: =Q42+R$20 -> 183944.03 | S42: =M42*L42*2 -> 10.08 | T42: =N42*L42*2 -> 2.4
B43: 3 | C43: ENCHAPE RECTO 2 CARAS | D43: 0.58 | E43: 0.58 | F43: M12 | G43: CARBON 2192 MT | H43: 47606 | I43: =H43*B43 -> 142818 | K43: 3 | L43: 3 | M43: =D43+M$19 -> 0.6 | N43: =E43+N$19 -> 0.6 | O43: =M43*N43 -> 0.36 | P43: =O43*L43 -> 1.08 | Q43: =Q$20*O43 -> 42605.721 | R43: =Q43+R$20 -> 47605.721 | S43: =M43*L43*2 -> 3.6 | T43: =N43*L43*2 -> 3.6
B44: 1 | C44: ENCHAPE RECTO 2 CARAS | D44: 2.5 | E44: 0.6 | F44: M12 | G44: CARBON 2192 MT | H44: 189909 | I44: =H44*B44 -> 189909 | K44: 1 | L44: 1 | M44: =D44+M$19 -> 2.52 | N44: =E44+N$19 -> 0.62 | O44: =M44*N44 -> 1.5624 | P44: =O44*L44 -> 1.5624 | Q44: =Q$20*O44 -> 184908.83 | R44: =Q44+R$20 -> 189908.83 | S44: =M44*L44*2 -> 5.04 | T44: =N44*L44*2 -> 1.24
B45: 2 | C45: ENCHAPE RECTO 2 CARAS | D45: 0.58 | E45: 0.58 | F45: M12 | G45: CARBON 2192 MT | H45: 47606 | I45: =H45*B45 -> 95212 | K45: 2 | L45: 2 | M45: =D45+M$19 -> 0.6 | N45: =E45+N$19 -> 0.6 | O45: =M45*N45 -> 0.36 | P45: =O45*L45 -> 0.72 | Q45: =Q$20*O45 -> 42605.721 | R45: =Q45+R$20 -> 47605.721 | S45: =M45*L45*2 -> 2.4 | T45: =N45*L45*2 -> 2.4
B46: 3 | C46: ENCHAPE RECTO 2 CARAS | D46: 0.95 | E46: 0.36 | F46: M14 | G46: VAINILLA 2109 MT | H46: 37237 | I46: =H46*B46 -> 111711 | K46: 3 | M46: =D46+M$19 -> 0.97 | N46: =E46+N$19 -> 0.38 | O46: =M46*N46 -> 0.3686 | P46: =O46*L46 -> 0 | Q46: =Q$20*O46 -> 43623.524 | R46: =Q46+R$20 -> 48623.524 | S46: =M46*L46*2 -> 0 | T46: =N46*L46*2 -> 0
B47: 2 | C47: ENCHAPE RECTO 2 CARAS | D47: 0.95 | E47: 0.36 | F47: M14 | G47: MINT 2236 MT | H47: 50452 | I47: =H47*B47 -> 100904 | K47: 2 | M47: =D47+M$19 -> 0.97 | N47: =E47+N$19 -> 0.38 | O47: =M47*N47 -> 0.3686 | P47: =O47*L47 -> 0 | Q47: =Q$20*O47 -> 43623.524 | R47: =Q47+R$20 -> 48623.524 | S47: =M47*L47*2 -> 0 | T47: =N47*L47*2 -> 0
B48: 2 | C48: ENCHAPE RECTO 2 CARAS | D48: 0.56 | E48: 0.298 | F48: M14 | G48: VAINILLA 2109 MT | H48: 21130 | I48: =H48*B48 -> 42260 | K48: 2 | M48: =D48+M$19 -> 0.58 | N48: =E48+N$19 -> 0.318 | O48: =M48*N48 -> 0.18444 | P48: =O48*L48 -> 0 | Q48: =Q$20*O48 -> 21828.331 | R48: =Q48+R$20 -> 26828.331 | S48: =M48*L48*2 -> 0 | T48: =N48*L48*2 -> 0
B49: 2 | C49: ENCHAPE RECTO 2 CARAS | D49: 0.56 | E49: 0.373 | F49: M14 | G49: BLEEN 2224 MT | H49: 32589 | I49: =H49*B49 -> 65178 | K49: 2 | M49: =D49+M$19 -> 0.58 | N49: =E49+N$19 -> 0.393 | O49: =M49*N49 -> 0.22794 | P49: =O49*L49 -> 0 | Q49: =Q$20*O49 -> 26976.522 | R49: =Q49+R$20 -> 31976.522 | S49: =M49*L49*2 -> 0 | T49: =N49*L49*2 -> 0
B50: 1 | C50: ENCHAPE RECTO 2 CARAS | D50: 0.95 | E50: 0.3 | F50: M17 | G50: VAINILLA 2109 MT | H50: 32147 | I50: =H50*B50 -> 32147 | K50: 1 | M50: =D50+M$19 -> 0.97 | N50: =E50+N$19 -> 0.32 | O50: =M50*N50 -> 0.3104 | P50: =O50*L50 -> 0 | Q50: =Q$20*O50 -> 36735.599 | R50: =Q50+R$20 -> 41735.599 | S50: =M50*L50*2 -> 0 | T50: =N50*L50*2 -> 0
...

Sheet COSTOS
B2: CENTRO DE COSTOS POSTFORMADOS
B5: FECHA: | C5: =puertas!H10 -> 45376
B6: CLIENTE: | C6: =puertas!C10 -> CONSTRUCTORA BIECSA LTDA | N6: Ventas Equilibrio = | P6: Costos Fijos Totales
B7: DIRECCION: | C7: =puertas!#REF! -> #REF! | H7: COSTOS INDIRECTOS DE FABRICA VARIABLES | O7: 1 - | P7: Costos Variables Totales
B8: PRESUPUESTO: | C8: =puertas!D8 -> N° 10779 | H8: Q/HRS | I8: $ | J8: DETALLE | K8: TOTAL | L8: TOTAL | P8: Total Venta | X8: =SUM(Q11:Q16) -> 6
H9: CANTIDAD | I9: PRECIO | J9: MATERIA PRIMA INDIRECTA | L9: =SUM(K10:K23) -> 2550 | S9: DETALLE | X9: =(E15-D11)/X8 -> -1582869.5
D10: NETO | E10: IVA | F10: TOTAL | H10: 3 | I10: 350 | J10: RESPALDO | K10: =I10*H10 -> 1050 | Q10: UNIDAD | R10: TIPO | S10: LARGO | T10: ANCHO | U10: COLOR | V10: VALOR | W10: TOTAL
C11: MONTO A COBRAR | D11: =puertas!I94 -> 9774392 | E11: =D11*0.19 -> 1857134.5 | F11: =E11+D11 -> 11631526 | H11: 3 | I11: 500 | J11: MEDIA CAÑA | K11: =I11*H11 -> 1500 | Q11: 1 | R11: CUB C/R R8 | S11: 2.8 | T11: 0.62 | U11: MADERA X DEFINIR | V11: 105990 | W11: =V11*Q11 -> 105990 | X11: =V11+$X$9 -> -1476879.5 | Y11: 108990
C12: COSTO TOTAL | D12: =SUM(M43:M45) -> 167984.69 | H12: 0 | I12: 7500 | J12: DUROLAC | K12: =I12*H12 -> 0 | Q12: 1 | R12: CUB C/R R8 | S12: 2.3 | T12: 0.62 | U12: MADERA X DEFINIR | V12: 87990 | W12: =V12*Q12 -> 87990 | X12: =V12+$X$9 -> -1494879.5 | Y12: 89990
C13: % UTILIDAD | D13: =D11-D12 -> 9606407.3 | E13: =(D11/D12)-1 -> 57.186207 | H13: 0 | I13: 50 | J13: TAPACANTO PVC | K13: =I13*H13 -> 0 | Q13: 1 | R13: CUB C/R R8 | S13: 2.03 | T13: 0.62 | U13: MADERA X DEFINIR | V13: 78990 | W13: =V13*Q13 -> 78990 | X13: =V13+$X$9 -> -1503879.5 | Y13: 81990
D14: % utilidad | E14: NETO | F14: UTILIDAD | H14: 0 | I14: 50 | J14: SOBERBIOS | K14: =I14*H14 -> 0 | Q14: 1 | R14: CUB C/R R8 | S14: 1.08 | T14: 0.62 | U14: MADERA X DEFINIR | V14: 39990 | W14: =V14*Q14 -> 39990 | X14: =V14+$X$9 -> -1542879.5 | Y14: 39990
C15: PROYECCION | D15: 0.65 | E15: =(100%+D15)*D12 -> 277174.74 | F15: =E15-D12 -> 109190.05 | H15: 0 | I15: 10 | J15: SOPORTE REPISA | K15: =I15*H15 -> 0 | Q15: 1 | R15: CUB C/R R8 | S15: 1.08 | T15: 0.62 | U15: MADERA X DEFINIR | V15: 39990 | W15: =V15*Q15 -> 39990 | X15: =V15+$X$9 -> -1542879.5 | Y15: 39990
H16: 1 | J16: PUNTAS | K16: =I16*H16 -> 0 | Q16: 1 | R16: CUB C/R R8 | S16: 2.06 | T16: 0.62 | U16: MADERA X DEFINIR | V16: 79990 | W16: =V16*Q16 -> 79990 | X16: =V16+$X$9 -> -1502879.5 | Y16: 83990
B17: M. PRIMA | C17: MATERIAL | D17: NETO | E17: IVA | F17: TOTAL | H17: 1 | J17: TORNILLOS | K17: =I17*H17 -> 0 | Q17: 6 | R17: CORTES 45° | V17: 5000 | W17: =V17*Q17 -> 30000
C18: LAMINA | D18: =puertas!O102 -> 37500 | E18: =D18*0.19 -> 7125 | F18: =SUM(D18:E18) -> 44625 | H18: 1 | J18: COLAFRIA | K18: =I18*H18 -> 0 | Q18: 1 | R18: PERFORACION LAVAPLATOS | V18: 10000 | W18: =V18*Q18 -> 10000
C19: MDF 18MM | D19: =puertas!O101 -> 50000 | E19: =D19*0.19 -> 9500 | F19: =SUM(D19:E19) -> 59500 | H19: 1 | J19: LIJAS | K19: =I19*H19 -> 0 | V19: NETO | W19: =SUM(W11:W18) -> 472940 | Y19: =SUM(Y11:Y16)+SUM(W17:W18) -> 484940
C20: ADHESIVO | D20: =puertas!O100 -> 50650.6 | E20: =D20*0.19 -> 9623.614 | F20: =SUM(D20:E20) -> 60274.214 | H20: 1 | J20: CARTON | K20: =I20*H20 -> 0 | V20: I.V.A. | W20: =W19*19% -> 89858.6 | Y20: =Y19*0.19 -> 92138.6
A21: =450000*1.2 -> 540000 | C21: TOTAL | D21: =SUM(D18:D20) -> 138150.6 | E21: =SUM(E18:E20) -> 26248.614 | F21: =SUM(F18:F20) -> 164399.21 | H21: 1 | J21: GUAIPE | K21: =I21*H21 -> 0 | M21: =B32/9 -> 2318.8406 | Q21: PLAZO DE ENTREGA : 8 DIAS HABILES | V21: TOTAL | W21: =W19+W20 -> 562798.6 | Y21: =SUM(Y19:Y20) -> 577078.6
A22: =450000*1.2 -> 540000 | B22: M. DE OBRA | C22: PROCESO | D22: COSTO x Hr. | E22: Q Hrs. | F22: TOTAL | H22: 1 | J22: DILUYENTE | K22: =I22*H22 -> 0 | Q22: FORMA DE PAGO: 50% CONTADO, SALDO C/E
A23: =800000*1.2 -> 960000 | B23: =A21/23 -> 23478.261 | C23: CORTE | D23: =B23/9 -> 2608.6957 | E23: 0.5 | F23: =D23*E23 -> 1304.3478 | H23: 1 | J23: CINTA EMBALAJE | K23: =I23*H23 -> 0 | Q23: VALIDEZ COTIZACIÓN: 5 DIAS
A24: 450000 | B24: =A22/23 -> 23478.261 | C24: CORTE LAMINA | D24: =B24/9 -> 2608.6957 | E24: 0.5 | F24: =D24*E24 -> 1304.3478 | H24: Q/HRS | I24: PRECIO | J24: MANO DE OBRA INDIRECTA | K24: VALOR | L24: =SUM(K25:K35) -> 0
A25: 450000 | B25: =A23/23 -> 41739.13 | C25: REBAJE LAMINA | D25: =B25/9 -> 4637.6812 | F25: =D25*E25 -> 0 | H25: 0 | I25: =((480000/23)/9) -> 2318.8406 | J25: FLETERO (HRS) | K25: =H25*I25 -> 0
B26: =A24/23 -> 19565.217 | C26: TUPIZADO | D26: =B26/9 -> 2173.913 | E26: 0.5 | F26: =D26*E26 -> 1086.9565 | H26: 0 | J26: BENCINA | K26: =H26*I26 -> 0
A27: 350000 | B27: =A25/23 -> 19565.217 | C27: ARMADO | D27: =B27/9 -> 2173.913 | E27: 0.5 | F27: =D27*E27 -> 1086.9565 | H27: 0 | J27: TAG | K27: =H27*I27 -> 0
A28: 500000 | B28: =A27/23 -> 15217.391 | C28: PEGADO | D28: =B28/9 -> 1690.8213 | E28: 0.7 | F28: =D28*E28 -> 1183.5749 | H28: 0 | J28: RECTIFICACION | K28: =H28*I28 -> 0
B29: =A28/23 -> 21739.13 | C29: POSTFORMADO | D29: =B29/9 -> 2415.4589 | E29: 0.7 | F29: =D29*E29 -> 1690.8213 | H29: 0 | I29: =((550000*1.2)/23)/9 -> 3188.4058 | J29: HR. TRAB. JUAN | K29: =H29*I29 -> 0
A30: 450000 | C30: MEDIA CAÑA | D30: 2415 | F30: =D30*E30 -> 0 | H30: 0 | I30: =((450000*1.2)/23)/9 -> 2608.6957 | J30: HR. TRAB. JULIO | K30: =H30*I30 -> 0
A31: 350000 | B31: =A30/23 -> 19565.217 | C31: CORTE-ENCHAPE | D31: =B31/9 -> 2173.913 | E31: 0 | F31: =D31*E31 -> 0 | H31: 0 | I31: =((450000*1.2)/23)/9 -> 2608.6957 | J31: HR. TRAB. EUGE | K31: =H31*I31 -> 0
A32: =A21+A24+A27+A28+A30 -> 2290000 | B32: =480000/23 -> 20869.565 | C32: CONTROL CALIDAD | D32: =B32/9 -> 2318.8406 | E32: 0.5 | F32: =D32*E32 -> 1159.4203 | H32: 0 | J32: COLACION | K32: =H32*I32 -> 0
C33: TOTAL | D33: =SUM(D23:D32) -> 25216.932 | E33: =SUM(E23:E32) -> 3.9 | F33: =SUM(F23:F32) -> 8816.4251 | H33: 0 | J33: BONO | K33: =H33*I33 -> 0
B34: CIF | C34: M. PRIMA INDIREC. | D34: =L9 -> 2550 | H34: 1 | J34: PERFORACION | K34: =H34*I34 -> 0
C35: M. OBRA INDIRECTA | D35: =L24 -> 0 | H35: 6 | J35: CORTE 45 | K35: =H35*I35 -> 0
C36: GASTOS DE FABRICA | D36: =L36 -> 18467.666 | H36: CANTIDAD | I36: PRECIO | J36: GASTOS DE FABRICACION | K36: VALOR | L36: =SUM(K37:K39) -> 18467.666
C37: DEPRECIACIONES | H37: =$E$33 -> 3.9 | I37: =32609.69/9 -> 3623.2989 | J37: ARRIENDO x HORA | K37: =I37*H37 -> 14130.866
C38: TOTAL | D38: =SUM(D34:D37) -> 21017.666 | H38: =$E$33 -> 3.9 | I38: 967 | J38: AGUA x HORA | K38: =I38*H38 -> 3771.3
H39: =$E$33 -> 3.9 | I39: 145 | J39: LUZ x HORA | K39: =I39*H39 -> 565.5
B40: PROVISIONAR | C40: IVA | D40: =E11-E21 -> 1830885.9
H41: ESTADO DE RESULTADOS
B42: TOTAL HRS TRABAJADAS | D42: =E33 -> 3.9 | H42: INGRESOS | I42: + TOTAL VENTA | M42: =D11 -> 9774392
H43: COSTOS | I43: - MATERIA PRIMA DIRECTA | M43: =D21 -> 138150.6
...
