Workbook

Sheet 2229
G2: MUEBLES SANTA FE SPA
G3: VENTAS POR MENOR DE MUEBLES
G4: RUT: 77.054.606-0
G5: SEPTIMA AVENIDA 1631, SAN MIGUEL
G6: FONO 22521 6502 | O6: 10077 SF PORTLAND MAPLE
G7: E-MAIL: ventas@topmobili.cl
B8: P R E S U P U E S T O | E8: 11007
L9: 56950
B10: CLIENTE: | D10: SISTEMA | G10: FECHA: | H10: 45469 | L10: =L9/1.19 -> 47857.143
B11: RUT: | G11: PLAZO ENTREGA: | H11: 7 DIAS HABILES | R11: MT2 PUERTAS
B12: GIRO: | G12: SERVICIO EXPRESS | H12: NO
B13: CONTACTO: | D13: BARBARA
B14: CORREO: | G14: CORTADA A LA MEDIDA | H14: SI | R14: ML CUBIERTAS
B15: FONO: | D15: +569 5767 0178 | G15: DESPACHO: | H15: NO
B16: DIRECCION: | G16: FORMA DE PAGO: | H16: ABONO 50%, SALDO C/E
B17: CIUDAD: | D17: SANTIAGO | G17: DURACION COTIZACION: 5 DIAS FERNANDO DONOSO
B19: , | M19: 0.05 | N19: 0.05 | P19: TOTAL | Q19: VALOR X MT2 | R19: ENCHAPE | S19: MT/L
B20: UNIDAD | C20: CODIGO | D20: TIPO | E20: LARGO | F20: ANCHO | G20: COLOR | H20: VALOR | I20: TOTAL | L20: =B20 -> UNIDAD | M20: ALTO | N20: =F20 -> ANCHO | O20: MT | P20: MT2 | Q20: =O51 -> 96300.773 | R20: 3000 | T20: m/l
B21: 1 | C21: M001 | D21: CUB S/R FRENTE ESPAÑOL | E21: 1.32 | F21: 0.6 | G21: NATURAL ELM 1499 MT | H21: =Q21 -> 85755.838 | I21: =H21*B21 -> 85755.838 | L21: =B21 -> 1 | M21: =E21+M$19 -> 1.37 | N21: =F21+N$19 -> 0.65 | O21: =M21*N21 -> 0.8905 | P21: =O21*L21 -> 0.8905 | Q21: =Q$20*O21 -> 85755.838 | R21: =Q21+R$20 -> 88755.838 | S21: =L21*M21 -> 1.37
B22: 1 | C22: M010 | D22: CUB S/R FRENTE ESPAÑOL | E22: 1.1 | F22: 0.6 | G22: NATURAL ELM 1499 MT | H22: =Q22 -> 71984.828 | I22: =H22*B22 -> 71984.828 | L22: =B22 -> 1 | M22: =E22+M$19 -> 1.15 | N22: =F22+N$19 -> 0.65 | O22: =M22*N22 -> 0.7475 | P22: =O22*L22 -> 0.7475 | Q22: =Q$20*O22 -> 71984.828 | R22: =Q22+R$20 -> 74984.828 | S22: =L22*M22 -> 1.15
B23: 1 | C23: M011 | D23: CUB S/R FRENTE ESPAÑOL | E23: 1.6 | F23: 0.6 | G23: NATURAL ELM 1499 MT | H23: =Q23 -> 103282.58 | I23: =H23*B23 -> 103282.58 | L23: =B23 -> 1 | M23: =E23+M$19 -> 1.65 | N23: =F23+N$19 -> 0.65 | O23: =M23*N23 -> 1.0725 | P23: =O23*L23 -> 1.0725 | Q23: =Q$20*O23 -> 103282.58 | R23: =Q23+R$20 -> 106282.58 | S23: =L23*M23 -> 1.65
B24: 1 | C24: M012 | D24: CUB S/R FRENTE ESPAÑOL | E24: 2.5 | F24: 0.6 | G24: NATURAL ELM 1499 MT | H24: =Q24 -> 159618.53 | I24: =H24*B24 -> 159618.53 | L24: =B24 -> 1 | M24: =E24+M$19 -> 2.55 | N24: =F24+N$19 -> 0.65 | O24: =M24*N24 -> 1.6575 | P24: =O24*L24 -> 1.6575 | Q24: =Q$20*O24 -> 159618.53 | R24: =Q24+R$20 -> 162618.53
B25: 1 | C25: M013 | D25: CUB S/R FRENTE ESPAÑOL | E25: 1.5 | F25: 0.6 | G25: NATURAL ELM 1499 MT | H25: =Q25 -> 97023.028 | I25: =H25*B25 -> 97023.028 | L25: =B25 -> 1 | M25: =E25+M$19 -> 1.55 | N25: =F25+N$19 -> 0.65 | O25: =M25*N25 -> 1.0075 | P25: =O25*L25 -> 1.0075 | Q25: =Q$20*O25 -> 97023.028 | R25: =Q25+R$20 -> 100023.03
B26: 1 | C26: M019 | D26: CUB MESA 2 LADOS FRENTE ESPAÑOL | E26: 2 | F26: 0.85 | G26: NATURAL ELM 1499 MT | H26: =Q26 -> 177674.93 | I26: =H26*B26 -> 177674.93 | L26: =B26 -> 1 | M26: =E26+M$19 -> 2.05 | N26: =F26+N$19 -> 0.9 | O26: =M26*N26 -> 1.845 | P26: =O26*L26 -> 1.845 | Q26: =Q$20*O26 -> 177674.93 | R26: =Q26+R$20 -> 180674.93
B27: 1 | C27: M022 | D27: CUB MESA 2 LADOS FRENTE ESPAÑOL | E27: 1.233 | F27: 0.786 | G27: NATURAL ELM 1499 MT | H27: =Q27 -> 103291.05 | I27: =H27*B27 -> 103291.05 | L27: =B27 -> 1 | M27: =E27+M$19 -> 1.283 | N27: =F27+N$19 -> 0.836 | O27: =M27*N27 -> 1.072588 | P27: =O27*L27 -> 1.072588 | Q27: =Q$20*O27 -> 103291.05 | R27: =Q27+R$20 -> 106291.05
B28: 1 | C28: M022 | D28: CUB MESA 2 LADOS FRENTE ESPAÑOL | E28: 1.2 | F28: 1 | G28: NATURAL ELM 1499 MT | H28: =Q28 -> 126394.76 | I28: =H28*B28 -> 126394.76 | L28: =B28 -> 1 | M28: =E28+M$19 -> 1.25 | N28: =F28+N$19 -> 1.05 | O28: =M28*N28 -> 1.3125 | P28: =O28*L28 -> 1.3125 | Q28: =Q$20*O28 -> 126394.76 | R28: =Q28+R$20 -> 129394.76
B29: 1 | C29: M023 | D29: CUB S/R FRENTE ESPAÑOL | E29: 1.87 | F29: 0.6 | G29: NATURAL ELM 1499 MT | H29: =Q29 -> 120183.36 | I29: =H29*B29 -> 120183.36 | L29: =B29 -> 1 | M29: =E29+M$19 -> 1.92 | N29: =F29+N$19 -> 0.65 | O29: =M29*N29 -> 1.248 | P29: =O29*L29 -> 1.248 | Q29: =Q$20*O29 -> 120183.36 | R29: =Q29+R$20 -> 123183.36
B30: 1 | C30: M028 | D30: CUB S/R FRENTE ESPAÑOL | E30: 1.75 | F30: 0.6 | G30: NATURAL ELM 1499 MT | H30: =Q30 -> 112671.9 | I30: =H30*B30 -> 112671.9 | L30: =B30 -> 1 | M30: =E30+M$19 -> 1.8 | N30: =F30+N$19 -> 0.65 | O30: =M30*N30 -> 1.17 | P30: =O30*L30 -> 1.17 | Q30: =Q$20*O30 -> 112671.9 | R30: =Q30+R$20 -> 115671.9
B31: 1 | C31: M029 | D31: CUB MESA 2 LADOS FRENTE ESPAÑOL | E31: 2.4 | F31: 0.786 | G31: NATURAL ELM 1499 MT | H31: =Q31 -> 197243.24 | I31: =H31*B31 -> 197243.24 | L31: =B31 -> 1 | M31: =E31+M$19 -> 2.45 | N31: =F31+N$19 -> 0.836 | O31: =M31*N31 -> 2.0482 | P31: =O31*L31 -> 2.0482 | Q31: =Q$20*O31 -> 197243.24 | R31: =Q31+R$20 -> 200243.24
B32: 1 | C32: M029 | D32: CUB MESA 2 LADOS FRENTE ESPAÑOL | E32: 1.24 | F32: 1 | G32: NATURAL ELM 1499 MT | H32: =Q32 -> 130439.4 | I32: =H32*B32 -> 130439.4 | L32: =B32 -> 1 | M32: =E32+M$19 -> 1.29 | N32: =F32+N$19 -> 1.05 | O32: =M32*N32 -> 1.3545 | P32: =O32*L32 -> 1.3545 | Q32: =Q$20*O32 -> 130439.4 | R32: =Q32+R$20 -> 133439.4
B33: 1 | C33: M033 | D33: CUB S/R FRENTE ESPAÑOL | E33: 0.85 | F33: 0.6 | G33: NATURAL ELM 1499 MT | H33: =Q33 -> 56335.952 | I33: =H33*B33 -> 56335.952 | L33: =B33 -> 1 | M33: =E33+M$19 -> 0.9 | N33: =F33+N$19 -> 0.65 | O33: =M33*N33 -> 0.585 | P33: =O33*L33 -> 0.585 | Q33: =Q$20*O33 -> 56335.952 | R33: =Q33+R$20 -> 59335.952
B34: 1 | C34: M034 | D34: CUB S/R FRENTE ESPAÑOL | E34: 1.2 | F34: 0.6 | G34: NATURAL ELM 1499 MT | H34: =Q34 -> 78244.378 | I34: =H34*B34 -> 78244.378 | L34: =B34 -> 1 | M34: =E34+M$19 -> 1.25 | N34: =F34+N$19 -> 0.65 | O34: =M34*N34 -> 0.8125 | P34: =O34*L34 -> 0.8125 | Q34: =Q$20*O34 -> 78244.378 | R34: =Q34+R$20 -> 81244.378
B35: =SUM(B21:B34) -> 14
H37: NETO | I37: =SUM(I21:I36) -> 1620143.8 | M37: =SUM(M21:M36)-M23 -> 20.813
H38: IVA | I38: =I37*19% -> 307827.32 | P38: =SUM(P21:P34) -> 16.823788
H39: TOTAL | I39: =I37+I38 -> 1927971.1 | P39: =P38 -> 16.823788 | S39: =SUM(S21:S38) -> 4.17
K40: 32 | P40: =P39*20% -> 3.3647576 | Q40: 20% PERDIDA
K41: 32 | P41: =P39+P40 -> 20.188546 | S41: 40
K42: 55
K43: =SUM(K40:K42) -> 119 | M43: =P41 -> 20.188546 | N43: 3500 | O43: =M43*N43 -> 70659.91 | P43: ADHESIVO | Q43: TRASCARA ENCHAPADA, ES POR 2
...

Sheet COSTOS
B2: CENTRO DE COSTOS POSTFORMADOS
B5: FECHA: | C5: ='2229'!H10 -> 45469
B6: CLIENTE: | C6: ='2229'!D10 -> SISTEMA | N6: Ventas Equilibrio = | P6: Costos Fijos Totales
B7: DIRECCION: | C7: ='2229'!#REF! -> #REF! | H7: COSTOS INDIRECTOS DE FABRICA VARIABLES | O7: 1 - | P7: Costos Variables Totales
B8: PRESUPUESTO: | C8: ='2229'!E8 -> 11007 | H8: Q/HRS | I8: $ | J8: DETALLE | K8: TOTAL | L8: TOTAL | P8: Total Venta | X8: =SUM(Q11:Q16) -> 6
H9: CANTIDAD | I9: PRECIO | J9: MATERIA PRIMA INDIRECTA | L9: =SUM(K10:K23) -> 2550 | S9: DETALLE | X9: =(E15-D11)/X8 -> -197700.61
D10: NETO | E10: IVA | F10: TOTAL | H10: 3 | I10: 350 | J10: RESPALDO | K10: =I10*H10 -> 1050 | Q10: UNIDAD | R10: TIPO | S10: LARGO | T10: ANCHO | U10: COLOR | V10: VALOR | W10: TOTAL
C11: MONTO A COBRAR | D11: ='2229'!I37 -> 1620143.8 | E11: =D11*0.19 -> 307827.32 | F11: =E11+D11 -> 1927971.1 | H11: 3 | I11: 500 | J11: MEDIA CAÑA | K11: =I11*H11 -> 1500 | Q11: 1 | R11: CUB C/R R8 | S11: 2.8 | T11: 0.62 | U11: MADERA X DEFINIR | V11: 105990 | W11: =V11*Q11 -> 105990 | X11: =V11+$X$9 -> -91710.614 | Y11: 108990
C12: COSTO TOTAL | D12: =SUM(M43:M45) -> 262994 | H12: 0 | I12: 7500 | J12: DUROLAC | K12: =I12*H12 -> 0 | Q12: 1 | R12: CUB C/R R8 | S12: 2.3 | T12: 0.62 | U12: MADERA X DEFINIR | V12: 87990 | W12: =V12*Q12 -> 87990 | X12: =V12+$X$9 -> -109710.61 | Y12: 89990
C13: % UTILIDAD | D13: =D11-D12 -> 1357149.8 | E13: =(D11/D12)-1 -> 5.1603831 | H13: 0 | I13: 50 | J13: TAPACANTO PVC | K13: =I13*H13 -> 0 | Q13: 1 | R13: CUB C/R R8 | S13: 2.03 | T13: 0.62 | U13: MADERA X DEFINIR | V13: 78990 | W13: =V13*Q13 -> 78990 | X13: =V13+$X$9 -> -118710.61 | Y13: 81990
D14: % utilidad | E14: NETO | F14: UTILIDAD | H14: 0 | I14: 50 | J14: SOBERBIOS | K14: =I14*H14 -> 0 | Q14: 1 | R14: CUB C/R R8 | S14: 1.08 | T14: 0.62 | U14: MADERA X DEFINIR | V14: 39990 | W14: =V14*Q14 -> 39990 | X14: =V14+$X$9 -> -157710.61 | Y14: 39990
C15: PROYECCION | D15: 0.65 | E15: =(100%+D15)*D12 -> 433940.1 | F15: =E15-D12 -> 170946.1 | H15: 0 | I15: 10 | J15: SOPORTE REPISA | K15: =I15*H15 -> 0 | Q15: 1 | R15: CUB C/R R8 | S15: 1.08 | T15: 0.62 | U15: MADERA X DEFINIR | V15: 39990 | W15: =V15*Q15 -> 39990 | X15: =V15+$X$9 -> -157710.61 | Y15: 39990
H16: 1 | J16: PUNTAS | K16: =I16*H16 -> 0 | Q16: 1 | R16: CUB C/R R8 | S16: 2.06 | T16: 0.62 | U16: MADERA X DEFINIR | V16: 79990 | W16: =V16*Q16 -> 79990 | X16: =V16+$X$9 -> -117710.61 | Y16: 83990
B17: M. PRIMA | C17: MATERIAL | D17: NETO | E17: IVA | F17: TOTAL | H17: 1 | J17: TORNILLOS | K17: =I17*H17 -> 0 | Q17: 6 | R17: CORTES 45° | V17: 5000 | W17: =V17*Q17 -> 30000
C18: LAMINA | D18: ='2229'!O45 -> 0 | E18: =D18*0.19 -> 0 | F18: =SUM(D18:E18) -> 0 | H18: 1 | J18: COLAFRIA | K18: =I18*H18 -> 0 | Q18: 1 | R18: PERFORACION LAVAPLATOS | V18: 10000 | W18: =V18*Q18 -> 10000
C19: MDF 18MM | D19: ='2229'!O44 -> 162500 | E19: =D19*0.19 -> 30875 | F19: =SUM(D19:E19) -> 193375 | H19: 1 | J19: LIJAS | K19: =I19*H19 -> 0 | V19: NETO | W19: =SUM(W11:W18) -> 472940 | Y19: =SUM(Y11:Y16)+SUM(W17:W18) -> 484940
C20: ADHESIVO | D20: ='2229'!O43 -> 70659.91 | E20: =D20*0.19 -> 13425.383 | F20: =SUM(D20:E20) -> 84085.292 | H20: 1 | J20: CARTON | K20: =I20*H20 -> 0 | V20: I.V.A. | W20: =W19*19% -> 89858.6 | Y20: =Y19*0.19 -> 92138.6
A21: =450000*1.2 -> 540000 | C21: TOTAL | D21: =SUM(D18:D20) -> 233159.91 | E21: =SUM(E18:E20) -> 44300.383 | F21: =SUM(F18:F20) -> 277460.29 | H21: 1 | J21: GUAIPE | K21: =I21*H21 -> 0 | M21: =B32/9 -> 2318.8406 | Q21: PLAZO DE ENTREGA : 8 DIAS HABILES | V21: TOTAL | W21: =W19+W20 -> 562798.6 | Y21: =SUM(Y19:Y20) -> 577078.6
A22: =450000*1.2 -> 540000 | B22: M. DE OBRA | C22: PROCESO | D22: COSTO x Hr. | E22: Q Hrs. | F22: TOTAL | H22: 1 | J22: DILUYENTE | K22: =I22*H22 -> 0 | Q22: FORMA DE PAGO: 50% CONTADO, SALDO C/E
A23: =800000*1.2 -> 960000 | B23: =A21/23 -> 23478.261 | C23: CORTE | D23: =B23/9 -> 2608.6957 | E23: 0.5 | F23: =D23*E23 -> 1304.3478 | H23: 1 | J23: CINTA EMBALAJE | K23: =I23*H23 -> 0 | Q23: VALIDEZ COTIZACIÓN: 5 DIAS
A24: 450000 | B24: =A22/23 -> 23478.261 | C24: CORTE LAMINA | D24: =B24/9 -> 2608.6957 | E24: 0.5 | F24: =D24*E24 -> 1304.3478 | H24: Q/HRS | I24: PRECIO | J24: MANO DE OBRA INDIRECTA | K24: VALOR | L24: =SUM(K25:K35) -> 0
A25: 450000 | B25: =A23/23 -> 41739.13 | C25: REBAJE LAMINA | D25: =B25/9 -> 4637.6812 | F25: =D25*E25 -> 0 | H25: 0 | I25: =((480000/23)/9) -> 2318.8406 | J25: FLETERO (HRS) | K25: =H25*I25 -> 0
B26: =A24/23 -> 19565.217 | C26: TUPIZADO | D26: =B26/9 -> 2173.913 | E26: 0.5 | F26: =D26*E26 -> 1086.9565 | H26: 0 | J26: BENCINA | K26: =H26*I26 -> 0
A27: 350000 | B27: =A25/23 -> 19565.217 | C27: ARMADO | D27: =B27/9 -> 2173.913 | E27: 0.5 | F27: =D27*E27 -> 1086.9565 | H27: 0 | J27: TAG | K27: =H27*I27 -> 0
A28: 500000 | B28: =A27/23 -> 15217.391 | C28: PEGADO | D28: =B28/9 -> 1690.8213 | E28: 0.7 | F28: =D28*E28 -> 1183.5749 | H28: 0 | J28: RECTIFICACION | K28: =H28*I28 -> 0
B29: =A28/23 -> 21739.13 | C29: POSTFORMADO | D29: =B29/9 -> 2415.4589 | E29: 0.7 | F29: =D29*E29 -> 1690.8213 | H29: 0 | I29: =((550000*1.2)/23)/9 -> 3188.4058 | J29: HR. TRAB. JUAN | K29: =H29*I29 -> 0
A30: 450000 | C30: MEDIA CAÑA | D30: 2415 | F30: =D30*E30 -> 0 | H30: 0 | I30: =((450000*1.2)/23)/9 -> 2608.6957 | J30: HR. TRAB. JULIO | K30: =H30*I30 -> 0
A31: 350000 | B31: =A30/23 -> 19565.217 | C31: CORTE-ENCHAPE | D31: =B31/9 -> 2173.913 | E31: 0 | F31: =D31*E31 -> 0 | H31: 0 | I31: =((450000*1.2)/23)/9 -> 2608.6957 | J31: HR. TRAB. EUGE | K31: =H31*I31 -> 0
A32: =A21+A24+A27+A28+A30 -> 2290000 | B32: =480000/23 -> 20869.565 | C32: CONTROL CALIDAD | D32: =B32/9 -> 2318.8406 | E32: 0.5 | F32: =D32*E32 -> 1159.4203 | H32: 0 | J32: COLACION | K32: =H32*I32 -> 0
C33: TOTAL | D33: =SUM(D23:D32) -> 25216.932 | E33: =SUM(E23:E32) -> 3.9 | F33: =SUM(F23:F32) -> 8816.4251 | H33: 0 | J33: BONO | K33: =H33*I33 -> 0
B34: CIF | C34: M. PRIMA INDIREC. | D34: =L9 -> 2550 | H34: 1 | J34: PERFORACION | K34: =H34*I34 -> 0
C35: M. OBRA INDIRECTA | D35: =L24 -> 0 | H35: 6 | J35: CORTE 45 | K35: =H35*I35 -> 0
C36: GASTOS DE FABRICA | D36: =L36 -> 18467.666 | H36: CANTIDAD | I36: PRECIO | J36: GASTOS DE FABRICACION | K36: VALOR | L36: =SUM(K37:K39) -> 18467.666
C37: DEPRECIACIONES | H37: =$E$33 -> 3.9 | I37: =32609.69/9 -> 3623.2989 | J37: ARRIENDO x HORA | K37: =I37*H37 -> 14130.866
C38: TOTAL | D38: =SUM(D34:D37) -> 21017.666 | H38: =$E$33 -> 3.9 | I38: 967 | J38: AGUA x HORA | K38: =I38*H38 -> 3771.3
H39: =$E$33 -> 3.9 | I39: 145 | J39: LUZ x HORA | K39: =I39*H39 -> 565.5
B40: PROVISIONAR | C40: IVA | D40: =E11-E21 -> 263526.94
H41: ESTADO DE RESULTADOS
B42: TOTAL HRS TRABAJADAS | D42: =E33 -> 3.9 | H42: INGRESOS | I42: + TOTAL VENTA | M42: =D11 -> 1620143.8
H43: COSTOS | I43: - MATERIA PRIMA DIRECTA | M43: =D21 -> 233159.91
...
