Workbook

Sheet 2229 (2)
F2: MUEBLES SANTA FE SPA
F3: VENTAS POR MENOR DE MUEBLES
F4: RUT: 77.054.606-0
F5: SEPTIMA AVENIDA 1631, SAN MIGUEL
F6: FONO +569 2032 3382 | O6: 10077 SF PORTLAND MAPLE
F7: E-MAIL: ventas@topmobili.cl
B8: P R E S U P U E S T O | D8: N° 12039
B10: NOMBRE: | C10: ANGEL MIRANDA | F10: FECHA: | G10: 45639
B11: RUT: | F11: PLAZO ENTREGA: | G11: 5 DIAS HABILES | R11: MT2 PUERTAS
B12: GIRO: | F12: SERVICIO EXPRESS | G12: NO
B13: CONTACTO:
B14: CORREO: | C14: MARCOS.VARELA.575@GMAIL.COM | F14: CORTADA A LA MEDIDA | G14: NO | R14: ML CUBIERTAS
B15: FONO: | C15: +569 6575 0468 | F15: DESPACHO: | G15: NO
B16: DIRECCION: | F16: FORMA DE PAGO: | G16: ABONO 50% SALDO C/ENTREGA
B17: CIUDAD: | C17: SANTIAGO | F17: DURACION COTIZACION: 5 DIAS FRANCO DONOSO
B19: DETALLE | M19: 0.08 | P19: TOTAL | Q19: VALOR X MT2 | R19: ENCHAPE | S19: MT/L
B20: UNIDAD | C20: TIPO | D20: LARGO | E20: ANCHO | F20: COLOR | G20: VALOR | H20: TOTAL | L20: =B20 -> UNIDAD | M20: ALTO | N20: =E20 -> ANCHO | O20: MT | P20: MT2 | Q20: =O38 -> 89868.612 | R20: 5000 | T20: m/l
B21: 1 | C21: CUB C/R 90° R6 | D21: 2.7 | E21: 0.61 | F21: BELLA NOCE 10491 SF | G21: 152399 | H21: =G21*B21 -> 152399 | L21: =B21 -> 1 | M21: =D21+M$19 -> 2.78 | N21: =E21+$N$19 -> 0.61 | O21: =M21*N21 -> 1.6958 | P21: =O21*L21 -> 1.6958 | Q21: =Q$20*O21 -> 152399.19 | R21: =Q21+R$20 -> 157399.19 | S21: =L21*M21*2 -> 5.56 | T21: =N21*2*L21*2 -> 2.44
G24: NETO | H24: =H21 -> 152399 | K24: 2600000 | T24: =SUM(T21:T23) -> 2.44
G25: IVA | H25: =H24*0.19 -> 28955.81 | M25: =SUM(M21:M21) -> 2.78 | P25: =SUM(P21:P21) -> 1.6958
G26: TOTAL | H26: =H24+H25 -> 181354.81 | P26: =P25 -> 1.6958 | S26: =SUM(S21:S25) -> 5.56
P27: =P26*20% -> 0.33916 | Q27: 20% PERDIDA | S27: =S26+T24 -> 8
P28: =P26+P27 -> 2.03496 | S28: =S27*20% -> 1.6
S29: =S27+S28 -> 9.6 | U29: ADHESIVO | V29: 58.000.- | W29: 44971
M30: =P28 -> 2.03496 | N30: 3500 | O30: =M30*N30 -> 7122.36 | P30: ADHESIVO | U30: LATA 16 LTS | V30: 3625 | W30: LITRO
M31: 0.6 | N31: 25000 | O31: =M31*N31 -> 15000 | P31: MDF 18MM | V31: 906.25 | W31: MT2 (4)
B32: CUENTA CORRIENTE BANCO SANTANDER Nº 87316181 A NOMBRE DE MUEBLES SANTA FE SPA | N32: 71000 | O32: =M32*N32 -> 0 | P32: LAMINA 153 X 366 | V32: =V31*20% -> 181.25 | W32: PERDIDA 20%
B33: RUT : 77.054.606-0 VENTAS@TOPMOBILI.CL | M33: 1 | N33: 43100 | O33: =M33*N33 -> 43100 | P33: LAMINA 122X244 | V33: =V31+V32 -> 1087.5 | W33: MINIMO A COTIZAR
B34: VISITANOS Y DESCUBRE NUESTROS PRODUCTOS EN | F34: WWW.TOPMOBILICHILE.CL | N34: 900 | O34: =M34*N34 -> 0 | P34: RESPALDO | R34: 1.52
M35: 2.7 | N35: 1500 | O35: =M35*N35 -> 4050 | P35: MEDIA CAÑA | R35: 2.44
O36: =SUM(O30:O35) -> 69272.36 | P36: COSTO | R36: =R34*R35 -> 3.7088
M37: PRECIO VENTA | O37: =O36*2.2 -> 152399.19 | P37: FACTOR 2,3 PARA 90° | R37: =P28/R36 -> 0.54868421
K38: 59760 | O38: =O37/P26 -> 89868.612 | P38: VALOR M2 | U38: MDF30MM | V38: 43650
K39: =K38/1.19 -> 50218.487 | O39: =O37/O36 -> 2.2 | U39: 46 UNIDADES | V39: 948.91 | W39: 2.4
U40: METRO LINEAL | V40: 395.37
U41: PERDIDA 20% | V41: 474.45
O48: 40935 | P48: MT2 | Q48: TERMO WOOD
C73: ,,,,,,,,,,,,,,,,,,,,,,,,,,,,,,,,,,,,,,,,,,,,,,,,,,,,,,,,,,,,,,,,,,,,,,,,,,,,,,,,,,,,,,,,,,,,,,,,,,,,,,,,,,,,,,,,,,,,,,,,,,,,,,,,,,,,,,,,,,,,,,,,,,,,,,,,,,,,,,,,,,,,,,,,,,,,,,,,,,,,,,,,,,,,,,,,,,,,,,,,,,,,,,,,,,,,,,,,,,,,,,,,,,,,,,,,,,,,,,,,,,,,,,,,,,,,,,,,,,,,,
C74: ,
C77: ,
...

Sheet 2229
F2: MUEBLES SANTA FE SPA
F3: VENTAS POR MENOR DE MUEBLES
F4: RUT: 77.054.606-0
F5: SEPTIMA AVENIDA 1631, SAN MIGUEL
F6: FONO +569 2032 3382 | O6: 10077 SF PORTLAND MAPLE
F7: E-MAIL: ventas@topmobili.cl
B8: P R E S U P U E S T O | D8: N° 11185
B10: NOMBRE: | C10: ANGEL MIRANDA | F10: FECHA: | G10: 45623
B11: RUT: | F11: PLAZO ENTREGA: | G11: 5 DIAS HABILES | R11: MT2 PUERTAS
B12: GIRO: | F12: SERVICIO EXPRESS | G12: NO
B13: CONTACTO:
B14: CORREO: | F14: CORTADA A LA MEDIDA | G14: SI | R14: ML CUBIERTAS
B15: FONO: | F15: DESPACHO: | G15: NO
B16: DIRECCION: | F16: FORMA DE PAGO: | G16: ABONO 50% SALDO C/ENTREGA
B17: CIUDAD: | C17: SANTIAGO | F17: DURACION COTIZACION: 5 DIAS FRANCO DONOSO
B19: DETALLE | M19: 0.08 | P19: TOTAL | Q19: VALOR X MT2 | R19: ENCHAPE | S19: MT/L
B20: UNIDAD | C20: TIPO | D20: LARGO | E20: ANCHO | F20: COLOR | G20: VALOR | H20: TOTAL | L20: =B20 -> UNIDAD | M20: ALTO | N20: =E20 -> ANCHO | O20: MT | P20: MT2 | Q20: =O38 -> 81423.04 | R20: 5000 | T20: m/l
B21: 1 | C21: CUB C/R 90° R6 | D21: 2.7 | E21: 0.61 | F21: MOUSE 2193 | G21: 138077 | H21: =G21*B21 -> 138077 | L21: =B21 -> 1 | M21: =D21+M$19 -> 2.78 | N21: =E21+$N$19 -> 0.61 | O21: =M21*N21 -> 1.6958 | P21: =O21*L21 -> 1.6958 | Q21: =Q$20*O21 -> 138077.19 | R21: =Q21+R$20 -> 143077.19 | S21: =L21*M21*2 -> 5.56 | T21: =N21*2*L21*2 -> 2.44
G24: NETO | H24: =H21 -> 138077 | K24: 2600000 | T24: =SUM(T21:T23) -> 2.44
G25: IVA | H25: =H24*0.19 -> 26234.63 | M25: =SUM(M21:M21) -> 2.78 | P25: =SUM(P21:P21) -> 1.6958
G26: TOTAL | H26: =H24+H25 -> 164311.63 | P26: =P25 -> 1.6958 | S26: =SUM(S21:S25) -> 5.56
P27: =P26*20% -> 0.33916 | Q27: 20% PERDIDA | S27: =S26+T24 -> 8
P28: =P26+P27 -> 2.03496 | S28: =S27*20% -> 1.6
S29: =S27+S28 -> 9.6 | U29: ADHESIVO | V29: 58.000.- | W29: 44971
M30: =P28 -> 2.03496 | N30: 3500 | O30: =M30*N30 -> 7122.36 | P30: ADHESIVO | U30: LATA 16 LTS | V30: 3625 | W30: LITRO
M31: 0.6 | N31: 25000 | O31: =M31*N31 -> 15000 | P31: MDF 18MM | V31: 906.25 | W31: MT2 (4)
B32: CUENTA CORRIENTE BANCO SANTANDER Nº 87316181 A NOMBRE DE MUEBLES SANTA FE SPA | N32: 71000 | O32: =M32*N32 -> 0 | P32: LAMINA 153 X 366 | V32: =V31*20% -> 181.25 | W32: PERDIDA 20%
B33: RUT : 77.054.606-0 VENTAS@TOPMOBILI.CL | M33: 1 | N33: 36590 | O33: =M33*N33 -> 36590 | P33: LAMINA 122X244 | V33: =V31+V32 -> 1087.5 | W33: MINIMO A COTIZAR
B34: VISITANOS Y DESCUBRE NUESTROS PRODUCTOS EN | F34: WWW.TOPMOBILICHILE.CL | N34: 900 | O34: =M34*N34 -> 0 | P34: RESPALDO | R34: 1.52
M35: 2.7 | N35: 1500 | O35: =M35*N35 -> 4050 | P35: MEDIA CAÑA | R35: 2.44
O36: =SUM(O30:O35) -> 62762.36 | P36: COSTO | R36: =R34*R35 -> 3.7088
M37: PRECIO VENTA | O37: =O36*2.2 -> 138077.19 | P37: FACTOR 2,3 PARA 90° | R37: =P28/R36 -> 0.54868421
K38: 59760 | O38: =O37/P26 -> 81423.04 | P38: VALOR M2 | U38: MDF30MM | V38: 43650
K39: =K38/1.19 -> 50218.487 | O39: =O37/O36 -> 2.2 | U39: 46 UNIDADES | V39: 948.91 | W39: 2.4
U40: METRO LINEAL | V40: 395.37
U41: PERDIDA 20% | V41: 474.45
O48: 40935 | P48: MT2 | Q48: TERMO WOOD
C73: ,,,,,,,,,,,,,,,,,,,,,,,,,,,,,,,,,,,,,,,,,,,,,,,,,,,,,,,,,,,,,,,,,,,,,,,,,,,,,,,,,,,,,,,,,,,,,,,,,,,,,,,,,,,,,,,,,,,,,,,,,,,,,,,,,,,,,,,,,,,,,,,,,,,,,,,,,,,,,,,,,,,,,,,,,,,,,,,,,,,,,,,,,,,,,,,,,,,,,,,,,,,,,,,,,,,,,,,,,,,,,,,,,,,,,,,,,,,,,,,,,,,,,,,,,,,,,,,,,,,,,
C74: ,
C77: ,
...

Sheet COSTOS
B2: CENTRO DE COSTOS POSTFORMADOS
B5: FECHA: | C5: ='2229'!G10 -> 45623
B6: CLIENTE: | C6: ='2229'!C10 -> ANGEL MIRANDA | N6: Ventas Equilibrio = | P6: Costos Fijos Totales
B7: DIRECCION: | C7: ='2229'!#REF! -> #REF! | H7: COSTOS INDIRECTOS DE FABRICA VARIABLES | O7: 1 - | P7: Costos Variables Totales
B8: PRESUPUESTO: | C8: ='2229'!D8 -> N° 11185 | H8: Q/HRS | I8: $ | J8: DETALLE | K8: TOTAL | L8: TOTAL | P8: Total Venta | X8: =SUM(Q11:Q16) -> 6
H9: CANTIDAD | I9: PRECIO | J9: MATERIA PRIMA INDIRECTA | L9: =SUM(K10:K23) -> 2550 | S9: DETALLE | X9: =(E15-D11)/X8 -> -8724.8094
D10: NETO | E10: IVA | F10: TOTAL | H10: 3 | I10: 350 | J10: RESPALDO | K10: =I10*H10 -> 1050 | Q10: UNIDAD | R10: TIPO | S10: LARGO | T10: ANCHO | U10: COLOR | V10: VALOR | W10: TOTAL
C11: MONTO A COBRAR | D11: ='2229'!H24 -> 138077 | E11: =D11*0.19 -> 26234.63 | F11: =E11+D11 -> 164311.63 | H11: 3 | I11: 500 | J11: MEDIA CAÑA | K11: =I11*H11 -> 1500 | Q11: 1 | R11: CUB C/R R8 | S11: 2.8 | T11: 0.62 | U11: MADERA X DEFINIR | V11: 105990 | W11: =V11*Q11 -> 105990 | X11: =V11+$X$9 -> 97265.191 | Y11: 108990
C12: COSTO TOTAL | D12: =SUM(M43:M45) -> 51956.451 | H12: 0 | I12: 7500 | J12: DUROLAC | K12: =I12*H12 -> 0 | Q12: 1 | R12: CUB C/R R8 | S12: 2.3 | T12: 0.62 | U12: MADERA X DEFINIR | V12: 87990 | W12: =V12*Q12 -> 87990 | X12: =V12+$X$9 -> 79265.191 | Y12: 89990
C13: % UTILIDAD | D13: =D11-D12 -> 86120.549 | E13: =(D11/D12)-1 -> 1.6575526 | H13: 0 | I13: 50 | J13: TAPACANTO PVC | K13: =I13*H13 -> 0 | Q13: 1 | R13: CUB C/R R8 | S13: 2.03 | T13: 0.62 | U13: MADERA X DEFINIR | V13: 78990 | W13: =V13*Q13 -> 78990 | X13: =V13+$X$9 -> 70265.191 | Y13: 81990
D14: % utilidad | E14: NETO | F14: UTILIDAD | H14: 0 | I14: 50 | J14: SOBERBIOS | K14: =I14*H14 -> 0 | Q14: 1 | R14: CUB C/R R8 | S14: 1.08 | T14: 0.62 | U14: MADERA X DEFINIR | V14: 39990 | W14: =V14*Q14 -> 39990 | X14: =V14+$X$9 -> 31265.191 | Y14: 39990
C15: PROYECCION | D15: 0.65 | E15: =(100%+D15)*D12 -> 85728.144 | F15: =E15-D12 -> 33771.693 | H15: 0 | I15: 10 | J15: SOPORTE REPISA | K15: =I15*H15 -> 0 | Q15: 1 | R15: CUB C/R R8 | S15: 1.08 | T15: 0.62 | U15: MADERA X DEFINIR | V15: 39990 | W15: =V15*Q15 -> 39990 | X15: =V15+$X$9 -> 31265.191 | Y15: 39990
H16: 1 | J16: PUNTAS | K16: =I16*H16 -> 0 | Q16: 1 | R16: CUB C/R R8 | S16: 2.06 | T16: 0.62 | U16: MADERA X DEFINIR | V16: 79990 | W16: =V16*Q16 -> 79990 | X16: =V16+$X$9 -> 71265.191 | Y16: 83990
B17: M. PRIMA | C17: MATERIAL | D17: NETO | E17: IVA | F17: TOTAL | H17: 1 | J17: TORNILLOS | K17: =I17*H17 -> 0 | Q17: 6 | R17: CORTES 45° | V17: 5000 | W17: =V17*Q17 -> 30000
C18: LAMINA | D18: ='2229'!O32 -> 0 | E18: =D18*0.19 -> 0 | F18: =SUM(D18:E18) -> 0 | H18: 1 | J18: COLAFRIA | K18: =I18*H18 -> 0 | Q18: 1 | R18: PERFORACION LAVAPLATOS | V18: 10000 | W18: =V18*Q18 -> 10000
C19: MDF 18MM | D19: ='2229'!O31 -> 15000 | E19: =D19*0.19 -> 2850 | F19: =SUM(D19:E19) -> 17850 | H19: 1 | J19: LIJAS | K19: =I19*H19 -> 0 | V19: NETO | W19: =SUM(W11:W18) -> 472940 | Y19: =SUM(Y11:Y16)+SUM(W17:W18) -> 484940
C20: ADHESIVO | D20: ='2229'!O30 -> 7122.36 | E20: =D20*0.19 -> 1353.2484 | F20: =SUM(D20:E20) -> 8475.6084 | H20: 1 | J20: CARTON | K20: =I20*H20 -> 0 | V20: I.V.A. | W20: =W19*19% -> 89858.6 | Y20: =Y19*0.19 -> 92138.6
A21: =450000*1.2 -> 540000 | C21: TOTAL | D21: =SUM(D18:D20) -> 22122.36 | E21: =SUM(E18:E20) -> 4203.2484 | F21: =SUM(F18:F20) -> 26325.608 | H21: 1 | J21: GUAIPE | K21: =I21*H21 -> 0 | M21: =B32/9 -> 2318.8406 | Q21: PLAZO DE ENTREGA : 8 DIAS HABILES | V21: TOTAL | W21: =W19+W20 -> 562798.6 | Y21: =SUM(Y19:Y20) -> 577078.6
A22: =450000*1.2 -> 540000 | B22: M. DE OBRA | C22: PROCESO | D22: COSTO x Hr. | E22: Q Hrs. | F22: TOTAL | H22: 1 | J22: DILUYENTE | K22: =I22*H22 -> 0 | Q22: FORMA DE PAGO: 50% CONTADO, SALDO C/E
A23: =800000*1.2 -> 960000 | B23: =A21/23 -> 23478.261 | C23: CORTE | D23: =B23/9 -> 2608.6957 | E23: 0.5 | F23: =D23*E23 -> 1304.3478 | H23: 1 | J23: CINTA EMBALAJE | K23: =I23*H23 -> 0 | Q23: VALIDEZ COTIZACIÓN: 5 DIAS
A24: 450000 | B24: =A22/23 -> 23478.261 | C24: CORTE LAMINA | D24: =B24/9 -> 2608.6957 | E24: 0.5 | F24: =D24*E24 -> 1304.3478 | H24: Q/HRS | I24: PRECIO | J24: MANO DE OBRA INDIRECTA | K24: VALOR | L24: =SUM(K25:K35) -> 0
A25: 450000 | B25: =A23/23 -> 41739.13 | C25: REBAJE LAMINA | D25: =B25/9 -> 4637.6812 | F25: =D25*E25 -> 0 | H25: 0 | I25: =((480000/23)/9) -> 2318.8406 | J25: FLETERO (HRS) | K25: =H25*I25 -> 0
B26: =A24/23 -> 19565.217 | C26: TUPIZADO | D26: =B26/9 -> 2173.913 | E26: 0.5 | F26: =D26*E26 -> 1086.9565 | H26: 0 | J26: BENCINA | K26: =H26*I26 -> 0
A27: 350000 | B27: =A25/23 -> 19565.217 | C27: ARMADO | D27: =B27/9 -> 2173.913 | E27: 0.5 | F27: =D27*E27 -> 1086.9565 | H27: 0 | J27: TAG | K27: =H27*I27 -> 0
A28: 500000 | B28: =A27/23 -> 15217.391 | C28: PEGADO | D28: =B28/9 -> 1690.8213 | E28: 0.7 | F28: =D28*E28 -> 1183.5749 | H28: 0 | J28: RECTIFICACION | K28: =H28*I28 -> 0
B29: =A28/23 -> 21739.13 | C29: POSTFORMADO | D29: =B29/9 -> 2415.4589 | E29: 0.7 | F29: =D29*E29 -> 1690.8213 | H29: 0 | I29: =((550000*1.2)/23)/9 -> 3188.4058 | J29: HR. TRAB. JUAN | K29: =H29*I29 -> 0
A30: 450000 | C30: MEDIA CAÑA | D30: 2415 | F30: =D30*E30 -> 0 | H30: 0 | I30: =((450000*1.2)/23)/9 -> 2608.6957 | J30: HR. TRAB. JULIO | K30: =H30*I30 -> 0
A31: 350000 | B31: =A30/23 -> 19565.217 | C31: CORTE-ENCHAPE | D31: =B31/9 -> 2173.913 | E31: 0 | F31: =D31*E31 -> 0 | H31: 0 | I31: =((450000*1.2)/23)/9 -> 2608.6957 | J31: HR. TRAB. EUGE | K31: =H31*I31 -> 0
A32: =A21+A24+A27+A28+A30 -> 2290000 | B32: =480000/23 -> 20869.565 | C32: CONTROL CALIDAD | D32: =B32/9 -> 2318.8406 | E32: 0.5 | F32: =D32*E32 -> 1159.4203 | H32: 0 | J32: COLACION | K32: =H32*I32 -> 0
C33: TOTAL | D33: =SUM(D23:D32) -> 25216.932 | E33: =SUM(E23:E32) -> 3.9 | F33: =SUM(F23:F32) -> 8816.4251 | H33: 0 | J33: BONO | K33: =H33*I33 -> 0
B34: CIF | C34: M. PRIMA INDIREC. | D34: =L9 -> 2550 | H34: 1 | J34: PERFORACION | K34: =H34*I34 -> 0
C35: M. OBRA INDIRECTA | D35: =L24 -> 0 | H35: 6 | J35: CORTE 45 | K35: =H35*I35 -> 0
C36: GASTOS DE FABRICA | D36: =L36 -> 18467.666 | H36: CANTIDAD | I36: PRECIO | J36: GASTOS DE FABRICACION | K36: VALOR | L36: =SUM(K37:K39) -> 18467.666
C37: DEPRECIACIONES | H37: =$E$33 -> 3.9 | I37: =32609.69/9 -> 3623.2989 | J37: ARRIENDO x HORA | K37: =I37*H37 -> 14130.866
C38: TOTAL | D38: =SUM(D34:D37) -> 21017.666 | H38: =$E$33 -> 3.9 | I38: 967 | J38: AGUA x HORA | K38: =I38*H38 -> 3771.3
H39: =$E$33 -> 3.9 | I39: 145 | J39: LUZ x HORA | K39: =I39*H39 -> 565.5
B40: PROVISIONAR | C40: IVA | D40: =E11-E21 -> 22031.382
H41: ESTADO DE RESULTADOS
B42: TOTAL HRS TRABAJADAS | D42: =E33 -> 3.9 | H42: INGRESOS | I42: + TOTAL VENTA | M42: =D11 -> 138077
H43: COSTOS | I43: - MATERIA PRIMA DIRECTA | M43: =D21 -> 22122.36
...
