Workbook

Sheet 2229
F2: MUEBLES SANTA FE SPA
F3: VENTAS POR MENOR DE MUEBLES
F4: RUT: 77.054.606-0
F5: SEPTIMA AVENIDA 1631, SAN MIGUEL
F6: FONO +569 2032 3382 | O6: 10077 SF PORTLAND MAPLE
F7: E-MAIL: ventas@topmobili.cl
B8: P R E S U P U E S T O | D8: N° 11821
B10: NOMBRE: | C10: FCA. DE MUEBLES ALVEAR Y ALVEAR LTDA | F10: FECHA | G10: 46028
B11: RUT: | C11: 76.143.978-2 | F11: PLAZO ENTREGA | G11: 5 DIAS HABILES | R11: MT2 PUERTAS
B12: GIRO: | C12: FCA DE MUEBLES | F12: SERVICIO EXPRESS | G12: NO
B13: CONTACTO: | C13: CLAUDIO ALVEAR | F13: CORTADA A LA MEDIDA | G13: NO
B14: CORREO: | C14: LINEALTA1 | F14: DESPACHO | G14: NO | R14: ML CUBIERTAS
B15: FONO: | C15: 56973069852 | F15: INSTALACIÓN | G15: NO
B16: DIRECCION: | C16: ROSA ESTER 03281 LA PINTANA | F16: FORMA DE PAGO: | G16: ABONO 50% SALDO C/ENTREGA
B17: CIUDAD: | C17: SANTIAGO | F17: Duración cotización 5 días hábiles | G17: Cotizado por: Franco Donoso
B19: DETALLE | M19: 0.08 | P19: TOTAL | Q19: VALOR X MT2 | R19: ENCHAPE | S19: MT/L
B20: UNIDAD | C20: TIPO | D20: LARGO | E20: ANCHO | F20: COLOR | G20: VALOR | H20: TOTAL | L20: =B20 -> UNIDAD | M20: ALTO | N20: =E20 -> ANCHO | O20: MT | P20: MT2 | Q20: =O49 -> 81949.837 | R20: 3000 | T20: m/l
B21: 5 | C21: CUB S/R 180° | D21: 1.1 | E21: 0.45 | F21: NIEBLA 2191 MT | G21: 42102 | H21: =G21*B21 -> 210510 | M21: =D21+M$19 -> 1.18 | N21: =E21+$N$19 -> 0.45 | O21: =M21*N21 -> 0.531 | P21: =O21*L21 -> 0 | Q21: =Q$20*O21 -> 43515.363 | R21: =Q21+R$20 -> 46515.363 | S21: =M21*L21 -> 0 | T21: =N21*2*L21*2 -> 0
B22: 1 | C22: CUB MESA 180° 2 LADOS | D22: 2.41 | E22: 0.6 | F22: VAINILLA 2109 MT | G22: 125433 | H22: =G22*B22 -> 125433 | L22: 1 | M22: =D22+M$19 -> 2.49 | N22: =E22+$N$19 -> 0.6 | O22: =M22*N22 -> 1.494 | P22: =O22*L22 -> 1.494 | Q22: =Q$20*O22 -> 122433.06 | R22: =Q22+R$20 -> 125433.06 | S22: =M22*L22 -> 2.49
B23: 1 | C23: CUB S/R 180° | D23: 1.73 | E23: 0.6 | F23: VAINILLA 2109 MT | G23: 91998 | H23: =G23*B23 -> 91998 | L23: 1 | M23: =D23+M$19 -> 1.81 | N23: =E23+$N$19 -> 0.6 | O23: =M23*N23 -> 1.086 | P23: =O23*L23 -> 1.086 | Q23: =Q$20*O23 -> 88997.523 | R23: =Q23+R$20 -> 91997.523 | S23: =M23*L23 -> 1.81
B24: 1 | C24: CUB S/R 180° | D24: 2.5 | E24: 0.6 | F24: NIEBLA 2191 MT | G24: 116992 | H24: =G24*B24 -> 116992 | M24: =D24+M$19 -> 2.58 | N24: =E24+$N$19 -> 0.6 | O24: =M24*N24 -> 1.548 | P24: =O24*L24 -> 0 | Q24: =Q$20*O24 -> 126858.35 | R24: =Q24+R$20 -> 129858.35 | S24: =M24*L24 -> 0
B25: 1 | C25: RESPALDO R8 | D25: 2.5 | E25: 0.06 | F25: NIEBLA 2191 MT | G25: 14399 | H25: =G25*B25 -> 14399 | M25: =D25+M$19 -> 2.58 | N25: =E25+$N$19 -> 0.06 | O25: =M25*N25 -> 0.1548 | P25: =O25*L25 -> 0 | Q25: =Q$20*O25 -> 12685.835 | R25: =Q25+R$20 -> 15685.835 | S25: =M25*L25 -> 0
B26: 1 | C26: CUB MESA 180° 2 LADOS | D26: 1.25 | E26: 0.5 | F26: VAINILLA 2109 MT | G26: 57497 | H26: =G26*B26 -> 57497 | L26: 1 | M26: =D26+M$19 -> 1.33 | N26: =E26+$N$19 -> 0.5 | O26: =M26*N26 -> 0.665 | P26: =O26*L26 -> 0.665 | Q26: =Q$20*O26 -> 54496.642 | R26: =Q26+R$20 -> 57496.642 | S26: =M26*L26 -> 1.33
B27: 1 | C27: CUB MESA 180° 2 LADOS | D27: 1.4 | E27: 0.5 | F27: VAINILLA 2109 MT | G27: 63643 | H27: =G27*B27 -> 63643 | L27: 1 | M27: =D27+M$19 -> 1.48 | N27: =E27+$N$19 -> 0.5 | O27: =M27*N27 -> 0.74 | P27: =O27*L27 -> 0.74 | Q27: =Q$20*O27 -> 60642.879 | R27: =Q27+R$20 -> 63642.879 | S27: =M27*L27 -> 1.48
B28: 2 | C28: CORTE 45° | G28: 15000 | H28: =G28*B28 -> 30000 | M28: =D28+M$19 -> 0.08 | N28: =E28+$N$19 -> 0 | O28: =M28*N28 -> 0 | P28: =O28*L28 -> 0 | Q28: =Q$20*O28 -> 0 | R28: =Q28+R$20 -> 3000 | S28: =M28*L28 -> 0
B29: 1 | C29: CUB S/R 180° | D29: 1.76 | E29: 0.6 | F29: NIEBLA 2191 MT | G29: 84297 | H29: =G29*B29 -> 84297 | M29: =D29+M$19 -> 1.84 | N29: =E29+$N$19 -> 0.6 | O29: =M29*N29 -> 1.104 | P29: =O29*L29 -> 0 | Q29: =Q$20*O29 -> 90472.62 | R29: =Q29+R$20 -> 93472.62 | S29: =M29*L29 -> 0
B30: 1 | C30: RESPALDO R8 | D30: 1.76 | E30: 0.06 | F30: NIEBLA 2191 MT | G30: 11130 | H30: =G30*B30 -> 11130 | M30: =D30+M$19 -> 1.84 | N30: =E30+$N$19 -> 0.06 | O30: =M30*N30 -> 0.1104 | P30: =O30*L30 -> 0 | Q30: =Q$20*O30 -> 9047.262 | R30: =Q30+R$20 -> 12047.262 | S30: =M30*L30 -> 0
G35: NETO | H35: =SUM(H21:H32) -> 805899 | T35: =SUM(T21:T32) -> 0
G36: IVA | H36: =H35*19% -> 153120.81 | K36: 450 | M36: =SUM(M21:M35) -> 17.21 | P36: =SUM(P21:P30) -> 3.985
G37: TOTAL | H37: =H35+H36 -> 959019.81 | K37: 60 | P37: =P36 -> 3.985 | S37: =SUM(S21:S36) -> 7.11
K38: =SUM(K36:K37) -> 510 | P38: =P37*20% -> 0.797 | Q38: 20% PERDIDA | S38: =S37+T35 -> 7.11
P39: =P37+P38 -> 4.782 | S39: =S38*20% -> 1.422
K40: 600 | S40: =S38+S39 -> 8.532 | U40: ADHESIVO | V40: 58.000.- | W40: 44971
K41: 60 | M41: =P39 -> 4.782 | N41: 3500 | O41: =M41*N41 -> 16737 | P41: ADHESIVO | U41: LATA 16 LTS | V41: 3625 | W41: LITRO
K42: =SUM(K40:K41) -> 660 | M42: 1.5 | N42: 23500 | O42: =M42*N42 -> 35250 | P42: MDF 18MM | V42: 906.25 | W42: MT2 (4)
B43: CUENTA CORRIENTE BANCO SANTANDER Nº 87316181 A NOMBRE DE MUEBLES SANTA FE SPA | N43: 58860 | O43: =M43*N43 -> 0 | P43: LAMINA 153 X 366 | V43: =V42*20% -> 181.25 | W43: PERDIDA 20%
B44: RUT : 77.054.606-0 CORREO: FRANCODONOSO@TOPMOBILI.CL | K44: =K38+K42 -> 1170 | M44: 3 | N44: 30000 | O44: =M44*N44 -> 90000 | P44: LAMINA 122X244 | V44: =V42+V43 -> 1087.5 | W44: MINIMO A COTIZAR
A45: GE | B45: VISITANOS Y DESCUBRE NUESTROS PRODUCTOS EN | F45: WWW.TOPMOBILICHILE.CL | N45: 900 | O45: =M45*N45 -> 0 | P45: RESPALDO | R45: 1.52
N46: 1500 | O46: =M46*N46 -> 0 | P46: MEDIA CAÑA | R46: 2.44
O47: =SUM(O41:O46) -> 141987 | P47: COSTO | R47: =R45*R46 -> 3.7088
...

Sheet COSTOS
B2: CENTRO DE COSTOS POSTFORMADOS
B5: FECHA: | C5: ='2229'!G10 -> 46028
B6: CLIENTE: | C6: ='2229'!C10 -> FCA. DE MUEBLES ALVEAR Y ALVEAR LTDA | N6: Ventas Equilibrio = | P6: Costos Fijos Totales
B7: DIRECCION: | C7: ='2229'!#REF! -> #REF! | H7: COSTOS INDIRECTOS DE FABRICA VARIABLES | O7: 1 - | P7: Costos Variables Totales
B8: PRESUPUESTO: | C8: ='2229'!D8 -> N° 11821 | H8: Q/HRS | I8: $ | J8: DETALLE | K8: TOTAL | L8: TOTAL | P8: Total Venta | X8: =SUM(Q11:Q16) -> 6
H9: CANTIDAD | I9: PRECIO | J9: MATERIA PRIMA INDIRECTA | L9: =SUM(K10:K23) -> 2550 | S9: DETALLE | X9: =(E15-D11)/X8 -> -111815.7
D10: NETO | E10: IVA | F10: TOTAL | H10: 3 | I10: 350 | J10: RESPALDO | K10: =I10*H10 -> 1050 | Q10: UNIDAD | R10: TIPO | S10: LARGO | T10: ANCHO | U10: COLOR | V10: VALOR | W10: TOTAL
C11: MONTO A COBRAR | D11: ='2229'!H35 -> 805899 | E11: =D11*0.19 -> 153120.81 | F11: =E11+D11 -> 959019.81 | H11: 3 | I11: 500 | J11: MEDIA CAÑA | K11: =I11*H11 -> 1500 | Q11: 1 | R11: CUB C/R R8 | S11: 2.8 | T11: 0.62 | U11: MADERA X DEFINIR | V11: 105990 | W11: =V11*Q11 -> 105990 | X11: =V11+$X$9 -> -5825.7 | Y11: 108990
C12: COSTO TOTAL | D12: =SUM(M43:M45) -> 81821.091 | H12: 0 | I12: 7500 | J12: DUROLAC | K12: =I12*H12 -> 0 | Q12: 1 | R12: CUB C/R R8 | S12: 2.3 | T12: 0.62 | U12: MADERA X DEFINIR | V12: 87990 | W12: =V12*Q12 -> 87990 | X12: =V12+$X$9 -> -23825.7 | Y12: 89990
C13: % UTILIDAD | D13: =D11-D12 -> 724077.91 | E13: =(D11/D12)-1 -> 8.8495265 | H13: 0 | I13: 50 | J13: TAPACANTO PVC | K13: =I13*H13 -> 0 | Q13: 1 | R13: CUB C/R R8 | S13: 2.03 | T13: 0.62 | U13: MADERA X DEFINIR | V13: 78990 | W13: =V13*Q13 -> 78990 | X13: =V13+$X$9 -> -32825.7 | Y13: 81990
D14: % utilidad | E14: NETO | F14: UTILIDAD | H14: 0 | I14: 50 | J14: SOBERBIOS | K14: =I14*H14 -> 0 | Q14: 1 | R14: CUB C/R R8 | S14: 1.08 | T14: 0.62 | U14: MADERA X DEFINIR | V14: 39990 | W14: =V14*Q14 -> 39990 | X14: =V14+$X$9 -> -71825.7 | Y14: 39990
C15: PROYECCION | D15: 0.65 | E15: =(100%+D15)*D12 -> 135004.8 | F15: =E15-D12 -> 53183.709 | H15: 0 | I15: 10 | J15: SOPORTE REPISA | K15: =I15*H15 -> 0 | Q15: 1 | R15: CUB C/R R8 | S15: 1.08 | T15: 0.62 | U15: MADERA X DEFINIR | V15: 39990 | W15: =V15*Q15 -> 39990 | X15: =V15+$X$9 -> -71825.7 | Y15: 39990
H16: 1 | J16: PUNTAS | K16: =I16*H16 -> 0 | Q16: 1 | R16: CUB C/R R8 | S16: 2.06 | T16: 0.62 | U16: MADERA X DEFINIR | V16: 79990 | W16: =V16*Q16 -> 79990 | X16: =V16+$X$9 -> -31825.7 | Y16: 83990
B17: M. PRIMA | C17: MATERIAL | D17: NETO | E17: IVA | F17: TOTAL | H17: 1 | J17: TORNILLOS | K17: =I17*H17 -> 0 | Q17: 6 | R17: CORTES 45° | V17: 5000 | W17: =V17*Q17 -> 30000
C18: LAMINA | D18: ='2229'!O43 -> 0 | E18: =D18*0.19 -> 0 | F18: =SUM(D18:E18) -> 0 | H18: 1 | J18: COLAFRIA | K18: =I18*H18 -> 0 | Q18: 1 | R18: PERFORACION LAVAPLATOS | V18: 10000 | W18: =V18*Q18 -> 10000
C19: MDF 18MM | D19: ='2229'!O42 -> 35250 | E19: =D19*0.19 -> 6697.5 | F19: =SUM(D19:E19) -> 41947.5 | H19: 1 | J19: LIJAS | K19: =I19*H19 -> 0 | V19: NETO | W19: =SUM(W11:W18) -> 472940 | Y19: =SUM(Y11:Y16)+SUM(W17:W18) -> 484940
C20: ADHESIVO | D20: ='2229'!O41 -> 16737 | E20: =D20*0.19 -> 3180.03 | F20: =SUM(D20:E20) -> 19917.03 | H20: 1 | J20: CARTON | K20: =I20*H20 -> 0 | V20: I.V.A. | W20: =W19*19% -> 89858.6 | Y20: =Y19*0.19 -> 92138.6
A21: =450000*1.2 -> 540000 | C21: TOTAL | D21: =SUM(D18:D20) -> 51987 | E21: =SUM(E18:E20) -> 9877.53 | F21: =SUM(F18:F20) -> 61864.53 | H21: 1 | J21: GUAIPE | K21: =I21*H21 -> 0 | M21: =B32/9 -> 2318.8406 | Q21: PLAZO DE ENTREGA : 8 DIAS HABILES | V21: TOTAL | W21: =W19+W20 -> 562798.6 | Y21: =SUM(Y19:Y20) -> 577078.6
A22: =450000*1.2 -> 540000 | B22: M. DE OBRA | C22: PROCESO | D22: COSTO x Hr. | E22: Q Hrs. | F22: TOTAL | H22: 1 | J22: DILUYENTE | K22: =I22*H22 -> 0 | Q22: FORMA DE PAGO: 50% CONTADO, SALDO C/E
A23: =800000*1.2 -> 960000 | B23: =A21/23 -> 23478.261 | C23: CORTE | D23: =B23/9 -> 2608.6957 | E23: 0.5 | F23: =D23*E23 -> 1304.3478 | H23: 1 | J23: CINTA EMBALAJE | K23: =I23*H23 -> 0 | Q23: VALIDEZ COTIZACIÓN: 5 DIAS
A24: 450000 | B24: =A22/23 -> 23478.261 | C24: CORTE LAMINA | D24: =B24/9 -> 2608.6957 | E24: 0.5 | F24: =D24*E24 -> 1304.3478 | H24: Q/HRS | I24: PRECIO | J24: MANO DE OBRA INDIRECTA | K24: VALOR | L24: =SUM(K25:K35) -> 0
A25: 450000 | B25: =A23/23 -> 41739.13 | C25: REBAJE LAMINA | D25: =B25/9 -> 4637.6812 | F25: =D25*E25 -> 0 | H25: 0 | I25: =((480000/23)/9) -> 2318.8406 | J25: FLETERO (HRS) | K25: =H25*I25 -> 0
B26: =A24/23 -> 19565.217 | C26: TUPIZADO | D26: =B26/9 -> 2173.913 | E26: 0.5 | F26: =D26*E26 -> 1086.9565 | H26: 0 | J26: BENCINA | K26: =H26*I26 -> 0
A27: 350000 | B27: =A25/23 -> 19565.217 | C27: ARMADO | D27: =B27/9 -> 2173.913 | E27: 0.5 | F27: =D27*E27 -> 1086.9565 | H27: 0 | J27: TAG | K27: =H27*I27 -> 0
A28: 500000 | B28: =A27/23 -> 15217.391 | C28: PEGADO | D28: =B28/9 -> 1690.8213 | E28: 0.7 | F28: =D28*E28 -> 1183.5749 | H28: 0 | J28: RECTIFICACION | K28: =H28*I28 -> 0
B29: =A28/23 -> 21739.13 | C29: POSTFORMADO | D29: =B29/9 -> 2415.4589 | E29: 0.7 | F29: =D29*E29 -> 1690.8213 | H29: 0 | I29: =((550000*1.2)/23)/9 -> 3188.4058 | J29: HR. TRAB. JUAN | K29: =H29*I29 -> 0
A30: 450000 | C30: MEDIA CAÑA | D30: 2415 | F30: =D30*E30 -> 0 | H30: 0 | I30: =((450000*1.2)/23)/9 -> 2608.6957 | J30: HR. TRAB. JULIO | K30: =H30*I30 -> 0
A31: 350000 | B31: =A30/23 -> 19565.217 | C31: CORTE-ENCHAPE | D31: =B31/9 -> 2173.913 | E31: 0 | F31: =D31*E31 -> 0 | H31: 0 | I31: =((450000*1.2)/23)/9 -> 2608.6957 | J31: HR. TRAB. EUGE | K31: =H31*I31 -> 0
A32: =A21+A24+A27+A28+A30 -> 2290000 | B32: =480000/23 -> 20869.565 | C32: CONTROL CALIDAD | D32: =B32/9 -> 2318.8406 | E32: 0.5 | F32: =D32*E32 -> 1159.4203 | H32: 0 | J32: COLACION | K32: =H32*I32 -> 0
C33: TOTAL | D33: =SUM(D23:D32) -> 25216.932 | E33: =SUM(E23:E32) -> 3.9 | F33: =SUM(F23:F32) -> 8816.4251 | H33: 0 | J33: BONO | K33: =H33*I33 -> 0
B34: CIF | C34: M. PRIMA INDIREC. | D34: =L9 -> 2550 | H34: 1 | J34: PERFORACION | K34: =H34*I34 -> 0
C35: M. OBRA INDIRECTA | D35: =L24 -> 0 | H35: 6 | J35: CORTE 45 | K35: =H35*I35 -> 0
C36: GASTOS DE FABRICA | D36: =L36 -> 18467.666 | H36: CANTIDAD | I36: PRECIO | J36: GASTOS DE FABRICACION | K36: VALOR | L36: =SUM(K37:K39) -> 18467.666
C37: DEPRECIACIONES | H37: =$E$33 -> 3.9 | I37: =32609.69/9 -> 3623.2989 | J37: ARRIENDO x HORA | K37: =I37*H37 -> 14130.866
C38: TOTAL | D38: =SUM(D34:D37) -> 21017.666 | H38: =$E$33 -> 3.9 | I38: 967 | J38: AGUA x HORA | K38: =I38*H38 -> 3771.3
H39: =$E$33 -> 3.9 | I39: 145 | J39: LUZ x HORA | K39: =I39*H39 -> 565.5
B40: PROVISIONAR | C40: IVA | D40: =E11-E21 -> 143243.28
H41: ESTADO DE RESULTADOS
B42: TOTAL HRS TRABAJADAS | D42: =E33 -> 3.9 | H42: INGRESOS | I42: + TOTAL VENTA | M42: =D11 -> 805899
H43: COSTOS | I43: - MATERIA PRIMA DIRECTA | M43: =D21 -> 51987
...

Sheet NOTA DE VENTA
F2: MUEBLES SANTA FE SPA
F3: VENTAS POR MENOR DE MUEBLES
F4: RUT: 77.054.606-0
F5: SEPTIMA AVENIDA 1631, SAN MIGUEL
F6: CELULAR: 963868755
F7: E-MAIL: fdonoso@topmobili.cl
B8: P R E S U P U E S T O | D8: ='2229'!D8 -> N° 11821 | F8: NOTA DE VENTA :
B10: CLIENTE: | C10: =IF('2229'!C10="","",'2229'!C10) -> FCA. DE MUEBLES ALVEAR Y ALVEAR LTDA | F10: FECHA : | G10: ='2229'!G10 -> 46028
B11: RUT: | C11: =IF('2229'!C11="","",'2229'!C11) -> 76.143.978-2 | F11: FECHA LIMITE : | G11: =WORKDAY(G10,5) -> 46035
B12: GIRO: | C12: =IF('2229'!C12="","",'2229'!C12) -> FCA DE MUEBLES | F12: DESPACHO: | G12: ='2229'!G14 -> NO
B13: CONTACTO: | C13: =IF('2229'!C13="","",'2229'!C13) -> CLAUDIO ALVEAR | F13: ORDEN DE COMPRA:
B14: CORREO: | C14: =IF('2229'!C14="","",'2229'!C14) -> LINEALTA1 | F14: HECHO POR: | G14: FERNANDO DONOSO
B15: FONO: | C15: =IF('2229'!C15="","",'2229'!C15) -> 56973069852 | F15: SERVICIO EXPRESS: | G15: ='2229'!G12 -> NO
B16: DIRECCION: | C16: =IF('2229'!C16="","",'2229'!C16) -> ROSA ESTER 03281 LA PINTANA | F16: FORMA DE PAGO : | G16: ='2229'!G16 -> ABONO 50% SALDO C/ENTREGA
B17: CIUDAD: | C17: =IF('2229'!C17="","",'2229'!C17) -> SANTIAGO | F17: VALIDEZ COTIZACIÓN: 5 DÍAS
B20: D E T A L L E
B21: UNIDAD | C21: TIPO | D21: LARGO | E21: ANCHO | F21: COLOR | G21: VALOR | H21: TOTAL
B22: ='2229'!B21 -> 5 | C22: ='2229'!C21 -> CUB S/R 180° | D22: ='2229'!D21*1000 -> 1100 | E22: ='2229'!E21*1000 -> 450 | F22: ='2229'!F21 -> NIEBLA 2191 MT | G22: ='2229'!G21 -> 42102 | H22: =G22*B22 -> 210510
G25: NETO | H25: =SUM(H22:H24) -> 210510
G26: I.V.A. | H26: =H25*19% -> 39996.9
G27: TOTAL | H27: =H25+H26 -> 250506.9
B30: CUENTA VISTA DEL BANCO ESTADO N° 35571389078 A NOMBRE DE
B31: "MUEBLES SANTA FE SPA." - RUT : 77.054.606-0, VENTAS@TOPMOBILI.CL
B32: VISITANOS Y DESCUBRE NUESTROS PRODUCTOS EN | E32: WWW.TOPMOBILICHILE.CL

Sheet REGLAS
B2: DETALLE CORTE LAMINA | G2: DETALLE CORTE SUSTRATO | P2: DETALLE CORTE MERA
B3: ALTO | C3: ANCHO | D3: TIPO | G3: ALTO | H3: ANCHO | I3: TIPO | P3: ALTO | Q3: ANCHO | R3: TIPO
B4: 40 | C4: 60 | D4: CEN 1V | E4: A1 | G4: 50 | H4: 100 | I4: CEN 1V | J4: REGLA SIEMPRE LLEVAR MEDIDA MINIMO A 100 | P4: 50 | Q4: -30 | R4: CUB C/R
B5: 40 | C5: 90 | D5: CEN 2V | E5: A2 | G5: 50 | I5: CEN 2V | J5: REGLA SIEMPRE LLEVAR MEDIDA MINIMO A 101 | P5: 50 | Q5: -30 | R5: CUB C/R
B6: 40 | C6: 100 | D6: CORNISA FRENTE ESPAÑOL 1 LADO | E6: A3 | G6: 50 | H6: 100 | I6: CORNISA FRENTE ESPAÑOL 1 LADO | P6: 50 | Q6: -30 | R6: CUB C/R 180°
B7: 40 | C7: 150 | D7: CORNISA FRENTE ESPAÑOL 2 LADO | E7: A4 | G7: 50 | I7: CORNISA FRENTE ESPAÑOL 2 LADO | P7: 50 | Q7: -30 | R7: CUB C/R FRENTE ESPAÑOL
B8: 40 | C8: 100 | D8: CORNISA 180° 1LADO | E8: A5 | G8: 50 | H8: 100 | I8: CORNISA 180° 1LADO | L8: DETALLE CORTE MERA | P8: 50 | Q8: -30 | R8: CUB C/R PUNTA 1 LADO
B9: 40 | C9: 50 | D9: CORNISA PUNTA TIBURON 1 LADO | E9: B | G9: 50 | H9: 100 | I9: CORNISA 1LADO | L9: ALTO | M9: ANCHO | N9: TIPO | P9: 50 | Q9: 0 | R9: CUB S/R FRENTE ESPAÑOL
B10: 40 | C10: 80 | D10: CORNISA PUNTA TIBURON 2 LADOS | E10: C | G10: 50 | I10: CORNISA 2 LADOS | L10: 50 | M10: -30 | N10: CUB C/R | P10: 50 | Q10: 0 | R10: CUB S/R
B11: 40 | C11: 60 | D11: CORNISA R8 1LADO | E11: D | G11: 50 | H11: 100 | I11: CORNISA PUNTA TIBURON 1 LADO | L11: 50 | M11: 0 | N11: CUB S/R y CUB MESA | P11: 50 | Q11: 0 | R11: CUB MESA 180° 2 LADOS
B12: 40 | C12: 100 | D12: CORNISA R8 2 LADOS | E12: E | G12: 50 | I12: CORNISA PUNTA TIBURON 2 LADOS | L12: 50 | M12: -2 | N12: PR | P12: 50 | Q12: 0 | R12: CUB MESA 180° 3 LADOS
B13: 40 | C13: 130 | D13: CUB C/R R6 | E13: F | G13: 50 | H13: -30 | I13: CUB C/R | P13: 50 | Q13: 0 | R13: CUB MESA 180° 4 LADOS
B14: 40 | C14: 150 | D14: CUB C/R 180° | G14: 50 | H14: -30 | I14: CUB C/R 180°
B15: 40 | C15: 150 | D15: CUB C/R FRENTE ESPAÑOL | E15: G | G15: 50 | H15: -30 | I15: CUB C/R FRENTE ESPAÑOL | P15: 50 | Q15: 0 | R15: CUB MESA 4 LADOS
B16: 40 | C16: 130 | D16: CUB C/R R2 | E16: H | G16: 50 | H16: -30 | I16: CUB C/R PUNTA TIBURON 1 LADO | P16: 50 | Q16: 0 | R16: CUB MESA FRENTE ESPAÑOL 2 LADOS
B17: 40 | C17: 150 | D17: CUB MESA 180° 2 LADOS | E17: I | G17: 50 | I17: CUB MESA 180° 2 LADOS | P17: 50 | Q17: 0 | R17: CUB MESA FRENTE ESPAÑOL 3 LADOS
B18: 140 | C18: 150 | D18: CUB MESA 180° 3 LADOS | E18: J | G18: 50 | I18: CUB MESA 180° 3 LADOS | P18: 50 | Q18: 0 | R18: CUB MESA FRENTE ESPAÑOL 4 LADOS
B19: 150 | C19: 150 | D19: CUB MESA 180° 4 LADOS | E19: K | G19: 50 | I19: CUB MESA 180° 4 LADOS | P19: 50 | Q19: 0 | R19: CUB MESA PUNTA TIBURON 2 LADOS
B20: 40 | C20: 100 | D20: CUB MESA 2L | E20: L | G20: 50 | H20: 0 | I20: CUB MESA 2L | J20: ES IGUAL A LO PEDIDO NO SE DEBE SUMAR NI RESTAR | P20: 50 | Q20: 0 | R20: CUB MESA PUNTA TIBURON 3 LADOS
B21: 100 | C21: 100 | D21: CUB MESA 3L | E21: M | G21: 50 | H21: 0 | I21: CUB MESA 3L | P21: 50 | Q21: 0 | R21: CUB MESA PUNTA TIBURON 4 LADOS
B22: 100 | C22: 100 | D22: CUB MESA 4 LADOS | E22: N | I22: CUB MESA 4 LADOS | P22: 50 | Q22: 0 | R22: CUB PUNTA TIBURON 1 LADO
B23: 40 | C23: 150 | D23: CUB MESA FRENTE ESPAÑOL 2 LADOS | E23: O | G23: 50 | I23: CUB MESA FRENTE ESPAÑOL 2 LADOS | R23: CENEFA 1 LADO
B24: 140 | C24: 150 | D24: CUB MESA FRENTE ESPAÑOL 3 LADOS | E24: P | G24: 50 | I24: CUB MESA FRENTE ESPAÑOL 3 LADOS | R24: CENEFA 2 LADOS
B25: 150 | C25: 150 | D25: CUB MESA FRENTE ESPAÑOL 4 LADOS | E25: Q | G25: 50 | I25: CUB MESA FRENTE ESPAÑOL 4 LADOS | R25: CORNISA FRENTE ESPAÑOL 1 LADO
B26: 40 | C26: 77 | D26: CUB MESA PUNTA TIBURON 2 LADOS | E26: R | G26: 50 | I26: CUB MESA PUNTA TIBURON 2 LADOS | R26: CORNISA FRENTE ESPAÑOL 2 LADO
B27: 110 | C27: 77 | D27: CUB MESA PUNTA TIBURON 3 LADOS | E27: S | G27: 50 | I27: CUB MESA PUNTA TIBURON 3 LADOS | R27: CORNISA 180° 1LADO
B28: 120 | C28: 77 | D28: CUB MESA PUNTA TIBURON 4 LADOS | E28: T | G28: 50 | I28: CUB MESA PUNTA TIBURON 4 LADOS | R28: CORNISA 1LADO
B29: 40 | C29: 50 | D29: CUB PUNTA TIBURON 1 LADO | E29: U | G29: 50 | I29: CUB PUNTA TIBURON 1 LADO | R29: CORNISA 2 LADOS
B30: 40 | C30: 60 | D30: CUB S/R | E30: V | G30: 50 | I30: CUB S/R | R30: CORNISA PUNTA TIBURON 1 LADO
B31: 40 | C31: 100 | D31: CUB S/R FRENTE ESPAÑOL | E31: W | G31: 50 | I31: CUB S/R FRENTE ESPAÑOL | R31: CORNISA PUNTA TIBURON 2 LADOS
B32: 40 | C32: 60 | D32: CUB S/R R2 | E32: X | G32: 50 | I32: CUB S/R R2 | R32: PR2
B33: 40 | C33: 90 | D33: PR12 | E33: Y | G33: 50 | H33: -2 | I33: PR12 | R33: PR6
B34: 40 | C34: 90 | D34: PR19 | G34: 50 | H34: -2 | I34: PR19
B35: 40 | C35: 90 | D35: PR2 | E35: Z | G35: 50 | H35: -2 | I35: PR2 | R35: PR8
B36: 40 | C36: 90 | D36: PR6 | G36: 50 | H36: -2 | I36: PR6 | R36: PR12
B37: 40 | C37: 90 | D37: PR8 | G37: 50 | H37: -2 | I37: PR8 | R37: PR19
B48: 40 | C48: 150

Sheet PRODUCCION
K2: NO BORRAR REGLAS!!!!! SI NO LAS SABEN USAR NO BORREN ESTO POR FAVOR!!!!!
K3: SUSTRATO | M3: LAMINADO
C4: NOTA DE VENTA : | D4: =IF('NOTA DE VENTA'!$G$8="","",'NOTA DE VENTA'!$G$8) | K4: ALTO | L4: ANCHO | M4: ALTO | N4: ANCHO
C5: CLIENTE : | D5: ='NOTA DE VENTA'!$C$10 -> FCA. DE MUEBLES ALVEAR Y ALVEAR LTDA | K5: =LOOKUP(F14,REGLAS!$I$4:$I$37,REGLAS!$G$4:$G$37)+J14 -> 1850 | L5: =LOOKUP(F14,REGLAS!$I$4:$I$37,REGLAS!$H$4:$H$37)+K14 -> 470 | M5: =LOOKUP(F14,REGLAS!$D$4:$D$37,REGLAS!$B$4:$B$37)+J21 -> 1840 | N5: =H10 -> 0
C7: ='NOTA DE VENTA'!$F$10 -> FECHA : | D7: ='NOTA DE VENTA'!$G$10 -> 46028
C8: FECHA ENTREGA: | D8: ='NOTA DE VENTA'!$G$11 -> 46035
A10: SUSTRATO
D12: ALTO | E12: ANCHO
A13: MATERIAL | B13: CANTIDAD | C13: CORTE | D13: 80 | E13: -30 | F13: DESCRIPCIÓN | J13: ALTO | K13: ANCHO
A14: MDF 18MM | B14: =I14 -> 1 | D14: =LOOKUP(F14,REGLAS!$I$4:$I$37,REGLAS!$G$4:$G$37)+J14 -> 1850 | E14: =LOOKUP(F14,REGLAS!$I$4:$I$37,REGLAS!$H$4:$H$37)+K14 -> 470 | F14: =C27 -> CUB C/R R8 | I14: =I21 -> 1 | J14: =D27 -> 1800 | K14: =E27 -> 500
A17: LAMINADO
D19: ALTO | E19: ANCHO
A20: MATERIAL | B20: CANTIDAD | C20: CORTE | D20: 40 | E20: 130 | F20: DESCRIPCIÓN | J20: ALTO | K20: ANCHO
A21: MDF 18MM | B21: =I21 -> 1 | D21: =LOOKUP(F14,REGLAS!$D$4:$D$37,REGLAS!$B$4:$B$37)+J21 -> 1840 | E21: =LOOKUP(F14,REGLAS!$D$4:$D$37,REGLAS!$C$4:$C$37)+K21 -> 630 | F21: =C27 -> CUB C/R R8 | I21: =B27 -> 1 | J21: =D27 -> 1800 | K21: =E27 -> 500
B24: MEDIDAS ORIGINALES
A26: MATERIAL | B26: CANTIDAD | C26: DESCRIPCIÓN | D26: ALTO | E26: ANCHO | F26: COLOR
A27: MDF 18MM | B27: ='[1]4637'!B21 -> 1 | C27: ='[1]4637'!C21 -> CUB C/R R8 | D27: ='[1]4637'!D21 -> 1800 | E27: ='[1]4637'!E21 -> 500 | F27: ='[1]4637'!F21 -> LATE 2167 MT
C39: NOTA DE VENTA : | D39: ='[1]4637'!G8 -> 7332
C40: CLIENTE : | D40: ='[1]4637'!C10 -> FMR MAKING SPA
C42: ='[1]4637'!F11 -> FECHA LIMITE : | D42: ='[1]4637'!G11 -> 45996
A45: PRODUCCIÓN
B47: DETALLE
B48: CANTIDAD | C48: CORTE | D48: ALTO | E48: ANCHO | F48: DESCRIPCION
A49: MDF18MM | B49: ='[1]4637'!B21 -> 1 | C49: ='[1]4637'!C21 -> CUB C/R R8 | D49: ='[1]4637'!D21 -> 1800 | E49: ='[1]4637'!E21 -> 500 | F49: ='[1]4637'!F21 -> LATE 2167 MT

Sheet SEGUIMIENTO
A1: NV | B1: N° COTIZA | C1: FECHA | D1: ENTREGA | E1: NOMBRE | F1: DETALLE | G1: COLOR | H1: NETO | I1: IVA | J1: TOTAL | K1: ABONO | L1: SALDO | M1: ESTADO
A2: ='NOTA DE VENTA'!$G$8 -> 0 | B2: ='NOTA DE VENTA'!$D$8 -> N° 11821 | C2: ='NOTA DE VENTA'!$G$10 -> 46028 | D2: ='NOTA DE VENTA'!$G$11 -> 46035 | E2: ='NOTA DE VENTA'!$C$10 -> FCA. DE MUEBLES ALVEAR Y ALVEAR LTDA | F2: ='NOTA DE VENTA'!$C$22 -> CUB S/R 180° | G2: ='NOTA DE VENTA'!$F$22 -> NIEBLA 2191 MT | H2: ='NOTA DE VENTA'!$H$25 -> 210510 | I2: =H2*0.19 -> 39996.9 | J2: =I2+H2 -> 250506.9 | L2: =J2-K2 -> 250506.9
