Workbook

Sheet 2229
O6: 10077 SF PORTLAND MAPLE
B8: P R E S U P U E S T O | D8: N° 11823
B10: NOMBRE: | C10: GONZALO PEÑA | G10: 46029
B11: RUT: | G11: 10 DIAS HABILES | R11: MT2 PUERTAS
B12: GIRO: | G12: NO
B13: CONTACTO: | G13: SI
B14: CORREO: | G14: NO | R14: ML CUBIERTAS
B15: FONO: | C15: +569 8466 2944 | G15: NO
B16: DIRECCION: | G16: ABONO 50% SALDO C/ENTREGA
B17: CIUDAD: | C17: SANTIAGO | G17: Cotizado por: Fernando Donoso
B19: DETALLE | M19: 0.02 | N19: 0.02 | P19: TOTAL | Q19: VALOR X MT2 | R19: ENCHAPE | S19: MT/L
B20: UNIDAD | C20: TIPO | D20: LARGO | E20: ANCHO | F20: COLOR | G20: VALOR | H20: TOTAL | L20: =B20 -> UNIDAD | M20: ALTO | N20: =E20 -> ANCHO | O20: MT | P20: MT2 | Q20: =O51 -> 63143.736 | R20: 5000 | S20: LARGO | T20: ANCHO
B21: 1 | C21: PR6 / 2 FRENTES | D21: 0.73 | E21: 0.57 | F21: PUMIC GREY 21321 SF | G21: =R21 -> 32941.103 | H21: =G21*B21 -> 32941.103 | L21: =B21 -> 1 | M21: =D21+M$19 -> 0.75 | N21: =E21+$N$19 -> 0.59 | O21: =M21*N21 -> 0.4425 | P21: =O21*L21 -> 0.4425 | Q21: =Q$20*O21 -> 27941.103 | R21: =Q21+R$20 -> 32941.103 | S21: =M21*L21*2 -> 1.5 | T21: =N21*L21*2 -> 1.18
B22: 6 | C22: PR6 | D22: 0.73 | E22: 0.298 | F22: PUMIC GREY 21321 SF | G22: =R22 -> 20059.781 | H22: =G22*B22 -> 120358.69 | L22: =B22 -> 6 | M22: =D22+M$19 -> 0.75 | N22: =E22+$N$19 -> 0.318 | O22: =M22*N22 -> 0.2385 | P22: =O22*L22 -> 1.431 | Q22: =Q$20*O22 -> 15059.781 | R22: =Q22+R$20 -> 20059.781 | S22: =M22*L22*2 -> 9 | T22: =N22*L22*2 -> 3.816
B23: 2 | C23: PR6 | D23: 0.73 | E23: 0.293 | F23: PUMIC GREY 21321 SF | G23: =R23 -> 19822.992 | H23: =G23*B23 -> 39645.984 | L23: =B23 -> 2 | M23: =D23+M$19 -> 0.75 | N23: =E23+$N$19 -> 0.313 | O23: =M23*N23 -> 0.23475 | P23: =O23*L23 -> 0.4695 | Q23: =Q$20*O23 -> 14822.992 | R23: =Q23+R$20 -> 19822.992 | S23: =M23*L23*2 -> 3 | T23: =N23*L23*2 -> 1.252
B24: 1 | C24: PR6 | D24: 0.73 | E24: 0.415 | F24: PUMIC GREY 21321 SF | G24: =R24 -> 25600.644 | H24: =G24*B24 -> 25600.644 | L24: =B24 -> 1 | M24: =D24+M$19 -> 0.75 | N24: =E24+$N$19 -> 0.435 | O24: =M24*N24 -> 0.32625 | P24: =O24*L24 -> 0.32625 | Q24: =Q$20*O24 -> 20600.644 | R24: =Q24+R$20 -> 25600.644 | S24: =M24*L24*2 -> 1.5 | T24: =N24*L24*2 -> 0.87
B25: 1 | C25: PR6 / 4 FRENTES | D25: 0.73 | E25: 0.448 | F25: PUMIC GREY 21321 SF | G25: =R25 -> 27163.452 | H25: =G25*B25 -> 27163.452 | L25: =B25 -> 1 | M25: =D25+M$19 -> 0.75 | N25: =E25+$N$19 -> 0.468 | O25: =M25*N25 -> 0.351 | P25: =O25*L25 -> 0.351 | Q25: =Q$20*O25 -> 22163.452 | R25: =Q25+R$20 -> 27163.452 | S25: =M25*L25*2 -> 1.5 | T25: =N25*L25*2 -> 0.936
B26: 2 | C26: PR6 | D26: 0.47 | E26: 0.298 | F26: PUMIC GREY 21321 SF | G26: =R26 -> 14839.057 | H26: =G26*B26 -> 29678.114 | L26: =B26 -> 2 | M26: =D26+M$19 -> 0.49 | N26: =E26+$N$19 -> 0.318 | O26: =M26*N26 -> 0.15582 | P26: =O26*L26 -> 0.31164 | Q26: =Q$20*O26 -> 9839.057 | R26: =Q26+R$20 -> 14839.057 | S26: =M26*L26*2 -> 1.96 | T26: =N26*L26*2 -> 1.272
B27: 1 | C27: PR6 | D27: 0.91 | E27: 0.415 | F27: PUMIC GREY 21321 SF | G27: =R27 -> 30544.799 | H27: =G27*B27 -> 30544.799 | L27: =B27 -> 1 | M27: =D27+M$19 -> 0.93 | N27: =E27+$N$19 -> 0.435 | O27: =M27*N27 -> 0.40455 | P27: =O27*L27 -> 0.40455 | Q27: =Q$20*O27 -> 25544.799 | R27: =Q27+R$20 -> 30544.799 | S27: =M27*L27*2 -> 1.86 | T27: =N27*L27*2 -> 0.87
B28: 1 | C28: PR6 | D28: 0.86 | E28: 0.598 | F28: PUMIC GREY 21321 SF | G28: =R28 -> 39340.09 | H28: =G28*B28 -> 39340.09 | L28: =B28 -> 1 | M28: =D28+M$19 -> 0.88 | N28: =E28+$N$19 -> 0.618 | O28: =M28*N28 -> 0.54384 | P28: =O28*L28 -> 0.54384 | Q28: =Q$20*O28 -> 34340.09 | R28: =Q28+R$20 -> 39340.09 | S28: =M28*L28*2 -> 1.76 | T28: =N28*L28*2 -> 1.236
B29: 1 | C29: PR6 | D29: 0.91 | E29: 0.298 | F29: PUMIC GREY 21321 SF | G29: =R29 -> 23674.129 | H29: =G29*B29 -> 23674.129 | L29: =B29 -> 1 | M29: =D29+M$19 -> 0.93 | N29: =E29+$N$19 -> 0.318 | O29: =M29*N29 -> 0.29574 | P29: =O29*L29 -> 0.29574 | Q29: =Q$20*O29 -> 18674.129 | R29: =Q29+R$20 -> 23674.129 | S29: =M29*L29*2 -> 1.86 | T29: =N29*L29*2 -> 0.636
B30: 4 | C30: PR6 | D30: 0.91 | E30: 0.312 | F30: PUMIC GREY 21321 SF | G30: =R30 -> 24496.26 | H30: =G30*B30 -> 97985.04 | L30: =B30 -> 4 | M30: =D30+M$19 -> 0.93 | N30: =E30+$N$19 -> 0.332 | O30: =M30*N30 -> 0.30876 | P30: =O30*L30 -> 1.23504 | Q30: =Q$20*O30 -> 19496.26 | R30: =Q30+R$20 -> 24496.26 | S30: =M30*L30*2 -> 7.44 | T30: =N30*L30*2 -> 2.656
B31: 2 | C31: PR6 | D31: 0.91 | E31: 0.283 | F31: PUMIC GREY 21321 SF | G31: =R31 -> 22793.274 | H31: =G31*B31 -> 45586.547 | L31: =B31 -> 2 | M31: =D31+M$19 -> 0.93 | N31: =E31+$N$19 -> 0.303 | O31: =M31*N31 -> 0.28179 | P31: =O31*L31 -> 0.56358 | Q31: =Q$20*O31 -> 17793.274 | R31: =Q31+R$20 -> 22793.274 | S31: =M31*L31*2 -> 3.72 | T31: =N31*L31*2 -> 1.212
B32: 1 | C32: PR6 | D32: 0.91 | E32: 0.375 | F32: PUMIC GREY 21321 SF | G32: =R32 -> 28195.852 | H32: =G32*B32 -> 28195.852 | L32: =B32 -> 1 | M32: =D32+M$19 -> 0.93 | N32: =E32+$N$19 -> 0.395 | O32: =M32*N32 -> 0.36735 | P32: =O32*L32 -> 0.36735 | Q32: =Q$20*O32 -> 23195.852 | R32: =Q32+R$20 -> 28195.852 | S32: =M32*L32*2 -> 1.86 | T32: =N32*L32*2 -> 0.79
B33: 1 | C33: PR6 | D33: 1.295 | E33: 0.375 | F33: PUMIC GREY 21321 SF | G33: =R33 -> 37798.435 | H33: =G33*B33 -> 37798.435 | L33: =B33 -> 1 | M33: =D33+M$19 -> 1.315 | N33: =E33+$N$19 -> 0.395 | O33: =M33*N33 -> 0.519425 | P33: =O33*L33 -> 0.519425 | Q33: =Q$20*O33 -> 32798.435 | R33: =Q33+R$20 -> 37798.435 | S33: =M33*L33*2 -> 2.63 | T33: =N33*L33*2 -> 0.79
B35: =SUM(B21:B33) -> 24
G37: NETO | H37: =SUM(H21:H36) -> 578512.88 | T37: =SUM(T21:T36) -> 17.516
G38: IVA | H38: =H37*19% -> 109917.45 | M38: =SUM(M21:M37) -> 11.085 | P38: =SUM(P21:P35) -> 7.261415
G39: TOTAL | H39: =H37+H38 -> 688430.32 | P39: =P38 -> 7.261415 | S39: =SUM(S21:S38) -> 39.59
P40: =P39*20% -> 1.452283 | Q40: 20% PERDIDA | S40: =S39+T37 -> 57.106
P41: =P39+P40 -> 8.713698 | S41: =S40*20% -> 11.4212
S42: =S40+S41 -> 68.5272 | U42: ADHESIVO | V42: 58.000.- | W42: 44971
M43: =P41 -> 8.713698 | N43: 1200 | O43: =M43*N43 -> 10456.438 | P43: ADHESIVO | U43: LATA 16 LTS | V43: 3625 | W43: LITRO
M44: 2.5 | N44: 40000 | O44: =M44*N44 -> 100000 | P44: MDF 18MM | V44: 906.25 | W44: MT2 (4)
B45: CUENTA CORRIENTE BANCO SANTANDER Nº 87316181 A NOMBRE DE MUEBLES SANTA FE SPA | N45: 15700 | O45: =M45*N45 -> 0 | P45: LAMINA 153 X 366 | V45: =V44*20% -> 181.25 | W45: PERDIDA 20%
B46: RUT : 77.054.606-0 CORREO: FRANCODONOSO@TOPMOBILI.CL | M46: 4 | N46: 29700 | O46: =M46*N46 -> 118800 | P46: LAMINA 122X244 | V46: =V44+V45 -> 1087.5 | W46: MINIMO A COTIZAR
A47: GE | B47: VISITANOS Y DESCUBRE NUESTROS PRODUCTOS EN | N47: 339 | O47: =M47*N47 -> 0 | P47: TAPACANTO 100 MTS 1,5X22 | R47: 1.52
N48: 1500 | O48: =M48*N48 -> 0 | P48: MEDIA CAÑA | R48: 2.44
O49: =SUM(O43:O48) -> 229256.44 | P49: COSTO | R49: =R47*R48 -> 3.7088
M50: PRECIO VENTA | O50: =O49*2 -> 458512.88 | P50: FACTOR 2,3 PARA 90° | R50: =P41/R49 -> 2.3494656
...

Sheet COSTOS
B2: CENTRO DE COSTOS POSTFORMADOS
B5: FECHA: | C5: ='2229'!G10 -> 46029
B6: CLIENTE: | C6: ='2229'!C10 -> GONZALO PEÑA | N6: Ventas Equilibrio = | P6: Costos Fijos Totales
B7: DIRECCION: | C7: ='2229'!#REF! -> #REF! | H7: COSTOS INDIRECTOS DE FABRICA VARIABLES | O7: 1 - | P7: Costos Variables Totales
B8: PRESUPUESTO: | C8: ='2229'!D8 -> N° 11823 | H8: Q/HRS | I8: $ | J8: DETALLE | K8: TOTAL | L8: TOTAL | P8: Total Venta | X8: =SUM(Q11:Q16) -> 6
H9: CANTIDAD | I9: PRECIO | J9: MATERIA PRIMA INDIRECTA | L9: =SUM(K10:K23) -> 2550 | S9: DETALLE | X9: =(E15-D11)/X8 -> -57838.917
D10: NETO | E10: IVA | F10: TOTAL | H10: 3 | I10: 350 | J10: RESPALDO | K10: =I10*H10 -> 1050 | Q10: UNIDAD | R10: TIPO | S10: LARGO | T10: ANCHO | U10: COLOR | V10: VALOR | W10: TOTAL
C11: MONTO A COBRAR | D11: ='2229'!H37 -> 578512.88 | E11: =D11*0.19 -> 109917.45 | F11: =E11+D11 -> 688430.32 | H11: 3 | I11: 500 | J11: MEDIA CAÑA | K11: =I11*H11 -> 1500 | Q11: 1 | R11: CUB C/R R8 | S11: 2.8 | T11: 0.62 | U11: MADERA X DEFINIR | V11: 105990 | W11: =V11*Q11 -> 105990 | X11: =V11+$X$9 -> 48151.083 | Y11: 108990
C12: COSTO TOTAL | D12: =SUM(M43:M45) -> 140290.53 | H12: 0 | I12: 7500 | J12: DUROLAC | K12: =I12*H12 -> 0 | Q12: 1 | R12: CUB C/R R8 | S12: 2.3 | T12: 0.62 | U12: MADERA X DEFINIR | V12: 87990 | W12: =V12*Q12 -> 87990 | X12: =V12+$X$9 -> 30151.083 | Y12: 89990
C13: % UTILIDAD | D13: =D11-D12 -> 438222.35 | E13: =(D11/D12)-1 -> 3.1236774 | H13: 0 | I13: 50 | J13: TAPACANTO PVC | K13: =I13*H13 -> 0 | Q13: 1 | R13: CUB C/R R8 | S13: 2.03 | T13: 0.62 | U13: MADERA X DEFINIR | V13: 78990 | W13: =V13*Q13 -> 78990 | X13: =V13+$X$9 -> 21151.083 | Y13: 81990
D14: % utilidad | E14: NETO | F14: UTILIDAD | H14: 0 | I14: 50 | J14: SOBERBIOS | K14: =I14*H14 -> 0 | Q14: 1 | R14: CUB C/R R8 | S14: 1.08 | T14: 0.62 | U14: MADERA X DEFINIR | V14: 39990 | W14: =V14*Q14 -> 39990 | X14: =V14+$X$9 -> -17848.917 | Y14: 39990
C15: PROYECCION | D15: 0.65 | E15: =(100%+D15)*D12 -> 231479.37 | F15: =E15-D12 -> 91188.843 | H15: 0 | I15: 10 | J15: SOPORTE REPISA | K15: =I15*H15 -> 0 | Q15: 1 | R15: CUB C/R R8 | S15: 1.08 | T15: 0.62 | U15: MADERA X DEFINIR | V15: 39990 | W15: =V15*Q15 -> 39990 | X15: =V15+$X$9 -> -17848.917 | Y15: 39990
H16: 1 | J16: PUNTAS | K16: =I16*H16 -> 0 | Q16: 1 | R16: CUB C/R R8 | S16: 2.06 | T16: 0.62 | U16: MADERA X DEFINIR | V16: 79990 | W16: =V16*Q16 -> 79990 | X16: =V16+$X$9 -> 22151.083 | Y16: 83990
B17: M. PRIMA | C17: MATERIAL | D17: NETO | E17: IVA | F17: TOTAL | H17: 1 | J17: TORNILLOS | K17: =I17*H17 -> 0 | Q17: 6 | R17: CORTES 45° | V17: 5000 | W17: =V17*Q17 -> 30000
C18: LAMINA | D18: ='2229'!O45 -> 0 | E18: =D18*0.19 -> 0 | F18: =SUM(D18:E18) -> 0 | H18: 1 | J18: COLAFRIA | K18: =I18*H18 -> 0 | Q18: 1 | R18: PERFORACION LAVAPLATOS | V18: 10000 | W18: =V18*Q18 -> 10000
C19: MDF 18MM | D19: ='2229'!O44 -> 100000 | E19: =D19*0.19 -> 19000 | F19: =SUM(D19:E19) -> 119000 | H19: 1 | J19: LIJAS | K19: =I19*H19 -> 0 | V19: NETO | W19: =SUM(W11:W18) -> 472940 | Y19: =SUM(Y11:Y16)+SUM(W17:W18) -> 484940
C20: ADHESIVO | D20: ='2229'!O43 -> 10456.438 | E20: =D20*0.19 -> 1986.7231 | F20: =SUM(D20:E20) -> 12443.161 | H20: 1 | J20: CARTON | K20: =I20*H20 -> 0 | V20: I.V.A. | W20: =W19*19% -> 89858.6 | Y20: =Y19*0.19 -> 92138.6
A21: =450000*1.2 -> 540000 | C21: TOTAL | D21: =SUM(D18:D20) -> 110456.44 | E21: =SUM(E18:E20) -> 20986.723 | F21: =SUM(F18:F20) -> 131443.16 | H21: 1 | J21: GUAIPE | K21: =I21*H21 -> 0 | M21: =B32/9 -> 2318.8406 | Q21: PLAZO DE ENTREGA : 8 DIAS HABILES | V21: TOTAL | W21: =W19+W20 -> 562798.6 | Y21: =SUM(Y19:Y20) -> 577078.6
A22: =450000*1.2 -> 540000 | B22: M. DE OBRA | C22: PROCESO | D22: COSTO x Hr. | E22: Q Hrs. | F22: TOTAL | H22: 1 | J22: DILUYENTE | K22: =I22*H22 -> 0 | Q22: FORMA DE PAGO: 50% CONTADO, SALDO C/E
A23: =800000*1.2 -> 960000 | B23: =A21/23 -> 23478.261 | C23: CORTE | D23: =B23/9 -> 2608.6957 | E23: 0.5 | F23: =D23*E23 -> 1304.3478 | H23: 1 | J23: CINTA EMBALAJE | K23: =I23*H23 -> 0 | Q23: VALIDEZ COTIZACIÓN: 5 DIAS
A24: 450000 | B24: =A22/23 -> 23478.261 | C24: CORTE LAMINA | D24: =B24/9 -> 2608.6957 | E24: 0.5 | F24: =D24*E24 -> 1304.3478 | H24: Q/HRS | I24: PRECIO | J24: MANO DE OBRA INDIRECTA | K24: VALOR | L24: =SUM(K25:K35) -> 0
A25: 450000 | B25: =A23/23 -> 41739.13 | C25: REBAJE LAMINA | D25: =B25/9 -> 4637.6812 | F25: =D25*E25 -> 0 | H25: 0 | I25: =((480000/23)/9) -> 2318.8406 | J25: FLETERO (HRS) | K25: =H25*I25 -> 0
B26: =A24/23 -> 19565.217 | C26: TUPIZADO | D26: =B26/9 -> 2173.913 | E26: 0.5 | F26: =D26*E26 -> 1086.9565 | H26: 0 | J26: BENCINA | K26: =H26*I26 -> 0
A27: 350000 | B27: =A25/23 -> 19565.217 | C27: ARMADO | D27: =B27/9 -> 2173.913 | E27: 0.5 | F27: =D27*E27 -> 1086.9565 | H27: 0 | J27: TAG | K27: =H27*I27 -> 0
A28: 500000 | B28: =A27/23 -> 15217.391 | C28: PEGADO | D28: =B28/9 -> 1690.8213 | E28: 0.7 | F28: =D28*E28 -> 1183.5749 | H28: 0 | J28: RECTIFICACION | K28: =H28*I28 -> 0
B29: =A28/23 -> 21739.13 | C29: POSTFORMADO | D29: =B29/9 -> 2415.4589 | E29: 0.7 | F29: =D29*E29 -> 1690.8213 | H29: 0 | I29: =((550000*1.2)/23)/9 -> 3188.4058 | J29: HR. TRAB. JUAN | K29: =H29*I29 -> 0
A30: 450000 | C30: MEDIA CAÑA | D30: 2415 | F30: =D30*E30 -> 0 | H30: 0 | I30: =((450000*1.2)/23)/9 -> 2608.6957 | J30: HR. TRAB. JULIO | K30: =H30*I30 -> 0
A31: 350000 | B31: =A30/23 -> 19565.217 | C31: CORTE-ENCHAPE | D31: =B31/9 -> 2173.913 | E31: 0 | F31: =D31*E31 -> 0 | H31: 0 | I31: =((450000*1.2)/23)/9 -> 2608.6957 | J31: HR. TRAB. EUGE | K31: =H31*I31 -> 0
A32: =A21+A24+A27+A28+A30 -> 2290000 | B32: =480000/23 -> 20869.565 | C32: CONTROL CALIDAD | D32: =B32/9 -> 2318.8406 | E32: 0.5 | F32: =D32*E32 -> 1159.4203 | H32: 0 | J32: COLACION | K32: =H32*I32 -> 0
C33: TOTAL | D33: =SUM(D23:D32) -> 25216.932 | E33: =SUM(E23:E32) -> 3.9 | F33: =SUM(F23:F32) -> 8816.4251 | H33: 0 | J33: BONO | K33: =H33*I33 -> 0
B34: CIF | C34: M. PRIMA INDIREC. | D34: =L9 -> 2550 | H34: 1 | J34: PERFORACION | K34: =H34*I34 -> 0
C35: M. OBRA INDIRECTA | D35: =L24 -> 0 | H35: 6 | J35: CORTE 45 | K35: =H35*I35 -> 0
C36: GASTOS DE FABRICA | D36: =L36 -> 18467.666 | H36: CANTIDAD | I36: PRECIO | J36: GASTOS DE FABRICACION | K36: VALOR | L36: =SUM(K37:K39) -> 18467.666
C37: DEPRECIACIONES | H37: =$E$33 -> 3.9 | I37: =32609.69/9 -> 3623.2989 | J37: ARRIENDO x HORA | K37: =I37*H37 -> 14130.866
C38: TOTAL | D38: =SUM(D34:D37) -> 21017.666 | H38: =$E$33 -> 3.9 | I38: 967 | J38: AGUA x HORA | K38: =I38*H38 -> 3771.3
H39: =$E$33 -> 3.9 | I39: 145 | J39: LUZ x HORA | K39: =I39*H39 -> 565.5
B40: PROVISIONAR | C40: IVA | D40: =E11-E21 -> 88930.723
H41: ESTADO DE RESULTADOS
B42: TOTAL HRS TRABAJADAS | D42: =E33 -> 3.9 | H42: INGRESOS | I42: + TOTAL VENTA | M42: =D11 -> 578512.88
H43: COSTOS | I43: - MATERIA PRIMA DIRECTA | M43: =D21 -> 110456.44
...

Sheet NOTA DE VENTA
F2: MUEBLES SANTA FE SPA
F3: VENTAS POR MENOR DE MUEBLES
F4: RUT: 77.054.606-0
F5: SEPTIMA AVENIDA 1631, SAN MIGUEL
F6: CELULAR: 963868755
F7: E-MAIL: fdonoso@topmobili.cl
B8: P R E S U P U E S T O | D8: ='2229'!D8 -> N° 11823 | F8: NOTA DE VENTA :
B10: CLIENTE: | C10: =IF('2229'!C10="","",'2229'!C10) -> GONZALO PEÑA | F10: FECHA : | G10: ='2229'!G10 -> 46029
B11: RUT: | C11: =IF('2229'!C11="","",'2229'!C11) | F11: FECHA LIMITE : | G11: =WORKDAY(G10,5) -> 46036
B12: GIRO: | C12: =IF('2229'!C12="","",'2229'!C12) | F12: DESPACHO: | G12: ='2229'!G14 -> NO
B13: CONTACTO: | C13: =IF('2229'!C13="","",'2229'!C13) | F13: ORDEN DE COMPRA:
B14: CORREO: | C14: =IF('2229'!C14="","",'2229'!C14) | F14: HECHO POR: | G14: FERNANDO DONOSO
B15: FONO: | C15: =IF('2229'!C15="","",'2229'!C15) -> +569 8466 2944 | F15: SERVICIO EXPRESS: | G15: ='2229'!G12 -> NO
B16: DIRECCION: | C16: =IF('2229'!C16="","",'2229'!C16) | F16: FORMA DE PAGO : | G16: ='2229'!G16 -> ABONO 50% SALDO C/ENTREGA
B17: CIUDAD: | C17: =IF('2229'!C17="","",'2229'!C17) -> SANTIAGO | F17: VALIDEZ COTIZACIÓN: 5 DÍAS
B20: D E T A L L E
B21: UNIDAD | C21: TIPO | D21: LARGO | E21: ANCHO | F21: COLOR | G21: VALOR | H21: TOTAL
B22: ='2229'!B21 -> 1 | C22: ='2229'!C21 -> PR6 / 2 FRENTES | D22: ='2229'!D21*1000 -> 730 | E22: ='2229'!E21*1000 -> 570 | F22: ='2229'!#REF! -> #REF! | G22: ='2229'!G21 -> 32941.103 | H22: =G22*B22 -> 32941.103
G25: NETO | H25: =SUM(H22:H24) -> 32941.103
G26: I.V.A. | H26: =H25*19% -> 6258.8096
G27: TOTAL | H27: =H25+H26 -> 39199.913
B30: CUENTA VISTA DEL BANCO ESTADO N° 35571389078 A NOMBRE DE
B31: "MUEBLES SANTA FE SPA." - RUT : 77.054.606-0, VENTAS@TOPMOBILI.CL
B32: VISITANOS Y DESCUBRE NUESTROS PRODUCTOS EN | E32: WWW.TOPMOBILICHILE.CL

Sheet REGLAS
B2: DETALLE CORTE LAMINA | G2: DETALLE CORTE SUSTRATO | P2: DETALLE CORTE MERA
B3: ALTO | C3: ANCHO | D3: TIPO | G3: ALTO | H3: ANCHO | I3: TIPO | P3: ALTO | Q3: ANCHO | R3: TIPO
B4: 40 | C4: 60 | D4: CEN 1V | E4: A1 | G4: 50 | H4: 100 | I4: CEN 1V | J4: REGLA SIEMPRE LLEVAR MEDIDA MINIMO A 100 | P4: 50 | Q4: -30 | R4: CUB C/R
B5: 40 | C5: 90 | D5: CEN 2V | E5: A2 | G5: 50 | I5: CEN 2V | J5: REGLA SIEMPRE LLEVAR MEDIDA MINIMO A 101 | P5: 50 | Q5: -30 | R5: CUB C/R
B6: 40 | C6: 100 | D6: CORNISA FRENTE ESPAÑOL 1 LADO | E6: A3 | G6: 50 | H6: 100 | I6: CORNISA FRENTE ESPAÑOL 1 LADO | P6: 50 | Q6: -30 | R6: CUB C/R 180°
B7: 40 | C7: 150 | D7: CORNISA FRENTE ESPAÑOL 2 LADO | E7: A4 | G7: 50 | I7: CORNISA FRENTE ESPAÑOL 2 LADO | P7: 50 | Q7: -30 | R7: CUB C/R FRENTE ESPAÑOL
B8: 40 | C8: 100 | D8: CORNISA 180° 1LADO | E8: A5 | G8: 50 | H8: 100 | I8: CORNISA 180° 1LADO | L8: DETALLE CORTE MERA | P8: 50 | Q8: -30 | R8: CUB C/R PUNTA 1 LADO
B9: 40 | C9: 50 | D9: CORNISA PUNTA TIBURON 1 LADO | E9: B | G9: 50 | H9: 100 | I9: CORNISA 1LADO | L9: ALTO | M9: ANCHO | N9: TIPO | P9: 50 | Q9: 0 | R9: CUB S/R FRENTE ESPAÑOL
B10: 40 | C10: 80 | D10: CORNISA PUNTA TIBURON 2 LADOS | E10: C | G10: 50 | I10: CORNISA 2 LADOS | L10: 50 | M10: -30 | N10: CUB C/R | P10: 50 | Q10: 0 | R10: CUB S/R
B11: 40 | C11: 60 | D11: CORNISA R8 1LADO | E11: D | G11: 50 | H11: 100 | I11: CORNISA PUNTA TIBURON 1 LADO | L11: 50 | M11: 0 | N11: CUB S/R y CUB MESA | P11: 50 | Q11: 0 | R11: CUB MESA 180° 2 LADOS
B12: 40 | C12: 100 | D12: CORNISA R8 2 LADOS | E12: E | G12: 50 | I12: CORNISA PUNTA TIBURON 2 LADOS | L12: 50 | M12: -2 | N12: PR | P12: 50 | Q12: 0 | R12: CUB MESA 180° 3 LADOS
B13: 40 | C13: 130 | D13: CUB C/R R6 | E13: F | G13: 50 | H13: -30 | I13: CUB C/R | P13: 50 | Q13: 0 | R13: CUB MESA 180° 4 LADOS
B14: 40 | C14: 150 | D14: CUB C/R 180° | G14: 50 | H14: -30 | I14: CUB C/R 180°
B15: 40 | C15: 150 | D15: CUB C/R FRENTE ESPAÑOL | E15: G | G15: 50 | H15: -30 | I15: CUB C/R FRENTE ESPAÑOL | P15: 50 | Q15: 0 | R15: CUB MESA 4 LADOS
B16: 40 | C16: 130 | D16: CUB C/R R2 | E16: H | G16: 50 | H16: -30 | I16: CUB C/R PUNTA TIBURON 1 LADO | P16: 50 | Q16: 0 | R16: CUB MESA FRENTE ESPAÑOL 2 LADOS
B17: 40 | C17: 150 | D17: CUB MESA 180° 2 LADOS | E17: I | G17: 50 | I17: CUB MESA 180° 2 LADOS | P17: 50 | Q17: 0 | R17: CUB MESA FRENTE ESPAÑOL 3 LADOS
B18: 140 | C18: 150 | D18: CUB MESA 180° 3 LADOS | E18: J | G18: 50 | I18: CUB MESA 180° 3 LADOS | P18: 50 | Q18: 0 | R18: CUB MESA FRENTE ESPAÑOL 4 LADOS
B19: 150 | C19: 150 | D19: CUB MESA 180° 4 LADOS | E19: K | G19: 50 | I19: CUB MESA 180° 4 LADOS | P19: 50 | Q19: 0 | R19: CUB MESA PUNTA TIBURON 2 LADOS
B20: 40 | C20: 100 | D20: CUB MESA 2L | E20: L | G20: 50 | H20: 0 | I20: CUB MESA 2L | J20: ES IGUAL A LO PEDIDO NO SE DEBE SUMAR NI RESTAR | P20: 50 | Q20: 0 | R20: CUB MESA PUNTA TIBURON 3 LADOS
B21: 100 | C21: 100 | D21: CUB MESA 3L | E21: M | G21: 50 | H21: 0 | I21: CUB MESA 3L | P21: 50 | Q21: 0 | R21: CUB MESA PUNTA TIBURON 4 LADOS
B22: 100 | C22: 100 | D22: CUB MESA 4 LADOS | E22: N | I22: CUB MESA 4 LADOS | P22: 50 | Q22: 0 | R22: CUB PUNTA TIBURON 1 LADO
B23: 40 | C23: 150 | D23: CUB MESA FRENTE ESPAÑOL 2 LADOS | E23: O | G23: 50 | I23: CUB MESA FRENTE ESPAÑOL 2 LADOS | R23: CENEFA 1 LADO
B24: 140 | C24: 150 | D24: CUB MESA FRENTE ESPAÑOL 3 LADOS | E24: P | G24: 50 | I24: CUB MESA FRENTE ESPAÑOL 3 LADOS | R24: CENEFA 2 LADOS
B25: 150 | C25: 150 | D25: CUB MESA FRENTE ESPAÑOL 4 LADOS | E25: Q | G25: 50 | I25: CUB MESA FRENTE ESPAÑOL 4 LADOS | R25: CORNISA FRENTE ESPAÑOL 1 LADO
B26: 40 | C26: 77 | D26: CUB MESA PUNTA TIBURON 2 LADOS | E26: R | G26: 50 | I26: CUB MESA PUNTA TIBURON 2 LADOS | R26: CORNISA FRENTE ESPAÑOL 2 LADO
B27: 110 | C27: 77 | D27: CUB MESA PUNTA TIBURON 3 LADOS | E27: S | G27: 50 | I27: CUB MESA PUNTA TIBURON 3 LADOS | R27: CORNISA 180° 1LADO
B28: 120 | C28: 77 | D28: CUB MESA PUNTA TIBURON 4 LADOS | E28: T | G28: 50 | I28: CUB MESA PUNTA TIBURON 4 LADOS | R28: CORNISA 1LADO
B29: 40 | C29: 50 | D29: CUB PUNTA TIBURON 1 LADO | E29: U | G29: 50 | I29: CUB PUNTA TIBURON 1 LADO | R29: CORNISA 2 LADOS
B30: 40 | C30: 60 | D30: CUB S/R | E30: V | G30: 50 | I30: CUB S/R | R30: CORNISA PUNTA TIBURON 1 LADO
B31: 40 | C31: 100 | D31: CUB S/R FRENTE ESPAÑOL | E31: W | G31: 50 | I31: CUB S/R FRENTE ESPAÑOL | R31: CORNISA PUNTA TIBURON 2 LADOS
B32: 40 | C32: 60 | D32: CUB S/R R2 | E32: X | G32: 50 | I32: CUB S/R R2 | R32: PR2
B33: 40 | C33: 90 | D33: PR12 | E33: Y | G33: 50 | H33: -2 | I33: PR12 | R33: PR6
B34: 40 | C34: 90 | D34: PR19 | G34: 50 | H34: -2 | I34: PR19
B35: 40 | C35: 90 | D35: PR2 | E35: Z | G35: 50 | H35: -2 | I35: PR2 | R35: PR8
B36: 40 | C36: 90 | D36: PR6 | G36: 50 | H36: -2 | I36: PR6 | R36: PR12
B37: 40 | C37: 90 | D37: PR8 | G37: 50 | H37: -2 | I37: PR8 | R37: PR19
B48: 40 | C48: 150

Sheet PRODUCCION
K2: NO BORRAR REGLAS!!!!! SI NO LAS SABEN USAR NO BORREN ESTO POR FAVOR!!!!!
K3: SUSTRATO | M3: LAMINADO
C4: NOTA DE VENTA : | D4: =IF('NOTA DE VENTA'!$G$8="","",'NOTA DE VENTA'!$G$8) | K4: ALTO | L4: ANCHO | M4: ALTO | N4: ANCHO
C5: CLIENTE : | D5: ='NOTA DE VENTA'!$C$10 -> GONZALO PEÑA | K5: =LOOKUP(F14,REGLAS!$I$4:$I$37,REGLAS!$G$4:$G$37)+J14 -> 1850 | L5: =LOOKUP(F14,REGLAS!$I$4:$I$37,REGLAS!$H$4:$H$37)+K14 -> 470 | M5: =LOOKUP(F14,REGLAS!$D$4:$D$37,REGLAS!$B$4:$B$37)+J21 -> 1840 | N5: =H10 -> 0
C7: ='NOTA DE VENTA'!$F$10 -> FECHA : | D7: ='NOTA DE VENTA'!$G$10 -> 46029
C8: FECHA ENTREGA: | D8: ='NOTA DE VENTA'!$G$11 -> 46036
A10: SUSTRATO
D12: ALTO | E12: ANCHO
A13: MATERIAL | B13: CANTIDAD | C13: CORTE | D13: 80 | E13: -30 | F13: DESCRIPCIÓN | J13: ALTO | K13: ANCHO
A14: MDF 18MM | B14: =I14 -> 1 | D14: =LOOKUP(F14,REGLAS!$I$4:$I$37,REGLAS!$G$4:$G$37)+J14 -> 1850 | E14: =LOOKUP(F14,REGLAS!$I$4:$I$37,REGLAS!$H$4:$H$37)+K14 -> 470 | F14: =C27 -> CUB C/R R8 | I14: =I21 -> 1 | J14: =D27 -> 1800 | K14: =E27 -> 500
A17: LAMINADO
D19: ALTO | E19: ANCHO
A20: MATERIAL | B20: CANTIDAD | C20: CORTE | D20: 40 | E20: 130 | F20: DESCRIPCIÓN | J20: ALTO | K20: ANCHO
A21: MDF 18MM | B21: =I21 -> 1 | D21: =LOOKUP(F14,REGLAS!$D$4:$D$37,REGLAS!$B$4:$B$37)+J21 -> 1840 | E21: =LOOKUP(F14,REGLAS!$D$4:$D$37,REGLAS!$C$4:$C$37)+K21 -> 630 | F21: =C27 -> CUB C/R R8 | I21: =B27 -> 1 | J21: =D27 -> 1800 | K21: =E27 -> 500
B24: MEDIDAS ORIGINALES
A26: MATERIAL | B26: CANTIDAD | C26: DESCRIPCIÓN | D26: ALTO | E26: ANCHO | F26: COLOR
A27: MDF 18MM | B27: ='[1]4637'!B21 -> 1 | C27: ='[1]4637'!C21 -> CUB C/R R8 | D27: ='[1]4637'!D21 -> 1800 | E27: ='[1]4637'!E21 -> 500 | F27: ='[1]4637'!F21 -> LATE 2167 MT
C39: NOTA DE VENTA : | D39: ='[1]4637'!G8 -> 7332
C40: CLIENTE : | D40: ='[1]4637'!C10 -> FMR MAKING SPA
C42: ='[1]4637'!F11 -> FECHA LIMITE : | D42: ='[1]4637'!G11 -> 45996
A45: PRODUCCIÓN
B47: DETALLE
B48: CANTIDAD | C48: CORTE | D48: ALTO | E48: ANCHO | F48: DESCRIPCION
A49: MDF18MM | B49: ='[1]4637'!B21 -> 1 | C49: ='[1]4637'!C21 -> CUB C/R R8 | D49: ='[1]4637'!D21 -> 1800 | E49: ='[1]4637'!E21 -> 500 | F49: ='[1]4637'!F21 -> LATE 2167 MT

Sheet SEGUIMIENTO
A1: NV | B1: N° COTIZA | C1: FECHA | D1: ENTREGA | E1: NOMBRE | F1: DETALLE | G1: COLOR | H1: NETO | I1: IVA | J1: TOTAL | K1: ABONO | L1: SALDO | M1: ESTADO
A2: ='NOTA DE VENTA'!$G$8 -> 0 | B2: ='NOTA DE VENTA'!$D$8 -> N° 11823 | C2: ='NOTA DE VENTA'!$G$10 -> 46029 | D2: ='NOTA DE VENTA'!$G$11 -> 46036 | E2: ='NOTA DE VENTA'!$C$10 -> GONZALO PEÑA | F2: ='NOTA DE VENTA'!$C$22 -> PR6 / 2 FRENTES | G2: ='NOTA DE VENTA'!$F$22 -> #REF! | H2: ='NOTA DE VENTA'!$H$25 -> 32941.103 | I2: =H2*0.19 -> 6258.8096 | J2: =I2+H2 -> 39199.913 | L2: =J2-K2 -> 39199.913
