Workbook

Sheet 4637
F2: MUEBLES SANTA FE SPA
F3: VENTAS POR MENOR DE MUEBLES
F4: RUT: 77.054.606-0
F5: SEPTIMA AVENIDA 1631, SAN MIGUEL
F6: FONO 22521 6502
F7: E-MAIL: ventas@topmobili.cl
B8: P R E S U P U E S T O | D8: 11355 | E8: 0 | F8: NOTA DE VENTA : | G8: 4159
B10: CLIENTE: | C10: MIGUEL ESTAY | F10: FECHA : | G10: 45736
B11: RUT: | F11: FECHA LIMITE : | G11: 45744
B12: CONTACTO: | F12: ORDEN DE COMPRA:
B13: GIRO: | F13: HECHO POR: | G13: FD
B14: FONO: | C14: +569 92196008
B15: DIRECCION: | F15: FORMA DE PAGO : | G15: CONTADO
B16: CIUDAD: | C16: SANTIAGO | F16: VALIDEZ COTIZACIÓN: 5 DÍAS
B19: D E T A L L E
B20: UNIDAD | C20: TIPO | D20: LARGO | E20: ANCHO | F20: COLOR | G20: VALOR | H20: TOTAL | N20: 65000
B21: 1 | C21: CUB C/R R8 | D21: 1500 | E21: 600 | F21: MARMORE CARRARA 3151 PL | G21: 88531 | H21: =G21*B21 -> 88531 | K21: =D25/1000 -> 0.698 | L21: =E25/1000 -> 0.428 | M21: =K21*L21 -> 0.298744 | N21: =M21*N$20 -> 19418.36
B22: 1 | C22: CUB C/R R8 | D22: 2100 | E22: 600 | F22: MARMORE CARRARA 3151 PL | G22: 122801 | H22: =G22*B22 -> 122801
B23: 1 | C23: CUB C/R R8 | D23: 1400 | E23: 550 | F23: MARMORE CARRARA 3151 PL | G23: 75918 | H23: =G23*B23 -> 75918
B24: 1 | C24: CUB S/R R8 | D24: 800 | E24: 340 | F24: MARMORE CARRARA 3151 PL | G24: 27511 | H24: =G24*B24 -> 27511
B25: 1 | C25: PR6 | D25: 698 | E25: 428 | F25: CARBON 2192 MT | G25: 31585 | H25: =G25*B25 -> 31585
B26: 2 | C26: PR6 / 3 FTES DE 230 | D26: 698 | E26: 448 | F26: CARBON 2192 MT | G26: 32968 | H26: =G26*B26 -> 65936
B27: 4 | C27: PR6 | D27: 698 | E27: 398 | F27: CARBON 2192 MT | G27: 29512 | H27: =G27*B27 -> 118048
B28: 1 | C28: PR6 | D28: 698 | E28: 378 | F28: CARBON 2192 MT | G28: 28129 | H28: =G28*B28 -> 28129
B29: 1 | C29: PR6 | D29: 698 | E29: 223 | F29: CARBON 2192 MT | G29: 17415 | H29: =G29*B29 -> 17415
B30: 2 | C30: PR6 | D30: 698 | E30: 388 | F30: CARBON 2192 MT | G30: 28820 | H30: =G30*B30 -> 57640
B31: 1 | C31: PR6 | D31: 677 | E31: 378 | F31: NIEBLA 2191 MT | G31: 29565 | H31: =G31*B31 -> 29565
B32: 2 | C32: PR6 | D32: 677 | E32: 398 | F32: NIEBLA 2191 MT | G32: 31023 | H32: =G32*B32 -> 62046
B33: 4 | C33: PR6 | D33: 327 | E33: 305 | F33: NIEBLA 2191 MT | G33: 13534 | H33: =G33*B33 -> 54136
... B37: 2 | C37: ZOCALOS | D37: 3000 | E37: 120 | F37: SILVERY 99981 MT | G37: 14500 | H37: =G37*B37 -> 29000
B38: 1 | C38: DESPACHO | G38: 30000 | H38: =G38*B38 -> 30000
G41: NETO | H41: =SUM(H21:H40) -> 976043
G42: ABONO
G43: TOTAL | H43: =H41+H42 -> 976043
B55: CUENTA CORRIENTE BANCO SANTANDER N° 87316181 A NOMBRE DE
B56: "MUEBLES SANTA FE SPA." - RUT : 77.054.606-0, VENTAS@TOPMOBILI.CL
B57: VISITANOS Y DESCUBRE NUESTROS PRODUCTOS EN
B58: WWW.TOPMOBILICHILE.CL
B60: FIRMA CONFORME
B62: VENDEDOR

Sheet REGLAS
B2: DETALLE CORTE LAMINA | G2: DETALLE CORTE SUSTRATO | P2: DETALLE CORTE MERA
B3: ALTO | C3: ANCHO | D3: TIPO | G3: ALTO | H3: ANCHO | I3: TIPO | P3: ALTO | Q3: ANCHO | R3: TIPO
B4: 40 | C4: 60 | D4: CEN 1V | E4: A1 | G4: 50 | H4: 100 | I4: CEN 1V | J4: REGLA SIEMPRE LLEVAR MEDIDA MINIMO A 100 | P4: 50 | Q4: -30 | R4: CUB C/R
B5: 40 | C5: 90 | D5: CEN 2V | E5: A2 | G5: 50 | I5: CEN 2V | J5: REGLA SIEMPRE LLEVAR MEDIDA MINIMO A 101 | P5: 50 | Q5: -30 | R5: CUB C/R
B6: 40 | C6: 100 | D6: CORNISA FRENTE ESPAÑOL 1 LADO | E6: A3 | G6: 50 | H6: 100 | I6: CORNISA FRENTE ESPAÑOL 1 LADO | P6: 50 | Q6: -30 | R6: CUB C/R 180°
B7: 40 | C7: 150 | D7: CORNISA FRENTE ESPAÑOL 2 LADO | E7: A4 | G7: 50 | I7: CORNISA FRENTE ESPAÑOL 2 LADO | P7: 50 | Q7: -30 | R7: CUB C/R FRENTE ESPAÑOL
B8: 40 | C8: 100 | D8: CORNISA 180° 1LADO | E8: A5 | G8: 50 | H8: 100 | I8: CORNISA 180° 1LADO | L8: DETALLE CORTE MERA | P8: 50 | Q8: -30 | R8: CUB C/R PUNTA 1 LADO
B9: 40 | C9: 50 | D9: CORNISA PUNTA TIBURON 1 LADO | E9: B | G9: 50 | H9: 100 | I9: CORNISA 1LADO | L9: ALTO | M9: ANCHO | N9: TIPO | P9: 50 | Q9: 0 | R9: CUB S/R FRENTE ESPAÑOL
B10: 40 | C10: 80 | D10: CORNISA PUNTA TIBURON 2 LADOS | E10: C | G10: 50 | I10: CORNISA 2 LADOS | L10: 50 | M10: -30 | N10: CUB C/R | P10: 50 | Q10: 0 | R10: CUB S/R
B11: 40 | C11: 60 | D11: CORNISA R8 1LADO | E11: D | G11: 50 | H11: 100 | I11: CORNISA PUNTA TIBURON 1 LADO | L11: 50 | M11: 0 | N11: CUB S/R y CUB MESA | P11: 50 | Q11: 0 | R11: CUB MESA 180° 2 LADOS
B12: 40 | C12: 100 | D12: CORNISA R8 2 LADOS | E12: E | G12: 50 | I12: CORNISA PUNTA TIBURON 2 LADOS | L12: 50 | M12: -2 | N12: PR | P12: 50 | Q12: 0 | R12: CUB MESA 180° 3 LADOS
B13: 40 | C13: 130 | D13: CUB C/R R6 | E13: F | G13: 50 | H13: -30 | I13: CUB C/R | P13: 50 | Q13: 0 | R13: CUB MESA 180° 4 LADOS
B14: 40 | C14: 150 | D14: CUB C/R 180° | G14: 50 | H14: -30 | I14: CUB C/R 180°
B15: 40 | C15: 150 | D15: CUB C/R FRENTE ESPAÑOL | E15: G | G15: 50 | H15: -30 | I15: CUB C/R FRENTE ESPAÑOL | P15: 50 | Q15: 0 | R15: CUB MESA 4 LADOS
B16: 40 | C16: 130 | D16: CUB C/R R2 | E16: H | G16: 50 | H16: -30 | I16: CUB C/R PUNTA TIBURON 1 LADO | P16: 50 | Q16: 0 | R16: CUB MESA FRENTE ESPAÑOL 2 LADOS
B17: 40 | C17: 150 | D17: CUB MESA 180° 2 LADOS | E17: I | G17: 50 | I17: CUB MESA 180° 2 LADOS | P17: 50 | Q17: 0 | R17: CUB MESA FRENTE ESPAÑOL 3 LADOS
B18: 140 | C18: 150 | D18: CUB MESA 180° 3 LADOS | E18: J | G18: 50 | I18: CUB MESA 180° 3 LADOS | P18: 50 | Q18: 0 | R18: CUB MESA FRENTE ESPAÑOL 4 LADOS
B19: 150 | C19: 150 | D19: CUB MESA 180° 4 LADOS | E19: K | G19: 50 | I19: CUB MESA 180° 4 LADOS | P19: 50 | Q19: 0 | R19: CUB MESA PUNTA TIBURON 2 LADOS
B20: 40 | C20: 100 | D20: CUB MESA 2L | E20: L | G20: 50 | H20: 0 | I20: CUB MESA 2L | J20: ES IGUAL A LO PEDIDO NO SE DEBE SUMAR NI RESTAR | P20: 50 | Q20: 0 | R20: CUB MESA PUNTA TIBURON 3 LADOS
B21: 100 | C21: 100 | D21: CUB MESA 3L | E21: M | G21: 50 | H21: 0 | I21: CUB MESA 3L | P21: 50 | Q21: 0 | R21: CUB MESA PUNTA TIBURON 4 LADOS
B22: 100 | C22: 100 | D22: CUB MESA 4 LADOS | E22: N | I22: CUB MESA 4 LADOS | P22: 50 | Q22: 0 | R22: CUB PUNTA TIBURON 1 LADO
B23: 40 | C23: 150 | D23: CUB MESA FRENTE ESPAÑOL 2 LADOS | E23: O | G23: 50 | I23: CUB MESA FRENTE ESPAÑOL 2 LADOS | R23: CENEFA 1 LADO
B24: 140 | C24: 150 | D24: CUB MESA FRENTE ESPAÑOL 3 LADOS | E24: P | G24: 50 | I24: CUB MESA FRENTE ESPAÑOL 3 LADOS | R24: CENEFA 2 LADOS
B25: 150 | C25: 150 | D25: CUB MESA FRENTE ESPAÑOL 4 LADOS | E25: Q | G25: 50 | I25: CUB MESA FRENTE ESPAÑOL 4 LADOS | R25: CORNISA FRENTE ESPAÑOL 1 LADO
B26: 40 | C26: 77 | D26: CUB MESA PUNTA TIBURON 2 LADOS | E26: R | G26: 50 | I26: CUB MESA PUNTA TIBURON 2 LADOS | R26: CORNISA FRENTE ESPAÑOL 2 LADO
B27: 110 | C27: 77 | D27: CUB MESA PUNTA TIBURON 3 LADOS | E27: S | G27: 50 | I27: CUB MESA PUNTA TIBURON 3 LADOS | R27: CORNISA 180° 1LADO
B28: 120 | C28: 77 | D28: CUB MESA PUNTA TIBURON 4 LADOS | E28: T | G28: 50 | I28: CUB MESA PUNTA TIBURON 4 LADOS | R28: CORNISA 1LADO
B29: 40 | C29: 50 | D29: CUB PUNTA TIBURON 1 LADO | E29: U | G29: 50 | I29: CUB PUNTA TIBURON 1 LADO | R29: CORNISA 2 LADOS
B30: 40 | C30: 60 | D30: CUB S/R | E30: V | G30: 50 | I30: CUB S/R | R30: CORNISA PUNTA TIBURON 1 LADO
B31: 40 | C31: 100 | D31: CUB S/R FRENTE ESPAÑOL | E31: W | G31: 50 | I31: CUB S/R FRENTE ESPAÑOL | R31: CORNISA PUNTA TIBURON 2 LADOS
B32: 40 | C32: 60 | D32: CUB S/R R2 | E32: X | G32: 50 | I32: CUB S/R R2 | R32: PR2
B33: 40 | C33: 90 | D33: PR12 | E33: Y | G33: 50 | H33: -2 | I33: PR12 | R33: PR6
B34: 40 | C34: 90 | D34: PR19 | G34: 50 | H34: -2 | I34: PR19
B35: 40 | C35: 90 | D35: PR2 | E35: Z | G35: 50 | H35: -2 | I35: PR2 | R35: PR8
B36: 40 | C36: 90 | D36: PR6 | G36: 50 | H36: -2 | I36: PR6 | R36: PR12
B37: 40 | C37: 90 | D37: PR8 | G37: 50 | H37: -2 | I37: PR8 | R37: PR19
B48: 40 | C48: 150

Sheet CUBIERTA
L2: NO BORRAR REGLAS!!!!! SI NO LAS SABEN USAR NO BORREN ESTO POR FAVOR!!!!!
L3: SUSTRATO | N3: LAMINADO
D4: NOTA DE VENTA : | E4: ='4637'!G8 -> 4159 | L4: ALTO | M4: ANCHO | N4: ALTO | O4: ANCHO
D5: CLIENTE : | E5: ='4637'!C10 -> MIGUEL ESTAY | L5: =LOOKUP(#REF!,REGLAS!$I$4:$I$37,REGLAS!$G$4:$G$37)+#REF! -> #REF! | M5: =LOOKUP(#REF!,REGLAS!$I$4:$I$37,REGLAS!$H$4:$H$37)+#REF! -> #REF! | N5: =LOOKUP(#REF!,REGLAS!$D$4:$D$37,REGLAS!$B$4:$B$37)+#REF! -> #REF! | O5: =LOOKUP(#REF!,REGLAS!$D$4:$D$37,REGLAS!$C$4:$C$37)+#REF! -> #REF!
D7: ='4637'!F11 -> FECHA LIMITE : | E7: ='4637'!G11 -> 45744 | G7: HECHO POR: FD
D8: FECHA ENTREGA:
B10: SUSTRATO
E12: ALTO | F12: ANCHO
B13: MATERIAL | C13: CANTIDAD | D13: CORTE | E13: 80 | F13: -30 | G13: DESCRIPCIÓN | K13: ALTO | L13: ANCHO
A14: 1 | C14: =J14 -> 1 | E14: =K14+E$13 -> 1580 | F14: =L14+F$13 -> 570 | G14: =D60 -> CUB C/R R8 | J14: =J38 -> 1 | K14: =E60 -> 1500 | L14: =F60 -> 600
A15: 2 | C15: =J15 -> 1 | E15: =K15+E$13 -> 2180 | F15: =L15+F$13 -> 570 | G15: =D61 -> CUB C/R R8 | J15: =J39 -> 1 | K15: =E61 -> 2100 | L15: =F61 -> 600
A16: 3 | C16: =J16 -> 1 | E16: =K16+E$13 -> 1480 | F16: =L16+F$13 -> 520 | G16: =D62 -> CUB C/R R8 | J16: =J40 -> 1 | K16: =E62 -> 1400 | L16: =F62 -> 550
A17: 4 | C17: =J17 -> 1 | E17: =K17+E$13 -> 880 | F17: =L17 -> 340 | G17: =D63 -> CUB S/R R8 | J17: =J41 -> 1 | K17: =E63 -> 800 | L17: =F63 -> 340
A18: 16 | C18: =J18 -> 2 | E18: =K18+E$13 -> 2580 | F18: =L18 -> 100 | G18: CEN R6 1V MDF DESNUDO | J18: 2 | K18: 2500 | L18: 100
B19: MATERIAL | C19: CANTIDAD | D19: CORTE | E19: 50 | F19: -2 | G19: DESCRIPCIÓN
A20: 5 | B20: MELAMIL 18MM | C20: =J20 -> 1 | E20: =K20+E$13 -> 778 | F20: =L20+F$19 -> 426 | G20: =D64 -> PR6 | J20: =J42 -> 1 | K20: =E64 -> 698 | L20: =F64 -> 428
A21: 6 | C21: =J21 -> 2 | D21: CORTAR 3 DE 230 | E21: =K21+E$13 -> 778 | F21: =L21+F$19 -> 446 | G21: =D65 -> PR6 / 3 FTES DE 230 | J21: =J43 -> 2 | K21: =E65 -> 698 | L21: =F65 -> 448
A22: 7 | C22: =J22 -> 4 | E22: =K22+E$13 -> 778 | F22: =L22+F$19 -> 396 | G22: =D66 -> PR6 | J22: =J44 -> 4 | K22: =E66 -> 698 | L22: =F66 -> 398
A23: 8 | C23: =J23 -> 1 | E23: =K23+E$13 -> 778 | F23: =L23+F$19 -> 376 | G23: =D67 -> PR6 | J23: =J45 -> 1 | K23: =E67 -> 698 | L23: =F67 -> 378
A24: 9 | C24: =J24 -> 1 | E24: =K24+E$13 -> 778 | F24: =L24+F$19 -> 221 | G24: =D68 -> PR6 | J24: =J46 -> 1 | K24: =E68 -> 698 | L24: =F68 -> 223
A25: 10 | C25: =J25 -> 2 | E25: =K25+E$13 -> 778 | F25: =L25+F$19 -> 386 | G25: =D69 -> PR6 | J25: =J47 -> 2 | K25: =E69 -> 698 | L25: =F69 -> 388
A26: 11 | C26: =J26 -> 1 | E26: =K26+E$13 -> 757 | F26: =L26+F$19 -> 376 | G26: =D70 -> PR6 | J26: =J48 -> 1 | K26: =E70 -> 677 | L26: =F70 -> 378
A27: 12 | C27: =J27 -> 2 | E27: =K27+E$13 -> 757 | F27: =L27+F$19 -> 396 | G27: =D71 -> PR6 | J27: =J49 -> 2 | K27: =E71 -> 677 | L27: =F71 -> 398
A28: 13 | C28: =J28 -> 4 | E28: =K28+E$13 -> 407 | F28: =L28+F$19 -> 303 | G28: =D72 -> PR6 | J28: =J50 -> 4 | K28: =E72 -> 327 | L28: =F72 -> 305
A29: 14 | C29: =J29 -> 2 | E29: =K29+E$13 -> 747 | F29: =L29+F$19 -> 411 | G29: =D73 -> PR6 | J29: =J51 -> 2 | K29: =E73 -> 667 | L29: =F73 -> 413
A30: 15 | C30: =J30 -> 2 | E30: =K30+E$13 -> 2080 | F30: 100 | G30: =D74 -> CEN R6 1V | J30: =J52 -> 2 | K30: =E74 -> 2000 | L30: =F74 -> 60
B34: LAMINADO
E36: ALTO | F36: ANCHO
B37: MATERIAL | C37: CANTIDAD | D37: CORTE | E37: 40 | F37: 130 | G37: DESCRIPCIÓN | K37: ALTO | L37: ANCHO
A38: 1 | C38: =J38 -> 1 | E38: =K38+E$37 -> 1540 | F38: =L38+F$37 -> 730 | G38: =D60 -> CUB C/R R8 | J38: =C60 -> 1 | K38: =E60 -> 1500 | L38: =F60 -> 600
A39: 2 | C39: =J39 -> 1 | E39: =K39+E$37 -> 2140 | F39: =L39+F$37 -> 730 | G39: =D61 -> CUB C/R R8 | J39: =C61 -> 1 | K39: =E61 -> 2100 | L39: =F61 -> 600
A40: 3 | C40: =J40 -> 1 | E40: =K40+E$37 -> 1440 | F40: =L40+F$37 -> 680 | G40: =D62 -> CUB C/R R8 | J40: =C62 -> 1 | K40: =E62 -> 1400 | L40: =F62 -> 550
A41: 4 | C41: =J41 -> 1 | E41: =K41+E$37 -> 840 | F41: =L41+60 -> 400 | G41: =D63 -> CUB S/R R8 | J41: =C63 -> 1 | K41: =E63 -> 800 | L41: =F63 -> 340 | M41: 2
A42: 5 | C42: =J42 -> 1 | E42: =K42+E$37 -> 738 | F42: =L42+90 -> 518 | G42: =D64 -> PR6 | J42: =C64 -> 1 | K42: =E64 -> 698 | L42: =F64 -> 428
A43: 6 | C43: =J43 -> 2 | E43: =K43+E$37 -> 738 | F43: =L43+90 -> 538 | G43: =D65 -> PR6 / 3 FTES DE 230 | J43: =C65 -> 2 | K43: =E65 -> 698 | L43: =F65 -> 448 | M43: 2
A44: 7 | C44: =J44 -> 4 | E44: =K44+E$37 -> 738 | F44: =L44+90 -> 488 | G44: =D66 -> PR6 | J44: =C66 -> 4 | K44: =E66 -> 698 | L44: =F66 -> 398
A45: 8 | C45: =J45 -> 1 | E45: =K45+E$37 -> 738 | F45: =L45+90 -> 468 | G45: =D67 -> PR6 | J45: =C67 -> 1 | K45: =E67 -> 698 | L45: =F67 -> 378
A46: 9 | C46: =J46 -> 1 | E46: =K46+E$37 -> 738 | F46: =L46+90 -> 313 | G46: =D68 -> PR6 | J46: =C68 -> 1 | K46: =E68 -> 698 | L46: =F68 -> 223
A47: 10 | C47: =J47 -> 2 | E47: =K47+E$37 -> 738 | F47: =L47+90 -> 478 | G47: =D69 -> PR6 | J47: =C69 -> 2 | K47: =E69 -> 698 | L47: =F69 -> 388
A48: 11 | C48: =J48 -> 1 | E48: =K48+E$37 -> 717 | F48: =L48+90 -> 468 | G48: =D70 -> PR6 | J48: =C70 -> 1 | K48: =E70 -> 677 | L48: =F70 -> 378
...
