Workbook

Sheet 4637
I2: MUEBLES SANTA FE SPA
I3: VENTAS POR MENOR DE MUEBLES
I4: RUT: 77.054.606-0
I5: SEPTIMA AVENIDA 1631, SAN MIGUEL
I6: FONO 22521 6502
I7: E-MAIL: ventas@topmobili.cl
B8: P R E S U P U E S T O | D8: 11328 | E8: 0 | I8: NOTA DE VENTA : | J8: 4160
B10: CLIENTE: | C10: CONSTANZA SAINT | I10: FECHA : | J10: 45740
B11: RUT: | I11: FECHA LIMITE :
B12: CONTACTO: | I12: ORDEN DE COMPRA:
B13: GIRO: | I13: HECHO POR: | J13: FD
B14: FONO: | C14: +569 92196008
B15: DIRECCION: | I15: FORMA DE PAGO : | J15: CONTADO
B16: CIUDAD: | C16: SANTIAGO | I16: VALIDEZ COTIZACIÓN: 5 DÍAS
B19: D E T A L L E
B20: UNIDAD | C20: TIPO | D20: ALTO | E20: ANCHO | F20: CON PERFORACION | G20: MEDIDA | H20: ENCHAPE | I20: COLOR | J20: VALOR | K20: TOTAL | Q20: 65000
B21: 2 | C21: E/R 1 CARA | D21: 765 | E21: 396 | F21: SI | G21: 12,5 CMS AL EJE | H21: 4 LADOS | I21: AZUL PACIFICO 2170 MT | J21: 33792 | K21: =J21*B21 -> 67584 | N21: =D25/1000 -> 0.425 | O21: =E25/1000 -> 0.301 | P21: =N21*O21 -> 0.127925 | Q21: =P21*Q$20 -> 8315.125
B22: 1 | C22: E/R 1 CARA | D22: 765 | E22: 315 | F22: SI | G22: 12,5 CMS AL EJE | H22: 4 LADOS | I22: AZUL PACIFICO 2170 MT | J22: 29549 | K22: =J22*B22 -> 29549
B23: 1 | C23: E/R 1 CARA | D23: 765 | E23: 275 | F23: SI | G23: 12,5 CMS AL EJE | H23: 4 LADOS | I23: AZUL PACIFICO 2170 MT | J23: 27454 | K23: =J23*B23 -> 27454
B24: 2 | C24: E/R 1 CARA | D24: 660 | E24: 301 | F24: SI | G24: 12,5 CMS AL EJE | H24: 4 LADOS | I24: AZUL PACIFICO 2170 MT | J24: 26567 | K24: =J24*B24 -> 53134
B25: 2 | C25: E/R 1 CARA | D25: 425 | E25: 301 | F25: SI | G25: 12,5 CMS AL EJE | H25: 4 LADOS | I25: AZUL PACIFICO 2170 MT | J25: 21533 | K25: =J25*B25 -> 43066
B26: 2 | C26: E/R 1 CARA | D26: 177 | E26: 506 | F26: NO | H26: 4 LADOS | I26: AZUL PACIFICO 2170 MT | J26: 18915 | K26: =J26*B26 -> 37830
B27: 1 | C27: E/R 1 CARA | D27: 397 | E27: 506 | F27: NO | H27: 4 LADOS | I27: AZUL PACIFICO 2170 MT | J27: 26637 | K27: =J27*B27 -> 26637
B28: 2 | C28: E/R 1 CARA | D28: 177 | E28: 898 | F28: NO | H28: 4 LADOS | I28: AZUL PACIFICO 2170 MT | J28: 24068 | K28: =J28*B28 -> 48136
B29: 1 | C29: E/R 1 CARA | D29: 397 | E29: 898 | F29: NO | H29: 4 LADOS | I29: AZUL PACIFICO 2170 MT | J29: 37546 | K29: =J29*B29 -> 37546
B30: 1 | C30: E/R 1 CARA | D30: 650 | E30: 587 | F30: NO | H30: 4 LADOS | I30: AZUL PACIFICO 2170 MT | J30: 39140 | K30: =J30*B30 -> 39140
J33: NETO | K33: =SUM(K21:K32) -> 410076
J34: ABONO
J35: TOTAL | K35: =K33+K34 -> 410076
B47: CUENTA CORRIENTE BANCO SANTANDER N° 87316181 A NOMBRE DE
B48: "MUEBLES SANTA FE SPA." - RUT : 77.054.606-0, VENTAS@TOPMOBILI.CL
B49: VISITANOS Y DESCUBRE NUESTROS PRODUCTOS EN
B50: WWW.TOPMOBILICHILE.CL
B52: FIRMA CONFORME
B54: VENDEDOR

Sheet REGLAS
B2: DETALLE CORTE LAMINA | G2: DETALLE CORTE SUSTRATO | P2: DETALLE CORTE MERA
B3: ALTO | C3: ANCHO | D3: TIPO | G3: ALTO | H3: ANCHO | I3: TIPO | P3: ALTO | Q3: ANCHO | R3: TIPO
B4: 40 | C4: 60 | D4: CEN 1V | E4: A1 | G4: 50 | H4: 100 | I4: CEN 1V | J4: REGLA SIEMPRE LLEVAR MEDIDA MINIMO A 100 | P4: 50 | Q4: -30 | R4: CUB C/R
B5: 40 | C5: 90 | D5: CEN 2V | E5: A2 | G5: 50 | I5: CEN 2V | J5: REGLA SIEMPRE LLEVAR MEDIDA MINIMO A 101 | P5: 50 | Q5: -30 | R5: CUB C/R
B6: 40 | C6: 100 | D6: CORNISA FRENTE ESPAÑOL 1 LADO | E6: A3 | G6: 50 | H6: 100 | I6: CORNISA FRENTE ESPAÑOL 1 LADO | P6: 50 | Q6: -30 | R6: CUB C/R 180°
B7: 40 | C7: 150 | D7: CORNISA FRENTE ESPAÑOL 2 LADO | E7: A4 | G7: 50 | I7: CORNISA FRENTE ESPAÑOL 2 LADO | P7: 50 | Q7: -30 | R7: CUB C/R FRENTE ESPAÑOL
B8: 40 | C8: 100 | D8: CORNISA 180° 1LADO | E8: A5 | G8: 50 | H8: 100 | I8: CORNISA 180° 1LADO | L8: DETALLE CORTE MERA | P8: 50 | Q8: -30 | R8: CUB C/R PUNTA 1 LADO
B9: 40 | C9: 50 | D9: CORNISA PUNTA TIBURON 1 LADO | E9: B | G9: 50 | H9: 100 | I9: CORNISA 1LADO | L9: ALTO | M9: ANCHO | N9: TIPO | P9: 50 | Q9: 0 | R9: CUB S/R FRENTE ESPAÑOL
B10: 40 | C10: 80 | D10: CORNISA PUNTA TIBURON 2 LADOS | E10: C | G10: 50 | I10: CORNISA 2 LADOS | L10: 50 | M10: -30 | N10: CUB C/R | P10: 50 | Q10: 0 | R10: CUB S/R
B11: 40 | C11: 60 | D11: CORNISA R8 1LADO | E11: D | G11: 50 | H11: 100 | I11: CORNISA PUNTA TIBURON 1 LADO | L11: 50 | M11: 0 | N11: CUB S/R y CUB MESA | P11: 50 | Q11: 0 | R11: CUB MESA 180° 2 LADOS
B12: 40 | C12: 100 | D12: CORNISA R8 2 LADOS | E12: E | G12: 50 | I12: CORNISA PUNTA TIBURON 2 LADOS | L12: 50 | M12: -2 | N12: PR | P12: 50 | Q12: 0 | R12: CUB MESA 180° 3 LADOS
B13: 40 | C13: 130 | D13: CUB C/R R6 | E13: F | G13: 50 | H13: -30 | I13: CUB C/R | P13: 50 | Q13: 0 | R13: CUB MESA 180° 4 LADOS
B14: 40 | C14: 150 | D14: CUB C/R 180° | G14: 50 | H14: -30 | I14: CUB C/R 180°
B15: 40 | C15: 150 | D15: CUB C/R FRENTE ESPAÑOL | E15: G | G15: 50 | H15: -30 | I15: CUB C/R FRENTE ESPAÑOL | P15: 50 | Q15: 0 | R15: CUB MESA 4 LADOS
B16: 40 | C16: 130 | D16: CUB C/R R2 | E16: H | G16: 50 | H16: -30 | I16: CUB C/R PUNTA TIBURON 1 LADO | P16: 50 | Q16: 0 | R16: CUB MESA FRENTE ESPAÑOL 2 LADOS
B17: 40 | C17: 150 | D17: CUB MESA 180° 2 LADOS | E17: I | G17: 50 | I17: CUB MESA 180° 2 LADOS | P17: 50 | Q17: 0 | R17: CUB MESA FRENTE ESPAÑOL 3 LADOS
B18: 140 | C18: 150 | D18: CUB MESA 180° 3 LADOS | E18: J | G18: 50 | I18: CUB MESA 180° 3 LADOS | P18: 50 | Q18: 0 | R18: CUB MESA FRENTE ESPAÑOL 4 LADOS
B19: 150 | C19: 150 | D19: CUB MESA 180° 4 LADOS | E19: K | G19: 50 | I19: CUB MESA 180° 4 LADOS | P19: 50 | Q19: 0 | R19: CUB MESA PUNTA TIBURON 2 LADOS
B20: 40 | C20: 100 | D20: CUB MESA 2L | E20: L | G20: 50 | H20: 0 | I20: CUB MESA 2L | J20: ES IGUAL A LO PEDIDO NO SE DEBE SUMAR NI RESTAR | P20: 50 | Q20: 0 | R20: CUB MESA PUNTA TIBURON 3 LADOS
B21: 100 | C21: 100 | D21: CUB MESA 3L | E21: M | G21: 50 | H21: 0 | I21: CUB MESA 3L | P21: 50 | Q21: 0 | R21: CUB MESA PUNTA TIBURON 4 LADOS
B22: 100 | C22: 100 | D22: CUB MESA 4 LADOS | E22: N | I22: CUB MESA 4 LADOS | P22: 50 | Q22: 0 | R22: CUB PUNTA TIBURON 1 LADO
B23: 40 | C23: 150 | D23: CUB MESA FRENTE ESPAÑOL 2 LADOS | E23: O | G23: 50 | I23: CUB MESA FRENTE ESPAÑOL 2 LADOS | R23: CENEFA 1 LADO
B24: 140 | C24: 150 | D24: CUB MESA FRENTE ESPAÑOL 3 LADOS | E24: P | G24: 50 | I24: CUB MESA FRENTE ESPAÑOL 3 LADOS | R24: CENEFA 2 LADOS
B25: 150 | C25: 150 | D25: CUB MESA FRENTE ESPAÑOL 4 LADOS | E25: Q | G25: 50 | I25: CUB MESA FRENTE ESPAÑOL 4 LADOS | R25: CORNISA FRENTE ESPAÑOL 1 LADO
B26: 40 | C26: 77 | D26: CUB MESA PUNTA TIBURON 2 LADOS | E26: R | G26: 50 | I26: CUB MESA PUNTA TIBURON 2 LADOS | R26: CORNISA FRENTE ESPAÑOL 2 LADO
B27: 110 | C27: 77 | D27: CUB MESA PUNTA TIBURON 3 LADOS | E27: S | G27: 50 | I27: CUB MESA PUNTA TIBURON 3 LADOS | R27: CORNISA 180° 1LADO
B28: 120 | C28: 77 | D28: CUB MESA PUNTA TIBURON 4 LADOS | E28: T | G28: 50 | I28: CUB MESA PUNTA TIBURON 4 LADOS | R28: CORNISA 1LADO
B29: 40 | C29: 50 | D29: CUB PUNTA TIBURON 1 LADO | E29: U | G29: 50 | I29: CUB PUNTA TIBURON 1 LADO | R29: CORNISA 2 LADOS
B30: 40 | C30: 60 | D30: CUB S/R | E30: V | G30: 50 | I30: CUB S/R | R30: CORNISA PUNTA TIBURON 1 LADO
B31: 40 | C31: 100 | D31: CUB S/R FRENTE ESPAÑOL | E31: W | G31: 50 | I31: CUB S/R FRENTE ESPAÑOL | R31: CORNISA PUNTA TIBURON 2 LADOS
B32: 40 | C32: 60 | D32: CUB S/R R2 | E32: X | G32: 50 | I32: CUB S/R R2 | R32: PR2
B33: 40 | C33: 90 | D33: PR12 | E33: Y | G33: 50 | H33: -2 | I33: PR12 | R33: PR6
B34: 40 | C34: 90 | D34: PR19 | G34: 50 | H34: -2 | I34: PR19
B35: 40 | C35: 90 | D35: PR2 | E35: Z | G35: 50 | H35: -2 | I35: PR2 | R35: PR8
B36: 40 | C36: 90 | D36: PR6 | G36: 50 | H36: -2 | I36: PR6 | R36: PR12
B37: 40 | C37: 90 | D37: PR8 | G37: 50 | H37: -2 | I37: PR8 | R37: PR19
B48: 40 | C48: 150

Sheet CUBIERTA
L2: NO BORRAR REGLAS!!!!! SI NO LAS SABEN USAR NO BORREN ESTO POR FAVOR!!!!!
L3: SUSTRATO | N3: LAMINADO
D4: NOTA DE VENTA : | E4: ='4637'!J8 -> 4160 | L4: ALTO | M4: ANCHO | N4: ALTO | O4: ANCHO
D5: CLIENTE : | E5: ='4637'!C10 -> CONSTANZA SAINT | L5: =LOOKUP(#REF!,REGLAS!$I$4:$I$37,REGLAS!$G$4:$G$37)+#REF! -> #REF! | M5: =LOOKUP(#REF!,REGLAS!$I$4:$I$37,REGLAS!$H$4:$H$37)+#REF! -> #REF! | N5: =LOOKUP(#REF!,REGLAS!$D$4:$D$37,REGLAS!$B$4:$B$37)+#REF! -> #REF! | O5: =LOOKUP(#REF!,REGLAS!$D$4:$D$37,REGLAS!$C$4:$C$37)+#REF! -> #REF!
D7: ='4637'!I11 -> FECHA LIMITE : | E7: ='4637'!J11 -> 0 | G7: HECHO POR: FD
D8: FECHA ENTREGA:
B10: SUSTRATO
E12: ALTO | F12: ANCHO
B13: MATERIAL | C13: CANTIDAD | D13: CORTE | E13: 20 | F13: 20 | G13: DESCRIPCIÓN | K13: ALTO | L13: ANCHO
A14: 1 | B14: MELAMIL 18MM | C14: =J14 -> 2 | E14: =K14+E$13 -> 785 | F14: =L14+F$13 -> 416 | G14: =D46 -> E/R 1 CARA | J14: =J31 -> 2 | K14: =E46 -> 765 | L14: =F46 -> 396
A15: 2 | C15: =J15 -> 1 | E15: =K15+E$13 -> 785 | F15: =L15+F$13 -> 335 | G15: =D47 -> E/R 1 CARA | J15: =J32 -> 1 | K15: =E47 -> 765 | L15: =F47 -> 315
A16: 3 | C16: =J16 -> 1 | E16: =K16+E$13 -> 785 | F16: =L16+F$13 -> 295 | G16: =D48 -> E/R 1 CARA | J16: =J33 -> 1 | K16: =E48 -> 765 | L16: =F48 -> 275
A17: 4 | C17: =J17 -> 2 | E17: =K17+E$13 -> 680 | F17: =L17+F$13 -> 321 | G17: =D49 -> E/R 1 CARA | J17: =J34 -> 2 | K17: =E49 -> 660 | L17: =F49 -> 301
A18: 5 | C18: =J18 -> 2 | E18: =K18+E$13 -> 445 | F18: =L18+F$13 -> 321 | G18: =D50 -> E/R 1 CARA | J18: =J35 -> 2 | K18: =E50 -> 425 | L18: =F50 -> 301
A19: 6 | C19: =J19 -> 2 | E19: =K19+E$13 -> 197 | F19: =L19+F$13 -> 526 | G19: =D51 -> E/R 1 CARA | J19: =J36 -> 2 | K19: =E51 -> 177 | L19: =F51 -> 506
A20: 7 | C20: =J20 -> 1 | E20: =K20+E$13 -> 417 | F20: =L20+F$13 -> 526 | G20: =D52 -> E/R 1 CARA | J20: =J37 -> 1 | K20: =E52 -> 397 | L20: =F52 -> 506
A21: 8 | C21: =J21 -> 2 | E21: =K21+E$13 -> 197 | F21: =L21+F$13 -> 918 | G21: =D53 -> E/R 1 CARA | J21: =J38 -> 2 | K21: =E53 -> 177 | L21: =F53 -> 898
A22: 9 | C22: =J22 -> 1 | E22: =K22+E$13 -> 417 | F22: =L22+F$13 -> 918 | G22: =D54 -> E/R 1 CARA | J22: =J39 -> 1 | K22: =E54 -> 397 | L22: =F54 -> 898
A23: 10 | C23: =J23 -> 1 | E23: =K23+E$13 -> 670 | F23: =L23+F$13 -> 607 | G23: =D55 -> E/R 1 CARA | J23: =J40 -> 1 | K23: =E55 -> 650 | L23: =F55 -> 587
B27: LAMINADO
E29: ALTO | F29: ANCHO
B30: MATERIAL | C30: CANTIDAD | D30: CORTE | E30: 20 | F30: 20 | G30: DESCRIPCIÓN | K30: ALTO | L30: ANCHO
A31: 1 | C31: =J31 -> 2 | D31: PERFORACION 1 12,5CMS AL EJE | E31: =K31+E$30 -> 785 | F31: =L31+F$30 -> 416 | G31: =D46 -> E/R 1 CARA | J31: =C46 -> 2 | K31: =E46 -> 765 | L31: =F46 -> 396
A32: 2 | C32: =J32 -> 1 | D32: PERFORACION 1 12,5CMS AL EJE | E32: =K32+E$30 -> 785 | F32: =L32+F$30 -> 335 | G32: =D47 -> E/R 1 CARA | J32: =C47 -> 1 | K32: =E47 -> 765 | L32: =F47 -> 315
A33: 3 | C33: =J33 -> 1 | D33: PERFORACION 1 12,5CMS AL EJE | E33: =K33+E$30 -> 785 | F33: =L33+F$30 -> 295 | G33: =D48 -> E/R 1 CARA | J33: =C48 -> 1 | K33: =E48 -> 765 | L33: =F48 -> 275
A34: 4 | C34: =J34 -> 2 | D34: PERFORACION 1 12,5CMS AL EJE | E34: =K34+E$30 -> 680 | F34: =L34+60 -> 361 | G34: =D49 -> E/R 1 CARA | J34: =C49 -> 2 | K34: =E49 -> 660 | L34: =F49 -> 301 | M34: 2
A35: 5 | C35: =J35 -> 2 | D35: PERFORACION 1 12,5CMS AL EJE | E35: =K35+E$30 -> 445 | F35: =L35+90 -> 391 | G35: =D50 -> E/R 1 CARA | J35: =C50 -> 2 | K35: =E50 -> 425 | L35: =F50 -> 301
A36: 6 | C36: =J36 -> 2 | E36: =K36+E$30 -> 197 | F36: =L36+90 -> 596 | G36: =D51 -> E/R 1 CARA | J36: =C51 -> 2 | K36: =E51 -> 177 | L36: =F51 -> 506 | M36: 2
A37: 7 | C37: =J37 -> 1 | E37: =K37+E$30 -> 417 | F37: =L37+90 -> 596 | G37: =D52 -> E/R 1 CARA | J37: =C52 -> 1 | K37: =E52 -> 397 | L37: =F52 -> 506
A38: 8 | C38: =J38 -> 2 | E38: =K38+E$30 -> 197 | F38: =L38+90 -> 988 | G38: =D53 -> E/R 1 CARA | J38: =C53 -> 2 | K38: =E53 -> 177 | L38: =F53 -> 898
A39: 9 | C39: =J39 -> 1 | E39: =K39+E$30 -> 417 | F39: =L39+90 -> 988 | G39: =D54 -> E/R 1 CARA | J39: =C54 -> 1 | K39: =E54 -> 397 | L39: =F54 -> 898
A40: 10 | C40: =J40 -> 1 | E40: =K40+E$30 -> 670 | F40: =L40+90 -> 677 | G40: =D55 -> E/R 1 CARA | J40: =C55 -> 1 | K40: =E55 -> 650 | L40: =F55 -> 587
C43: MEDIDAS ORIGINALES
B45: MATERIAL | C45: CANTIDAD | D45: DESCRIPCIÓN | E45: ALTO | F45: ANCHO | G45: COLOR
A46: 1 | B46: MELAMIL18MM | C46: =C78 -> 2 | D46: =D78 -> E/R 1 CARA | E46: =E78 -> 765 | F46: =F78 -> 396 | G46: =G78 -> AZUL PACIFICO 2170 MT | I46: =E46*F46/1000000 -> 0.30294 | J46: =I46*C46 -> 0.60588
A47: 2 | C47: =C79 -> 1 | D47: =D79 -> E/R 1 CARA | E47: =E79 -> 765 | F47: =F79 -> 315 | G47: =G79 -> AZUL PACIFICO 2170 MT
A48: 3 | C48: =C80 -> 1 | D48: =D80 -> E/R 1 CARA | E48: =E80 -> 765 | F48: =F80 -> 275 | G48: =G80 -> AZUL PACIFICO 2170 MT
A49: 4 | C49: =C81 -> 2 | D49: =D81 -> E/R 1 CARA | E49: =E81 -> 660 | F49: =F81 -> 301 | G49: =G81 -> AZUL PACIFICO 2170 MT
A50: 5 | C50: =C82 -> 2 | D50: =D82 -> E/R 1 CARA | E50: =E82 -> 425 | F50: =F82 -> 301 | G50: =G82 -> AZUL PACIFICO 2170 MT
A51: 6 | C51: =C83 -> 2 | D51: =D83 -> E/R 1 CARA | E51: =E83 -> 177 | F51: =F83 -> 506 | G51: =G83 -> AZUL PACIFICO 2170 MT
...
