Workbook

Sheet 2229
F2: MUEBLES SANTA FE SPA
F3: VENTAS POR MENOR DE MUEBLES
F4: RUT: 77.054.606-0
F5: SEPTIMA AVENIDA 1631, SAN MIGUEL
F6: FONO +569 2032 3382 | O6: 10077 SF PORTLAND MAPLE
F7: E-MAIL: ventas@topmobili.cl
B8: P R E S U P U E S T O | D8: N° 11429 | J8: 152
J9: 129
B10: NOMBRE: | C10: CONSTRUCTORA MV | F10: FECHA: | G10: 45789 | J10: =J8-J9 -> 23
B11: RUT: | F11: PLAZO ENTREGA: | G11: 5 DIAS HABILES | R11: MT2 PUERTAS
B12: GIRO: | F12: SERVICIO EXPRESS | G12: no | J12: 44
B13: CONTACTO: | C13: ANDREA VOGEL | J13: 114
B14: CORREO: | F14: CORTADA A LA MEDIDA | G14: NO | R14: ML CUBIERTAS
B15: FONO: | C15: 56981371910 | F15: DESPACHO: | G15: SI | J15: =SUM(J12:J14) -> 158
B16: DIRECCION: | F16: FORMA DE PAGO: | G16: ABONO 50% SALDO C/ENTREGA
B17: CIUDAD: | C17: SANTIAGO | F17: DURACION COTIZACION: 5 DIAS FRANCO DONOSO
B19: DETALLE | M19: 0.08 | P19: TOTAL | Q19: VALOR X MT2 | R19: ENCHAPE | S19: MT/L
B20: UNIDAD | C20: TIPO | D20: LARGO | E20: ANCHO | F20: COLOR | G20: VALOR | H20: TOTAL | L20: =B20 -> UNIDAD | M20: ALTO | N20: =E20 -> ANCHO | O20: MT | P20: MT2 | Q20: =O42 -> 110506.95 | R20: 3000 | T20: m/l
B21: 1 | C21: CUB RECTA FRENTE 30MM | D21: 1.4 | E21: 0.72 | F21: BLOND HECHO 7939-60 | G21: 120756 | H21: =G21*B21 -> 120756 | L21: =B21 -> 1 | M21: =D21+M$19 -> 1.48 | N21: =E21+$N$19 -> 0.72 | O21: =M21*N21 -> 1.0656 | P21: =O21*L21 -> 1.0656 | Q21: =Q$20*O21 -> 117756.21 | R21: =Q21+R$20 -> 120756.21 | S21: =M21*L21 -> 1.48 | T21: =M21*L21 -> 1.48
B22: 2 | C22: E/R 1 CARA 15MM | D22: 1.75 | E22: 0.72 | F22: BLOND HECHO 7939-60 | G22: 148604 | H22: =G22*B22 -> 297208 | L22: =B22 -> 2 | M22: =D22+M$19 -> 1.83 | N22: =E22+$N$19 -> 0.72 | O22: =M22*N22 -> 1.3176 | P22: =O22*L22 -> 2.6352 | Q22: =Q$20*O22 -> 145603.96 | R22: =Q22+R$20 -> 148603.96
B23: 2 | C23: E/R 1 CARA 40MM | D23: 1.75 | E23: 0.04 | F23: TEAL 2321 MT | G23: 11089 | H23: =G23*B23 -> 22178 | L23: =B23 -> 2 | M23: =D23+M$19 -> 1.83 | N23: =E23+$N$19 -> 0.04 | O23: =M23*N23 -> 0.0732 | P23: =O23*L23 -> 0.1464 | Q23: =Q$20*O23 -> 8089.1091 | R23: =Q23+R$20 -> 11089.109
B24: 2 | C24: E/R 1 CARA 40MM | D24: 1.4 | E24: 0.04 | F24: TEAL 2321 MT | G24: 9542 | H24: =G24*B24 -> 19084 | L24: =B24 -> 2 | M24: =D24+M$19 -> 1.48 | N24: =E24+$N$19 -> 0.04 | O24: =M24*N24 -> 0.0592 | P24: =O24*L24 -> 0.1184 | Q24: =Q$20*O24 -> 6542.0117 | R24: =Q24+R$20 -> 9542.0117
B25: 2 | C25: E/R 1 CARA | D25: 0.7 | E25: 0.4 | F25: TEAL 2321 MT | G25: 47478 | H25: =G25*B25 -> 94956 | L25: =B25 -> 2 | M25: =D25+M$19 -> 0.78 | N25: =E25+$N$19 -> 0.4 | O25: =M25*N25 -> 0.312 | P25: =O25*L25 -> 0.624 | Q25: =Q$20*O25 -> 34478.17 | R25: =Q25+R$20 -> 37478.17
G28: NETO | H28: =SUM(H21:H27) -> 554182 | T28: =SUM(T21:T27) -> 1.48
G29: IVA | H29: =H28*19% -> 105294.58 | M29: =SUM(M21:M28) -> 7.4 | P29: =SUM(P21:P27) -> 4.5896
G30: TOTAL | H30: =H28+H29 -> 659476.58 | P30: =P29 -> 4.5896 | S30: =SUM(S21:S29) -> 1.48
P31: =P30*20% -> 0.91792 | Q31: 20% PERDIDA | S31: =S30+T28 -> 2.96
P32: =P30+P31 -> 5.50752 | S32: =S31*20% -> 0.592
S33: =S31+S32 -> 3.552 | U33: ADHESIVO | V33: 58.000.- | W33: 44971
M34: =P32*2 -> 11.01504 | N34: 2500 | O34: =M34*N34 -> 27537.6 | P34: ADHESIVO | U34: LATA 16 LTS | V34: 3625 | W34: LITRO
M35: 2 | N35: 25000 | O35: =M35*N35 -> 50000 | P35: MDF 18MM | V35: 906.25 | W35: MT2 (4)
B36: CUENTA CORRIENTE BANCO SANTANDER Nº 87316181 A NOMBRE DE MUEBLES SANTA FE SPA | N36: 35000 | O36: =M36*N36 -> 0 | P36: LAMINA 153 X 366 | V36: =V35*20% -> 181.25 | W36: PERDIDA 20%
B37: RUT : 77.054.606-0 VENTAS@TOPMOBILI.CL | M37: 3 | N37: 51000 | O37: =M37*N37 -> 153000 | P37: LAMINA 122X244 | V37: =V35+V36 -> 1087.5 | W37: MINIMO A COTIZAR
B38: VISITANOS Y DESCUBRE NUESTROS PRODUCTOS EN | F38: WWW.TOPMOBILICHILE.CL | N38: 900 | O38: =M38*N38 -> 0 | P38: RESPALDO | R38: 1.52
N39: 500 | O39: =M39*N39 -> 0 | P39: MEDIA CAÑA | R39: 2.44
O40: =SUM(O34:O39) -> 230537.6 | P40: COSTO | R40: =R38*R39 -> 3.7088
M41: PRECIO VENTA | O41: =O40*2.2 -> 507182.72 | P41: FACTOR 2,3 PARA 90° | R41: =P32/R40 -> 1.4849871
K42: 60590 | O42: =O41/P30 -> 110506.95 | P42: VALOR M2 | U42: MDF30MM | V42: 43650
K43: =K42/1.19 -> 50915.966 | O43: =O41/O40 -> 2.2 | U43: 46 UNIDADES | V43: 948.91 | W43: 2.4
U44: METRO LINEAL | V44: 395.37
...

Sheet COSTOS
B2: CENTRO DE COSTOS POSTFORMADOS
B5: FECHA: | C5: ='2229'!G10 -> 45789
B6: CLIENTE: | C6: ='2229'!C10 -> CONSTRUCTORA MV | N6: Ventas Equilibrio = | P6: Costos Fijos Totales
B7: DIRECCION: | C7: ='2229'!#REF! -> #REF! | H7: COSTOS INDIRECTOS DE FABRICA VARIABLES | O7: 1 - | P7: Costos Variables Totales
B8: PRESUPUESTO: | C8: ='2229'!D8 -> N° 11429 | H8: Q/HRS | I8: $ | J8: DETALLE | K8: TOTAL | L8: TOTAL | P8: Total Venta | X8: =SUM(Q11:Q16) -> 6
H9: CANTIDAD | I9: PRECIO | J9: MATERIA PRIMA INDIRECTA | L9: =SUM(K10:K23) -> 2550 | S9: DETALLE | X9: =(E15-D11)/X8 -> -62836.452
D10: NETO | E10: IVA | F10: TOTAL | H10: 3 | I10: 350 | J10: RESPALDO | K10: =I10*H10 -> 1050 | Q10: UNIDAD | R10: TIPO | S10: LARGO | T10: ANCHO | U10: COLOR | V10: VALOR | W10: TOTAL
C11: MONTO A COBRAR | D11: ='2229'!H28 -> 554182 | E11: =D11*0.19 -> 105294.58 | F11: =E11+D11 -> 659476.58 | H11: 3 | I11: 500 | J11: MEDIA CAÑA | K11: =I11*H11 -> 1500 | Q11: 1 | R11: CUB C/R R8 | S11: 2.8 | T11: 0.62 | U11: MADERA X DEFINIR | V11: 105990 | W11: =V11*Q11 -> 105990 | X11: =V11+$X$9 -> 43153.548 | Y11: 108990
C12: COSTO TOTAL | D12: =SUM(M43:M45) -> 107371.69 | H12: 0 | I12: 7500 | J12: DUROLAC | K12: =I12*H12 -> 0 | Q12: 1 | R12: CUB C/R R8 | S12: 2.3 | T12: 0.62 | U12: MADERA X DEFINIR | V12: 87990 | W12: =V12*Q12 -> 87990 | X12: =V12+$X$9 -> 25153.548 | Y12: 89990
C13: % UTILIDAD | D13: =D11-D12 -> 446810.31 | E13: =(D11/D12)-1 -> 4.1613418 | H13: 0 | I13: 50 | J13: TAPACANTO PVC | K13: =I13*H13 -> 0 | Q13: 1 | R13: CUB C/R R8 | S13: 2.03 | T13: 0.62 | U13: MADERA X DEFINIR | V13: 78990 | W13: =V13*Q13 -> 78990 | X13: =V13+$X$9 -> 16153.548 | Y13: 81990
D14: % utilidad | E14: NETO | F14: UTILIDAD | H14: 0 | I14: 50 | J14: SOBERBIOS | K14: =I14*H14 -> 0 | Q14: 1 | R14: CUB C/R R8 | S14: 1.08 | T14: 0.62 | U14: MADERA X DEFINIR | V14: 39990 | W14: =V14*Q14 -> 39990 | X14: =V14+$X$9 -> -22846.452 | Y14: 39990
C15: PROYECCION | D15: 0.65 | E15: =(100%+D15)*D12 -> 177163.29 | F15: =E15-D12 -> 69791.599 | H15: 0 | I15: 10 | J15: SOPORTE REPISA | K15: =I15*H15 -> 0 | Q15: 1 | R15: CUB C/R R8 | S15: 1.08 | T15: 0.62 | U15: MADERA X DEFINIR | V15: 39990 | W15: =V15*Q15 -> 39990 | X15: =V15+$X$9 -> -22846.452 | Y15: 39990
H16: 1 | J16: PUNTAS | K16: =I16*H16 -> 0 | Q16: 1 | R16: CUB C/R R8 | S16: 2.06 | T16: 0.62 | U16: MADERA X DEFINIR | V16: 79990 | W16: =V16*Q16 -> 79990 | X16: =V16+$X$9 -> 17153.548 | Y16: 83990
B17: M. PRIMA | C17: MATERIAL | D17: NETO | E17: IVA | F17: TOTAL | H17: 1 | J17: TORNILLOS | K17: =I17*H17 -> 0 | Q17: 6 | R17: CORTES 45° | V17: 5000 | W17: =V17*Q17 -> 30000
C18: LAMINA | D18: ='2229'!O36 -> 0 | E18: =D18*0.19 -> 0 | F18: =SUM(D18:E18) -> 0 | H18: 1 | J18: COLAFRIA | K18: =I18*H18 -> 0 | Q18: 1 | R18: PERFORACION LAVAPLATOS | V18: 10000 | W18: =V18*Q18 -> 10000
C19: MDF 18MM | D19: ='2229'!O35 -> 50000 | E19: =D19*0.19 -> 9500 | F19: =SUM(D19:E19) -> 59500 | H19: 1 | J19: LIJAS | K19: =I19*H19 -> 0 | V19: NETO | W19: =SUM(W11:W18) -> 472940 | Y19: =SUM(Y11:Y16)+SUM(W17:W18) -> 484940
C20: ADHESIVO | D20: ='2229'!O34 -> 27537.6 | E20: =D20*0.19 -> 5232.144 | F20: =SUM(D20:E20) -> 32769.744 | H20: 1 | J20: CARTON | K20: =I20*H20 -> 0 | V20: I.V.A. | W20: =W19*19% -> 89858.6 | Y20: =Y19*0.19 -> 92138.6
A21: =450000*1.2 -> 540000 | C21: TOTAL | D21: =SUM(D18:D20) -> 77537.6 | E21: =SUM(E18:E20) -> 14732.144 | F21: =SUM(F18:F20) -> 92269.744 | H21: 1 | J21: GUAIPE | K21: =I21*H21 -> 0 | M21: =B32/9 -> 2318.8406 | Q21: PLAZO DE ENTREGA : 8 DIAS HABILES | V21: TOTAL | W21: =W19+W20 -> 562798.6 | Y21: =SUM(Y19:Y20) -> 577078.6
A22: =450000*1.2 -> 540000 | B22: M. DE OBRA | C22: PROCESO | D22: COSTO x Hr. | E22: Q Hrs. | F22: TOTAL | H22: 1 | J22: DILUYENTE | K22: =I22*H22 -> 0 | Q22: FORMA DE PAGO: 50% CONTADO, SALDO C/E
A23: =800000*1.2 -> 960000 | B23: =A21/23 -> 23478.261 | C23: CORTE | D23: =B23/9 -> 2608.6957 | E23: 0.5 | F23: =D23*E23 -> 1304.3478 | H23: 1 | J23: CINTA EMBALAJE | K23: =I23*H23 -> 0 | Q23: VALIDEZ COTIZACIÓN: 5 DIAS
A24: 450000 | B24: =A22/23 -> 23478.261 | C24: CORTE LAMINA | D24: =B24/9 -> 2608.6957 | E24: 0.5 | F24: =D24*E24 -> 1304.3478 | H24: Q/HRS | I24: PRECIO | J24: MANO DE OBRA INDIRECTA | K24: VALOR | L24: =SUM(K25:K35) -> 0
A25: 450000 | B25: =A23/23 -> 41739.13 | C25: REBAJE LAMINA | D25: =B25/9 -> 4637.6812 | F25: =D25*E25 -> 0 | H25: 0 | I25: =((480000/23)/9) -> 2318.8406 | J25: FLETERO (HRS) | K25: =H25*I25 -> 0
B26: =A24/23 -> 19565.217 | C26: TUPIZADO | D26: =B26/9 -> 2173.913 | E26: 0.5 | F26: =D26*E26 -> 1086.9565 | H26: 0 | J26: BENCINA | K26: =H26*I26 -> 0
A27: 350000 | B27: =A25/23 -> 19565.217 | C27: ARMADO | D27: =B27/9 -> 2173.913 | E27: 0.5 | F27: =D27*E27 -> 1086.9565 | H27: 0 | J27: TAG | K27: =H27*I27 -> 0
A28: 500000 | B28: =A27/23 -> 15217.391 | C28: PEGADO | D28: =B28/9 -> 1690.8213 | E28: 0.7 | F28: =D28*E28 -> 1183.5749 | H28: 0 | J28: RECTIFICACION | K28: =H28*I28 -> 0
B29: =A28/23 -> 21739.13 | C29: POSTFORMADO | D29: =B29/9 -> 2415.4589 | E29: 0.7 | F29: =D29*E29 -> 1690.8213 | H29: 0 | I29: =((550000*1.2)/23)/9 -> 3188.4058 | J29: HR. TRAB. JUAN | K29: =H29*I29 -> 0
A30: 450000 | C30: MEDIA CAÑA | D30: 2415 | F30: =D30*E30 -> 0 | H30: 0 | I30: =((450000*1.2)/23)/9 -> 2608.6957 | J30: HR. TRAB. JULIO | K30: =H30*I30 -> 0
A31: 350000 | B31: =A30/23 -> 19565.217 | C31: CORTE-ENCHAPE | D31: =B31/9 -> 2173.913 | E31: 0 | F31: =D31*E31 -> 0 | H31: 0 | I31: =((450000*1.2)/23)/9 -> 2608.6957 | J31: HR. TRAB. EUGE | K31: =H31*I31 -> 0
A32: =A21+A24+A27+A28+A30 -> 2290000 | B32: =480000/23 -> 20869.565 | C32: CONTROL CALIDAD | D32: =B32/9 -> 2318.8406 | E32: 0.5 | F32: =D32*E32 -> 1159.4203 | H32: 0 | J32: COLACION | K32: =H32*I32 -> 0
C33: TOTAL | D33: =SUM(D23:D32) -> 25216.932 | E33: =SUM(E23:E32) -> 3.9 | F33: =SUM(F23:F32) -> 8816.4251 | H33: 0 | J33: BONO | K33: =H33*I33 -> 0
B34: CIF | C34: M. PRIMA INDIREC. | D34: =L9 -> 2550 | H34: 1 | J34: PERFORACION | K34: =H34*I34 -> 0
C35: M. OBRA INDIRECTA | D35: =L24 -> 0 | H35: 6 | J35: CORTE 45 | K35: =H35*I35 -> 0
C36: GASTOS DE FABRICA | D36: =L36 -> 18467.666 | H36: CANTIDAD | I36: PRECIO | J36: GASTOS DE FABRICACION | K36: VALOR | L36: =SUM(K37:K39) -> 18467.666
C37: DEPRECIACIONES | H37: =$E$33 -> 3.9 | I37: =32609.69/9 -> 3623.2989 | J37: ARRIENDO x HORA | K37: =I37*H37 -> 14130.866
C38: TOTAL | D38: =SUM(D34:D37) -> 21017.666 | H38: =$E$33 -> 3.9 | I38: 967 | J38: AGUA x HORA | K38: =I38*H38 -> 3771.3
H39: =$E$33 -> 3.9 | I39: 145 | J39: LUZ x HORA | K39: =I39*H39 -> 565.5
B40: PROVISIONAR | C40: IVA | D40: =E11-E21 -> 90562.436
H41: ESTADO DE RESULTADOS
B42: TOTAL HRS TRABAJADAS | D42: =E33 -> 3.9 | H42: INGRESOS | I42: + TOTAL VENTA | M42: =D11 -> 554182
H43: COSTOS | I43: - MATERIA PRIMA DIRECTA | M43: =D21 -> 77537.6
...
