Workbook

Sheet 2229
F2: MUEBLES SANTA FE SPA
F3: VENTAS POR MENOR DE MUEBLES
F4: RUT: 77.054.606-0
F5: SEPTIMA AVENIDA 1631, SAN MIGUEL
F6: FONO 22521 6502 | N6: 10077 SF PORTLAND MAPLE
F7: E-MAIL: ventas@topmobili.cl
B8: P R E S U P U E S T O | D8: N° 11426
B10: NOMBRE: | C10: MARI GOMEZ | F10: FECHA: | G10: 45785
B11: RUT: | F11: PLAZO ENTREGA: | G11: 5 DIAS HABILES | Q11: MT2 PUERTAS
B12: GIRO: | F12: SERVICIO EXPRESS | G12: NO
B13: CONTACTO: | F13: CORTADA A LA MEDIDA | G13: NO
B14: CORREO: | F14: EMBALAJE | G14: NO | Q14: ML CUBIERTAS
B15: FONO: | C15: +569 7881 7969 | F15: DESPACHO: | G15: NO
B16: DIRECCION: | F16: FORMA DE PAGO: | G16: ABONO 50% SALDO C/ENTREGA
B17: CIUDAD: | C17: SANTIAGO | F17: DURACION COTIZACION: 5 DIAS FRANCO DONOSO
B19: , | L19: 0.05 | M19: 0.08 | O19: TOTAL | P19: VALOR X MT2 | Q19: ENCHAPE | R19: MT/L
B20: UNIDAD | C20: TIPO | D20: LARGO | E20: ANCHO | F20: COLOR | G20: VALOR | H20: TOTAL | K20: =B20 -> UNIDAD | L20: ALTO | M20: =E20 -> ANCHO | N20: MT | O20: MT2 | P20: =N39 -> 24786.176 | Q20: 10000 | S20: m/l
B21: 1 | C21: CUBIERTA CON RESPALDO 90° | D21: 3 | E21: 0.6 | F21: BLANCO BR | G21: 54613.4 | H21: =G21*B21 -> 54613.4 | K21: =B21 -> 1 | L21: =D21+L$19 -> 3.05 | M21: =E21+M$19 -> 0.68 | N21: =L21*M21 -> 2.074 | O21: =N21*K21 -> 2.074 | P21: =P$20*N21 -> 51406.53 | Q21: =P21+Q$20 -> 61406.53 | R21: =L21*K21*2 -> 6.1 | S21: =M21*2*K21 -> 1.36
R22: =L22*K22*2 -> 0
N24: 0
G25: NETO | H25: =SUM(H21:H24) -> 54613.4 | L25: =SUM(L21:L24) -> 3.05 | S25: =SUM(S21:S24) -> 1.36
G26: IVA | H26: =H25*19% -> 10376.546 | O26: =SUM(O21:O22) -> 2.074 | S26: =S25*20% -> 0.272
G27: TOTAL | H27: =H25+H26 -> 64989.946 | O27: =O26 -> 2.074 | R27: =SUM(R21:R26) -> 6.1 | S27: =S25+S26 -> 1.632
J28: 147074 | O28: =O27*20% -> 0.4148 | P28: 20% PERDIDA
J29: 33749 | O29: =O27+O28 -> 2.4888 | R29: 40
J30: 94650 | T30: ADHESIVO | U30: 58.000.- | V30: 44971
J31: =SUM(J28:J30) -> 275473 | L31: =O29 -> 2.4888 | M31: 3500 | N31: =L31*M31 -> 8710.8 | O31: ADHESIVO | T31: LATA 16 LTS | U31: 3625 | V31: LITRO
L32: 0.671 | M32: 23500 | N32: =L32*M32 -> 15768.5 | O32: MDF 18MM | U32: 906.25 | V32: MT2 (4)
M33: 61860 | N33: =L33*M33 -> 0 | O33: LAMINA 153 X 366 | U33: =U32*20% -> 181.25 | V33: PERDIDA 20%
B34: CUENTA CORRIENTE BANCO SANTANDER Nº 87316181 A NOMBRE DE MUEBLES SANTA FE SPA | M34: 0 | N34: =L34*M34 -> 0 | O34: LAMINA 122 X 306 | U34: =U32+U33 -> 1087.5 | V34: MINIMO A COTIZAR
B35: RUT : 77.054.606-0 VENTAS@TOPMOBILI.CL | J35: 27000 | M35: 300 | N35: =L35*M35 -> 0 | O35: RESPALDO | Q35: 1.52
B36: VISITANOS Y DESCUBRE NUESTROS PRODUCTOS EN | F36: WWW.TOPMOBILICHILE.CL | J36: =J35*19% -> 5130 | M36: 1500 | N36: =L36*M36 -> 0 | O36: MEDIA CAÑA | Q36: 2.44
I37: KING | J37: =J35+J36 -> 32130 | N37: =SUM(N31:N36) -> 24479.3 | O37: COSTO | Q37: =Q35*Q36 -> 3.7088
L38: PRECIO VENTA | N38: =N37*2.1 -> 51406.53 | O38: FACTOR 2,3 PARA 90° | Q38: =O29/Q37 -> 0.67105263
I39: GRIS NUBE | J39: 23560 | K39: 0 | N39: =N38/O27 -> 24786.176 | O39: VALOR M2 | T39: MDF30MM | U39: 43650
J40: =J39/1.19 -> 19798.319 | N40: =N38/N37 -> 2.1 | T40: 46 UNIDADES | U40: 948.91 | V40: 2.4
T41: METRO LINEAL | U41: 395.37
I42: MDF 3MM | T42: PERDIDA 20% | U42: 474.45
I43: 152X244 | J43: 8990
I45: 46850
...

Sheet COSTOS
B2: CENTRO DE COSTOS POSTFORMADOS
B5: FECHA: | C5: ='2229'!G10 -> 45785
B6: CLIENTE: | C6: ='2229'!C10 -> MARI GOMEZ | N6: Ventas Equilibrio = | P6: Costos Fijos Totales
B7: DIRECCION: | C7: ='2229'!#REF! -> #REF! | H7: COSTOS INDIRECTOS DE FABRICA VARIABLES | O7: 1 - | P7: Costos Variables Totales
B8: PRESUPUESTO: | C8: ='2229'!D8 -> N° 11426 | H8: Q/HRS | I8: $ | J8: DETALLE | K8: TOTAL | L8: TOTAL | P8: Total Venta | X8: =SUM(Q11:Q16) -> 6
B9: ML | C9: =SUM('2229'!L25) -> 3.05 | H9: CANTIDAD | I9: PRECIO | J9: MATERIA PRIMA INDIRECTA | L9: =SUM(K10:K23) -> 6136.4 | S9: DETALLE | X9: =(E15-D11)/X8 -> 3355.6028
B10: M.ANCHO | C10: =SUM('2229'!M21:M24) -> 0.68 | D10: NETO | E10: IVA | F10: TOTAL | H10: =C9 -> 3.05 | I10: 300 | J10: RESPALDO | K10: =I10*H10 -> 915 | Q10: UNIDAD | R10: TIPO | S10: LARGO | T10: ANCHO | U10: COLOR | V10: VALOR | W10: TOTAL
C11: MONTO A COBRAR | D11: ='2229'!H25 -> 54613.4 | E11: =D11*0.19 -> 10376.546 | F11: =E11+D11 -> 64989.946 | H11: =C9 -> 3.05 | I11: 1500 | J11: MEDIA CAÑA | K11: =I11*H11 -> 4575 | Q11: 1 | R11: CUB C/R R8 | S11: 2.8 | T11: 0.62 | U11: MADERA X DEFINIR | V11: 105990 | W11: =V11*Q11 -> 105990 | X11: =V11+$X$9 -> 109345.6 | Y11: 108990
C12: COSTO TOTAL | D12: =SUM(M53:M55) -> 45301.222 | H12: 0 | I12: 7500 | J12: DUROLAC | K12: =I12*H12 -> 0 | Q12: 1 | R12: CUB C/R R8 | S12: 2.3 | T12: 0.62 | U12: MADERA X DEFINIR | V12: 87990 | W12: =V12*Q12 -> 87990 | X12: =V12+$X$9 -> 91345.603 | Y12: 89990
C13: % UTILIDAD | D13: =D11-D12 -> 9312.1776 | E13: =(D11/D12)-1 -> 0.20556129 | H13: 0 | I13: 50 | J13: TAPACANTO PVC | K13: =I13*H13 -> 0 | Q13: 1 | R13: CUB C/R R8 | S13: 2.03 | T13: 0.62 | U13: MADERA X DEFINIR | V13: 78990 | W13: =V13*Q13 -> 78990 | X13: =V13+$X$9 -> 82345.603 | Y13: 81990
D14: % utilidad | E14: NETO | F14: UTILIDAD | H14: =IF('2229'!G14="SI",(I14*C9),0) -> 0 | I14: 50 | J14: FILM | K14: =I14*H14 -> 0 | Q14: 1 | R14: CUB C/R R8 | S14: 1.08 | T14: 0.62 | U14: MADERA X DEFINIR | V14: 39990 | W14: =V14*Q14 -> 39990 | X14: =V14+$X$9 -> 43345.603 | Y14: 39990
C15: PROYECCION | D15: 0.65 | E15: =(100%+D15)*D12 -> 74747.017 | F15: =E15-D12 -> 29445.795 | H15: =C9 -> 3.05 | I15: 22 | J15: AGUARRAS | K15: =I15*H15 -> 67.1 | Q15: 1 | R15: CUB C/R R8 | S15: 1.08 | T15: 0.62 | U15: MADERA X DEFINIR | V15: 39990 | W15: =V15*Q15 -> 39990 | X15: =V15+$X$9 -> 43345.603 | Y15: 39990
H16: 12 | I16: 2 | J16: PUNTAS | K16: =I16*H16 -> 24 | Q16: 1 | R16: CUB C/R R8 | S16: 2.06 | T16: 0.62 | U16: MADERA X DEFINIR | V16: 79990 | W16: =V16*Q16 -> 79990 | X16: =V16+$X$9 -> 83345.603 | Y16: 83990
B17: M. PRIMA | C17: MATERIAL | D17: NETO | E17: IVA | F17: TOTAL | H17: 12 | I17: 11 | J17: TORNILLOS | K17: =I17*H17 -> 132 | N17: =25000/1.19 -> 21008.403 | Q17: 6 | R17: CORTES 45° | V17: 5000 | W17: =V17*Q17 -> 30000
C18: LAMINA | D18: ='2229'!N33 -> 0 | E18: =D18*0.19 -> 0 | F18: =SUM(D18:E18) -> 0 | H18: =C9 -> 3.05 | I18: 90 | J18: COLAFRIA | K18: =I18*H18 -> 274.5 | N18: =N17/25 -> 840.33613 | Q18: 1 | R18: PERFORACION LAVAPLATOS | V18: 10000 | W18: =V18*Q18 -> 10000
C19: MDF 18MM | D19: ='2229'!N32 -> 15768.5 | E19: =D19*0.19 -> 2996.015 | F19: =SUM(D19:E19) -> 18764.515 | H19: =C9 -> 3.05 | I19: 2 | J19: LIJAS | K19: =I19*H19 -> 6.1 | V19: NETO | W19: =SUM(W11:W18) -> 472940 | Y19: =SUM(Y11:Y16)+SUM(W17:W18) -> 484940
C20: ADHESIVO | D20: ='2229'!N31 -> 8710.8 | E20: =D20*0.19 -> 1655.052 | F20: =SUM(D20:E20) -> 10365.852 | H20: =IF('2229'!G14="SI",C9,0) -> 0 | I20: 841 | J20: CARTON | K20: =I20*H20 -> 0 | V20: I.V.A. | W20: =W19*19% -> 89858.6 | Y20: =Y19*0.19 -> 92138.6
A21: =950000*1.2 -> 1140000 | C21: TOTAL | D21: =SUM(D18:D20) -> 24479.3 | E21: =SUM(E18:E20) -> 4651.067 | F21: =SUM(F18:F20) -> 29130.367 | H21: =C9 -> 3.05 | I21: 21 | J21: GUAIPE | K21: =I21*H21 -> 64.05 | Q21: PLAZO DE ENTREGA : 8 DIAS HABILES | V21: TOTAL | W21: =W19+W20 -> 562798.6 | Y21: =SUM(Y19:Y20) -> 577078.6
A22: =950000*1.2 -> 1140000 | B22: M. DE OBRA | C22: PROCESO | D22: COSTO x Hr. | E22: Q Hrs. | F22: TOTAL | H22: =E33 -> 0.55 | I22: 143 | J22: DILUYENTE | K22: =I22*H22 -> 78.65 | Q22: FORMA DE PAGO: 50% CONTADO, SALDO C/E
A23: =800000*1.2 -> 960000 | B23: =A21/22 -> 51818.182 | C23: CORTE | D23: =B23/8 -> 6477.2727 | E23: 0.1 | F23: =D23*E23 -> 647.72727 | H23: =IF('2229'!G14="SI",((C10*3)*3),0) -> 0 | I23: 13 | J23: CINTA EMBALAJE | K23: =I23*H23 -> 0 | Q23: VALIDEZ COTIZACIÓN: 5 DIAS
A24: 1300000 | B24: =A22/22 -> 51818.182 | C24: CORTE LAMINA | D24: =B24/8 -> 6477.2727 | E24: 0.05 | F24: =D24*E24 -> 323.86364 | H24: Q/HRS | I24: PRECIO | J24: MANO DE OBRA INDIRECTA | K24: VALOR | L24: =SUM(K25:K35) -> 7819.1406
A25: 1300000 | B25: =A23/22 -> 43636.364 | C25: REBAJE LAMINA (R2) | D25: =B25/8 -> 5454.5455 | F25: =D25*E25 -> 0 | H25: 1 | I25: =((480000/23)/9) -> 2318.8406 | J25: FLETERO (HRS) | K25: =H25*I25 -> 2318.8406
B26: =A24/22 -> 59090.909 | C26: TUPIZADO | D26: =B26/8 -> 7386.3636 | E26: 0.1 | F26: =D26*E26 -> 738.63636 | H26: 1 | I26: 3000 | J26: BENCINA | K26: =H26*I26 -> 3000
A27: 1300000 | B27: =A25/22 -> 59090.909 | C27: ARMADO | D27: =B27/8 -> 7386.3636 | E27: 0.1 | F27: =D27*E27 -> 738.63636 | H27: 0 | J27: TAG | K27: =H27*I27 -> 0
A28: 450000 | B28: =A27/22 -> 59090.909 | C28: PEGADO | D28: =B28/8 -> 7386.3636 | E28: 0.1 | F28: =D28*E28 -> 738.63636 | H28: 0 | J28: RECTIFICACION | K28: =H28*I28 -> 0
B29: =A28/22 -> 20454.545 | C29: POSTFORMADO | D29: =B29/8 -> 2556.8182 | E29: 0.1 | F29: =D29*E29 -> 255.68182 | H29: 0 | I29: =((400000/22)/8) -> 2272.7273 | J29: CONTROL CALIDAD | K29: =H29*I29 -> 0
A30: 950000 | C30: MEDIA CAÑA | D30: =D28 -> 7386.3636 | F30: =D30*E30 -> 0 | H30: =E33 -> 0.55 | I30: 2020 | J30: ADMINISTRADOR | K30: =H30*I30 -> 1111
A31: 350000 | B31: =A30/22 -> 43181.818 | C31: CORTE-ENCHAPE | D31: =B31/8 -> 5397.7273 | E31: 0 | F31: =D31*E31 -> 0 | H31: =E33 -> 0.55 | I31: 2526 | J31: VENDEDOR | K31: =H31*I31 -> 1389.3
A32: =A21+A24+A27+A28+A30 -> 5140000 | B32: =400000/22 -> 18181.818 | C32: CONTROL CALIDAD | D32: =B32/8 -> 2272.7273 | E32: 0 | F32: =D32*E32 -> 0 | H32: 0 | J32: COLACION | K32: =H32*I32 -> 0
C33: TOTAL | D33: =SUM(D23:D32) -> 58181.818 | E33: =SUM(E23:E32) -> 0.55 | F33: =SUM(F23:F32) -> 3443.1818 | H33: 0 | J33: BONO | K33: =H33*I33 -> 0
B34: CIF | C34: M. PRIMA INDIREC. | D34: =L9 -> 6136.4 | H34: 0 | I34: 15000 | J34: PERFORACION | K34: =H34*I34 -> 0
C35: M. OBRA INDIRECTA | D35: =L24 -> 7819.1406 | H35: 0 | I35: 7500 | J35: CORTE 45 | K35: =H35*I35 -> 0
C36: GASTOS DE FABRICA | D36: =L36 -> 3423.2 | H36: CANTIDAD | I36: PRECIO | J36: GASTOS INDIRECTOS | K36: VALOR | L36: =SUM(K37:K49) -> 3423.2
C37: DEPRECIACIONES | H37: =$E$33 -> 0.55 | I37: 4394 | J37: ARRIENDO x HORA | K37: =I37*H37 -> 2416.7
C38: TOTAL | D38: =SUM(D34:D37) -> 17378.741 | H38: =$E$33 -> 0.55 | I38: 127 | J38: AGUA x HORA | K38: =I38*H38 -> 69.85
H39: =$E$33 -> 0.55 | I39: 253 | J39: GAS | K39: =I39*H39 -> 139.15
H40: =$E$33 -> 0.55 | I40: 61 | J40: INTERNET | K40: =I40*H40 -> 33.55 | O40: =O39/22 -> 0
H41: =$E$33 -> 0.55 | I41: 379 | J41: DEPRECIACION MAQUINARIA | K41: =I41*H41 -> 208.45 | O41: =O40/9 -> 0
J42: DEPRECIACION CAMIONETA
H43: =$E$33 -> 0.55 | I43: 26 | J43: REPARACION MAQUINARIA
...
