Workbook

Sheet 2229
I2: MUEBLES SANTA FE SPA
I3: VENTAS POR MENOR DE MUEBLES
I4: RUT: 77.054.606-0
I5: SEPTIMA AVENIDA 1631, SAN MIGUEL
I6: FONO +569 2032 3382 | R6: 10077 SF PORTLAND MAPLE
I7: E-MAIL: ventas@topmobili.cl
B8: P R E S U P U E S T O | D8: N° 11328
B10: NOMBRE: | C10: CONSTANZA SAINT | I10: FECHA: | J10: 45740
B11: RUT: | I11: PLAZO ENTREGA: | J11: 8 DIAS HABILES | U11: MT2 PUERTAS
B12: GIRO: | I12: SERVICIO EXPRESS | J12: NO
B13: CONTACTO:
B14: CORREO: | I14: CORTADA A LA MEDIDA | J14: NO | U14: ML CUBIERTAS
B15: FONO: | C15: +569 34390482 | I15: DESPACHO: | J15: NO
B16: DIRECCION: | I16: FORMA DE PAGO: | J16: ABONO 50% SALDO C/ENTREGA
B17: CIUDAD: | C17: SANTIAGO | I17: DURACION COTIZACION: 5 DIAS FRANCO DONOSO
B19: DETALLE | P19: 0.02 | Q19: 0.02 | S19: TOTAL | T19: VALOR X MT2 | U19: ENCHAPE | V19: MT/L
B20: UNIDAD | C20: TIPO | D20: ALTO | E20: ANCHO | F20: CON PERFORACION | G20: MEDIDA | H20: ENCHAPE | I20: COLOR | J20: VALOR | K20: TOTAL | O20: =B20 -> UNIDAD | P20: ALTO | Q20: =E20 -> ANCHO | R20: MT | S20: MT2 | T20: =R47 -> 66733.501 | U20: 12000 | W20: m/l
B21: 2 | C21: E/R 1 CARA | D21: 0.765 | E21: 0.396 | F21: SI | G21: 12 CMS AL EJE | H21: 4 LADOS | I21: AZUL PACIFICO 2170 MT | J21: 33792 | K21: =J21*B21 -> 67584 | O21: =B21 -> 2 | P21: =D21+P$19 -> 0.785 | Q21: =E21+$Q$19 -> 0.416 | R21: =P21*Q21 -> 0.32656 | S21: =R21*O21 -> 0.65312 | T21: =T$20*R21 -> 21792.492 | U21: =T21+U$20 -> 33792.492 | V21: =P21*2*O21 -> 3.14 | W21: =Q21*2*O21 -> 1.664
B22: 1 | C22: E/R 1 CARA | D22: 0.765 | E22: 0.315 | F22: SI | G22: 12 CMS AL EJE | H22: 4 LADOS | I22: AZUL PACIFICO 2170 MT | J22: 29549 | K22: =J22*B22 -> 29549 | O22: =B22 -> 1 | P22: =D22+P$19 -> 0.785 | Q22: =E22+$Q$19 -> 0.335 | R22: =P22*Q22 -> 0.262975 | S22: =R22*O22 -> 0.262975 | T22: =T$20*R22 -> 17549.243 | U22: =T22+U$20 -> 29549.243 | V22: =P22*2*O22 -> 1.57 | W22: =Q22*2*O22 -> 0.67
B23: 1 | C23: E/R 1 CARA | D23: 0.765 | E23: 0.275 | F23: SI | G23: 12 CMS AL EJE | H23: 4 LADOS | I23: AZUL PACIFICO 2170 MT | J23: 27454 | K23: =J23*B23 -> 27454 | O23: =B23 -> 1 | P23: =D23+P$19 -> 0.785 | Q23: =E23+$Q$19 -> 0.295 | R23: =P23*Q23 -> 0.231575 | S23: =R23*O23 -> 0.231575 | T23: =T$20*R23 -> 15453.811 | U23: =T23+U$20 -> 27453.811 | V23: =P23*2*O23 -> 1.57 | W23: =Q23*2*O23 -> 0.59
B24: 2 | C24: E/R 1 CARA | D24: 0.66 | E24: 0.301 | F24: SI | G24: 12 CMS AL EJE | H24: 4 LADOS | I24: AZUL PACIFICO 2170 MT | J24: 26567 | K24: =J24*B24 -> 53134 | O24: =B24 -> 2 | P24: =D24+P$19 -> 0.68 | Q24: =E24+$Q$19 -> 0.321 | R24: =P24*Q24 -> 0.21828 | S24: =R24*O24 -> 0.43656 | T24: =T$20*R24 -> 14566.589 | U24: =T24+U$20 -> 26566.589 | V24: =P24*2*O24 -> 2.72 | W24: =Q24*2*O24 -> 1.284
B25: 2 | C25: E/R 1 CARA | D25: 0.425 | E25: 0.301 | F25: SI | G25: 12 CMS AL EJE | H25: 4 LADOS | I25: AZUL PACIFICO 2170 MT | J25: 21533 | K25: =J25*B25 -> 43066 | O25: =B25 -> 2 | P25: =D25+P$19 -> 0.445 | Q25: =E25+$Q$19 -> 0.321 | R25: =P25*Q25 -> 0.142845 | S25: =R25*O25 -> 0.28569 | T25: =T$20*R25 -> 9532.547 | U25: =T25+U$20 -> 21532.547 | V25: =P25*2*O25 -> 1.78 | W25: =Q25*2*O25 -> 1.284
B26: 2 | C26: E/R 1 CARA | D26: 0.177 | E26: 0.506 | F26: NO | H26: 4 LADOS | I26: AZUL PACIFICO 2170 MT | J26: 18915 | K26: =J26*B26 -> 37830 | O26: =B26 -> 2 | P26: =D26+P$19 -> 0.197 | Q26: =E26+$Q$19 -> 0.526 | R26: =P26*Q26 -> 0.103622 | S26: =R26*O26 -> 0.207244 | T26: =T$20*R26 -> 6915.0589 | U26: =T26+U$20 -> 18915.059 | V26: =P26*2*O26 -> 0.788 | W26: =Q26*2*O26 -> 2.104
B27: 1 | C27: E/R 1 CARA | D27: 0.397 | E27: 0.506 | F27: NO | H27: 4 LADOS | I27: AZUL PACIFICO 2170 MT | J27: 26637 | K27: =J27*B27 -> 26637 | O27: =B27 -> 1 | P27: =D27+P$19 -> 0.417 | Q27: =E27+$Q$19 -> 0.526 | R27: =P27*Q27 -> 0.219342 | S27: =R27*O27 -> 0.219342 | T27: =T$20*R27 -> 14637.46 | U27: =T27+U$20 -> 26637.46 | V27: =P27*2*O27 -> 0.834 | W27: =Q27*2*O27 -> 1.052
B28: 2 | C28: E/R 1 CARA | D28: 0.177 | E28: 0.898 | F28: NO | H28: 4 LADOS | I28: AZUL PACIFICO 2170 MT | J28: 24068 | K28: =J28*B28 -> 48136 | O28: =B28 -> 2 | P28: =D28+P$19 -> 0.197 | Q28: =E28+$Q$19 -> 0.918 | R28: =P28*Q28 -> 0.180846 | S28: =R28*O28 -> 0.361692 | T28: =T$20*R28 -> 12068.487 | U28: =T28+U$20 -> 24068.487 | V28: =P28*2*O28 -> 0.788 | W28: =Q28*2*O28 -> 3.672
B29: 1 | C29: E/R 1 CARA | D29: 0.397 | E29: 0.898 | F29: NO | H29: 4 LADOS | I29: AZUL PACIFICO 2170 MT | J29: 37546 | K29: =J29*B29 -> 37546 | O29: =B29 -> 1 | P29: =D29+P$19 -> 0.417 | Q29: =E29+$Q$19 -> 0.918 | R29: =P29*Q29 -> 0.382806 | S29: =R29*O29 -> 0.382806 | T29: =T$20*R29 -> 25545.985 | U29: =T29+U$20 -> 37545.985 | V29: =P29*2*O29 -> 0.834 | W29: =Q29*2*O29 -> 1.836
B30: 1 | C30: E/R 1 CARA | D30: 0.65 | E30: 0.587 | F30: NO | H30: 4 LADOS | I30: AZUL PACIFICO 2170 MT | J30: 39140 | K30: =J30*B30 -> 39140 | O30: =B30 -> 1 | P30: =D30+P$19 -> 0.67 | Q30: =E30+$Q$19 -> 0.607 | R30: =P30*Q30 -> 0.40669 | S30: =R30*O30 -> 0.40669 | T30: =T$20*R30 -> 27139.848 | U30: =T30+U$20 -> 39139.848 | V30: =P30*2*O30 -> 1.34 | W30: =Q30*2*O30 -> 1.214
J33: NETO | K33: =SUM(K21:K32) -> 410076 | N33: 2600000 | W33: =SUM(W21:W32) -> 15.37
J34: IVA | K34: =K33*19% -> 77914.44 | P34: =SUM(P21:P22) -> 1.57 | S34: =SUM(S21:S32) -> 3.447694 | V34: =SUM(V21:V33) -> 15.364
J35: TOTAL | K35: =K33+K34 -> 487990.44 | S35: =S34 -> 3.447694
S36: =S35*20% -> 0.6895388 | T36: 20% PERDIDA | V36: =V34+W33 -> 30.734
S37: =S35+S36 -> 4.1372328 | V37: =V36*20% -> 6.1468
V38: =V36+V37 -> 36.8808 | X38: ADHESIVO | Y38: 58.000.- | Z38: 44971
P39: =S37 -> 4.1372328 | Q39: 3500 | R39: =P39*Q39 -> 14480.315 | S39: ADHESIVO | X39: LATA 16 LTS | Y39: 3625 | Z39: LITRO
P40: 1.1 | Q40: 45000 | R40: =P40*Q40 -> 49500 | S40: MDF 18MM | Y40: 906.25 | Z40: MT2 (4)
B41: CUENTA CORRIENTE BANCO SANTANDER Nº 87316181 A NOMBRE DE MUEBLES SANTA FE SPA | Q41: 36000 | R41: =P41*Q41 -> 0 | S41: LAMINA 153 X 366 | Y41: =Y40*20% -> 181.25 | Z41: PERDIDA 20%
B42: RUT : 77.054.606-0 VENTAS@TOPMOBILI.CL | P42: 1 | Q42: 40600 | R42: =P42*Q42 -> 40600 | S42: LAMINA 122X244 | Y42: =Y40+Y41 -> 1087.5 | Z42: MINIMO A COTIZAR
B43: VISITANOS Y DESCUBRE NUESTROS PRODUCTOS EN | I43: WWW.TOPMOBILICHILE.CL | Q43: 900 | R43: =P43*Q43 -> 0 | S43: RESPALDO | U43: 1.52
Q44: 1500 | R44: =P44*Q44 -> 0 | S44: MEDIA CAÑA | U44: 2.44
R45: =SUM(R39:R44) -> 104580.31 | S45: COSTO | U45: =U43*U44 -> 3.7088
...

Sheet COSTOS
B2: CENTRO DE COSTOS POSTFORMADOS
B5: FECHA: | C5: ='2229'!J10 -> 45740
B6: CLIENTE: | C6: ='2229'!C10 -> CONSTANZA SAINT | N6: Ventas Equilibrio = | P6: Costos Fijos Totales
B7: DIRECCION: | C7: ='2229'!#REF! -> #REF! | H7: COSTOS INDIRECTOS DE FABRICA VARIABLES | O7: 1 - | P7: Costos Variables Totales
B8: PRESUPUESTO: | C8: ='2229'!D8 -> N° 11328 | H8: Q/HRS | I8: $ | J8: DETALLE | K8: TOTAL | L8: TOTAL | P8: Total Venta | X8: =SUM(Q11:Q16) -> 6
H9: CANTIDAD | I9: PRECIO | J9: MATERIA PRIMA INDIRECTA | L9: =SUM(K10:K23) -> 2550 | S9: DETALLE | X9: =(E15-D11)/X8 -> -42547.038
D10: NETO | E10: IVA | F10: TOTAL | H10: 3 | I10: 350 | J10: RESPALDO | K10: =I10*H10 -> 1050 | Q10: UNIDAD | R10: TIPO | S10: LARGO | T10: ANCHO | U10: COLOR | V10: VALOR | W10: TOTAL
C11: MONTO A COBRAR | D11: ='2229'!K33 -> 410076 | E11: =D11*0.19 -> 77914.44 | F11: =E11+D11 -> 487990.44 | H11: 3 | I11: 500 | J11: MEDIA CAÑA | K11: =I11*H11 -> 1500 | Q11: 1 | R11: CUB C/R R8 | S11: 2.8 | T11: 0.62 | U11: MADERA X DEFINIR | V11: 105990 | W11: =V11*Q11 -> 105990 | X11: =V11+$X$9 -> 63442.962 | Y11: 108990
C12: COSTO TOTAL | D12: =SUM(M43:M45) -> 93814.406 | H12: 0 | I12: 7500 | J12: DUROLAC | K12: =I12*H12 -> 0 | Q12: 1 | R12: CUB C/R R8 | S12: 2.3 | T12: 0.62 | U12: MADERA X DEFINIR | V12: 87990 | W12: =V12*Q12 -> 87990 | X12: =V12+$X$9 -> 45442.962 | Y12: 89990
C13: % UTILIDAD | D13: =D11-D12 -> 316261.59 | E13: =(D11/D12)-1 -> 3.3711411 | H13: 0 | I13: 50 | J13: TAPACANTO PVC | K13: =I13*H13 -> 0 | Q13: 1 | R13: CUB C/R R8 | S13: 2.03 | T13: 0.62 | U13: MADERA X DEFINIR | V13: 78990 | W13: =V13*Q13 -> 78990 | X13: =V13+$X$9 -> 36442.962 | Y13: 81990
D14: % utilidad | E14: NETO | F14: UTILIDAD | H14: 0 | I14: 50 | J14: SOBERBIOS | K14: =I14*H14 -> 0 | Q14: 1 | R14: CUB C/R R8 | S14: 1.08 | T14: 0.62 | U14: MADERA X DEFINIR | V14: 39990 | W14: =V14*Q14 -> 39990 | X14: =V14+$X$9 -> -2557.0385 | Y14: 39990
C15: PROYECCION | D15: 0.65 | E15: =(100%+D15)*D12 -> 154793.77 | F15: =E15-D12 -> 60979.364 | H15: 0 | I15: 10 | J15: SOPORTE REPISA | K15: =I15*H15 -> 0 | Q15: 1 | R15: CUB C/R R8 | S15: 1.08 | T15: 0.62 | U15: MADERA X DEFINIR | V15: 39990 | W15: =V15*Q15 -> 39990 | X15: =V15+$X$9 -> -2557.0385 | Y15: 39990
H16: 1 | J16: PUNTAS | K16: =I16*H16 -> 0 | Q16: 1 | R16: CUB C/R R8 | S16: 2.06 | T16: 0.62 | U16: MADERA X DEFINIR | V16: 79990 | W16: =V16*Q16 -> 79990 | X16: =V16+$X$9 -> 37442.962 | Y16: 83990
B17: M. PRIMA | C17: MATERIAL | D17: NETO | E17: IVA | F17: TOTAL | H17: 1 | J17: TORNILLOS | K17: =I17*H17 -> 0 | Q17: 6 | R17: CORTES 45° | V17: 5000 | W17: =V17*Q17 -> 30000
C18: LAMINA | D18: ='2229'!R41 -> 0 | E18: =D18*0.19 -> 0 | F18: =SUM(D18:E18) -> 0 | H18: 1 | J18: COLAFRIA | K18: =I18*H18 -> 0 | Q18: 1 | R18: PERFORACION LAVAPLATOS | V18: 10000 | W18: =V18*Q18 -> 10000
C19: MDF 18MM | D19: ='2229'!R40 -> 49500 | E19: =D19*0.19 -> 9405 | F19: =SUM(D19:E19) -> 58905 | H19: 1 | J19: LIJAS | K19: =I19*H19 -> 0 | V19: NETO | W19: =SUM(W11:W18) -> 472940 | Y19: =SUM(Y11:Y16)+SUM(W17:W18) -> 484940
C20: ADHESIVO | D20: ='2229'!R39 -> 14480.315 | E20: =D20*0.19 -> 2751.2598 | F20: =SUM(D20:E20) -> 17231.575 | H20: 1 | J20: CARTON | K20: =I20*H20 -> 0 | V20: I.V.A. | W20: =W19*19% -> 89858.6 | Y20: =Y19*0.19 -> 92138.6
A21: =450000*1.2 -> 540000 | C21: TOTAL | D21: =SUM(D18:D20) -> 63980.315 | E21: =SUM(E18:E20) -> 12156.26 | F21: =SUM(F18:F20) -> 76136.575 | H21: 1 | J21: GUAIPE | K21: =I21*H21 -> 0 | M21: =B32/9 -> 2318.8406 | Q21: PLAZO DE ENTREGA : 8 DIAS HABILES | V21: TOTAL | W21: =W19+W20 -> 562798.6 | Y21: =SUM(Y19:Y20) -> 577078.6
A22: =450000*1.2 -> 540000 | B22: M. DE OBRA | C22: PROCESO | D22: COSTO x Hr. | E22: Q Hrs. | F22: TOTAL | H22: 1 | J22: DILUYENTE | K22: =I22*H22 -> 0 | Q22: FORMA DE PAGO: 50% CONTADO, SALDO C/E
A23: =800000*1.2 -> 960000 | B23: =A21/23 -> 23478.261 | C23: CORTE | D23: =B23/9 -> 2608.6957 | E23: 0.5 | F23: =D23*E23 -> 1304.3478 | H23: 1 | J23: CINTA EMBALAJE | K23: =I23*H23 -> 0 | Q23: VALIDEZ COTIZACIÓN: 5 DIAS
A24: 450000 | B24: =A22/23 -> 23478.261 | C24: CORTE LAMINA | D24: =B24/9 -> 2608.6957 | E24: 0.5 | F24: =D24*E24 -> 1304.3478 | H24: Q/HRS | I24: PRECIO | J24: MANO DE OBRA INDIRECTA | K24: VALOR | L24: =SUM(K25:K35) -> 0
A25: 450000 | B25: =A23/23 -> 41739.13 | C25: REBAJE LAMINA | D25: =B25/9 -> 4637.6812 | F25: =D25*E25 -> 0 | H25: 0 | I25: =((480000/23)/9) -> 2318.8406 | J25: FLETERO (HRS) | K25: =H25*I25 -> 0
B26: =A24/23 -> 19565.217 | C26: TUPIZADO | D26: =B26/9 -> 2173.913 | E26: 0.5 | F26: =D26*E26 -> 1086.9565 | H26: 0 | J26: BENCINA | K26: =H26*I26 -> 0
A27: 350000 | B27: =A25/23 -> 19565.217 | C27: ARMADO | D27: =B27/9 -> 2173.913 | E27: 0.5 | F27: =D27*E27 -> 1086.9565 | H27: 0 | J27: TAG | K27: =H27*I27 -> 0
A28: 500000 | B28: =A27/23 -> 15217.391 | C28: PEGADO | D28: =B28/9 -> 1690.8213 | E28: 0.7 | F28: =D28*E28 -> 1183.5749 | H28: 0 | J28: RECTIFICACION | K28: =H28*I28 -> 0
B29: =A28/23 -> 21739.13 | C29: POSTFORMADO | D29: =B29/9 -> 2415.4589 | E29: 0.7 | F29: =D29*E29 -> 1690.8213 | H29: 0 | I29: =((550000*1.2)/23)/9 -> 3188.4058 | J29: HR. TRAB. JUAN | K29: =H29*I29 -> 0
A30: 450000 | C30: MEDIA CAÑA | D30: 2415 | F30: =D30*E30 -> 0 | H30: 0 | I30: =((450000*1.2)/23)/9 -> 2608.6957 | J30: HR. TRAB. JULIO | K30: =H30*I30 -> 0
A31: 350000 | B31: =A30/23 -> 19565.217 | C31: CORTE-ENCHAPE | D31: =B31/9 -> 2173.913 | E31: 0 | F31: =D31*E31 -> 0 | H31: 0 | I31: =((450000*1.2)/23)/9 -> 2608.6957 | J31: HR. TRAB. EUGE | K31: =H31*I31 -> 0
A32: =A21+A24+A27+A28+A30 -> 2290000 | B32: =480000/23 -> 20869.565 | C32: CONTROL CALIDAD | D32: =B32/9 -> 2318.8406 | E32: 0.5 | F32: =D32*E32 -> 1159.4203 | H32: 0 | J32: COLACION | K32: =H32*I32 -> 0
C33: TOTAL | D33: =SUM(D23:D32) -> 25216.932 | E33: =SUM(E23:E32) -> 3.9 | F33: =SUM(F23:F32) -> 8816.4251 | H33: 0 | J33: BONO | K33: =H33*I33 -> 0
B34: CIF | C34: M. PRIMA INDIREC. | D34: =L9 -> 2550 | H34: 1 | J34: PERFORACION | K34: =H34*I34 -> 0
C35: M. OBRA INDIRECTA | D35: =L24 -> 0 | H35: 6 | J35: CORTE 45 | K35: =H35*I35 -> 0
C36: GASTOS DE FABRICA | D36: =L36 -> 18467.666 | H36: CANTIDAD | I36: PRECIO | J36: GASTOS DE FABRICACION | K36: VALOR | L36: =SUM(K37:K39) -> 18467.666
C37: DEPRECIACIONES | H37: =$E$33 -> 3.9 | I37: =32609.69/9 -> 3623.2989 | J37: ARRIENDO x HORA | K37: =I37*H37 -> 14130.866
C38: TOTAL | D38: =SUM(D34:D37) -> 21017.666 | H38: =$E$33 -> 3.9 | I38: 967 | J38: AGUA x HORA | K38: =I38*H38 -> 3771.3
H39: =$E$33 -> 3.9 | I39: 145 | J39: LUZ x HORA | K39: =I39*H39 -> 565.5
B40: PROVISIONAR | C40: IVA | D40: =E11-E21 -> 65758.18
H41: ESTADO DE RESULTADOS
B42: TOTAL HRS TRABAJADAS | D42: =E33 -> 3.9 | H42: INGRESOS | I42: + TOTAL VENTA | M42: =D11 -> 410076
H43: COSTOS | I43: - MATERIA PRIMA DIRECTA | M43: =D21 -> 63980.315
...
