Workbook

Sheet 2229
G2: MUEBLES SANTA FE SPA
G3: VENTAS POR MENOR DE MUEBLES
G4: RUT: 77.054.606-0
G5: SEPTIMA AVENIDA 1631, SAN MIGUEL
G6: FONO +569 2032 3382 | P6: 10077 SF PORTLAND MAPLE
G7: E-MAIL: ventas@topmobili.cl
B8: P R E S U P U E S T O | D8: N° 11805
B10: NOMBRE: | C10: GONZALO PEÑA | G10: FECHA | H10: 46006
B11: RUT: | G11: PLAZO ENTREGA | H11: 15 DIAS HABILES | S11: MT2 PUERTAS
B12: GIRO: | G12: SERVICIO EXPRESS | H12: NO
B13: CONTACTO: | G13: CORTADA A LA MEDIDA | H13: SI
B14: CORREO: | G14: DESPACHO | H14: NO | S14: ML CUBIERTAS
B15: FONO: | C15: +569 8466 2944 | G15: INSTALACIÓN | H15: NO
B16: DIRECCION: | G16: FORMA DE PAGO: | H16: ABONO 50% SALDO C/ENTREGA
B17: CIUDAD: | C17: SANTIAGO | G17: Duración cotización 5 días hábiles | H17: Cotizado por: Fernando Donoso
B19: DETALLE | N19: 0.02 | O19: 0.02 | Q19: TOTAL | R19: VALOR X MT2 | S19: ENCHAPE | T19: MT/L
B20: UNIDAD | C20: TIPO | D20: LARGO | E20: ANCHO | F20: ENCHAPE | G20: COLOR | H20: VALOR | I20: TOTAL | M20: =B20 -> UNIDAD | N20: ALTO | O20: =E20 -> ANCHO | P20: MT | Q20: MT2 | R20: =P87 -> 65912.253 | S20: 1000 | T20: LARGO | U20: ANCHO
B21: 20 | C21: ENCHAPE RECTO 2 CARAS MDF 18MM | D21: 0.664 | E21: 0.309 | F21: 2A + 1L | G21: BLANCO - HUMO 2108 MT | H21: =S21 -> 15832.63 | I21: =H21*B21 -> 316652.6 | M21: =B21 -> 20 | N21: =D21+N$19 -> 0.684 | O21: =E21+$O$19 -> 0.329 | P21: =N21*O21 -> 0.225036 | Q21: =P21*M21 -> 4.50072 | R21: =R$20*P21 -> 14832.63 | S21: =R21+S$20 -> 15832.63 | T21: =O21*2*M21 -> 13.16 | U21: =M21*N21 -> 13.68
B22: 20 | C22: ENCHAPE RECTO 2 CARAS MDF 18MM | D22: 0.664 | E22: 0.289 | F22: 1A | G22: BLANCO - HUMO 2108 MT | H22: =S22 -> 14930.95 | I22: =H22*B22 -> 298619 | M22: =B22 -> 20 | N22: =D22+N$19 -> 0.684 | O22: =E22+$O$19 -> 0.309 | P22: =N22*O22 -> 0.211356 | Q22: =P22*M22 -> 4.22712 | R22: =R$20*P22 -> 13930.95 | S22: =R22+S$20 -> 14930.95 | U22: =O22*M22 -> 6.18
B23: 20 | C23: ENCHAPE RECTO 2 CARAS MDF 18MM | D23: 0.797 | E23: 0.289 | F23: 1A + 1L | G23: BLANCO - HUMO 2108 MT | H23: =S23 -> 17639.746 | I23: =H23*B23 -> 352794.92 | M23: =B23 -> 20 | N23: =D23+N$19 -> 0.817 | O23: =E23+$O$19 -> 0.309 | P23: =N23*O23 -> 0.252453 | Q23: =P23*M23 -> 5.04906 | R23: =R$20*P23 -> 16639.746 | S23: =R23+S$20 -> 17639.746 | T23: =N23*M23 -> 16.34 | U23: =O23*M23 -> 6.18
B24: 20 | C24: ENCHAPE RECTO 2 CARAS MDF 18MM | D24: 0.797 | E24: 0.289 | F24: 1A + 1L | G24: BLANCO - HUMO 2108 MT | H24: =S24 -> 17639.746 | I24: =H24*B24 -> 352794.92 | M24: =B24 -> 20 | N24: =D24+N$19 -> 0.817 | O24: =E24+$O$19 -> 0.309 | P24: =N24*O24 -> 0.252453 | Q24: =P24*M24 -> 5.04906 | R24: =R$20*P24 -> 16639.746 | S24: =R24+S$20 -> 17639.746 | T24: =N24*M24 -> 16.34 | U24: =O24*M24 -> 6.18
B25: 40 | C25: ENCHAPE RECTO 2 CARAS MDF 18MM | D25: 0.7 | E25: 0.346 | F25: 1A + 1L | G25: BLANCO - HUMO 2108 MT | H25: =S25 -> 18369.197 | I25: =H25*B25 -> 734767.88 | M25: =B25 -> 40 | N25: =D25+N$19 -> 0.72 | O25: =E25+$O$19 -> 0.366 | P25: =N25*O25 -> 0.26352 | Q25: =P25*M25 -> 10.5408 | R25: =R$20*P25 -> 17369.197 | S25: =R25+S$20 -> 18369.197 | T25: =N25*M25 -> 28.8 | U25: =O25*M25 -> 14.64
B26: 26 | C26: ENCHAPE RECTO 2 CARAS MDF 18MM | D26: 0.664 | E26: 0.309 | F26: 2A + 2L | G26: BLANCO - HUMO 2108 MT | H26: =S26 -> 15832.63 | I26: =H26*B26 -> 411648.37 | M26: =B26 -> 26 | N26: =D26+N$19 -> 0.684 | O26: =E26+$O$19 -> 0.329 | P26: =N26*O26 -> 0.225036 | Q26: =P26*M26 -> 5.850936 | R26: =R$20*P26 -> 14832.63 | S26: =R26+S$20 -> 15832.63 | T26: =M26*N26*2 -> 35.568 | U26: =O26*M26*2 -> 17.108
B27: 26 | C27: ENCHAPE RECTO 2 CARAS MDF 18MM | D27: 0.664 | E27: 0.289 | F27: 1A | G27: BLANCO - HUMO 2108 MT | H27: =S27 -> 14930.95 | I27: =H27*B27 -> 388204.7 | M27: =B27 -> 26 | N27: =D27+N$19 -> 0.684 | O27: =E27+$O$19 -> 0.309 | P27: =N27*O27 -> 0.211356 | Q27: =P27*M27 -> 5.495256 | R27: =R$20*P27 -> 13930.95 | S27: =R27+S$20 -> 14930.95 | U27: =O27*M27 -> 8.034
B28: 26 | C28: ENCHAPE RECTO 2 CARAS MDF 18MM | D28: 0.797 | E28: 0.289 | F28: 1A + 1L | G28: BLANCO - HUMO 2108 MT | H28: =S28 -> 17639.746 | I28: =H28*B28 -> 458633.4 | M28: =B28 -> 26 | N28: =D28+N$19 -> 0.817 | O28: =E28+$O$19 -> 0.309 | P28: =N28*O28 -> 0.252453 | Q28: =P28*M28 -> 6.563778 | R28: =R$20*P28 -> 16639.746 | S28: =R28+S$20 -> 17639.746 | T28: =M28*N28 -> 21.242 | U28: =O28*M28 -> 8.034
B29: 26 | C29: ENCHAPE RECTO 2 CARAS MDF 18MM | D29: 0.797 | E29: 0.289 | F29: 1A + 1L | G29: BLANCO - HUMO 2108 MT | H29: =S29 -> 17639.746 | I29: =H29*B29 -> 458633.4 | M29: =B29 -> 26 | N29: =D29+N$19 -> 0.817 | O29: =E29+$O$19 -> 0.309 | P29: =N29*O29 -> 0.252453 | Q29: =P29*M29 -> 6.563778 | R29: =R$20*P29 -> 16639.746 | S29: =R29+S$20 -> 17639.746 | T29: =M29*N29 -> 21.242 | U29: =O29*M29 -> 8.034
B30: 2 | C30: ENCHAPE RECTO 2 CARAS MDF 18MM | D30: 0.145 | E30: 0.534 | F30: 2A + 2L | G30: BLANCO - HUMO 2108 MT | H30: =S30 -> 7025.039 | I30: =H30*B30 -> 14050.078 | M30: =B30 -> 2 | N30: =D30+N$19 -> 0.165 | O30: =E30+$O$19 -> 0.554 | P30: =N30*O30 -> 0.09141 | Q30: =P30*M30 -> 0.18282 | R30: =R$20*P30 -> 6025.039 | S30: =R30+S$20 -> 7025.039 | T30: =N30*M30*2 -> 0.66 | U30: =O30*M30*2 -> 2.216
B31: 1 | C31: ENCHAPE RECTO 2 CARAS MDF 18MM | D31: 0.228 | E31: 0.534 | F31: 2A + 2L | G31: BLANCO - HUMO 2108 MT | H31: =S31 -> 10055.816 | I31: =H31*B31 -> 10055.816 | M31: =B31 -> 1 | N31: =D31+N$19 -> 0.248 | O31: =E31+$O$19 -> 0.554 | P31: =N31*O31 -> 0.137392 | Q31: =P31*M31 -> 0.137392 | R31: =R$20*P31 -> 9055.8163 | S31: =R31+S$20 -> 10055.816 | T31: =N31*M31*2 -> 0.496 | U31: =O31*M31*2 -> 1.108
B32: 2 | C32: ENCHAPE RECTO 2 CARAS MDF 18MM | D32: 0.524 | E32: 0.391 | F32: 2A + 2L | G32: BLANCO - HUMO 2108 MT | H32: =S32 -> 15736.925 | I32: =H32*B32 -> 31473.85 | M32: =B32 -> 2 | N32: =D32+N$19 -> 0.544 | O32: =E32+$O$19 -> 0.411 | P32: =N32*O32 -> 0.223584 | Q32: =P32*M32 -> 0.447168 | R32: =R$20*P32 -> 14736.925 | S32: =R32+S$20 -> 15736.925 | T32: =N32*M32*2 -> 2.176 | U32: =O32*M32*2 -> 1.644
B33: 18 | C33: ENCHAPE RECTO 2 CARAS MDF 18MM | D33: 0.53 | E33: 0.55 | F33: 1A + 1L | G33: BLANCO - HUMO 2108 MT | H33: =S33 -> 21663.491 | I33: =H33*B33 -> 389942.84 | M33: =B33 -> 18 | N33: =D33+N$19 -> 0.55 | O33: =E33+$O$19 -> 0.57 | P33: =N33*O33 -> 0.3135 | Q33: =P33*M33 -> 5.643 | R33: =R$20*P33 -> 20663.491 | S33: =R33+S$20 -> 21663.491 | T33: =M33*N33 -> 9.9 | U33: =O33*M33 -> 10.26
B34: 9 | C34: ENCHAPE RECTO 2 CARAS MDF 18MM | D34: 0.53 | E34: 0.523 | F34: 1A | G34: BLANCO - HUMO 2108 MT | H34: =S34 -> 20684.694 | I34: =H34*B34 -> 186162.25 | M34: =B34 -> 9 | N34: =D34+N$19 -> 0.55 | O34: =E34+$O$19 -> 0.543 | P34: =N34*O34 -> 0.29865 | Q34: =P34*M34 -> 2.68785 | R34: =R$20*P34 -> 19684.694 | S34: =R34+S$20 -> 20684.694 | U34: =O34*M34 -> 4.887
B35: 18 | C35: ENCHAPE RECTO 2 CARAS MDF 18MM | D35: 0.143 | E35: 0.376 | F35: 2A + 2L | G35: BLANCO - HUMO 2108 MT | H35: =S35 -> 5254.5041 | I35: =H35*B35 -> 94581.074 | M35: =B35 -> 18 | N35: =D35+N$19 -> 0.163 | O35: =E35+$O$19 -> 0.396 | P35: =N35*O35 -> 0.064548 | Q35: =P35*M35 -> 1.161864 | R35: =R$20*P35 -> 4254.5041 | S35: =R35+S$20 -> 5254.5041 | T35: =M35*N35*2 -> 5.868 | U35: =O35*M35*2 -> 14.256
B36: 9 | C36: ENCHAPE RECTO 2 CARAS MDF 18MM | D36: 0.228 | E36: 0.476 | F36: 2A + 2L | G36: BLANCO - HUMO 2108 MT | H36: =S36 -> 9107.7344 | I36: =H36*B36 -> 81969.61 | M36: =B36 -> 9 | N36: =D36+N$19 -> 0.248 | O36: =E36+$O$19 -> 0.496 | P36: =N36*O36 -> 0.123008 | Q36: =P36*M36 -> 1.107072 | R36: =R$20*P36 -> 8107.7344 | S36: =R36+S$20 -> 9107.7344 | U36: =O36*M36 -> 4.464
B37: 9 | C37: ENCHAPE RECTO 2 CARAS MDF 18MM | D37: 0.514 | E37: 0.541 | F37: 1A | G37: BLANCO - HUMO 2108 MT | H37: =S37 -> 20745.597 | I37: =H37*B37 -> 186710.38 | M37: =B37 -> 9 | N37: =D37+N$19 -> 0.534 | O37: =E37+$O$19 -> 0.561 | P37: =N37*O37 -> 0.299574 | Q37: =P37*M37 -> 2.696166 | R37: =R$20*P37 -> 19745.597 | S37: =R37+S$20 -> 20745.597 | U37: =O37*M37 -> 5.049
B38: 18 | C38: ENCHAPE RECTO 2 CARAS MDF 18MM | D38: 0.53 | E38: 0.541 | F38: 1A | G38: BLANCO - HUMO 2108 MT | H38: =S38 -> 21337.226 | I38: =H38*B38 -> 384070.06 | M38: =B38 -> 18 | N38: =D38+N$19 -> 0.55 | O38: =E38+$O$19 -> 0.561 | P38: =N38*O38 -> 0.30855 | Q38: =P38*M38 -> 5.5539 | R38: =R$20*P38 -> 20337.226 | S38: =R38+S$20 -> 21337.226 | U38: =O38*M38 -> 10.098
B39: 9 | C39: ENCHAPE RECTO 2 CARAS MDF 18MM | D39: 0.514 | E39: 0.531 | F39: 1A | G39: BLANCO - HUMO 2108 MT | H39: =S39 -> 20393.626 | I39: =H39*B39 -> 183542.63 | M39: =B39 -> 9 | N39: =D39+N$19 -> 0.534 | O39: =E39+$O$19 -> 0.551 | P39: =N39*O39 -> 0.294234 | Q39: =P39*M39 -> 2.648106 | R39: =R$20*P39 -> 19393.626 | S39: =R39+S$20 -> 20393.626
B40: 18 | C40: ENCHAPE RECTO 2 CARAS MDF 18MM | D40: 0.524 | E40: 0.362 | F40: 2A + 2L | G40: BLANCO - HUMO 2108 MT | H40: =S40 -> 14697.093 | I40: =H40*B40 -> 264547.68 | M40: =B40 -> 18 | N40: =D40+N$19 -> 0.544 | O40: =E40+$O$19 -> 0.382 | P40: =N40*O40 -> 0.207808 | Q40: =P40*M40 -> 3.740544 | R40: =R$20*P40 -> 13697.093 | S40: =R40+S$20 -> 14697.093 | T40: =N40*2*M40 -> 19.584 | U40: =O40*2*M40 -> 13.752
B41: 1 | C41: ENCHAPE RECTO 2 CARAS MDF 18MM | D41: 0.82 | E41: 0.57 | F41: 1A | G41: BLANCO - HUMO 2108 MT | H41: =S41 -> 33666.113 | I41: =H41*B41 -> 33666.113 | M41: =B41 -> 1 | N41: =D41+N$19 -> 0.84 | O41: =E41+$O$19 -> 0.59 | P41: =N41*O41 -> 0.4956 | Q41: =P41*M41 -> 0.4956 | R41: =R$20*P41 -> 32666.113 | S41: =R41+S$20 -> 33666.113 | U41: =O41*M41 -> 0.59
B42: 1 | C42: ENCHAPE RECTO 2 CARAS MDF 18MM | D42: 0.192 | E42: 0.567 | F42: 1A | G42: BLANCO - HUMO 2108 MT | H42: =S42 -> 9202.3844 | I42: =H42*B42 -> 9202.3844 | M42: =B42 -> 1 | N42: =D42+N$19 -> 0.212 | O42: =E42+$O$19 -> 0.587 | P42: =N42*O42 -> 0.124444 | Q42: =P42*M42 -> 0.124444 | R42: =R$20*P42 -> 8202.3844 | S42: =R42+S$20 -> 9202.3844 | U42: =O42*M42 -> 0.587
B43: 2 | C43: ENCHAPE RECTO 2 CARAS MDF 18MM | D43: 0.712 | E43: 0.567 | F43: 1A | G43: BLANCO - HUMO 2108 MT | H43: =S43 -> 29321.44 | I43: =H43*B43 -> 58642.881 | M43: =B43 -> 2 | N43: =D43+N$19 -> 0.732 | O43: =E43+$O$19 -> 0.587 | P43: =N43*O43 -> 0.429684 | Q43: =P43*M43 -> 0.859368 | R43: =R$20*P43 -> 28321.44 | S43: =R43+S$20 -> 29321.44 | U43: =O43*M43 -> 1.174
...

Sheet COSTOS
B2: CENTRO DE COSTOS POSTFORMADOS
B5: FECHA: | C5: ='2229'!H10 -> 46006
B6: CLIENTE: | C6: ='2229'!C10 -> GONZALO PEÑA | N6: Ventas Equilibrio = | P6: Costos Fijos Totales
B7: DIRECCION: | C7: ='2229'!#REF! -> #REF! | H7: COSTOS INDIRECTOS DE FABRICA VARIABLES | O7: 1 - | P7: Costos Variables Totales
B8: PRESUPUESTO: | C8: ='2229'!D8 -> N° 11805 | H8: Q/HRS | I8: $ | J8: DETALLE | K8: TOTAL | L8: TOTAL | P8: Total Venta | X8: =SUM(Q11:Q16) -> 6
H9: CANTIDAD | I9: PRECIO | J9: MATERIA PRIMA INDIRECTA | L9: =SUM(K10:K23) -> 2550 | S9: DETALLE | X9: =(E15-D11)/X8 -> -559768.66
D10: NETO | E10: IVA | F10: TOTAL | H10: 3 | I10: 350 | J10: RESPALDO | K10: =I10*H10 -> 1050 | Q10: UNIDAD | R10: TIPO | S10: LARGO | T10: ANCHO | U10: COLOR | V10: VALOR | W10: TOTAL
C11: MONTO A COBRAR | D11: ='2229'!I73 -> 6714110.9 | E11: =D11*0.19 -> 1275681.1 | F11: =E11+D11 -> 7989791.9 | H11: 3 | I11: 500 | J11: MEDIA CAÑA | K11: =I11*H11 -> 1500 | Q11: 1 | R11: CUB C/R R8 | S11: 2.8 | T11: 0.62 | U11: MADERA X DEFINIR | V11: 105990 | W11: =V11*Q11 -> 105990 | X11: =V11+$X$9 -> -453778.66 | Y11: 108990
C12: COSTO TOTAL | D12: =SUM(M43:M45) -> 2033635.7 | H12: 0 | I12: 7500 | J12: DUROLAC | K12: =I12*H12 -> 0 | Q12: 1 | R12: CUB C/R R8 | S12: 2.3 | T12: 0.62 | U12: MADERA X DEFINIR | V12: 87990 | W12: =V12*Q12 -> 87990 | X12: =V12+$X$9 -> -471778.66 | Y12: 89990
C13: % UTILIDAD | D13: =D11-D12 -> 4680475.2 | E13: =(D11/D12)-1 -> 2.3015308 | H13: 0 | I13: 50 | J13: TAPACANTO PVC | K13: =I13*H13 -> 0 | Q13: 1 | R13: CUB C/R R8 | S13: 2.03 | T13: 0.62 | U13: MADERA X DEFINIR | V13: 78990 | W13: =V13*Q13 -> 78990 | X13: =V13+$X$9 -> -480778.66 | Y13: 81990
D14: % utilidad | E14: NETO | F14: UTILIDAD | H14: 0 | I14: 50 | J14: SOBERBIOS | K14: =I14*H14 -> 0 | Q14: 1 | R14: CUB C/R R8 | S14: 1.08 | T14: 0.62 | U14: MADERA X DEFINIR | V14: 39990 | W14: =V14*Q14 -> 39990 | X14: =V14+$X$9 -> -519778.66 | Y14: 39990
C15: PROYECCION | D15: 0.65 | E15: =(100%+D15)*D12 -> 3355498.9 | F15: =E15-D12 -> 1321863.2 | H15: 0 | I15: 10 | J15: SOPORTE REPISA | K15: =I15*H15 -> 0 | Q15: 1 | R15: CUB C/R R8 | S15: 1.08 | T15: 0.62 | U15: MADERA X DEFINIR | V15: 39990 | W15: =V15*Q15 -> 39990 | X15: =V15+$X$9 -> -519778.66 | Y15: 39990
H16: 1 | J16: PUNTAS | K16: =I16*H16 -> 0 | Q16: 1 | R16: CUB C/R R8 | S16: 2.06 | T16: 0.62 | U16: MADERA X DEFINIR | V16: 79990 | W16: =V16*Q16 -> 79990 | X16: =V16+$X$9 -> -479778.66 | Y16: 83990
B17: M. PRIMA | C17: MATERIAL | D17: NETO | E17: IVA | F17: TOTAL | H17: 1 | J17: TORNILLOS | K17: =I17*H17 -> 0 | Q17: 6 | R17: CORTES 45° | V17: 5000 | W17: =V17*Q17 -> 30000
C18: LAMINA | D18: ='2229'!P81 -> 471000 | E18: =D18*0.19 -> 89490 | F18: =SUM(D18:E18) -> 560490 | H18: 1 | J18: COLAFRIA | K18: =I18*H18 -> 0 | Q18: 1 | R18: PERFORACION LAVAPLATOS | V18: 10000 | W18: =V18*Q18 -> 10000
C19: MDF 18MM | D19: ='2229'!P80 -> 728500 | E19: =D19*0.19 -> 138415 | F19: =SUM(D19:E19) -> 866915 | H19: 1 | J19: LIJAS | K19: =I19*H19 -> 0 | V19: NETO | W19: =SUM(W11:W18) -> 472940 | Y19: =SUM(Y11:Y16)+SUM(W17:W18) -> 484940
C20: ADHESIVO | D20: ='2229'!P79 -> 804301.61 | E20: =D20*0.19 -> 152817.31 | F20: =SUM(D20:E20) -> 957118.92 | H20: 1 | J20: CARTON | K20: =I20*H20 -> 0 | V20: I.V.A. | W20: =W19*19% -> 89858.6 | Y20: =Y19*0.19 -> 92138.6
A21: =450000*1.2 -> 540000 | C21: TOTAL | D21: =SUM(D18:D20) -> 2003801.6 | E21: =SUM(E18:E20) -> 380722.31 | F21: =SUM(F18:F20) -> 2384523.9 | H21: 1 | J21: GUAIPE | K21: =I21*H21 -> 0 | M21: =B32/9 -> 2318.8406 | Q21: PLAZO DE ENTREGA : 8 DIAS HABILES | V21: TOTAL | W21: =W19+W20 -> 562798.6 | Y21: =SUM(Y19:Y20) -> 577078.6
A22: =450000*1.2 -> 540000 | B22: M. DE OBRA | C22: PROCESO | D22: COSTO x Hr. | E22: Q Hrs. | F22: TOTAL | H22: 1 | J22: DILUYENTE | K22: =I22*H22 -> 0 | Q22: FORMA DE PAGO: 50% CONTADO, SALDO C/E
A23: =800000*1.2 -> 960000 | B23: =A21/23 -> 23478.261 | C23: CORTE | D23: =B23/9 -> 2608.6957 | E23: 0.5 | F23: =D23*E23 -> 1304.3478 | H23: 1 | J23: CINTA EMBALAJE | K23: =I23*H23 -> 0 | Q23: VALIDEZ COTIZACIÓN: 5 DIAS
A24: 450000 | B24: =A22/23 -> 23478.261 | C24: CORTE LAMINA | D24: =B24/9 -> 2608.6957 | E24: 0.5 | F24: =D24*E24 -> 1304.3478 | H24: Q/HRS | I24: PRECIO | J24: MANO DE OBRA INDIRECTA | K24: VALOR | L24: =SUM(K25:K35) -> 0
A25: 450000 | B25: =A23/23 -> 41739.13 | C25: REBAJE LAMINA | D25: =B25/9 -> 4637.6812 | F25: =D25*E25 -> 0 | H25: 0 | I25: =((480000/23)/9) -> 2318.8406 | J25: FLETERO (HRS) | K25: =H25*I25 -> 0
B26: =A24/23 -> 19565.217 | C26: TUPIZADO | D26: =B26/9 -> 2173.913 | E26: 0.5 | F26: =D26*E26 -> 1086.9565 | H26: 0 | J26: BENCINA | K26: =H26*I26 -> 0
A27: 350000 | B27: =A25/23 -> 19565.217 | C27: ARMADO | D27: =B27/9 -> 2173.913 | E27: 0.5 | F27: =D27*E27 -> 1086.9565 | H27: 0 | J27: TAG | K27: =H27*I27 -> 0
A28: 500000 | B28: =A27/23 -> 15217.391 | C28: PEGADO | D28: =B28/9 -> 1690.8213 | E28: 0.7 | F28: =D28*E28 -> 1183.5749 | H28: 0 | J28: RECTIFICACION | K28: =H28*I28 -> 0
B29: =A28/23 -> 21739.13 | C29: POSTFORMADO | D29: =B29/9 -> 2415.4589 | E29: 0.7 | F29: =D29*E29 -> 1690.8213 | H29: 0 | I29: =((550000*1.2)/23)/9 -> 3188.4058 | J29: HR. TRAB. JUAN | K29: =H29*I29 -> 0
A30: 450000 | C30: MEDIA CAÑA | D30: 2415 | F30: =D30*E30 -> 0 | H30: 0 | I30: =((450000*1.2)/23)/9 -> 2608.6957 | J30: HR. TRAB. JULIO | K30: =H30*I30 -> 0
A31: 350000 | B31: =A30/23 -> 19565.217 | C31: CORTE-ENCHAPE | D31: =B31/9 -> 2173.913 | E31: 0 | F31: =D31*E31 -> 0 | H31: 0 | I31: =((450000*1.2)/23)/9 -> 2608.6957 | J31: HR. TRAB. EUGE | K31: =H31*I31 -> 0
A32: =A21+A24+A27+A28+A30 -> 2290000 | B32: =480000/23 -> 20869.565 | C32: CONTROL CALIDAD | D32: =B32/9 -> 2318.8406 | E32: 0.5 | F32: =D32*E32 -> 1159.4203 | H32: 0 | J32: COLACION | K32: =H32*I32 -> 0
C33: TOTAL | D33: =SUM(D23:D32) -> 25216.932 | E33: =SUM(E23:E32) -> 3.9 | F33: =SUM(F23:F32) -> 8816.4251 | H33: 0 | J33: BONO | K33: =H33*I33 -> 0
B34: CIF | C34: M. PRIMA INDIREC. | D34: =L9 -> 2550 | H34: 1 | J34: PERFORACION | K34: =H34*I34 -> 0
C35: M. OBRA INDIRECTA | D35: =L24 -> 0 | H35: 6 | J35: CORTE 45 | K35: =H35*I35 -> 0
C36: GASTOS DE FABRICA | D36: =L36 -> 18467.666 | H36: CANTIDAD | I36: PRECIO | J36: GASTOS DE FABRICACION | K36: VALOR | L36: =SUM(K37:K39) -> 18467.666
C37: DEPRECIACIONES | H37: =$E$33 -> 3.9 | I37: =32609.69/9 -> 3623.2989 | J37: ARRIENDO x HORA | K37: =I37*H37 -> 14130.866
C38: TOTAL | D38: =SUM(D34:D37) -> 21017.666 | H38: =$E$33 -> 3.9 | I38: 967 | J38: AGUA x HORA | K38: =I38*H38 -> 3771.3
H39: =$E$33 -> 3.9 | I39: 145 | J39: LUZ x HORA | K39: =I39*H39 -> 565.5
B40: PROVISIONAR | C40: IVA | D40: =E11-E21 -> 894958.76
H41: ESTADO DE RESULTADOS
B42: TOTAL HRS TRABAJADAS | D42: =E33 -> 3.9 | H42: INGRESOS | I42: + TOTAL VENTA | M42: =D11 -> 6714110.9
H43: COSTOS | I43: - MATERIA PRIMA DIRECTA | M43: =D21 -> 2003801.6
...

Sheet NOTA DE VENTA
F2: MUEBLES SANTA FE SPA
F3: VENTAS POR MENOR DE MUEBLES
F4: RUT: 77.054.606-0
F5: SEPTIMA AVENIDA 1631, SAN MIGUEL
F6: CELULAR: 963868755
F7: E-MAIL: fdonoso@topmobili.cl
B8: P R E S U P U E S T O | D8: ='2229'!D8 -> N° 11805 | F8: NOTA DE VENTA :
B10: CLIENTE: | C10: =IF('2229'!C10="","",'2229'!C10) -> GONZALO PEÑA | F10: FECHA : | G10: ='2229'!H10 -> 46006
B11: RUT: | C11: =IF('2229'!C11="","",'2229'!C11) | F11: FECHA LIMITE : | G11: =WORKDAY(G10,5) -> 46013
B12: GIRO: | C12: =IF('2229'!C12="","",'2229'!C12) | F12: DESPACHO: | G12: ='2229'!H14 -> NO
B13: CONTACTO: | C13: =IF('2229'!C13="","",'2229'!C13) | F13: ORDEN DE COMPRA:
B14: CORREO: | C14: =IF('2229'!C14="","",'2229'!C14) | F14: HECHO POR: | G14: FERNANDO DONOSO
B15: FONO: | C15: =IF('2229'!C15="","",'2229'!C15) -> +569 8466 2944 | F15: SERVICIO EXPRESS: | G15: ='2229'!H12 -> NO
B16: DIRECCION: | C16: =IF('2229'!C16="","",'2229'!C16) | F16: FORMA DE PAGO : | G16: ='2229'!H16 -> ABONO 50% SALDO C/ENTREGA
B17: CIUDAD: | C17: =IF('2229'!C17="","",'2229'!C17) -> SANTIAGO | F17: VALIDEZ COTIZACIÓN: 5 DÍAS
B20: D E T A L L E
B21: UNIDAD | C21: TIPO | D21: LARGO | E21: ANCHO | F21: COLOR | G21: VALOR | H21: TOTAL
B22: ='2229'!B21 -> 20 | C22: ='2229'!C21 -> ENCHAPE RECTO 2 CARAS MDF 18MM | D22: ='2229'!D21*1000 -> 664 | E22: ='2229'!E21*1000 -> 309 | F22: ='2229'!G21 -> BLANCO - HUMO 2108 MT | G22: ='2229'!H21 -> 15832.63 | H22: =G22*B22 -> 316652.6
G25: NETO | H25: =SUM(H22:H24) -> 316652.6
G26: I.V.A. | H26: =H25*19% -> 60163.993
G27: TOTAL | H27: =H25+H26 -> 376816.59
B30: CUENTA VISTA DEL BANCO ESTADO N° 35571389078 A NOMBRE DE
B31: "MUEBLES SANTA FE SPA." - RUT : 77.054.606-0, VENTAS@TOPMOBILI.CL
B32: VISITANOS Y DESCUBRE NUESTROS PRODUCTOS EN | E32: WWW.TOPMOBILICHILE.CL

Sheet REGLAS
B2: DETALLE CORTE LAMINA | G2: DETALLE CORTE SUSTRATO | P2: DETALLE CORTE MERA
B3: ALTO | C3: ANCHO | D3: TIPO | G3: ALTO | H3: ANCHO | I3: TIPO | P3: ALTO | Q3: ANCHO | R3: TIPO
B4: 40 | C4: 60 | D4: CEN 1V | E4: A1 | G4: 50 | H4: 100 | I4: CEN 1V | J4: REGLA SIEMPRE LLEVAR MEDIDA MINIMO A 100 | P4: 50 | Q4: -30 | R4: CUB C/R
B5: 40 | C5: 90 | D5: CEN 2V | E5: A2 | G5: 50 | I5: CEN 2V | J5: REGLA SIEMPRE LLEVAR MEDIDA MINIMO A 101 | P5: 50 | Q5: -30 | R5: CUB C/R
B6: 40 | C6: 100 | D6: CORNISA FRENTE ESPAÑOL 1 LADO | E6: A3 | G6: 50 | H6: 100 | I6: CORNISA FRENTE ESPAÑOL 1 LADO | P6: 50 | Q6: -30 | R6: CUB C/R 180°
B7: 40 | C7: 150 | D7: CORNISA FRENTE ESPAÑOL 2 LADO | E7: A4 | G7: 50 | I7: CORNISA FRENTE ESPAÑOL 2 LADO | P7: 50 | Q7: -30 | R7: CUB C/R FRENTE ESPAÑOL
B8: 40 | C8: 100 | D8: CORNISA 180° 1LADO | E8: A5 | G8: 50 | H8: 100 | I8: CORNISA 180° 1LADO | L8: DETALLE CORTE MERA | P8: 50 | Q8: -30 | R8: CUB C/R PUNTA 1 LADO
B9: 40 | C9: 50 | D9: CORNISA PUNTA TIBURON 1 LADO | E9: B | G9: 50 | H9: 100 | I9: CORNISA 1LADO | L9: ALTO | M9: ANCHO | N9: TIPO | P9: 50 | Q9: 0 | R9: CUB S/R FRENTE ESPAÑOL
B10: 40 | C10: 80 | D10: CORNISA PUNTA TIBURON 2 LADOS | E10: C | G10: 50 | I10: CORNISA 2 LADOS | L10: 50 | M10: -30 | N10: CUB C/R | P10: 50 | Q10: 0 | R10: CUB S/R
B11: 40 | C11: 60 | D11: CORNISA R8 1LADO | E11: D | G11: 50 | H11: 100 | I11: CORNISA PUNTA TIBURON 1 LADO | L11: 50 | M11: 0 | N11: CUB S/R y CUB MESA | P11: 50 | Q11: 0 | R11: CUB MESA 180° 2 LADOS
B12: 40 | C12: 100 | D12: CORNISA R8 2 LADOS | E12: E | G12: 50 | I12: CORNISA PUNTA TIBURON 2 LADOS | L12: 50 | M12: -2 | N12: PR | P12: 50 | Q12: 0 | R12: CUB MESA 180° 3 LADOS
B13: 40 | C13: 130 | D13: CUB C/R R6 | E13: F | G13: 50 | H13: -30 | I13: CUB C/R | P13: 50 | Q13: 0 | R13: CUB MESA 180° 4 LADOS
B14: 40 | C14: 150 | D14: CUB C/R 180° | G14: 50 | H14: -30 | I14: CUB C/R 180°
B15: 40 | C15: 150 | D15: CUB C/R FRENTE ESPAÑOL | E15: G | G15: 50 | H15: -30 | I15: CUB C/R FRENTE ESPAÑOL | P15: 50 | Q15: 0 | R15: CUB MESA 4 LADOS
B16: 40 | C16: 130 | D16: CUB C/R R2 | E16: H | G16: 50 | H16: -30 | I16: CUB C/R PUNTA TIBURON 1 LADO | P16: 50 | Q16: 0 | R16: CUB MESA FRENTE ESPAÑOL 2 LADOS
B17: 40 | C17: 150 | D17: CUB MESA 180° 2 LADOS | E17: I | G17: 50 | I17: CUB MESA 180° 2 LADOS | P17: 50 | Q17: 0 | R17: CUB MESA FRENTE ESPAÑOL 3 LADOS
B18: 140 | C18: 150 | D18: CUB MESA 180° 3 LADOS | E18: J | G18: 50 | I18: CUB MESA 180° 3 LADOS | P18: 50 | Q18: 0 | R18: CUB MESA FRENTE ESPAÑOL 4 LADOS
B19: 150 | C19: 150 | D19: CUB MESA 180° 4 LADOS | E19: K | G19: 50 | I19: CUB MESA 180° 4 LADOS | P19: 50 | Q19: 0 | R19: CUB MESA PUNTA TIBURON 2 LADOS
B20: 40 | C20: 100 | D20: CUB MESA 2L | E20: L | G20: 50 | H20: 0 | I20: CUB MESA 2L | J20: ES IGUAL A LO PEDIDO NO SE DEBE SUMAR NI RESTAR | P20: 50 | Q20: 0 | R20: CUB MESA PUNTA TIBURON 3 LADOS
B21: 100 | C21: 100 | D21: CUB MESA 3L | E21: M | G21: 50 | H21: 0 | I21: CUB MESA 3L | P21: 50 | Q21: 0 | R21: CUB MESA PUNTA TIBURON 4 LADOS
B22: 100 | C22: 100 | D22: CUB MESA 4 LADOS | E22: N | I22: CUB MESA 4 LADOS | P22: 50 | Q22: 0 | R22: CUB PUNTA TIBURON 1 LADO
B23: 40 | C23: 150 | D23: CUB MESA FRENTE ESPAÑOL 2 LADOS | E23: O | G23: 50 | I23: CUB MESA FRENTE ESPAÑOL 2 LADOS | R23: CENEFA 1 LADO
B24: 140 | C24: 150 | D24: CUB MESA FRENTE ESPAÑOL 3 LADOS | E24: P | G24: 50 | I24: CUB MESA FRENTE ESPAÑOL 3 LADOS | R24: CENEFA 2 LADOS
B25: 150 | C25: 150 | D25: CUB MESA FRENTE ESPAÑOL 4 LADOS | E25: Q | G25: 50 | I25: CUB MESA FRENTE ESPAÑOL 4 LADOS | R25: CORNISA FRENTE ESPAÑOL 1 LADO
B26: 40 | C26: 77 | D26: CUB MESA PUNTA TIBURON 2 LADOS | E26: R | G26: 50 | I26: CUB MESA PUNTA TIBURON 2 LADOS | R26: CORNISA FRENTE ESPAÑOL 2 LADO
B27: 110 | C27: 77 | D27: CUB MESA PUNTA TIBURON 3 LADOS | E27: S | G27: 50 | I27: CUB MESA PUNTA TIBURON 3 LADOS | R27: CORNISA 180° 1LADO
B28: 120 | C28: 77 | D28: CUB MESA PUNTA TIBURON 4 LADOS | E28: T | G28: 50 | I28: CUB MESA PUNTA TIBURON 4 LADOS | R28: CORNISA 1LADO
B29: 40 | C29: 50 | D29: CUB PUNTA TIBURON 1 LADO | E29: U | G29: 50 | I29: CUB PUNTA TIBURON 1 LADO | R29: CORNISA 2 LADOS
B30: 40 | C30: 60 | D30: CUB S/R | E30: V | G30: 50 | I30: CUB S/R | R30: CORNISA PUNTA TIBURON 1 LADO
B31: 40 | C31: 100 | D31: CUB S/R FRENTE ESPAÑOL | E31: W | G31: 50 | I31: CUB S/R FRENTE ESPAÑOL | R31: CORNISA PUNTA TIBURON 2 LADOS
B32: 40 | C32: 60 | D32: CUB S/R R2 | E32: X | G32: 50 | I32: CUB S/R R2 | R32: PR2
B33: 40 | C33: 90 | D33: PR12 | E33: Y | G33: 50 | H33: -2 | I33: PR12 | R33: PR6
B34: 40 | C34: 90 | D34: PR19 | G34: 50 | H34: -2 | I34: PR19
B35: 40 | C35: 90 | D35: PR2 | E35: Z | G35: 50 | H35: -2 | I35: PR2 | R35: PR8
B36: 40 | C36: 90 | D36: PR6 | G36: 50 | H36: -2 | I36: PR6 | R36: PR12
B37: 40 | C37: 90 | D37: PR8 | G37: 50 | H37: -2 | I37: PR8 | R37: PR19
B48: 40 | C48: 150

Sheet PRODUCCION
K2: NO BORRAR REGLAS!!!!! SI NO LAS SABEN USAR NO BORREN ESTO POR FAVOR!!!!!
K3: SUSTRATO | M3: LAMINADO
C4: NOTA DE VENTA : | D4: =IF('NOTA DE VENTA'!$G$8="","",'NOTA DE VENTA'!$G$8) | K4: ALTO | L4: ANCHO | M4: ALTO | N4: ANCHO
C5: CLIENTE : | D5: ='NOTA DE VENTA'!$C$10 -> GONZALO PEÑA | K5: =LOOKUP(F14,REGLAS!$I$4:$I$37,REGLAS!$G$4:$G$37)+J14 -> 1850 | L5: =LOOKUP(F14,REGLAS!$I$4:$I$37,REGLAS!$H$4:$H$37)+K14 -> 470 | M5: =LOOKUP(F14,REGLAS!$D$4:$D$37,REGLAS!$B$4:$B$37)+J21 -> 1840 | N5: =H10 -> 0
C7: ='NOTA DE VENTA'!$F$10 -> FECHA : | D7: ='NOTA DE VENTA'!$G$10 -> 46006
C8: FECHA ENTREGA: | D8: ='NOTA DE VENTA'!$G$11 -> 46013
A10: SUSTRATO
D12: ALTO | E12: ANCHO
A13: MATERIAL | B13: CANTIDAD | C13: CORTE | D13: 80 | E13: -30 | F13: DESCRIPCIÓN | J13: ALTO | K13: ANCHO
A14: MDF 18MM | B14: =I14 -> 1 | D14: =LOOKUP(F14,REGLAS!$I$4:$I$37,REGLAS!$G$4:$G$37)+J14 -> 1850 | E14: =LOOKUP(F14,REGLAS!$I$4:$I$37,REGLAS!$H$4:$H$37)+K14 -> 470 | F14: =C27 -> CUB C/R R8 | I14: =I21 -> 1 | J14: =D27 -> 1800 | K14: =E27 -> 500
A17: LAMINADO
D19: ALTO | E19: ANCHO
A20: MATERIAL | B20: CANTIDAD | C20: CORTE | D20: 40 | E20: 130 | F20: DESCRIPCIÓN | J20: ALTO | K20: ANCHO
A21: MDF 18MM | B21: =I21 -> 1 | D21: =LOOKUP(F14,REGLAS!$D$4:$D$37,REGLAS!$B$4:$B$37)+J21 -> 1840 | E21: =LOOKUP(F14,REGLAS!$D$4:$D$37,REGLAS!$C$4:$C$37)+K21 -> 630 | F21: =C27 -> CUB C/R R8 | I21: =B27 -> 1 | J21: =D27 -> 1800 | K21: =E27 -> 500
B24: MEDIDAS ORIGINALES
A26: MATERIAL | B26: CANTIDAD | C26: DESCRIPCIÓN | D26: ALTO | E26: ANCHO | F26: COLOR
A27: MDF 18MM | B27: ='[1]4637'!B21 -> 1 | C27: ='[1]4637'!C21 -> CUB C/R R8 | D27: ='[1]4637'!D21 -> 1800 | E27: ='[1]4637'!E21 -> 500 | F27: ='[1]4637'!F21 -> LATE 2167 MT
C39: NOTA DE VENTA : | D39: ='[1]4637'!G8 -> 7332
C40: CLIENTE : | D40: ='[1]4637'!C10 -> FMR MAKING SPA
C42: ='[1]4637'!F11 -> FECHA LIMITE : | D42: ='[1]4637'!G11 -> 45996
A45: PRODUCCIÓN
B47: DETALLE
B48: CANTIDAD | C48: CORTE | D48: ALTO | E48: ANCHO | F48: DESCRIPCION
A49: MDF18MM | B49: ='[1]4637'!B21 -> 1 | C49: ='[1]4637'!C21 -> CUB C/R R8 | D49: ='[1]4637'!D21 -> 1800 | E49: ='[1]4637'!E21 -> 500 | F49: ='[1]4637'!F21 -> LATE 2167 MT

Sheet SEGUIMIENTO
A1: NV | B1: N° COTIZA | C1: FECHA | D1: ENTREGA | E1: NOMBRE | F1: DETALLE | G1: COLOR | H1: NETO | I1: IVA | J1: TOTAL | K1: ABONO | L1: SALDO | M1: ESTADO
A2: ='NOTA DE VENTA'!$G$8 -> 0 | B2: ='NOTA DE VENTA'!$D$8 -> N° 11805 | C2: ='NOTA DE VENTA'!$G$10 -> 46006 | D2: ='NOTA DE VENTA'!$G$11 -> 46013 | E2: ='NOTA DE VENTA'!$C$10 -> GONZALO PEÑA | F2: ='NOTA DE VENTA'!$C$22 -> ENCHAPE RECTO 2 CARAS MDF 18MM | G2: ='NOTA DE VENTA'!$F$22 -> BLANCO - HUMO 2108 MT | H2: ='NOTA DE VENTA'!$H$25 -> 316652.6 | I2: =H2*0.19 -> 60163.993 | J2: =I2+H2 -> 376816.59 | L2: =J2-K2 -> 376816.59
