Workbook

Sheet COMERDOR MUEBLE CON REPISAS
F2: MUEBLES SANTA FE SPA
F3: VENTAS POR MENOR DE MUEBLES
F4: RUT: 77.054.606-0
F5: SEPTIMA AVENIDA 1631, SAN MIGUEL
F6: FONO +569 2032 3382 | O6: 10077 SF PORTLAND MAPLE
F7: E-MAIL: ventas@topmobili.cl
B8: P R E S U P U E S T O | D8: N° 11810
B10: NOMBRE: | C10: FCA. DE MUEBLES ALVEAR Y ALVEAR LTDA | F10: FECHA | G10: 46009
B11: RUT: | C11: 76.143.978-2 | F11: PLAZO ENTREGA | G11: 2 DIAS HABILES | R11: MT2 PUERTAS
B12: GIRO: | C12: FCA DE MUEBLES | F12: SERVICIO EXPRESS | G12: NO
B13: CONTACTO: | C13: CLAUDIO ALVEAR | F13: CORTADA A LA MEDIDA | G13: NO
B14: CORREO: | C14: LINEALTA1 | F14: DESPACHO | G14: NO | R14: ML CUBIERTAS
B15: FONO: | C15: 56973069852 | F15: INSTALACIÓN | G15: NO
B16: DIRECCION: | C16: ROSA ESTER 03281 LA PINTANA | F16: FORMA DE PAGO: | G16: ABONO 50% SALDO C/ENTREGA
B17: CIUDAD: | C17: SANTIAGO | F17: Duración cotización 5 días hábiles | G17: Cotizado por: Franco Donoso
B19: DETALLE | M19: 0.08 | P19: TOTAL | Q19: VALOR X MT2 | R19: ENCHAPE | S19: MT/L
B20: UNIDAD | C20: TIPO | D20: LARGO | E20: ANCHO | F20: COLOR | G20: VALOR | H20: TOTAL | L20: =B20 -> UNIDAD | M20: ALTO | N20: =E20 -> ANCHO | O20: MT | P20: MT2 | Q20: =O40 -> 138963.58 | R20: 20000 | T20: m/l
B21: 4 | C21: E/R 2 CARAS | D21: 2.4 | E21: 0.35 | F21: VAINILLA 2109 MT | G21: 474978 | H21: =G21*B21 -> 1899912 | L21: 1 | M21: =D21+M$19 -> 2.48 | N21: =E21+$N$19 -> 0.35 | O21: =M21*N21 -> 0.868 | P21: =O21*L21 -> 0.868 | Q21: =Q$20*O21 -> 120620.38 | R21: =Q21+R$20 -> 140620.38 | S21: =M21*L21 -> 2.48 | T21: =N21*2*L21*2 -> 1.4
B22: 2 | C22: PUERTAS | D22: 1 | E22: 0.35 | G22: 22942 | H22: =G22*B22 -> 45884 | L22: =B22 -> 2 | M22: =D22+M$19 -> 1.08 | N22: =E22+$N$19 -> 0.35 | O22: =M22*N22 -> 0.378 | P22: =O22*L22 -> 0.756 | Q22: =Q$20*O22 -> 52528.232 | R22: =Q22+R$20 -> 72528.232 | S22: =M22*L22 -> 2.16
B23: 3 | D23: 2.4 | E23: 0.35 | L23: =B23 -> 3 | M23: =D23+M$19 -> 2.48 | N23: =E23+$N$19 -> 0.35 | O23: =M23*N23 -> 0.868 | P23: =O23*L23 -> 2.604 | Q23: =Q$20*O23 -> 120620.38 | R23: =Q23+R$20 -> 140620.38 | S23: =M23*L23 -> 7.44
G26: NETO | H26: =SUM(H21:H25) -> 1945796 | K26: 2600000 | T26: =SUM(T21:T25) -> 1.4
G27: IVA | H27: =H26*19% -> 369701.24 | M27: =SUM(M21:M26) -> 6.04 | P27: =SUM(P21:P23) -> 4.228
G28: TOTAL | H28: =H26+H27 -> 2315497.2 | P28: =P27 -> 4.228 | S28: =SUM(S21:S27) -> 12.08
P29: =P28*20% -> 0.8456 | Q29: 20% PERDIDA | S29: =S28+T26 -> 13.48
P30: =P28+P29 -> 5.0736 | S30: =S29*20% -> 2.696
S31: =S29+S30 -> 16.176 | U31: ADHESIVO | V31: 58.000.- | W31: 44971
M32: =P30*2 -> 10.1472 | N32: 3500 | O32: =M32*N32 -> 35515.2 | P32: ADHESIVO | U32: LATA 16 LTS | V32: 3625 | W32: LITRO
M33: 2 | N33: 23500 | O33: =M33*N33 -> 47000 | P33: MDF 18MM | V33: 906.25 | W33: MT2 (4)
B34: CUENTA CORRIENTE BANCO SANTANDER Nº 87316181 A NOMBRE DE MUEBLES SANTA FE SPA | M34: 1 | N34: 42500 | O34: =M34*N34 -> 42500 | P34: LAMINA 153 X 366 | V34: =V33*20% -> 181.25 | W34: PERDIDA 20%
B35: RUT : 77.054.606-0 CORREO: FRANCODONOSO@TOPMOBILI.CL | M35: 3 | N35: 25000 | O35: =M35*N35 -> 75000 | P35: LAMINA 122X244 | V35: =V33+V34 -> 1087.5 | W35: MINIMO A COTIZAR
A36: GE | B36: VISITANOS Y DESCUBRE NUESTROS PRODUCTOS EN | F36: WWW.TOPMOBILICHILE.CL | M36: 1 | N36: 35000 | O36: =M36*N36 -> 35000 | P36: RESPALDO | R36: 1.52
N37: 1500 | O37: =M37*N37 -> 0 | P37: MEDIA CAÑA | R37: 2.44
O38: =SUM(O32:O37) -> 235015.2 | P38: COSTO | R38: =R36*R37 -> 3.7088
M39: PRECIO VENTA | O39: =O38*2.5 -> 587538 | P39: FACTOR 2,3 PARA 90° | R39: =P30/R38 -> 1.3679896
K40: 42800 | O40: =O39/P28 -> 138963.58 | P40: VALOR M2 | U40: MDF30MM | V40: 43650
K41: =K40/1.19 -> 35966.387 | O41: =O39/O38 -> 2.5 | U41: 46 UNIDADES | V41: 948.91 | W41: 2.4
U42: METRO LINEAL | V42: 395.37
U43: PERDIDA 20% | V43: 474.45
O50: 40935 | P50: MT2 | Q50: TERMO WOOD
C75: ,,,,,,,,,,,,,,,,,,,,,,,,,,,,,,,,,,,,,,,,,,,,,,,,,,,,,,,,,,,,,,,,,,,,,,,,,,,,,,,,,,,,,,,,,,,,,,,,,,,,,,,,,,,,,,,,,,,,,,,,,,,,,,,,,,,,,,,,,,,,,,,,,,,,,,,,,,,,,,,,,,,,,,,,,,,,,,,,,,,,,,,,,,,,,,,,,,,,,,,,,,,,,,,,,,,,,,,,,,,,,,,,,,,,,,,,,,,,,,,,,,,,,,,,,,,,,,,,,,,,,
...

Sheet COMEDOR OPERACIONES
F2: MUEBLES SANTA FE SPA
F3: VENTAS POR MENOR DE MUEBLES
F4: RUT: 77.054.606-0
F5: SEPTIMA AVENIDA 1631, SAN MIGUEL
F6: FONO +569 2032 3382 | O6: 10077 SF PORTLAND MAPLE
F7: E-MAIL: ventas@topmobili.cl
B8: P R E S U P U E S T O | D8: N° 11810
B10: NOMBRE: | C10: FCA. DE MUEBLES ALVEAR Y ALVEAR LTDA | F10: FECHA | G10: 46009
B11: RUT: | C11: 76.143.978-2 | F11: PLAZO ENTREGA | G11: 2 DIAS HABILES | R11: MT2 PUERTAS
B12: GIRO: | C12: FCA DE MUEBLES | F12: SERVICIO EXPRESS | G12: NO
B13: CONTACTO: | C13: CLAUDIO ALVEAR | F13: CORTADA A LA MEDIDA | G13: NO
B14: CORREO: | C14: LINEALTA1 | F14: DESPACHO | G14: NO | R14: ML CUBIERTAS
B15: FONO: | C15: 56973069852 | F15: INSTALACIÓN | G15: NO
B16: DIRECCION: | C16: ROSA ESTER 03281 LA PINTANA | F16: FORMA DE PAGO: | G16: ABONO 50% SALDO C/ENTREGA
B17: CIUDAD: | C17: SANTIAGO | F17: Duración cotización 5 días hábiles | G17: Cotizado por: Franco Donoso
B19: DETALLE | M19: 0.08 | P19: TOTAL | Q19: VALOR X MT2 | R19: ENCHAPE | S19: MT/L
B20: UNIDAD | C20: TIPO | D20: LARGO | E20: ANCHO | F20: COLOR | G20: VALOR | H20: TOTAL | L20: =B20 -> UNIDAD | M20: ALTO | N20: =E20 -> ANCHO | O20: MT | P20: MT2 | Q20: =O37 -> 139680.61 | R20: 25000 | T20: m/l
B21: 4 | C21: CUB ENCHAPE RECTO 1 CARA TRASCARA BALENCE | D21: 1.8 | E21: 0.7 | F21: VAINILLA 2109 MT | G21: 208820 | H21: =G21*B21 -> 835280 | L21: =B21 -> 4 | M21: =D21+M$19 -> 1.88 | N21: =E21+$N$19 -> 0.7 | O21: =M21*N21 -> 1.316 | P21: =O21*L21 -> 5.264 | Q21: =Q$20*O21 -> 183819.68 | R21: =Q21+R$20 -> 208819.68 | S21: =M21*L21 -> 7.52 | T21: =N21*2*L21*2 -> 11.2
G23: NETO | H23: =SUM(H21:H22) -> 835280 | K23: 2600000 | T23: =SUM(T21:T22) -> 11.2
G24: IVA | H24: =H23*19% -> 158703.2 | M24: =SUM(M21:M23) -> 1.88 | P24: =SUM(P21:P21) -> 5.264
G25: TOTAL | H25: =H23+H24 -> 993983.2 | P25: =P24 -> 5.264 | S25: =SUM(S21:S24) -> 7.52
P26: =P25*20% -> 1.0528 | Q26: 20% PERDIDA | S26: =S25+T23 -> 18.72
P27: =P25+P26 -> 6.3168 | S27: =S26*20% -> 3.744
S28: =S26+S27 -> 22.464 | U28: ADHESIVO | V28: 58.000.- | W28: 44971
M29: =P27*2 -> 12.6336 | N29: 3500 | O29: =M29*N29 -> 44217.6 | P29: ADHESIVO | U29: LATA 16 LTS | V29: 3625 | W29: LITRO
M30: 2 | N30: 40000 | O30: =M30*N30 -> 80000 | P30: MDF 18MM | V30: 906.25 | W30: MT2 (4)
B31: CUENTA CORRIENTE BANCO SANTANDER Nº 87316181 A NOMBRE DE MUEBLES SANTA FE SPA | M31: 4 | N31: 16500 | O31: =M31*N31 -> 66000 | P31: LAMINA 153 X 366 | V31: =V30*20% -> 181.25 | W31: PERDIDA 20%
B32: RUT : 77.054.606-0 CORREO: FRANCODONOSO@TOPMOBILI.CL | M32: 4 | N32: 36000 | O32: =M32*N32 -> 144000 | P32: LAMINA 122X244 | V32: =V30+V31 -> 1087.5 | W32: MINIMO A COTIZAR
A33: GE | B33: VISITANOS Y DESCUBRE NUESTROS PRODUCTOS EN | F33: WWW.TOPMOBILICHILE.CL | N33: 900 | O33: =M33*N33 -> 0 | P33: RESPALDO | R33: 1.52
N34: 1500 | O34: =M34*N34 -> 0 | P34: MEDIA CAÑA | R34: 2.44
O35: =SUM(O29:O34) -> 334217.6 | P35: COSTO | R35: =R33*R34 -> 3.7088
M36: PRECIO VENTA | O36: =O35*2.2 -> 735278.72 | P36: FACTOR 2,3 PARA 90° | R36: =P27/R35 -> 1.7031924
K37: 42800 | O37: =O36/P25 -> 139680.61 | P37: VALOR M2 | U37: MDF30MM | V37: 43650
K38: =K37/1.19 -> 35966.387 | O38: =O36/O35 -> 2.2 | U38: 46 UNIDADES | V38: 948.91 | W38: 2.4
U39: METRO LINEAL | V39: 395.37
U40: PERDIDA 20% | V40: 474.45
O47: 40935 | P47: MT2 | Q47: TERMO WOOD
C72: ,,,,,,,,,,,,,,,,,,,,,,,,,,,,,,,,,,,,,,,,,,,,,,,,,,,,,,,,,,,,,,,,,,,,,,,,,,,,,,,,,,,,,,,,,,,,,,,,,,,,,,,,,,,,,,,,,,,,,,,,,,,,,,,,,,,,,,,,,,,,,,,,,,,,,,,,,,,,,,,,,,,,,,,,,,,,,,,,,,,,,,,,,,,,,,,,,,,,,,,,,,,,,,,,,,,,,,,,,,,,,,,,,,,,,,,,,,,,,,,,,,,,,,,,,,,,,,,,,,,,,
C73: ,
C76: ,
...

Sheet JEFE DE BODEGA
F2: MUEBLES SANTA FE SPA
F3: VENTAS POR MENOR DE MUEBLES
F4: RUT: 77.054.606-0
F5: SEPTIMA AVENIDA 1631, SAN MIGUEL
F6: FONO +569 2032 3382 | O6: 10077 SF PORTLAND MAPLE
F7: E-MAIL: ventas@topmobili.cl
B8: P R E S U P U E S T O | D8: N° 11810
B10: NOMBRE: | C10: FCA. DE MUEBLES ALVEAR Y ALVEAR LTDA | F10: FECHA | G10: 46009
B11: RUT: | C11: 76.143.978-2 | F11: PLAZO ENTREGA | G11: 2 DIAS HABILES | R11: MT2 PUERTAS
B12: GIRO: | C12: FCA DE MUEBLES | F12: SERVICIO EXPRESS | G12: NO
B13: CONTACTO: | C13: CLAUDIO ALVEAR | F13: CORTADA A LA MEDIDA | G13: NO
B14: CORREO: | C14: LINEALTA1 | F14: DESPACHO | G14: NO | R14: ML CUBIERTAS
B15: FONO: | C15: 56973069852 | F15: INSTALACIÓN | G15: NO
B16: DIRECCION: | C16: ROSA ESTER 03281 LA PINTANA | F16: FORMA DE PAGO: | G16: ABONO 50% SALDO C/ENTREGA
B17: CIUDAD: | C17: SANTIAGO | F17: Duración cotización 5 días hábiles | G17: Cotizado por: Franco Donoso
B19: DETALLE | M19: 0.08 | P19: TOTAL | Q19: VALOR X MT2 | R19: ENCHAPE | S19: MT/L
B20: UNIDAD | C20: TIPO | D20: LARGO | E20: ANCHO | F20: COLOR | G20: VALOR | H20: TOTAL | L20: =B20 -> UNIDAD | M20: ALTO | N20: =E20 -> ANCHO | O20: MT | P20: MT2 | Q20: =O37 -> 85060.787 | R20: 15000 | T20: m/l
B21: 1 | C21: CUB ENCHAPE RECTO 1 CARA TRASCARA BALENCE | D21: 2.9 | E21: 0.74 | F21: VAINILLA 2109 MT | G21: 202576 | H21: =G21*B21 -> 202576 | L21: =B21 -> 1 | M21: =D21+M$19 -> 2.98 | N21: =E21+$N$19 -> 0.74 | O21: =M21*N21 -> 2.2052 | P21: =O21*L21 -> 2.2052 | Q21: =Q$20*O21 -> 187576.05 | R21: =Q21+R$20 -> 202576.05 | S21: =M21*L21 -> 2.98 | T21: =N21*2*L21*2 -> 2.96
G23: NETO | H23: =SUM(H21:H22) -> 202576 | K23: 2600000 | T23: =SUM(T21:T22) -> 2.96
G24: IVA | H24: =H23*19% -> 38489.44 | M24: =SUM(M21:M23) -> 2.98 | P24: =SUM(P21:P21) -> 2.2052
G25: TOTAL | H25: =H23+H24 -> 241065.44 | P25: =P24 -> 2.2052 | S25: =SUM(S21:S24) -> 2.98
P26: =P25*20% -> 0.44104 | Q26: 20% PERDIDA | S26: =S25+T23 -> 5.94
P27: =P25+P26 -> 2.64624 | S27: =S26*20% -> 1.188
S28: =S26+S27 -> 7.128 | U28: ADHESIVO | V28: 58.000.- | W28: 44971
M29: =P27 -> 2.64624 | N29: 3500 | O29: =M29*N29 -> 9261.84 | P29: ADHESIVO | U29: LATA 16 LTS | V29: 3625 | W29: LITRO
M30: 1 | N30: 40000 | O30: =M30*N30 -> 40000 | P30: MDF 18MM | V30: 906.25 | W30: MT2 (4)
B31: CUENTA CORRIENTE BANCO SANTANDER Nº 87316181 A NOMBRE DE MUEBLES SANTA FE SPA | N31: 58860 | O31: =M31*N31 -> 0 | P31: LAMINA 153 X 366 | V31: =V30*20% -> 181.25 | W31: PERDIDA 20%
B32: RUT : 77.054.606-0 CORREO: FRANCODONOSO@TOPMOBILI.CL | M32: 1 | N32: 36000 | O32: =M32*N32 -> 36000 | P32: LAMINA 122X244 | V32: =V30+V31 -> 1087.5 | W32: MINIMO A COTIZAR
A33: GE | B33: VISITANOS Y DESCUBRE NUESTROS PRODUCTOS EN | F33: WWW.TOPMOBILICHILE.CL | N33: 900 | O33: =M33*N33 -> 0 | P33: RESPALDO | R33: 1.52
N34: 1500 | O34: =M34*N34 -> 0 | P34: MEDIA CAÑA | R34: 2.44
O35: =SUM(O29:O34) -> 85261.84 | P35: COSTO | R35: =R33*R34 -> 3.7088
M36: PRECIO VENTA | O36: =O35*2.2 -> 187576.05 | P36: FACTOR 2,3 PARA 90° | R36: =P27/R35 -> 0.71350302
K37: 42800 | O37: =O36/P25 -> 85060.787 | P37: VALOR M2 | U37: MDF30MM | V37: 43650
K38: =K37/1.19 -> 35966.387 | O38: =O36/O35 -> 2.2 | U38: 46 UNIDADES | V38: 948.91 | W38: 2.4
U39: METRO LINEAL | V39: 395.37
U40: PERDIDA 20% | V40: 474.45
O47: 40935 | P47: MT2 | Q47: TERMO WOOD
C72: ,,,,,,,,,,,,,,,,,,,,,,,,,,,,,,,,,,,,,,,,,,,,,,,,,,,,,,,,,,,,,,,,,,,,,,,,,,,,,,,,,,,,,,,,,,,,,,,,,,,,,,,,,,,,,,,,,,,,,,,,,,,,,,,,,,,,,,,,,,,,,,,,,,,,,,,,,,,,,,,,,,,,,,,,,,,,,,,,,,,,,,,,,,,,,,,,,,,,,,,,,,,,,,,,,,,,,,,,,,,,,,,,,,,,,,,,,,,,,,,,,,,,,,,,,,,,,,,,,,,,,
C73: ,
C76: ,
...

Sheet SALA REUNIONES
F2: MUEBLES SANTA FE SPA
F3: VENTAS POR MENOR DE MUEBLES
F4: RUT: 77.054.606-0
F5: SEPTIMA AVENIDA 1631, SAN MIGUEL
F6: FONO +569 2032 3382 | O6: 10077 SF PORTLAND MAPLE
F7: E-MAIL: ventas@topmobili.cl
B8: P R E S U P U E S T O | D8: N° 11810
B10: NOMBRE: | C10: FCA. DE MUEBLES ALVEAR Y ALVEAR LTDA | F10: FECHA | G10: 46009
B11: RUT: | C11: 76.143.978-2 | F11: PLAZO ENTREGA | G11: 2 DIAS HABILES | R11: MT2 PUERTAS
B12: GIRO: | C12: FCA DE MUEBLES | F12: SERVICIO EXPRESS | G12: NO
B13: CONTACTO: | C13: CLAUDIO ALVEAR | F13: CORTADA A LA MEDIDA | G13: NO
B14: CORREO: | C14: LINEALTA1 | F14: DESPACHO | G14: NO | R14: ML CUBIERTAS
B15: FONO: | C15: 56973069852 | F15: INSTALACIÓN | G15: NO
B16: DIRECCION: | C16: ROSA ESTER 03281 LA PINTANA | F16: FORMA DE PAGO: | G16: ABONO 50% SALDO C/ENTREGA
B17: CIUDAD: | C17: SANTIAGO | F17: Duración cotización 5 días hábiles | G17: Cotizado por: Franco Donoso
B19: DETALLE | M19: 0.08 | P19: TOTAL | Q19: VALOR X MT2 | R19: ENCHAPE | S19: MT/L
B20: UNIDAD | C20: TIPO | D20: LARGO | E20: ANCHO | F20: COLOR | G20: VALOR | H20: TOTAL | L20: =B20 -> UNIDAD | M20: ALTO | N20: =E20 -> ANCHO | O20: MT | P20: MT2 | Q20: =O37 -> 107028.75 | R20: 15000 | T20: m/l
B21: 2 | C21: CUB DIAMETRO | D21: 0.9 | E21: 0.9 | F21: VAINILLA 2109 MT | G21: 84750 | H21: =G21*B21 -> 169500 | L21: =B21 -> 2 | M21: =D21+M$19 -> 0.98 | N21: =E21+$N$19 -> 0.9 | O21: =M21*N21 -> 0.882 | P21: =O21*L21 -> 1.764 | Q21: =Q$20*O21 -> 94399.36 | R21: =Q21+R$20 -> 109399.36 | S21: =M21*L21 -> 1.96 | T21: =N21*2*L21*2 -> 7.2
G23: NETO | H23: =SUM(H21:H22) -> 169500 | K23: 2600000 | T23: =SUM(T21:T22) -> 7.2
G24: IVA | H24: =H23*19% -> 32205 | M24: =SUM(M21:M23) -> 0.98 | P24: =SUM(P21:P21) -> 1.764
G25: TOTAL | H25: =H23+H24 -> 201705 | P25: =P24 -> 1.764 | S25: =SUM(S21:S24) -> 1.96
P26: =P25*20% -> 0.3528 | Q26: 20% PERDIDA | S26: =S25+T23 -> 9.16
P27: =P25+P26 -> 2.1168 | S27: =S26*20% -> 1.832
S28: =S26+S27 -> 10.992 | U28: ADHESIVO | V28: 58.000.- | W28: 44971
M29: =P27*2 -> 4.2336 | N29: 3500 | O29: =M29*N29 -> 14817.6 | P29: ADHESIVO | U29: LATA 16 LTS | V29: 3625 | W29: LITRO
M30: 0.5 | N30: 40000 | O30: =M30*N30 -> 20000 | P30: MDF 18MM | V30: 906.25 | W30: MT2 (4)
B31: CUENTA CORRIENTE BANCO SANTANDER Nº 87316181 A NOMBRE DE MUEBLES SANTA FE SPA | M31: 1 | N31: 15000 | O31: =M31*N31 -> 15000 | P31: LAMINA 153 X 366 | V31: =V30*20% -> 181.25 | W31: PERDIDA 20%
B32: RUT : 77.054.606-0 CORREO: FRANCODONOSO@TOPMOBILI.CL | M32: 1 | N32: 36000 | O32: =M32*N32 -> 36000 | P32: LAMINA 122X244 | V32: =V30+V31 -> 1087.5 | W32: MINIMO A COTIZAR
A33: GE | B33: VISITANOS Y DESCUBRE NUESTROS PRODUCTOS EN | F33: WWW.TOPMOBILICHILE.CL | N33: 900 | O33: =M33*N33 -> 0 | P33: RESPALDO | R33: 1.52
N34: 1500 | O34: =M34*N34 -> 0 | P34: MEDIA CAÑA | R34: 2.44
O35: =SUM(O29:O34) -> 85817.6 | P35: COSTO | R35: =R33*R34 -> 3.7088
M36: PRECIO VENTA | O36: =O35*2.2 -> 188798.72 | P36: FACTOR 2,3 PARA 90° | R36: =P27/R35 -> 0.57075065
K37: 42800 | O37: =O36/P25 -> 107028.75 | P37: VALOR M2 | U37: MDF30MM | V37: 43650
K38: =K37/1.19 -> 35966.387 | O38: =O36/O35 -> 2.2 | U38: 46 UNIDADES | V38: 948.91 | W38: 2.4
U39: METRO LINEAL | V39: 395.37
U40: PERDIDA 20% | V40: 474.45
O47: 40935 | P47: MT2 | Q47: TERMO WOOD
C72: ,,,,,,,,,,,,,,,,,,,,,,,,,,,,,,,,,,,,,,,,,,,,,,,,,,,,,,,,,,,,,,,,,,,,,,,,,,,,,,,,,,,,,,,,,,,,,,,,,,,,,,,,,,,,,,,,,,,,,,,,,,,,,,,,,,,,,,,,,,,,,,,,,,,,,,,,,,,,,,,,,,,,,,,,,,,,,,,,,,,,,,,,,,,,,,,,,,,,,,,,,,,,,,,,,,,,,,,,,,,,,,,,,,,,,,,,,,,,,,,,,,,,,,,,,,,,,,,,,,,,,
C73: ,
C76: ,
...

Sheet COSTOS
B2: CENTRO DE COSTOS POSTFORMADOS
B5: FECHA: | C5: ='SALA REUNIONES'!G10 -> 46009
B6: CLIENTE: | C6: ='SALA REUNIONES'!C10 -> FCA. DE MUEBLES ALVEAR Y ALVEAR LTDA | N6: Ventas Equilibrio = | P6: Costos Fijos Totales
B7: DIRECCION: | C7: ='SALA REUNIONES'!#REF! -> #REF! | H7: COSTOS INDIRECTOS DE FABRICA VARIABLES | O7: 1 - | P7: Costos Variables Totales
B8: PRESUPUESTO: | C8: ='SALA REUNIONES'!D8 -> N° 11810 | H8: Q/HRS | I8: $ | J8: DETALLE | K8: TOTAL | L8: TOTAL | P8: Total Venta | X8: =SUM(Q11:Q16) -> 6
H9: CANTIDAD | I9: PRECIO | J9: MATERIA PRIMA INDIRECTA | L9: =SUM(K10:K23) -> 2550 | S9: DETALLE | X9: =(E15-D11)/X8 -> -6345.785
D10: NETO | E10: IVA | F10: TOTAL | H10: 3 | I10: 350 | J10: RESPALDO | K10: =I10*H10 -> 1050 | Q10: UNIDAD | R10: TIPO | S10: LARGO | T10: ANCHO | U10: COLOR | V10: VALOR | W10: TOTAL
C11: MONTO A COBRAR | D11: ='SALA REUNIONES'!H23 -> 169500 | E11: =D11*0.19 -> 32205 | F11: =E11+D11 -> 201705 | H11: 3 | I11: 500 | J11: MEDIA CAÑA | K11: =I11*H11 -> 1500 | Q11: 1 | R11: CUB C/R R8 | S11: 2.8 | T11: 0.62 | U11: MADERA X DEFINIR | V11: 105990 | W11: =V11*Q11 -> 105990 | X11: =V11+$X$9 -> 99644.215 | Y11: 108990
C12: COSTO TOTAL | D12: =SUM(M43:M45) -> 79651.691 | H12: 0 | I12: 7500 | J12: DUROLAC | K12: =I12*H12 -> 0 | Q12: 1 | R12: CUB C/R R8 | S12: 2.3 | T12: 0.62 | U12: MADERA X DEFINIR | V12: 87990 | W12: =V12*Q12 -> 87990 | X12: =V12+$X$9 -> 81644.215 | Y12: 89990
C13: % UTILIDAD | D13: =D11-D12 -> 89848.309 | E13: =(D11/D12)-1 -> 1.1280151 | H13: 0 | I13: 50 | J13: TAPACANTO PVC | K13: =I13*H13 -> 0 | Q13: 1 | R13: CUB C/R R8 | S13: 2.03 | T13: 0.62 | U13: MADERA X DEFINIR | V13: 78990 | W13: =V13*Q13 -> 78990 | X13: =V13+$X$9 -> 72644.215 | Y13: 81990
D14: % utilidad | E14: NETO | F14: UTILIDAD | H14: 0 | I14: 50 | J14: SOBERBIOS | K14: =I14*H14 -> 0 | Q14: 1 | R14: CUB C/R R8 | S14: 1.08 | T14: 0.62 | U14: MADERA X DEFINIR | V14: 39990 | W14: =V14*Q14 -> 39990 | X14: =V14+$X$9 -> 33644.215 | Y14: 39990
C15: PROYECCION | D15: 0.65 | E15: =(100%+D15)*D12 -> 131425.29 | F15: =E15-D12 -> 51773.599 | H15: 0 | I15: 10 | J15: SOPORTE REPISA | K15: =I15*H15 -> 0 | Q15: 1 | R15: CUB C/R R8 | S15: 1.08 | T15: 0.62 | U15: MADERA X DEFINIR | V15: 39990 | W15: =V15*Q15 -> 39990 | X15: =V15+$X$9 -> 33644.215 | Y15: 39990
H16: 1 | J16: PUNTAS | K16: =I16*H16 -> 0 | Q16: 1 | R16: CUB C/R R8 | S16: 2.06 | T16: 0.62 | U16: MADERA X DEFINIR | V16: 79990 | W16: =V16*Q16 -> 79990 | X16: =V16+$X$9 -> 73644.215 | Y16: 83990
B17: M. PRIMA | C17: MATERIAL | D17: NETO | E17: IVA | F17: TOTAL | H17: 1 | J17: TORNILLOS | K17: =I17*H17 -> 0 | Q17: 6 | R17: CORTES 45° | V17: 5000 | W17: =V17*Q17 -> 30000
C18: LAMINA | D18: ='SALA REUNIONES'!O31 -> 15000 | E18: =D18*0.19 -> 2850 | F18: =SUM(D18:E18) -> 17850 | H18: 1 | J18: COLAFRIA | K18: =I18*H18 -> 0 | Q18: 1 | R18: PERFORACION LAVAPLATOS | V18: 10000 | W18: =V18*Q18 -> 10000
C19: MDF 18MM | D19: ='SALA REUNIONES'!O30 -> 20000 | E19: =D19*0.19 -> 3800 | F19: =SUM(D19:E19) -> 23800 | H19: 1 | J19: LIJAS | K19: =I19*H19 -> 0 | V19: NETO | W19: =SUM(W11:W18) -> 472940 | Y19: =SUM(Y11:Y16)+SUM(W17:W18) -> 484940
C20: ADHESIVO | D20: ='SALA REUNIONES'!O29 -> 14817.6 | E20: =D20*0.19 -> 2815.344 | F20: =SUM(D20:E20) -> 17632.944 | H20: 1 | J20: CARTON | K20: =I20*H20 -> 0 | V20: I.V.A. | W20: =W19*19% -> 89858.6 | Y20: =Y19*0.19 -> 92138.6
A21: =450000*1.2 -> 540000 | C21: TOTAL | D21: =SUM(D18:D20) -> 49817.6 | E21: =SUM(E18:E20) -> 9465.344 | F21: =SUM(F18:F20) -> 59282.944 | H21: 1 | J21: GUAIPE | K21: =I21*H21 -> 0 | M21: =B32/9 -> 2318.8406 | Q21: PLAZO DE ENTREGA : 8 DIAS HABILES | V21: TOTAL | W21: =W19+W20 -> 562798.6 | Y21: =SUM(Y19:Y20) -> 577078.6
A22: =450000*1.2 -> 540000 | B22: M. DE OBRA | C22: PROCESO | D22: COSTO x Hr. | E22: Q Hrs. | F22: TOTAL | H22: 1 | J22: DILUYENTE | K22: =I22*H22 -> 0 | Q22: FORMA DE PAGO: 50% CONTADO, SALDO C/E
A23: =800000*1.2 -> 960000 | B23: =A21/23 -> 23478.261 | C23: CORTE | D23: =B23/9 -> 2608.6957 | E23: 0.5 | F23: =D23*E23 -> 1304.3478 | H23: 1 | J23: CINTA EMBALAJE | K23: =I23*H23 -> 0 | Q23: VALIDEZ COTIZACIÓN: 5 DIAS
A24: 450000 | B24: =A22/23 -> 23478.261 | C24: CORTE LAMINA | D24: =B24/9 -> 2608.6957 | E24: 0.5 | F24: =D24*E24 -> 1304.3478 | H24: Q/HRS | I24: PRECIO | J24: MANO DE OBRA INDIRECTA | K24: VALOR | L24: =SUM(K25:K35) -> 0
A25: 450000 | B25: =A23/23 -> 41739.13 | C25: REBAJE LAMINA | D25: =B25/9 -> 4637.6812 | F25: =D25*E25 -> 0 | H25: 0 | I25: =((480000/23)/9) -> 2318.8406 | J25: FLETERO (HRS) | K25: =H25*I25 -> 0
B26: =A24/23 -> 19565.217 | C26: TUPIZADO | D26: =B26/9 -> 2173.913 | E26: 0.5 | F26: =D26*E26 -> 1086.9565 | H26: 0 | J26: BENCINA | K26: =H26*I26 -> 0
A27: 350000 | B27: =A25/23 -> 19565.217 | C27: ARMADO | D27: =B27/9 -> 2173.913 | E27: 0.5 | F27: =D27*E27 -> 1086.9565 | H27: 0 | J27: TAG | K27: =H27*I27 -> 0
A28: 500000 | B28: =A27/23 -> 15217.391 | C28: PEGADO | D28: =B28/9 -> 1690.8213 | E28: 0.7 | F28: =D28*E28 -> 1183.5749 | H28: 0 | J28: RECTIFICACION | K28: =H28*I28 -> 0
B29: =A28/23 -> 21739.13 | C29: POSTFORMADO | D29: =B29/9 -> 2415.4589 | E29: 0.7 | F29: =D29*E29 -> 1690.8213 | H29: 0 | I29: =((550000*1.2)/23)/9 -> 3188.4058 | J29: HR. TRAB. JUAN | K29: =H29*I29 -> 0
A30: 450000 | C30: MEDIA CAÑA | D30: 2415 | F30: =D30*E30 -> 0 | H30: 0 | I30: =((450000*1.2)/23)/9 -> 2608.6957 | J30: HR. TRAB. JULIO | K30: =H30*I30 -> 0
A31: 350000 | B31: =A30/23 -> 19565.217 | C31: CORTE-ENCHAPE | D31: =B31/9 -> 2173.913 | E31: 0 | F31: =D31*E31 -> 0 | H31: 0 | I31: =((450000*1.2)/23)/9 -> 2608.6957 | J31: HR. TRAB. EUGE | K31: =H31*I31 -> 0
A32: =A21+A24+A27+A28+A30 -> 2290000 | B32: =480000/23 -> 20869.565 | C32: CONTROL CALIDAD | D32: =B32/9 -> 2318.8406 | E32: 0.5 | F32: =D32*E32 -> 1159.4203 | H32: 0 | J32: COLACION | K32: =H32*I32 -> 0
C33: TOTAL | D33: =SUM(D23:D32) -> 25216.932 | E33: =SUM(E23:E32) -> 3.9 | F33: =SUM(F23:F32) -> 8816.4251 | H33: 0 | J33: BONO | K33: =H33*I33 -> 0
B34: CIF | C34: M. PRIMA INDIREC. | D34: =L9 -> 2550 | H34: 1 | J34: PERFORACION | K34: =H34*I34 -> 0
C35: M. OBRA INDIRECTA | D35: =L24 -> 0 | H35: 6 | J35: CORTE 45 | K35: =H35*I35 -> 0
C36: GASTOS DE FABRICA | D36: =L36 -> 18467.666 | H36: CANTIDAD | I36: PRECIO | J36: GASTOS DE FABRICACION | K36: VALOR | L36: =SUM(K37:K39) -> 18467.666
C37: DEPRECIACIONES | H37: =$E$33 -> 3.9 | I37: =32609.69/9 -> 3623.2989 | J37: ARRIENDO x HORA | K37: =I37*H37 -> 14130.866
C38: TOTAL | D38: =SUM(D34:D37) -> 21017.666 | H38: =$E$33 -> 3.9 | I38: 967 | J38: AGUA x HORA | K38: =I38*H38 -> 3771.3
H39: =$E$33 -> 3.9 | I39: 145 | J39: LUZ x HORA | K39: =I39*H39 -> 565.5
B40: PROVISIONAR | C40: IVA | D40: =E11-E21 -> 22739.656
H41: ESTADO DE RESULTADOS
B42: TOTAL HRS TRABAJADAS | D42: =E33 -> 3.9 | H42: INGRESOS | I42: + TOTAL VENTA | M42: =D11 -> 169500
H43: COSTOS | I43: - MATERIA PRIMA DIRECTA | M43: =D21 -> 49817.6
...

Sheet NOTA DE VENTA
F2: MUEBLES SANTA FE SPA
F3: VENTAS POR MENOR DE MUEBLES
F4: RUT: 77.054.606-0
F5: SEPTIMA AVENIDA 1631, SAN MIGUEL
F6: CELULAR: 963868755
F7: E-MAIL: fdonoso@topmobili.cl
B8: P R E S U P U E S T O | D8: ='SALA REUNIONES'!D8 -> N° 11810 | F8: NOTA DE VENTA :
B10: CLIENTE: | C10: =IF('SALA REUNIONES'!C10="","",'SALA REUNIONES'!C10) -> FCA. DE MUEBLES ALVEAR Y ALVEAR LTDA | F10: FECHA : | G10: ='SALA REUNIONES'!G10 -> 46009
B11: RUT: | C11: =IF('SALA REUNIONES'!C11="","",'SALA REUNIONES'!C11) -> 76.143.978-2 | F11: FECHA LIMITE : | G11: =WORKDAY(G10,5) -> 46016
B12: GIRO: | C12: =IF('SALA REUNIONES'!C12="","",'SALA REUNIONES'!C12) -> FCA DE MUEBLES | F12: DESPACHO: | G12: ='SALA REUNIONES'!G14 -> NO
B13: CONTACTO: | C13: =IF('SALA REUNIONES'!C13="","",'SALA REUNIONES'!C13) -> CLAUDIO ALVEAR | F13: ORDEN DE COMPRA:
B14: CORREO: | C14: =IF('SALA REUNIONES'!C14="","",'SALA REUNIONES'!C14) -> LINEALTA1 | F14: HECHO POR: | G14: FERNANDO DONOSO
B15: FONO: | C15: =IF('SALA REUNIONES'!C15="","",'SALA REUNIONES'!C15) -> 56973069852 | F15: SERVICIO EXPRESS: | G15: ='SALA REUNIONES'!G12 -> NO
B16: DIRECCION: | C16: =IF('SALA REUNIONES'!C16="","",'SALA REUNIONES'!C16) -> ROSA ESTER 03281 LA PINTANA | F16: FORMA DE PAGO : | G16: ='SALA REUNIONES'!G16 -> ABONO 50% SALDO C/ENTREGA
B17: CIUDAD: | C17: =IF('SALA REUNIONES'!C17="","",'SALA REUNIONES'!C17) -> SANTIAGO | F17: VALIDEZ COTIZACIÓN: 5 DÍAS
B20: D E T A L L E
B21: UNIDAD | C21: TIPO | D21: LARGO | E21: ANCHO | F21: COLOR | G21: VALOR | H21: TOTAL
B22: ='SALA REUNIONES'!B21 -> 2 | C22: ='SALA REUNIONES'!C21 -> CUB DIAMETRO | D22: ='SALA REUNIONES'!D21*1000 -> 900 | E22: ='SALA REUNIONES'!E21*1000 -> 900 | F22: ='SALA REUNIONES'!F21 -> VAINILLA 2109 MT | G22: ='SALA REUNIONES'!G21 -> 84750 | H22: =G22*B22 -> 169500
G25: NETO | H25: =SUM(H22:H24) -> 169500
G26: I.V.A. | H26: =H25*19% -> 32205
G27: TOTAL | H27: =H25+H26 -> 201705
B30: CUENTA VISTA DEL BANCO ESTADO N° 35571389078 A NOMBRE DE
B31: "MUEBLES SANTA FE SPA." - RUT : 77.054.606-0, VENTAS@TOPMOBILI.CL
B32: VISITANOS Y DESCUBRE NUESTROS PRODUCTOS EN | E32: WWW.TOPMOBILICHILE.CL

Sheet REGLAS
B2: DETALLE CORTE LAMINA | G2: DETALLE CORTE SUSTRATO | P2: DETALLE CORTE MERA
B3: ALTO | C3: ANCHO | D3: TIPO | G3: ALTO | H3: ANCHO | I3: TIPO | P3: ALTO | Q3: ANCHO | R3: TIPO
B4: 40 | C4: 60 | D4: CEN 1V | E4: A1 | G4: 50 | H4: 100 | I4: CEN 1V | J4: REGLA SIEMPRE LLEVAR MEDIDA MINIMO A 100 | P4: 50 | Q4: -30 | R4: CUB C/R
B5: 40 | C5: 90 | D5: CEN 2V | E5: A2 | G5: 50 | I5: CEN 2V | J5: REGLA SIEMPRE LLEVAR MEDIDA MINIMO A 101 | P5: 50 | Q5: -30 | R5: CUB C/R
B6: 40 | C6: 100 | D6: CORNISA FRENTE ESPAÑOL 1 LADO | E6: A3 | G6: 50 | H6: 100 | I6: CORNISA FRENTE ESPAÑOL 1 LADO | P6: 50 | Q6: -30 | R6: CUB C/R 180°
B7: 40 | C7: 150 | D7: CORNISA FRENTE ESPAÑOL 2 LADO | E7: A4 | G7: 50 | I7: CORNISA FRENTE ESPAÑOL 2 LADO | P7: 50 | Q7: -30 | R7: CUB C/R FRENTE ESPAÑOL
B8: 40 | C8: 100 | D8: CORNISA 180° 1LADO | E8: A5 | G8: 50 | H8: 100 | I8: CORNISA 180° 1LADO | L8: DETALLE CORTE MERA | P8: 50 | Q8: -30 | R8: CUB C/R PUNTA 1 LADO
B9: 40 | C9: 50 | D9: CORNISA PUNTA TIBURON 1 LADO | E9: B | G9: 50 | H9: 100 | I9: CORNISA 1LADO | L9: ALTO | M9: ANCHO | N9: TIPO | P9: 50 | Q9: 0 | R9: CUB S/R FRENTE ESPAÑOL
B10: 40 | C10: 80 | D10: CORNISA PUNTA TIBURON 2 LADOS | E10: C | G10: 50 | I10: CORNISA 2 LADOS | L10: 50 | M10: -30 | N10: CUB C/R | P10: 50 | Q10: 0 | R10: CUB S/R
B11: 40 | C11: 60 | D11: CORNISA R8 1LADO | E11: D | G11: 50 | H11: 100 | I11: CORNISA PUNTA TIBURON 1 LADO | L11: 50 | M11: 0 | N11: CUB S/R y CUB MESA | P11: 50 | Q11: 0 | R11: CUB MESA 180° 2 LADOS
B12: 40 | C12: 100 | D12: CORNISA R8 2 LADOS | E12: E | G12: 50 | I12: CORNISA PUNTA TIBURON 2 LADOS | L12: 50 | M12: -2 | N12: PR | P12: 50 | Q12: 0 | R12: CUB MESA 180° 3 LADOS
B13: 40 | C13: 130 | D13: CUB C/R R6 | E13: F | G13: 50 | H13: -30 | I13: CUB C/R | P13: 50 | Q13: 0 | R13: CUB MESA 180° 4 LADOS
B14: 40 | C14: 150 | D14: CUB C/R 180° | G14: 50 | H14: -30 | I14: CUB C/R 180°
B15: 40 | C15: 150 | D15: CUB C/R FRENTE ESPAÑOL | E15: G | G15: 50 | H15: -30 | I15: CUB C/R FRENTE ESPAÑOL | P15: 50 | Q15: 0 | R15: CUB MESA 4 LADOS
B16: 40 | C16: 130 | D16: CUB C/R R2 | E16: H | G16: 50 | H16: -30 | I16: CUB C/R PUNTA TIBURON 1 LADO | P16: 50 | Q16: 0 | R16: CUB MESA FRENTE ESPAÑOL 2 LADOS
B17: 40 | C17: 150 | D17: CUB MESA 180° 2 LADOS | E17: I | G17: 50 | I17: CUB MESA 180° 2 LADOS | P17: 50 | Q17: 0 | R17: CUB MESA FRENTE ESPAÑOL 3 LADOS
B18: 140 | C18: 150 | D18: CUB MESA 180° 3 LADOS | E18: J | G18: 50 | I18: CUB MESA 180° 3 LADOS | P18: 50 | Q18: 0 | R18: CUB MESA FRENTE ESPAÑOL 4 LADOS
B19: 150 | C19: 150 | D19: CUB MESA 180° 4 LADOS | E19: K | G19: 50 | I19: CUB MESA 180° 4 LADOS | P19: 50 | Q19: 0 | R19: CUB MESA PUNTA TIBURON 2 LADOS
B20: 40 | C20: 100 | D20: CUB MESA 2L | E20: L | G20: 50 | H20: 0 | I20: CUB MESA 2L | J20: ES IGUAL A LO PEDIDO NO SE DEBE SUMAR NI RESTAR | P20: 50 | Q20: 0 | R20: CUB MESA PUNTA TIBURON 3 LADOS
B21: 100 | C21: 100 | D21: CUB MESA 3L | E21: M | G21: 50 | H21: 0 | I21: CUB MESA 3L | P21: 50 | Q21: 0 | R21: CUB MESA PUNTA TIBURON 4 LADOS
B22: 100 | C22: 100 | D22: CUB MESA 4 LADOS | E22: N | I22: CUB MESA 4 LADOS | P22: 50 | Q22: 0 | R22: CUB PUNTA TIBURON 1 LADO
B23: 40 | C23: 150 | D23: CUB MESA FRENTE ESPAÑOL 2 LADOS | E23: O | G23: 50 | I23: CUB MESA FRENTE ESPAÑOL 2 LADOS | R23: CENEFA 1 LADO
B24: 140 | C24: 150 | D24: CUB MESA FRENTE ESPAÑOL 3 LADOS | E24: P | G24: 50 | I24: CUB MESA FRENTE ESPAÑOL 3 LADOS | R24: CENEFA 2 LADOS
B25: 150 | C25: 150 | D25: CUB MESA FRENTE ESPAÑOL 4 LADOS | E25: Q | G25: 50 | I25: CUB MESA FRENTE ESPAÑOL 4 LADOS | R25: CORNISA FRENTE ESPAÑOL 1 LADO
B26: 40 | C26: 77 | D26: CUB MESA PUNTA TIBURON 2 LADOS | E26: R | G26: 50 | I26: CUB MESA PUNTA TIBURON 2 LADOS | R26: CORNISA FRENTE ESPAÑOL 2 LADO
B27: 110 | C27: 77 | D27: CUB MESA PUNTA TIBURON 3 LADOS | E27: S | G27: 50 | I27: CUB MESA PUNTA TIBURON 3 LADOS | R27: CORNISA 180° 1LADO
B28: 120 | C28: 77 | D28: CUB MESA PUNTA TIBURON 4 LADOS | E28: T | G28: 50 | I28: CUB MESA PUNTA TIBURON 4 LADOS | R28: CORNISA 1LADO
B29: 40 | C29: 50 | D29: CUB PUNTA TIBURON 1 LADO | E29: U | G29: 50 | I29: CUB PUNTA TIBURON 1 LADO | R29: CORNISA 2 LADOS
B30: 40 | C30: 60 | D30: CUB S/R | E30: V | G30: 50 | I30: CUB S/R | R30: CORNISA PUNTA TIBURON 1 LADO
B31: 40 | C31: 100 | D31: CUB S/R FRENTE ESPAÑOL | E31: W | G31: 50 | I31: CUB S/R FRENTE ESPAÑOL | R31: CORNISA PUNTA TIBURON 2 LADOS
B32: 40 | C32: 60 | D32: CUB S/R R2 | E32: X | G32: 50 | I32: CUB S/R R2 | R32: PR2
B33: 40 | C33: 90 | D33: PR12 | E33: Y | G33: 50 | H33: -2 | I33: PR12 | R33: PR6
B34: 40 | C34: 90 | D34: PR19 | G34: 50 | H34: -2 | I34: PR19
B35: 40 | C35: 90 | D35: PR2 | E35: Z | G35: 50 | H35: -2 | I35: PR2 | R35: PR8
B36: 40 | C36: 90 | D36: PR6 | G36: 50 | H36: -2 | I36: PR6 | R36: PR12
B37: 40 | C37: 90 | D37: PR8 | G37: 50 | H37: -2 | I37: PR8 | R37: PR19
B48: 40 | C48: 150

Sheet PRODUCCION
K2: NO BORRAR REGLAS!!!!! SI NO LAS SABEN USAR NO BORREN ESTO POR FAVOR!!!!!
K3: SUSTRATO | M3: LAMINADO
C4: NOTA DE VENTA : | D4: =IF('NOTA DE VENTA'!$G$8="","",'NOTA DE VENTA'!$G$8) | K4: ALTO | L4: ANCHO | M4: ALTO | N4: ANCHO
C5: CLIENTE : | D5: ='NOTA DE VENTA'!$C$10 -> FCA. DE MUEBLES ALVEAR Y ALVEAR LTDA | K5: =LOOKUP(F14,REGLAS!$I$4:$I$37,REGLAS!$G$4:$G$37)+J14 -> 1850 | L5: =LOOKUP(F14,REGLAS!$I$4:$I$37,REGLAS!$H$4:$H$37)+K14 -> 470 | M5: =LOOKUP(F14,REGLAS!$D$4:$D$37,REGLAS!$B$4:$B$37)+J21 -> 1840 | N5: =H10 -> 0
C7: ='NOTA DE VENTA'!$F$10 -> FECHA : | D7: ='NOTA DE VENTA'!$G$10 -> 46009
C8: FECHA ENTREGA: | D8: ='NOTA DE VENTA'!$G$11 -> 46016
A10: SUSTRATO
D12: ALTO | E12: ANCHO
A13: MATERIAL | B13: CANTIDAD | C13: CORTE | D13: 80 | E13: -30 | F13: DESCRIPCIÓN | J13: ALTO | K13: ANCHO
A14: MDF 18MM | B14: =I14 -> 1 | D14: =LOOKUP(F14,REGLAS!$I$4:$I$37,REGLAS!$G$4:$G$37)+J14 -> 1850 | E14: =LOOKUP(F14,REGLAS!$I$4:$I$37,REGLAS!$H$4:$H$37)+K14 -> 470 | F14: =C27 -> CUB C/R R8 | I14: =I21 -> 1 | J14: =D27 -> 1800 | K14: =E27 -> 500
A17: LAMINADO
D19: ALTO | E19: ANCHO
A20: MATERIAL | B20: CANTIDAD | C20: CORTE | D20: 40 | E20: 130 | F20: DESCRIPCIÓN | J20: ALTO | K20: ANCHO
A21: MDF 18MM | B21: =I21 -> 1 | D21: =LOOKUP(F14,REGLAS!$D$4:$D$37,REGLAS!$B$4:$B$37)+J21 -> 1840 | E21: =LOOKUP(F14,REGLAS!$D$4:$D$37,REGLAS!$C$4:$C$37)+K21 -> 630 | F21: =C27 -> CUB C/R R8 | I21: =B27 -> 1 | J21: =D27 -> 1800 | K21: =E27 -> 500
B24: MEDIDAS ORIGINALES
A26: MATERIAL | B26: CANTIDAD | C26: DESCRIPCIÓN | D26: ALTO | E26: ANCHO | F26: COLOR
A27: MDF 18MM | B27: ='[1]4637'!B21 -> 1 | C27: ='[1]4637'!C21 -> CUB C/R R8 | D27: ='[1]4637'!D21 -> 1800 | E27: ='[1]4637'!E21 -> 500 | F27: ='[1]4637'!F21 -> LATE 2167 MT
C39: NOTA DE VENTA : | D39: ='[1]4637'!G8 -> 7332
C40: CLIENTE : | D40: ='[1]4637'!C10 -> FMR MAKING SPA
C42: ='[1]4637'!F11 -> FECHA LIMITE : | D42: ='[1]4637'!G11 -> 45996
A45: PRODUCCIÓN
B47: DETALLE
B48: CANTIDAD | C48: CORTE | D48: ALTO | E48: ANCHO | F48: DESCRIPCION
A49: MDF18MM | B49: ='[1]4637'!B21 -> 1 | C49: ='[1]4637'!C21 -> CUB C/R R8 | D49: ='[1]4637'!D21 -> 1800 | E49: ='[1]4637'!E21 -> 500 | F49: ='[1]4637'!F21 -> LATE 2167 MT

Sheet SEGUIMIENTO
A1: NV | B1: N° COTIZA | C1: FECHA | D1: ENTREGA | E1: NOMBRE | F1: DETALLE | G1: COLOR | H1: NETO | I1: IVA | J1: TOTAL | K1: ABONO | L1: SALDO | M1: ESTADO
A2: ='NOTA DE VENTA'!$G$8 -> 0 | B2: ='NOTA DE VENTA'!$D$8 -> N° 11810 | C2: ='NOTA DE VENTA'!$G$10 -> 46009 | D2: ='NOTA DE VENTA'!$G$11 -> 46016 | E2: ='NOTA DE VENTA'!$C$10 -> FCA. DE MUEBLES ALVEAR Y ALVEAR LTDA | F2: ='NOTA DE VENTA'!$C$22 -> CUB DIAMETRO | G2: ='NOTA DE VENTA'!$F$22 -> VAINILLA 2109 MT | H2: ='NOTA DE VENTA'!$H$25 -> 169500 | I2: =H2*0.19 -> 32205 | J2: =I2+H2 -> 201705 | L2: =J2-K2 -> 201705
