Workbook

Sheet CAJONERA
G2: MUEBLES SANTA FE SPA
G3: VENTAS POR MENOR DE MUEBLES
G4: RUT: 77.054.606-0
G5: SEPTIMA AVENIDA 1631, SAN MIGUEL
G6: FONO 22521 6502 | O6: 10077 SF PORTLAND MAPLE
G7: E-MAIL: ventas@topmobili.cl
B8: P R E S U P U E S T O | D8: N° 10917
L9: 56950
B10: CLIENTE: | C10: COMERCIALIZADORA MDM | G10: FECHA: | H10: 45390 | L10: =L9/1.19 -> 47857.143
B11: RUT: | G11: PLAZO ENTREGA: | H11: 5 DIAS HABILES | R11: MT2 PUERTAS
B12: GIRO: | G12: SERVICIO EXPRESS | H12: NO
B13: CONTACTO: | C13: DANIELA
B14: CORREO: | G14: CORTADA A LA MEDIDA | H14: NO | R14: ML CUBIERTAS
B15: FONO: | C15: +569 9744 8059 | G15: DESPACHO: | H15: NO | L15: 600
B16: DIRECCION: | G16: FORMA DE PAGO: | H16: ABONO 50%, SALDO C/E | L16: 36
B17: CIUDAD: | C17: SANTIAGO | G17: DURACION COTIZACION: 5 DIAS FERNANDO DONOSO | L17: =L15-L16 -> 564
B19: , | M19: 0.02 | N19: 0.02 | P19: TOTAL | Q19: VALOR X MT2 | R19: ENCHAPE | S19: MT/L
B20: UNIDAD | C20: TIPO | D20: ALTO | E20: FRENTE | F20: FONDO | G20: COLOR | H20: VALOR | I20: TOTAL | L20: =B20 -> UNIDAD | M20: ALTO | N20: =F20 -> FONDO | O20: MT | P20: MT2 | Q20: =O37 -> 230768.51 | R20: 15000 | T20: m/l
B21: 22 | C21: CAJONERA | D21: 0.64 | E21: 0.6 | F21: 0.5 | G21: BLANCO OPACO | H21: 123451 | I21: =H21*B21 -> 2715922 | L21: =B21 -> 22 | M21: =D21+M$19 -> 0.66 | N21: =F21+N$19 -> 0.52 | O21: =M21*N21 -> 0.3432 | P21: =O21*L21 -> 7.5504 | Q21: =Q$20*O21 -> 79199.751 | R21: =Q21+R$20 -> 94199.751 | S21: =M21*L21*2 -> 29.04
H23: NETO | I23: =SUM(I21:I22) -> 2715922 | M23: =SUM(M21:M22) -> 0.66
H24: IVA | I24: =I23*0.19 -> 516025.18 | P24: =SUM(P21:P21) -> 7.5504
H25: TOTAL | I25: =I23+I24 -> 3231947.2 | P25: =P24 -> 7.5504 | S25: =SUM(S21:S24) -> 29.04 | T25: 120
K26: 32 | P26: =P25*20% -> 1.51008 | Q26: 20% PERDIDA | T26: =S25*T25 -> 3484.8
K27: 32 | P27: =P25+P26 -> 9.06048 | S27: 40 | T27: =T26/22 -> 158.4
K28: 55
K29: =SUM(K26:K28) -> 119 | M29: =P27 -> 9.06048 | N29: 3500 | O29: =M29*N29 -> 31711.68 | P29: ADHESIVO | Q29: TRASCARA ENCHAPADA, ES POR 2
M30: 12 | N30: 43000 | O30: =M30*N30 -> 516000 | P30: MDF25MM
N31: 43000 | O31: =M31*N31 -> 0 | P31: LAMINA 153 X 366
B32: CUENTA CORRIENTE BANCO SANTANDER Nº 87316181 A NOMBRE DE MUEBLES SANTA FE SPA | M32: 12 | N32: 23500 | O32: =M32*N32 -> 282000 | P32: LAMINA 122X244
B33: RUT : 77.054.606-0 VENTAS@TOPMOBILI.CL | I33: 94592 | J33: COSTO | N33: 800 | O33: =M33*N33 -> 0 | P33: RESPALDO | R33: 1.52 | T33: 1.23
B34: VISITANOS Y DESCUBRE NUESTROS PRODUCTOS EN | G34: WWW.TOPMOBILICHILE.CL | I34: 2000 | J34: RUEDAS C/FRENO | N34: 1500 | O34: =M34*N34 -> 0 | P34: MEDIA CAÑA | R34: 2.44 | T34: 3.05
I35: 1496 | J35: RUEDEAS S(FRENO | O35: =SUM(O29:O34) -> 829711.68 | P35: COSTO | R35: =R33*R34 -> 3.7088 | T35: =T33*T34 -> 3.7515
I36: 3689 | J36: CIERRE KARDEX | K36: 5900 | M36: PRECIO VENTA | O36: =O35*2.1 -> 1742394.5 | P36: FACTOR 2,3 PARA 90° | R36: =P25/R35 -> 2.0358067 | T36: =P25/T35 -> 2.0126349
I37: 1500 | J37: TAPACANTO | K37: =K36/1.19 -> 4957.9832 | L37: =K37*3 -> 14873.95 | O37: =O36/P25 -> 230768.51 | P37: VALOR M2
I38: 5300 | J38: MELAMINA 15MM | O38: =O36/O35 -> 2.1
I39: 14874 | J39: RIELES TELESCOPICOS
I40: =SUM(I33:I39) -> 123451 | T40: 1.83
I41: MELAMINA BLANCA 15MM 183X250 | L41: 5900 | T41: 2.5
L42: =L41/3 -> 1966.6667 | T42: =T40*T41 -> 4.575
T43: =P27/T42 -> 1.9804328
...

Sheet 2229
F2: MUEBLES SANTA FE SPA
F3: VENTAS POR MENOR DE MUEBLES
F4: RUT: 77.054.606-0
F5: SEPTIMA AVENIDA 1631, SAN MIGUEL
F6: FONO 22521 6502 | N6: 10077 SF PORTLAND MAPLE
F7: E-MAIL: ventas@topmobili.cl
B8: P R E S U P U E S T O | D8: N° 10917
K9: 56950
B10: CLIENTE: | C10: COMERCIALIZADORA MDM | F10: FECHA: | G10: 45390 | K10: =K9/1.19 -> 47857.143
B11: RUT: | F11: PLAZO ENTREGA: | G11: 5 DIAS HABILES | Q11: MT2 PUERTAS
B12: GIRO: | F12: SERVICIO EXPRESS | G12: NO
B13: CONTACTO: | C13: DANIELA
B14: CORREO: | F14: CORTADA A LA MEDIDA | G14: NO | Q14: ML CUBIERTAS
B15: FONO: | C15: +569 9744 8059 | F15: DESPACHO: | G15: NO | K15: 600
B16: DIRECCION: | F16: FORMA DE PAGO: | G16: ABONO 50%, SALDO C/E | K16: 36
B17: CIUDAD: | C17: SANTIAGO | F17: DURACION COTIZACION: 5 DIAS FERNANDO DONOSO | K17: =K15-K16 -> 564
B19: , | L19: 0.02 | M19: 0.02 | O19: TOTAL | P19: VALOR X MT2 | Q19: ENCHAPE | R19: MT/L
B20: UNIDAD | C20: TIPO | D20: LARGO | E20: ANCHO | F20: COLOR | G20: VALOR | H20: TOTAL | K20: =B20 -> UNIDAD | L20: ALTO | M20: =E20 -> ANCHO | N20: MT | O20: MT2 | P20: =N40 -> 45294.204 | Q20: 15000 | S20: m/l
B21: 44 | C21: COSTADOS | D21: 0.64 | E21: 0.5 | F21: BLANCO OPACO | G21: 15545 | H21: =G21*B21 -> 683980 | K21: =B21 -> 44 | L21: =D21+L$19 -> 0.66 | M21: =E21+M$19 -> 0.52 | N21: =L21*M21 -> 0.3432 | O21: =N21*K21 -> 15.1008 | P21: =P$20*N21 -> 15544.971 | Q21: =P21+Q$20 -> 30544.971 | R21: =L21*K21*2 -> 58.08
B22: 44 | C22: PISO + CIELO | D22: 0.564 | E22: 0.5 | G22: 13755 | H22: =G22*B22 -> 605220 | K22: =B22 -> 44 | L22: =D22+L$19 -> 0.584 | M22: =E22+M$19 -> 0.52 | N22: =L22*M22 -> 0.30368 | O22: =N22*K22 -> 13.36192 | P22: =P$20*N22 -> 13754.944 | Q22: =P22+Q$20 -> 28754.944 | R22: =L22*K22*2 -> 51.392
B23: 22 | C23: TRASERA | D23: 0.64 | E23: 0.564 | G23: 17458 | H23: =G23*B23 -> 384076 | K23: =B23 -> 22 | L23: =D23+L$19 -> 0.66 | M23: =E23+M$19 -> 0.584 | N23: =L23*M23 -> 0.38544 | O23: =N23*K23 -> 8.47968 | P23: =P$20*N23 -> 17458.198 | Q23: =P23+Q$20 -> 32458.198 | R23: =L23*K23*2 -> 29.04
B24: 22 | C24: PUERTAS | D24: 0.64 | E24: 0.6 | G24: 18534 | H24: =G24*B24 -> 407748 | K24: =B24 -> 22 | L24: =D24+L$19 -> 0.66 | M24: =E24+M$19 -> 0.62 | N24: =L24*M24 -> 0.4092 | O24: =N24*K24 -> 9.0024 | P24: =P$20*N24 -> 18534.388 | Q24: =P24+Q$20 -> 33534.388 | R24: =L24*K24*2 -> 29.04
G25: =SUM(G21:G24) -> 65292
G26: NETO | H26: =SUM(H21:H25) -> 2081024 | I26: =H26/22 -> 94592 | L26: =SUM(L21:L25) -> 2.564
G27: IVA | H27: =H26*0.19 -> 395394.56 | O27: =SUM(O21:O24) -> 45.9448
G28: TOTAL | H28: =H26+H27 -> 2476418.6 | O28: =O27 -> 45.9448 | R28: =SUM(R21:R27) -> 167.552 | S28: 120
J29: 32 | O29: =O28*20% -> 9.18896 | P29: 20% PERDIDA | S29: =R28*S28 -> 20106.24
J30: 32 | O30: =O28+O29 -> 55.13376 | R30: 40 | S30: =S29/22 -> 913.92
J31: 55
J32: =SUM(J29:J31) -> 119 | L32: =O30 -> 55.13376 | M32: 3500 | N32: =L32*M32 -> 192968.16 | O32: ADHESIVO | P32: TRASCARA ENCHAPADA, ES POR 2
L33: 12 | M33: 43000 | N33: =L33*M33 -> 516000 | O33: MDF25MM
M34: 43000 | N34: =L34*M34 -> 0 | O34: LAMINA 153 X 366
B35: CUENTA CORRIENTE BANCO SANTANDER Nº 87316181 A NOMBRE DE MUEBLES SANTA FE SPA | L35: 12 | M35: 23500 | N35: =L35*M35 -> 282000 | O35: LAMINA 122X244
B36: RUT : 77.054.606-0 VENTAS@TOPMOBILI.CL | H36: 65292 | M36: 800 | N36: =L36*M36 -> 0 | O36: RESPALDO | Q36: 1.52 | S36: 1.23
B37: VISITANOS Y DESCUBRE NUESTROS PRODUCTOS EN | F37: WWW.TOPMOBILICHILE.CL | H37: 2000 | M37: 1500 | N37: =L37*M37 -> 0 | O37: MEDIA CAÑA | Q37: 2.44 | S37: 3.05
H38: 1496 | N38: =SUM(N32:N37) -> 990968.16 | O38: COSTO | Q38: =Q36*Q37 -> 3.7088 | S38: =S36*S37 -> 3.7515
H39: 3689 | J39: 4390 | L39: PRECIO VENTA | N39: =N38*2.1 -> 2081033.1 | O39: FACTOR 2,3 PARA 90° | Q39: =O28/Q38 -> 12.38805 | S39: =O28/S38 -> 12.247048
H40: 1500 | J40: =J39/1.19 -> 3689.0756 | N40: =N39/O28 -> 45294.204 | O40: VALOR M2
H41: =SUM(H36:H40) -> 73977 | N41: =N39/N38 -> 2.1
S43: 1.83
...

Sheet COSTOS
B2: CENTRO DE COSTOS POSTFORMADOS
B5: FECHA: | C5: ='2229'!G10 -> 45390
B6: CLIENTE: | C6: ='2229'!C10 -> COMERCIALIZADORA MDM | N6: Ventas Equilibrio = | P6: Costos Fijos Totales
B7: DIRECCION: | C7: ='2229'!#REF! -> #REF! | H7: COSTOS INDIRECTOS DE FABRICA VARIABLES | O7: 1 - | P7: Costos Variables Totales
B8: PRESUPUESTO: | C8: ='2229'!D8 -> N° 10917 | H8: Q/HRS | I8: $ | J8: DETALLE | K8: TOTAL | L8: TOTAL | P8: Total Venta | X8: =SUM(Q11:Q16) -> 6
H9: CANTIDAD | I9: PRECIO | J9: MATERIA PRIMA INDIRECTA | L9: =SUM(K10:K23) -> 2550 | S9: DETALLE | X9: =(E15-D11)/X8 -> -143666.71
D10: NETO | E10: IVA | F10: TOTAL | H10: 3 | I10: 350 | J10: RESPALDO | K10: =I10*H10 -> 1050 | Q10: UNIDAD | R10: TIPO | S10: LARGO | T10: ANCHO | U10: COLOR | V10: VALOR | W10: TOTAL
C11: MONTO A COBRAR | D11: ='2229'!H26 -> 2081024 | E11: =D11*0.19 -> 395394.56 | F11: =E11+D11 -> 2476418.6 | H11: 3 | I11: 500 | J11: MEDIA CAÑA | K11: =I11*H11 -> 1500 | Q11: 1 | R11: CUB C/R R8 | S11: 2.8 | T11: 0.62 | U11: MADERA X DEFINIR | V11: 105990 | W11: =V11*Q11 -> 105990 | X11: =V11+$X$9 -> -37676.714 | Y11: 108990
C12: COSTO TOTAL | D12: =SUM(M43:M45) -> 738802.25 | H12: 0 | I12: 7500 | J12: DUROLAC | K12: =I12*H12 -> 0 | Q12: 1 | R12: CUB C/R R8 | S12: 2.3 | T12: 0.62 | U12: MADERA X DEFINIR | V12: 87990 | W12: =V12*Q12 -> 87990 | X12: =V12+$X$9 -> -55676.714 | Y12: 89990
C13: % UTILIDAD | D13: =D11-D12 -> 1342221.7 | E13: =(D11/D12)-1 -> 1.8167537 | H13: 0 | I13: 50 | J13: TAPACANTO PVC | K13: =I13*H13 -> 0 | Q13: 1 | R13: CUB C/R R8 | S13: 2.03 | T13: 0.62 | U13: MADERA X DEFINIR | V13: 78990 | W13: =V13*Q13 -> 78990 | X13: =V13+$X$9 -> -64676.714 | Y13: 81990
D14: % utilidad | E14: NETO | F14: UTILIDAD | H14: 0 | I14: 50 | J14: SOBERBIOS | K14: =I14*H14 -> 0 | Q14: 1 | R14: CUB C/R R8 | S14: 1.08 | T14: 0.62 | U14: MADERA X DEFINIR | V14: 39990 | W14: =V14*Q14 -> 39990 | X14: =V14+$X$9 -> -103676.71 | Y14: 39990
C15: PROYECCION | D15: 0.65 | E15: =(100%+D15)*D12 -> 1219023.7 | F15: =E15-D12 -> 480221.46 | H15: 0 | I15: 10 | J15: SOPORTE REPISA | K15: =I15*H15 -> 0 | Q15: 1 | R15: CUB C/R R8 | S15: 1.08 | T15: 0.62 | U15: MADERA X DEFINIR | V15: 39990 | W15: =V15*Q15 -> 39990 | X15: =V15+$X$9 -> -103676.71 | Y15: 39990
H16: 1 | J16: PUNTAS | K16: =I16*H16 -> 0 | Q16: 1 | R16: CUB C/R R8 | S16: 2.06 | T16: 0.62 | U16: MADERA X DEFINIR | V16: 79990 | W16: =V16*Q16 -> 79990 | X16: =V16+$X$9 -> -63676.714 | Y16: 83990
B17: M. PRIMA | C17: MATERIAL | D17: NETO | E17: IVA | F17: TOTAL | H17: 1 | J17: TORNILLOS | K17: =I17*H17 -> 0 | Q17: 6 | R17: CORTES 45° | V17: 5000 | W17: =V17*Q17 -> 30000
C18: LAMINA | D18: ='2229'!N34 -> 0 | E18: =D18*0.19 -> 0 | F18: =SUM(D18:E18) -> 0 | H18: 1 | J18: COLAFRIA | K18: =I18*H18 -> 0 | Q18: 1 | R18: PERFORACION LAVAPLATOS | V18: 10000 | W18: =V18*Q18 -> 10000
C19: MDF 18MM | D19: ='2229'!N33 -> 516000 | E19: =D19*0.19 -> 98040 | F19: =SUM(D19:E19) -> 614040 | H19: 1 | J19: LIJAS | K19: =I19*H19 -> 0 | V19: NETO | W19: =SUM(W11:W18) -> 472940 | Y19: =SUM(Y11:Y16)+SUM(W17:W18) -> 484940
C20: ADHESIVO | D20: ='2229'!N32 -> 192968.16 | E20: =D20*0.19 -> 36663.95 | F20: =SUM(D20:E20) -> 229632.11 | H20: 1 | J20: CARTON | K20: =I20*H20 -> 0 | V20: I.V.A. | W20: =W19*19% -> 89858.6 | Y20: =Y19*0.19 -> 92138.6
A21: =450000*1.2 -> 540000 | C21: TOTAL | D21: =SUM(D18:D20) -> 708968.16 | E21: =SUM(E18:E20) -> 134703.95 | F21: =SUM(F18:F20) -> 843672.11 | H21: 1 | J21: GUAIPE | K21: =I21*H21 -> 0 | M21: =B32/9 -> 2318.8406 | Q21: PLAZO DE ENTREGA : 8 DIAS HABILES | V21: TOTAL | W21: =W19+W20 -> 562798.6 | Y21: =SUM(Y19:Y20) -> 577078.6
A22: =450000*1.2 -> 540000 | B22: M. DE OBRA | C22: PROCESO | D22: COSTO x Hr. | E22: Q Hrs. | F22: TOTAL | H22: 1 | J22: DILUYENTE | K22: =I22*H22 -> 0 | Q22: FORMA DE PAGO: 50% CONTADO, SALDO C/E
A23: =800000*1.2 -> 960000 | B23: =A21/23 -> 23478.261 | C23: CORTE | D23: =B23/9 -> 2608.6957 | E23: 0.5 | F23: =D23*E23 -> 1304.3478 | H23: 1 | J23: CINTA EMBALAJE | K23: =I23*H23 -> 0 | Q23: VALIDEZ COTIZACIÓN: 5 DIAS
A24: 450000 | B24: =A22/23 -> 23478.261 | C24: CORTE LAMINA | D24: =B24/9 -> 2608.6957 | E24: 0.5 | F24: =D24*E24 -> 1304.3478 | H24: Q/HRS | I24: PRECIO | J24: MANO DE OBRA INDIRECTA | K24: VALOR | L24: =SUM(K25:K35) -> 0
A25: 450000 | B25: =A23/23 -> 41739.13 | C25: REBAJE LAMINA | D25: =B25/9 -> 4637.6812 | F25: =D25*E25 -> 0 | H25: 0 | I25: =((480000/23)/9) -> 2318.8406 | J25: FLETERO (HRS) | K25: =H25*I25 -> 0
B26: =A24/23 -> 19565.217 | C26: TUPIZADO | D26: =B26/9 -> 2173.913 | E26: 0.5 | F26: =D26*E26 -> 1086.9565 | H26: 0 | J26: BENCINA | K26: =H26*I26 -> 0
A27: 350000 | B27: =A25/23 -> 19565.217 | C27: ARMADO | D27: =B27/9 -> 2173.913 | E27: 0.5 | F27: =D27*E27 -> 1086.9565 | H27: 0 | J27: TAG | K27: =H27*I27 -> 0
A28: 500000 | B28: =A27/23 -> 15217.391 | C28: PEGADO | D28: =B28/9 -> 1690.8213 | E28: 0.7 | F28: =D28*E28 -> 1183.5749 | H28: 0 | J28: RECTIFICACION | K28: =H28*I28 -> 0
B29: =A28/23 -> 21739.13 | C29: POSTFORMADO | D29: =B29/9 -> 2415.4589 | E29: 0.7 | F29: =D29*E29 -> 1690.8213 | H29: 0 | I29: =((550000*1.2)/23)/9 -> 3188.4058 | J29: HR. TRAB. JUAN | K29: =H29*I29 -> 0
A30: 450000 | C30: MEDIA CAÑA | D30: 2415 | F30: =D30*E30 -> 0 | H30: 0 | I30: =((450000*1.2)/23)/9 -> 2608.6957 | J30: HR. TRAB. JULIO | K30: =H30*I30 -> 0
A31: 350000 | B31: =A30/23 -> 19565.217 | C31: CORTE-ENCHAPE | D31: =B31/9 -> 2173.913 | E31: 0 | F31: =D31*E31 -> 0 | H31: 0 | I31: =((450000*1.2)/23)/9 -> 2608.6957 | J31: HR. TRAB. EUGE | K31: =H31*I31 -> 0
A32: =A21+A24+A27+A28+A30 -> 2290000 | B32: =480000/23 -> 20869.565 | C32: CONTROL CALIDAD | D32: =B32/9 -> 2318.8406 | E32: 0.5 | F32: =D32*E32 -> 1159.4203 | H32: 0 | J32: COLACION | K32: =H32*I32 -> 0
C33: TOTAL | D33: =SUM(D23:D32) -> 25216.932 | E33: =SUM(E23:E32) -> 3.9 | F33: =SUM(F23:F32) -> 8816.4251 | H33: 0 | J33: BONO | K33: =H33*I33 -> 0
B34: CIF | C34: M. PRIMA INDIREC. | D34: =L9 -> 2550 | H34: 1 | J34: PERFORACION | K34: =H34*I34 -> 0
C35: M. OBRA INDIRECTA | D35: =L24 -> 0 | H35: 6 | J35: CORTE 45 | K35: =H35*I35 -> 0
C36: GASTOS DE FABRICA | D36: =L36 -> 18467.666 | H36: CANTIDAD | I36: PRECIO | J36: GASTOS DE FABRICACION | K36: VALOR | L36: =SUM(K37:K39) -> 18467.666
C37: DEPRECIACIONES | H37: =$E$33 -> 3.9 | I37: =32609.69/9 -> 3623.2989 | J37: ARRIENDO x HORA | K37: =I37*H37 -> 14130.866
C38: TOTAL | D38: =SUM(D34:D37) -> 21017.666 | H38: =$E$33 -> 3.9 | I38: 967 | J38: AGUA x HORA | K38: =I38*H38 -> 3771.3
H39: =$E$33 -> 3.9 | I39: 145 | J39: LUZ x HORA | K39: =I39*H39 -> 565.5
B40: PROVISIONAR | C40: IVA | D40: =E11-E21 -> 260690.61
H41: ESTADO DE RESULTADOS
B42: TOTAL HRS TRABAJADAS | D42: =E33 -> 3.9 | H42: INGRESOS | I42: + TOTAL VENTA | M42: =D11 -> 2081024
H43: COSTOS | I43: - MATERIA PRIMA DIRECTA | M43: =D21 -> 708968.16
...
