Workbook

Sheet 2229
E2: MUEBLES SANTA FE SPA
E3: VENTAS POR MENOR DE MUEBLES
E4: RUT: 77.054.606-0
E5: SEPTIMA AVENIDA 1631, SAN MIGUEL
E6: FONO 22521 6502 | M6: 10077 SF PORTLAND MAPLE
E7: E-MAIL: ventas@topmobili.cl
B8: P R E S U P U E S T O | D8: N° 10937
B10: CLIENTE: | C10: CONSTRUCTORA E INMOBILIARIA CERRO BAYO S.A. | E10: FECHA: | F10: 45412
B11: RUT: | C11: 96.574.230-1 | E11: PLAZO ENTREGA: | F11: A CONVENIR | P11: MT2 PUERTAS
B12: GIRO: | E12: SERVICIO EXPRESS | F12: NO
B13: CONTACTO: | C13: PAULO SALGADO | E13: LICITACION: | F13: CONFUTURO | K13: 32.98 | L13: MT2
B14: CORREO: | E14: CORTADA A LA MEDIDA | F14: NO | P14: ML CUBIERTAS
B15: FONO: | C15: 56986690342 | E15: DESPACHO: | F15: NO | J15: =G35/K13 -> 1442625.4
B16: DIRECCION: | E16: FORMA DE PAGO: | F16: ABONO 50%, SALDO C/E
B17: CIUDAD: | C17: SANTIAGO | E17: DURACION COTIZACION: 5 DIAS FRANCO DONOSO
B19: , | K19: 0.05 | N19: TOTAL | O19: VALOR X MT2 | P19: ENCHAPE | Q19: MT/L
B20: UNIDAD | C20: TIPO | D20: ESTRUCTURA | E20: OBSERVACIONES | F20: VALOR | G20: TOTAL | J20: =#REF! -> #REF! | K20: ALTO | L20: =#REF! -> #REF! | M20: MT | N20: MT2 | O20: =M49 -> #REF! | P20: 3000 | R20: m/l
B21: 1 | C21: LOCKERS | D21: SEGÚN EETT | E21: INCLUYE CERRADURA DIGITAL | F21: 10420769 | G21: =F21*B21 -> 10420769 | J21: =B20 -> UNIDAD | K21: =#REF!+K$19 -> #REF! | L21: =D20+L$19 -> #VALUE! | M21: =K21*L21 -> #REF! | N21: =M21*J21 -> #REF! | O21: =O$20*M21 -> #REF! | P21: =O21+P$20 -> #REF! | Q21: =J21*K21 -> #VALUE!
B22: 1 | C22: MUEBLE RECEPCION CHICO 2 PISO | D22: SEGÚN EETT | F22: 1466964 | G22: =F22*B22 -> 1466964
B23: 1 | C23: MUEBLE RECEPCION 2 PISO | D23: SEGÚN EETT | F23: 2105950 | G23: =F23*B23 -> 2105950
B24: 1 | C24: KITCHENETTE | D24: SEGÚN EETT | F24: 5380500 | G24: =F24*B24 -> 5380500
B25: 1 | C25: MUEBLES CAFETERIA 3 PISO | D25: SEGÚN EETT | F25: 1980500 | G25: =F25*B25 -> 1980500
B26: 1 | C26: MUEBLE CAFETERIA 2 PISO | D26: SEGÚN EETT | F26: 871000 | G26: =F26*B26 -> 871000
B27: 1 | C27: MUEBLE IT 3 PISO | D27: SEGÚN EETT | F27: 1708750 | G27: =F27*B27 -> 1708750
B28: 1 | C28: CAFÉ ZONA DE ESPERA | D28: SEGÚN EETT | F28: 1780950 | G28: =F28*B28 -> 1780950
B29: 1 | C29: TABIQUE TIPO MADERA | D29: SEGÚN EETT | F29: 1511800 | G29: =F29*B29 -> 1511800
B30: 1 | C30: SEPARADORES (6 UNIDADES) | D30: SEGÚN EETT | E30: FALTA CONFIRMAR COLOR LAMINA | F30: 6931732 | G30: =F30*B30 -> 6931732
B31: 1 | C31: CLOSET | D31: SEGÚN EETT | F31: 8069950 | G31: =F31*B31 -> 8069950
B32: 1 | C32: ENCHAPE MURO ZONA DE ESPERA | D32: SEGÚN EETT | F32: 5348920 | G32: =F32*B32 -> 5348920
F35: NETO | G35: =SUM(G20:G34) -> 47577785 | K35: =SUM(K21:K34) -> #REF!
F36: IVA | G36: =G35*0.19 -> 9039779.2 | N36: =SUM(N21:N21) -> #REF!
F37: TOTAL | G37: =G35+G36 -> 56617564 | N37: =N36 -> #REF! | Q37: =SUM(Q21:Q36) -> #VALUE!
N38: =N37*0.2 -> #REF! | O38: 20% PERDIDA
N39: =N37+N38 -> #REF! | Q39: 40
K41: =N39 -> #REF! | L41: 3500 | M41: =K41*L41 -> #REF! | N41: ADHESIVO | O41: TRASCARA ENCHAPADA, ES POR 2
K42: 0.22 | L42: 25000 | M42: =K42*L42 -> 5500 | N42: MDF25MM
B43: CUENTA CORRIENTE BANCO SANTANDER Nº 87316181 A NOMBRE DE MUEBLES SANTA FE SPA | L43: 150000 | M43: =K43*L43 -> 0 | N43: LAMINA 153 X 366
B44: RUT : 77.054.606-0 VENTAS@TOPMOBILI.CL | K44: 1 | L44: 22000 | M44: =K44*L44 -> 22000 | N44: LAMINA 122X244
B45: VISITANOS Y DESCUBRE NUESTROS PRODUCTOS EN | E45: WWW.TOPMOBILICHILE.CL | K45: 1 | L45: 800 | M45: =K45*L45 -> 800 | N45: RESPALDO | P45: 1.83
K46: =K35 -> #REF! | L46: 1500 | M46: =K46*L46 -> #REF! | N46: MEDIA CAÑA | P46: 3.66 | R46: 1500
...

Sheet COSTOS
B2: CENTRO DE COSTOS POSTFORMADOS
B5: FECHA: | C5: ='2229'!F10 -> 45412
B6: CLIENTE: | C6: ='2229'!C10 -> CONSTRUCTORA E INMOBILIARIA CERRO BAYO S.A. | N6: Ventas Equilibrio = | P6: Costos Fijos Totales
B7: DIRECCION: | C7: ='2229'!#REF! -> #REF! | H7: COSTOS INDIRECTOS DE FABRICA VARIABLES | O7: 1 - | P7: Costos Variables Totales
B8: PRESUPUESTO: | C8: ='2229'!#REF! -> #REF! | H8: Q/HRS | I8: $ | J8: DETALLE | K8: TOTAL | L8: TOTAL | P8: Total Venta | X8: =SUM(Q11:Q16) -> 6
H9: CANTIDAD | I9: PRECIO | J9: MATERIA PRIMA INDIRECTA | L9: =SUM(K10:K23) -> 2550 | S9: DETALLE | X9: =(E15-D11)/X8 -> #REF!
D10: NETO | E10: IVA | F10: TOTAL | H10: 3 | I10: 350 | J10: RESPALDO | K10: =I10*H10 -> 1050 | Q10: UNIDAD | R10: TIPO | S10: LARGO | T10: ANCHO | U10: COLOR | V10: VALOR | W10: TOTAL
C11: MONTO A COBRAR | D11: ='2229'!G35 -> 47577785 | E11: =D11*0.19 -> 9039779.2 | F11: =E11+D11 -> 56617564 | H11: 3 | I11: 500 | J11: MEDIA CAÑA | K11: =I11*H11 -> 1500 | Q11: 1 | R11: CUB C/R R8 | S11: 2.8 | T11: 0.62 | U11: MADERA X DEFINIR | V11: 105990 | W11: =V11*Q11 -> 105990 | X11: =V11+$X$9 -> #REF! | Y11: 108990
C12: COSTO TOTAL | D12: =SUM(M43:M45) -> #REF! | H12: 0 | I12: 7500 | J12: DUROLAC | K12: =I12*H12 -> 0 | Q12: 1 | R12: CUB C/R R8 | S12: 2.3 | T12: 0.62 | U12: MADERA X DEFINIR | V12: 87990 | W12: =V12*Q12 -> 87990 | X12: =V12+$X$9 -> #REF! | Y12: 89990
C13: % UTILIDAD | D13: =D11-D12 -> #REF! | E13: =(D11/D12)-1 -> #REF! | H13: 0 | I13: 50 | J13: TAPACANTO PVC | K13: =I13*H13 -> 0 | Q13: 1 | R13: CUB C/R R8 | S13: 2.03 | T13: 0.62 | U13: MADERA X DEFINIR | V13: 78990 | W13: =V13*Q13 -> 78990 | X13: =V13+$X$9 -> #REF! | Y13: 81990
D14: % utilidad | E14: NETO | F14: UTILIDAD | H14: 0 | I14: 50 | J14: SOBERBIOS | K14: =I14*H14 -> 0 | Q14: 1 | R14: CUB C/R R8 | S14: 1.08 | T14: 0.62 | U14: MADERA X DEFINIR | V14: 39990 | W14: =V14*Q14 -> 39990 | X14: =V14+$X$9 -> #REF! | Y14: 39990
C15: PROYECCION | D15: 0.65 | E15: =(100%+D15)*D12 -> #REF! | F15: =E15-D12 -> #REF! | H15: 0 | I15: 10 | J15: SOPORTE REPISA | K15: =I15*H15 -> 0 | Q15: 1 | R15: CUB C/R R8 | S15: 1.08 | T15: 0.62 | U15: MADERA X DEFINIR | V15: 39990 | W15: =V15*Q15 -> 39990 | X15: =V15+$X$9 -> #REF! | Y15: 39990
H16: 1 | J16: PUNTAS | K16: =I16*H16 -> 0 | Q16: 1 | R16: CUB C/R R8 | S16: 2.06 | T16: 0.62 | U16: MADERA X DEFINIR | V16: 79990 | W16: =V16*Q16 -> 79990 | X16: =V16+$X$9 -> #REF! | Y16: 83990
B17: M. PRIMA | C17: MATERIAL | D17: NETO | E17: IVA | F17: TOTAL | H17: 1 | J17: TORNILLOS | K17: =I17*H17 -> 0 | Q17: 6 | R17: CORTES 45° | V17: 5000 | W17: =V17*Q17 -> 30000
C18: LAMINA | D18: ='2229'!M43 -> 0 | E18: =D18*0.19 -> 0 | F18: =SUM(D18:E18) -> 0 | H18: 1 | J18: COLAFRIA | K18: =I18*H18 -> 0 | Q18: 1 | R18: PERFORACION LAVAPLATOS | V18: 10000 | W18: =V18*Q18 -> 10000
C19: MDF 18MM | D19: ='2229'!M42 -> 5500 | E19: =D19*0.19 -> 1045 | F19: =SUM(D19:E19) -> 6545 | H19: 1 | J19: LIJAS | K19: =I19*H19 -> 0 | V19: NETO | W19: =SUM(W11:W18) -> 472940 | Y19: =SUM(Y11:Y16)+SUM(W17:W18) -> 484940
C20: ADHESIVO | D20: ='2229'!M41 -> #REF! | E20: =D20*0.19 -> #REF! | F20: =SUM(D20:E20) -> #REF! | H20: 1 | J20: CARTON | K20: =I20*H20 -> 0 | V20: I.V.A. | W20: =W19*19% -> 89858.6 | Y20: =Y19*0.19 -> 92138.6
A21: =450000*1.2 -> 540000 | C21: TOTAL | D21: =SUM(D18:D20) -> #REF! | E21: =SUM(E18:E20) -> #REF! | F21: =SUM(F18:F20) -> #REF! | H21: 1 | J21: GUAIPE | K21: =I21*H21 -> 0 | M21: =B32/9 -> 2318.8406 | Q21: PLAZO DE ENTREGA : 8 DIAS HABILES | V21: TOTAL | W21: =W19+W20 -> 562798.6 | Y21: =SUM(Y19:Y20) -> 577078.6
A22: =450000*1.2 -> 540000 | B22: M. DE OBRA | C22: PROCESO | D22: COSTO x Hr. | E22: Q Hrs. | F22: TOTAL | H22: 1 | J22: DILUYENTE | K22: =I22*H22 -> 0 | Q22: FORMA DE PAGO: 50% CONTADO, SALDO C/E
A23: =800000*1.2 -> 960000 | B23: =A21/23 -> 23478.261 | C23: CORTE | D23: =B23/9 -> 2608.6957 | E23: 0.5 | F23: =D23*E23 -> 1304.3478 | H23: 1 | J23: CINTA EMBALAJE | K23: =I23*H23 -> 0 | Q23: VALIDEZ COTIZACIÓN: 5 DIAS
A24: 450000 | B24: =A22/23 -> 23478.261 | C24: CORTE LAMINA | D24: =B24/9 -> 2608.6957 | E24: 0.5 | F24: =D24*E24 -> 1304.3478 | H24: Q/HRS | I24: PRECIO | J24: MANO DE OBRA INDIRECTA | K24: VALOR | L24: =SUM(K25:K35) -> 0
A25: 450000 | B25: =A23/23 -> 41739.13 | C25: REBAJE LAMINA | D25: =B25/9 -> 4637.6812 | F25: =D25*E25 -> 0 | H25: 0 | I25: =((480000/23)/9) -> 2318.8406 | J25: FLETERO (HRS) | K25: =H25*I25 -> 0
B26: =A24/23 -> 19565.217 | C26: TUPIZADO | D26: =B26/9 -> 2173.913 | E26: 0.5 | F26: =D26*E26 -> 1086.9565 | H26: 0 | J26: BENCINA | K26: =H26*I26 -> 0
A27: 350000 | B27: =A25/23 -> 19565.217 | C27: ARMADO | D27: =B27/9 -> 2173.913 | E27: 0.5 | F27: =D27*E27 -> 1086.9565 | H27: 0 | J27: TAG | K27: =H27*I27 -> 0
A28: 500000 | B28: =A27/23 -> 15217.391 | C28: PEGADO | D28: =B28/9 -> 1690.8213 | E28: 0.7 | F28: =D28*E28 -> 1183.5749 | H28: 0 | J28: RECTIFICACION | K28: =H28*I28 -> 0
B29: =A28/23 -> 21739.13 | C29: POSTFORMADO | D29: =B29/9 -> 2415.4589 | E29: 0.7 | F29: =D29*E29 -> 1690.8213 | H29: 0 | I29: =((550000*1.2)/23)/9 -> 3188.4058 | J29: HR. TRAB. JUAN | K29: =H29*I29 -> 0
A30: 450000 | C30: MEDIA CAÑA | D30: 2415 | F30: =D30*E30 -> 0 | H30: 0 | I30: =((450000*1.2)/23)/9 -> 2608.6957 | J30: HR. TRAB. JULIO | K30: =H30*I30 -> 0
A31: 350000 | B31: =A30/23 -> 19565.217 | C31: CORTE-ENCHAPE | D31: =B31/9 -> 2173.913 | E31: 0 | F31: =D31*E31 -> 0 | H31: 0 | I31: =((450000*1.2)/23)/9 -> 2608.6957 | J31: HR. TRAB. EUGE | K31: =H31*I31 -> 0
A32: =A21+A24+A27+A28+A30 -> 2290000 | B32: =480000/23 -> 20869.565 | C32: CONTROL CALIDAD | D32: =B32/9 -> 2318.8406 | E32: 0.5 | F32: =D32*E32 -> 1159.4203 | H32: 0 | J32: COLACION | K32: =H32*I32 -> 0
C33: TOTAL | D33: =SUM(D23:D32) -> 25216.932 | E33: =SUM(E23:E32) -> 3.9 | F33: =SUM(F23:F32) -> 8816.4251 | H33: 0 | J33: BONO | K33: =H33*I33 -> 0
B34: CIF | C34: M. PRIMA INDIREC. | D34: =L9 -> 2550 | H34: 1 | J34: PERFORACION | K34: =H34*I34 -> 0
C35: M. OBRA INDIRECTA | D35: =L24 -> 0 | H35: 6 | J35: CORTE 45 | K35: =H35*I35 -> 0
C36: GASTOS DE FABRICA | D36: =L36 -> 18467.666 | H36: CANTIDAD | I36: PRECIO | J36: GASTOS DE FABRICACION | K36: VALOR | L36: =SUM(K37:K39) -> 18467.666
C37: DEPRECIACIONES | H37: =$E$33 -> 3.9 | I37: =32609.69/9 -> 3623.2989 | J37: ARRIENDO x HORA | K37: =I37*H37 -> 14130.866
C38: TOTAL | D38: =SUM(D34:D37) -> 21017.666 | H38: =$E$33 -> 3.9 | I38: 967 | J38: AGUA x HORA | K38: =I38*H38 -> 3771.3
H39: =$E$33 -> 3.9 | I39: 145 | J39: LUZ x HORA | K39: =I39*H39 -> 565.5
B40: PROVISIONAR | C40: IVA | D40: =E11-E21 -> #REF!
H41: ESTADO DE RESULTADOS
B42: TOTAL HRS TRABAJADAS | D42: =E33 -> 3.9 | H42: INGRESOS | I42: + TOTAL VENTA | M42: =D11 -> 47577785
H43: COSTOS | I43: - MATERIA PRIMA DIRECTA | M43: =D21 -> #REF!
...
