Workbook

Sheet CLOSET
F2: MUEBLES SANTA FE SPA
F3: VENTAS POR MENOR DE MUEBLES
F4: RUT: 77.054.606-0
F5: SEPTIMA AVENIDA 1631, SAN MIGUEL
F6: FONO 22521 6502 | N6: 10077 SF PORTLAND MAPLE
F7: E-MAIL: ventas@topmobili.cl
B8: P R E S U P U E S T O | D8: N° 10935
K9: 56950
B10: CLIENTE: | C10: CONSTRUCTORA BAYO | F10: FECHA: | G10: 45408 | K10: =K9/1.19 -> 47857.143
B11: RUT: | F11: PLAZO ENTREGA: | G11: LICITACION | Q11: MT2 PUERTAS
B12: GIRO: | F12: SERVICIO EXPRESS | G12: NO
B13: CONTACTO: | C13: PAULO SALGADO | F13: PROYECTO: CONFUTURO
B14: CORREO: | F14: CORTADA A LA MEDIDA | G14: NO | Q14: ML CUBIERTAS
B15: FONO: | C15: +569 9744 8059 | F15: DESPACHO: | G15: NO
B16: DIRECCION: | F16: FORMA DE PAGO: | G16: ABONO 50%, SALDO C/E
B17: CIUDAD: | C17: SANTIAGO | F17: DURACION COTIZACION: 5 DIAS FERNANDO DONOSO
B19: , | L19: 0.02 | M19: 0.02 | O19: TOTAL | P19: VALOR X MT2 | Q19: ENCHAPE | R19: MT/L
B20: UNIDAD | C20: TIPO | D20: LARGO | E20: ANCHO | F20: COLOR | G20: VALOR | H20: TOTAL | K20: =B20 -> UNIDAD | L20: ALTO | M20: =E20 -> ANCHO | N20: MT | O20: MT2 | P20: =N44 -> 160665.66 | Q20: 30000 | S20: m/l
B21: 2 | C21: E/R 2 CARAS | D21: 2.28 | E21: 0.88 | F21: CARBON 2192 MT | G21: 362578 | H21: =G21*B21 -> 725156 | K21: =B21 -> 2 | L21: =D21+L$19 -> 2.3 | M21: =E21+M$19 -> 0.9 | N21: =L21*M21 -> 2.07 | O21: =N21*K21 -> 4.14 | P21: =P$20*N21 -> 332577.92 | Q21: =P21+Q$20 -> 362577.92 | R21: =K21*L21*2 -> 9.2 | S21: =K21*M21*2 -> 3.6
B22: 1 | C22: E/R 2 CARAS | D22: 2.28 | E22: 0.9 | F22: CARBON 2192 MT | G22: 369969 | H22: =G22*B22 -> 369969 | K22: =B22 -> 1 | L22: =D22+L$19 -> 2.3 | M22: =E22+M$19 -> 0.92 | N22: =L22*M22 -> 2.116 | O22: =N22*K22 -> 2.116 | P22: =P$20*N22 -> 339968.54 | Q22: =P22+Q$20 -> 369968.54 | R22: =K22*L22*2 -> 4.6 | S22: =K22*M22*2 -> 1.84
B23: 2 | C23: E/R 2 CARAS | D23: 2.28 | E23: 0.66 | F23: CARBON 2192 MT | G23: 281281 | H23: =G23*B23 -> 562562 | K23: =B23 -> 2 | L23: =D23+L$19 -> 2.3 | M23: =E23+M$19 -> 0.68 | N23: =L23*M23 -> 1.564 | O23: =N23*K23 -> 3.128 | P23: =P$20*N23 -> 251281.1 | Q23: =P23+Q$20 -> 281281.1 | R23: =K23*L23*2 -> 9.2 | S23: =K23*M23*2 -> 2.72
B24: 3 | C24: E/R 2 CARAS | D24: 2.28 | E24: 0.8 | F24: CARBON 2192 MT | G24: 333015 | H24: =G24*B24 -> 999045 | K24: =B24 -> 3 | L24: =D24+L$19 -> 2.3 | M24: =E24+M$19 -> 0.82 | N24: =L24*M24 -> 1.886 | O24: =N24*K24 -> 5.658 | P24: =P$20*N24 -> 303015.44 | Q24: =P24+Q$20 -> 333015.44 | R24: =K24*L24*2 -> 13.8 | S24: =K24*M24*2 -> 4.92
B25: 2 | C25: E/R 2 CARAS | D25: 2.28 | E25: 0.7 | F25: CARBON 2192 MT | G25: 296062 | H25: =G25*B25 -> 592124 | K25: =B25 -> 2 | L25: =D25+L$19 -> 2.3 | M25: =E25+M$19 -> 0.72 | N25: =L25*M25 -> 1.656 | O25: =N25*K25 -> 3.312 | P25: =P$20*N25 -> 266062.34 | Q25: =P25+Q$20 -> 296062.34 | R25: =K25*L25*2 -> 9.2 | S25: =K25*M25*2 -> 2.88
B26: 4 | C26: E/R 2 CARAS | D26: 2.28 | E26: 0.76 | F26: CARBON 2192 MT | G26: 318234 | H26: =G26*B26 -> 1272936 | K26: =B26 -> 4 | L26: =D26+L$19 -> 2.3 | M26: =E26+M$19 -> 0.78 | N26: =L26*M26 -> 1.794 | O26: =N26*K26 -> 7.176 | P26: =P$20*N26 -> 288234.2 | Q26: =P26+Q$20 -> 318234.2 | R26: =K26*L26*2 -> 18.4
B27: 6 | C27: E/R 2 CARAS | D27: 1.52 | E27: 0.45 | F27: CARBON 2192 MT | G27: 146290 | H27: =G27*B27 -> 877740 | K27: =B27 -> 6 | L27: =D27+L$19 -> 1.54 | M27: =E27+M$19 -> 0.47 | N27: =L27*M27 -> 0.7238 | O27: =N27*K27 -> 4.3428 | P27: =P$20*N27 -> 116289.81 | Q27: =P27+Q$20 -> 146289.81 | R27: =K27*L27*2 -> 18.48
F28: se
R29: =SUM(R21:R28) -> 82.88 | S29: =SUM(S21:S28) -> 15.96
G30: NETO | H30: =SUM(H21:H29) -> 5399532 | L30: =SUM(L21:L29) -> 15.34
G31: IVA | H31: =H30*0.19 -> 1025911.1 | O31: =SUM(O21:O26) -> 25.53 | R31: =R29+S29 -> 98.84
G32: TOTAL | H32: =H30+H31 -> 6425443.1 | O32: =O31 -> 25.53 | R32: =R31*20% -> 19.768
J33: 28 | O33: =O32*20% -> 5.106 | P33: 20% PERDIDA | R33: =R31+R32 -> 118.608
J34: 32 | O34: =O32+O33 -> 30.636 | R34: 40
J35: 8
J36: =SUM(J33:J35) -> 68 | L36: =O34*2 -> 61.272 | M36: 3500 | N36: =L36*M36 -> 214452 | O36: ADHESIVO | P36: TRASCARA ENCHAPADA, ES POR 2
L37: 10 | M37: 25000 | N37: =L37*M37 -> 250000 | O37: MDF25MM
M38: 20000 | N38: =L38*M38 -> 0 | O38: BALANCE
B39: CUENTA CORRIENTE BANCO SANTANDER Nº 87316181 A NOMBRE DE MUEBLES SANTA FE SPA | L39: 28 | M39: 50000 | N39: =L39*M39 -> 1400000 | O39: LAMINA 122X244
B40: RUT : 77.054.606-0 VENTAS@TOPMOBILI.CL | M40: 4000 | N40: =L40*M40 -> 0 | O40: PERNO SUJECION | Q40: 1.52
B41: VISITANOS Y DESCUBRE NUESTROS PRODUCTOS EN | F41: WWW.TOPMOBILICHILE.CL | M41: 1500 | N41: =L41*M41 -> 0 | O41: MEDIA CAÑA | Q41: 2.44 | S41: 1500
N42: =SUM(N36:N41) -> 1864452 | O42: COSTO | Q42: =Q40*Q41 -> 3.7088 | S42: =R34*S41 -> 60000
...

Sheet M.RECEPCION PISO 2
F2: MUEBLES SANTA FE SPA
F3: VENTAS POR MENOR DE MUEBLES
F4: RUT: 77.054.606-0
F5: SEPTIMA AVENIDA 1631, SAN MIGUEL
F6: FONO 22521 6502 | N6: 10077 SF PORTLAND MAPLE
F7: E-MAIL: ventas@topmobili.cl
B8: P R E S U P U E S T O | D8: N° 10935
K9: 56950
B10: CLIENTE: | C10: CONSTRUCTORA BAYO | F10: FECHA: | G10: 45408 | K10: =K9/1.19 -> 47857.143
B11: RUT: | F11: PLAZO ENTREGA: | G11: LICITACION | Q11: MT2 PUERTAS
B12: GIRO: | F12: SERVICIO EXPRESS | G12: NO
B13: CONTACTO: | C13: PAULO SALGADO | F13: PROYECTO: CONFUTURO
B14: CORREO: | F14: CORTADA A LA MEDIDA | G14: NO | Q14: ML CUBIERTAS
B15: FONO: | C15: +569 9744 8059 | F15: DESPACHO: | G15: NO
B16: DIRECCION: | F16: FORMA DE PAGO: | G16: ABONO 50%, SALDO C/E
B17: CIUDAD: | C17: SANTIAGO | F17: DURACION COTIZACION: 5 DIAS FERNANDO DONOSO
B19: , | L19: 0.02 | M19: 0.02 | O19: TOTAL | P19: VALOR X MT2 | Q19: ENCHAPE | R19: MT/L
B20: UNIDAD | C20: TIPO | D20: LARGO | E20: ANCHO | F20: COLOR | G20: VALOR | H20: TOTAL | K20: =B20 -> UNIDAD | L20: ALTO | M20: =E20 -> ANCHO | N20: MT | O20: MT2 | P20: =N42 -> 163784.95 | Q20: 20000 | S20: m/l
B21: 2 | C21: E/R 2 CARAS | D21: 0.94 | E21: 0.65 | F21: COLOR DEFENIR | G21: 125346 | H21: =G21*B21 -> 250692 | K21: =B21 -> 2 | L21: =D21+L$19 -> 0.96 | M21: =E21+M$19 -> 0.67 | N21: =L21*M21 -> 0.6432 | O21: =N21*K21 -> 1.2864 | P21: =P$20*N21 -> 105346.48 | Q21: =P21+Q$20 -> 125346.48 | R21: =K21*L21*2 -> 3.84 | S21: =K21*M21*2 -> 2.68
B22: 1 | C22: E/R 2 CARAS | D22: 1.4 | E22: 0.94 | F22: CARBON 2192 MT | G22: 243272 | H22: =G22*B22 -> 243272 | K22: =B22 -> 1 | L22: =D22+L$19 -> 1.42 | M22: =E22+M$19 -> 0.96 | N22: =L22*M22 -> 1.3632 | O22: =N22*K22 -> 1.3632 | P22: =P$20*N22 -> 223271.65 | Q22: =P22+Q$20 -> 243271.65 | R22: =K22*L22*2 -> 2.84 | S22: =K22*M22*2 -> 1.92
B23: 1 | C23: E/R 2 CARAS | D23: 0.96 | E23: 0.35 | F23: CARBON 2192 MT | H23: =G23*B23 -> 0 | L23: =D23+L$19 -> 0.98 | M23: =E23+M$19 -> 0.37 | N23: =L23*M23 -> 0.3626 | O23: =N23*K23 -> 0 | P23: =P$20*N23 -> 59388.423 | Q23: =P23+Q$20 -> 79388.423 | R23: =K23*L23*2 -> 0 | S23: =K23*M23*2 -> 0
B24: 1 | C24: E/R 2 CARAS | D24: 0.5 | E24: 0.35 | F24: CARBON 2192 MT | H24: =G24*B24 -> 0 | L24: =D24+L$19 -> 0.52 | M24: =E24+M$19 -> 0.37 | N24: =L24*M24 -> 0.1924 | O24: =N24*K24 -> 0 | P24: =P$20*N24 -> 31512.225 | Q24: =P24+Q$20 -> 51512.225 | R24: =K24*L24*2 -> 0 | S24: =K24*M24*2 -> 0
B25: 2 | C25: E/R 2 CARAS | D25: 1.44 | E25: 0.58 | F25: CARBON 2192 MT | H25: =G25*B25 -> 0 | L25: =D25+L$19 -> 1.46 | M25: =E25+M$19 -> 0.6 | N25: =L25*M25 -> 0.876 | O25: =N25*K25 -> 0 | P25: =P$20*N25 -> 143475.62 | Q25: =P25+Q$20 -> 163475.62 | R25: =K25*L25*2 -> 0 | S25: =K25*M25*2 -> 0
F26: se
R27: =SUM(R21:R26) -> 6.68 | S27: =SUM(S21:S26) -> 4.6
G28: NETO | H28: =SUM(H21:H27) -> 493964 | L28: =SUM(L21:L27) -> 5.34
G29: IVA | H29: =H28*0.19 -> 93853.16 | O29: =SUM(O21:O25) -> 2.6496 | R29: =R27+S27 -> 11.28
G30: TOTAL | H30: =H28+H29 -> 587817.16 | O30: =O29 -> 2.6496 | R30: =R29*20% -> 2.256
J31: 28 | O31: =O30*20% -> 0.52992 | P31: 20% PERDIDA | R31: =R29+R30 -> 13.536
J32: 32 | O32: =O30+O31 -> 3.17952 | R32: 40
J33: 8
J34: =SUM(J31:J33) -> 68 | L34: =O32*2 -> 6.35904 | M34: 3500 | N34: =L34*M34 -> 22256.64 | O34: ADHESIVO | P34: TRASCARA ENCHAPADA, ES POR 2
L35: 1 | M35: 25000 | N35: =L35*M35 -> 25000 | O35: MDF25MM
M36: 20000 | N36: =L36*M36 -> 0 | O36: BALANCE
B37: CUENTA CORRIENTE BANCO SANTANDER Nº 87316181 A NOMBRE DE MUEBLES SANTA FE SPA | L37: 3 | M37: 50000 | N37: =L37*M37 -> 150000 | O37: LAMINA 122X244
B38: RUT : 77.054.606-0 VENTAS@TOPMOBILI.CL | M38: 4000 | N38: =L38*M38 -> 0 | O38: PERNO SUJECION | Q38: 1.52
B39: VISITANOS Y DESCUBRE NUESTROS PRODUCTOS EN | F39: WWW.TOPMOBILICHILE.CL | M39: 1500 | N39: =L39*M39 -> 0 | O39: MEDIA CAÑA | Q39: 2.44 | S39: 1500
N40: =SUM(N34:N39) -> 197256.64 | O40: COSTO | Q40: =Q38*Q39 -> 3.7088 | S40: =R32*S39 -> 60000
J41: 49780 | L41: PRECIO VENTA | N41: =N40*2.2 -> 433964.61 | O41: FACTOR 2,3 PARA 90° | Q41: =O30/Q40 -> 0.71440897 | S41: =S40/#REF! -> #REF!
J42: =J41/1.19 -> 41831.933 | N42: =N41/O30 -> 163784.95 | O42: VALOR M2
...

Sheet TABIQUE
F2: MUEBLES SANTA FE SPA
F3: VENTAS POR MENOR DE MUEBLES
F4: RUT: 77.054.606-0
F5: SEPTIMA AVENIDA 1631, SAN MIGUEL
F6: FONO 22521 6502 | N6: 10077 SF PORTLAND MAPLE
F7: E-MAIL: ventas@topmobili.cl
B8: P R E S U P U E S T O | D8: N° 10935
K9: 56950
B10: CLIENTE: | C10: CONSTRUCTORA BAYO | F10: FECHA: | G10: 45408 | K10: =K9/1.19 -> 47857.143
B11: RUT: | F11: PLAZO ENTREGA: | G11: LICITACION | Q11: MT2 PUERTAS
B12: GIRO: | F12: SERVICIO EXPRESS | G12: NO
B13: CONTACTO: | C13: PAULO SALGADO | F13: PROYECTO: CONFUTURO
B14: CORREO: | F14: CORTADA A LA MEDIDA | G14: NO | Q14: ML CUBIERTAS
B15: FONO: | C15: +569 9744 8059 | F15: DESPACHO: | G15: NO
B16: DIRECCION: | F16: FORMA DE PAGO: | G16: ABONO 50%, SALDO C/E
B17: CIUDAD: | C17: SANTIAGO | F17: DURACION COTIZACION: 5 DIAS FERNANDO DONOSO
B19: , | L19: 0.02 | M19: 0.02 | O19: TOTAL | P19: VALOR X MT2 | Q19: ENCHAPE | R19: MT/L
B20: UNIDAD | C20: TIPO | D20: LARGO | E20: ANCHO | F20: COLOR | G20: VALOR | H20: TOTAL | K20: =B20 -> UNIDAD | L20: ALTO | M20: =E20 -> ANCHO | N20: MT | O20: MT2 | P20: =N42 -> 124305.79 | Q20: 5000 | S20: m/l
B21: 10 | C21: E/R 2 CARAS | D21: 2.4 | E21: 0.2 | F21: COLOR DEFENIR | G21: 71180 | H21: =G21*B21 -> 711800 | K21: =B21 -> 10 | L21: =D21+L$19 -> 2.42 | M21: =E21+M$19 -> 0.22 | N21: =L21*M21 -> 0.5324 | O21: =N21*K21 -> 5.324 | P21: =P$20*N21 -> 66180.4 | Q21: =P21+Q$20 -> 71180.4 | R21: =K21*L21*2 -> 48.4 | S21: =K21*M21*2 -> 4.4
B22: 6 | C22: E/R 2 CARAS | D22: 0.48 | E22: 0.35 | F22: CARBON 2192 MT | H22: =G22*B22 -> 0 | L22: =D22+L$19 -> 0.5 | M22: =E22+M$19 -> 0.37 | N22: =L22*M22 -> 0.185 | O22: =N22*K22 -> 0 | P22: =P$20*N22 -> 22996.57 | Q22: =P22+Q$20 -> 27996.57 | R22: =K22*L22*2 -> 0 | S22: =K22*M22*2 -> 0
B23: 1 | C23: E/R 2 CARAS | D23: 0.96 | E23: 0.35 | F23: CARBON 2192 MT | H23: =G23*B23 -> 0 | L23: =D23+L$19 -> 0.98 | M23: =E23+M$19 -> 0.37 | N23: =L23*M23 -> 0.3626 | O23: =N23*K23 -> 0 | P23: =P$20*N23 -> 45073.278 | Q23: =P23+Q$20 -> 50073.278 | R23: =K23*L23*2 -> 0 | S23: =K23*M23*2 -> 0
B24: 1 | C24: E/R 2 CARAS | D24: 0.5 | E24: 0.35 | F24: CARBON 2192 MT | H24: =G24*B24 -> 0 | L24: =D24+L$19 -> 0.52 | M24: =E24+M$19 -> 0.37 | N24: =L24*M24 -> 0.1924 | O24: =N24*K24 -> 0 | P24: =P$20*N24 -> 23916.433 | Q24: =P24+Q$20 -> 28916.433 | R24: =K24*L24*2 -> 0 | S24: =K24*M24*2 -> 0
B25: 2 | C25: E/R 2 CARAS | D25: 1.44 | E25: 0.58 | F25: CARBON 2192 MT | G25: 250000 | H25: =G25*B25 -> 500000 | L25: =D25+L$19 -> 1.46 | M25: =E25+M$19 -> 0.6 | N25: =L25*M25 -> 0.876 | O25: =N25*K25 -> 0 | P25: =P$20*N25 -> 108891.87 | Q25: =P25+Q$20 -> 113891.87 | R25: =K25*L25*2 -> 0 | S25: =K25*M25*2 -> 0
F26: se
R27: =SUM(R21:R26) -> 48.4 | S27: =SUM(S21:S26) -> 4.4
G28: NETO | H28: =SUM(H21:H27) -> 1211800 | L28: =SUM(L21:L27) -> 5.88
G29: IVA | H29: =H28*0.19 -> 230242 | O29: =SUM(O21:O25) -> 5.324 | R29: =R27+S27 -> 52.8
G30: TOTAL | H30: =H28+H29 -> 1442042 | O30: =O29 -> 5.324 | R30: =R29*20% -> 10.56
J31: 28 | O31: =O30*20% -> 1.0648 | P31: 20% PERDIDA | R31: =R29+R30 -> 63.36
J32: 32 | O32: =O30+O31 -> 6.3888 | R32: 40
J33: 8
J34: =SUM(J31:J33) -> 68 | L34: =O32*2 -> 12.7776 | M34: 3500 | N34: =L34*M34 -> 44721.6 | O34: ADHESIVO | P34: TRASCARA ENCHAPADA, ES POR 2
L35: 2 | M35: 30000 | N35: =L35*M35 -> 60000 | O35: MDF25MM
L36: 1 | M36: 20000 | N36: =L36*M36 -> 20000 | O36: PLETINA DE ACERO
B37: CUENTA CORRIENTE BANCO SANTANDER Nº 87316181 A NOMBRE DE MUEBLES SANTA FE SPA | L37: 2 | M37: 50000 | N37: =L37*M37 -> 100000 | O37: LAMINA 122X244
B38: RUT : 77.054.606-0 VENTAS@TOPMOBILI.CL | L38: 10 | M38: 4000 | N38: =L38*M38 -> 40000 | O38: PERNO SUJECION | Q38: 1.52
B39: VISITANOS Y DESCUBRE NUESTROS PRODUCTOS EN | F39: WWW.TOPMOBILICHILE.CL | M39: 1500 | N39: =L39*M39 -> 0 | O39: MEDIA CAÑA | Q39: 2.44 | S39: 1500
N40: =SUM(N34:N39) -> 264721.6 | O40: COSTO | Q40: =Q38*Q39 -> 3.7088 | S40: =R32*S39 -> 60000
J41: 49780 | L41: PRECIO VENTA | N41: =N40*2.5 -> 661804 | O41: FACTOR 2,3 PARA 90° | Q41: =O30/Q40 -> 1.4355047 | S41: =S40/#REF! -> #REF!
J42: =J41/1.19 -> 41831.933 | N42: =N41/O30 -> 124305.79 | O42: VALOR M2
...

Sheet SEPARADORES
F2: MUEBLES SANTA FE SPA
F3: VENTAS POR MENOR DE MUEBLES
F4: RUT: 77.054.606-0
F5: SEPTIMA AVENIDA 1631, SAN MIGUEL
F6: FONO 22521 6502 | N6: 10077 SF PORTLAND MAPLE
F7: E-MAIL: ventas@topmobili.cl
B8: P R E S U P U E S T O | D8: N° 10935
K9: 56950
B10: CLIENTE: | C10: CONSTRUCTORA BAYO | F10: FECHA: | G10: 45408 | K10: =K9/1.19 -> 47857.143
B11: RUT: | F11: PLAZO ENTREGA: | G11: LICITACION | Q11: MT2 PUERTAS
B12: GIRO: | F12: SERVICIO EXPRESS | G12: NO
B13: CONTACTO: | C13: PAULO SALGADO | F13: PROYECTO: CONFUTURO
B14: CORREO: | F14: CORTADA A LA MEDIDA | G14: NO | Q14: ML CUBIERTAS
B15: FONO: | C15: +569 9744 8059 | F15: DESPACHO: | G15: NO
B16: DIRECCION: | F16: FORMA DE PAGO: | G16: ABONO 50%, SALDO C/E
B17: CIUDAD: | C17: SANTIAGO | F17: DURACION COTIZACION: 5 DIAS FERNANDO DONOSO
B19: , | L19: 0.02 | M19: 0.02 | O19: TOTAL | P19: VALOR X MT2 | Q19: ENCHAPE | R19: MT/L
B20: UNIDAD | C20: TIPO | D20: LARGO | E20: ANCHO | F20: COLOR | G20: VALOR | H20: TOTAL | K20: =B20 -> UNIDAD | L20: ALTO | M20: =E20 -> ANCHO | N20: MT | O20: MT2 | P20: =N42 -> 108388.53 | Q20: 5000 | S20: m/l
B21: 6 | C21: E/R 2 CARAS | D21: 1.5 | E21: 0.35 | F21: CARBON 2192 MT | G21: 65958 | H21: =G21*B21 -> 395748 | K21: =B21 -> 6 | L21: =D21+L$19 -> 1.52 | M21: =E21+M$19 -> 0.37 | N21: =L21*M21 -> 0.5624 | O21: =N21*K21 -> 3.3744 | P21: =P$20*N21 -> 60957.708 | Q21: =P21+Q$20 -> 65957.708 | R21: =K21*L21*2 -> 18.24 | S21: =K21*M21*2 -> 4.44
B22: 6 | C22: E/R 2 CARAS | D22: 0.48 | E22: 0.35 | F22: CARBON 2192 MT | G22: 25052 | H22: =G22*B22 -> 150312 | K22: =B22 -> 6 | L22: =D22+L$19 -> 0.5 | M22: =E22+M$19 -> 0.37 | N22: =L22*M22 -> 0.185 | O22: =N22*K22 -> 1.11 | P22: =P$20*N22 -> 20051.878 | Q22: =P22+Q$20 -> 25051.878 | R22: =K22*L22*2 -> 6 | S22: =K22*M22*2 -> 4.44
B23: 1 | C23: E/R 2 CARAS | D23: 0.96 | E23: 0.35 | F23: CARBON 2192 MT | G23: 44302 | H23: =G23*B23 -> 44302 | K23: =B23 -> 1 | L23: =D23+L$19 -> 0.98 | M23: =E23+M$19 -> 0.37 | N23: =L23*M23 -> 0.3626 | O23: =N23*K23 -> 0.3626 | P23: =P$20*N23 -> 39301.68 | Q23: =P23+Q$20 -> 44301.68 | R23: =K23*L23*2 -> 1.96 | S23: =K23*M23*2 -> 0.74
B24: 1 | C24: E/R 2 CARAS | D24: 0.5 | E24: 0.35 | F24: CARBON 2192 MT | G24: 25854 | H24: =G24*B24 -> 25854 | K24: =B24 -> 1 | L24: =D24+L$19 -> 0.52 | M24: =E24+M$19 -> 0.37 | N24: =L24*M24 -> 0.1924 | O24: =N24*K24 -> 0.1924 | P24: =P$20*N24 -> 20853.953 | Q24: =P24+Q$20 -> 25853.953 | R24: =K24*L24*2 -> 1.04 | S24: =K24*M24*2 -> 0.74
B25: 2 | C25: E/R 2 CARAS | D25: 1.44 | E25: 0.58 | F25: CARBON 2192 MT | G25: 99948 | H25: =G25*B25 -> 199896 | K25: =B25 -> 2 | L25: =D25+L$19 -> 1.46 | M25: =E25+M$19 -> 0.6 | N25: =L25*M25 -> 0.876 | O25: =N25*K25 -> 1.752 | P25: =P$20*N25 -> 94948.35 | Q25: =P25+Q$20 -> 99948.35 | R25: =K25*L25*2 -> 5.84 | S25: =K25*M25*2 -> 2.4
F26: se
R27: =SUM(R21:R26) -> 33.08 | S27: =SUM(S21:S26) -> 12.76
G28: NETO | H28: =SUM(H21:H27) -> 816112 | L28: =SUM(L21:L27) -> 4.98
G29: IVA | H29: =H28*0.19 -> 155061.28 | O29: =SUM(O21:O25) -> 6.7914 | R29: =R27+S27 -> 45.84
G30: TOTAL | H30: =H28+H29 -> 971173.28 | O30: =O29 -> 6.7914 | R30: =R29*20% -> 9.168
J31: 28 | O31: =O30*20% -> 1.35828 | P31: 20% PERDIDA | R31: =R29+R30 -> 55.008
J32: 32 | O32: =O30+O31 -> 8.14968 | R32: 40
J33: 8
J34: =SUM(J31:J33) -> 68 | L34: =O32*2 -> 16.29936 | M34: 3500 | N34: =L34*M34 -> 57047.76 | O34: ADHESIVO | P34: TRASCARA ENCHAPADA, ES POR 2
L35: 2 | M35: 25000 | N35: =L35*M35 -> 50000 | O35: MDF25MM
L36: 60 | M36: 750 | N36: =L36*M36 -> 45000 | O36: TAPACANTO PVC 2MM
B37: CUENTA CORRIENTE BANCO SANTANDER Nº 87316181 A NOMBRE DE MUEBLES SANTA FE SPA | L37: 4 | M37: 42000 | N37: =L37*M37 -> 168000 | O37: LAMINA 122X244
B38: RUT : 77.054.606-0 VENTAS@TOPMOBILI.CL | M38: 800 | N38: =L38*M38 -> 0 | O38: RESPALDO | Q38: 1.52
B39: VISITANOS Y DESCUBRE NUESTROS PRODUCTOS EN | F39: WWW.TOPMOBILICHILE.CL | M39: 1500 | N39: =L39*M39 -> 0 | O39: MEDIA CAÑA | Q39: 2.44 | S39: 1500
N40: =SUM(N34:N39) -> 320047.76 | O40: COSTO | Q40: =Q38*Q39 -> 3.7088 | S40: =R32*S39 -> 60000
J41: 49780 | L41: PRECIO VENTA | N41: =N40*2.3 -> 736109.85 | O41: FACTOR 2,3 PARA 90° | Q41: =O30/Q40 -> 1.8311583 | S41: =S40/#REF! -> #REF!
J42: =J41/1.19 -> 41831.933 | N42: =N41/O30 -> 108388.53 | O42: VALOR M2
...

Sheet LOCKERS
F2: MUEBLES SANTA FE SPA
F3: VENTAS POR MENOR DE MUEBLES
F4: RUT: 77.054.606-0
F5: SEPTIMA AVENIDA 1631, SAN MIGUEL
F6: FONO 22521 6502 | N6: 10077 SF PORTLAND MAPLE
F7: E-MAIL: ventas@topmobili.cl
B8: P R E S U P U E S T O | D8: N° 10935
K9: 56950
B10: CLIENTE: | C10: CONSTRUCTORA BAYO | F10: FECHA: | G10: 45408 | K10: =K9/1.19 -> 47857.143
B11: RUT: | F11: PLAZO ENTREGA: | G11: LICITACION | Q11: MT2 PUERTAS
B12: GIRO: | F12: SERVICIO EXPRESS | G12: NO
B13: CONTACTO: | C13: PAULO SALGADO | F13: PROYECTO: CONFUTURO
B14: CORREO: | F14: CORTADA A LA MEDIDA | G14: NO | Q14: ML CUBIERTAS
B15: FONO: | C15: +569 9744 8059 | F15: DESPACHO: | G15: NO
B16: DIRECCION: | F16: FORMA DE PAGO: | G16: ABONO 50%, SALDO C/E
B17: CIUDAD: | C17: SANTIAGO | F17: DURACION COTIZACION: 5 DIAS FERNANDO DONOSO
B19: , | L19: 0.02 | M19: 0.02 | O19: TOTAL | P19: VALOR X MT2 | Q19: ENCHAPE | R19: MT/L
B20: UNIDAD | C20: TIPO | D20: LARGO | E20: ANCHO | F20: COLOR | G20: VALOR | H20: TOTAL | K20: =B20 -> UNIDAD | L20: ALTO | M20: =E20 -> ANCHO | N20: MT | O20: MT2 | P20: =N42 -> 78727.786 | Q20: 5000 | S20: m/l
B21: 28 | C21: E/R 2 CARAS | D21: 0.38 | E21: 0.35 | F21: COLOR X DEFINIR | G21: 16652 | H21: =G21*B21 -> 466256 | K21: =B21 -> 28 | L21: =D21+L$19 -> 0.4 | M21: =E21+M$19 -> 0.37 | N21: =L21*M21 -> 0.148 | O21: =N21*K21 -> 4.144 | P21: =P$20*N21 -> 11651.712 | Q21: =P21+Q$20 -> 16651.712 | R21: =K21*L21*2 -> 22.4 | S21: =K21*M21*2 -> 20.72
B22: 7 | C22: E/R 2 CARAS | D22: 0.76 | E22: 0.35 | F22: COLOR X DEFINIR | G22: 27721 | H22: =G22*B22 -> 194047 | K22: =B22 -> 7 | L22: =D22+L$19 -> 0.78 | M22: =E22+M$19 -> 0.37 | N22: =L22*M22 -> 0.2886 | O22: =N22*K22 -> 2.0202 | P22: =P$20*N22 -> 22720.839 | Q22: =P22+Q$20 -> 27720.839 | R22: =K22*L22*2 -> 10.92 | S22: =K22*M22*2 -> 5.18
B23: 32 | C23: E/R 2 CARAS | D23: 0.38 | E23: 0.35 | F23: COLOR X DEFINIR | G23: 16652 | H23: =G23*B23 -> 532864 | K23: =B23 -> 32 | L23: =D23+L$19 -> 0.4 | M23: =E23+M$19 -> 0.37 | N23: =L23*M23 -> 0.148 | O23: =N23*K23 -> 4.736 | P23: =P$20*N23 -> 11651.712 | Q23: =P23+Q$20 -> 16651.712 | R23: =K23*L23*2 -> 25.6 | S23: =K23*M23*2 -> 23.68
B24: 8 | C24: E/R 2 CARAS | D24: 0.76 | E24: 0.35 | F24: COLOR X DEFINIR | G24: 27721 | H24: =G24*B24 -> 221768 | K24: =B24 -> 8 | L24: =D24+L$19 -> 0.78 | M24: =E24+M$19 -> 0.37 | N24: =L24*M24 -> 0.2886 | O24: =N24*K24 -> 2.3088 | P24: =P$20*N24 -> 22720.839 | Q24: =P24+Q$20 -> 27720.839 | R24: =K24*L24*2 -> 12.48 | S24: =K24*M24*2 -> 5.92
B25: 4 | C25: E/R 2 CARAS | D25: 2.3 | E25: 0.58 | F25: COLOR X DEFINIR | G25: 114589 | H25: =G25*B25 -> 458356 | K25: =B25 -> 4 | L25: =D25+L$19 -> 2.32 | M25: =E25+M$19 -> 0.6 | N25: =L25*M25 -> 1.392 | O25: =N25*K25 -> 5.568 | P25: =P$20*N25 -> 109589.08 | Q25: =P25+Q$20 -> 114589.08 | R25: =K25*L25*2 -> 18.56 | S25: =K25*M25*2 -> 4.8
R27: =SUM(R21:R26) -> 89.96 | S27: =SUM(S21:S26) -> 60.3
G28: NETO | H28: =SUM(H21:H27) -> 1873291 | L28: =SUM(L21:L27) -> 4.68
G29: IVA | H29: =H28*0.19 -> 355925.29 | O29: =SUM(O21:O25) -> 18.777 | R29: =R27+S27 -> 150.26
G30: TOTAL | H30: =H28+H29 -> 2229216.3 | O30: =O29 -> 18.777 | R30: =R29*20% -> 30.052
J31: 28 | O31: =O30*20% -> 3.7554 | P31: 20% PERDIDA | R31: =R29+R30 -> 180.312
J32: 32 | O32: =O30+O31 -> 22.5324 | R32: 40
J33: 8
J34: =SUM(J31:J33) -> 68 | L34: =O32*2 -> 45.0648 | M34: 3500 | N34: =L34*M34 -> 157726.8 | O34: ADHESIVO | P34: TRASCARA ENCHAPADA, ES POR 2
L35: 5 | M35: 25000 | N35: =L35*M35 -> 125000 | O35: MDF25MM
L36: 200 | M36: 750 | N36: =L36*M36 -> 150000 | O36: TAPACANTO PVC 2MM
B37: CUENTA CORRIENTE BANCO SANTANDER Nº 87316181 A NOMBRE DE MUEBLES SANTA FE SPA | L37: 5 | M37: 42000 | N37: =L37*M37 -> 210000 | O37: LAMINA 122X244
B38: RUT : 77.054.606-0 VENTAS@TOPMOBILI.CL | M38: 800 | N38: =L38*M38 -> 0 | O38: RESPALDO | Q38: 1.52
B39: VISITANOS Y DESCUBRE NUESTROS PRODUCTOS EN | F39: WWW.TOPMOBILICHILE.CL | M39: 1500 | N39: =L39*M39 -> 0 | O39: MEDIA CAÑA | Q39: 2.44 | S39: 1500
N40: =SUM(N34:N39) -> 642726.8 | O40: COSTO | Q40: =Q38*Q39 -> 3.7088 | S40: =R32*S39 -> 60000
J41: 49780 | L41: PRECIO VENTA | N41: =N40*2.3 -> 1478271.6 | O41: FACTOR 2,3 PARA 90° | Q41: =O30/Q40 -> 5.0628236 | S41: =S40/#REF! -> #REF!
J42: =J41/1.19 -> 41831.933 | N42: =N41/O30 -> 78727.786 | O42: VALOR M2
N43: =N41/N40 -> 2.3
...

Sheet COSTOS
B2: CENTRO DE COSTOS POSTFORMADOS
B5: FECHA: | C5: =LOCKERS!G10 -> 45408
B6: CLIENTE: | C6: =LOCKERS!C10 -> CONSTRUCTORA BAYO | N6: Ventas Equilibrio = | P6: Costos Fijos Totales
B7: DIRECCION: | C7: =LOCKERS!#REF! -> #REF! | H7: COSTOS INDIRECTOS DE FABRICA VARIABLES | O7: 1 - | P7: Costos Variables Totales
B8: PRESUPUESTO: | C8: =LOCKERS!D8 -> N° 10935 | H8: Q/HRS | I8: $ | J8: DETALLE | K8: TOTAL | L8: TOTAL | P8: Total Venta | X8: =SUM(Q11:Q16) -> 6
H9: CANTIDAD | I9: PRECIO | J9: MATERIA PRIMA INDIRECTA | L9: =SUM(K10:K23) -> 2550 | S9: DETALLE | X9: =(E15-D11)/X8 -> -185010.92
D10: NETO | E10: IVA | F10: TOTAL | H10: 3 | I10: 350 | J10: RESPALDO | K10: =I10*H10 -> 1050 | Q10: UNIDAD | R10: TIPO | S10: LARGO | T10: ANCHO | U10: COLOR | V10: VALOR | W10: TOTAL
C11: MONTO A COBRAR | D11: =LOCKERS!H28 -> 1873291 | E11: =D11*0.19 -> 355925.29 | F11: =E11+D11 -> 2229216.3 | H11: 3 | I11: 500 | J11: MEDIA CAÑA | K11: =I11*H11 -> 1500 | Q11: 1 | R11: CUB C/R R8 | S11: 2.8 | T11: 0.62 | U11: MADERA X DEFINIR | V11: 105990 | W11: =V11*Q11 -> 105990 | X11: =V11+$X$9 -> -79020.922 | Y11: 108990
C12: COSTO TOTAL | D12: =SUM(M43:M45) -> 462560.89 | H12: 0 | I12: 7500 | J12: DUROLAC | K12: =I12*H12 -> 0 | Q12: 1 | R12: CUB C/R R8 | S12: 2.3 | T12: 0.62 | U12: MADERA X DEFINIR | V12: 87990 | W12: =V12*Q12 -> 87990 | X12: =V12+$X$9 -> -97020.922 | Y12: 89990
C13: % UTILIDAD | D13: =D11-D12 -> 1410730.1 | E13: =(D11/D12)-1 -> 3.0498257 | H13: 0 | I13: 50 | J13: TAPACANTO PVC | K13: =I13*H13 -> 0 | Q13: 1 | R13: CUB C/R R8 | S13: 2.03 | T13: 0.62 | U13: MADERA X DEFINIR | V13: 78990 | W13: =V13*Q13 -> 78990 | X13: =V13+$X$9 -> -106020.92 | Y13: 81990
D14: % utilidad | E14: NETO | F14: UTILIDAD | H14: 0 | I14: 50 | J14: SOBERBIOS | K14: =I14*H14 -> 0 | Q14: 1 | R14: CUB C/R R8 | S14: 1.08 | T14: 0.62 | U14: MADERA X DEFINIR | V14: 39990 | W14: =V14*Q14 -> 39990 | X14: =V14+$X$9 -> -145020.92 | Y14: 39990
C15: PROYECCION | D15: 0.65 | E15: =(100%+D15)*D12 -> 763225.47 | F15: =E15-D12 -> 300664.58 | H15: 0 | I15: 10 | J15: SOPORTE REPISA | K15: =I15*H15 -> 0 | Q15: 1 | R15: CUB C/R R8 | S15: 1.08 | T15: 0.62 | U15: MADERA X DEFINIR | V15: 39990 | W15: =V15*Q15 -> 39990 | X15: =V15+$X$9 -> -145020.92 | Y15: 39990
H16: 1 | J16: PUNTAS | K16: =I16*H16 -> 0 | Q16: 1 | R16: CUB C/R R8 | S16: 2.06 | T16: 0.62 | U16: MADERA X DEFINIR | V16: 79990 | W16: =V16*Q16 -> 79990 | X16: =V16+$X$9 -> -105020.92 | Y16: 83990
B17: M. PRIMA | C17: MATERIAL | D17: NETO | E17: IVA | F17: TOTAL | H17: 1 | J17: TORNILLOS | K17: =I17*H17 -> 0 | Q17: 6 | R17: CORTES 45° | V17: 5000 | W17: =V17*Q17 -> 30000
C18: LAMINA | D18: =LOCKERS!N36 -> 150000 | E18: =D18*0.19 -> 28500 | F18: =SUM(D18:E18) -> 178500 | H18: 1 | J18: COLAFRIA | K18: =I18*H18 -> 0 | Q18: 1 | R18: PERFORACION LAVAPLATOS | V18: 10000 | W18: =V18*Q18 -> 10000
C19: MDF 18MM | D19: =LOCKERS!N35 -> 125000 | E19: =D19*0.19 -> 23750 | F19: =SUM(D19:E19) -> 148750 | H19: 1 | J19: LIJAS | K19: =I19*H19 -> 0 | V19: NETO | W19: =SUM(W11:W18) -> 472940 | Y19: =SUM(Y11:Y16)+SUM(W17:W18) -> 484940
C20: ADHESIVO | D20: =LOCKERS!N34 -> 157726.8 | E20: =D20*0.19 -> 29968.092 | F20: =SUM(D20:E20) -> 187694.89 | H20: 1 | J20: CARTON | K20: =I20*H20 -> 0 | V20: I.V.A. | W20: =W19*19% -> 89858.6 | Y20: =Y19*0.19 -> 92138.6
A21: =450000*1.2 -> 540000 | C21: TOTAL | D21: =SUM(D18:D20) -> 432726.8 | E21: =SUM(E18:E20) -> 82218.092 | F21: =SUM(F18:F20) -> 514944.89 | H21: 1 | J21: GUAIPE | K21: =I21*H21 -> 0 | M21: =B32/9 -> 2318.8406 | Q21: PLAZO DE ENTREGA : 8 DIAS HABILES | V21: TOTAL | W21: =W19+W20 -> 562798.6 | Y21: =SUM(Y19:Y20) -> 577078.6
A22: =450000*1.2 -> 540000 | B22: M. DE OBRA | C22: PROCESO | D22: COSTO x Hr. | E22: Q Hrs. | F22: TOTAL | H22: 1 | J22: DILUYENTE | K22: =I22*H22 -> 0 | Q22: FORMA DE PAGO: 50% CONTADO, SALDO C/E
A23: =800000*1.2 -> 960000 | B23: =A21/23 -> 23478.261 | C23: CORTE | D23: =B23/9 -> 2608.6957 | E23: 0.5 | F23: =D23*E23 -> 1304.3478 | H23: 1 | J23: CINTA EMBALAJE | K23: =I23*H23 -> 0 | Q23: VALIDEZ COTIZACIÓN: 5 DIAS
A24: 450000 | B24: =A22/23 -> 23478.261 | C24: CORTE LAMINA | D24: =B24/9 -> 2608.6957 | E24: 0.5 | F24: =D24*E24 -> 1304.3478 | H24: Q/HRS | I24: PRECIO | J24: MANO DE OBRA INDIRECTA | K24: VALOR | L24: =SUM(K25:K35) -> 0
A25: 450000 | B25: =A23/23 -> 41739.13 | C25: REBAJE LAMINA | D25: =B25/9 -> 4637.6812 | F25: =D25*E25 -> 0 | H25: 0 | I25: =((480000/23)/9) -> 2318.8406 | J25: FLETERO (HRS) | K25: =H25*I25 -> 0
B26: =A24/23 -> 19565.217 | C26: TUPIZADO | D26: =B26/9 -> 2173.913 | E26: 0.5 | F26: =D26*E26 -> 1086.9565 | H26: 0 | J26: BENCINA | K26: =H26*I26 -> 0
A27: 350000 | B27: =A25/23 -> 19565.217 | C27: ARMADO | D27: =B27/9 -> 2173.913 | E27: 0.5 | F27: =D27*E27 -> 1086.9565 | H27: 0 | J27: TAG | K27: =H27*I27 -> 0
A28: 500000 | B28: =A27/23 -> 15217.391 | C28: PEGADO | D28: =B28/9 -> 1690.8213 | E28: 0.7 | F28: =D28*E28 -> 1183.5749 | H28: 0 | J28: RECTIFICACION | K28: =H28*I28 -> 0
B29: =A28/23 -> 21739.13 | C29: POSTFORMADO | D29: =B29/9 -> 2415.4589 | E29: 0.7 | F29: =D29*E29 -> 1690.8213 | H29: 0 | I29: =((550000*1.2)/23)/9 -> 3188.4058 | J29: HR. TRAB. JUAN | K29: =H29*I29 -> 0
A30: 450000 | C30: MEDIA CAÑA | D30: 2415 | F30: =D30*E30 -> 0 | H30: 0 | I30: =((450000*1.2)/23)/9 -> 2608.6957 | J30: HR. TRAB. JULIO | K30: =H30*I30 -> 0
A31: 350000 | B31: =A30/23 -> 19565.217 | C31: CORTE-ENCHAPE | D31: =B31/9 -> 2173.913 | E31: 0 | F31: =D31*E31 -> 0 | H31: 0 | I31: =((450000*1.2)/23)/9 -> 2608.6957 | J31: HR. TRAB. EUGE | K31: =H31*I31 -> 0
A32: =A21+A24+A27+A28+A30 -> 2290000 | B32: =480000/23 -> 20869.565 | C32: CONTROL CALIDAD | D32: =B32/9 -> 2318.8406 | E32: 0.5 | F32: =D32*E32 -> 1159.4203 | H32: 0 | J32: COLACION | K32: =H32*I32 -> 0
C33: TOTAL | D33: =SUM(D23:D32) -> 25216.932 | E33: =SUM(E23:E32) -> 3.9 | F33: =SUM(F23:F32) -> 8816.4251 | H33: 0 | J33: BONO | K33: =H33*I33 -> 0
B34: CIF | C34: M. PRIMA INDIREC. | D34: =L9 -> 2550 | H34: 1 | J34: PERFORACION | K34: =H34*I34 -> 0
C35: M. OBRA INDIRECTA | D35: =L24 -> 0 | H35: 6 | J35: CORTE 45 | K35: =H35*I35 -> 0
C36: GASTOS DE FABRICA | D36: =L36 -> 18467.666 | H36: CANTIDAD | I36: PRECIO | J36: GASTOS DE FABRICACION | K36: VALOR | L36: =SUM(K37:K39) -> 18467.666
C37: DEPRECIACIONES | H37: =$E$33 -> 3.9 | I37: =32609.69/9 -> 3623.2989 | J37: ARRIENDO x HORA | K37: =I37*H37 -> 14130.866
C38: TOTAL | D38: =SUM(D34:D37) -> 21017.666 | H38: =$E$33 -> 3.9 | I38: 967 | J38: AGUA x HORA | K38: =I38*H38 -> 3771.3
H39: =$E$33 -> 3.9 | I39: 145 | J39: LUZ x HORA | K39: =I39*H39 -> 565.5
B40: PROVISIONAR | C40: IVA | D40: =E11-E21 -> 273707.2
H41: ESTADO DE RESULTADOS
B42: TOTAL HRS TRABAJADAS | D42: =E33 -> 3.9 | H42: INGRESOS | I42: + TOTAL VENTA | M42: =D11 -> 1873291
H43: COSTOS | I43: - MATERIA PRIMA DIRECTA | M43: =D21 -> 432726.8
...
