Workbook

Sheet 2229
F2: MUEBLES SANTA FE SPA
F3: VENTAS POR MENOR DE MUEBLES
F4: RUT: 77.054.606-0
F5: SEPTIMA AVENIDA 1631, SAN MIGUEL
F6: FONO +569 2032 3382 | O6: 10077 SF PORTLAND MAPLE
F7: E-MAIL: ventas@topmobili.cl
B8: P R E S U P U E S T O | D8: N° 11882
B10: NOMBRE: | C10: MARIO ZAPATA | F10: FECHA | G10: 46063
B11: RUT: | F11: PLAZO ENTREGA | G11: 5 DIAS HABILES | R11: MT2 PUERTAS
B12: GIRO: | F12: SERVICIO EXPRESS | G12: NO
B13: CONTACTO: | F13: CORTADA A LA MEDIDA | G13: NO
B14: CORREO: | F14: DESPACHO | G14: NO | R14: ML CUBIERTAS
B15: FONO: | C15: +569 4510 6187 | F15: INSTALACIÓN | G15: NO
B16: DIRECCION: | F16: FORMA DE PAGO: | G16: ABONO 50% SALDO C/ENTREGA
B17: CIUDAD: | C17: SANTIAGO | F17: Duración cotización 5 días hábiles | G17: Cotizado por: Franco Donoso
B19: DETALLE | M19: 0.05 | P19: TOTAL | Q19: VALOR X MT2 | R19: ENCHAPE | S19: MT/L
B20: UNIDAD | C20: TIPO | D20: LARGO | E20: ANCHO | F20: COLOR | G20: VALOR | H20: TOTAL | L20: =B20 -> UNIDAD | M20: ALTO | N20: =E20 -> ANCHO | O20: MT | P20: MT2 | Q20: =O37 -> 65853.333 | R20: 3000 | T20: m/l
B21: 1 | C21: CUB C/R 90° | D21: 1.45 | E21: 0.5 | F21: COLOR MADERA CAFÉ STOCK | G21: =Q21 -> 49390 | H21: =G21*B21 -> 49390 | L21: =B21 -> 1 | M21: =D21+M$19 -> 1.5 | N21: =E21+$N$19 -> 0.5 | O21: =M21*N21 -> 0.75 | P21: =O21*L21 -> 0.75 | Q21: =Q$20*O21 -> 49390 | R21: =Q21+R$20 -> 52390 | S21: =M21*L21 -> 1.5 | T21: =N21*2*L21*2 -> 2
G23: NETO | H23: =SUM(H21:H21) -> 49390 | T23: =SUM(T21:T22) -> 2
G24: IVA | H24: =H23*0.19 -> 9384.1 | M24: =SUM(M22:M23) -> 0 | P24: =SUM(P21:P21) -> 0.75
G25: TOTAL | H25: =H24+H23 -> 58774.1 | P25: =P24 -> 0.75 | S25: =SUM(S21:S24) -> 1.5
P26: =P25*20% -> 0.15 | Q26: 20% PERDIDA | S26: =S25+T23 -> 3.5
P27: =P25+P26 -> 0.9 | S27: =S26*20% -> 0.7
S28: =S26+S27 -> 4.2 | U28: ADHESIVO | V28: 58.000.- | W28: 44971
M29: =P27 -> 0.9 | N29: 3500 | O29: =M29*N29 -> 3150 | P29: ADHESIVO | U29: LATA 16 LTS | V29: 3625 | W29: LITRO
M30: 0.3 | N30: 23500 | O30: =M30*N30 -> 7050 | P30: MDF 18MM | V30: 906.25 | W30: MT2 (4)
B31: CUENTA CORRIENTE BANCO SANTANDER Nº 87316181 A NOMBRE DE MUEBLES SANTA FE SPA | N31: 58860 | O31: =M31*N31 -> 0 | P31: LAMINA 153 X 366 | V31: =V30*20% -> 181.25 | W31: PERDIDA 20%
B32: RUT : 77.054.606-0 CORREO: FRANCODONOSO@TOPMOBILI.CL | M32: 0.5 | N32: 20000 | O32: =M32*N32 -> 10000 | P32: LAMINA 122X244 | V32: =V30+V31 -> 1087.5 | W32: MINIMO A COTIZAR
A33: GE | B33: VISITANOS Y DESCUBRE NUESTROS PRODUCTOS EN | F33: WWW.TOPMOBILICHILE.CL | N33: 900 | O33: =M33*N33 -> 0 | P33: RESPALDO | R33: 1.52
M34: 1.5 | N34: 1500 | O34: =M34*N34 -> 2250 | P34: MEDIA CAÑA | R34: 2.44
O35: =SUM(O29:O34) -> 22450 | P35: COSTO | R35: =R33*R34 -> 3.7088
M36: PRECIO VENTA | O36: =O35*2.2 -> 49390 | P36: FACTOR 2,3 PARA 90° | R36: =P27/R35 -> 0.24266609
K37: 70970 | O37: =O36/P25 -> 65853.333 | P37: VALOR M2 | U37: MDF30MM | V37: 43650
K38: =K37/1.19 -> 59638.655 | O38: =O36/O35 -> 2.2 | U38: 46 UNIDADES | V38: 948.91 | W38: 2.4
U39: METRO LINEAL | V39: 395.37
U40: PERDIDA 20% | V40: 474.45
O47: 40935 | P47: MT2 | Q47: TERMO WOOD
C72: ,,,,,,,,,,,,,,,,,,,,,,,,,,,,,,,,,,,,,,,,,,,,,,,,,,,,,,,,,,,,,,,,,,,,,,,,,,,,,,,,,,,,,,,,,,,,,,,,,,,,,,,,,,,,,,,,,,,,,,,,,,,,,,,,,,,,,,,,,,,,,,,,,,,,,,,,,,,,,,,,,,,,,,,,,,,,,,,,,,,,,,,,,,,,,,,,,,,,,,,,,,,,,,,,,,,,,,,,,,,,,,,,,,,,,,,,,,,,,,,,,,,,,,,,,,,,,,,,,,,,,
C73: ,
C76: ,
...

Sheet COSTOS
B2: CENTRO DE COSTOS POSTFORMADOS
B5: FECHA: | C5: ='2229'!G10 -> 46063
B6: CLIENTE: | C6: ='2229'!C10 -> MARIO ZAPATA | N6: Ventas Equilibrio = | P6: Costos Fijos Totales
B7: DIRECCION: | C7: ='2229'!#REF! -> #REF! | H7: COSTOS INDIRECTOS DE FABRICA VARIABLES | O7: 1 - | P7: Costos Variables Totales
B8: PRESUPUESTO: | C8: ='2229'!D8 -> N° 11882 | H8: Q/HRS | I8: $ | J8: DETALLE | K8: TOTAL | L8: TOTAL | P8: Total Venta | X8: =SUM(Q11:Q16) -> 6
H9: CANTIDAD | I9: PRECIO | J9: MATERIA PRIMA INDIRECTA | L9: =SUM(K10:K24) -> 2550 | S9: DETALLE | X9: =(E15-D11)/X8 -> 5527.7083
D10: NETO | E10: IVA | F10: TOTAL | H10: 3 | I10: 350 | J10: RESPALDO | K10: =I10*H10 -> 1050 | Q10: UNIDAD | R10: TIPO | S10: LARGO | T10: ANCHO | U10: COLOR | V10: VALOR | W10: TOTAL
C11: MONTO A COBRAR | D11: ='2229'!H23 -> 49390 | E11: =D11*0.19 -> 9384.1 | F11: =E11+D11 -> 58774.1 | H11: 3 | I11: 500 | J11: MEDIA CAÑA | K11: =I11*H11 -> 1500 | Q11: 1 | R11: CUB C/R R8 | S11: 2.8 | T11: 0.62 | U11: MADERA X DEFINIR | V11: 105990 | W11: =V11*Q11 -> 105990 | X11: =V11+$X$9 -> 111517.71 | Y11: 108990
C12: COSTO TOTAL | D12: =SUM(M44:M46) -> 50034.091 | H12: 0 | I12: 7500 | J12: DUROLAC | K12: =I12*H12 -> 0 | Q12: 1 | R12: CUB C/R R8 | S12: 2.3 | T12: 0.62 | U12: MADERA X DEFINIR | V12: 87990 | W12: =V12*Q12 -> 87990 | X12: =V12+$X$9 -> 93517.708 | Y12: 89990
C13: % UTILIDAD | D13: =D11-D12 -> -644.09079 | E13: =(D11/D12)-1 -> -0.012873039 | H13: 0 | I13: 50 | J13: TAPACANTO PVC | K13: =I13*H13 -> 0 | Q13: 1 | R13: CUB C/R R8 | S13: 2.03 | T13: 0.62 | U13: MADERA X DEFINIR | V13: 78990 | W13: =V13*Q13 -> 78990 | X13: =V13+$X$9 -> 84517.708 | Y13: 81990
D14: % utilidad | E14: NETO | F14: UTILIDAD | H14: 0 | I14: 50 | J14: SOBERBIOS | K14: =I14*H14 -> 0 | Q14: 1 | R14: CUB C/R R8 | S14: 1.08 | T14: 0.62 | U14: MADERA X DEFINIR | V14: 39990 | W14: =V14*Q14 -> 39990 | X14: =V14+$X$9 -> 45517.708 | Y14: 39990
C15: PROYECCION | D15: 0.65 | E15: =(100%+D15)*D12 -> 82556.25 | F15: =E15-D12 -> 32522.159 | H15: 0 | I15: 10 | J15: SOPORTE REPISA | K15: =I15*H15 -> 0 | Q15: 1 | R15: CUB C/R R8 | S15: 1.08 | T15: 0.62 | U15: MADERA X DEFINIR | V15: 39990 | W15: =V15*Q15 -> 39990 | X15: =V15+$X$9 -> 45517.708 | Y15: 39990
H16: 1 | J16: PUNTAS | K16: =I16*H16 -> 0 | Q16: 1 | R16: CUB C/R R8 | S16: 2.06 | T16: 0.62 | U16: MADERA X DEFINIR | V16: 79990 | W16: =V16*Q16 -> 79990 | X16: =V16+$X$9 -> 85517.708 | Y16: 83990
B17: M. PRIMA | C17: MATERIAL | D17: NETO | E17: IVA | F17: TOTAL | H17: 1 | J17: TORNILLOS | K17: =I17*H17 -> 0 | Q17: 6 | R17: CORTES 45° | V17: 5000 | W17: =V17*Q17 -> 30000
C18: LAMINA | D18: ='2229'!O31 -> 0 | E18: =D18*0.19 -> 0 | F18: =SUM(D18:E18) -> 0 | H18: 1 | J18: COLAFRIA | K18: =I18*H18 -> 0 | Q18: 1 | R18: PERFORACION LAVAPLATOS | V18: 10000 | W18: =V18*Q18 -> 10000
C19: LAMINA CHICA | D19: ='2229'!O32 -> 10000 | E19: =D19*0.19 -> 1900 | F19: =SUM(D19:E19) -> 11900
C20: MDF 18MM | D20: ='2229'!O30 -> 7050 | E20: =D20*0.19 -> 1339.5 | F20: =SUM(D20:E20) -> 8389.5 | H20: 1 | J20: LIJAS | K20: =I20*H20 -> 0 | V20: NETO | W20: =SUM(W11:W18) -> 472940 | Y20: =SUM(Y11:Y16)+SUM(W17:W18) -> 484940
C21: ADHESIVO | D21: ='2229'!O29 -> 3150 | E21: =D21*0.19 -> 598.5 | F21: =SUM(D21:E21) -> 3748.5 | H21: 1 | J21: CARTON | K21: =I21*H21 -> 0 | V21: I.V.A. | W21: =W20*19% -> 89858.6 | Y21: =Y20*0.19 -> 92138.6
A22: =450000*1.2 -> 540000 | C22: TOTAL | D22: =SUM(D18:D21) -> 20200 | E22: =SUM(E18:E21) -> 3838 | F22: =SUM(F18:F21) -> 24038 | H22: 1 | J22: GUAIPE | K22: =I22*H22 -> 0 | M22: =B33/9 -> 2318.8406 | Q22: PLAZO DE ENTREGA : 8 DIAS HABILES | V22: TOTAL | W22: =W20+W21 -> 562798.6 | Y22: =SUM(Y20:Y21) -> 577078.6
A23: =450000*1.2 -> 540000 | B23: M. DE OBRA | C23: PROCESO | D23: COSTO x Hr. | E23: Q Hrs. | F23: TOTAL | H23: 1 | J23: DILUYENTE | K23: =I23*H23 -> 0 | Q23: FORMA DE PAGO: 50% CONTADO, SALDO C/E
A24: =800000*1.2 -> 960000 | B24: =A22/23 -> 23478.261 | C24: CORTE | D24: =B24/9 -> 2608.6957 | E24: 0.5 | F24: =D24*E24 -> 1304.3478 | H24: 1 | J24: CINTA EMBALAJE | K24: =I24*H24 -> 0 | Q24: VALIDEZ COTIZACIÓN: 5 DIAS
A25: 450000 | B25: =A23/23 -> 23478.261 | C25: CORTE LAMINA | D25: =B25/9 -> 2608.6957 | E25: 0.5 | F25: =D25*E25 -> 1304.3478 | H25: Q/HRS | I25: PRECIO | J25: MANO DE OBRA INDIRECTA | K25: VALOR | L25: =SUM(K26:K36) -> 0
A26: 450000 | B26: =A24/23 -> 41739.13 | C26: REBAJE LAMINA | D26: =B26/9 -> 4637.6812 | F26: =D26*E26 -> 0 | H26: 0 | I26: =((480000/23)/9) -> 2318.8406 | J26: FLETERO (HRS) | K26: =H26*I26 -> 0
B27: =A25/23 -> 19565.217 | C27: TUPIZADO | D27: =B27/9 -> 2173.913 | E27: 0.5 | F27: =D27*E27 -> 1086.9565 | H27: 0 | J27: BENCINA | K27: =H27*I27 -> 0
A28: 350000 | B28: =A26/23 -> 19565.217 | C28: ARMADO | D28: =B28/9 -> 2173.913 | E28: 0.5 | F28: =D28*E28 -> 1086.9565 | H28: 0 | J28: TAG | K28: =H28*I28 -> 0
A29: 500000 | B29: =A28/23 -> 15217.391 | C29: PEGADO | D29: =B29/9 -> 1690.8213 | E29: 0.7 | F29: =D29*E29 -> 1183.5749 | H29: 0 | J29: RECTIFICACION | K29: =H29*I29 -> 0
B30: =A29/23 -> 21739.13 | C30: POSTFORMADO | D30: =B30/9 -> 2415.4589 | E30: 0.7 | F30: =D30*E30 -> 1690.8213 | H30: 0 | I30: =((550000*1.2)/23)/9 -> 3188.4058 | J30: HR. TRAB. JUAN | K30: =H30*I30 -> 0
A31: 450000 | C31: MEDIA CAÑA | D31: 2415 | F31: =D31*E31 -> 0 | H31: 0 | I31: =((450000*1.2)/23)/9 -> 2608.6957 | J31: HR. TRAB. JULIO | K31: =H31*I31 -> 0
A32: 350000 | B32: =A31/23 -> 19565.217 | C32: CORTE-ENCHAPE | D32: =B32/9 -> 2173.913 | E32: 0 | F32: =D32*E32 -> 0 | H32: 0 | I32: =((450000*1.2)/23)/9 -> 2608.6957 | J32: HR. TRAB. EUGE | K32: =H32*I32 -> 0
A33: =A22+A25+A28+A29+A31 -> 2290000 | B33: =480000/23 -> 20869.565 | C33: CONTROL CALIDAD | D33: =B33/9 -> 2318.8406 | E33: 0.5 | F33: =D33*E33 -> 1159.4203 | H33: 0 | J33: COLACION | K33: =H33*I33 -> 0
C34: TOTAL | D34: =SUM(D24:D33) -> 25216.932 | E34: =SUM(E24:E33) -> 3.9 | F34: =SUM(F24:F33) -> 8816.4251 | H34: 0 | J34: BONO | K34: =H34*I34 -> 0
B35: CIF | C35: M. PRIMA INDIREC. | D35: =L9 -> 2550 | H35: 1 | J35: PERFORACION | K35: =H35*I35 -> 0
C36: M. OBRA INDIRECTA | D36: =L25 -> 0 | H36: 6 | J36: CORTE 45 | K36: =H36*I36 -> 0
C37: GASTOS DE FABRICA | D37: =L37 -> 18467.666 | H37: CANTIDAD | I37: PRECIO | J37: GASTOS DE FABRICACION | K37: VALOR | L37: =SUM(K38:K40) -> 18467.666
C38: DEPRECIACIONES | H38: =$E$34 -> 3.9 | I38: =32609.69/9 -> 3623.2989 | J38: ARRIENDO x HORA | K38: =I38*H38 -> 14130.866
C39: TOTAL | D39: =SUM(D35:D38) -> 21017.666 | H39: =$E$34 -> 3.9 | I39: 967 | J39: AGUA x HORA | K39: =I39*H39 -> 3771.3
H40: =$E$34 -> 3.9 | I40: 145 | J40: LUZ x HORA | K40: =I40*H40 -> 565.5
B41: PROVISIONAR | C41: IVA | D41: =E11-E22 -> 5546.1
H42: ESTADO DE RESULTADOS
B43: TOTAL HRS TRABAJADAS | D43: =E34 -> 3.9 | H43: INGRESOS | I43: + TOTAL VENTA | M43: =D11 -> 49390
...

Sheet NOTA DE VENTA
F2: MUEBLES SANTA FE SPA
F3: VENTAS POR MENOR DE MUEBLES
F4: RUT: 77.054.606-0
F5: SEPTIMA AVENIDA 1631, SAN MIGUEL
F6: CELULAR: 963868755
F7: E-MAIL: fdonoso@topmobili.cl
B8: P R E S U P U E S T O | D8: ='2229'!D8 -> N° 11882 | F8: NOTA DE VENTA : | G8: 7385
B10: CLIENTE: | C10: =IF('2229'!C10="","",'2229'!C10) -> MARIO ZAPATA | F10: FECHA : | G10: ='2229'!G10 -> 46063
B11: RUT: | C11: =IF('2229'!C11="","",'2229'!C11) | F11: FECHA LIMITE : | G11: =WORKDAY(G10,5) -> 46070
B12: GIRO: | C12: =IF('2229'!C12="","",'2229'!C12) | F12: DESPACHO: | G12: ='2229'!G14 -> NO
B13: CONTACTO: | C13: =IF('2229'!C13="","",'2229'!C13) | F13: ORDEN DE COMPRA:
B14: CORREO: | C14: =IF('2229'!C14="","",'2229'!C14) | F14: HECHO POR: | G14: FERNANDO DONOSO
B15: FONO: | C15: =IF('2229'!C15="","",'2229'!C15) -> +569 4510 6187 | F15: SERVICIO EXPRESS: | G15: ='2229'!G12 -> NO
B16: DIRECCION: | C16: =IF('2229'!C16="","",'2229'!C16) | F16: FORMA DE PAGO : | G16: ='2229'!G16 -> ABONO 50% SALDO C/ENTREGA
B17: CIUDAD: | C17: =IF('2229'!C17="","",'2229'!C17) -> SANTIAGO | F17: VALIDEZ COTIZACIÓN: 5 DÍAS
B20: D E T A L L E
B21: UNIDAD | C21: TIPO | D21: LARGO | E21: ANCHO | F21: COLOR | G21: VALOR | H21: TOTAL
B22: ='2229'!B21 -> 1 | C22: ='2229'!C21 -> CUB C/R 90° | D22: ='2229'!D21*1000 -> 1450 | E22: ='2229'!E21*1000 -> 500 | F22: ='2229'!F21 -> COLOR MADERA CAFÉ STOCK | G22: ='2229'!G21 -> 49390 | H22: =G22*B22 -> 49390
G25: NETO | H25: =SUM(H22:H24) -> 49390
G26: I.V.A. | H26: =H25*19% -> 9384.1
G27: TOTAL | H27: =H25+H26 -> 58774.1
B30: CUENTA VISTA DEL BANCO ESTADO N° 35571389078 A NOMBRE DE
B31: "MUEBLES SANTA FE SPA." - RUT : 77.054.606-0, VENTAS@TOPMOBILI.CL
B32: VISITANOS Y DESCUBRE NUESTROS PRODUCTOS EN | E32: WWW.TOPMOBILICHILE.CL

Sheet REGLAS
B2: DETALLE CORTE LAMINA | G2: DETALLE CORTE SUSTRATO | P2: DETALLE CORTE MERA
B3: ALTO | C3: ANCHO | D3: TIPO | G3: ALTO | H3: ANCHO | I3: TIPO | P3: ALTO | Q3: ANCHO | R3: TIPO
B4: 40 | C4: 60 | D4: CEN 1V | E4: A1 | G4: 50 | H4: 100 | I4: CEN 1V | J4: REGLA SIEMPRE LLEVAR MEDIDA MINIMO A 100 | P4: 50 | Q4: -30 | R4: CUB C/R
B5: 40 | C5: 90 | D5: CEN 2V | E5: A2 | G5: 50 | I5: CEN 2V | J5: REGLA SIEMPRE LLEVAR MEDIDA MINIMO A 101 | P5: 50 | Q5: -30 | R5: CUB C/R
B6: 40 | C6: 100 | D6: CORNISA FRENTE ESPAÑOL 1 LADO | E6: A3 | G6: 50 | H6: 100 | I6: CORNISA FRENTE ESPAÑOL 1 LADO | P6: 50 | Q6: -30 | R6: CUB C/R 180°
B7: 40 | C7: 150 | D7: CORNISA FRENTE ESPAÑOL 2 LADO | E7: A4 | G7: 50 | I7: CORNISA FRENTE ESPAÑOL 2 LADO | P7: 50 | Q7: -30 | R7: CUB C/R FRENTE ESPAÑOL
B8: 40 | C8: 100 | D8: CORNISA 180° 1LADO | E8: A5 | G8: 50 | H8: 100 | I8: CORNISA 180° 1LADO | L8: DETALLE CORTE MERA | P8: 50 | Q8: -30 | R8: CUB C/R PUNTA 1 LADO
B9: 40 | C9: 50 | D9: CORNISA PUNTA TIBURON 1 LADO | E9: B | G9: 50 | H9: 100 | I9: CORNISA 1LADO | L9: ALTO | M9: ANCHO | N9: TIPO | P9: 50 | Q9: 0 | R9: CUB S/R FRENTE ESPAÑOL
B10: 40 | C10: 80 | D10: CORNISA PUNTA TIBURON 2 LADOS | E10: C | G10: 50 | I10: CORNISA 2 LADOS | L10: 50 | M10: -30 | N10: CUB C/R | P10: 50 | Q10: 0 | R10: CUB S/R
B11: 40 | C11: 60 | D11: CORNISA R8 1LADO | E11: D | G11: 50 | H11: 100 | I11: CORNISA PUNTA TIBURON 1 LADO | L11: 50 | M11: 0 | N11: CUB S/R y CUB MESA | P11: 50 | Q11: 0 | R11: CUB MESA 180° 2 LADOS
B12: 40 | C12: 100 | D12: CORNISA R8 2 LADOS | E12: E | G12: 50 | I12: CORNISA PUNTA TIBURON 2 LADOS | L12: 50 | M12: -2 | N12: PR | P12: 50 | Q12: 0 | R12: CUB MESA 180° 3 LADOS
B13: 40 | C13: 130 | D13: CUB C/R R6 | E13: F | G13: 50 | H13: -30 | I13: CUB C/R | P13: 50 | Q13: 0 | R13: CUB MESA 180° 4 LADOS
B14: 40 | C14: 150 | D14: CUB C/R 180° | G14: 50 | H14: -30 | I14: CUB C/R 180°
B15: 40 | C15: 150 | D15: CUB C/R FRENTE ESPAÑOL | E15: G | G15: 50 | H15: -30 | I15: CUB C/R FRENTE ESPAÑOL | P15: 50 | Q15: 0 | R15: CUB MESA 4 LADOS
B16: 40 | C16: 130 | D16: CUB C/R R2 | E16: H | G16: 50 | H16: -30 | I16: CUB C/R PUNTA TIBURON 1 LADO | P16: 50 | Q16: 0 | R16: CUB MESA FRENTE ESPAÑOL 2 LADOS
B17: 40 | C17: 150 | D17: CUB MESA 180° 2 LADOS | E17: I | G17: 50 | I17: CUB MESA 180° 2 LADOS | P17: 50 | Q17: 0 | R17: CUB MESA FRENTE ESPAÑOL 3 LADOS
B18: 140 | C18: 150 | D18: CUB MESA 180° 3 LADOS | E18: J | G18: 50 | I18: CUB MESA 180° 3 LADOS | P18: 50 | Q18: 0 | R18: CUB MESA FRENTE ESPAÑOL 4 LADOS
B19: 150 | C19: 150 | D19: CUB MESA 180° 4 LADOS | E19: K | G19: 50 | I19: CUB MESA 180° 4 LADOS | P19: 50 | Q19: 0 | R19: CUB MESA PUNTA TIBURON 2 LADOS
B20: 40 | C20: 100 | D20: CUB MESA 2L | E20: L | G20: 50 | H20: 0 | I20: CUB MESA 2L | J20: ES IGUAL A LO PEDIDO NO SE DEBE SUMAR NI RESTAR | P20: 50 | Q20: 0 | R20: CUB MESA PUNTA TIBURON 3 LADOS
B21: 100 | C21: 100 | D21: CUB MESA 3L | E21: M | G21: 50 | H21: 0 | I21: CUB MESA 3L | P21: 50 | Q21: 0 | R21: CUB MESA PUNTA TIBURON 4 LADOS
B22: 100 | C22: 100 | D22: CUB MESA 4 LADOS | E22: N | I22: CUB MESA 4 LADOS | P22: 50 | Q22: 0 | R22: CUB PUNTA TIBURON 1 LADO
B23: 40 | C23: 150 | D23: CUB MESA FRENTE ESPAÑOL 2 LADOS | E23: O | G23: 50 | I23: CUB MESA FRENTE ESPAÑOL 2 LADOS | R23: CENEFA 1 LADO
B24: 140 | C24: 150 | D24: CUB MESA FRENTE ESPAÑOL 3 LADOS | E24: P | G24: 50 | I24: CUB MESA FRENTE ESPAÑOL 3 LADOS | R24: CENEFA 2 LADOS
B25: 150 | C25: 150 | D25: CUB MESA FRENTE ESPAÑOL 4 LADOS | E25: Q | G25: 50 | I25: CUB MESA FRENTE ESPAÑOL 4 LADOS | R25: CORNISA FRENTE ESPAÑOL 1 LADO
B26: 40 | C26: 77 | D26: CUB MESA PUNTA TIBURON 2 LADOS | E26: R | G26: 50 | I26: CUB MESA PUNTA TIBURON 2 LADOS | R26: CORNISA FRENTE ESPAÑOL 2 LADO
B27: 110 | C27: 77 | D27: CUB MESA PUNTA TIBURON 3 LADOS | E27: S | G27: 50 | I27: CUB MESA PUNTA TIBURON 3 LADOS | R27: CORNISA 180° 1LADO
B28: 120 | C28: 77 | D28: CUB MESA PUNTA TIBURON 4 LADOS | E28: T | G28: 50 | I28: CUB MESA PUNTA TIBURON 4 LADOS | R28: CORNISA 1LADO
B29: 40 | C29: 50 | D29: CUB PUNTA TIBURON 1 LADO | E29: U | G29: 50 | I29: CUB PUNTA TIBURON 1 LADO | R29: CORNISA 2 LADOS
B30: 40 | C30: 60 | D30: CUB S/R | E30: V | G30: 50 | I30: CUB S/R | R30: CORNISA PUNTA TIBURON 1 LADO
B31: 40 | C31: 100 | D31: CUB S/R FRENTE ESPAÑOL | E31: W | G31: 50 | I31: CUB S/R FRENTE ESPAÑOL | R31: CORNISA PUNTA TIBURON 2 LADOS
B32: 40 | C32: 60 | D32: CUB S/R R2 | E32: X | G32: 50 | I32: CUB S/R R2 | R32: PR2
B33: 40 | C33: 90 | D33: PR12 | E33: Y | G33: 50 | H33: -2 | I33: PR12 | R33: PR6
B34: 40 | C34: 90 | D34: PR19 | G34: 50 | H34: -2 | I34: PR19
B35: 40 | C35: 90 | D35: PR2 | E35: Z | G35: 50 | H35: -2 | I35: PR2 | R35: PR8
B36: 40 | C36: 90 | D36: PR6 | G36: 50 | H36: -2 | I36: PR6 | R36: PR12
B37: 40 | C37: 90 | D37: PR8 | G37: 50 | H37: -2 | I37: PR8 | R37: PR19
B48: 40 | C48: 150

Sheet PRODUCCION
K2: NO BORRAR REGLAS!!!!! SI NO LAS SABEN USAR NO BORREN ESTO POR FAVOR!!!!!
K3: SUSTRATO | M3: LAMINADO
C4: NOTA DE VENTA : | D4: =IF('NOTA DE VENTA'!$G$8="","",'NOTA DE VENTA'!$G$8) -> 7385 | K4: ALTO | L4: ANCHO | M4: ALTO | N4: ANCHO
C5: CLIENTE : | D5: ='NOTA DE VENTA'!$C$10 -> MARIO ZAPATA | K5: =LOOKUP(F14,REGLAS!$I$4:$I$37,REGLAS!$G$4:$G$37)+J14 -> 1500 | L5: =LOOKUP(F14,REGLAS!$I$4:$I$37,REGLAS!$H$4:$H$37)+K14 -> 470 | M5: =LOOKUP(F14,REGLAS!$D$4:$D$37,REGLAS!$B$4:$B$37)+J21 -> 1490 | N5: =H10 -> 0
C7: ='NOTA DE VENTA'!$F$10 -> FECHA : | D7: ='NOTA DE VENTA'!$G$10 -> 46063
C8: FECHA ENTREGA: | D8: ='NOTA DE VENTA'!$G$11 -> 46070
A10: SUSTRATO
D12: ALTO | E12: ANCHO
A13: MATERIAL | B13: CANTIDAD | C13: CORTE | D13: 50 | E13: -30 | F13: DESCRIPCIÓN | J13: ALTO | K13: ANCHO
A14: MDF 18MM | B14: =I14 -> 1 | D14: =LOOKUP(F14,REGLAS!$I$4:$I$37,REGLAS!$G$4:$G$37)+J14 -> 1500 | E14: =LOOKUP(F14,REGLAS!$I$4:$I$37,REGLAS!$H$4:$H$37)+K14 -> 470 | F14: =C27 -> CUB C/R 90° | I14: =I21 -> 1 | J14: =D27 -> 1450 | K14: =E27 -> 500
A17: LAMINADO
D19: ALTO | E19: ANCHO
A20: MATERIAL | B20: CANTIDAD | C20: CORTE | D20: 40 | E20: 130 | F20: DESCRIPCIÓN | J20: ALTO | K20: ANCHO
A21: MDF 18MM | B21: =I21 -> 1 | D21: =LOOKUP(F14,REGLAS!$D$4:$D$37,REGLAS!$B$4:$B$37)+J21 -> 1490 | E21: 630 | F21: =C27 -> CUB C/R 90° | I21: =B27 -> 1 | J21: =D27 -> 1450 | K21: =E27 -> 500
B24: MEDIDAS ORIGINALES
A26: MATERIAL | B26: CANTIDAD | C26: DESCRIPCIÓN | D26: ALTO | E26: ANCHO | F26: COLOR
A27: MDF 18MM | B27: =B49 -> 1 | C27: =C49 -> CUB C/R 90° | D27: =D49 -> 1450 | E27: =E49 -> 500 | F27: =F49 -> COLOR MADERA CAFÉ STOCK
C39: NOTA DE VENTA : | D39: ='[1]4637'!G8 -> 7332
C40: CLIENTE : | D40: ='[1]4637'!C10 -> FMR MAKING SPA
C42: ='[1]4637'!F11 -> FECHA LIMITE : | D42: ='[1]4637'!G11 -> 45996
A45: PRODUCCIÓN
B47: DETALLE
B48: CANTIDAD | C48: CORTE | D48: ALTO | E48: ANCHO | F48: DESCRIPCION
A49: MDF18MM | B49: ='NOTA DE VENTA'!B22 -> 1 | C49: ='NOTA DE VENTA'!C22 -> CUB C/R 90° | D49: ='NOTA DE VENTA'!D22 -> 1450 | E49: ='NOTA DE VENTA'!E22 -> 500 | F49: ='NOTA DE VENTA'!F22 -> COLOR MADERA CAFÉ STOCK

Sheet SEGUIMIENTO
A1: NV | B1: N° COTIZA | C1: FECHA | D1: ENTREGA | E1: NOMBRE | F1: DETALLE | G1: COLOR | H1: NETO | I1: IVA | J1: TOTAL | K1: ABONO | L1: SALDO | M1: ESTADO
A2: ='NOTA DE VENTA'!$G$8 -> 7385 | B2: ='NOTA DE VENTA'!$D$8 -> N° 11882 | C2: ='NOTA DE VENTA'!$G$10 -> 46063 | D2: ='NOTA DE VENTA'!$G$11 -> 46070 | E2: ='NOTA DE VENTA'!$C$10 -> MARIO ZAPATA | F2: ='NOTA DE VENTA'!$C$22 -> CUB C/R 90° | G2: ='NOTA DE VENTA'!$F$22 -> COLOR MADERA CAFÉ STOCK | H2: ='NOTA DE VENTA'!$H$25 -> 49390 | I2: =H2*0.19 -> 9384.1 | J2: =I2+H2 -> 58774.1 | L2: =J2-K2 -> 58774.1
