Workbook

Sheet 2229
H2: MUEBLES SANTA FE SPA
H3: VENTAS POR MENOR DE MUEBLES
H4: RUT: 77.054.606-0
H5: SEPTIMA AVENIDA 1631, SAN MIGUEL
H6: FONO +569 2032 3382 | Q6: 10077 SF PORTLAND MAPLE
H7: E-MAIL: ventas@topmobili.cl
B8: P R E S U P U E S T O | D8: N° 11713 | L8: 152
L9: 129
B10: NOMBRE: | C10: CRISTIAN ROMO | H10: FECHA: | I10: 45952 | L10: =L8-L9 -> 23
B11: RUT: | H11: PLAZO ENTREGA: | I11: 10 DIAS HABILES | T11: MT2 PUERTAS
B12: GIRO: | H12: SERVICIO EXPRESS | I12: NO | L12: 44
B13: CONTACTO: | L13: 114
B14: CORREO: | H14: CORTADA A LA MEDIDA | I14: SI | T14: ML CUBIERTAS
B15: FONO: | C15: 5699519 4283 | H15: DESPACHO: | L15: =SUM(L12:L14) -> 158
B16: DIRECCION: | H16: FORMA DE PAGO: | I16: ABONO 50% SALDO C/ENTREGA
B17: CIUDAD: | C17: SANTIAGO | H17: DURACION COTIZACION: 5 DIAS FRANCO DONOSO
B19: DETALLE | O19: 0.02 | P19: 0.02 | R19: TOTAL | S19: VALOR X MT2 | T19: ENCHAPE | U19: MT/L
B20: UNIDAD | C20: TIPO | D20: LARGO | E20: ANCHO | F20: MODULO 1 | G20: ENCHAPE | H20: COLOR | I20: VALOR | J20: TOTAL | N20: =B20 -> UNIDAD | O20: ALTO | P20: =E20 -> ANCHO | Q20: MT | R20: MT2 | S20: =Q44 -> 83132.905 | T20: 3000 | V20: m/l
B21: 1 | C21: ENCHAPE RECTO 1 CARA MELAMIL 18MM | D21: 1.82 | E21: 0.35 | G21: 4 CANTOS TURQUESA | H21: TURQUESA BRILLO | I21: 56597 | J21: =I21*B21 -> 56597 | N21: =B21 -> 1 | O21: =D21+O$19 -> 1.84 | P21: =E21+$P$19 -> 0.37 | Q21: =O21*P21 -> 0.6808 | R21: =Q21*N21 -> 0.6808 | S21: =S$20*Q21 -> 56596.882 | T21: =S21+T$20 -> 59596.882 | U21: =O21*N21*2 -> 3.68 | V21: =P21*N21*2 -> 0.74
B22: 1 | C22: ENCHAPE RECTO 1 CARA MELAMIL 18MM | D22: 0.61 | E22: 0.35 | G22: 1 LARGO CANTO TURQUESA | H22: TURQUESA BRILLO | I22: 19378 | J22: =I22*B22 -> 19378 | N22: =B22 -> 1 | O22: =D22+O$19 -> 0.63 | P22: =E22+$P$19 -> 0.37 | Q22: =O22*P22 -> 0.2331 | R22: =Q22*N22 -> 0.2331 | S22: =S$20*Q22 -> 19378.28 | T22: =S22+T$20 -> 22378.28 | U22: =O22*N22*2 -> 1.26 | V22: =P22*N22*2 -> 0.74
B23: 1 | C23: ENCHA RECTO 2 CARAS MDF 18MM | D23: 0.61 | E23: 0.35 | G23: 1 LARGO CANTO TURQUESA | H23: TURQUESA BRILLO | I23: 19378 | J23: =I23*B23 -> 19378 | N23: =B23 -> 1 | O23: =D23+O$19 -> 0.63 | P23: =E23+$P$19 -> 0.37 | Q23: =O23*P23 -> 0.2331 | R23: =Q23*N23 -> 0.2331 | S23: =S$20*Q23 -> 19378.28 | T23: =S23+T$20 -> 22378.28 | U23: =O23*N23*2 -> 1.26 | V23: =P23*N23*2 -> 0.74
B24: 3 | C24: ENCHAPE RECTO 1 CARA MELAMIL 18MM | D24: 0.963 | E24: 0.3 | G24: 1 LARGO CANTO TURQUESA | H24: TURQUESA BRILLO | I24: 26150 | J24: =I24*B24 -> 78450 | N24: =B24 -> 3 | O24: =D24+O$19 -> 0.983 | P24: =E24+$P$19 -> 0.32 | Q24: =O24*P24 -> 0.31456 | R24: =Q24*N24 -> 0.94368 | S24: =S$20*Q24 -> 26150.287 | T24: =S24+T$20 -> 29150.287 | U24: =O24*N24*2 -> 5.898 | V24: =P24*N24*2 -> 1.92
B25: 1 | C25: ENCHAPE RECTO 1 CARA MELAMIL 18MM | D25: 1.644 | E25: 0.35 | F25: MODULO 2 | G25: 1 LARGO CANTO TURQUESA | H25: TURQUESA BRILLO | I25: 51183 | J25: =I25*B25 -> 51183 | N25: =B25 -> 1 | O25: =D25+O$19 -> 1.664 | P25: =E25+$P$19 -> 0.37 | Q25: =O25*P25 -> 0.61568 | R25: =Q25*N25 -> 0.61568 | S25: =S$20*Q25 -> 51183.267 | T25: =S25+T$20 -> 54183.267 | U25: =O25*N25*2 -> 3.328 | V25: =P25*N25*2 -> 0.74
B26: 1 | C26: ENCHAPE RECTO 1 CARA MELAMIL 18MM | D26: 1 | E26: 0.35 | F26: MODULO 3 | G26: 1 LARGO + 1 CORTO | H26: TURQUESA BRILLO | I26: 31374 | J26: =I26*B26 -> 31374 | N26: =B26 -> 1 | O26: =D26+O$19 -> 1.02 | P26: =E26+$P$19 -> 0.37 | Q26: =O26*P26 -> 0.3774 | R26: =Q26*N26 -> 0.3774 | S26: =S$20*Q26 -> 31374.359 | T26: =S26+T$20 -> 34374.359 | U26: =O26*N26*2 -> 2.04 | V26: =P26*N26*2 -> 0.74
B27: 1 | C27: ENCHAPE RECTO 1 CARA MELAMIL 18MM | D27: 0.493 | E27: 0.35 | G27: 1 LARGO CANTO TURQUESA | H27: TURQUESA BRILLO | I27: 15779 | J27: =I27*B27 -> 15779 | N27: =B27 -> 1 | O27: =D27+O$19 -> 0.513 | P27: =E27+$P$19 -> 0.37 | Q27: =O27*P27 -> 0.18981 | R27: =Q27*N27 -> 0.18981 | S27: =S$20*Q27 -> 15779.457 | T27: =S27+T$20 -> 18779.457 | U27: =O27*N27*2 -> 1.026 | V27: =P27*N27*2 -> 0.74
B28: 1 | C28: TAPA ZOCALO MDF 18MM | D28: 1.82 | E28: 0.05 | G28: 2 CORTOS TURQUESA | H28: TURQUESA BRILLO | I28: 10708 | J28: =I28*B28 -> 10708 | N28: =B28 -> 1 | O28: =D28+O$19 -> 1.84 | P28: =E28+$P$19 -> 0.07 | Q28: =O28*P28 -> 0.1288 | R28: =Q28*N28 -> 0.1288 | S28: =S$20*Q28 -> 10707.518 | T28: =S28+T$20 -> 13707.518
I30: NETO | J30: =SUM(J21:J29) -> 282847 | V30: =SUM(V21:V29) -> 6.36
I31: IVA | J31: =J30*19% -> 53740.93 | O31: =SUM(O21:O21) -> 1.84 | R31: =SUM(R21:R29) -> 3.40237 | U31: =SUM(U21:U30) -> 18.492
I32: TOTAL | J32: =J30+J31 -> 336587.93 | R32: =R31 -> 3.40237
R33: =R32*20% -> 0.680474 | S33: 20% PERDIDA | U33: =V30+U31 -> 24.852
R34: =R32+R33 -> 4.082844 | U34: =U33*20% -> 4.9704
U35: =U33+U34 -> 29.8224 | W35: ADHESIVO | X35: 58.000.- | Y35: 44971
O36: =R34 -> 4.082844 | P36: 3500 | Q36: =O36*P36 -> 14289.954 | R36: ADHESIVO | W36: LATA 16 LTS | X36: 3625 | Y36: LITRO
O37: 1.2 | P37: 42000 | Q37: =O37*P37 -> 50400 | R37: MDF 18MM | X37: 906.25 | Y37: MT2 (4)
B38: CUENTA CORRIENTE BANCO SANTANDER Nº 87316181 A NOMBRE DE MUEBLES SANTA FE SPA | P38: 42000 | Q38: =O38*P38 -> 0 | R38: MDF 30MM | X38: =X37*20% -> 181.25 | Y38: PERDIDA 20%
B39: RUT : 77.054.606-0 VENTAS@TOPMOBILI.CL | O39: 2 | P39: 35000 | Q39: =O39*P39 -> 70000 | R39: LAMINA 122X244 | X39: =X37+X38 -> 1087.5 | Y39: MINIMO A COTIZAR
B40: VISITANOS Y DESCUBRE NUESTROS PRODUCTOS EN | H40: WWW.TOPMOBILICHILE.CL | P40: 900 | Q40: =O40*P40 -> 0 | R40: RESPALDO | T40: 1.52
L41: WHITE OAK | M41: 38300 | P41: 600 | Q41: =O41*P41 -> 0 | R41: TAPACANTO PVC 0,45 X 50MM | T41: 2.44
L42: NIEBLA | M42: 31000 | Q42: =SUM(Q36:Q41) -> 134689.95 | R42: COSTO | T42: =T40*T41 -> 3.7088
L43: 73340 | O43: PRECIO VENTA | Q43: =Q42*2.1 -> 282848.9 | R43: FACTOR 2,3 PARA 90° | T43: =R34/T42 -> 1.1008531
...

Sheet COSTOS
B2: CENTRO DE COSTOS POSTFORMADOS
B5: FECHA: | C5: ='2229'!I10 -> 45952
B6: CLIENTE: | C6: ='2229'!C10 -> CRISTIAN ROMO | N6: Ventas Equilibrio = | P6: Costos Fijos Totales
B7: DIRECCION: | C7: ='2229'!#REF! -> #REF! | H7: COSTOS INDIRECTOS DE FABRICA VARIABLES | O7: 1 - | P7: Costos Variables Totales
B8: PRESUPUESTO: | C8: ='2229'!D8 -> N° 11713 | H8: Q/HRS | I8: $ | J8: DETALLE | K8: TOTAL | L8: TOTAL | P8: Total Venta | X8: =SUM(Q11:Q16) -> 6
H9: CANTIDAD | I9: PRECIO | J9: MATERIA PRIMA INDIRECTA | L9: =SUM(K10:K23) -> 2550 | S9: DETALLE | X9: =(E15-D11)/X8 -> -21147.054
D10: NETO | E10: IVA | F10: TOTAL | H10: 3 | I10: 350 | J10: RESPALDO | K10: =I10*H10 -> 1050 | Q10: UNIDAD | R10: TIPO | S10: LARGO | T10: ANCHO | U10: COLOR | V10: VALOR | W10: TOTAL
C11: MONTO A COBRAR | D11: ='2229'!J30 -> 282847 | E11: =D11*0.19 -> 53740.93 | F11: =E11+D11 -> 336587.93 | H11: 3 | I11: 500 | J11: MEDIA CAÑA | K11: =I11*H11 -> 1500 | Q11: 1 | R11: CUB C/R R8 | S11: 2.8 | T11: 0.62 | U11: MADERA X DEFINIR | V11: 105990 | W11: =V11*Q11 -> 105990 | X11: =V11+$X$9 -> 84842.946 | Y11: 108990
C12: COSTO TOTAL | D12: =SUM(M43:M45) -> 94524.045 | H12: 0 | I12: 7500 | J12: DUROLAC | K12: =I12*H12 -> 0 | Q12: 1 | R12: CUB C/R R8 | S12: 2.3 | T12: 0.62 | U12: MADERA X DEFINIR | V12: 87990 | W12: =V12*Q12 -> 87990 | X12: =V12+$X$9 -> 66842.946 | Y12: 89990
C13: % UTILIDAD | D13: =D11-D12 -> 188322.96 | E13: =(D11/D12)-1 -> 1.9923286 | H13: 0 | I13: 50 | J13: TAPACANTO PVC | K13: =I13*H13 -> 0 | Q13: 1 | R13: CUB C/R R8 | S13: 2.03 | T13: 0.62 | U13: MADERA X DEFINIR | V13: 78990 | W13: =V13*Q13 -> 78990 | X13: =V13+$X$9 -> 57842.946 | Y13: 81990
D14: % utilidad | E14: NETO | F14: UTILIDAD | H14: 0 | I14: 50 | J14: SOBERBIOS | K14: =I14*H14 -> 0 | Q14: 1 | R14: CUB C/R R8 | S14: 1.08 | T14: 0.62 | U14: MADERA X DEFINIR | V14: 39990 | W14: =V14*Q14 -> 39990 | X14: =V14+$X$9 -> 18842.946 | Y14: 39990
C15: PROYECCION | D15: 0.65 | E15: =(100%+D15)*D12 -> 155964.67 | F15: =E15-D12 -> 61440.629 | H15: 0 | I15: 10 | J15: SOPORTE REPISA | K15: =I15*H15 -> 0 | Q15: 1 | R15: CUB C/R R8 | S15: 1.08 | T15: 0.62 | U15: MADERA X DEFINIR | V15: 39990 | W15: =V15*Q15 -> 39990 | X15: =V15+$X$9 -> 18842.946 | Y15: 39990
H16: 1 | J16: PUNTAS | K16: =I16*H16 -> 0 | Q16: 1 | R16: CUB C/R R8 | S16: 2.06 | T16: 0.62 | U16: MADERA X DEFINIR | V16: 79990 | W16: =V16*Q16 -> 79990 | X16: =V16+$X$9 -> 58842.946 | Y16: 83990
B17: M. PRIMA | C17: MATERIAL | D17: NETO | E17: IVA | F17: TOTAL | H17: 1 | J17: TORNILLOS | K17: =I17*H17 -> 0 | Q17: 6 | R17: CORTES 45° | V17: 5000 | W17: =V17*Q17 -> 30000
C18: LAMINA | D18: ='2229'!Q38 -> 0 | E18: =D18*0.19 -> 0 | F18: =SUM(D18:E18) -> 0 | H18: 1 | J18: COLAFRIA | K18: =I18*H18 -> 0 | Q18: 1 | R18: PERFORACION LAVAPLATOS | V18: 10000 | W18: =V18*Q18 -> 10000
C19: MDF 18MM | D19: ='2229'!Q37 -> 50400 | E19: =D19*0.19 -> 9576 | F19: =SUM(D19:E19) -> 59976 | H19: 1 | J19: LIJAS | K19: =I19*H19 -> 0 | V19: NETO | W19: =SUM(W11:W18) -> 472940 | Y19: =SUM(Y11:Y16)+SUM(W17:W18) -> 484940
C20: ADHESIVO | D20: ='2229'!Q36 -> 14289.954 | E20: =D20*0.19 -> 2715.0913 | F20: =SUM(D20:E20) -> 17005.045 | H20: 1 | J20: CARTON | K20: =I20*H20 -> 0 | V20: I.V.A. | W20: =W19*19% -> 89858.6 | Y20: =Y19*0.19 -> 92138.6
A21: =450000*1.2 -> 540000 | C21: TOTAL | D21: =SUM(D18:D20) -> 64689.954 | E21: =SUM(E18:E20) -> 12291.091 | F21: =SUM(F18:F20) -> 76981.045 | H21: 1 | J21: GUAIPE | K21: =I21*H21 -> 0 | M21: =B32/9 -> 2318.8406 | Q21: PLAZO DE ENTREGA : 8 DIAS HABILES | V21: TOTAL | W21: =W19+W20 -> 562798.6 | Y21: =SUM(Y19:Y20) -> 577078.6
A22: =450000*1.2 -> 540000 | B22: M. DE OBRA | C22: PROCESO | D22: COSTO x Hr. | E22: Q Hrs. | F22: TOTAL | H22: 1 | J22: DILUYENTE | K22: =I22*H22 -> 0 | Q22: FORMA DE PAGO: 50% CONTADO, SALDO C/E
A23: =800000*1.2 -> 960000 | B23: =A21/23 -> 23478.261 | C23: CORTE | D23: =B23/9 -> 2608.6957 | E23: 0.5 | F23: =D23*E23 -> 1304.3478 | H23: 1 | J23: CINTA EMBALAJE | K23: =I23*H23 -> 0 | Q23: VALIDEZ COTIZACIÓN: 5 DIAS
A24: 450000 | B24: =A22/23 -> 23478.261 | C24: CORTE LAMINA | D24: =B24/9 -> 2608.6957 | E24: 0.5 | F24: =D24*E24 -> 1304.3478 | H24: Q/HRS | I24: PRECIO | J24: MANO DE OBRA INDIRECTA | K24: VALOR | L24: =SUM(K25:K35) -> 0
A25: 450000 | B25: =A23/23 -> 41739.13 | C25: REBAJE LAMINA | D25: =B25/9 -> 4637.6812 | F25: =D25*E25 -> 0 | H25: 0 | I25: =((480000/23)/9) -> 2318.8406 | J25: FLETERO (HRS) | K25: =H25*I25 -> 0
B26: =A24/23 -> 19565.217 | C26: TUPIZADO | D26: =B26/9 -> 2173.913 | E26: 0.5 | F26: =D26*E26 -> 1086.9565 | H26: 0 | J26: BENCINA | K26: =H26*I26 -> 0
A27: 350000 | B27: =A25/23 -> 19565.217 | C27: ARMADO | D27: =B27/9 -> 2173.913 | E27: 0.5 | F27: =D27*E27 -> 1086.9565 | H27: 0 | J27: TAG | K27: =H27*I27 -> 0
A28: 500000 | B28: =A27/23 -> 15217.391 | C28: PEGADO | D28: =B28/9 -> 1690.8213 | E28: 0.7 | F28: =D28*E28 -> 1183.5749 | H28: 0 | J28: RECTIFICACION | K28: =H28*I28 -> 0
B29: =A28/23 -> 21739.13 | C29: POSTFORMADO | D29: =B29/9 -> 2415.4589 | E29: 0.7 | F29: =D29*E29 -> 1690.8213 | H29: 0 | I29: =((550000*1.2)/23)/9 -> 3188.4058 | J29: HR. TRAB. JUAN | K29: =H29*I29 -> 0
A30: 450000 | C30: MEDIA CAÑA | D30: 2415 | F30: =D30*E30 -> 0 | H30: 0 | I30: =((450000*1.2)/23)/9 -> 2608.6957 | J30: HR. TRAB. JULIO | K30: =H30*I30 -> 0
A31: 350000 | B31: =A30/23 -> 19565.217 | C31: CORTE-ENCHAPE | D31: =B31/9 -> 2173.913 | E31: 0 | F31: =D31*E31 -> 0 | H31: 0 | I31: =((450000*1.2)/23)/9 -> 2608.6957 | J31: HR. TRAB. EUGE | K31: =H31*I31 -> 0
A32: =A21+A24+A27+A28+A30 -> 2290000 | B32: =480000/23 -> 20869.565 | C32: CONTROL CALIDAD | D32: =B32/9 -> 2318.8406 | E32: 0.5 | F32: =D32*E32 -> 1159.4203 | H32: 0 | J32: COLACION | K32: =H32*I32 -> 0
C33: TOTAL | D33: =SUM(D23:D32) -> 25216.932 | E33: =SUM(E23:E32) -> 3.9 | F33: =SUM(F23:F32) -> 8816.4251 | H33: 0 | J33: BONO | K33: =H33*I33 -> 0
B34: CIF | C34: M. PRIMA INDIREC. | D34: =L9 -> 2550 | H34: 1 | J34: PERFORACION | K34: =H34*I34 -> 0
C35: M. OBRA INDIRECTA | D35: =L24 -> 0 | H35: 6 | J35: CORTE 45 | K35: =H35*I35 -> 0
C36: GASTOS DE FABRICA | D36: =L36 -> 18467.666 | H36: CANTIDAD | I36: PRECIO | J36: GASTOS DE FABRICACION | K36: VALOR | L36: =SUM(K37:K39) -> 18467.666
C37: DEPRECIACIONES | H37: =$E$33 -> 3.9 | I37: =32609.69/9 -> 3623.2989 | J37: ARRIENDO x HORA | K37: =I37*H37 -> 14130.866
C38: TOTAL | D38: =SUM(D34:D37) -> 21017.666 | H38: =$E$33 -> 3.9 | I38: 967 | J38: AGUA x HORA | K38: =I38*H38 -> 3771.3
H39: =$E$33 -> 3.9 | I39: 145 | J39: LUZ x HORA | K39: =I39*H39 -> 565.5
B40: PROVISIONAR | C40: IVA | D40: =E11-E21 -> 41449.839
H41: ESTADO DE RESULTADOS
B42: TOTAL HRS TRABAJADAS | D42: =E33 -> 3.9 | H42: INGRESOS | I42: + TOTAL VENTA | M42: =D11 -> 282847
H43: COSTOS | I43: - MATERIA PRIMA DIRECTA | M43: =D21 -> 64689.954
...
