Workbook

Sheet G
F2: MUEBLES SANTA FE SPA
F3: VENTAS POR MENOR DE MUEBLES
F4: RUT: 77.054.606-0
F5: SEPTIMA AVENIDA 1631, SAN MIGUEL
F6: FONO +569 2032 3382 | O6: 10077 SF PORTLAND MAPLE
F7: E-MAIL: ventas@topmobili.cl
B8: P R E S U P U E S T O | D8: N° 11725 | J8: 152
J9: 129
B10: NOMBRE: | C10: CONSTRUCTORA HALTRA | F10: FECHA: | G10: 45958 | J10: =J8-J9 -> 23
B11: RUT: | F11: PLAZO ENTREGA: | G11: 8 DIAS HABILES | R11: MT2 PUERTAS
B12: GIRO: | F12: SERVICIO EXPRESS | G12: NO | J12: 44
B13: CONTACTO: | J13: 114
B14: CORREO: | F14: CORTADA A LA MEDIDA | G14: NO | R14: ML CUBIERTAS
B15: FONO: | C15: 5699833 5638 | F15: DESPACHO: | G15: NO | J15: =SUM(J12:J14) -> 158
B16: DIRECCION: | F16: FORMA DE PAGO: | G16: ABONO 50% SALDO C/ENTREGA
B17: CIUDAD: | C17: SANTIAGO | F17: DURACION COTIZACION: 5 DIAS FRANCO DONOSO
B19: DETALLE | M19: 0.08 | N19: 0.05 | P19: TOTAL | Q19: VALOR X MT2 | R19: ENCHAPE | S19: MT/L
B20: UNIDAD | C20: TIPO | D20: LARGO | E20: ANCHO | F20: COLOR | G20: VALOR | H20: TOTAL | L20: =B20 -> UNIDAD | M20: ALTO | N20: =E20 -> ANCHO | O20: MT | P20: MT2 | Q20: =O43 -> 68979.13 | R20: 10000 | T20: m/l
B21: 4 | C21: CUB S/R FALDON 5 CMS R6 | D21: 2.15 | E21: 0.4 | F21: FASHION GREY 21371 GL | G21: 79221 | H21: =G21*B21 -> 316884 | L21: =B21 -> 4 | M21: =D21+M$19 -> 2.23 | N21: =E21+$N$19 -> 0.45 | O21: =M21*N21 -> 1.0035 | P21: =O21*L21 -> 4.014 | Q21: =Q$20*O21 -> 69220.557 | R21: =Q21+R$20 -> 79220.557 | S21: =M21*L21*2 -> 17.84 | T21: =N21*L21*2 -> 3.6
B22: 2 | C22: CUB S/R FALDON 5 CMS R6 | D22: 1.9 | E22: 0.4 | F22: FASHION GREY 21371 GL | G22: 71460 | H22: =G22*B22 -> 142920 | L22: =B22 -> 2 | M22: =D22+M$19 -> 1.98 | N22: =E22+$N$19 -> 0.45 | O22: =M22*N22 -> 0.891 | P22: =O22*L22 -> 1.782 | Q22: =Q$20*O22 -> 61460.405 | R22: =Q22+R$20 -> 71460.405 | S22: =M22*L22*2 -> 7.92 | T22: =N22*L22*2 -> 1.8
B23: 4 | C23: RESPALDO 1V R6 | D23: 1.7 | E23: 0.4 | F23: FASHION GREY 21371 GL | G23: 59113 | H23: =G23*B23 -> 236452 | L23: =B23 -> 4 | M23: =D23+M$19 -> 1.78 | N23: =E23 -> 0.4 | O23: =M23*N23 -> 0.712 | P23: =O23*L23 -> 2.848 | Q23: =Q$20*O23 -> 49113.141 | R23: =Q23+R$20 -> 59113.141 | S23: =M23*L23*2 -> 14.24 | T23: =N23*L23*2 -> 3.2
B24: 4 | C24: RESPALDO 1V R6 | D24: 1.08 | E24: 0.4 | F24: FASHION GREY 21371 GL | G24: 42006 | H24: =G24*B24 -> 168024 | L24: 1 | M24: =D24+M$19 -> 1.16 | N24: =E24 -> 0.4 | O24: =M24*N24 -> 0.464 | P24: =O24*L24 -> 0.464 | Q24: =Q$20*O24 -> 32006.317 | R24: =Q24+R$20 -> 42006.317 | S24: =M24*L24*2 -> 2.32
B25: 2 | C25: MDF 9MM | D25: 1,,52 | E25: 2.44 | F25: LAMINA ALUMINIUN | G25: 20000 | H25: =G25*B25 -> 40000
C26: PERFIL 30X30 1MM | D26: 2.8 | G26: 8090 | H26: =G26*B26 -> 0
B27: 2
G29: NETO | H29: =SUM(H21:H28) -> 904280 | I29: 0.35 | T29: =SUM(T21:T28) -> 8.6
G30: IVA | H30: =H29*19% -> 171813.2 | I30: =H29*35% -> 316498 | M30: =SUM(M21:M21) -> 2.23 | P30: =SUM(P21:P28) -> 9.108 | S30: =SUM(S21:S29) -> 42.32
G31: TOTAL | H31: =H29+H30 -> 1076093.2 | I31: =H29+I30 -> 1220778 | P31: =P30 -> 9.108
P32: =P31*20% -> 1.8216 | Q32: 20% PERDIDA | S32: =T29+S30 -> 50.92
P33: =P31+P32 -> 10.9296 | S33: =S32*20% -> 10.184
S34: =S32+S33 -> 61.104 | U34: ADHESIVO | V34: 58.000.- | W34: 44971
M35: =P33 -> 10.9296 | N35: 3500 | O35: =M35*N35 -> 38253.6 | P35: ADHESIVO | U35: LATA 16 LTS | V35: 3625 | W35: LITRO
M36: 3 | N36: 23500 | O36: =M36*N36 -> 70500 | P36: MDF 18MM | V36: 906.25 | W36: MT2 (4)
B37: CUENTA CORRIENTE BANCO SANTANDER Nº 87316181 A NOMBRE DE MUEBLES SANTA FE SPA | N37: 42000 | O37: =M37*N37 -> 0 | P37: MDF 30MM | V37: =V36*20% -> 181.25 | W37: PERDIDA 20%
B38: RUT : 77.054.606-0 VENTAS@TOPMOBILI.CL | M38: 5 | N38: 35364 | O38: =M38*N38 -> 176820 | P38: LAMINA 122X244 | V38: =V36+V37 -> 1087.5 | W38: MINIMO A COTIZAR
B39: VISITANOS Y DESCUBRE NUESTROS PRODUCTOS EN | F39: WWW.TOPMOBILICHILE.CL | N39: 900 | O39: =M39*N39 -> 0 | P39: RESPALDO | R39: 1.52
J40: WHITE OAK | K40: 38300 | N40: 200 | O40: =M40*N40 -> 0 | P40: TAPACANTO PVC 0,45 X 50MM | R40: 2.44
J41: NIEBLA | K41: 31000 | O41: =SUM(O35:O40) -> 285573.6 | P41: COSTO | R41: =R39*R40 -> 3.7088
J42: 73340 | M42: PRECIO VENTA | O42: =O41*2.2 -> 628261.92 | P42: FACTOR 2,3 PARA 90° | R42: =P33/R41 -> 2.946937
J43: =J42/1.19 -> 61630.252 | O43: =O42/P31 -> 68979.13 | P43: VALOR M2 | U43: MDF30MM | V43: 43650
...

Sheet F
F2: MUEBLES SANTA FE SPA
F3: VENTAS POR MENOR DE MUEBLES
F4: RUT: 77.054.606-0
F5: SEPTIMA AVENIDA 1631, SAN MIGUEL
F6: FONO +569 2032 3382 | O6: 10077 SF PORTLAND MAPLE
F7: E-MAIL: ventas@topmobili.cl
B8: P R E S U P U E S T O | D8: N° 11720 | J8: 152
J9: 129
B10: NOMBRE: | C10: CONSTRUCTORA HALTRA | F10: FECHA: | G10: 27-10-20255 | J10: =J8-J9 -> 23
B11: RUT: | F11: PLAZO ENTREGA: | G11: 8 DIAS HABILES | R11: MT2 PUERTAS
B12: GIRO: | F12: SERVICIO EXPRESS | G12: NO | J12: 44
B13: CONTACTO: | J13: 114
B14: CORREO: | F14: CORTADA A LA MEDIDA | G14: NO | R14: ML CUBIERTAS
B15: FONO: | C15: 5699833 5638 | F15: DESPACHO: | G15: NO | J15: =SUM(J12:J14) -> 158
B16: DIRECCION: | F16: FORMA DE PAGO: | G16: ABONO 50% SALDO C/ENTREGA
B17: CIUDAD: | C17: SANTIAGO | F17: DURACION COTIZACION: 5 DIAS FRANCO DONOSO
B19: DETALLE | M19: 0.05 | N19: 0.02 | P19: TOTAL | Q19: VALOR X MT2 | R19: ENCHAPE | S19: MT/L
B20: UNIDAD | C20: TIPO | D20: LARGO | E20: ANCHO | F20: COLOR | G20: VALOR | H20: TOTAL | L20: =B20 -> UNIDAD | M20: ALTO | N20: =E20 -> ANCHO | O20: MT | P20: MT2 | Q20: =O42 -> 138404.44 | R20: 10000 | T20: m/l
B21: 1 | C21: CUBIERTA MDF 18 + REGRUESO MDF 18MM | D21: 1.6 | E21: 0.7 | F21: FASHION GREY 21371 GL | G21: 83732 | H21: =G21*B21 -> 83732 | M21: =D21+M$19 -> 1.65 | N21: =E21+$N$19 -> 0.72 | O21: =M21*N21 -> 1.188 | P21: =O21*L21 -> 0 | Q21: =Q$20*O21 -> 164424.48 | R21: =Q21+R$20 -> 174424.48 | S21: =M21*L21*2 -> 0 | T21: =N21*L21*2 -> 0
C22: SEPARADOR 2 CARAS MDF 18 + MDF 18MM | D22: 1.3 | E22: 1.1 | F22: WINTER SAMSARA MAPLE 14689 SF | G22: 206123 | H22: =G22*B22 -> 0 | L22: =B22 -> 0 | M22: =D22+M$19 -> 1.35 | N22: =E22+$N$19 -> 1.12 | O22: =M22*N22 -> 1.512 | P22: =O22*L22 -> 0 | Q22: =Q$20*O22 -> 209267.52 | R22: =Q22+R$20 -> 219267.52 | S22: =M22*L22*2 -> 0 | T22: =N22*L22*2 -> 0
B23: 2 | C23: COSTADO 2 CARAS MDF 18 + MDF 18MM | D23: 0.75 | E23: 0.7 | F23: WINTER SAMSARA MAPLE 14689 SF | G23: 89721 | H23: =G23*B23 -> 179442 | L23: =B23 -> 2 | M23: =D23+M$19 -> 0.8 | N23: =E23+$N$19 -> 0.72 | O23: =M23*N23 -> 0.576 | P23: =O23*L23 -> 1.152 | Q23: =Q$20*O23 -> 79720.96 | R23: =Q23+R$20 -> 89720.96 | S23: =M23*L23*2 -> 3.2 | T23: =N23*L23*2 -> 2.88
B24: 1 | C24: FRENTE MDF 18 MM 1 CARA | D24: 1.6 | E24: 0.7 | F24: WINTER SAMSARA MAPLE 14689 SF | G24: 174424 | H24: =G24*B24 -> 174424 | L24: 1 | M24: =D24+M$19 -> 1.65 | N24: =E24+$N$19 -> 0.72 | O24: =M24*N24 -> 1.188 | P24: =O24*L24 -> 1.188 | Q24: =Q$20*O24 -> 164424.48 | R24: =Q24+R$20 -> 174424.48 | S24: =M24*L24*2 -> 3.3
B25: 1 | C25: ZOCALO | D25: 1.6 | E25: 0.1 | F25: LAMINA ALUMINIUN | G25: 14000 | H25: =G25*B25 -> 14000
B26: 1 | C26: PERFIL 30X30 1MM | D26: 2.8 | G26: 8090 | H26: =G26*B26 -> 8090
G28: NETO | H28: =SUM(H21:H27) -> 459688 | I28: 0.35 | T28: =SUM(T21:T27) -> 2.88
G29: IVA | H29: =H28*19% -> 87340.72 | I29: =H28*35% -> 160890.8 | M29: =SUM(M21:M21) -> 1.65 | P29: =SUM(P21:P27) -> 2.34 | S29: =SUM(S21:S28) -> 6.5
G30: TOTAL | H30: =H28+H29 -> 547028.72 | I30: =H28+I29 -> 620578.8 | P30: =P29 -> 2.34
P31: =P30*20% -> 0.468 | Q31: 20% PERDIDA | S31: =T28+S29 -> 9.38
P32: =P30+P31 -> 2.808 | S32: =S31*20% -> 1.876
S33: =S31+S32 -> 11.256 | U33: ADHESIVO | V33: 58.000.- | W33: 44971
M34: =P32*3 -> 8.424 | N34: 3500 | O34: =M34*N34 -> 29484 | P34: ADHESIVO | U34: LATA 16 LTS | V34: 3625 | W34: LITRO
M35: 2 | N35: 23500 | O35: =M35*N35 -> 47000 | P35: MDF 18MM | V35: 906.25 | W35: MT2 (4)
B36: CUENTA CORRIENTE BANCO SANTANDER Nº 87316181 A NOMBRE DE MUEBLES SANTA FE SPA | N36: 42000 | O36: =M36*N36 -> 0 | P36: MDF 30MM | V36: =V35*20% -> 181.25 | W36: PERDIDA 20%
B37: RUT : 77.054.606-0 VENTAS@TOPMOBILI.CL | M37: 2 | N37: 35364 | O37: =M37*N37 -> 70728 | P37: LAMINA 122X244 | V37: =V35+V36 -> 1087.5 | W37: MINIMO A COTIZAR
B38: VISITANOS Y DESCUBRE NUESTROS PRODUCTOS EN | F38: WWW.TOPMOBILICHILE.CL | N38: 900 | O38: =M38*N38 -> 0 | P38: RESPALDO | R38: 1.52
J39: WHITE OAK | K39: 38300 | N39: 200 | O39: =M39*N39 -> 0 | P39: TAPACANTO PVC 0,45 X 50MM | R39: 2.44
J40: NIEBLA | K40: 31000 | O40: =SUM(O34:O39) -> 147212 | P40: COSTO | R40: =R38*R39 -> 3.7088
J41: 73340 | M41: PRECIO VENTA | O41: =O40*2.2 -> 323866.4 | P41: FACTOR 2,3 PARA 90° | R41: =P32/R40 -> 0.75711821
J42: =J41/1.19 -> 61630.252 | O42: =O41/P30 -> 138404.44 | P42: VALOR M2 | U42: MDF30MM | V42: 43650
O43: =O41/O40 -> 2.2 | U43: 46 UNIDADES | V43: 948.91 | W43: 2.4
...

Sheet C
F2: MUEBLES SANTA FE SPA
F3: VENTAS POR MENOR DE MUEBLES
F4: RUT: 77.054.606-0
F5: SEPTIMA AVENIDA 1631, SAN MIGUEL
F6: FONO +569 2032 3382 | O6: 10077 SF PORTLAND MAPLE
F7: E-MAIL: ventas@topmobili.cl
B8: P R E S U P U E S T O | D8: N° 11720 | J8: 152
J9: 129
B10: NOMBRE: | C10: CONSTRUCTORA HALTRA | F10: FECHA: | G10: 27-10-20255 | J10: =J8-J9 -> 23
B11: RUT: | F11: PLAZO ENTREGA: | G11: 8 DIAS HABILES | R11: MT2 PUERTAS
B12: GIRO: | F12: SERVICIO EXPRESS | G12: NO | J12: 44
B13: CONTACTO: | J13: 114
B14: CORREO: | F14: CORTADA A LA MEDIDA | G14: NO | R14: ML CUBIERTAS
B15: FONO: | C15: 5699833 5638 | F15: DESPACHO: | G15: NO | J15: =SUM(J12:J14) -> 158
B16: DIRECCION: | F16: FORMA DE PAGO: | G16: ABONO 50% SALDO C/ENTREGA
B17: CIUDAD: | C17: SANTIAGO | F17: DURACION COTIZACION: 5 DIAS FRANCO DONOSO
B19: DETALLE | M19: 0.05 | N19: 0.02 | P19: TOTAL | Q19: VALOR X MT2 | R19: ENCHAPE | S19: MT/L
B20: UNIDAD | C20: TIPO | D20: LARGO | E20: ANCHO | F20: COLOR | G20: VALOR | H20: TOTAL | L20: =B20 -> UNIDAD | M20: ALTO | N20: =E20 -> ANCHO | O20: MT | P20: MT2 | Q20: =O42 -> 142896.74 | R20: 10000 | T20: m/l
B21: 1 | C21: CUBIERTA MDF 18 + REGRUESO MDF 18MM | D21: 0.7 | E21: 0.7 | F21: FASHION GREY 21371 GL | G21: 66815 | H21: =G21*B21 -> 66815 | M21: =D21+M$19 -> 0.75 | N21: =E21+$N$19 -> 0.72 | O21: =M21*N21 -> 0.54 | P21: =O21*L21 -> 0 | Q21: =Q$20*O21 -> 77164.238 | R21: =Q21+R$20 -> 87164.238 | S21: =M21*L21*2 -> 0 | T21: =N21*L21*2 -> 0
B22: 2 | C22: SEPARADOR 2 CARAS MDF 18 + MDF 18MM | D22: 0.3 | E22: 0.55 | F22: WINTER SAMSARA MAPLE 14689 SF | G22: 38508 | H22: =G22*B22 -> 77016 | L22: =B22 -> 2 | M22: =D22+M$19 -> 0.35 | N22: =E22+$N$19 -> 0.57 | O22: =M22*N22 -> 0.1995 | P22: =O22*L22 -> 0.399 | Q22: =Q$20*O22 -> 28507.899 | R22: =Q22+R$20 -> 38507.899 | S22: =M22*L22*2 -> 1.4 | T22: =N22*L22*2 -> 2.28
B23: 2 | C23: COSTADO 2 CARAS MDF 18 + MDF 18MM | D23: 0.75 | E23: 0.7 | F23: WINTER SAMSARA MAPLE 14689 SF | G23: 92309 | H23: =G23*B23 -> 184618 | L23: =B23 -> 2 | M23: =D23+M$19 -> 0.8 | N23: =E23+$N$19 -> 0.72 | O23: =M23*N23 -> 0.576 | P23: =O23*L23 -> 1.152 | Q23: =Q$20*O23 -> 82308.521 | R23: =Q23+R$20 -> 92308.521 | S23: =M23*L23*2 -> 3.2 | T23: =N23*L23*2 -> 2.88
C24: FRENTE MDF 18 MM 1 CARA | D24: 1.3 | E24: 0.7 | F24: WINTER SAMSARA MAPLE 14689 SF | G24: 136079 | H24: =G24*B24 -> 0 | L24: =B24 -> 0 | M24: =D24+M$19 -> 1.35 | N24: =E24+$N$19 -> 0.72 | O24: =M24*N24 -> 0.972 | P24: =O24*L24 -> 0 | Q24: =Q$20*O24 -> 138895.63 | R24: =Q24+R$20 -> 148895.63 | S24: =M24*L24*2 -> 0
C25: ZOCALO | D25: 1.41 | E25: 0.1 | F25: LAMINA ALUMINIUN | G25: 14000 | H25: =G25*B25 -> 0
B26: 1 | C26: PERFIL 30X30 1MM | D26: 2.8 | G26: 8090 | H26: =G26*B26 -> 8090
G28: NETO | H28: =SUM(H21:H27) -> 336539 | I28: 0.35 | T28: =SUM(T21:T27) -> 5.16
G29: IVA | H29: =H28*19% -> 63942.41 | I29: =H28*35% -> 117788.65 | M29: =SUM(M21:M21) -> 0.75 | P29: =SUM(P21:P27) -> 1.551 | S29: =SUM(S21:S28) -> 4.6
G30: TOTAL | H30: =H28+H29 -> 400481.41 | I30: =H28+I29 -> 454327.65 | P30: =P29 -> 1.551
P31: =P30*20% -> 0.3102 | Q31: 20% PERDIDA | S31: =T28+S29 -> 9.76
P32: =P30+P31 -> 1.8612 | S32: =S31*20% -> 1.952
S33: =S31+S32 -> 11.712 | U33: ADHESIVO | V33: 58.000.- | W33: 44971
M34: =P32 -> 1.8612 | N34: 3500 | O34: =M34*N34 -> 6514.2 | P34: ADHESIVO | U34: LATA 16 LTS | V34: 3625 | W34: LITRO
M35: 1 | N35: 23500 | O35: =M35*N35 -> 23500 | P35: MDF 18MM | V35: 906.25 | W35: MT2 (4)
B36: CUENTA CORRIENTE BANCO SANTANDER Nº 87316181 A NOMBRE DE MUEBLES SANTA FE SPA | N36: 42000 | O36: =M36*N36 -> 0 | P36: MDF 30MM | V36: =V35*20% -> 181.25 | W36: PERDIDA 20%
B37: RUT : 77.054.606-0 VENTAS@TOPMOBILI.CL | M37: 2 | N37: 35364 | O37: =M37*N37 -> 70728 | P37: LAMINA 122X244 | V37: =V35+V36 -> 1087.5 | W37: MINIMO A COTIZAR
B38: VISITANOS Y DESCUBRE NUESTROS PRODUCTOS EN | F38: WWW.TOPMOBILICHILE.CL | N38: 900 | O38: =M38*N38 -> 0 | P38: RESPALDO | R38: 1.52
J39: WHITE OAK | K39: 38300 | N39: 200 | O39: =M39*N39 -> 0 | P39: TAPACANTO PVC 0,45 X 50MM | R39: 2.44
J40: NIEBLA | K40: 31000 | O40: =SUM(O34:O39) -> 100742.2 | P40: COSTO | R40: =R38*R39 -> 3.7088
J41: 73340 | M41: PRECIO VENTA | O41: =O40*2.2 -> 221632.84 | P41: FACTOR 2,3 PARA 90° | R41: =P32/R40 -> 0.50183348
J42: =J41/1.19 -> 61630.252 | O42: =O41/P30 -> 142896.74 | P42: VALOR M2 | U42: MDF30MM | V42: 43650
O43: =O41/O40 -> 2.2 | U43: 46 UNIDADES | V43: 948.91 | W43: 2.4
...

Sheet A2
F2: MUEBLES SANTA FE SPA
F3: VENTAS POR MENOR DE MUEBLES
F4: RUT: 77.054.606-0
F5: SEPTIMA AVENIDA 1631, SAN MIGUEL
F6: FONO +569 2032 3382 | O6: 10077 SF PORTLAND MAPLE
F7: E-MAIL: ventas@topmobili.cl
B8: P R E S U P U E S T O | D8: N° 11720 | J8: 152
J9: 129
B10: NOMBRE: | C10: CONSTRUCTORA HALTRA | F10: FECHA: | G10: 27-10-20255 | J10: =J8-J9 -> 23
B11: RUT: | F11: PLAZO ENTREGA: | G11: 8 DIAS HABILES | R11: MT2 PUERTAS
B12: GIRO: | F12: SERVICIO EXPRESS | G12: NO | J12: 44
B13: CONTACTO: | J13: 114
B14: CORREO: | F14: CORTADA A LA MEDIDA | G14: NO | R14: ML CUBIERTAS
B15: FONO: | C15: 5699833 5638 | F15: DESPACHO: | G15: NO | J15: =SUM(J12:J14) -> 158
B16: DIRECCION: | F16: FORMA DE PAGO: | G16: ABONO 50% SALDO C/ENTREGA
B17: CIUDAD: | C17: SANTIAGO | F17: DURACION COTIZACION: 5 DIAS FRANCO DONOSO
B19: DETALLE | M19: 0.05 | N19: 0.02 | P19: TOTAL | Q19: VALOR X MT2 | R19: ENCHAPE | S19: MT/L
B20: UNIDAD | C20: TIPO | D20: LARGO | E20: ANCHO | F20: COLOR | G20: VALOR | H20: TOTAL | L20: =B20 -> UNIDAD | M20: ALTO | N20: =E20 -> ANCHO | O20: MT | P20: MT2 | Q20: =O42 -> 137786.14 | R20: 10000 | T20: m/l
B21: 1 | C21: CUBIERTA MDF 18 + REGRUESO MDF 18MM | D21: 1.45 | E21: 0.7 | F21: FASHION GREY 21371 GL | G21: 84730 | H21: =G21*B21 -> 84730 | M21: =D21+M$19 -> 1.5 | N21: =E21+$N$19 -> 0.72 | O21: =M21*N21 -> 1.08 | P21: =O21*L21 -> 0 | Q21: =Q$20*O21 -> 148809.04 | R21: =Q21+R$20 -> 158809.04 | S21: =M21*L21*2 -> 0 | T21: =N21*L21*2 -> 0
B22: 1 | C22: SEPARADOR 2 CARAS MDF 18 + MDF 18MM | D22: 1.3 | E22: 1.1 | F22: WINTER SAMSARA MAPLE 14689 SF | G22: 218333 | H22: =G22*B22 -> 218333 | L22: 1 | M22: =D22+M$19 -> 1.35 | N22: =E22+$N$19 -> 1.12 | O22: =M22*N22 -> 1.512 | P22: =O22*L22 -> 1.512 | Q22: =Q$20*O22 -> 208332.65 | R22: =Q22+R$20 -> 218332.65 | S22: =M22*L22*2 -> 2.7 | T22: =N22*L22*2 -> 2.24
B23: 2 | C23: COSTADO 2 CARAS MDF 18 + MDF 18MM | D23: 0.75 | E23: 0.7 | F23: WINTER SAMSARA MAPLE 14689 SF | G23: 89365 | H23: =G23*B23 -> 178730 | L23: 1 | M23: =D23+M$19 -> 0.8 | N23: =E23+$N$19 -> 0.72 | O23: =M23*N23 -> 0.576 | P23: =O23*L23 -> 0.576 | Q23: =Q$20*O23 -> 79364.819 | R23: =Q23+R$20 -> 89364.819 | S23: =M23*L23*2 -> 1.6 | T23: =N23*L23*2 -> 1.44
B24: 1 | C24: FRENTE MDF 18 MM 1 CARA | D24: 1.3 | E24: 0.7 | F24: WINTER SAMSARA MAPLE 14689 SF | G24: 143928 | H24: =G24*B24 -> 143928 | L24: 1 | M24: =D24+M$19 -> 1.35 | N24: =E24+$N$19 -> 0.72 | O24: =M24*N24 -> 0.972 | P24: =O24*L24 -> 0.972 | Q24: =Q$20*O24 -> 133928.13 | R24: =Q24+R$20 -> 143928.13 | S24: =M24*L24*2 -> 2.7
B25: 1 | C25: ZOCALO | D25: 1.41 | E25: 0.1 | F25: LAMINA ALUMINIUN | G25: 14000 | H25: =G25*B25 -> 14000
B26: 1 | C26: PERFIL 30X30 1MM | D26: 2.8 | G26: 8090 | H26: =G26*B26 -> 8090
G28: NETO | H28: =SUM(H21:H27) -> 647811 | I28: 0.35 | T28: =SUM(T21:T27) -> 3.68
G29: IVA | H29: =H28*19% -> 123084.09 | I29: =H28*35% -> 226733.85 | M29: =SUM(M21:M21) -> 1.5 | P29: =SUM(P21:P27) -> 3.06 | S29: =SUM(S21:S28) -> 7
G30: TOTAL | H30: =H28+H29 -> 770895.09 | I30: =H28+I29 -> 874544.85 | P30: =P29 -> 3.06
P31: =P30*20% -> 0.612 | Q31: 20% PERDIDA | S31: =T28+S29 -> 10.68
P32: =P30+P31 -> 3.672 | S32: =S31*20% -> 2.136
S33: =S31+S32 -> 12.816 | U33: ADHESIVO | V33: 58.000.- | W33: 44971
M34: =P32*3 -> 11.016 | N34: 3500 | O34: =M34*N34 -> 38556 | P34: ADHESIVO | U34: LATA 16 LTS | V34: 3625 | W34: LITRO
M35: 2 | N35: 23500 | O35: =M35*N35 -> 47000 | P35: MDF 18MM | V35: 906.25 | W35: MT2 (4)
B36: CUENTA CORRIENTE BANCO SANTANDER Nº 87316181 A NOMBRE DE MUEBLES SANTA FE SPA | N36: 42000 | O36: =M36*N36 -> 0 | P36: MDF 30MM | V36: =V35*20% -> 181.25 | W36: PERDIDA 20%
B37: RUT : 77.054.606-0 VENTAS@TOPMOBILI.CL | M37: 3 | N37: 35364 | O37: =M37*N37 -> 106092 | P37: LAMINA 122X244 | V37: =V35+V36 -> 1087.5 | W37: MINIMO A COTIZAR
B38: VISITANOS Y DESCUBRE NUESTROS PRODUCTOS EN | F38: WWW.TOPMOBILICHILE.CL | N38: 900 | O38: =M38*N38 -> 0 | P38: RESPALDO | R38: 1.52
J39: WHITE OAK | K39: 38300 | N39: 200 | O39: =M39*N39 -> 0 | P39: TAPACANTO PVC 0,45 X 50MM | R39: 2.44
J40: NIEBLA | K40: 31000 | O40: =SUM(O34:O39) -> 191648 | P40: COSTO | R40: =R38*R39 -> 3.7088
J41: 73340 | M41: PRECIO VENTA | O41: =O40*2.2 -> 421625.6 | P41: FACTOR 2,3 PARA 90° | R41: =P32/R40 -> 0.99007765
J42: =J41/1.19 -> 61630.252 | O42: =O41/P30 -> 137786.14 | P42: VALOR M2 | U42: MDF30MM | V42: 43650
O43: =O41/O40 -> 2.2 | U43: 46 UNIDADES | V43: 948.91 | W43: 2.4
...

Sheet E
F2: MUEBLES SANTA FE SPA
F3: VENTAS POR MENOR DE MUEBLES
F4: RUT: 77.054.606-0
F5: SEPTIMA AVENIDA 1631, SAN MIGUEL
F6: FONO +569 2032 3382 | O6: 10077 SF PORTLAND MAPLE
F7: E-MAIL: ventas@topmobili.cl
B8: P R E S U P U E S T O | D8: N° 11720 | J8: 152
J9: 129
B10: NOMBRE: | C10: CONSTRUCTORA HALTRA | F10: FECHA: | G10: 27-10-20255 | J10: =J8-J9 -> 23
B11: RUT: | F11: PLAZO ENTREGA: | G11: 8 DIAS HABILES | R11: MT2 PUERTAS
B12: GIRO: | F12: SERVICIO EXPRESS | G12: NO | J12: 44
B13: CONTACTO: | J13: 114
B14: CORREO: | F14: CORTADA A LA MEDIDA | G14: NO | R14: ML CUBIERTAS
B15: FONO: | C15: 5699833 5638 | F15: DESPACHO: | G15: NO | J15: =SUM(J12:J14) -> 158
B16: DIRECCION: | F16: FORMA DE PAGO: | G16: ABONO 50% SALDO C/ENTREGA
B17: CIUDAD: | C17: SANTIAGO | F17: DURACION COTIZACION: 5 DIAS FRANCO DONOSO
B19: DETALLE | M19: 0.05 | N19: 0.02 | P19: TOTAL | Q19: VALOR X MT2 | R19: ENCHAPE | S19: MT/L
B20: UNIDAD | C20: TIPO | D20: LARGO | E20: ANCHO | F20: COLOR | G20: VALOR | H20: TOTAL | L20: =B20 -> UNIDAD | M20: ALTO | N20: =E20 -> ANCHO | O20: MT | P20: MT2 | Q20: =O42 -> 129711.08 | R20: 10000 | T20: m/l
B21: 1 | C21: CUBIERTA MDF 18 + REGRUESO MDF 18MM | D21: 1.3 | E21: 0.7 | F21: FASHION GREY 21371 GL | G21: 83732 | H21: =G21*B21 -> 83732 | M21: =D21+M$19 -> 1.35 | N21: =E21+$N$19 -> 0.72 | O21: =M21*N21 -> 0.972 | P21: =O21*L21 -> 0 | Q21: =Q$20*O21 -> 126079.17 | R21: =Q21+R$20 -> 136079.17 | S21: =M21*L21*2 -> 0 | T21: =N21*L21*2 -> 0
B22: 2 | C22: SEPARADOR 2 CARAS MDF 18 + MDF 18MM | D22: 1.3 | E22: 1.1 | F22: WINTER SAMSARA MAPLE 14689 SF | G22: 206123 | H22: =G22*B22 -> 412246 | L22: =B22 -> 2 | M22: =D22+M$19 -> 1.35 | N22: =E22+$N$19 -> 1.12 | O22: =M22*N22 -> 1.512 | P22: =O22*L22 -> 3.024 | Q22: =Q$20*O22 -> 196123.15 | R22: =Q22+R$20 -> 206123.15 | S22: =M22*L22*2 -> 5.4 | T22: =N22*L22*2 -> 4.48
B23: 1 | C23: COSTADO 2 CARAS MDF 18 + MDF 18MM | D23: 0.75 | E23: 0.7 | F23: WINTER SAMSARA MAPLE 14689 SF | G23: 84714 | H23: =G23*B23 -> 84714 | L23: 1 | M23: =D23+M$19 -> 0.8 | N23: =E23+$N$19 -> 0.72 | O23: =M23*N23 -> 0.576 | P23: =O23*L23 -> 0.576 | Q23: =Q$20*O23 -> 74713.58 | R23: =Q23+R$20 -> 84713.58 | S23: =M23*L23*2 -> 1.6 | T23: =N23*L23*2 -> 1.44
B24: 1 | C24: FRENTE MDF 18 MM 1 CARA | D24: 1.3 | E24: 0.7 | F24: WINTER SAMSARA MAPLE 14689 SF | G24: 136079 | H24: =G24*B24 -> 136079 | L24: 1 | M24: =D24+M$19 -> 1.35 | N24: =E24+$N$19 -> 0.72 | O24: =M24*N24 -> 0.972 | P24: =O24*L24 -> 0.972 | Q24: =Q$20*O24 -> 126079.17 | R24: =Q24+R$20 -> 136079.17 | S24: =M24*L24*2 -> 2.7
B25: 1 | C25: ZOCALO | D25: 1.41 | E25: 0.1 | F25: LAMINA ALUMINIUN | G25: 14000 | H25: =G25*B25 -> 14000
B26: 1 | C26: PERFIL 30X30 1MM | D26: 2.8 | G26: 8090 | H26: =G26*B26 -> 8090
G28: NETO | H28: =SUM(H21:H27) -> 738861 | I28: 0.35 | T28: =SUM(T21:T27) -> 5.92
G29: IVA | H29: =H28*19% -> 140383.59 | I29: =H28*35% -> 258601.35 | M29: =SUM(M21:M21) -> 1.35 | P29: =SUM(P21:P27) -> 4.572 | S29: =SUM(S21:S28) -> 9.7
G30: TOTAL | H30: =H28+H29 -> 879244.59 | I30: =H28+I29 -> 997462.35 | P30: =P29 -> 4.572
P31: =P30*20% -> 0.9144 | Q31: 20% PERDIDA | S31: =T28+S29 -> 15.62
P32: =P30+P31 -> 5.4864 | S32: =S31*20% -> 3.124
S33: =S31+S32 -> 18.744 | U33: ADHESIVO | V33: 58.000.- | W33: 44971
M34: =P32*3 -> 16.4592 | N34: 3500 | O34: =M34*N34 -> 57607.2 | P34: ADHESIVO | U34: LATA 16 LTS | V34: 3625 | W34: LITRO
M35: 3 | N35: 23500 | O35: =M35*N35 -> 70500 | P35: MDF 18MM | V35: 906.25 | W35: MT2 (4)
B36: CUENTA CORRIENTE BANCO SANTANDER Nº 87316181 A NOMBRE DE MUEBLES SANTA FE SPA | N36: 42000 | O36: =M36*N36 -> 0 | P36: MDF 30MM | V36: =V35*20% -> 181.25 | W36: PERDIDA 20%
B37: RUT : 77.054.606-0 VENTAS@TOPMOBILI.CL | M37: 4 | N37: 35364 | O37: =M37*N37 -> 141456 | P37: LAMINA 122X244 | V37: =V35+V36 -> 1087.5 | W37: MINIMO A COTIZAR
B38: VISITANOS Y DESCUBRE NUESTROS PRODUCTOS EN | F38: WWW.TOPMOBILICHILE.CL | N38: 900 | O38: =M38*N38 -> 0 | P38: RESPALDO | R38: 1.52
J39: WHITE OAK | K39: 38300 | N39: 200 | O39: =M39*N39 -> 0 | P39: TAPACANTO PVC 0,45 X 50MM | R39: 2.44
J40: NIEBLA | K40: 31000 | O40: =SUM(O34:O39) -> 269563.2 | P40: COSTO | R40: =R38*R39 -> 3.7088
J41: 73340 | M41: PRECIO VENTA | O41: =O40*2.2 -> 593039.04 | P41: FACTOR 2,3 PARA 90° | R41: =P32/R40 -> 1.4792925
J42: =J41/1.19 -> 61630.252 | O42: =O41/P30 -> 129711.08 | P42: VALOR M2 | U42: MDF30MM | V42: 43650
O43: =O41/O40 -> 2.2 | U43: 46 UNIDADES | V43: 948.91 | W43: 2.4
...

Sheet D
F2: MUEBLES SANTA FE SPA
F3: VENTAS POR MENOR DE MUEBLES
F4: RUT: 77.054.606-0
F5: SEPTIMA AVENIDA 1631, SAN MIGUEL
F6: FONO +569 2032 3382 | O6: 10077 SF PORTLAND MAPLE
F7: E-MAIL: ventas@topmobili.cl
B8: P R E S U P U E S T O | D8: N° 11720 | J8: 152
J9: 129
B10: NOMBRE: | C10: CONSTRUCTORA HALTRA | F10: FECHA: | G10: 27-10-20255 | J10: =J8-J9 -> 23
B11: RUT: | F11: PLAZO ENTREGA: | G11: 8 DIAS HABILES | R11: MT2 PUERTAS
B12: GIRO: | F12: SERVICIO EXPRESS | G12: NO | J12: 44
B13: CONTACTO: | J13: 114
B14: CORREO: | F14: CORTADA A LA MEDIDA | G14: NO | R14: ML CUBIERTAS
B15: FONO: | C15: 5699833 5638 | F15: DESPACHO: | G15: NO | J15: =SUM(J12:J14) -> 158
B16: DIRECCION: | F16: FORMA DE PAGO: | G16: ABONO 50% SALDO C/ENTREGA
B17: CIUDAD: | C17: SANTIAGO | F17: DURACION COTIZACION: 5 DIAS FRANCO DONOSO
B19: DETALLE | M19: 0.05 | N19: 0.02 | P19: TOTAL | Q19: VALOR X MT2 | R19: ENCHAPE | S19: MT/L
B20: UNIDAD | C20: TIPO | D20: LARGO | E20: ANCHO | F20: COLOR | G20: VALOR | H20: TOTAL | L20: =B20 -> UNIDAD | M20: ALTO | N20: =E20 -> ANCHO | O20: MT | P20: MT2 | Q20: =O42 -> 78417.778 | R20: 10000 | T20: m/l
B21: 1 | C21: CUBIERTA MDF 18 + REGRUESO MDF 18MM | D21: 1.25 | E21: 0.7 | F21: FASHION GREY 21371 GL | G21: 83399 | H21: =G21*B21 -> 83399 | L21: 1 | M21: =D21+M$19 -> 1.3 | N21: =E21+$N$19 -> 0.72 | O21: =M21*N21 -> 0.936 | P21: =O21*L21 -> 0.936 | Q21: =Q$20*O21 -> 73399.04 | R21: =Q21+R$20 -> 83399.04 | S21: =M21*L21*2 -> 2.6 | T21: =N21*L21*2 -> 1.44
C22: SEPARADOR 2 CARAS MDF 18 + MDF 18MM | D22: 1.3 | E22: 1.1 | F22: WINTER SAMSARA MAPLE 14689 SF | G22: 214507 | H22: =G22*B22 -> 0 | M22: =D22+M$19 -> 1.35 | N22: =E22+$N$19 -> 1.12 | O22: =M22*N22 -> 1.512 | P22: =O22*L22 -> 0 | Q22: =Q$20*O22 -> 118567.68 | R22: =Q22+R$20 -> 128567.68 | S22: =M22*L22*2 -> 0 | T22: =N22*L22*2 -> 0
B23: 2 | C23: COSTADO 2 CARAS MDF 18 + MDF 18MM | D23: 0.75 | E23: 0.7 | F23: WINTER SAMSARA MAPLE 14689 SF | G23: 99674 | H23: =G23*B23 -> 199348 | M23: =D23+M$19 -> 0.8 | N23: =E23+$N$19 -> 0.72 | O23: =M23*N23 -> 0.576 | P23: =O23*L23 -> 0 | Q23: =Q$20*O23 -> 45168.64 | R23: =Q23+R$20 -> 55168.64 | S23: =M23*L23*2 -> 0 | T23: =N23*L23*2 -> 0
B24: 1 | C24: FRENTE MDF 18 MM 1 CARA | D24: 1.4 | E24: 0.7 | F24: WINTER SAMSARA MAPLE 14689 SF | G24: 172534 | H24: =G24*B24 -> 172534 | M24: =D24+M$19 -> 1.45 | N24: =E24+$N$19 -> 0.72 | O24: =M24*N24 -> 1.044 | P24: =O24*L24 -> 0 | Q24: =Q$20*O24 -> 81868.16 | R24: =Q24+R$20 -> 91868.16 | S24: =M24*L24*2 -> 0
B25: 1 | C25: ZOCALO | D25: 1.41 | E25: 0.1 | F25: LAMINA ALUMINIUN | G25: 14000 | H25: =G25*B25 -> 14000
B26: 1 | C26: PERFIL 30X30 1MM | D26: 2.8 | G26: 8090 | H26: =G26*B26 -> 8090
G28: NETO | H28: =SUM(H21:H27) -> 477371 | I28: 0.35 | T28: =SUM(T21:T27) -> 1.44
G29: IVA | H29: =H28*19% -> 90700.49 | I29: =H28*35% -> 167079.85 | M29: =SUM(M21:M21) -> 1.3 | P29: =SUM(P21:P27) -> 0.936 | S29: =SUM(S21:S28) -> 2.6
G30: TOTAL | H30: =H28+H29 -> 568071.49 | I30: =H28+I29 -> 644450.85 | P30: =P29 -> 0.936
P31: =P30*20% -> 0.1872 | Q31: 20% PERDIDA | S31: =T28+S29 -> 4.04
P32: =P30+P31 -> 1.1232 | S32: =S31*20% -> 0.808
S33: =S31+S32 -> 4.848 | U33: ADHESIVO | V33: 58.000.- | W33: 44971
M34: =P32 -> 1.1232 | N34: 3500 | O34: =M34*N34 -> 3931.2 | P34: ADHESIVO | U34: LATA 16 LTS | V34: 3625 | W34: LITRO
M35: 0.5 | N35: 23500 | O35: =M35*N35 -> 11750 | P35: MDF 18MM | V35: 906.25 | W35: MT2 (4)
B36: CUENTA CORRIENTE BANCO SANTANDER Nº 87316181 A NOMBRE DE MUEBLES SANTA FE SPA | N36: 42000 | O36: =M36*N36 -> 0 | P36: MDF 30MM | V36: =V35*20% -> 181.25 | W36: PERDIDA 20%
B37: RUT : 77.054.606-0 VENTAS@TOPMOBILI.CL | F37: B | M37: 0.5 | N37: 35364 | O37: =M37*N37 -> 17682 | P37: LAMINA 122X244 | V37: =V35+V36 -> 1087.5 | W37: MINIMO A COTIZAR
B38: VISITANOS Y DESCUBRE NUESTROS PRODUCTOS EN | F38: WWW.TOPMOBILICHILE.CL | N38: 900 | O38: =M38*N38 -> 0 | P38: RESPALDO | R38: 1.52
J39: WHITE OAK | K39: 38300 | N39: 200 | O39: =M39*N39 -> 0 | P39: TAPACANTO PVC 0,45 X 50MM | R39: 2.44
J40: NIEBLA | K40: 31000 | O40: =SUM(O34:O39) -> 33363.2 | P40: COSTO | R40: =R38*R39 -> 3.7088
J41: 73340 | M41: PRECIO VENTA | O41: =O40*2.2 -> 73399.04 | P41: FACTOR 2,3 PARA 90° | R41: =P32/R40 -> 0.30284728
J42: =J41/1.19 -> 61630.252 | O42: =O41/P30 -> 78417.778 | P42: VALOR M2 | U42: MDF30MM | V42: 43650
O43: =O41/O40 -> 2.2 | U43: 46 UNIDADES | V43: 948.91 | W43: 2.4
...

Sheet B
F2: MUEBLES SANTA FE SPA
F3: VENTAS POR MENOR DE MUEBLES
F4: RUT: 77.054.606-0
F5: SEPTIMA AVENIDA 1631, SAN MIGUEL
F6: FONO +569 2032 3382 | O6: 10077 SF PORTLAND MAPLE
F7: E-MAIL: ventas@topmobili.cl
B8: P R E S U P U E S T O | D8: N° 11720 | J8: 152
J9: 129
B10: NOMBRE: | C10: CONSTRUCTORA HALTRA | F10: FECHA: | G10: 27-10-20255 | J10: =J8-J9 -> 23
B11: RUT: | F11: PLAZO ENTREGA: | G11: 8 DIAS HABILES | R11: MT2 PUERTAS
B12: GIRO: | F12: SERVICIO EXPRESS | G12: NO | J12: 44
B13: CONTACTO: | J13: 114
B14: CORREO: | F14: CORTADA A LA MEDIDA | G14: NO | R14: ML CUBIERTAS
B15: FONO: | C15: 5699833 5638 | F15: DESPACHO: | G15: NO | J15: =SUM(J12:J14) -> 158
B16: DIRECCION: | F16: FORMA DE PAGO: | G16: ABONO 50% SALDO C/ENTREGA
B17: CIUDAD: | C17: SANTIAGO | F17: DURACION COTIZACION: 5 DIAS FRANCO DONOSO
B19: DETALLE | M19: 0.05 | N19: 0.02 | P19: TOTAL | Q19: VALOR X MT2 | R19: ENCHAPE | S19: MT/L
B20: UNIDAD | C20: TIPO | D20: LARGO | E20: ANCHO | F20: COLOR | G20: VALOR | H20: TOTAL | L20: =B20 -> UNIDAD | M20: ALTO | N20: =E20 -> ANCHO | O20: MT | P20: MT2 | Q20: =O42 -> 89741.456 | R20: 10000 | T20: m/l
B21: 1 | C21: CUBIERTA MDF 18 + REGRUESO MDF 18MM | D21: 1.4 | E21: 0.7 | F21: FASHION GREY 21371 GL | G21: 103690 | H21: =G21*B21 -> 103690 | L21: 1 | M21: =D21+M$19 -> 1.45 | N21: =E21+$N$19 -> 0.72 | O21: =M21*N21 -> 1.044 | P21: =O21*L21 -> 1.044 | Q21: =Q$20*O21 -> 93690.08 | R21: =Q21+R$20 -> 103690.08 | S21: =M21*L21*2 -> 2.9 | T21: =N21*L21*2 -> 1.44
C22: SEPARADOR 2 CARAS MDF 18 + MDF 18MM | D22: 1.3 | E22: 1.1 | F22: WINTER SAMSARA MAPLE 14689 SF | G22: 214507 | H22: =G22*B22 -> 0 | M22: =D22+M$19 -> 1.35 | N22: =E22+$N$19 -> 1.12 | O22: =M22*N22 -> 1.512 | P22: =O22*L22 -> 0 | Q22: =Q$20*O22 -> 135689.08 | R22: =Q22+R$20 -> 145689.08 | S22: =M22*L22*2 -> 0 | T22: =N22*L22*2 -> 0
B23: 2 | C23: COSTADO 2 CARAS MDF 18 + MDF 18MM | D23: 0.75 | E23: 0.7 | F23: WINTER SAMSARA MAPLE 14689 SF | G23: 99674 | H23: =G23*B23 -> 199348 | M23: =D23+M$19 -> 0.8 | N23: =E23+$N$19 -> 0.72 | O23: =M23*N23 -> 0.576 | P23: =O23*L23 -> 0 | Q23: =Q$20*O23 -> 51691.079 | R23: =Q23+R$20 -> 61691.079 | S23: =M23*L23*2 -> 0 | T23: =N23*L23*2 -> 0
B24: 1 | C24: FRENTE MDF 18 MM 1 CARA | D24: 1.4 | E24: 0.7 | F24: WINTER SAMSARA MAPLE 14689 SF | G24: 172534 | H24: =G24*B24 -> 172534 | M24: =D24+M$19 -> 1.45 | N24: =E24+$N$19 -> 0.72 | O24: =M24*N24 -> 1.044 | P24: =O24*L24 -> 0 | Q24: =Q$20*O24 -> 93690.08 | R24: =Q24+R$20 -> 103690.08 | S24: =M24*L24*2 -> 0
B25: 1 | C25: ZOCALO | D25: 1.41 | E25: 0.1 | F25: LAMINA ALUMINIUN | G25: 14000 | H25: =G25*B25 -> 14000
B26: 1 | C26: PERFIL 30X30 1MM | D26: 2.8 | G26: 8090 | H26: =G26*B26 -> 8090
G28: NETO | H28: =SUM(H21:H27) -> 497662 | I28: 0.35 | T28: =SUM(T21:T27) -> 1.44
G29: IVA | H29: =H28*19% -> 94555.78 | I29: =H28*35% -> 174181.7 | M29: =SUM(M21:M21) -> 1.45 | P29: =SUM(P21:P27) -> 1.044 | S29: =SUM(S21:S28) -> 2.9
G30: TOTAL | H30: =H28+H29 -> 592217.78 | I30: =H28+I29 -> 671843.7 | P30: =P29 -> 1.044
P31: =P30*20% -> 0.2088 | Q31: 20% PERDIDA | S31: =T28+S29 -> 4.34
P32: =P30+P31 -> 1.2528 | S32: =S31*20% -> 0.868
S33: =S31+S32 -> 5.208 | U33: ADHESIVO | V33: 58.000.- | W33: 44971
M34: =P32*3 -> 3.7584 | N34: 3500 | O34: =M34*N34 -> 13154.4 | P34: ADHESIVO | U34: LATA 16 LTS | V34: 3625 | W34: LITRO
M35: 0.5 | N35: 23500 | O35: =M35*N35 -> 11750 | P35: MDF 18MM | V35: 906.25 | W35: MT2 (4)
B36: CUENTA CORRIENTE BANCO SANTANDER Nº 87316181 A NOMBRE DE MUEBLES SANTA FE SPA | N36: 42000 | O36: =M36*N36 -> 0 | P36: MDF 30MM | V36: =V35*20% -> 181.25 | W36: PERDIDA 20%
B37: RUT : 77.054.606-0 VENTAS@TOPMOBILI.CL | F37: B | M37: 0.5 | N37: 35364 | O37: =M37*N37 -> 17682 | P37: LAMINA 122X244 | V37: =V35+V36 -> 1087.5 | W37: MINIMO A COTIZAR
B38: VISITANOS Y DESCUBRE NUESTROS PRODUCTOS EN | F38: WWW.TOPMOBILICHILE.CL | N38: 900 | O38: =M38*N38 -> 0 | P38: RESPALDO | R38: 1.52
J39: WHITE OAK | K39: 38300 | N39: 200 | O39: =M39*N39 -> 0 | P39: TAPACANTO PVC 0,45 X 50MM | R39: 2.44
J40: NIEBLA | K40: 31000 | O40: =SUM(O34:O39) -> 42586.4 | P40: COSTO | R40: =R38*R39 -> 3.7088
J41: 73340 | M41: PRECIO VENTA | O41: =O40*2.2 -> 93690.08 | P41: FACTOR 2,3 PARA 90° | R41: =P32/R40 -> 0.3377912
J42: =J41/1.19 -> 61630.252 | O42: =O41/P30 -> 89741.456 | P42: VALOR M2 | U42: MDF30MM | V42: 43650
O43: =O41/O40 -> 2.2 | U43: 46 UNIDADES | V43: 948.91 | W43: 2.4
...

Sheet A1
F2: MUEBLES SANTA FE SPA
F3: VENTAS POR MENOR DE MUEBLES
F4: RUT: 77.054.606-0
F5: SEPTIMA AVENIDA 1631, SAN MIGUEL
F6: FONO +569 2032 3382 | O6: 10077 SF PORTLAND MAPLE
F7: E-MAIL: ventas@topmobili.cl
B8: P R E S U P U E S T O | D8: N° 11720 | J8: 152
J9: 129
B10: NOMBRE: | C10: CONSTRUCTORA HALTRA | F10: FECHA: | G10: 27-10-20255 | J10: =J8-J9 -> 23
B11: RUT: | F11: PLAZO ENTREGA: | G11: 8 DIAS HABILES | R11: MT2 PUERTAS
B12: GIRO: | F12: SERVICIO EXPRESS | G12: NO | J12: 44
B13: CONTACTO: | J13: 114
B14: CORREO: | F14: CORTADA A LA MEDIDA | G14: NO | R14: ML CUBIERTAS
B15: FONO: | C15: 5699833 5638 | F15: DESPACHO: | G15: NO | J15: =SUM(J12:J14) -> 158
B16: DIRECCION: | F16: FORMA DE PAGO: | G16: ABONO 50% SALDO C/ENTREGA
B17: CIUDAD: | C17: SANTIAGO | F17: DURACION COTIZACION: 5 DIAS FRANCO DONOSO
B19: DETALLE | M19: 0.05 | N19: 0.02 | P19: TOTAL | Q19: VALOR X MT2 | R19: ENCHAPE | S19: MT/L
B20: UNIDAD | C20: TIPO | D20: LARGO | E20: ANCHO | F20: COLOR | G20: VALOR | H20: TOTAL | L20: =B20 -> UNIDAD | M20: ALTO | N20: =E20 -> ANCHO | O20: MT | P20: MT2 | Q20: =O42 -> 69194.074 | R20: 10000 | T20: m/l
B21: 1 | C21: CUBIERTA MDF 18 + REGRUESO MDF 18MM | D21: 1.45 | E21: 0.7 | F21: FASHION GREY 21371 GL | G21: 84730 | H21: =G21*B21 -> 84730 | L21: 1 | M21: =D21+M$19 -> 1.5 | N21: =E21+$N$19 -> 0.72 | O21: =M21*N21 -> 1.08 | P21: =O21*L21 -> 1.08 | Q21: =Q$20*O21 -> 74729.6 | R21: =Q21+R$20 -> 84729.6 | S21: =M21*L21*2 -> 3 | T21: =N21*L21*2 -> 1.44
B22: 1 | C22: SEPARADOR 2 CARAS MDF 18 + MDF 18MM | D22: 1.3 | E22: 1.1 | F22: WINTER SAMSARA MAPLE 14689 SF | G22: 214134 | H22: =G22*B22 -> 214134 | M22: =D22+M$19 -> 1.35 | N22: =E22+$N$19 -> 1.12 | O22: =M22*N22 -> 1.512 | P22: =O22*L22 -> 0 | Q22: =Q$20*O22 -> 104621.44 | R22: =Q22+R$20 -> 114621.44 | S22: =M22*L22*2 -> 0 | T22: =N22*L22*2 -> 0
B23: 1 | C23: COSTADO 2 CARAS MDF 18 + MDF 18MM | D23: 0.75 | E23: 0.7 | F23: WINTER SAMSARA MAPLE 14689 SF | G23: 87765 | H23: =G23*B23 -> 87765 | M23: =D23+M$19 -> 0.8 | N23: =E23+$N$19 -> 0.72 | O23: =M23*N23 -> 0.576 | P23: =O23*L23 -> 0 | Q23: =Q$20*O23 -> 39855.787 | R23: =Q23+R$20 -> 49855.787 | S23: =M23*L23*2 -> 0 | T23: =N23*L23*2 -> 0
B24: 1 | C24: FRENTE MDF 18 MM 1 CARA | D24: 1.41 | E24: 0.7 | F24: WINTER SAMSARA MAPLE 14689 SF | G24: 151922 | H24: =G24*B24 -> 151922 | M24: =D24+M$19 -> 1.46 | N24: =E24+$N$19 -> 0.72 | O24: =M24*N24 -> 1.0512 | P24: =O24*L24 -> 0 | Q24: =Q$20*O24 -> 72736.811 | R24: =Q24+R$20 -> 82736.811 | S24: =M24*L24*2 -> 0
B25: 1 | C25: ZOCALO | D25: 1.41 | E25: 0.1 | F25: LAMINA ALUMINIUN | G25: 14000 | H25: =G25*B25 -> 14000
B26: 1 | C26: PERFIL 30X30 1MM | D26: 2.8 | G26: 8090 | H26: =G26*B26 -> 8090
G28: NETO | H28: =SUM(H21:H27) -> 560641 | I28: 0.35 | T28: =SUM(T21:T27) -> 1.44
G29: IVA | H29: =H28*19% -> 106521.79 | I29: =H28*35% -> 196224.35 | M29: =SUM(M21:M21) -> 1.5 | P29: =SUM(P21:P27) -> 1.08 | S29: =SUM(S21:S28) -> 3
G30: TOTAL | H30: =H28+H29 -> 667162.79 | I30: =H28+I29 -> 756865.35 | P30: =P29 -> 1.08
P31: =P30*20% -> 0.216 | Q31: 20% PERDIDA | S31: =T28+S29 -> 4.44
P32: =P30+P31 -> 1.296 | S32: =S31*20% -> 0.888
S33: =S31+S32 -> 5.328 | U33: ADHESIVO | V33: 58.000.- | W33: 44971
M34: =P32 -> 1.296 | N34: 3500 | O34: =M34*N34 -> 4536 | P34: ADHESIVO | U34: LATA 16 LTS | V34: 3625 | W34: LITRO
M35: 0.5 | N35: 23500 | O35: =M35*N35 -> 11750 | P35: MDF 18MM | V35: 906.25 | W35: MT2 (4)
B36: CUENTA CORRIENTE BANCO SANTANDER Nº 87316181 A NOMBRE DE MUEBLES SANTA FE SPA | N36: 42000 | O36: =M36*N36 -> 0 | P36: MDF 30MM | V36: =V35*20% -> 181.25 | W36: PERDIDA 20%
B37: RUT : 77.054.606-0 VENTAS@TOPMOBILI.CL | M37: 0.5 | N37: 35364 | O37: =M37*N37 -> 17682 | P37: LAMINA 122X244 | V37: =V35+V36 -> 1087.5 | W37: MINIMO A COTIZAR
B38: VISITANOS Y DESCUBRE NUESTROS PRODUCTOS EN | F38: WWW.TOPMOBILICHILE.CL | N38: 900 | O38: =M38*N38 -> 0 | P38: RESPALDO | R38: 1.52
J39: WHITE OAK | K39: 38300 | N39: 200 | O39: =M39*N39 -> 0 | P39: TAPACANTO PVC 0,45 X 50MM | R39: 2.44
J40: NIEBLA | K40: 31000 | O40: =SUM(O34:O39) -> 33968 | P40: COSTO | R40: =R38*R39 -> 3.7088
J41: 73340 | M41: PRECIO VENTA | O41: =O40*2.2 -> 74729.6 | P41: FACTOR 2,3 PARA 90° | R41: =P32/R40 -> 0.34943917
J42: =J41/1.19 -> 61630.252 | O42: =O41/P30 -> 69194.074 | P42: VALOR M2 | U42: MDF30MM | V42: 43650
O43: =O41/O40 -> 2.2 | U43: 46 UNIDADES | V43: 948.91 | W43: 2.4
...

Sheet COSTOS
B2: CENTRO DE COSTOS POSTFORMADOS
B5: FECHA: | C5: ='A1'!G10 -> 27-10-20255
B6: CLIENTE: | C6: ='A1'!C10 -> CONSTRUCTORA HALTRA | N6: Ventas Equilibrio = | P6: Costos Fijos Totales
B7: DIRECCION: | C7: ='A1'!#REF! -> #REF! | H7: COSTOS INDIRECTOS DE FABRICA VARIABLES | O7: 1 - | P7: Costos Variables Totales
B8: PRESUPUESTO: | C8: ='A1'!D8 -> N° 11720 | H8: Q/HRS | I8: $ | J8: DETALLE | K8: TOTAL | L8: TOTAL | P8: Total Venta | X8: =SUM(Q11:Q16) -> 6
H9: CANTIDAD | I9: PRECIO | J9: MATERIA PRIMA INDIRECTA | L9: =SUM(K10:K23) -> 2550 | S9: DETALLE | X9: =(E15-D11)/X8 -> -80757.142
D10: NETO | E10: IVA | F10: TOTAL | H10: 3 | I10: 350 | J10: RESPALDO | K10: =I10*H10 -> 1050 | Q10: UNIDAD | R10: TIPO | S10: LARGO | T10: ANCHO | U10: COLOR | V10: VALOR | W10: TOTAL
C11: MONTO A COBRAR | D11: ='A1'!H28 -> 560641 | E11: =D11*0.19 -> 106521.79 | F11: =E11+D11 -> 667162.79 | H11: 3 | I11: 500 | J11: MEDIA CAÑA | K11: =I11*H11 -> 1500 | Q11: 1 | R11: CUB C/R R8 | S11: 2.8 | T11: 0.62 | U11: MADERA X DEFINIR | V11: 105990 | W11: =V11*Q11 -> 105990 | X11: =V11+$X$9 -> 25232.858 | Y11: 108990
C12: COSTO TOTAL | D12: =SUM(M43:M45) -> 46120.091 | H12: 0 | I12: 7500 | J12: DUROLAC | K12: =I12*H12 -> 0 | Q12: 1 | R12: CUB C/R R8 | S12: 2.3 | T12: 0.62 | U12: MADERA X DEFINIR | V12: 87990 | W12: =V12*Q12 -> 87990 | X12: =V12+$X$9 -> 7232.8583 | Y12: 89990
C13: % UTILIDAD | D13: =D11-D12 -> 514520.91 | E13: =(D11/D12)-1 -> 11.156112 | H13: 0 | I13: 50 | J13: TAPACANTO PVC | K13: =I13*H13 -> 0 | Q13: 1 | R13: CUB C/R R8 | S13: 2.03 | T13: 0.62 | U13: MADERA X DEFINIR | V13: 78990 | W13: =V13*Q13 -> 78990 | X13: =V13+$X$9 -> -1767.1417 | Y13: 81990
D14: % utilidad | E14: NETO | F14: UTILIDAD | H14: 0 | I14: 50 | J14: SOBERBIOS | K14: =I14*H14 -> 0 | Q14: 1 | R14: CUB C/R R8 | S14: 1.08 | T14: 0.62 | U14: MADERA X DEFINIR | V14: 39990 | W14: =V14*Q14 -> 39990 | X14: =V14+$X$9 -> -40767.142 | Y14: 39990
C15: PROYECCION | D15: 0.65 | E15: =(100%+D15)*D12 -> 76098.15 | F15: =E15-D12 -> 29978.059 | H15: 0 | I15: 10 | J15: SOPORTE REPISA | K15: =I15*H15 -> 0 | Q15: 1 | R15: CUB C/R R8 | S15: 1.08 | T15: 0.62 | U15: MADERA X DEFINIR | V15: 39990 | W15: =V15*Q15 -> 39990 | X15: =V15+$X$9 -> -40767.142 | Y15: 39990
H16: 1 | J16: PUNTAS | K16: =I16*H16 -> 0 | Q16: 1 | R16: CUB C/R R8 | S16: 2.06 | T16: 0.62 | U16: MADERA X DEFINIR | V16: 79990 | W16: =V16*Q16 -> 79990 | X16: =V16+$X$9 -> -767.1417 | Y16: 83990
B17: M. PRIMA | C17: MATERIAL | D17: NETO | E17: IVA | F17: TOTAL | H17: 1 | J17: TORNILLOS | K17: =I17*H17 -> 0 | Q17: 6 | R17: CORTES 45° | V17: 5000 | W17: =V17*Q17 -> 30000
C18: LAMINA | D18: ='A1'!O36 -> 0 | E18: =D18*0.19 -> 0 | F18: =SUM(D18:E18) -> 0 | H18: 1 | J18: COLAFRIA | K18: =I18*H18 -> 0 | Q18: 1 | R18: PERFORACION LAVAPLATOS | V18: 10000 | W18: =V18*Q18 -> 10000
C19: MDF 18MM | D19: ='A1'!O35 -> 11750 | E19: =D19*0.19 -> 2232.5 | F19: =SUM(D19:E19) -> 13982.5 | H19: 1 | J19: LIJAS | K19: =I19*H19 -> 0 | V19: NETO | W19: =SUM(W11:W18) -> 472940 | Y19: =SUM(Y11:Y16)+SUM(W17:W18) -> 484940
C20: ADHESIVO | D20: ='A1'!O34 -> 4536 | E20: =D20*0.19 -> 861.84 | F20: =SUM(D20:E20) -> 5397.84 | H20: 1 | J20: CARTON | K20: =I20*H20 -> 0 | V20: I.V.A. | W20: =W19*19% -> 89858.6 | Y20: =Y19*0.19 -> 92138.6
A21: =450000*1.2 -> 540000 | C21: TOTAL | D21: =SUM(D18:D20) -> 16286 | E21: =SUM(E18:E20) -> 3094.34 | F21: =SUM(F18:F20) -> 19380.34 | H21: 1 | J21: GUAIPE | K21: =I21*H21 -> 0 | M21: =B32/9 -> 2318.8406 | Q21: PLAZO DE ENTREGA : 8 DIAS HABILES | V21: TOTAL | W21: =W19+W20 -> 562798.6 | Y21: =SUM(Y19:Y20) -> 577078.6
A22: =450000*1.2 -> 540000 | B22: M. DE OBRA | C22: PROCESO | D22: COSTO x Hr. | E22: Q Hrs. | F22: TOTAL | H22: 1 | J22: DILUYENTE | K22: =I22*H22 -> 0 | Q22: FORMA DE PAGO: 50% CONTADO, SALDO C/E
A23: =800000*1.2 -> 960000 | B23: =A21/23 -> 23478.261 | C23: CORTE | D23: =B23/9 -> 2608.6957 | E23: 0.5 | F23: =D23*E23 -> 1304.3478 | H23: 1 | J23: CINTA EMBALAJE | K23: =I23*H23 -> 0 | Q23: VALIDEZ COTIZACIÓN: 5 DIAS
A24: 450000 | B24: =A22/23 -> 23478.261 | C24: CORTE LAMINA | D24: =B24/9 -> 2608.6957 | E24: 0.5 | F24: =D24*E24 -> 1304.3478 | H24: Q/HRS | I24: PRECIO | J24: MANO DE OBRA INDIRECTA | K24: VALOR | L24: =SUM(K25:K35) -> 0
A25: 450000 | B25: =A23/23 -> 41739.13 | C25: REBAJE LAMINA | D25: =B25/9 -> 4637.6812 | F25: =D25*E25 -> 0 | H25: 0 | I25: =((480000/23)/9) -> 2318.8406 | J25: FLETERO (HRS) | K25: =H25*I25 -> 0
B26: =A24/23 -> 19565.217 | C26: TUPIZADO | D26: =B26/9 -> 2173.913 | E26: 0.5 | F26: =D26*E26 -> 1086.9565 | H26: 0 | J26: BENCINA | K26: =H26*I26 -> 0
A27: 350000 | B27: =A25/23 -> 19565.217 | C27: ARMADO | D27: =B27/9 -> 2173.913 | E27: 0.5 | F27: =D27*E27 -> 1086.9565 | H27: 0 | J27: TAG | K27: =H27*I27 -> 0
A28: 500000 | B28: =A27/23 -> 15217.391 | C28: PEGADO | D28: =B28/9 -> 1690.8213 | E28: 0.7 | F28: =D28*E28 -> 1183.5749 | H28: 0 | J28: RECTIFICACION | K28: =H28*I28 -> 0
B29: =A28/23 -> 21739.13 | C29: POSTFORMADO | D29: =B29/9 -> 2415.4589 | E29: 0.7 | F29: =D29*E29 -> 1690.8213 | H29: 0 | I29: =((550000*1.2)/23)/9 -> 3188.4058 | J29: HR. TRAB. JUAN | K29: =H29*I29 -> 0
A30: 450000 | C30: MEDIA CAÑA | D30: 2415 | F30: =D30*E30 -> 0 | H30: 0 | I30: =((450000*1.2)/23)/9 -> 2608.6957 | J30: HR. TRAB. JULIO | K30: =H30*I30 -> 0
A31: 350000 | B31: =A30/23 -> 19565.217 | C31: CORTE-ENCHAPE | D31: =B31/9 -> 2173.913 | E31: 0 | F31: =D31*E31 -> 0 | H31: 0 | I31: =((450000*1.2)/23)/9 -> 2608.6957 | J31: HR. TRAB. EUGE | K31: =H31*I31 -> 0
A32: =A21+A24+A27+A28+A30 -> 2290000 | B32: =480000/23 -> 20869.565 | C32: CONTROL CALIDAD | D32: =B32/9 -> 2318.8406 | E32: 0.5 | F32: =D32*E32 -> 1159.4203 | H32: 0 | J32: COLACION | K32: =H32*I32 -> 0
C33: TOTAL | D33: =SUM(D23:D32) -> 25216.932 | E33: =SUM(E23:E32) -> 3.9 | F33: =SUM(F23:F32) -> 8816.4251 | H33: 0 | J33: BONO | K33: =H33*I33 -> 0
B34: CIF | C34: M. PRIMA INDIREC. | D34: =L9 -> 2550 | H34: 1 | J34: PERFORACION | K34: =H34*I34 -> 0
C35: M. OBRA INDIRECTA | D35: =L24 -> 0 | H35: 6 | J35: CORTE 45 | K35: =H35*I35 -> 0
C36: GASTOS DE FABRICA | D36: =L36 -> 18467.666 | H36: CANTIDAD | I36: PRECIO | J36: GASTOS DE FABRICACION | K36: VALOR | L36: =SUM(K37:K39) -> 18467.666
C37: DEPRECIACIONES | H37: =$E$33 -> 3.9 | I37: =32609.69/9 -> 3623.2989 | J37: ARRIENDO x HORA | K37: =I37*H37 -> 14130.866
C38: TOTAL | D38: =SUM(D34:D37) -> 21017.666 | H38: =$E$33 -> 3.9 | I38: 967 | J38: AGUA x HORA | K38: =I38*H38 -> 3771.3
H39: =$E$33 -> 3.9 | I39: 145 | J39: LUZ x HORA | K39: =I39*H39 -> 565.5
B40: PROVISIONAR | C40: IVA | D40: =E11-E21 -> 103427.45
H41: ESTADO DE RESULTADOS
B42: TOTAL HRS TRABAJADAS | D42: =E33 -> 3.9 | H42: INGRESOS | I42: + TOTAL VENTA | M42: =D11 -> 560641
H43: COSTOS | I43: - MATERIA PRIMA DIRECTA | M43: =D21 -> 16286
...
