Workbook

Sheet ESTANTERIA OF 1
M1: M. BAJO
F2: MUEBLES SANTA FE SPA
F3: VENTAS POR MENOR DE MUEBLES
F4: RUT: 77.054.606-0
F5: SEPTIMA AVENIDA 1631, SAN MIGUEL
F6: FONO +569 2032 3382 | O6: 10077 SF PORTLAND MAPLE
F7: E-MAIL: ventas@topmobili.cl
B8: P R E S U P U E S T O | D8: N° 12076
B10: NOMBRE: | C10: JAVIER MOYA | F10: FECHA | G10: 46113
B11: RUT: | F11: PLAZO ENTREGA | G11: 15 DIAS HABILES | R11: MT2 PUERTAS
B12: GIRO: | F12: SERVICIO EXPRESS | G12: NO
B13: CONTACTO: | F13: CORTADA A LA MEDIDA | G13: NO
B14: CORREO: | F14: DESPACHO | G14: NO | R14: ML CUBIERTAS
B15: FONO: | C15: +56 9 6609 2180 | F15: INSTALACIÓN | G15: NO
B16: DIRECCION: | F16: FORMA DE PAGO: | G16: ABONO 50% SALDO C/ENTREGA
B17: CIUDAD: | C17: SANTIAGO | F17: Duración cotización 5 días hábiles | G17: Cotizado por: Franco Donoso
B19: DETALLE | M19: 0.05 | P19: TOTAL | Q19: VALOR X MT2 | R19: ENCHAPE | S19: MT/L
B20: UNIDAD | C20: TIPO | D20: LARGO | E20: ANCHO | F20: COLOR | G20: VALOR | H20: TOTAL | L20: =B20 -> UNIDAD | M20: ALTO | N20: =E20 -> ANCHO | O20: MT | P20: MT2 | Q20: =O41 -> 48412.842 | R20: 15000 | T20: m/l
B21: 2 | C21: ENCHAPE RECTO 1 CARAS MDF 18MM | D21: 2.45 | E21: 0.45 | F21: BLANCO OPACO 2114 MT | G21: 54464 | H21: =G21*B21 -> 108928 | L21: =B21 -> 2 | M21: =D21+M$19 -> 2.5 | N21: =E21+$N$19 -> 0.45 | O21: =M21*N21 -> 1.125 | P21: =O21*L21 -> 2.25 | Q21: =Q$20*O21 -> 54464.447 | R21: =Q21+R$20 -> 69464.447 | S21: =M21*L21*2 -> 10
B22: 3 | C22: ENCHAPE RECTO 1 CARAS MDF 18MM | D22: 0.92 | E22: 0.466 | F22: BLANCO OPACO 2114 MT | G22: 21884 | H22: =G22*B22 -> 65652 | L22: =B22 -> 3 | M22: =D22+M$19 -> 0.97 | N22: =E22+$N$19 -> 0.466 | O22: =M22*N22 -> 0.45202 | P22: =O22*L22 -> 1.35606 | Q22: =Q$20*O22 -> 21883.573 | R22: =Q22+R$20 -> 36883.573
B23: 3 | C23: ENCHAPE RECTO 1 CARAS MDF 25MM | D23: 1.53 | E23: 0.466 | F23: BLANCO OPACO 2114 MT | G23: 35645 | H23: =G23*B23 -> 106935 | L23: =B23 -> 3 | M23: =D23+M$19 -> 1.58 | N23: =E23+$N$19 -> 0.466 | O23: =M23*N23 -> 0.73628 | P23: =O23*L23 -> 2.20884 | Q23: =Q$20*O23 -> 35645.407 | R23: =Q23+R$20 -> 50645.407 | S23: =M23*L23*2 -> 9.48
B24: 1 | C24: ENCHAPE RECTO 2 CARAS MDF 25MM | D24: 1.4 | E24: 0.45 | F24: BLANCO OPACO 2114 MT | G24: 73930 | H24: =G24*B24 -> 73930 | M24: =D24+M$19 -> 1.45 | N24: =E24+$N$19 -> 0.45 | O24: =M24*N24 -> 0.6525 | P24: =O24*L24 -> 0 | Q24: =Q$20*O24 -> 31589.38 | R24: =Q24+R$20 -> 46589.38 | S24: =M24*L24*2 -> 0 | T24: =N24*L24*2 -> 0
B25: 1 | C25: ENCHAPE RECTO 1 CARAS MDF 25MM | D25: 1.4 | E25: 0.45 | F25: BLANCO OPACO 2114 MT | G25: 73930 | H25: =G25*B25 -> 73930 | M25: =D25+M$19 -> 1.45 | N25: =E25+$N$19 -> 0.45 | O25: =M25*N25 -> 0.6525 | P25: =O25*L25 -> 0 | Q25: =Q$20*O25 -> 31589.38 | R25: =Q25+R$20 -> 46589.38 | S25: =M25*L25*2 -> 0 | T25: =N25*L25*2 -> 0
G27: NETO | H27: =SUM(H21:H25) -> 429375 | T27: =SUM(T21:T25) -> 0
G28: IVA | H28: =H27*19% -> 81581.25 | L28: =M28*10 -> 79.5 | M28: =SUM(M21:M27) -> 7.95 | P28: =SUM(P21:P25) -> 5.8149
G29: TOTAL | H29: =H27+H28 -> 510956.25 | P29: =P28 -> 5.8149 | S29: =SUM(S21:S28) -> 19.48
P30: =P29*20% -> 1.16298 | Q30: 20% PERDIDA | S30: =S29+T27 -> 19.48
P31: =P29+P30 -> 6.97788 | S31: =S30*20% -> 3.896
S32: =S30+S31 -> 23.376 | U32: ADHESIVO | V32: 58.000.- | W32: 44971
M33: =P31*2 -> 13.95576 | N33: 3500 | O33: =M33*N33 -> 48845.16 | P33: ADHESIVO | U33: LATA 16 LTS | V33: 3625 | W33: LITRO
M34: 2 | N34: 42950 | O34: 24910 | P34: MDF MELAMIL 18MM 1C | V34: 906.25 | W34: MT2 (4)
B35: CUENTA CORRIENTE BANCO SANTANDER Nº 87316181 A NOMBRE DE MUEBLES SANTA FE SPA | M35: 1 | N35: 33975 | O35: =M35*N35 -> 33975 | P35: TAPACANTO PVC 50MTS 29X2 | V35: =V34*20% -> 181.25 | W35: PERDIDA 20%
B36: RUT : 77.054.606-0 CORREO: FRANCODONOSO@TOPMOBILI.CL | M36: 1.5 | N36: 17550 | O36: =M36*N36 -> 26325 | P36: LAMINA 122X244 | V36: =V34+V35 -> 1087.5 | W36: MINIMO A COTIZAR
A37: GE | B37: VISITANOS Y DESCUBRE NUESTROS PRODUCTOS EN | F37: WWW.TOPMOBILICHILE.CL | N37: 900 | O37: =M37*N37 -> 0 | P37: RESPALDO | R37: 3.05 | S37: 0.5
N38: 1500 | O38: =M38*N38 -> 0 | P38: MEDIA CAÑA | R38: 1.22
O39: =SUM(O33:O38) -> 134055.16 | P39: COSTO | R39: =R37*R38 -> 3.721
M40: PRECIO VENTA | O40: =O39*2.1 -> 281515.84 | P40: FACTOR 2,3 PARA 90° | R40: =P31/R39 -> 1.8752701
K41: 51290 | O41: =O40/P29 -> 48412.842 | P41: VALOR M2 | U41: MDF30MM | V41: 43650
K42: =K41/1.19 -> 43100.84 | O42: =O40/O39 -> 2.1 | U42: 46 UNIDADES | V42: 948.91 | W42: 2.4
U43: METRO LINEAL | V43: 395.37
...

Sheet M. BAJO VENTANA
M1: M. BAJO
F2: MUEBLES SANTA FE SPA
F3: VENTAS POR MENOR DE MUEBLES
F4: RUT: 77.054.606-0
F5: SEPTIMA AVENIDA 1631, SAN MIGUEL
F6: FONO +569 2032 3382 | O6: 10077 SF PORTLAND MAPLE
F7: E-MAIL: ventas@topmobili.cl
B8: P R E S U P U E S T O | D8: N° 12076
B10: NOMBRE: | C10: JAVIER MOYA | F10: FECHA | G10: 46113
B11: RUT: | F11: PLAZO ENTREGA | G11: 15 DIAS HABILES | R11: MT2 PUERTAS
B12: GIRO: | F12: SERVICIO EXPRESS | G12: NO
B13: CONTACTO: | F13: CORTADA A LA MEDIDA | G13: NO
B14: CORREO: | F14: DESPACHO | G14: NO | R14: ML CUBIERTAS
B15: FONO: | C15: +56 9 6609 2180 | F15: INSTALACIÓN | G15: NO
B16: DIRECCION: | F16: FORMA DE PAGO: | G16: ABONO 50% SALDO C/ENTREGA
B17: CIUDAD: | C17: SANTIAGO | F17: Duración cotización 5 días hábiles | G17: Cotizado por: Franco Donoso
B19: DETALLE | M19: 0.05 | P19: TOTAL | Q19: VALOR X MT2 | R19: ENCHAPE | S19: MT/L
B20: UNIDAD | C20: TIPO | D20: LARGO | E20: ANCHO | F20: COLOR | G20: VALOR | H20: TOTAL | L20: =B20 -> UNIDAD | M20: ALTO | N20: =E20 -> ANCHO | O20: MT | P20: MT2 | Q20: =O41 -> 102861.24 | R20: 15000 | T20: m/l
B21: 3 | C21: ENCHAPE RECTO 1 CARAS MDF 18MM | D21: 0.7 | E21: 0.466 | F21: BLANCO OPACO 2114 MT | G21: 32608 | H21: =G21*B21 -> 97824 | M21: =D21+M$19 -> 0.75 | N21: =E21+$N$19 -> 0.466 | O21: =M21*N21 -> 0.3495 | P21: =O21*L21 -> 0 | Q21: =Q$20*O21 -> 35950.004 | R21: =Q21+R$20 -> 50950.004 | S21: =M21*L21*2 -> 0
C22: ENCHAPE RECTO 1 CARAS MDF 18MM | D22: 0.56 | E22: 0.5 | F22: BLANCO OPACO 2114 MT | G22: 9290 | H22: =G22*B22 -> 0 | M22: =D22+M$19 -> 0.61 | N22: =E22+$N$19 -> 0.5 | O22: =M22*N22 -> 0.305 | P22: =O22*L22 -> 0 | Q22: =Q$20*O22 -> 31372.679 | R22: =Q22+R$20 -> 46372.679
C23: ENCHAPE RECTO 1 CARAS MDF 25MM | D23: 0.4 | E23: 0.5 | F23: BLANCO OPACO 2114 MT | G23: 6727 | H23: =G23*B23 -> 0 | M23: =D23+M$19 -> 0.45 | N23: =E23+$N$19 -> 0.5 | O23: =M23*N23 -> 0.225 | P23: =O23*L23 -> 0 | Q23: =Q$20*O23 -> 23143.78 | R23: =Q23+R$20 -> 38143.78 | S23: =M23*L23*2 -> 0
B24: 2 | C24: ENCHAPE RECTO 1 CARAS MDF 18MM | D24: 0.7 | E24: 0.45 | F24: BLANCO OPACO 2114 MT | G24: 34716 | H24: =G24*B24 -> 69432 | L24: =B24 -> 2 | M24: =D24+M$19 -> 0.75 | N24: =E24+$N$19 -> 0.45 | O24: =M24*N24 -> 0.3375 | P24: =O24*L24 -> 0.675 | Q24: =Q$20*O24 -> 34715.669 | R24: =Q24+R$20 -> 49715.669 | S24: =M24*L24*2 -> 3 | T24: =N24*L24*2 -> 1.8
B25: 1 | C25: ENCHAPE RECTO 1 CARAS MDF 25MM | D25: 1.4 | E25: 0.45 | F25: BLANCO OPACO 2114 MT | G25: 62117 | H25: =G25*B25 -> 62117 | L25: =B25 -> 1 | M25: =D25+M$19 -> 1.45 | N25: =E25+$N$19 -> 0.45 | O25: =M25*N25 -> 0.6525 | P25: =O25*L25 -> 0.6525 | Q25: =Q$20*O25 -> 67116.961 | R25: =Q25+R$20 -> 82116.961 | S25: =M25*L25*2 -> 2.9 | T25: =N25*L25*2 -> 0.9
G27: NETO | H27: =SUM(H21:H25) -> 229373 | T27: =SUM(T21:T25) -> 2.7
G28: IVA | H28: =H27*19% -> 43580.87 | L28: =M28*10 -> 40.1 | M28: =SUM(M21:M27) -> 4.01 | P28: =SUM(P21:P25) -> 1.3275
G29: TOTAL | H29: =H27+H28 -> 272953.87 | P29: =P28 -> 1.3275 | S29: =SUM(S21:S28) -> 5.9
P30: =P29*20% -> 0.2655 | Q30: 20% PERDIDA | S30: =S29+T27 -> 8.6
P31: =P29+P30 -> 1.593 | S31: =S30*20% -> 1.72
S32: =S30+S31 -> 10.32 | U32: ADHESIVO | V32: 58.000.- | W32: 44971
M33: =P31 -> 1.593 | N33: 3500 | O33: =M33*N33 -> 5575.5 | P33: ADHESIVO | U33: LATA 16 LTS | V33: 3625 | W33: LITRO
M34: 0.5 | N34: 38500 | O34: 24910 | P34: MDF MELAMIL 18MM 1C | V34: 906.25 | W34: MT2 (4)
B35: CUENTA CORRIENTE BANCO SANTANDER Nº 87316181 A NOMBRE DE MUEBLES SANTA FE SPA | M35: 0.5 | N35: 33975 | O35: =M35*N35 -> 16987.5 | P35: TAPACANTO PVC 50MTS 29X2 | V35: =V34*20% -> 181.25 | W35: PERDIDA 20%
B36: RUT : 77.054.606-0 CORREO: FRANCODONOSO@TOPMOBILI.CL | M36: 1 | N36: 17550 | O36: =M36*N36 -> 17550 | P36: LAMINA 122X244 | V36: =V34+V35 -> 1087.5 | W36: MINIMO A COTIZAR
A37: GE | B37: VISITANOS Y DESCUBRE NUESTROS PRODUCTOS EN | F37: WWW.TOPMOBILICHILE.CL | N37: 900 | O37: =M37*N37 -> 0 | P37: RESPALDO | R37: 3.05 | S37: 0.5
N38: 1500 | O38: =M38*N38 -> 0 | P38: MEDIA CAÑA | R38: 1.22
O39: =SUM(O33:O38) -> 65023 | P39: COSTO | R39: =R37*R38 -> 3.721
M40: PRECIO VENTA | O40: =O39*2.1 -> 136548.3 | P40: FACTOR 2,3 PARA 90° | R40: =P31/R39 -> 0.42811072
K41: 51290 | O41: =O40/P29 -> 102861.24 | P41: VALOR M2 | U41: MDF30MM | V41: 43650
K42: =K41/1.19 -> 43100.84 | O42: =O40/O39 -> 2.1 | U42: 46 UNIDADES | V42: 948.91 | W42: 2.4
U43: METRO LINEAL | V43: 395.37
...

Sheet CAJONERAS
F2: MUEBLES SANTA FE SPA
F3: VENTAS POR MENOR DE MUEBLES
F4: RUT: 77.054.606-0
F5: SEPTIMA AVENIDA 1631, SAN MIGUEL
F6: FONO +569 2032 3382 | O6: 10077 SF PORTLAND MAPLE
F7: E-MAIL: ventas@topmobili.cl
B8: P R E S U P U E S T O | D8: N° 12076
B10: NOMBRE: | C10: JAVIER MOYA | F10: FECHA | G10: 46113
B11: RUT: | F11: PLAZO ENTREGA | G11: 15 DIAS HABILES | R11: MT2 PUERTAS
B12: GIRO: | F12: SERVICIO EXPRESS | G12: NO
B13: CONTACTO: | F13: CORTADA A LA MEDIDA | G13: NO
B14: CORREO: | F14: DESPACHO | G14: NO | R14: ML CUBIERTAS
B15: FONO: | C15: +56 9 6609 2180 | F15: INSTALACIÓN | G15: NO
B16: DIRECCION: | F16: FORMA DE PAGO: | G16: ABONO 50% SALDO C/ENTREGA
B17: CIUDAD: | C17: SANTIAGO | F17: Duración cotización 5 días hábiles | G17: Cotizado por: Franco Donoso
B19: DETALLE | M19: 0.02 | N19: 0.02 | P19: TOTAL | Q19: VALOR X MT2 | R19: ENCHAPE | S19: MT/L
B20: UNIDAD | C20: TIPO | D20: LARGO | E20: ANCHO | F20: COLOR | G20: VALOR | H20: TOTAL | L20: =B20 -> UNIDAD | M20: ALTO | N20: =E20 -> ANCHO | O20: MT | P20: MT2 | Q20: =O41 -> 52790.044 | R20: 15000 | T20: m/l
B21: 26 | C21: ENCHAPE RECTO 1 CARAS MDF 18MM | D21: 0.56 | E21: 0.5 | F21: BLANCO OPACO 2114 MT | G21: 9290 | H21: =G21*B21 -> 241540 | K21: 11 | M21: =D21+M$19 -> 0.58 | N21: =E21+$N$19 -> 0.52 | O21: =M21*N21 -> 0.3016 | P21: =O21*L21 -> 0 | Q21: =Q$20*O21 -> 15921.477 | R21: =Q21+R$20 -> 30921.477 | S21: =M21*L21*2 -> 0
B22: 13 | C22: ENCHAPE RECTO 1 CARAS MDF 18MM | D22: 0.56 | E22: 0.5 | F22: BLANCO OPACO 2114 MT | G22: 9290 | H22: =G22*B22 -> 120770 | K22: 3 | M22: =D22+M$19 -> 0.58 | N22: =E22+$N$19 -> 0.52 | O22: =M22*N22 -> 0.3016 | P22: =O22*L22 -> 0 | Q22: =Q$20*O22 -> 15921.477 | R22: =Q22+R$20 -> 30921.477
B23: 26 | C23: ENCHAPE RECTO 1 CARAS MDF 18MM | D23: 0.4 | E23: 0.5 | F23: BLANCO OPACO 2114 MT | G23: 6727 | H23: =G23*B23 -> 174902 | K23: 2 | M23: =D23+M$19 -> 0.42 | N23: =E23+$N$19 -> 0.52 | O23: =M23*N23 -> 0.2184 | P23: =O23*L23 -> 0 | Q23: =Q$20*O23 -> 11529.346 | R23: =Q23+R$20 -> 26529.346 | S23: =M23*L23*2 -> 0
B24: 13 | C24: ENCHAPE RECTO 1 CARAS MDF 18MM | D24: 0.56 | E24: 0.4 | F24: BLANCO OPACO 2114 MT | G24: 7503 | H24: =G24*B24 -> 97539 | K24: 2 | M24: =D24+M$19 -> 0.58 | N24: =E24+$N$19 -> 0.42 | O24: =M24*N24 -> 0.2436 | P24: =O24*L24 -> 0 | Q24: =Q$20*O24 -> 12859.655 | R24: =Q24+R$20 -> 27859.655 | S24: =M24*L24*2 -> 0 | T24: =N24*L24*2 -> 0
B25: 13 | C25: ENCHAPE RECTO 1 CARAS MDF 25MM | D25: 0.5 | E25: 0.4 | F25: BLANCO OPACO 2114 MT | G25: 11530 | H25: =G25*B25 -> 149890 | L25: =B25 -> 13 | M25: =D25+M$19 -> 0.52 | N25: =E25+$N$19 -> 0.42 | O25: =M25*N25 -> 0.2184 | P25: =O25*L25 -> 2.8392 | Q25: =Q$20*O25 -> 11529.346 | R25: =Q25+R$20 -> 26529.346 | S25: =M25*L25*2 -> 13.52 | T25: =N25*L25*2 -> 10.92
G27: NETO | H27: =SUM(H21:H25) -> 784641 | T27: =SUM(T21:T25) -> 10.92
G28: IVA | H28: =H27*19% -> 149081.79 | L28: =M28*10 -> 26.8 | M28: =SUM(M21:M27) -> 2.68 | P28: =SUM(P21:P25) -> 2.8392
G29: TOTAL | H29: =H27+H28 -> 933722.79 | P29: =P28 -> 2.8392 | S29: =SUM(S21:S28) -> 13.52
P30: =P29*20% -> 0.56784 | Q30: 20% PERDIDA | S30: =S29+T27 -> 24.44
P31: =P29+P30 -> 3.40704 | S31: =S30*20% -> 4.888
S32: =S30+S31 -> 29.328 | U32: ADHESIVO | V32: 58.000.- | W32: 44971
M33: =P31 -> 3.40704 | N33: 3500 | O33: =M33*N33 -> 11924.64 | P33: ADHESIVO | U33: LATA 16 LTS | V33: 3625 | W33: LITRO
M34: 1 | N34: 38100 | O34: 24910 | P34: MDF MELAMIL 18MM 1C | V34: 906.25 | W34: MT2 (4)
B35: CUENTA CORRIENTE BANCO SANTANDER Nº 87316181 A NOMBRE DE MUEBLES SANTA FE SPA | M35: 0.5 | N35: 33975 | O35: =M35*N35 -> 16987.5 | P35: TAPACANTO PVC 50MTS 29X2 | V35: =V34*20% -> 181.25 | W35: PERDIDA 20%
B36: RUT : 77.054.606-0 CORREO: FRANCODONOSO@TOPMOBILI.CL | M36: 1 | N36: 17550 | O36: =M36*N36 -> 17550 | P36: LAMINA 122X244 | V36: =V34+V35 -> 1087.5 | W36: MINIMO A COTIZAR
A37: GE | B37: VISITANOS Y DESCUBRE NUESTROS PRODUCTOS EN | F37: WWW.TOPMOBILICHILE.CL | N37: 900 | O37: =M37*N37 -> 0 | P37: RESPALDO | R37: 3.05 | S37: 0.5
N38: 1500 | O38: =M38*N38 -> 0 | P38: MEDIA CAÑA | R38: 1.22
O39: =SUM(O33:O38) -> 71372.14 | P39: COSTO | R39: =R37*R38 -> 3.721
M40: PRECIO VENTA | O40: =O39*2.1 -> 149881.49 | P40: FACTOR 2,3 PARA 90° | R40: =P31/R39 -> 0.91562483
K41: 51290 | O41: =O40/P29 -> 52790.044 | P41: VALOR M2 | U41: MDF30MM | V41: 43650
K42: =K41/1.19 -> 43100.84 | O42: =O40/O39 -> 2.1 | U42: 46 UNIDADES | V42: 948.91 | W42: 2.4
U43: METRO LINEAL | V43: 395.37
U44: PERDIDA 20% | V44: 474.45
...

Sheet 2229
F2: MUEBLES SANTA FE SPA
F3: VENTAS POR MENOR DE MUEBLES
F4: RUT: 77.054.606-0
F5: SEPTIMA AVENIDA 1631, SAN MIGUEL
F6: FONO +569 2032 3382 | O6: 10077 SF PORTLAND MAPLE
F7: E-MAIL: ventas@topmobili.cl
B8: P R E S U P U E S T O | D8: N° 12076
B10: NOMBRE: | C10: JAVIER MOYA | F10: FECHA | G10: 46113
B11: RUT: | F11: PLAZO ENTREGA | G11: 15 DIAS HABILES | R11: MT2 PUERTAS
B12: GIRO: | F12: SERVICIO EXPRESS | G12: NO
B13: CONTACTO: | F13: CORTADA A LA MEDIDA | G13: NO
B14: CORREO: | F14: DESPACHO | G14: NO | R14: ML CUBIERTAS
B15: FONO: | C15: +56 9 6609 2180 | F15: INSTALACIÓN | G15: NO
B16: DIRECCION: | F16: FORMA DE PAGO: | G16: ABONO 50% SALDO C/ENTREGA
B17: CIUDAD: | C17: SANTIAGO | F17: Duración cotización 5 días hábiles | G17: Cotizado por: Franco Donoso
B19: DETALLE | M19: 0.02 | N19: 0.02 | P19: TOTAL | Q19: VALOR X MT2 | R19: ENCHAPE | S19: MT/L
B20: UNIDAD | C20: TIPO | D20: LARGO | E20: ANCHO | F20: COLOR | G20: VALOR | H20: TOTAL | L20: =B20 -> UNIDAD | M20: ALTO | N20: =E20 -> ANCHO | O20: MT | P20: MT2 | Q20: =O42 -> 86740.028 | R20: 15000 | T20: m/l
B21: 11 | C21: ENCHAPE RECTO 2 CARAS MDF 25MM | D21: 1.2 | E21: 0.7 | F21: BLANCO OPACO 2114 MT | G21: =Q21 -> 76192.441 | H21: =G21*B21 -> 838116.85 | K21: 11 | L21: =B21 -> 11 | M21: =D21+M$19 -> 1.22 | N21: =E21+$N$19 -> 0.72 | O21: =M21*N21 -> 0.8784 | P21: =O21*L21 -> 9.6624 | Q21: =Q$20*O21 -> 76192.441 | R21: =Q21+R$20 -> 91192.441 | S21: =M21*L21*2 -> 26.84 | T21: =N21*L21*2 -> 15.84
B22: 3 | C22: ENCHAPE RECTO 2 CARAS MDF 25MM | D22: 1.5 | E22: 0.7 | F22: BLANCO OPACO 2114 MT | G22: =Q22 -> 94928.287 | H22: =G22*B22 -> 284784.86 | K22: 3 | L22: =B22 -> 3 | M22: =D22+M$19 -> 1.52 | N22: =E22+$N$19 -> 0.72 | O22: =M22*N22 -> 1.0944 | P22: =O22*L22 -> 3.2832 | Q22: =Q$20*O22 -> 94928.287 | R22: =Q22+R$20 -> 109928.29 | S22: =M22*L22*2 -> 9.12 | T22: =N22*L22*2 -> 4.32
B23: 1 | C23: ENCHAPE RECTO 2 CARAS MDF 25MM IZQ | D23: 1.97 | E23: 0.98 | F23: BLANCO OPACO 2114 MT | G23: =Q23 -> 172612.66 | H23: =G23*B23 -> 172612.66 | K23: 2 | L23: =B23 -> 1 | M23: =D23+M$19 -> 1.99 | N23: =E23+$N$19 -> 1 | O23: =M23*N23 -> 1.99 | P23: =O23*L23 -> 1.99 | Q23: =Q$20*O23 -> 172612.66 | R23: =Q23+R$20 -> 187612.66 | S23: =M23*L23*2 -> 3.98 | T23: =N23*L23*2 -> 2
B24: 1 | C24: ENCHAPE RECTO 2 CARAS MDF 25MM DER | D24: 1.97 | E24: 0.98 | F24: BLANCO OPACO 2114 MT | G24: 1000 | H24: =G24*B24 -> 1000 | K24: 2 | L24: =B24 -> 1 | M24: =D24+M$19 -> 1.99 | N24: =E24+$N$19 -> 1 | O24: =M24*N24 -> 1.99 | P24: =O24*L24 -> 1.99 | Q24: =Q$20*O24 -> 172612.66 | R24: =Q24+R$20 -> 187612.66 | S24: =M24*L24*2 -> 3.98 | T24: =N24*L24*2 -> 2
B25: 3 | C25: ENCHAPE RECTO 1 CARA MELAMIL 18MM | D25: 1.5 | E25: 0.35 | F25: BLANCO OPACO 2114 MT | G25: 15000 | H25: =G25*B25 -> 45000 | K25: =SUM(K21:K24) -> 18 | L25: =B25 -> 3 | M25: =D25+M$19 -> 1.52 | N25: =E25+$N$19 -> 0.37 | O25: =M25*N25 -> 0.5624 | P25: =O25*L25 -> 1.6872 | Q25: =Q$20*O25 -> 48782.592 | R25: =Q25+R$20 -> 63782.592 | S25: =M25*L25*2 -> 9.12 | T25: =N25*L25*2 -> 2.22
G28: NETO | H28: =SUM(H21:H26) -> 1341514.4 | T28: =SUM(T21:T26) -> 26.38
G29: IVA | H29: =H28*19% -> 254887.73 | L29: =M29*10 -> 82.4 | M29: =SUM(M21:M28) -> 8.24 | P29: =SUM(P21:P26) -> 18.6128
G30: TOTAL | H30: =H28+H29 -> 1596402.1 | P30: =P29 -> 18.6128 | S30: =SUM(S21:S29) -> 53.04
P31: =P30*20% -> 3.72256 | Q31: 20% PERDIDA | S31: =S30+T28 -> 79.42
P32: =P30+P31 -> 22.33536 | S32: =S31*20% -> 15.884
S33: =S31+S32 -> 95.304 | U33: ADHESIVO | V33: 58.000.- | W33: 44971
M34: =P32*2 -> 44.67072 | N34: 3500 | O34: =M34*N34 -> 156347.52 | P34: ADHESIVO | U34: LATA 16 LTS | V34: 3625 | W34: LITRO
M35: 6 | N35: 38100 | O35: =M35*N35 -> 228600 | P35: MDF 25MM | V35: 906.25 | W35: MT2 (4)
B36: CUENTA CORRIENTE BANCO SANTANDER Nº 87316181 A NOMBRE DE MUEBLES SANTA FE SPA | M36: 2 | N36: 33975 | O36: =M36*N36 -> 67950 | P36: TAPACANTO PVC 50MTS 29X2 | V36: =V35*20% -> 181.25 | W36: PERDIDA 20%
B37: RUT : 77.054.606-0 CORREO: FRANCODONOSO@TOPMOBILI.CL | M37: 18 | N37: 17550 | O37: =M37*N37 -> 315900 | P37: LAMINA 122X244 | V37: =V35+V36 -> 1087.5 | W37: MINIMO A COTIZAR
A38: GE | B38: VISITANOS Y DESCUBRE NUESTROS PRODUCTOS EN | F38: WWW.TOPMOBILICHILE.CL | N38: 900 | O38: =M38*N38 -> 0 | P38: RESPALDO | R38: 1.52
N39: 1500 | O39: =M39*N39 -> 0 | P39: MEDIA CAÑA | R39: 2.44
O40: =SUM(O34:O39) -> 768797.52 | P40: COSTO | R40: =R38*R39 -> 3.7088
M41: PRECIO VENTA | O41: =O40*2.1 -> 1614474.8 | P41: FACTOR 2,3 PARA 90° | R41: =P32/R40 -> 6.0222606
K42: 51290 | O42: =O41/P30 -> 86740.028 | P42: VALOR M2 | U42: MDF30MM | V42: 43650
K43: =K42/1.19 -> 43100.84 | O43: =O41/O40 -> 2.1 | U43: 46 UNIDADES | V43: 948.91 | W43: 2.4
U44: METRO LINEAL | V44: 395.37
U45: PERDIDA 20% | V45: 474.45
...

Sheet COSTOS
B2: CENTRO DE COSTOS POSTFORMADOS
B5: FECHA: | C5: ='2229'!G10 -> 46113
B6: CLIENTE: | C6: ='2229'!C10 -> JAVIER MOYA | N6: Ventas Equilibrio = | P6: Costos Fijos Totales
B7: DIRECCION: | C7: ='2229'!#REF! -> #REF! | H7: COSTOS INDIRECTOS DE FABRICA VARIABLES | O7: 1 - | P7: Costos Variables Totales
B8: PRESUPUESTO: | C8: ='2229'!D8 -> N° 12076 | H8: Q/HRS | I8: $ | J8: DETALLE | K8: TOTAL | L8: TOTAL | P8: Total Venta | X8: =SUM(Q11:Q16) -> 6
H9: CANTIDAD | I9: PRECIO | J9: MATERIA PRIMA INDIRECTA | L9: =SUM(K10:K23) -> 2550 | S9: DETALLE | X9: =(E15-D11)/X8 -> -90834.534
D10: NETO | E10: IVA | F10: TOTAL | H10: 3 | I10: 350 | J10: RESPALDO | K10: =I10*H10 -> 1050 | Q10: UNIDAD | R10: TIPO | S10: LARGO | T10: ANCHO | U10: COLOR | V10: VALOR | W10: TOTAL
C11: MONTO A COBRAR | D11: ='2229'!H28 -> 1341514.4 | E11: =D11*0.19 -> 254887.73 | F11: =E11+D11 -> 1596402.1 | H11: 3 | I11: 500 | J11: MEDIA CAÑA | K11: =I11*H11 -> 1500 | Q11: 1 | R11: CUB C/R R8 | S11: 2.8 | T11: 0.62 | U11: MADERA X DEFINIR | V11: 105990 | W11: =V11*Q11 -> 105990 | X11: =V11+$X$9 -> 15155.466 | Y11: 108990
C12: COSTO TOTAL | D12: =SUM(M43:M45) -> 482731.61 | H12: 0 | I12: 7500 | J12: DUROLAC | K12: =I12*H12 -> 0 | Q12: 1 | R12: CUB C/R R8 | S12: 2.3 | T12: 0.62 | U12: MADERA X DEFINIR | V12: 87990 | W12: =V12*Q12 -> 87990 | X12: =V12+$X$9 -> -2844.5339 | Y12: 89990
C13: % UTILIDAD | D13: =D11-D12 -> 858782.75 | E13: =(D11/D12)-1 -> 1.7790067 | H13: 0 | I13: 50 | J13: TAPACANTO PVC | K13: =I13*H13 -> 0 | Q13: 1 | R13: CUB C/R R8 | S13: 2.03 | T13: 0.62 | U13: MADERA X DEFINIR | V13: 78990 | W13: =V13*Q13 -> 78990 | X13: =V13+$X$9 -> -11844.534 | Y13: 81990
D14: % utilidad | E14: NETO | F14: UTILIDAD | H14: 0 | I14: 50 | J14: SOBERBIOS | K14: =I14*H14 -> 0 | Q14: 1 | R14: CUB C/R R8 | S14: 1.08 | T14: 0.62 | U14: MADERA X DEFINIR | V14: 39990 | W14: =V14*Q14 -> 39990 | X14: =V14+$X$9 -> -50844.534 | Y14: 39990
C15: PROYECCION | D15: 0.65 | E15: =(100%+D15)*D12 -> 796507.16 | F15: =E15-D12 -> 313775.55 | H15: 0 | I15: 10 | J15: SOPORTE REPISA | K15: =I15*H15 -> 0 | Q15: 1 | R15: CUB C/R R8 | S15: 1.08 | T15: 0.62 | U15: MADERA X DEFINIR | V15: 39990 | W15: =V15*Q15 -> 39990 | X15: =V15+$X$9 -> -50844.534 | Y15: 39990
H16: 1 | J16: PUNTAS | K16: =I16*H16 -> 0 | Q16: 1 | R16: CUB C/R R8 | S16: 2.06 | T16: 0.62 | U16: MADERA X DEFINIR | V16: 79990 | W16: =V16*Q16 -> 79990 | X16: =V16+$X$9 -> -10844.534 | Y16: 83990
B17: M. PRIMA | C17: MATERIAL | D17: NETO | E17: IVA | F17: TOTAL | H17: 1 | J17: TORNILLOS | K17: =I17*H17 -> 0 | Q17: 6 | R17: CORTES 45° | V17: 5000 | W17: =V17*Q17 -> 30000
C18: LAMINA | D18: ='2229'!O36 -> 67950 | E18: =D18*0.19 -> 12910.5 | F18: =SUM(D18:E18) -> 80860.5 | H18: 1 | J18: COLAFRIA | K18: =I18*H18 -> 0 | Q18: 1 | R18: PERFORACION LAVAPLATOS | V18: 10000 | W18: =V18*Q18 -> 10000
C19: MDF 18MM | D19: ='2229'!O35 -> 228600 | E19: =D19*0.19 -> 43434 | F19: =SUM(D19:E19) -> 272034 | H19: 1 | J19: LIJAS | K19: =I19*H19 -> 0 | V19: NETO | W19: =SUM(W11:W18) -> 472940 | Y19: =SUM(Y11:Y16)+SUM(W17:W18) -> 484940
C20: ADHESIVO | D20: ='2229'!O34 -> 156347.52 | E20: =D20*0.19 -> 29706.029 | F20: =SUM(D20:E20) -> 186053.55 | H20: 1 | J20: CARTON | K20: =I20*H20 -> 0 | V20: I.V.A. | W20: =W19*19% -> 89858.6 | Y20: =Y19*0.19 -> 92138.6
A21: =450000*1.2 -> 540000 | C21: TOTAL | D21: =SUM(D18:D20) -> 452897.52 | E21: =SUM(E18:E20) -> 86050.529 | F21: =SUM(F18:F20) -> 538948.05 | H21: 1 | J21: GUAIPE | K21: =I21*H21 -> 0 | M21: =B32/9 -> 2318.8406 | Q21: PLAZO DE ENTREGA : 8 DIAS HABILES | V21: TOTAL | W21: =W19+W20 -> 562798.6 | Y21: =SUM(Y19:Y20) -> 577078.6
A22: =450000*1.2 -> 540000 | B22: M. DE OBRA | C22: PROCESO | D22: COSTO x Hr. | E22: Q Hrs. | F22: TOTAL | H22: 1 | J22: DILUYENTE | K22: =I22*H22 -> 0 | Q22: FORMA DE PAGO: 50% CONTADO, SALDO C/E
A23: =800000*1.2 -> 960000 | B23: =A21/23 -> 23478.261 | C23: CORTE | D23: =B23/9 -> 2608.6957 | E23: 0.5 | F23: =D23*E23 -> 1304.3478 | H23: 1 | J23: CINTA EMBALAJE | K23: =I23*H23 -> 0 | Q23: VALIDEZ COTIZACIÓN: 5 DIAS
A24: 450000 | B24: =A22/23 -> 23478.261 | C24: CORTE LAMINA | D24: =B24/9 -> 2608.6957 | E24: 0.5 | F24: =D24*E24 -> 1304.3478 | H24: Q/HRS | I24: PRECIO | J24: MANO DE OBRA INDIRECTA | K24: VALOR | L24: =SUM(K25:K35) -> 0
A25: 450000 | B25: =A23/23 -> 41739.13 | C25: REBAJE LAMINA | D25: =B25/9 -> 4637.6812 | F25: =D25*E25 -> 0 | H25: 0 | I25: =((480000/23)/9) -> 2318.8406 | J25: FLETERO (HRS) | K25: =H25*I25 -> 0
B26: =A24/23 -> 19565.217 | C26: TUPIZADO | D26: =B26/9 -> 2173.913 | E26: 0.5 | F26: =D26*E26 -> 1086.9565 | H26: 0 | J26: BENCINA | K26: =H26*I26 -> 0
A27: 350000 | B27: =A25/23 -> 19565.217 | C27: ARMADO | D27: =B27/9 -> 2173.913 | E27: 0.5 | F27: =D27*E27 -> 1086.9565 | H27: 0 | J27: TAG | K27: =H27*I27 -> 0
A28: 500000 | B28: =A27/23 -> 15217.391 | C28: PEGADO | D28: =B28/9 -> 1690.8213 | E28: 0.7 | F28: =D28*E28 -> 1183.5749 | H28: 0 | J28: RECTIFICACION | K28: =H28*I28 -> 0
B29: =A28/23 -> 21739.13 | C29: POSTFORMADO | D29: =B29/9 -> 2415.4589 | E29: 0.7 | F29: =D29*E29 -> 1690.8213 | H29: 0 | I29: =((550000*1.2)/23)/9 -> 3188.4058 | J29: HR. TRAB. JUAN | K29: =H29*I29 -> 0
A30: 450000 | C30: MEDIA CAÑA | D30: 2415 | F30: =D30*E30 -> 0 | H30: 0 | I30: =((450000*1.2)/23)/9 -> 2608.6957 | J30: HR. TRAB. JULIO | K30: =H30*I30 -> 0
A31: 350000 | B31: =A30/23 -> 19565.217 | C31: CORTE-ENCHAPE | D31: =B31/9 -> 2173.913 | E31: 0 | F31: =D31*E31 -> 0 | H31: 0 | I31: =((450000*1.2)/23)/9 -> 2608.6957 | J31: HR. TRAB. EUGE | K31: =H31*I31 -> 0
A32: =A21+A24+A27+A28+A30 -> 2290000 | B32: =480000/23 -> 20869.565 | C32: CONTROL CALIDAD | D32: =B32/9 -> 2318.8406 | E32: 0.5 | F32: =D32*E32 -> 1159.4203 | H32: 0 | J32: COLACION | K32: =H32*I32 -> 0
C33: TOTAL | D33: =SUM(D23:D32) -> 25216.932 | E33: =SUM(E23:E32) -> 3.9 | F33: =SUM(F23:F32) -> 8816.4251 | H33: 0 | J33: BONO | K33: =H33*I33 -> 0
B34: CIF | C34: M. PRIMA INDIREC. | D34: =L9 -> 2550 | H34: 1 | J34: PERFORACION | K34: =H34*I34 -> 0
C35: M. OBRA INDIRECTA | D35: =L24 -> 0 | H35: 6 | J35: CORTE 45 | K35: =H35*I35 -> 0
C36: GASTOS DE FABRICA | D36: =L36 -> 18467.666 | H36: CANTIDAD | I36: PRECIO | J36: GASTOS DE FABRICACION | K36: VALOR | L36: =SUM(K37:K39) -> 18467.666
C37: DEPRECIACIONES | H37: =$E$33 -> 3.9 | I37: =32609.69/9 -> 3623.2989 | J37: ARRIENDO x HORA | K37: =I37*H37 -> 14130.866
C38: TOTAL | D38: =SUM(D34:D37) -> 21017.666 | H38: =$E$33 -> 3.9 | I38: 967 | J38: AGUA x HORA | K38: =I38*H38 -> 3771.3
H39: =$E$33 -> 3.9 | I39: 145 | J39: LUZ x HORA | K39: =I39*H39 -> 565.5
B40: PROVISIONAR | C40: IVA | D40: =E11-E21 -> 168837.2
H41: ESTADO DE RESULTADOS
B42: TOTAL HRS TRABAJADAS | D42: =E33 -> 3.9 | H42: INGRESOS | I42: + TOTAL VENTA | M42: =D11 -> 1341514.4
H43: COSTOS | I43: - MATERIA PRIMA DIRECTA | M43: =D21 -> 452897.52
...

Sheet NOTA DE VENTA
F2: MUEBLES SANTA FE SPA
F3: VENTAS POR MENOR DE MUEBLES
F4: RUT: 77.054.606-0
F5: SEPTIMA AVENIDA 1631, SAN MIGUEL
F6: CELULAR: 963868755
F7: E-MAIL: fdonoso@topmobili.cl
B8: P R E S U P U E S T O | D8: ='2229'!D8 -> N° 12076 | F8: NOTA DE VENTA :
B10: CLIENTE: | C10: =IF('2229'!C10="","",'2229'!C10) -> JAVIER MOYA | F10: FECHA : | G10: ='2229'!G10 -> 46113
B11: RUT: | C11: =IF('2229'!C11="","",'2229'!C11) | F11: FECHA LIMITE : | G11: =WORKDAY(G10,5) -> 46120
B12: GIRO: | C12: =IF('2229'!C12="","",'2229'!C12) | F12: DESPACHO: | G12: ='2229'!G14 -> NO
B13: CONTACTO: | C13: =IF('2229'!C13="","",'2229'!C13) | F13: ORDEN DE COMPRA:
B14: CORREO: | C14: =IF('2229'!C14="","",'2229'!C14) | F14: HECHO POR: | G14: FERNANDO DONOSO
B15: FONO: | C15: =IF('2229'!C15="","",'2229'!C15) -> +56 9 6609 2180 | F15: SERVICIO EXPRESS: | G15: ='2229'!G12 -> NO
B16: DIRECCION: | C16: =IF('2229'!C16="","",'2229'!C16) | F16: FORMA DE PAGO : | G16: ='2229'!G16 -> ABONO 50% SALDO C/ENTREGA
B17: CIUDAD: | C17: =IF('2229'!C17="","",'2229'!C17) -> SANTIAGO | F17: VALIDEZ COTIZACIÓN: 5 DÍAS
B20: D E T A L L E
B21: UNIDAD | C21: TIPO | D21: LARGO | E21: ANCHO | F21: COLOR | G21: VALOR | H21: TOTAL
B22: ='2229'!#REF! -> #REF! | C22: ='2229'!#REF! -> #REF! | D22: ='2229'!#REF!*1000 -> #REF! | E22: ='2229'!#REF!*1000 -> #REF! | F22: ='2229'!#REF! -> #REF! | G22: ='2229'!#REF! -> #REF! | H22: =G22*B22 -> #REF!
G25: NETO | H25: =SUM(H22:H24) -> #REF!
G26: I.V.A. | H26: =H25*19% -> #REF!
G27: TOTAL | H27: =H25+H26 -> #REF!
B30: CUENTA VISTA DEL BANCO ESTADO N° 35571389078 A NOMBRE DE
B31: "MUEBLES SANTA FE SPA." - RUT : 77.054.606-0, VENTAS@TOPMOBILI.CL
B32: VISITANOS Y DESCUBRE NUESTROS PRODUCTOS EN | E32: WWW.TOPMOBILICHILE.CL

Sheet REGLAS
B2: DETALLE CORTE LAMINA | G2: DETALLE CORTE SUSTRATO | P2: DETALLE CORTE MERA
B3: ALTO | C3: ANCHO | D3: TIPO | G3: ALTO | H3: ANCHO | I3: TIPO | P3: ALTO | Q3: ANCHO | R3: TIPO
B4: 40 | C4: 60 | D4: CEN 1V | E4: A1 | G4: 50 | H4: 100 | I4: CEN 1V | J4: REGLA SIEMPRE LLEVAR MEDIDA MINIMO A 100 | P4: 50 | Q4: -30 | R4: CUB C/R
B5: 40 | C5: 90 | D5: CEN 2V | E5: A2 | G5: 50 | I5: CEN 2V | J5: REGLA SIEMPRE LLEVAR MEDIDA MINIMO A 101 | P5: 50 | Q5: -30 | R5: CUB C/R
B6: 40 | C6: 100 | D6: CORNISA FRENTE ESPAÑOL 1 LADO | E6: A3 | G6: 50 | H6: 100 | I6: CORNISA FRENTE ESPAÑOL 1 LADO | P6: 50 | Q6: -30 | R6: CUB C/R 180°
B7: 40 | C7: 150 | D7: CORNISA FRENTE ESPAÑOL 2 LADO | E7: A4 | G7: 50 | I7: CORNISA FRENTE ESPAÑOL 2 LADO | P7: 50 | Q7: -30 | R7: CUB C/R FRENTE ESPAÑOL
B8: 40 | C8: 100 | D8: CORNISA 180° 1LADO | E8: A5 | G8: 50 | H8: 100 | I8: CORNISA 180° 1LADO | L8: DETALLE CORTE MERA | P8: 50 | Q8: -30 | R8: CUB C/R PUNTA 1 LADO
B9: 40 | C9: 50 | D9: CORNISA PUNTA TIBURON 1 LADO | E9: B | G9: 50 | H9: 100 | I9: CORNISA 1LADO | L9: ALTO | M9: ANCHO | N9: TIPO | P9: 50 | Q9: 0 | R9: CUB S/R FRENTE ESPAÑOL
B10: 40 | C10: 80 | D10: CORNISA PUNTA TIBURON 2 LADOS | E10: C | G10: 50 | I10: CORNISA 2 LADOS | L10: 50 | M10: -30 | N10: CUB C/R | P10: 50 | Q10: 0 | R10: CUB S/R
B11: 40 | C11: 60 | D11: CORNISA R8 1LADO | E11: D | G11: 50 | H11: 100 | I11: CORNISA PUNTA TIBURON 1 LADO | L11: 50 | M11: 0 | N11: CUB S/R y CUB MESA | P11: 50 | Q11: 0 | R11: CUB MESA 180° 2 LADOS
B12: 40 | C12: 100 | D12: CORNISA R8 2 LADOS | E12: E | G12: 50 | I12: CORNISA PUNTA TIBURON 2 LADOS | L12: 50 | M12: -2 | N12: PR | P12: 50 | Q12: 0 | R12: CUB MESA 180° 3 LADOS
B13: 40 | C13: 130 | D13: CUB C/R R6 | E13: F | G13: 50 | H13: -30 | I13: CUB C/R | P13: 50 | Q13: 0 | R13: CUB MESA 180° 4 LADOS
B14: 40 | C14: 150 | D14: CUB C/R 180° | G14: 50 | H14: -30 | I14: CUB C/R 180°
B15: 40 | C15: 150 | D15: CUB C/R FRENTE ESPAÑOL | E15: G | G15: 50 | H15: -30 | I15: CUB C/R FRENTE ESPAÑOL | P15: 50 | Q15: 0 | R15: CUB MESA 4 LADOS
B16: 40 | C16: 130 | D16: CUB C/R R2 | E16: H | G16: 50 | H16: -30 | I16: CUB C/R PUNTA TIBURON 1 LADO | P16: 50 | Q16: 0 | R16: CUB MESA FRENTE ESPAÑOL 2 LADOS
B17: 40 | C17: 150 | D17: CUB MESA 180° 2 LADOS | E17: I | G17: 50 | I17: CUB MESA 180° 2 LADOS | P17: 50 | Q17: 0 | R17: CUB MESA FRENTE ESPAÑOL 3 LADOS
B18: 140 | C18: 150 | D18: CUB MESA 180° 3 LADOS | E18: J | G18: 50 | I18: CUB MESA 180° 3 LADOS | P18: 50 | Q18: 0 | R18: CUB MESA FRENTE ESPAÑOL 4 LADOS
B19: 150 | C19: 150 | D19: CUB MESA 180° 4 LADOS | E19: K | G19: 50 | I19: CUB MESA 180° 4 LADOS | P19: 50 | Q19: 0 | R19: CUB MESA PUNTA TIBURON 2 LADOS
B20: 40 | C20: 100 | D20: CUB MESA 2L | E20: L | G20: 50 | H20: 0 | I20: CUB MESA 2L | J20: ES IGUAL A LO PEDIDO NO SE DEBE SUMAR NI RESTAR | P20: 50 | Q20: 0 | R20: CUB MESA PUNTA TIBURON 3 LADOS
B21: 100 | C21: 100 | D21: CUB MESA 3L | E21: M | G21: 50 | H21: 0 | I21: CUB MESA 3L | P21: 50 | Q21: 0 | R21: CUB MESA PUNTA TIBURON 4 LADOS
B22: 100 | C22: 100 | D22: CUB MESA 4 LADOS | E22: N | I22: CUB MESA 4 LADOS | P22: 50 | Q22: 0 | R22: CUB PUNTA TIBURON 1 LADO
B23: 40 | C23: 150 | D23: CUB MESA FRENTE ESPAÑOL 2 LADOS | E23: O | G23: 50 | I23: CUB MESA FRENTE ESPAÑOL 2 LADOS | R23: CENEFA 1 LADO
B24: 140 | C24: 150 | D24: CUB MESA FRENTE ESPAÑOL 3 LADOS | E24: P | G24: 50 | I24: CUB MESA FRENTE ESPAÑOL 3 LADOS | R24: CENEFA 2 LADOS
B25: 150 | C25: 150 | D25: CUB MESA FRENTE ESPAÑOL 4 LADOS | E25: Q | G25: 50 | I25: CUB MESA FRENTE ESPAÑOL 4 LADOS | R25: CORNISA FRENTE ESPAÑOL 1 LADO
B26: 40 | C26: 77 | D26: CUB MESA PUNTA TIBURON 2 LADOS | E26: R | G26: 50 | I26: CUB MESA PUNTA TIBURON 2 LADOS | R26: CORNISA FRENTE ESPAÑOL 2 LADO
B27: 110 | C27: 77 | D27: CUB MESA PUNTA TIBURON 3 LADOS | E27: S | G27: 50 | I27: CUB MESA PUNTA TIBURON 3 LADOS | R27: CORNISA 180° 1LADO
B28: 120 | C28: 77 | D28: CUB MESA PUNTA TIBURON 4 LADOS | E28: T | G28: 50 | I28: CUB MESA PUNTA TIBURON 4 LADOS | R28: CORNISA 1LADO
B29: 40 | C29: 50 | D29: CUB PUNTA TIBURON 1 LADO | E29: U | G29: 50 | I29: CUB PUNTA TIBURON 1 LADO | R29: CORNISA 2 LADOS
B30: 40 | C30: 60 | D30: CUB S/R | E30: V | G30: 50 | I30: CUB S/R | R30: CORNISA PUNTA TIBURON 1 LADO
B31: 40 | C31: 100 | D31: CUB S/R FRENTE ESPAÑOL | E31: W | G31: 50 | I31: CUB S/R FRENTE ESPAÑOL | R31: CORNISA PUNTA TIBURON 2 LADOS
B32: 40 | C32: 60 | D32: CUB S/R R2 | E32: X | G32: 50 | I32: CUB S/R R2 | R32: PR2
B33: 40 | C33: 90 | D33: PR12 | E33: Y | G33: 50 | H33: -2 | I33: PR12 | R33: PR6
B34: 40 | C34: 90 | D34: PR19 | G34: 50 | H34: -2 | I34: PR19
B35: 40 | C35: 90 | D35: PR2 | E35: Z | G35: 50 | H35: -2 | I35: PR2 | R35: PR8
B36: 40 | C36: 90 | D36: PR6 | G36: 50 | H36: -2 | I36: PR6 | R36: PR12
B37: 40 | C37: 90 | D37: PR8 | G37: 50 | H37: -2 | I37: PR8 | R37: PR19
B48: 40 | C48: 150

Sheet PRODUCCION
K2: NO BORRAR REGLAS!!!!! SI NO LAS SABEN USAR NO BORREN ESTO POR FAVOR!!!!!
K3: SUSTRATO | M3: LAMINADO
C4: NOTA DE VENTA : | D4: =IF('NOTA DE VENTA'!$G$8="","",'NOTA DE VENTA'!$G$8) | K4: ALTO | L4: ANCHO | M4: ALTO | N4: ANCHO
C5: CLIENTE : | D5: ='NOTA DE VENTA'!$C$10 -> JAVIER MOYA | K5: =LOOKUP(F14,REGLAS!$I$4:$I$37,REGLAS!$G$4:$G$37)+J14 -> 1850 | L5: =LOOKUP(F14,REGLAS!$I$4:$I$37,REGLAS!$H$4:$H$37)+K14 -> 470 | M5: =LOOKUP(F14,REGLAS!$D$4:$D$37,REGLAS!$B$4:$B$37)+J21 -> 1840 | N5: =H10 -> 0
C7: ='NOTA DE VENTA'!$F$10 -> FECHA : | D7: ='NOTA DE VENTA'!$G$10 -> 46113
C8: FECHA ENTREGA: | D8: ='NOTA DE VENTA'!$G$11 -> 46120
A10: SUSTRATO
D12: ALTO | E12: ANCHO
A13: MATERIAL | B13: CANTIDAD | C13: CORTE | D13: 80 | E13: -30 | F13: DESCRIPCIÓN | J13: ALTO | K13: ANCHO
A14: MDF 18MM | B14: =I14 -> 1 | D14: =LOOKUP(F14,REGLAS!$I$4:$I$37,REGLAS!$G$4:$G$37)+J14 -> 1850 | E14: =LOOKUP(F14,REGLAS!$I$4:$I$37,REGLAS!$H$4:$H$37)+K14 -> 470 | F14: =C27 -> CUB C/R R8 | I14: =I21 -> 1 | J14: =D27 -> 1800 | K14: =E27 -> 500
A17: LAMINADO
D19: ALTO | E19: ANCHO
A20: MATERIAL | B20: CANTIDAD | C20: CORTE | D20: 40 | E20: 130 | F20: DESCRIPCIÓN | J20: ALTO | K20: ANCHO
A21: MDF 18MM | B21: =I21 -> 1 | D21: =LOOKUP(F14,REGLAS!$D$4:$D$37,REGLAS!$B$4:$B$37)+J21 -> 1840 | E21: =LOOKUP(F14,REGLAS!$D$4:$D$37,REGLAS!$C$4:$C$37)+K21 -> 630 | F21: =C27 -> CUB C/R R8 | I21: =B27 -> 1 | J21: =D27 -> 1800 | K21: =E27 -> 500
B24: MEDIDAS ORIGINALES
A26: MATERIAL | B26: CANTIDAD | C26: DESCRIPCIÓN | D26: ALTO | E26: ANCHO | F26: COLOR
A27: MDF 18MM | B27: ='[1]4637'!B21 -> 1 | C27: ='[1]4637'!C21 -> CUB C/R R8 | D27: ='[1]4637'!D21 -> 1800 | E27: ='[1]4637'!E21 -> 500 | F27: ='[1]4637'!F21 -> LATE 2167 MT
C39: NOTA DE VENTA : | D39: ='[1]4637'!G8 -> 7332
C40: CLIENTE : | D40: ='[1]4637'!C10 -> FMR MAKING SPA
C42: ='[1]4637'!F11 -> FECHA LIMITE : | D42: ='[1]4637'!G11 -> 45996
A45: PRODUCCIÓN
B47: DETALLE
B48: CANTIDAD | C48: CORTE | D48: ALTO | E48: ANCHO | F48: DESCRIPCION
A49: MDF18MM | B49: ='[1]4637'!B21 -> 1 | C49: ='[1]4637'!C21 -> CUB C/R R8 | D49: ='[1]4637'!D21 -> 1800 | E49: ='[1]4637'!E21 -> 500 | F49: ='[1]4637'!F21 -> LATE 2167 MT

Sheet SEGUIMIENTO
A1: NV | B1: N° COTIZA | C1: FECHA | D1: ENTREGA | E1: NOMBRE | F1: DETALLE | G1: COLOR | H1: NETO | I1: IVA | J1: TOTAL | K1: ABONO | L1: SALDO | M1: ESTADO
A2: ='NOTA DE VENTA'!$G$8 -> 0 | B2: ='NOTA DE VENTA'!$D$8 -> N° 12076 | C2: ='NOTA DE VENTA'!$G$10 -> 46113 | D2: ='NOTA DE VENTA'!$G$11 -> 46120 | E2: ='NOTA DE VENTA'!$C$10 -> JAVIER MOYA | F2: ='NOTA DE VENTA'!$C$22 -> #REF! | G2: ='NOTA DE VENTA'!$F$22 -> #REF! | H2: ='NOTA DE VENTA'!$H$25 -> #REF! | I2: =H2*0.19 -> #REF! | J2: =I2+H2 -> #REF! | L2: =J2-K2 -> #REF!
