Workbook

Sheet DUROLAC Y MELAMIL
F2: MUEBLES SANTA FE SPA
F3: VENTAS POR MENOR DE MUEBLES
F4: RUT: 77.054.606-0
F5: SEPTIMA AVENIDA 1631, SAN MIGUEL
F6: FONO +569 2032 3382 | O6: 10077 SF PORTLAND MAPLE
F7: E-MAIL: ventas@topmobili.cl
B8: P R E S U P U E S T O | D8: N° 12105B
B10: NOMBRE: | C10: ESTEBAN ALBORNOZ CABRERA | F10: FECHA | G10: 46137
B11: RUT: | C11: 12.654.086-6 | F11: PLAZO ENTREGA | G11: 10 DIAS HABILES | R11: MT2 PUERTAS
B12: GIRO: | F12: SERVICIO EXPRESS | G12: NO
B13: CONTACTO: | F13: CORTADA A LA MEDIDA | G13: SI
B14: CORREO: | F14: DESPACHO | G14: NO | R14: ML CUBIERTAS
B15: FONO: | F15: INSTALACIÓN | G15: NO
B16: DIRECCION: | F16: FORMA DE PAGO: | G16: ABONO 50% SALDO C/ENTREGA
B17: CIUDAD: | C17: SANTIAGO | F17: Duración cotización 5 días hábiles | G17: Cotizado por: Franco Donoso
B19: DETALLE | M19: 0.02 | N19: 0.02 | P19: TOTAL | Q19: VALOR X MT2 | R19: ENCHAPE | S19: MT/L
B20: UNIDAD | C20: TIPO | D20: LARGO | E20: ANCHO | F20: COLOR | G20: VALOR | H20: TOTAL | L20: =B20 -> UNIDAD | M20: ALTO | N20: =E20 -> ANCHO | O20: MT | P20: MT2 | Q20: =O40 -> 25657.358 | R20: 3000 | T20: m/l
B21: 9 | C21: DUROLAC PINTADO BLANCO 3MM | D21: 2.5 | E21: 1.83 | G21: 12990 | H21: =G21*B21 -> 116910 | L21: =B21 -> 9 | M21: =D21+M$19 -> 2.52 | N21: =E21+$N$19 -> 1.85 | O21: =M21*N21 -> 4.662 | P21: =O21*L21 -> 41.958 | Q21: =Q$20*O21 -> 119614.6 | R21: =Q21+R$20 -> 122614.6 | S21: =M21*L21*2 -> 45.36 | T21: =N21*L21*2 -> 33.3
B22: 24 | C22: MELAMINA BLANCA 15MM VESTO | D22: 2.5 | E22: 1.83 | G22: 39990 | H22: =G22*B22 -> 959760 | L22: =B22 -> 24 | M22: =D22+M$19 -> 2.52 | N22: =E22+$N$19 -> 1.85 | O22: =M22*N22 -> 4.662 | P22: =O22*L22 -> 111.888 | Q22: =Q$20*O22 -> 119614.6 | R22: =Q22+R$20 -> 122614.6 | S22: =M22*L22 -> 60.48 | T22: =N22*2*L22*2 -> 177.6
B23: 1 | C23: SERVICIO CORTE Y ENCHAPE | G23: 321450 | H23: =G23*B23 -> 321450 | L23: =B23 -> 1 | M23: =D23+M$19 -> 0.02 | N23: =E23+$N$19 -> 0.02 | O23: =M23*N23 -> 0.0004 | P23: =O23*L23 -> 0.0004 | Q23: =Q$20*O23 -> 10.262943 | R23: =Q23+R$20 -> 3010.2629 | S23: =M23*L23 -> 0.02 | T23: =N23*2*L23*2 -> 0.08
G26: NETO | H26: =SUM(H21:H23) -> 1398120 | T26: =SUM(T21:T23) -> 210.98
G27: IVA | H27: =H26*19% -> 265642.8 | M27: =SUM(M21:M26) -> 5.06 | P27: =SUM(P21:P25) -> 153.8464
G28: TOTAL | H28: =H26+H27 -> 1663762.8 | P28: =P27 -> 153.8464 | S28: =SUM(S21:S27) -> 105.86
P29: =P28*20% -> 30.76928 | Q29: 20% PERDIDA | S29: =S28+T26 -> 316.84
P30: =P28+P29 -> 184.61568 | S30: =S29*20% -> 63.368
S31: =S29+S30 -> 380.208 | U31: ADHESIVO | V31: 58.000.- | W31: 44971
M32: =P30 -> 184.61568 | N32: 4000 | O32: =M32*N32 -> 738462.72 | P32: ADHESIVO | U32: LATA 16 LTS | V32: 3625 | W32: LITRO
M33: 13 | N33: 41000 | O33: =M33*N33 -> 533000 | P33: MDF 18MM | V33: 906.25 | W33: MT2 (4)
B34: CUENTA CORRIENTE BANCO SANTANDER Nº 87316181 A NOMBRE DE MUEBLES SANTA FE SPA | M34: 3 | N34: 32090 | O34: =M34*N34 -> 96270 | P34: TAPACANTYO PVC 0,45MM 100 MTS | V34: =V33*20% -> 181.25 | W34: PERDIDA 20%
B35: RUT : 77.054.606-0 CORREO: FRANCODONOSO@TOPMOBILI.CL | M35: 13 | N35: 32807 | O35: =M35*N35 -> 426491 | P35: LAMINA 122X244 | V35: =V33+V34 -> 1087.5 | W35: MINIMO A COTIZAR
A36: GE | B36: VISITANOS Y DESCUBRE NUESTROS PRODUCTOS EN | F36: WWW.TOPMOBILICHILE.CL | N36: 900 | O36: =M36*N36 -> 0 | P36: RESPALDO | R36: 1.52
N37: 2000 | O37: =M37*N37 -> 0 | P37: MEDIA CAÑA | R37: 2.44
O38: =SUM(O32:O37) -> 1794223.7 | P38: COSTO | R38: =R36*R37 -> 3.7088
M39: PRECIO VENTA | O39: =O38*2.2 -> 3947292.2 | P39: FACTOR 2,3 PARA 90° | R39: =P30/R38 -> 49.777739
K40: 42800 | O40: =O39/P28 -> 25657.358 | P40: VALOR M2 | U40: MDF30MM | V40: 43650
K41: =K40/1.19 -> 35966.387 | O41: =O39/O38 -> 2.2 | U41: 46 UNIDADES | V41: 948.91 | W41: 2.4
U42: METRO LINEAL | V42: 395.37
U43: PERDIDA 20% | V43: 474.45
O50: 40935 | P50: MT2 | Q50: TERMO WOOD
C75: ,,,,,,,,,,,,,,,,,,,,,,,,,,,,,,,,,,,,,,,,,,,,,,,,,,,,,,,,,,,,,,,,,,,,,,,,,,,,,,,,,,,,,,,,,,,,,,,,,,,,,,,,,,,,,,,,,,,,,,,,,,,,,,,,,,,,,,,,,,,,,,,,,,,,,,,,,,,,,,,,,,,,,,,,,,,,,,,,,,,,,,,,,,,,,,,,,,,,,,,,,,,,,,,,,,,,,,,,,,,,,,,,,,,,,,,,,,,,,,,,,,,,,,,,,,,,,,,,,,,,,
...

Sheet PUERTAS
F2: MUEBLES SANTA FE SPA
F3: VENTAS POR MENOR DE MUEBLES
F4: RUT: 77.054.606-0
F5: SEPTIMA AVENIDA 1631, SAN MIGUEL
F6: FONO +569 2032 3382 | O6: 10077 SF PORTLAND MAPLE
F7: E-MAIL: ventas@topmobili.cl
B8: P R E S U P U E S T O | D8: N° 12105A
B10: NOMBRE: | C10: ESTEBAN ALBORNOZ CABRERA | F10: FECHA | G10: 46147
B11: RUT: | C11: 12.654.086-6 | F11: PLAZO ENTREGA | G11: 10 DIAS HABILES | R11: MT2 PUERTAS
B12: GIRO: | F12: SERVICIO EXPRESS | G12: NO
B13: CONTACTO: | F13: CORTADA A LA MEDIDA | G13: SI
B14: CORREO: | F14: DESPACHO | G14: NO | R14: ML CUBIERTAS
B15: FONO: | F15: INSTALACIÓN | G15: NO
B16: DIRECCION: | F16: FORMA DE PAGO: | G16: ABONO 50% SALDO C/ENTREGA
B17: CIUDAD: | C17: SANTIAGO | F17: Duración cotización 5 días hábiles | G17: Cotizado por: Franco Donoso
B19: DETALLE | M19: 0.02 | N19: 0.02 | P19: TOTAL | Q19: VALOR X MT2 | R19: ENCHAPE | S19: MT/L
B20: UNIDAD | C20: TIPO | D20: LARGO | E20: ANCHO | F20: COLOR | G20: VALOR | H20: TOTAL | L20: =B20 -> UNIDAD | M20: ALTO | N20: =E20 -> ANCHO | O20: MT | P20: MT2 | Q20: =O55 -> 66047.957 | R20: 3000 | T20: m/l
B21: 6 | C21: E/R 1 CARA | D21: 2.3 | E21: 0.433 | F21: SUNSET 2239 MT | G21: =Q21 -> 69413.761 | H21: =G21*B21 -> 416482.57 | L21: =B21 -> 6 | M21: =D21+M$19 -> 2.32 | N21: =E21+$N$19 -> 0.453 | O21: =M21*N21 -> 1.05096 | P21: =O21*L21 -> 6.30576 | Q21: =Q$20*O21 -> 69413.761 | R21: =Q21+R$20 -> 72413.761 | S21: =M21*L21*2 -> 27.84 | T21: =N21*L21*2 -> 5.436
B22: 2 | C22: E/R 1 CARA | D22: 0.78 | E22: 0.448 | F22: SUNSET 2239 MT | G22: =Q22 -> 24728.355 | H22: =G22*B22 -> 49456.71 | L22: =B22 -> 2 | M22: =D22+M$19 -> 0.8 | N22: =E22+$N$19 -> 0.468 | O22: =M22*N22 -> 0.3744 | P22: =O22*L22 -> 0.7488 | Q22: =Q$20*O22 -> 24728.355 | R22: =Q22+R$20 -> 27728.355 | S22: =M22*L22 -> 1.6 | T22: =N22*2*L22*2 -> 3.744
B23: 4 | C23: E/R 1 CARA | D23: 0.78 | E23: 0.38 | F23: SUNSET 2239 MT | G23: =Q23 -> 21135.346 | H23: =G23*B23 -> 84541.385 | L23: =B23 -> 4 | M23: =D23+M$19 -> 0.8 | N23: =E23+$N$19 -> 0.4 | O23: =M23*N23 -> 0.32 | P23: =O23*L23 -> 1.28 | Q23: =Q$20*O23 -> 21135.346 | R23: =Q23+R$20 -> 24135.346 | S23: =M23*L23 -> 3.2 | T23: =N23*2*L23*2 -> 6.4
B24: 4 | C24: E/R 1 CARA | D24: 0.9 | E24: 0.458 | F24: SUNSET 2239 MT | G24: =Q24 -> 29045.25 | H24: =G24*B24 -> 116181 | L24: =B24 -> 4 | M24: =D24+M$19 -> 0.92 | N24: =E24+$N$19 -> 0.478 | O24: =M24*N24 -> 0.43976 | P24: =O24*L24 -> 1.75904 | Q24: =Q$20*O24 -> 29045.25 | R24: =Q24+R$20 -> 32045.25 | S24: =M24*L24 -> 3.68 | T24: =N24*2*L24*2 -> 7.648
B25: 4 | C25: E/R 1 CARA | D25: 1.398 | E25: 0.458 | F25: SUNSET 2239 MT | G25: =Q25 -> 44767.569 | H25: =G25*B25 -> 179070.28 | L25: =B25 -> 4 | M25: =D25+M$19 -> 1.418 | N25: =E25+$N$19 -> 0.478 | O25: =M25*N25 -> 0.677804 | P25: =O25*L25 -> 2.711216 | Q25: =Q$20*O25 -> 44767.569 | R25: =Q25+R$20 -> 47767.569 | S25: =M25*L25 -> 5.672 | T25: =N25*2*L25*2 -> 7.648
B26: 6 | C26: E/R 1 CARA | D26: 0.9 | E26: 0.31 | F26: SUNSET 2239 MT | G26: =Q26 -> 20052.16 | H26: =G26*B26 -> 120312.96 | L26: =B26 -> 6 | M26: =D26+M$19 -> 0.92 | N26: =E26+$N$19 -> 0.33 | O26: =M26*N26 -> 0.3036 | P26: =O26*L26 -> 1.8216 | Q26: =Q$20*O26 -> 20052.16 | R26: =Q26+R$20 -> 23052.16 | S26: =M26*L26 -> 5.52 | T26: =N26*2*L26*2 -> 7.92
B27: 6 | C27: E/R 1 CARA | D27: 0.78 | E27: 0.31 | F27: SUNSET 2239 MT | G27: =Q27 -> 17436.661 | H27: =G27*B27 -> 104619.96 | L27: =B27 -> 6 | M27: =D27+M$19 -> 0.8 | N27: =E27+$N$19 -> 0.33 | O27: =M27*N27 -> 0.264 | P27: =O27*L27 -> 1.584 | Q27: =Q$20*O27 -> 17436.661 | R27: =Q27+R$20 -> 20436.661 | S27: =M27*L27 -> 4.8 | T27: =N27*2*L27*2 -> 7.92
B28: 4 | C28: E/R 1 CARA | D28: 0.9 | E28: 0.513 | F28: SUNSET 2239 MT | G28: =Q28 -> 32387.276 | H28: =G28*B28 -> 129549.1 | L28: =B28 -> 4 | M28: =D28+M$19 -> 0.92 | N28: =E28+$N$19 -> 0.533 | O28: =M28*N28 -> 0.49036 | P28: =O28*L28 -> 1.96144 | Q28: =Q$20*O28 -> 32387.276 | R28: =Q28+R$20 -> 35387.276 | S28: =M28*L28 -> 3.68 | T28: =N28*2*L28*2 -> 8.528
B29: 4 | C29: E/R 1 CARA | D29: 0.48 | E29: 0.513 | F29: SUNSET 2239 MT | G29: =Q29 -> 17601.781 | H29: =G29*B29 -> 70407.122 | L29: =B29 -> 4 | M29: =D29+M$19 -> 0.5 | N29: =E29+$N$19 -> 0.533 | O29: =M29*N29 -> 0.2665 | P29: =O29*L29 -> 1.066 | Q29: =Q$20*O29 -> 17601.781 | R29: =Q29+R$20 -> 20601.781 | S29: =M29*L29 -> 2 | T29: =N29*2*L29*2 -> 8.528
B30: 4 | C30: E/R 1 CARA | D30: 0.9 | E30: 0.598 | F30: SUNSET 2239 MT | G30: =Q30 -> 37552.226 | H30: =G30*B30 -> 150208.91 | L30: =B30 -> 4 | M30: =D30+M$19 -> 0.92 | N30: =E30+$N$19 -> 0.618 | O30: =M30*N30 -> 0.56856 | P30: =O30*L30 -> 2.27424 | Q30: =Q$20*O30 -> 37552.226 | R30: =Q30+R$20 -> 40552.226 | S30: =M30*L30 -> 3.68 | T30: =N30*2*L30*2 -> 9.888
B31: 4 | C31: E/R 1 CARA | D31: 1.398 | E31: 0.598 | F31: SUNSET 2239 MT | G31: =Q31 -> 57879.41 | H31: =G31*B31 -> 231517.64 | L31: =B31 -> 4 | M31: =D31+M$19 -> 1.418 | N31: =E31+$N$19 -> 0.618 | O31: =M31*N31 -> 0.876324 | P31: =O31*L31 -> 3.505296 | Q31: =Q$20*O31 -> 57879.41 | R31: =Q31+R$20 -> 60879.41 | S31: =M31*L31 -> 5.672 | T31: =N31*2*L31*2 -> 9.888
B32: 4 | C32: E/R 1 CARA | D32: 0.9 | E32: 0.645 | F32: SUNSET 2239 MT | G32: =Q32 -> 40408.14 | H32: =G32*B32 -> 161632.56 | L32: =B32 -> 4 | M32: =D32+M$19 -> 0.92 | N32: =E32+$N$19 -> 0.665 | O32: =M32*N32 -> 0.6118 | P32: =O32*L32 -> 2.4472 | Q32: =Q$20*O32 -> 40408.14 | R32: =Q32+R$20 -> 43408.14 | S32: =M32*L32 -> 3.68 | T32: =N32*2*L32*2 -> 10.64
B33: 4 | C33: E/R 1 CARA | D33: 1.398 | E33: 0.645 | F33: SUNSET 2239 MT | G33: =Q33 -> 62281.242 | H33: =G33*B33 -> 249124.97 | L33: =B33 -> 4 | M33: =D33+M$19 -> 1.418 | N33: =E33+$N$19 -> 0.665 | O33: =M33*N33 -> 0.94297 | P33: =O33*L33 -> 3.77188 | Q33: =Q$20*O33 -> 62281.242 | R33: =Q33+R$20 -> 65281.242 | S33: =M33*L33 -> 5.672 | T33: =N33*2*L33*2 -> 10.64
... B38: 12 | C38: E/R 1 CARA | D38: 0.38 | E38: 0.568 | F38: SUNSET 2239 MT | G38: =Q38 -> 15534.479 | H38: =G38*B38 -> 186413.75 | L38: =B38 -> 12 | M38: =D38+M$19 -> 0.4 | N38: =E38+$N$19 -> 0.588 | O38: =M38*N38 -> 0.2352 | P38: =O38*L38 -> 2.8224 | Q38: =Q$20*O38 -> 15534.479 | R38: =Q38+R$20 -> 18534.479 | S38: =M38*L38 -> 4.8 | T38: =N38*2*L38*2 -> 28.224
G41: NETO | H41: =SUM(H21:H38) -> 2628534.3 | T41: =SUM(T21:T38) -> 159.196
G42: IVA | H42: =H41*19% -> 499421.52 | M42: =SUM(M21:M41) -> 18.232 | P42: =SUM(P21:P40) -> 39.79736
G43: TOTAL | H43: =H41+H42 -> 3127955.8 | P43: =P42 -> 39.79736 | S43: =SUM(S21:S42) -> 91.852
P44: =P43*20% -> 7.959472 | Q44: 20% PERDIDA | S44: =S43+T41 -> 251.048
P45: =P43+P44 -> 47.756832 | S45: =S44*20% -> 50.2096
S46: =S44+S45 -> 301.2576 | U46: ADHESIVO | V46: 58.000.- | W46: 44971
M47: =P45 -> 47.756832 | N47: 4000 | O47: =M47*N47 -> 191027.33 | P47: ADHESIVO | U47: LATA 16 LTS | V47: 3625 | W47: LITRO
M48: 13 | N48: 37000 | O48: =M48*N48 -> 481000 | P48: MDF 18MM | V48: 906.25 | W48: MT2 (4)
B49: CUENTA CORRIENTE BANCO SANTANDER Nº 87316181 A NOMBRE DE MUEBLES SANTA FE SPA | M49: 3 | N49: 32090 | O49: =M49*N49 -> 96270 | P49: TAPACANTYO PVC 0,45MM 100 MTS | V49: =V48*20% -> 181.25 | W49: PERDIDA 20%
...

Sheet CUBIERTAS
F2: MUEBLES SANTA FE SPA
F3: VENTAS POR MENOR DE MUEBLES
F4: RUT: 77.054.606-0
F5: SEPTIMA AVENIDA 1631, SAN MIGUEL
F6: FONO +569 2032 3382 | O6: 10077 SF PORTLAND MAPLE
F7: E-MAIL: ventas@topmobili.cl
B8: P R E S U P U E S T O | D8: N° 12105
B10: NOMBRE: | C10: ESTEBAN ALBORNOZ CABRERA | F10: FECHA | G10: 46137
B11: RUT: | C11: 12.654.086-6 | F11: PLAZO ENTREGA | G11: 10 DIAS HABILES | R11: MT2 PUERTAS
B12: GIRO: | F12: SERVICIO EXPRESS | G12: NO
B13: CONTACTO: | F13: CORTADA A LA MEDIDA | G13: SI
B14: CORREO: | F14: DESPACHO | G14: NO | R14: ML CUBIERTAS
B15: FONO: | F15: INSTALACIÓN | G15: NO
B16: DIRECCION: | F16: FORMA DE PAGO: | G16: ABONO 50% SALDO C/ENTREGA
B17: CIUDAD: | C17: SANTIAGO | F17: Duración cotización 5 días hábiles | G17: Cotizado por: Franco Donoso
B19: DETALLE | M19: 0.08 | P19: TOTAL | Q19: VALOR X MT2 | R19: ENCHAPE | S19: MT/L
B20: UNIDAD | C20: TIPO | D20: LARGO | E20: ANCHO | F20: COLOR | G20: VALOR | H20: TOTAL | L20: =B20 -> UNIDAD | M20: ALTO | N20: =E20 -> ANCHO | O20: MT | P20: MT2 | Q20: =O41 -> 99211.223 | R20: 3000 | T20: m/l
B21: 1 | C21: CUBIERTA CON RESPALDO Y FEENTE 90° | D21: 2.01 | E21: 0.6 | F21: GRAFITO 2174 MT | G21: =Q21 -> 124410.87 | H21: =G21*B21 -> 124410.87 | L21: =B21 -> 1 | M21: =D21+M$19 -> 2.09 | N21: =E21+$N$19 -> 0.6 | O21: =M21*N21 -> 1.254 | P21: =O21*L21 -> 1.254 | Q21: =Q$20*O21 -> 124410.87 | R21: =Q21+R$20 -> 127410.87 | S21: =M21*L21 -> 2.09 | T21: =N21*2*L21*2 -> 2.4
B22: 1 | C22: CUBIERTA CON RESPALDO Y FEENTE 90° | D22: 2.07 | E22: 0.55 | F22: GRAFITO 2174 MT | G22: =Q22 -> 117317.27 | H22: =G22*B22 -> 117317.27 | L22: =B22 -> 1 | M22: =D22+M$19 -> 2.15 | N22: =E22+$N$19 -> 0.55 | O22: =M22*N22 -> 1.1825 | P22: =O22*L22 -> 1.1825 | Q22: =Q$20*O22 -> 117317.27 | R22: =Q22+R$20 -> 120317.27 | S22: =M22*L22 -> 2.15 | T22: =N22*2*L22*2 -> 2.2
B23: 1 | C23: CUBIERTA CON RESPALDO Y FEENTE 90° | D23: 1.88 | E23: 0.5 | F23: GRAFITO 2174 MT | G23: =Q23 -> 97226.999 | H23: =G23*B23 -> 97226.999 | L23: =B23 -> 1 | M23: =D23+M$19 -> 1.96 | N23: =E23+$N$19 -> 0.5 | O23: =M23*N23 -> 0.98 | P23: =O23*L23 -> 0.98 | Q23: =Q$20*O23 -> 97226.999 | R23: =Q23+R$20 -> 100227 | S23: =M23*L23 -> 1.96 | T23: =N23*2*L23*2 -> 2
B24: 1 | C24: CUBIERTA CON RESPALDO Y FEENTE 90° | D24: 2.435 | E24: 0.6 | F24: GRAFITO 2174 MT | G24: =Q24 -> 149709.74 | H24: =G24*B24 -> 149709.74 | L24: =B24 -> 1 | M24: =D24+M$19 -> 2.515 | N24: =E24+$N$19 -> 0.6 | O24: =M24*N24 -> 1.509 | P24: =O24*L24 -> 1.509 | Q24: =Q$20*O24 -> 149709.74 | R24: =Q24+R$20 -> 152709.74 | S24: =M24*L24 -> 2.515
G27: NETO | H27: =SUM(H21:H24) -> 488664.88 | T27: =SUM(T21:T24) -> 6.6
G28: IVA | H28: =H27*19% -> 92846.327 | M28: =SUM(M21:M27) -> 8.715 | P28: =SUM(P21:P26) -> 4.9255
G29: TOTAL | H29: =H27+H28 -> 581511.21 | P29: =P28 -> 4.9255 | S29: =SUM(S21:S28) -> 8.715
P30: =P29*20% -> 0.9851 | Q30: 20% PERDIDA | S30: =S29+T27 -> 15.315
P31: =P29+P30 -> 5.9106 | S31: =S30*20% -> 3.063
S32: =S30+S31 -> 18.378 | U32: ADHESIVO | V32: 58.000.- | W32: 44971
M33: =P31 -> 5.9106 | N33: 4000 | O33: =M33*N33 -> 23642.4 | P33: ADHESIVO | U33: LATA 16 LTS | V33: 3625 | W33: LITRO
M34: 2 | N34: 24910 | O34: =M34*N34 -> 49820 | P34: MDF 18MM | V34: 906.25 | W34: MT2 (4)
B35: CUENTA CORRIENTE BANCO SANTANDER Nº 87316181 A NOMBRE DE MUEBLES SANTA FE SPA | N35: 58860 | O35: =M35*N35 -> 0 | P35: LAMINA 153 X 366 | V35: =V34*20% -> 181.25 | W35: PERDIDA 20%
B36: RUT : 77.054.606-0 CORREO: FRANCODONOSO@TOPMOBILI.CL | M36: 4 | N36: 32807 | O36: =M36*N36 -> 131228 | P36: LAMINA 122X244 | V36: =V34+V35 -> 1087.5 | W36: MINIMO A COTIZAR
A37: GE | B37: VISITANOS Y DESCUBRE NUESTROS PRODUCTOS EN | F37: WWW.TOPMOBILICHILE.CL | N37: 900 | O37: =M37*N37 -> 0 | P37: RESPALDO | R37: 1.52
M38: 8.715 | N38: 2000 | O38: =M38*N38 -> 17430 | P38: MEDIA CAÑA | R38: 2.44
O39: =SUM(O33:O38) -> 222120.4 | P39: COSTO | R39: =R37*R38 -> 3.7088
M40: PRECIO VENTA | O40: =O39*2.2 -> 488664.88 | P40: FACTOR 2,3 PARA 90° | R40: =P31/R39 -> 1.5936691
K41: 42800 | O41: =O40/P29 -> 99211.223 | P41: VALOR M2 | U41: MDF30MM | V41: 43650
K42: =K41/1.19 -> 35966.387 | O42: =O40/O39 -> 2.2 | U42: 46 UNIDADES | V42: 948.91 | W42: 2.4
U43: METRO LINEAL | V43: 395.37
U44: PERDIDA 20% | V44: 474.45
O51: 40935 | P51: MT2 | Q51: TERMO WOOD
...

Sheet COSTOS
B2: CENTRO DE COSTOS POSTFORMADOS
B5: FECHA: | C5: =CUBIERTAS!G10 -> 46137
B6: CLIENTE: | C6: =CUBIERTAS!C10 -> ESTEBAN ALBORNOZ CABRERA | N6: Ventas Equilibrio = | P6: Costos Fijos Totales
B7: DIRECCION: | C7: =CUBIERTAS!#REF! -> #REF! | H7: COSTOS INDIRECTOS DE FABRICA VARIABLES | O7: 1 - | P7: Costos Variables Totales
B8: PRESUPUESTO: | C8: =CUBIERTAS!D8 -> N° 12105 | H8: Q/HRS | I8: $ | J8: DETALLE | K8: TOTAL | L8: TOTAL | P8: Total Venta | X8: =SUM(Q11:Q16) -> 6
H9: CANTIDAD | I9: PRECIO | J9: MATERIA PRIMA INDIRECTA | L9: =SUM(K10:K23) -> 2550 | S9: DETALLE | X9: =(E15-D11)/X8 -> -53037.612
D10: NETO | E10: IVA | F10: TOTAL | H10: 3 | I10: 350 | J10: RESPALDO | K10: =I10*H10 -> 1050 | Q10: UNIDAD | R10: TIPO | S10: LARGO | T10: ANCHO | U10: COLOR | V10: VALOR | W10: TOTAL
C11: MONTO A COBRAR | D11: =CUBIERTAS!H27 -> 488664.88 | E11: =D11*0.19 -> 92846.327 | F11: =E11+D11 -> 581511.21 | H11: 3 | I11: 500 | J11: MEDIA CAÑA | K11: =I11*H11 -> 1500 | Q11: 1 | R11: CUB C/R R8 | S11: 2.8 | T11: 0.62 | U11: MADERA X DEFINIR | V11: 105990 | W11: =V11*Q11 -> 105990 | X11: =V11+$X$9 -> 52952.388 | Y11: 108990
C12: COSTO TOTAL | D12: =SUM(M43:M45) -> 103296.49 | H12: 0 | I12: 7500 | J12: DUROLAC | K12: =I12*H12 -> 0 | Q12: 1 | R12: CUB C/R R8 | S12: 2.3 | T12: 0.62 | U12: MADERA X DEFINIR | V12: 87990 | W12: =V12*Q12 -> 87990 | X12: =V12+$X$9 -> 34952.388 | Y12: 89990
C13: % UTILIDAD | D13: =D11-D12 -> 385368.39 | E13: =(D11/D12)-1 -> 3.7307017 | H13: 0 | I13: 50 | J13: TAPACANTO PVC | K13: =I13*H13 -> 0 | Q13: 1 | R13: CUB C/R R8 | S13: 2.03 | T13: 0.62 | U13: MADERA X DEFINIR | V13: 78990 | W13: =V13*Q13 -> 78990 | X13: =V13+$X$9 -> 25952.388 | Y13: 81990
D14: % utilidad | E14: NETO | F14: UTILIDAD | H14: 0 | I14: 50 | J14: SOBERBIOS | K14: =I14*H14 -> 0 | Q14: 1 | R14: CUB C/R R8 | S14: 1.08 | T14: 0.62 | U14: MADERA X DEFINIR | V14: 39990 | W14: =V14*Q14 -> 39990 | X14: =V14+$X$9 -> -13047.612 | Y14: 39990
C15: PROYECCION | D15: 0.65 | E15: =(100%+D15)*D12 -> 170439.21 | F15: =E15-D12 -> 67142.719 | H15: 0 | I15: 10 | J15: SOPORTE REPISA | K15: =I15*H15 -> 0 | Q15: 1 | R15: CUB C/R R8 | S15: 1.08 | T15: 0.62 | U15: MADERA X DEFINIR | V15: 39990 | W15: =V15*Q15 -> 39990 | X15: =V15+$X$9 -> -13047.612 | Y15: 39990
H16: 1 | J16: PUNTAS | K16: =I16*H16 -> 0 | Q16: 1 | R16: CUB C/R R8 | S16: 2.06 | T16: 0.62 | U16: MADERA X DEFINIR | V16: 79990 | W16: =V16*Q16 -> 79990 | X16: =V16+$X$9 -> 26952.388 | Y16: 83990
B17: M. PRIMA | C17: MATERIAL | D17: NETO | E17: IVA | F17: TOTAL | H17: 1 | J17: TORNILLOS | K17: =I17*H17 -> 0 | Q17: 6 | R17: CORTES 45° | V17: 5000 | W17: =V17*Q17 -> 30000
C18: LAMINA | D18: =CUBIERTAS!O35 -> 0 | E18: =D18*0.19 -> 0 | F18: =SUM(D18:E18) -> 0 | H18: 1 | J18: COLAFRIA | K18: =I18*H18 -> 0 | Q18: 1 | R18: PERFORACION LAVAPLATOS | V18: 10000 | W18: =V18*Q18 -> 10000
C19: MDF 18MM | D19: =CUBIERTAS!O34 -> 49820 | E19: =D19*0.19 -> 9465.8 | F19: =SUM(D19:E19) -> 59285.8 | H19: 1 | J19: LIJAS | K19: =I19*H19 -> 0 | V19: NETO | W19: =SUM(W11:W18) -> 472940 | Y19: =SUM(Y11:Y16)+SUM(W17:W18) -> 484940
C20: ADHESIVO | D20: =CUBIERTAS!O33 -> 23642.4 | E20: =D20*0.19 -> 4492.056 | F20: =SUM(D20:E20) -> 28134.456 | H20: 1 | J20: CARTON | K20: =I20*H20 -> 0 | V20: I.V.A. | W20: =W19*19% -> 89858.6 | Y20: =Y19*0.19 -> 92138.6
A21: =450000*1.2 -> 540000 | C21: TOTAL | D21: =SUM(D18:D20) -> 73462.4 | E21: =SUM(E18:E20) -> 13957.856 | F21: =SUM(F18:F20) -> 87420.256 | H21: 1 | J21: GUAIPE | K21: =I21*H21 -> 0 | M21: =B32/9 -> 2318.8406 | Q21: PLAZO DE ENTREGA : 8 DIAS HABILES | V21: TOTAL | W21: =W19+W20 -> 562798.6 | Y21: =SUM(Y19:Y20) -> 577078.6
A22: =450000*1.2 -> 540000 | B22: M. DE OBRA | C22: PROCESO | D22: COSTO x Hr. | E22: Q Hrs. | F22: TOTAL | H22: 1 | J22: DILUYENTE | K22: =I22*H22 -> 0 | Q22: FORMA DE PAGO: 50% CONTADO, SALDO C/E
A23: =800000*1.2 -> 960000 | B23: =A21/23 -> 23478.261 | C23: CORTE | D23: =B23/9 -> 2608.6957 | E23: 0.5 | F23: =D23*E23 -> 1304.3478 | H23: 1 | J23: CINTA EMBALAJE | K23: =I23*H23 -> 0 | Q23: VALIDEZ COTIZACIÓN: 5 DIAS
A24: 450000 | B24: =A22/23 -> 23478.261 | C24: CORTE LAMINA | D24: =B24/9 -> 2608.6957 | E24: 0.5 | F24: =D24*E24 -> 1304.3478 | H24: Q/HRS | I24: PRECIO | J24: MANO DE OBRA INDIRECTA | K24: VALOR | L24: =SUM(K25:K35) -> 0
A25: 450000 | B25: =A23/23 -> 41739.13 | C25: REBAJE LAMINA | D25: =B25/9 -> 4637.6812 | F25: =D25*E25 -> 0 | H25: 0 | I25: =((480000/23)/9) -> 2318.8406 | J25: FLETERO (HRS) | K25: =H25*I25 -> 0
B26: =A24/23 -> 19565.217 | C26: TUPIZADO | D26: =B26/9 -> 2173.913 | E26: 0.5 | F26: =D26*E26 -> 1086.9565 | H26: 0 | J26: BENCINA | K26: =H26*I26 -> 0
A27: 350000 | B27: =A25/23 -> 19565.217 | C27: ARMADO | D27: =B27/9 -> 2173.913 | E27: 0.5 | F27: =D27*E27 -> 1086.9565 | H27: 0 | J27: TAG | K27: =H27*I27 -> 0
A28: 500000 | B28: =A27/23 -> 15217.391 | C28: PEGADO | D28: =B28/9 -> 1690.8213 | E28: 0.7 | F28: =D28*E28 -> 1183.5749 | H28: 0 | J28: RECTIFICACION | K28: =H28*I28 -> 0
B29: =A28/23 -> 21739.13 | C29: POSTFORMADO | D29: =B29/9 -> 2415.4589 | E29: 0.7 | F29: =D29*E29 -> 1690.8213 | H29: 0 | I29: =((550000*1.2)/23)/9 -> 3188.4058 | J29: HR. TRAB. JUAN | K29: =H29*I29 -> 0
A30: 450000 | C30: MEDIA CAÑA | D30: 2415 | F30: =D30*E30 -> 0 | H30: 0 | I30: =((450000*1.2)/23)/9 -> 2608.6957 | J30: HR. TRAB. JULIO | K30: =H30*I30 -> 0
A31: 350000 | B31: =A30/23 -> 19565.217 | C31: CORTE-ENCHAPE | D31: =B31/9 -> 2173.913 | E31: 0 | F31: =D31*E31 -> 0 | H31: 0 | I31: =((450000*1.2)/23)/9 -> 2608.6957 | J31: HR. TRAB. EUGE | K31: =H31*I31 -> 0
A32: =A21+A24+A27+A28+A30 -> 2290000 | B32: =480000/23 -> 20869.565 | C32: CONTROL CALIDAD | D32: =B32/9 -> 2318.8406 | E32: 0.5 | F32: =D32*E32 -> 1159.4203 | H32: 0 | J32: COLACION | K32: =H32*I32 -> 0
C33: TOTAL | D33: =SUM(D23:D32) -> 25216.932 | E33: =SUM(E23:E32) -> 3.9 | F33: =SUM(F23:F32) -> 8816.4251 | H33: 0 | J33: BONO | K33: =H33*I33 -> 0
B34: CIF | C34: M. PRIMA INDIREC. | D34: =L9 -> 2550 | H34: 1 | J34: PERFORACION | K34: =H34*I34 -> 0
C35: M. OBRA INDIRECTA | D35: =L24 -> 0 | H35: 6 | J35: CORTE 45 | K35: =H35*I35 -> 0
C36: GASTOS DE FABRICA | D36: =L36 -> 18467.666 | H36: CANTIDAD | I36: PRECIO | J36: GASTOS DE FABRICACION | K36: VALOR | L36: =SUM(K37:K39) -> 18467.666
C37: DEPRECIACIONES | H37: =$E$33 -> 3.9 | I37: =32609.69/9 -> 3623.2989 | J37: ARRIENDO x HORA | K37: =I37*H37 -> 14130.866
C38: TOTAL | D38: =SUM(D34:D37) -> 21017.666 | H38: =$E$33 -> 3.9 | I38: 967 | J38: AGUA x HORA | K38: =I38*H38 -> 3771.3
H39: =$E$33 -> 3.9 | I39: 145 | J39: LUZ x HORA | K39: =I39*H39 -> 565.5
B40: PROVISIONAR | C40: IVA | D40: =E11-E21 -> 78888.471
H41: ESTADO DE RESULTADOS
B42: TOTAL HRS TRABAJADAS | D42: =E33 -> 3.9 | H42: INGRESOS | I42: + TOTAL VENTA | M42: =D11 -> 488664.88
H43: COSTOS | I43: - MATERIA PRIMA DIRECTA | M43: =D21 -> 73462.4
...

Sheet NOTA DE VENTA
F2: MUEBLES SANTA FE SPA
F3: VENTAS POR MENOR DE MUEBLES
F4: RUT: 77.054.606-0
F5: SEPTIMA AVENIDA 1631, SAN MIGUEL
F6: CELULAR: 963868755
F7: E-MAIL: fdonoso@topmobili.cl
B8: P R E S U P U E S T O | D8: =CUBIERTAS!D8 -> N° 12105 | F8: NOTA DE VENTA :
B10: CLIENTE: | C10: =IF(CUBIERTAS!C10="","",CUBIERTAS!C10) -> ESTEBAN ALBORNOZ CABRERA | F10: FECHA : | G10: =CUBIERTAS!G10 -> 46137
B11: RUT: | C11: =IF(CUBIERTAS!C11="","",CUBIERTAS!C11) -> 12.654.086-6 | F11: FECHA LIMITE : | G11: =WORKDAY(G10,5) -> 46143
B12: GIRO: | C12: =IF(CUBIERTAS!C12="","",CUBIERTAS!C12) | F12: DESPACHO: | G12: =CUBIERTAS!G14 -> NO
B13: CONTACTO: | C13: =IF(CUBIERTAS!C13="","",CUBIERTAS!C13) | F13: ORDEN DE COMPRA:
B14: CORREO: | C14: =IF(CUBIERTAS!C14="","",CUBIERTAS!C14) | F14: HECHO POR: | G14: FERNANDO DONOSO
B15: FONO: | C15: =IF(CUBIERTAS!C15="","",CUBIERTAS!C15) | F15: SERVICIO EXPRESS: | G15: =CUBIERTAS!G12 -> NO
B16: DIRECCION: | C16: =IF(CUBIERTAS!C16="","",CUBIERTAS!C16) | F16: FORMA DE PAGO : | G16: =CUBIERTAS!G16 -> ABONO 50% SALDO C/ENTREGA
B17: CIUDAD: | C17: =IF(CUBIERTAS!C17="","",CUBIERTAS!C17) -> SANTIAGO | F17: VALIDEZ COTIZACIÓN: 5 DÍAS
B20: D E T A L L E
B21: UNIDAD | C21: TIPO | D21: LARGO | E21: ANCHO | F21: COLOR | G21: VALOR | H21: TOTAL
B22: =CUBIERTAS!B21 -> 1 | C22: =CUBIERTAS!C21 -> CUBIERTA CON RESPALDO Y FEENTE 90° | D22: =CUBIERTAS!D21*1000 -> 2010 | E22: =CUBIERTAS!E21*1000 -> 600 | F22: =CUBIERTAS!F21 -> GRAFITO 2174 MT | G22: =CUBIERTAS!G21 -> 124410.87 | H22: =G22*B22 -> 124410.87
G25: NETO | H25: =SUM(H22:H24) -> 124410.87
G26: I.V.A. | H26: =H25*19% -> 23638.066
G27: TOTAL | H27: =H25+H26 -> 148048.94
B30: CUENTA VISTA DEL BANCO ESTADO N° 35571389078 A NOMBRE DE
B31: "MUEBLES SANTA FE SPA." - RUT : 77.054.606-0, VENTAS@TOPMOBILI.CL
B32: VISITANOS Y DESCUBRE NUESTROS PRODUCTOS EN | E32: WWW.TOPMOBILICHILE.CL

Sheet REGLAS
B2: DETALLE CORTE LAMINA | G2: DETALLE CORTE SUSTRATO | P2: DETALLE CORTE MERA
B3: ALTO | C3: ANCHO | D3: TIPO | G3: ALTO | H3: ANCHO | I3: TIPO | P3: ALTO | Q3: ANCHO | R3: TIPO
B4: 40 | C4: 60 | D4: CEN 1V | E4: A1 | G4: 50 | H4: 100 | I4: CEN 1V | J4: REGLA SIEMPRE LLEVAR MEDIDA MINIMO A 100 | P4: 50 | Q4: -30 | R4: CUB C/R
B5: 40 | C5: 90 | D5: CEN 2V | E5: A2 | G5: 50 | I5: CEN 2V | J5: REGLA SIEMPRE LLEVAR MEDIDA MINIMO A 101 | P5: 50 | Q5: -30 | R5: CUB C/R
B6: 40 | C6: 100 | D6: CORNISA FRENTE ESPAÑOL 1 LADO | E6: A3 | G6: 50 | H6: 100 | I6: CORNISA FRENTE ESPAÑOL 1 LADO | P6: 50 | Q6: -30 | R6: CUB C/R 180°
B7: 40 | C7: 150 | D7: CORNISA FRENTE ESPAÑOL 2 LADO | E7: A4 | G7: 50 | I7: CORNISA FRENTE ESPAÑOL 2 LADO | P7: 50 | Q7: -30 | R7: CUB C/R FRENTE ESPAÑOL
B8: 40 | C8: 100 | D8: CORNISA 180° 1LADO | E8: A5 | G8: 50 | H8: 100 | I8: CORNISA 180° 1LADO | L8: DETALLE CORTE MERA | P8: 50 | Q8: -30 | R8: CUB C/R PUNTA 1 LADO
B9: 40 | C9: 50 | D9: CORNISA PUNTA TIBURON 1 LADO | E9: B | G9: 50 | H9: 100 | I9: CORNISA 1LADO | L9: ALTO | M9: ANCHO | N9: TIPO | P9: 50 | Q9: 0 | R9: CUB S/R FRENTE ESPAÑOL
B10: 40 | C10: 80 | D10: CORNISA PUNTA TIBURON 2 LADOS | E10: C | G10: 50 | I10: CORNISA 2 LADOS | L10: 50 | M10: -30 | N10: CUB C/R | P10: 50 | Q10: 0 | R10: CUB S/R
B11: 40 | C11: 60 | D11: CORNISA R8 1LADO | E11: D | G11: 50 | H11: 100 | I11: CORNISA PUNTA TIBURON 1 LADO | L11: 50 | M11: 0 | N11: CUB S/R y CUB MESA | P11: 50 | Q11: 0 | R11: CUB MESA 180° 2 LADOS
B12: 40 | C12: 100 | D12: CORNISA R8 2 LADOS | E12: E | G12: 50 | I12: CORNISA PUNTA TIBURON 2 LADOS | L12: 50 | M12: -2 | N12: PR | P12: 50 | Q12: 0 | R12: CUB MESA 180° 3 LADOS
B13: 40 | C13: 130 | D13: CUB C/R R6 | E13: F | G13: 50 | H13: -30 | I13: CUB C/R | P13: 50 | Q13: 0 | R13: CUB MESA 180° 4 LADOS
B14: 40 | C14: 150 | D14: CUB C/R 180° | G14: 50 | H14: -30 | I14: CUB C/R 180°
B15: 40 | C15: 150 | D15: CUB C/R FRENTE ESPAÑOL | E15: G | G15: 50 | H15: -30 | I15: CUB C/R FRENTE ESPAÑOL | P15: 50 | Q15: 0 | R15: CUB MESA 4 LADOS
B16: 40 | C16: 130 | D16: CUB C/R R2 | E16: H | G16: 50 | H16: -30 | I16: CUB C/R PUNTA TIBURON 1 LADO | P16: 50 | Q16: 0 | R16: CUB MESA FRENTE ESPAÑOL 2 LADOS
B17: 40 | C17: 150 | D17: CUB MESA 180° 2 LADOS | E17: I | G17: 50 | I17: CUB MESA 180° 2 LADOS | P17: 50 | Q17: 0 | R17: CUB MESA FRENTE ESPAÑOL 3 LADOS
B18: 140 | C18: 150 | D18: CUB MESA 180° 3 LADOS | E18: J | G18: 50 | I18: CUB MESA 180° 3 LADOS | P18: 50 | Q18: 0 | R18: CUB MESA FRENTE ESPAÑOL 4 LADOS
B19: 150 | C19: 150 | D19: CUB MESA 180° 4 LADOS | E19: K | G19: 50 | I19: CUB MESA 180° 4 LADOS | P19: 50 | Q19: 0 | R19: CUB MESA PUNTA TIBURON 2 LADOS
B20: 40 | C20: 100 | D20: CUB MESA 2L | E20: L | G20: 50 | H20: 0 | I20: CUB MESA 2L | J20: ES IGUAL A LO PEDIDO NO SE DEBE SUMAR NI RESTAR | P20: 50 | Q20: 0 | R20: CUB MESA PUNTA TIBURON 3 LADOS
B21: 100 | C21: 100 | D21: CUB MESA 3L | E21: M | G21: 50 | H21: 0 | I21: CUB MESA 3L | P21: 50 | Q21: 0 | R21: CUB MESA PUNTA TIBURON 4 LADOS
B22: 100 | C22: 100 | D22: CUB MESA 4 LADOS | E22: N | I22: CUB MESA 4 LADOS | P22: 50 | Q22: 0 | R22: CUB PUNTA TIBURON 1 LADO
B23: 40 | C23: 150 | D23: CUB MESA FRENTE ESPAÑOL 2 LADOS | E23: O | G23: 50 | I23: CUB MESA FRENTE ESPAÑOL 2 LADOS | R23: CENEFA 1 LADO
B24: 140 | C24: 150 | D24: CUB MESA FRENTE ESPAÑOL 3 LADOS | E24: P | G24: 50 | I24: CUB MESA FRENTE ESPAÑOL 3 LADOS | R24: CENEFA 2 LADOS
B25: 150 | C25: 150 | D25: CUB MESA FRENTE ESPAÑOL 4 LADOS | E25: Q | G25: 50 | I25: CUB MESA FRENTE ESPAÑOL 4 LADOS | R25: CORNISA FRENTE ESPAÑOL 1 LADO
B26: 40 | C26: 77 | D26: CUB MESA PUNTA TIBURON 2 LADOS | E26: R | G26: 50 | I26: CUB MESA PUNTA TIBURON 2 LADOS | R26: CORNISA FRENTE ESPAÑOL 2 LADO
B27: 110 | C27: 77 | D27: CUB MESA PUNTA TIBURON 3 LADOS | E27: S | G27: 50 | I27: CUB MESA PUNTA TIBURON 3 LADOS | R27: CORNISA 180° 1LADO
B28: 120 | C28: 77 | D28: CUB MESA PUNTA TIBURON 4 LADOS | E28: T | G28: 50 | I28: CUB MESA PUNTA TIBURON 4 LADOS | R28: CORNISA 1LADO
B29: 40 | C29: 50 | D29: CUB PUNTA TIBURON 1 LADO | E29: U | G29: 50 | I29: CUB PUNTA TIBURON 1 LADO | R29: CORNISA 2 LADOS
B30: 40 | C30: 60 | D30: CUB S/R | E30: V | G30: 50 | I30: CUB S/R | R30: CORNISA PUNTA TIBURON 1 LADO
B31: 40 | C31: 100 | D31: CUB S/R FRENTE ESPAÑOL | E31: W | G31: 50 | I31: CUB S/R FRENTE ESPAÑOL | R31: CORNISA PUNTA TIBURON 2 LADOS
B32: 40 | C32: 60 | D32: CUB S/R R2 | E32: X | G32: 50 | I32: CUB S/R R2 | R32: PR2
B33: 40 | C33: 90 | D33: PR12 | E33: Y | G33: 50 | H33: -2 | I33: PR12 | R33: PR6
B34: 40 | C34: 90 | D34: PR19 | G34: 50 | H34: -2 | I34: PR19
B35: 40 | C35: 90 | D35: PR2 | E35: Z | G35: 50 | H35: -2 | I35: PR2 | R35: PR8
B36: 40 | C36: 90 | D36: PR6 | G36: 50 | H36: -2 | I36: PR6 | R36: PR12
B37: 40 | C37: 90 | D37: PR8 | G37: 50 | H37: -2 | I37: PR8 | R37: PR19
B48: 40 | C48: 150

Sheet PRODUCCION
K2: NO BORRAR REGLAS!!!!! SI NO LAS SABEN USAR NO BORREN ESTO POR FAVOR!!!!!
K3: SUSTRATO | M3: LAMINADO
C4: NOTA DE VENTA : | D4: =IF('NOTA DE VENTA'!$G$8="","",'NOTA DE VENTA'!$G$8) | K4: ALTO | L4: ANCHO | M4: ALTO | N4: ANCHO
C5: CLIENTE : | D5: ='NOTA DE VENTA'!$C$10 -> ESTEBAN ALBORNOZ CABRERA | K5: =LOOKUP(F14,REGLAS!$I$4:$I$37,REGLAS!$G$4:$G$37)+J14 -> 1850 | L5: =LOOKUP(F14,REGLAS!$I$4:$I$37,REGLAS!$H$4:$H$37)+K14 -> 470 | M5: =LOOKUP(F14,REGLAS!$D$4:$D$37,REGLAS!$B$4:$B$37)+J21 -> 1840 | N5: =H10 -> 0
C7: ='NOTA DE VENTA'!$F$10 -> FECHA : | D7: ='NOTA DE VENTA'!$G$10 -> 46137
C8: FECHA ENTREGA: | D8: ='NOTA DE VENTA'!$G$11 -> 46143
A10: SUSTRATO
D12: ALTO | E12: ANCHO
A13: MATERIAL | B13: CANTIDAD | C13: CORTE | D13: 80 | E13: -30 | F13: DESCRIPCIÓN | J13: ALTO | K13: ANCHO
A14: MDF 18MM | B14: =I14 -> 1 | D14: =LOOKUP(F14,REGLAS!$I$4:$I$37,REGLAS!$G$4:$G$37)+J14 -> 1850 | E14: =LOOKUP(F14,REGLAS!$I$4:$I$37,REGLAS!$H$4:$H$37)+K14 -> 470 | F14: =C27 -> CUB C/R R8 | I14: =I21 -> 1 | J14: =D27 -> 1800 | K14: =E27 -> 500
A17: LAMINADO
D19: ALTO | E19: ANCHO
A20: MATERIAL | B20: CANTIDAD | C20: CORTE | D20: 40 | E20: 130 | F20: DESCRIPCIÓN | J20: ALTO | K20: ANCHO
A21: MDF 18MM | B21: =I21 -> 1 | D21: =LOOKUP(F14,REGLAS!$D$4:$D$37,REGLAS!$B$4:$B$37)+J21 -> 1840 | E21: =LOOKUP(F14,REGLAS!$D$4:$D$37,REGLAS!$C$4:$C$37)+K21 -> 630 | F21: =C27 -> CUB C/R R8 | I21: =B27 -> 1 | J21: =D27 -> 1800 | K21: =E27 -> 500
B24: MEDIDAS ORIGINALES
A26: MATERIAL | B26: CANTIDAD | C26: DESCRIPCIÓN | D26: ALTO | E26: ANCHO | F26: COLOR
A27: MDF 18MM | B27: ='[1]4637'!B21 -> 1 | C27: ='[1]4637'!C21 -> CUB C/R R8 | D27: ='[1]4637'!D21 -> 1800 | E27: ='[1]4637'!E21 -> 500 | F27: ='[1]4637'!F21 -> LATE 2167 MT
C39: NOTA DE VENTA : | D39: ='[1]4637'!G8 -> 7332
C40: CLIENTE : | D40: ='[1]4637'!C10 -> FMR MAKING SPA
C42: ='[1]4637'!F11 -> FECHA LIMITE : | D42: ='[1]4637'!G11 -> 45996
A45: PRODUCCIÓN
B47: DETALLE
B48: CANTIDAD | C48: CORTE | D48: ALTO | E48: ANCHO | F48: DESCRIPCION
A49: MDF18MM | B49: ='[1]4637'!B21 -> 1 | C49: ='[1]4637'!C21 -> CUB C/R R8 | D49: ='[1]4637'!D21 -> 1800 | E49: ='[1]4637'!E21 -> 500 | F49: ='[1]4637'!F21 -> LATE 2167 MT

Sheet SEGUIMIENTO
A1: NV | B1: N° COTIZA | C1: FECHA | D1: ENTREGA | E1: NOMBRE | F1: DETALLE | G1: COLOR | H1: NETO | I1: IVA | J1: TOTAL | K1: ABONO | L1: SALDO | M1: ESTADO
A2: ='NOTA DE VENTA'!$G$8 -> 0 | B2: ='NOTA DE VENTA'!$D$8 -> N° 12105 | C2: ='NOTA DE VENTA'!$G$10 -> 46137 | D2: ='NOTA DE VENTA'!$G$11 -> 46143 | E2: ='NOTA DE VENTA'!$C$10 -> ESTEBAN ALBORNOZ CABRERA | F2: ='NOTA DE VENTA'!$C$22 -> CUBIERTA CON RESPALDO Y FEENTE 90° | G2: ='NOTA DE VENTA'!$F$22 -> GRAFITO 2174 MT | H2: ='NOTA DE VENTA'!$H$25 -> 124410.87 | I2: =H2*0.19 -> 23638.066 | J2: =I2+H2 -> 148048.94 | L2: =J2-K2 -> 148048.94
