Workbook

Sheet 2229
G2: MUEBLES SANTA FE SPA
G3: VENTAS POR MENOR DE MUEBLES
G4: RUT: 77.054.606-0
G5: SEPTIMA AVENIDA 1631, SAN MIGUEL
G6: FONO +569 2032 3382 | P6: 10077 SF PORTLAND MAPLE
G7: E-MAIL: ventas@topmobili.cl
B8: P R E S U P U E S T O | D8: N° 11391
B10: NOMBRE: | C10: SISTEMA MUEBLES | G10: FECHA: | H10: 45757
B11: RUT: | G11: PLAZO ENTREGA: | H11: A CONVENIR | S11: MT2 PUERTAS
B12: GIRO: | G12: SERVICIO EXPRESS | H12: NO
B13: CONTACTO: | C13: MARIOLI CONCHA
B14: CORREO: | G14: CORTADA A LA MEDIDA | H14: NO | S14: ML CUBIERTAS
B15: FONO: | C15: +569 9408 2633 | G15: DESPACHO: | H15: NO
B16: DIRECCION: | G16: FORMA DE PAGO: | H16: ABONO 50% SALDO C/ENTREGA
B17: CIUDAD: | C17: SANTIAGO | G17: DURACION COTIZACION: 5 DIAS FRANCO DONOSO
B19: DETALLE | N19: 0.08 | Q19: TOTAL | R19: VALOR X MT2 | S19: ENCHAPE | T19: MT/L
B20: UNIDAD | C20: TIPO | D20: LARGO | E20: ANCHO | G20: COLOR | H20: VALOR | I20: TOTAL | M20: =B20 -> UNIDAD | N20: ALTO | O20: =E20 -> ANCHO | P20: MT | Q20: MT2 | R20: =P73 -> 132809.65 | S20: 3000 | U20: m/l
B21: 1 | C21: CUB C/R 90° R8 MDF 25MM | D21: 1.05 | E21: 0.6 | F21: M03 | G21: PUMIC GREY 21321 TRASCARA BLANCO OPACO | H21: 93045 | I21: =H21*B21 -> 93045 | M21: =B21 -> 1 | N21: =D21+N$19 -> 1.13 | O21: =E21+$O$19 -> 0.6 | P21: =N21*O21 -> 0.678 | Q21: =P21*M21 -> 0.678 | R21: =R$20*P21 -> 90044.946 | S21: =R21+S$20 -> 93044.946 | T21: =M21*N21*2 -> 2.26 | U21: =O21*2*M21*2 -> 2.4 | W21: =M21*S21 -> 93044.946
B22: 1 | C22: CUB C/R 90° R8 MDF 25MM | D22: 1.2 | E22: 0.6 | F22: M03 | G22: PUMIC GREY 21321 TRASCARA BLANCO OPACO | H22: 104998 | I22: =H22*B22 -> 104998 | M22: =B22 -> 1 | N22: =D22+N$19 -> 1.28 | O22: =E22+$O$19 -> 0.6 | P22: =N22*O22 -> 0.768 | Q22: =P22*M22 -> 0.768 | R22: =R$20*P22 -> 101997.81 | S22: =R22+S$20 -> 104997.81 | T22: =M22*N22*2 -> 2.56 | W22: =M22*S22 -> 104997.81
B23: 3 | C23: CUB C/R 90° R8 MDF 25MM | D23: 1.3 | E23: 0.6 | F23: M03 | G23: PUMIC GREY 21321 TRASCARA BLANCO OPACO | H23: 112966 | I23: =H23*B23 -> 338898 | M23: =B23 -> 3 | N23: =D23+N$19 -> 1.38 | O23: =E23+$O$19 -> 0.6 | P23: =N23*O23 -> 0.828 | Q23: =P23*M23 -> 2.484 | R23: =R$20*P23 -> 109966.39 | S23: =R23+S$20 -> 112966.39 | T23: =M23*N23*2 -> 8.28 | W23: =M23*S23 -> 338899.18
B24: 15 | C24: CUB C/R 90° R8 MDF 25MM | D24: 1.5 | E24: 0.6 | F24: M03 | G24: PUMIC GREY 21321 TRASCARA BLANCO OPACO | H24: 128904 | I24: =H24*B24 -> 1933560 | M24: =B24 -> 15 | N24: =D24+N$19 -> 1.58 | O24: =E24+$O$19 -> 0.6 | P24: =N24*O24 -> 0.948 | Q24: =P24*M24 -> 14.22 | R24: =R$20*P24 -> 125903.55 | S24: =R24+S$20 -> 128903.55 | T24: =M24*N24*2 -> 47.4 | W24: =M24*S24 -> 1933553.3
B25: 1 | C25: CUB C/R 90° R8 MDF 25MM | D25: 1.65 | E25: 0.6 | F25: M03 | G25: PUMIC GREY 21321 TRASCARA BLANCO OPACO | H25: 140856 | I25: =H25*B25 -> 140856 | M25: =B25 -> 1 | N25: =D25+N$19 -> 1.73 | O25: =E25+$O$19 -> 0.6 | P25: =N25*O25 -> 1.038 | Q25: =P25*M25 -> 1.038 | R25: =R$20*P25 -> 137856.42 | S25: =R25+S$20 -> 140856.42 | T25: =M25*N25*2 -> 3.46 | W25: =M25*S25 -> 140856.42
B26: 1 | C26: CUB C/R 90° R8 MDF 25MM | D26: 2.2 | E26: 0.6 | F26: M03 | G26: PUMIC GREY 21321 TRASCARA BLANCO OPACO | H26: 184684 | I26: =H26*B26 -> 184684 | M26: =B26 -> 1 | N26: =D26+N$19 -> 2.28 | O26: =E26+$O$19 -> 0.6 | P26: =N26*O26 -> 1.368 | Q26: =P26*M26 -> 1.368 | R26: =R$20*P26 -> 181683.61 | S26: =R26+S$20 -> 184683.61 | T26: =M26*N26*2 -> 4.56 | W26: =M26*S26 -> 184683.61
B27: 1 | C27: CUB C/R 90° R8 MDF 25MM | D27: 2.4 | E27: 0.6 | F27: M03A | G27: PUMIC GREY 21321 TRASCARA BLANCO OPACO | H27: 200621 | I27: =H27*B27 -> 200621 | M27: =B27 -> 1 | N27: =D27+N$19 -> 2.48 | O27: =E27+$O$19 -> 0.6 | P27: =N27*O27 -> 1.488 | Q27: =P27*M27 -> 1.488 | R27: =R$20*P27 -> 197620.77 | S27: =R27+S$20 -> 200620.77 | T27: =M27*N27*2 -> 4.96 | W27: =M27*S27 -> 200620.77
B28: 1 | C28: CUB C/R 90° R8 MDF 25MM | D28: 1 | E28: 0.6 | F28: M03A | G28: PUMIC GREY 21321 TRASCARA BLANCO OPACO | H28: 89061 | I28: =H28*B28 -> 89061 | M28: =B28 -> 1 | N28: =D28+N$19 -> 1.08 | O28: =E28+$O$19 -> 0.6 | P28: =N28*O28 -> 0.648 | Q28: =P28*M28 -> 0.648 | R28: =R$20*P28 -> 86060.656 | S28: =R28+S$20 -> 89060.656 | T28: =M28*N28*2 -> 2.16 | W28: =M28*S28 -> 89060.656
B29: 2 | C29: CUB C/R 90° R8 MDF 25MM | D29: 1 | E29: 0.6 | F29: M04 | G29: PUMIC GREY 21321 TRASCARA BLANCO OPACO | H29: 89061 | I29: =H29*B29 -> 178122 | M29: =B29 -> 2 | N29: =D29+N$19 -> 1.08 | O29: =E29+$O$19 -> 0.6 | P29: =N29*O29 -> 0.648 | Q29: =P29*M29 -> 1.296 | R29: =R$20*P29 -> 86060.656 | S29: =R29+S$20 -> 89060.656 | T29: =M29*N29*2 -> 4.32 | W29: =M29*S29 -> 178121.31
B30: 1 | C30: CUB C/R 90° R8 MDF 25MM | D30: 1.2 | E30: 0.6 | F30: M04 | G30: PUMIC GREY 21321 TRASCARA BLANCO OPACO | H30: 104998 | I30: =H30*B30 -> 104998 | M30: =B30 -> 1 | N30: =D30+N$19 -> 1.28 | O30: =E30+$O$19 -> 0.6 | P30: =N30*O30 -> 0.768 | Q30: =P30*M30 -> 0.768 | R30: =R$20*P30 -> 101997.81 | S30: =R30+S$20 -> 104997.81 | T30: =M30*N30*2 -> 2.56 | W30: =M30*S30 -> 104997.81
B31: 2 | C31: CUB C/R 90° R8 MDF 25MM | D31: 1.55 | E31: 0.6 | F31: M04 | G31: PUMIC GREY 21321 TRASCARA BLANCO OPACO | H31: 132888 | I31: =H31*B31 -> 265776 | M31: =B31 -> 2 | N31: =D31+N$19 -> 1.63 | O31: =E31+$O$19 -> 0.6 | P31: =N31*O31 -> 0.978 | Q31: =P31*M31 -> 1.956 | R31: =R$20*P31 -> 129887.84 | S31: =R31+S$20 -> 132887.84 | T31: =M31*N31*2 -> 6.52 | W31: =M31*S31 -> 265775.68
B32: 1 | C32: CUB C/R 90° R8 MDF 25MM | D32: 1.6 | E32: 0.6 | F32: M04 | G32: PUMIC GREY 21321 TRASCARA BLANCO OPACO | H32: 136872 | I32: =H32*B32 -> 136872 | K32: MDF 25MM | M32: =B32 -> 1 | N32: =D32+N$19 -> 1.68 | O32: =E32+$O$19 -> 0.6 | P32: =N32*O32 -> 1.008 | Q32: =P32*M32 -> 1.008 | R32: =R$20*P32 -> 133872.13 | S32: =R32+S$20 -> 136872.13 | T32: =M32*N32*2 -> 3.36 | W32: =M32*S32 -> 136872.13
B33: 1 | C33: CUB C/R 90° R8 MDF 25MM | D33: 2.5 | E33: 0.6 | F33: M04 | G33: PUMIC GREY 21321 TRASCARA BLANCO OPACO | H33: 208589 | I33: =H33*B33 -> 208589 | K33: 6.25 | M33: =B33 -> 1 | N33: =D33+N$19 -> 2.58 | O33: =E33+$O$19 -> 0.6 | P33: =N33*O33 -> 1.548 | Q33: =P33*M33 -> 1.548 | R33: =R$20*P33 -> 205589.35 | S33: =R33+S$20 -> 208589.35 | T33: =M33*N33*2 -> 5.16 | W33: =M33*S33 -> 208589.35
B34: 2 | C34: CUB C/R 90° R8 MDF 25MM | D34: 2.15 | E34: 0.6 | F34: M04 | G34: PUMIC GREY 21321 TRASCARA BLANCO OPACO | H34: 180699 | I34: =H34*B34 -> 361398 | K34: 2 | M34: =B34 -> 2 | N34: =D34+N$19 -> 2.23 | O34: =E34+$O$19 -> 0.6 | P34: =N34*O34 -> 1.338 | Q34: =P34*M34 -> 2.676 | R34: =R$20*P34 -> 177699.32 | S34: =R34+S$20 -> 180699.32 | T34: =M34*N34*2 -> 8.92 | W34: =M34*S34 -> 361398.64
B35: 2 | C35: CUB C/R 90° R8 MDF 25MM | D35: 1.68 | E35: 0.6 | F35: M04A | G35: PUMIC GREY 21321 TRASCARA BLANCO OPACO | H35: 143247 | I35: =H35*B35 -> 286494 | K35: 17 | M35: =B35 -> 2 | N35: =D35+N$19 -> 1.76 | O35: =E35+$O$19 -> 0.6 | P35: =N35*O35 -> 1.056 | Q35: =P35*M35 -> 2.112 | R35: =R$20*P35 -> 140247 | S35: =R35+S$20 -> 143247 | T35: =M35*N35*2 -> 7.04 | W35: =M35*S35 -> 286493.99
B36: 2 | C36: CUB C/R 90° R8 MDF 25MM | D36: 1.98 | E36: 0.6 | F36: M04A | G36: PUMIC GREY 21321 TRASCARA BLANCO OPACO | H36: 167153 | I36: =H36*B36 -> 334306 | K36: =SUM(K33:K35) -> 25.25 | M36: =B36 -> 2 | N36: =D36+N$19 -> 2.06 | O36: =E36+$O$19 -> 0.6 | P36: =N36*O36 -> 1.236 | Q36: =P36*M36 -> 2.472 | R36: =R$20*P36 -> 164152.73 | S36: =R36+S$20 -> 167152.73 | T36: =M36*N36*2 -> 8.24 | W36: =M36*S36 -> 334305.47
B37: 2 | C37: CUB C/R 90° R8 MDF 25MM | D37: 2.29 | E37: 0.6 | F37: M04A | G37: PUMIC GREY 21321 TRASCARA BLANCO OPACO | H37: 191855 | I37: =H37*B37 -> 383710 | M37: =B37 -> 2 | N37: =D37+N$19 -> 2.37 | O37: =E37+$O$19 -> 0.6 | P37: =N37*O37 -> 1.422 | Q37: =P37*M37 -> 2.844 | R37: =R$20*P37 -> 188855.33 | S37: =R37+S$20 -> 191855.33 | T37: =M37*N37*2 -> 9.48 | W37: =M37*S37 -> 383710.66
B38: 4 | C38: CUB C/R 90° R8 MDF 25MM | D38: 1.6 | E38: 0.3 | F38: M05A | G38: PUMIC GREY 21321 TRASCARA BLANCO OPACO | H38: 69936 | I38: =H38*B38 -> 279744 | M38: =B38 -> 4 | N38: =D38+N$19 -> 1.68 | O38: =E38+$O$19 -> 0.3 | P38: =N38*O38 -> 0.504 | Q38: =P38*M38 -> 2.016 | R38: =R$20*P38 -> 66936.066 | S38: =R38+S$20 -> 69936.066 | T38: =M38*N38*2 -> 13.44 | W38: =M38*S38 -> 279744.26
B39: 2 | C39: CUB C/R 90° R8 MDF 25MM | D39: 1.65 | E39: 0.6 | F39: M05A | G39: PUMIC GREY 21321 TRASCARA BLANCO OPACO | H39: 140856 | I39: =H39*B39 -> 281712 | K39: LAMINA | M39: =B39 -> 2 | N39: =D39+N$19 -> 1.73 | O39: =E39+$O$19 -> 0.6 | P39: =N39*O39 -> 1.038 | Q39: =P39*M39 -> 2.076 | R39: =R$20*P39 -> 137856.42 | S39: =R39+S$20 -> 140856.42 | T39: =M39*N39*2 -> 6.92 | W39: =M39*S39 -> 281712.84
B40: 1 | C40: CUB C/R 90° R8 MDF 25MM | D40: 2.25 | E40: 0.6 | F40: M05 | G40: PUMIC GREY 21321 TRASCARA BLANCO OPACO | H40: 188668 | I40: =H40*B40 -> 188668 | K40: 8 | M40: =B40 -> 1 | N40: =D40+N$19 -> 2.33 | O40: =E40+$O$19 -> 0.6 | P40: =N40*O40 -> 1.398 | Q40: =P40*M40 -> 1.398 | R40: =R$20*P40 -> 185667.9 | S40: =R40+S$20 -> 188667.9 | T40: =M40*N40*2 -> 4.66 | W40: =M40*S40 -> 188667.9
B41: 2 | C41: CUB C/R 90° R8 MDF 25MM | D41: 2.2 | E41: 0.6 | F41: M05 | G41: PUMIC GREY 21321 TRASCARA BLANCO OPACO | H41: 184684 | I41: =H41*B41 -> 369368 | K41: 22 | M41: =B41 -> 2 | N41: =D41+N$19 -> 2.28 | O41: =E41+$O$19 -> 0.6 | P41: =N41*O41 -> 1.368 | Q41: =P41*M41 -> 2.736 | R41: =R$20*P41 -> 181683.61 | S41: =R41+S$20 -> 184683.61 | T41: =M41*N41*2 -> 9.12 | W41: =M41*S41 -> 369367.21
B42: 2 | C42: CUB C/R 90° R8 MDF 25MM | D42: 2.5 | E42: 0.6 | F42: M21 | G42: PUMIC GREY 21321 TRASCARA BLANCO OPACO | H42: 208589 | I42: =H42*B42 -> 417178 | K42: 24 | M42: =B42 -> 2 | N42: =D42+N$19 -> 2.58 | O42: =E42+$O$19 -> 0.6 | P42: =N42*O42 -> 1.548 | Q42: =P42*M42 -> 3.096 | R42: =R$20*P42 -> 205589.35 | S42: =R42+S$20 -> 208589.35 | T42: =M42*N42*2 -> 10.32 | W42: =M42*S42 -> 417178.69
B43: 1 | C43: CUB C/R 90° R8 MDF 25MM | D43: 2.55 | E43: 0.6 | F43: M21 | G43: PUMIC GREY 21321 TRASCARA BLANCO OPACO | H43: 212574 | I43: =H43*B43 -> 212574 | K43: =SUM(K40:K42) -> 54 | M43: =B43 -> 1 | N43: =D43+N$19 -> 2.63 | O43: =E43+$O$19 -> 0.6 | P43: =N43*O43 -> 1.578 | Q43: =P43*M43 -> 1.578 | R43: =R$20*P43 -> 209573.63 | S43: =R43+S$20 -> 212573.63 | T43: =M43*N43*2 -> 5.26 | W43: =M43*S43 -> 212573.63
...

Sheet COSTOS
B2: CENTRO DE COSTOS POSTFORMADOS
B5: FECHA: | C5: ='2229'!H10 -> 45757
B6: CLIENTE: | C6: ='2229'!C10 -> SISTEMA MUEBLES | N6: Ventas Equilibrio = | P6: Costos Fijos Totales
B7: DIRECCION: | C7: ='2229'!#REF! -> #REF! | H7: COSTOS INDIRECTOS DE FABRICA VARIABLES | O7: 1 - | P7: Costos Variables Totales
B8: PRESUPUESTO: | C8: ='2229'!D8 -> N° 11391 | H8: Q/HRS | I8: $ | J8: DETALLE | K8: TOTAL | L8: TOTAL | P8: Total Venta | X8: =SUM(Q11:Q16) -> 6
H9: CANTIDAD | I9: PRECIO | J9: MATERIA PRIMA INDIRECTA | L9: =SUM(K10:K23) -> 2550 | S9: DETALLE | X9: =(E15-D11)/X8 -> -927006.32
D10: NETO | E10: IVA | F10: TOTAL | H10: 3 | I10: 350 | J10: RESPALDO | K10: =I10*H10 -> 1050 | Q10: UNIDAD | R10: TIPO | S10: LARGO | T10: ANCHO | U10: COLOR | V10: VALOR | W10: TOTAL
C11: MONTO A COBRAR | D11: ='2229'!I59 -> 9577644 | E11: =D11*0.19 -> 1819752.4 | F11: =E11+D11 -> 11397396 | H11: 3 | I11: 500 | J11: MEDIA CAÑA | K11: =I11*H11 -> 1500 | Q11: 1 | R11: CUB C/R R8 | S11: 2.8 | T11: 0.62 | U11: MADERA X DEFINIR | V11: 105990 | W11: =V11*Q11 -> 105990 | X11: =V11+$X$9 -> -821016.32 | Y11: 108990
C12: COSTO TOTAL | D12: =SUM(M43:M45) -> 2433700.7 | H12: 0 | I12: 7500 | J12: DUROLAC | K12: =I12*H12 -> 0 | Q12: 1 | R12: CUB C/R R8 | S12: 2.3 | T12: 0.62 | U12: MADERA X DEFINIR | V12: 87990 | W12: =V12*Q12 -> 87990 | X12: =V12+$X$9 -> -839016.32 | Y12: 89990
C13: % UTILIDAD | D13: =D11-D12 -> 7143943.3 | E13: =(D11/D12)-1 -> 2.935424 | H13: 0 | I13: 50 | J13: TAPACANTO PVC | K13: =I13*H13 -> 0 | Q13: 1 | R13: CUB C/R R8 | S13: 2.03 | T13: 0.62 | U13: MADERA X DEFINIR | V13: 78990 | W13: =V13*Q13 -> 78990 | X13: =V13+$X$9 -> -848016.32 | Y13: 81990
D14: % utilidad | E14: NETO | F14: UTILIDAD | H14: 0 | I14: 50 | J14: SOBERBIOS | K14: =I14*H14 -> 0 | Q14: 1 | R14: CUB C/R R8 | S14: 1.08 | T14: 0.62 | U14: MADERA X DEFINIR | V14: 39990 | W14: =V14*Q14 -> 39990 | X14: =V14+$X$9 -> -887016.32 | Y14: 39990
C15: PROYECCION | D15: 0.65 | E15: =(100%+D15)*D12 -> 4015606.1 | F15: =E15-D12 -> 1581905.4 | H15: 0 | I15: 10 | J15: SOPORTE REPISA | K15: =I15*H15 -> 0 | Q15: 1 | R15: CUB C/R R8 | S15: 1.08 | T15: 0.62 | U15: MADERA X DEFINIR | V15: 39990 | W15: =V15*Q15 -> 39990 | X15: =V15+$X$9 -> -887016.32 | Y15: 39990
H16: 1 | J16: PUNTAS | K16: =I16*H16 -> 0 | Q16: 1 | R16: CUB C/R R8 | S16: 2.06 | T16: 0.62 | U16: MADERA X DEFINIR | V16: 79990 | W16: =V16*Q16 -> 79990 | X16: =V16+$X$9 -> -847016.32 | Y16: 83990
B17: M. PRIMA | C17: MATERIAL | D17: NETO | E17: IVA | F17: TOTAL | H17: 1 | J17: TORNILLOS | K17: =I17*H17 -> 0 | Q17: 6 | R17: CORTES 45° | V17: 5000 | W17: =V17*Q17 -> 30000
C18: LAMINA | D18: ='2229'!P67 -> 916596 | E18: =D18*0.19 -> 174153.24 | F18: =SUM(D18:E18) -> 1090749.2 | H18: 1 | J18: COLAFRIA | K18: =I18*H18 -> 0 | Q18: 1 | R18: PERFORACION LAVAPLATOS | V18: 10000 | W18: =V18*Q18 -> 10000
C19: MDF 18MM | D19: ='2229'!P66 -> 912808 | E19: =D19*0.19 -> 173433.52 | F19: =SUM(D19:E19) -> 1086241.5 | H19: 1 | J19: LIJAS | K19: =I19*H19 -> 0 | V19: NETO | W19: =SUM(W11:W18) -> 472940 | Y19: =SUM(Y11:Y16)+SUM(W17:W18) -> 484940
C20: ADHESIVO | D20: ='2229'!P65 -> 574462.56 | E20: =D20*0.19 -> 109147.89 | F20: =SUM(D20:E20) -> 683610.45 | H20: 1 | J20: CARTON | K20: =I20*H20 -> 0 | V20: I.V.A. | W20: =W19*19% -> 89858.6 | Y20: =Y19*0.19 -> 92138.6
A21: =450000*1.2 -> 540000 | C21: TOTAL | D21: =SUM(D18:D20) -> 2403866.6 | E21: =SUM(E18:E20) -> 456734.65 | F21: =SUM(F18:F20) -> 2860601.2 | H21: 1 | J21: GUAIPE | K21: =I21*H21 -> 0 | M21: =B32/9 -> 2318.8406 | Q21: PLAZO DE ENTREGA : 8 DIAS HABILES | V21: TOTAL | W21: =W19+W20 -> 562798.6 | Y21: =SUM(Y19:Y20) -> 577078.6
A22: =450000*1.2 -> 540000 | B22: M. DE OBRA | C22: PROCESO | D22: COSTO x Hr. | E22: Q Hrs. | F22: TOTAL | H22: 1 | J22: DILUYENTE | K22: =I22*H22 -> 0 | Q22: FORMA DE PAGO: 50% CONTADO, SALDO C/E
A23: =800000*1.2 -> 960000 | B23: =A21/23 -> 23478.261 | C23: CORTE | D23: =B23/9 -> 2608.6957 | E23: 0.5 | F23: =D23*E23 -> 1304.3478 | H23: 1 | J23: CINTA EMBALAJE | K23: =I23*H23 -> 0 | Q23: VALIDEZ COTIZACIÓN: 5 DIAS
A24: 450000 | B24: =A22/23 -> 23478.261 | C24: CORTE LAMINA | D24: =B24/9 -> 2608.6957 | E24: 0.5 | F24: =D24*E24 -> 1304.3478 | H24: Q/HRS | I24: PRECIO | J24: MANO DE OBRA INDIRECTA | K24: VALOR | L24: =SUM(K25:K35) -> 0
A25: 450000 | B25: =A23/23 -> 41739.13 | C25: REBAJE LAMINA | D25: =B25/9 -> 4637.6812 | F25: =D25*E25 -> 0 | H25: 0 | I25: =((480000/23)/9) -> 2318.8406 | J25: FLETERO (HRS) | K25: =H25*I25 -> 0
B26: =A24/23 -> 19565.217 | C26: TUPIZADO | D26: =B26/9 -> 2173.913 | E26: 0.5 | F26: =D26*E26 -> 1086.9565 | H26: 0 | J26: BENCINA | K26: =H26*I26 -> 0
A27: 350000 | B27: =A25/23 -> 19565.217 | C27: ARMADO | D27: =B27/9 -> 2173.913 | E27: 0.5 | F27: =D27*E27 -> 1086.9565 | H27: 0 | J27: TAG | K27: =H27*I27 -> 0
A28: 500000 | B28: =A27/23 -> 15217.391 | C28: PEGADO | D28: =B28/9 -> 1690.8213 | E28: 0.7 | F28: =D28*E28 -> 1183.5749 | H28: 0 | J28: RECTIFICACION | K28: =H28*I28 -> 0
B29: =A28/23 -> 21739.13 | C29: POSTFORMADO | D29: =B29/9 -> 2415.4589 | E29: 0.7 | F29: =D29*E29 -> 1690.8213 | H29: 0 | I29: =((550000*1.2)/23)/9 -> 3188.4058 | J29: HR. TRAB. JUAN | K29: =H29*I29 -> 0
A30: 450000 | C30: MEDIA CAÑA | D30: 2415 | F30: =D30*E30 -> 0 | H30: 0 | I30: =((450000*1.2)/23)/9 -> 2608.6957 | J30: HR. TRAB. JULIO | K30: =H30*I30 -> 0
A31: 350000 | B31: =A30/23 -> 19565.217 | C31: CORTE-ENCHAPE | D31: =B31/9 -> 2173.913 | E31: 0 | F31: =D31*E31 -> 0 | H31: 0 | I31: =((450000*1.2)/23)/9 -> 2608.6957 | J31: HR. TRAB. EUGE | K31: =H31*I31 -> 0
A32: =A21+A24+A27+A28+A30 -> 2290000 | B32: =480000/23 -> 20869.565 | C32: CONTROL CALIDAD | D32: =B32/9 -> 2318.8406 | E32: 0.5 | F32: =D32*E32 -> 1159.4203 | H32: 0 | J32: COLACION | K32: =H32*I32 -> 0
C33: TOTAL | D33: =SUM(D23:D32) -> 25216.932 | E33: =SUM(E23:E32) -> 3.9 | F33: =SUM(F23:F32) -> 8816.4251 | H33: 0 | J33: BONO | K33: =H33*I33 -> 0
B34: CIF | C34: M. PRIMA INDIREC. | D34: =L9 -> 2550 | H34: 1 | J34: PERFORACION | K34: =H34*I34 -> 0
C35: M. OBRA INDIRECTA | D35: =L24 -> 0 | H35: 6 | J35: CORTE 45 | K35: =H35*I35 -> 0
C36: GASTOS DE FABRICA | D36: =L36 -> 18467.666 | H36: CANTIDAD | I36: PRECIO | J36: GASTOS DE FABRICACION | K36: VALOR | L36: =SUM(K37:K39) -> 18467.666
C37: DEPRECIACIONES | H37: =$E$33 -> 3.9 | I37: =32609.69/9 -> 3623.2989 | J37: ARRIENDO x HORA | K37: =I37*H37 -> 14130.866
C38: TOTAL | D38: =SUM(D34:D37) -> 21017.666 | H38: =$E$33 -> 3.9 | I38: 967 | J38: AGUA x HORA | K38: =I38*H38 -> 3771.3
H39: =$E$33 -> 3.9 | I39: 145 | J39: LUZ x HORA | K39: =I39*H39 -> 565.5
B40: PROVISIONAR | C40: IVA | D40: =E11-E21 -> 1363017.7
H41: ESTADO DE RESULTADOS
B42: TOTAL HRS TRABAJADAS | D42: =E33 -> 3.9 | H42: INGRESOS | I42: + TOTAL VENTA | M42: =D11 -> 9577644
H43: COSTOS | I43: - MATERIA PRIMA DIRECTA | M43: =D21 -> 2403866.6
...
