Workbook

Sheet CUBIERTA
F2: MUEBLES SANTA FE SPA
F3: VENTAS POR MENOR DE MUEBLES
F4: RUT: 77.054.606-0
F5: SEPTIMA AVENIDA 1631, SAN MIGUEL
F6: FONO +569 2032 3382 | O6: 10077 SF PORTLAND MAPLE
F7: E-MAIL: ventas@topmobili.cl
B8: P R E S U P U E S T O | D8: N° 11181
B10: NOMBRE: | C10: FRANCISCO MORENO | F10: FECHA: | G10: 45622
B11: RUT: | F11: PLAZO ENTREGA: | G11: 10 DIAS HABILES | R11: MT2 PUERTAS
B12: GIRO: | F12: SERVICIO EXPRESS | G12: NO
B13: CONTACTO:
B14: CORREO: | F14: CORTADA A LA MEDIDA | G14: SI | R14: ML CUBIERTAS
B15: FONO: | C15: +569 9004 4098 | F15: DESPACHO: | G15: NO
B16: DIRECCION: | F16: FORMA DE PAGO: | G16: ABONO 50% SALDO C/ENTREGA
B17: CIUDAD: | C17: SANTIAGO | F17: DURACION COTIZACION: 5 DIAS FRANCO DONOSO
B19: DETALLE | M19: 0.08 | P19: TOTAL | Q19: VALOR X MT2 | R19: ENCHAPE | S19: MT/L
B20: UNIDAD | C20: TIPO | D20: LARGO | E20: ANCHO | F20: COLOR | G20: VALOR | H20: TOTAL | L20: =B20 -> UNIDAD | M20: ALTO | N20: =E20 -> ANCHO | O20: MT | P20: MT2 | Q20: =O38 -> 84742.959 | R20: 2000 | T20: m/l
B21: 1 | C21: CUB C/R FRENTE 90° | D21: 3.3 | E21: 0.6 | F21: BLACKS SF | G21: 190000 | H21: =G21*B21 -> 190000 | L21: 1 | M21: =D21+M$19 -> 3.38 | N21: =E21+$N$19 -> 0.6 | O21: =M21*N21 -> 2.028 | P21: =O21*L21 -> 2.028 | Q21: =Q$20*O21 -> 171858.72 | R21: =Q21+R$20 -> 173858.72 | S21: =L21*M21*2 -> 6.76 | T21: =N21*2*L21*2 -> 2.4
G24: NETO | H24: =SUM(H21:H23) -> 190000 | K24: 2600000 | T24: =SUM(T21:T23) -> 2.4
G25: IVA | M25: =SUM(M21:M24) -> 3.38 | P25: =SUM(P21:P21) -> 2.028
G26: TOTAL | H26: =H24+H25 -> 190000 | P26: =P25 -> 2.028 | S26: =SUM(S21:S25) -> 6.76
P27: =P26*20% -> 0.4056 | Q27: 20% PERDIDA | S27: =S26+T24 -> 9.16
P28: =P26+P27 -> 2.4336 | S28: =S27*20% -> 1.832
S29: =S27+S28 -> 10.992 | U29: ADHESIVO | V29: 58.000.- | W29: 44971
M30: =P28 -> 2.4336 | N30: 3500 | O30: =M30*N30 -> 8517.6 | P30: ADHESIVO | U30: LATA 16 LTS | V30: 3625 | W30: LITRO
M31: 0.7 | N31: 25000 | O31: =M31*N31 -> 17500 | P31: MDF 18MM | V31: 906.25 | W31: MT2 (4)
B32: CUENTA CORRIENTE BANCO SANTANDER Nº 87316181 A NOMBRE DE MUEBLES SANTA FE SPA | M32: 1 | N32: 47000 | O32: =M32*N32 -> 47000 | P32: LAMINA 153 X 366 | V32: =V31*20% -> 181.25 | W32: PERDIDA 20%
B33: RUT : 77.054.606-0 VENTAS@TOPMOBILI.CL | N33: 63950 | O33: =M33*N33 -> 0 | P33: LAMINA 122X244 | V33: =V31+V32 -> 1087.5 | W33: MINIMO A COTIZAR
B34: VISITANOS Y DESCUBRE NUESTROS PRODUCTOS EN | F34: WWW.TOPMOBILICHILE.CL | N34: 900 | O34: =M34*N34 -> 0 | P34: RESPALDO | R34: 1.52
M35: 3.4 | N35: 1500 | O35: =M35*N35 -> 5100 | P35: MEDIA CAÑA | R35: 2.44
O36: =SUM(O30:O35) -> 78117.6 | P36: COSTO | R36: =R34*R35 -> 3.7088
M37: PRECIO VENTA | O37: =O36*2.2 -> 171858.72 | P37: FACTOR 2,3 PARA 90° | R37: =P28/R36 -> 0.65616911
K38: 76090 | O38: =O37/P26 -> 84742.959 | P38: VALOR M2 | U38: MDF30MM | V38: 43650
K39: =K38/1.19 -> 63941.176 | O39: =O37/O36 -> 2.2 | U39: 46 UNIDADES | V39: 948.91 | W39: 2.4
U40: METRO LINEAL | V40: 395.37
U41: PERDIDA 20% | V41: 474.45
O48: 40935 | P48: MT2 | Q48: TERMO WOOD
C73: ,,,,,,,,,,,,,,,,,,,,,,,,,,,,,,,,,,,,,,,,,,,,,,,,,,,,,,,,,,,,,,,,,,,,,,,,,,,,,,,,,,,,,,,,,,,,,,,,,,,,,,,,,,,,,,,,,,,,,,,,,,,,,,,,,,,,,,,,,,,,,,,,,,,,,,,,,,,,,,,,,,,,,,,,,,,,,,,,,,,,,,,,,,,,,,,,,,,,,,,,,,,,,,,,,,,,,,,,,,,,,,,,,,,,,,,,,,,,,,,,,,,,,,,,,,,,,,,,,,,,,
C74: ,
C77: ,
...

Sheet 2229
F2: MUEBLES SANTA FE SPA
F3: VENTAS POR MENOR DE MUEBLES
F4: RUT: 77.054.606-0
F5: SEPTIMA AVENIDA 1631, SAN MIGUEL
F6: FONO +569 2032 3382 | O6: 10077 SF PORTLAND MAPLE
F7: E-MAIL: ventas@topmobili.cl
B8: P R E S U P U E S T O | D8: N° 11181
B10: NOMBRE: | C10: FRANCISCO MORENO | F10: FECHA: | G10: 45622
B11: RUT: | F11: PLAZO ENTREGA: | G11: 10 DIAS HABILES | R11: MT2 PUERTAS
B12: GIRO: | F12: SERVICIO EXPRESS | G12: NO
B13: CONTACTO:
B14: CORREO: | F14: CORTADA A LA MEDIDA | G14: SI | R14: ML CUBIERTAS
B15: FONO: | C15: +569 9004 4098 | F15: DESPACHO: | G15: NO
B16: DIRECCION: | F16: FORMA DE PAGO: | G16: ABONO 50% SALDO C/ENTREGA
B17: CIUDAD: | C17: SANTIAGO | F17: DURACION COTIZACION: 5 DIAS FRANCO DONOSO
B19: DETALLE | M19: 0.08 | P19: TOTAL | Q19: VALOR X MT2 | R19: ENCHAPE | S19: MT/L
B20: UNIDAD | C20: TIPO | D20: LARGO | E20: ANCHO | F20: COLOR | G20: VALOR | H20: TOTAL | L20: =B20 -> UNIDAD | M20: ALTO | N20: =E20 -> ANCHO | O20: MT | P20: MT2 | Q20: =O47 -> 106777.3 | R20: 2000 | T20: m/l
B21: 2 | C21: PR6 | D21: 0.6 | E21: 0.348 | F21: BLACKS SF | G21: 17726 | H21: =G21*B21 -> 35452 | M21: =D21+M$19 -> 0.68 | N21: =E21+$N$19 -> 0.348 | O21: =M21*N21 -> 0.23664 | P21: =O21*L21 -> 0 | Q21: =Q$20*O21 -> 25267.78 | R21: =Q21+R$20 -> 27267.78 | S21: =L21*M21*2 -> 0 | T21: =N21*2*L21*2 -> 0
B22: 6 | C22: PR6 | D22: 0.9 | E22: 0.298 | F22: BLACKS SF | G22: 21408 | H22: =G22*B22 -> 128448 | M22: =D22+M$19 -> 0.98 | N22: =E22+$N$19 -> 0.298 | O22: =M22*N22 -> 0.29204 | P22: =O22*L22 -> 0 | Q22: =Q$20*O22 -> 31183.242 | R22: =Q22+R$20 -> 33183.242 | S22: =L22*M22*2 -> 0
B23: 2 | C23: PR6 | D23: 0.9 | E23: 0.398 | F23: BLACKS SF | G23: 27920 | H23: =G23*B23 -> 55840 | M23: =D23+M$19 -> 0.98 | N23: =E23+$N$19 -> 0.398 | O23: =M23*N23 -> 0.39004 | P23: =O23*L23 -> 0 | Q23: =Q$20*O23 -> 41647.417 | R23: =Q23+R$20 -> 43647.417 | S23: =L23*M23*2 -> 0
B24: 2 | C24: PR6 | D24: 0.9 | E24: 0.198 | F24: BLACKS SF | G24: 14895 | H24: =G24*B24 -> 29790 | M24: =D24+M$19 -> 0.98 | N24: =E24+$N$19 -> 0.198 | O24: =M24*N24 -> 0.19404 | P24: =O24*L24 -> 0 | Q24: =Q$20*O24 -> 20719.067 | R24: =Q24+R$20 -> 22719.067 | S24: =L24*M24*2 -> 0
B25: 2 | C25: PR6 | D25: 2.4 | E25: 0.498 | F25: BLACKS SF | G25: 84076 | H25: =G25*B25 -> 168152 | M25: =D25+M$19 -> 2.48 | N25: =E25+$N$19 -> 0.498 | O25: =M25*N25 -> 1.23504 | P25: =O25*L25 -> 0 | Q25: =Q$20*O25 -> 131874.23 | R25: =Q25+R$20 -> 133874.23 | S25: =L25*M25*2 -> 0
B26: 1 | C26: PR6 | D26: 2.4 | E26: 0.6 | F26: BLACKS SF | G26: 49511 | H26: =G26*B26 -> 49511 | M26: =D26+M$19 -> 2.48 | N26: =E26+$N$19 -> 0.6 | O26: =M26*N26 -> 1.488 | P26: =O26*L26 -> 0 | Q26: =Q$20*O26 -> 158884.62 | R26: =Q26+R$20 -> 160884.62 | S26: =L26*M26*2 -> 0 | U26: 49511
B27: 2 | C27: PR6 | D27: 0.7 | E27: 0.6 | F27: BLACKS SF | G27: 16944 | H27: =G27*B27 -> 33888 | M27: =D27+M$19 -> 0.78 | N27: =E27+$N$19 -> 0.6 | O27: =M27*N27 -> 0.468 | P27: =O27*L27 -> 0 | Q27: =Q$20*O27 -> 49971.776 | R27: =Q27+R$20 -> 51971.776 | S27: =L27*M27*2 -> 0 | U27: 16943 | V27: =U27/2 -> 8471.5
B28: 2 | C28: PR2 | D28: 0.398 | E28: 0.77 | F28: ROYAL WALNUT 1536 UP | G28: 41300 | H28: =G28*B28 -> 82600 | L28: =B28 -> 2 | M28: =D28+M$19 -> 0.478 | N28: =E28+$N$19 -> 0.77 | O28: =M28*N28 -> 0.36806 | P28: =O28*L28 -> 0.73612 | Q28: =Q$20*O28 -> 39300.452 | R28: =Q28+R$20 -> 41300.452 | S28: =L28*M28*2 -> 1.912 | U28: =SUM(U26:U27) -> 66454
B29: 2 | C29: PR2 | D29: 0.6 | E29: 0.77 | F29: ROYAL WALNUT 1536 UP | G29: 57909 | H29: =G29*B29 -> 115818 | L29: =B29 -> 2 | M29: =D29+M$19 -> 0.68 | N29: =E29+$N$19 -> 0.77 | O29: =M29*N29 -> 0.5236 | P29: =O29*L29 -> 1.0472 | Q29: =Q$20*O29 -> 55908.593 | R29: =Q29+R$20 -> 57908.593 | S29: =L29*M29*2 -> 2.72
B30: 1 | C30: PR2 | D30: 0.4 | E30: 0.77 | F30: ROYAL WALNUT 1536 UP | G30: 41465 | H30: =G30*B30 -> 41465 | L30: =B30 -> 1 | M30: =D30+M$19 -> 0.48 | N30: =E30+$N$19 -> 0.77 | O30: =M30*N30 -> 0.3696 | P30: =O30*L30 -> 0.3696 | Q30: =Q$20*O30 -> 39464.889 | R30: =Q30+R$20 -> 41464.889 | S30: =L30*M30*2 -> 0.96
G33: NETO | H33: =SUM(H21:H32) -> 740964 | K33: 2600000 | T33: =SUM(T21:T32) -> 0
G34: IVA | M34: =SUM(M21:M33) -> 10.998 | P34: =SUM(P21:P30) -> 2.15292
G35: TOTAL | H35: =H33+H34 -> 740964 | P35: =P34 -> 2.15292 | S35: =SUM(S21:S34) -> 5.592
P36: =P35*20% -> 0.430584 | Q36: 20% PERDIDA | S36: =S35+T33 -> 5.592
P37: =P35+P36 -> 2.583504 | S37: =S36*20% -> 1.1184
S38: =S36+S37 -> 6.7104 | U38: ADHESIVO | V38: 58.000.- | W38: 44971
M39: =P37 -> 2.583504 | N39: 3500 | O39: =M39*N39 -> 9042.264 | P39: ADHESIVO | U39: LATA 16 LTS | V39: 3625 | W39: LITRO
M40: 0.7 | N40: 45000 | O40: =M40*N40 -> 31500 | P40: MDF 18MM | V40: 906.25 | W40: MT2 (4)
B41: CUENTA CORRIENTE BANCO SANTANDER Nº 87316181 A NOMBRE DE MUEBLES SANTA FE SPA | N41: 71000 | O41: =M41*N41 -> 0 | P41: LAMINA 153 X 366 | V41: =V40*20% -> 181.25 | W41: PERDIDA 20%
B42: RUT : 77.054.606-0 VENTAS@TOPMOBILI.CL | M42: 1 | N42: 63950 | O42: =M42*N42 -> 63950 | P42: LAMINA 122X244 | V42: =V40+V41 -> 1087.5 | W42: MINIMO A COTIZAR
B43: VISITANOS Y DESCUBRE NUESTROS PRODUCTOS EN | F43: WWW.TOPMOBILICHILE.CL | N43: 900 | O43: =M43*N43 -> 0 | P43: RESPALDO | R43: 1.52
N44: 1500 | O44: =M44*N44 -> 0 | P44: MEDIA CAÑA | R44: 2.44
O45: =SUM(O39:O44) -> 104492.26 | P45: COSTO | R45: =R43*R44 -> 3.7088
...

Sheet COSTOS
B2: CENTRO DE COSTOS POSTFORMADOS
B5: FECHA: | C5: ='2229'!G10 -> 45622
B6: CLIENTE: | C6: ='2229'!C10 -> FRANCISCO MORENO | N6: Ventas Equilibrio = | P6: Costos Fijos Totales
B7: DIRECCION: | C7: ='2229'!#REF! -> #REF! | H7: COSTOS INDIRECTOS DE FABRICA VARIABLES | O7: 1 - | P7: Costos Variables Totales
B8: PRESUPUESTO: | C8: ='2229'!D8 -> N° 11181 | H8: Q/HRS | I8: $ | J8: DETALLE | K8: TOTAL | L8: TOTAL | P8: Total Venta | X8: =SUM(Q11:Q16) -> 6
H9: CANTIDAD | I9: PRECIO | J9: MATERIA PRIMA INDIRECTA | L9: =SUM(K10:K23) -> 2550 | S9: DETALLE | X9: =(E15-D11)/X8 -> -104140.5
D10: NETO | E10: IVA | F10: TOTAL | H10: 3 | I10: 350 | J10: RESPALDO | K10: =I10*H10 -> 1050 | Q10: UNIDAD | R10: TIPO | S10: LARGO | T10: ANCHO | U10: COLOR | V10: VALOR | W10: TOTAL
C11: MONTO A COBRAR | D11: ='2229'!H33 -> 740964 | E11: =D11*0.19 -> 140783.16 | F11: =E11+D11 -> 881747.16 | H11: 3 | I11: 500 | J11: MEDIA CAÑA | K11: =I11*H11 -> 1500 | Q11: 1 | R11: CUB C/R R8 | S11: 2.8 | T11: 0.62 | U11: MADERA X DEFINIR | V11: 105990 | W11: =V11*Q11 -> 105990 | X11: =V11+$X$9 -> 1849.4976 | Y11: 108990
C12: COSTO TOTAL | D12: =SUM(M43:M45) -> 70376.355 | H12: 0 | I12: 7500 | J12: DUROLAC | K12: =I12*H12 -> 0 | Q12: 1 | R12: CUB C/R R8 | S12: 2.3 | T12: 0.62 | U12: MADERA X DEFINIR | V12: 87990 | W12: =V12*Q12 -> 87990 | X12: =V12+$X$9 -> -16150.502 | Y12: 89990
C13: % UTILIDAD | D13: =D11-D12 -> 670587.65 | E13: =(D11/D12)-1 -> 9.5285931 | H13: 0 | I13: 50 | J13: TAPACANTO PVC | K13: =I13*H13 -> 0 | Q13: 1 | R13: CUB C/R R8 | S13: 2.03 | T13: 0.62 | U13: MADERA X DEFINIR | V13: 78990 | W13: =V13*Q13 -> 78990 | X13: =V13+$X$9 -> -25150.502 | Y13: 81990
D14: % utilidad | E14: NETO | F14: UTILIDAD | H14: 0 | I14: 50 | J14: SOBERBIOS | K14: =I14*H14 -> 0 | Q14: 1 | R14: CUB C/R R8 | S14: 1.08 | T14: 0.62 | U14: MADERA X DEFINIR | V14: 39990 | W14: =V14*Q14 -> 39990 | X14: =V14+$X$9 -> -64150.502 | Y14: 39990
C15: PROYECCION | D15: 0.65 | E15: =(100%+D15)*D12 -> 116120.99 | F15: =E15-D12 -> 45744.631 | H15: 0 | I15: 10 | J15: SOPORTE REPISA | K15: =I15*H15 -> 0 | Q15: 1 | R15: CUB C/R R8 | S15: 1.08 | T15: 0.62 | U15: MADERA X DEFINIR | V15: 39990 | W15: =V15*Q15 -> 39990 | X15: =V15+$X$9 -> -64150.502 | Y15: 39990
H16: 1 | J16: PUNTAS | K16: =I16*H16 -> 0 | Q16: 1 | R16: CUB C/R R8 | S16: 2.06 | T16: 0.62 | U16: MADERA X DEFINIR | V16: 79990 | W16: =V16*Q16 -> 79990 | X16: =V16+$X$9 -> -24150.502 | Y16: 83990
B17: M. PRIMA | C17: MATERIAL | D17: NETO | E17: IVA | F17: TOTAL | H17: 1 | J17: TORNILLOS | K17: =I17*H17 -> 0 | Q17: 6 | R17: CORTES 45° | V17: 5000 | W17: =V17*Q17 -> 30000
C18: LAMINA | D18: ='2229'!O41 -> 0 | E18: =D18*0.19 -> 0 | F18: =SUM(D18:E18) -> 0 | H18: 1 | J18: COLAFRIA | K18: =I18*H18 -> 0 | Q18: 1 | R18: PERFORACION LAVAPLATOS | V18: 10000 | W18: =V18*Q18 -> 10000
C19: MDF 18MM | D19: ='2229'!O40 -> 31500 | E19: =D19*0.19 -> 5985 | F19: =SUM(D19:E19) -> 37485 | H19: 1 | J19: LIJAS | K19: =I19*H19 -> 0 | V19: NETO | W19: =SUM(W11:W18) -> 472940 | Y19: =SUM(Y11:Y16)+SUM(W17:W18) -> 484940
C20: ADHESIVO | D20: ='2229'!O39 -> 9042.264 | E20: =D20*0.19 -> 1718.0302 | F20: =SUM(D20:E20) -> 10760.294 | H20: 1 | J20: CARTON | K20: =I20*H20 -> 0 | V20: I.V.A. | W20: =W19*19% -> 89858.6 | Y20: =Y19*0.19 -> 92138.6
A21: =450000*1.2 -> 540000 | C21: TOTAL | D21: =SUM(D18:D20) -> 40542.264 | E21: =SUM(E18:E20) -> 7703.0302 | F21: =SUM(F18:F20) -> 48245.294 | H21: 1 | J21: GUAIPE | K21: =I21*H21 -> 0 | M21: =B32/9 -> 2318.8406 | Q21: PLAZO DE ENTREGA : 8 DIAS HABILES | V21: TOTAL | W21: =W19+W20 -> 562798.6 | Y21: =SUM(Y19:Y20) -> 577078.6
A22: =450000*1.2 -> 540000 | B22: M. DE OBRA | C22: PROCESO | D22: COSTO x Hr. | E22: Q Hrs. | F22: TOTAL | H22: 1 | J22: DILUYENTE | K22: =I22*H22 -> 0 | Q22: FORMA DE PAGO: 50% CONTADO, SALDO C/E
A23: =800000*1.2 -> 960000 | B23: =A21/23 -> 23478.261 | C23: CORTE | D23: =B23/9 -> 2608.6957 | E23: 0.5 | F23: =D23*E23 -> 1304.3478 | H23: 1 | J23: CINTA EMBALAJE | K23: =I23*H23 -> 0 | Q23: VALIDEZ COTIZACIÓN: 5 DIAS
A24: 450000 | B24: =A22/23 -> 23478.261 | C24: CORTE LAMINA | D24: =B24/9 -> 2608.6957 | E24: 0.5 | F24: =D24*E24 -> 1304.3478 | H24: Q/HRS | I24: PRECIO | J24: MANO DE OBRA INDIRECTA | K24: VALOR | L24: =SUM(K25:K35) -> 0
A25: 450000 | B25: =A23/23 -> 41739.13 | C25: REBAJE LAMINA | D25: =B25/9 -> 4637.6812 | F25: =D25*E25 -> 0 | H25: 0 | I25: =((480000/23)/9) -> 2318.8406 | J25: FLETERO (HRS) | K25: =H25*I25 -> 0
B26: =A24/23 -> 19565.217 | C26: TUPIZADO | D26: =B26/9 -> 2173.913 | E26: 0.5 | F26: =D26*E26 -> 1086.9565 | H26: 0 | J26: BENCINA | K26: =H26*I26 -> 0
A27: 350000 | B27: =A25/23 -> 19565.217 | C27: ARMADO | D27: =B27/9 -> 2173.913 | E27: 0.5 | F27: =D27*E27 -> 1086.9565 | H27: 0 | J27: TAG | K27: =H27*I27 -> 0
A28: 500000 | B28: =A27/23 -> 15217.391 | C28: PEGADO | D28: =B28/9 -> 1690.8213 | E28: 0.7 | F28: =D28*E28 -> 1183.5749 | H28: 0 | J28: RECTIFICACION | K28: =H28*I28 -> 0
B29: =A28/23 -> 21739.13 | C29: POSTFORMADO | D29: =B29/9 -> 2415.4589 | E29: 0.7 | F29: =D29*E29 -> 1690.8213 | H29: 0 | I29: =((550000*1.2)/23)/9 -> 3188.4058 | J29: HR. TRAB. JUAN | K29: =H29*I29 -> 0
A30: 450000 | C30: MEDIA CAÑA | D30: 2415 | F30: =D30*E30 -> 0 | H30: 0 | I30: =((450000*1.2)/23)/9 -> 2608.6957 | J30: HR. TRAB. JULIO | K30: =H30*I30 -> 0
A31: 350000 | B31: =A30/23 -> 19565.217 | C31: CORTE-ENCHAPE | D31: =B31/9 -> 2173.913 | E31: 0 | F31: =D31*E31 -> 0 | H31: 0 | I31: =((450000*1.2)/23)/9 -> 2608.6957 | J31: HR. TRAB. EUGE | K31: =H31*I31 -> 0
A32: =A21+A24+A27+A28+A30 -> 2290000 | B32: =480000/23 -> 20869.565 | C32: CONTROL CALIDAD | D32: =B32/9 -> 2318.8406 | E32: 0.5 | F32: =D32*E32 -> 1159.4203 | H32: 0 | J32: COLACION | K32: =H32*I32 -> 0
C33: TOTAL | D33: =SUM(D23:D32) -> 25216.932 | E33: =SUM(E23:E32) -> 3.9 | F33: =SUM(F23:F32) -> 8816.4251 | H33: 0 | J33: BONO | K33: =H33*I33 -> 0
B34: CIF | C34: M. PRIMA INDIREC. | D34: =L9 -> 2550 | H34: 1 | J34: PERFORACION | K34: =H34*I34 -> 0
C35: M. OBRA INDIRECTA | D35: =L24 -> 0 | H35: 6 | J35: CORTE 45 | K35: =H35*I35 -> 0
C36: GASTOS DE FABRICA | D36: =L36 -> 18467.666 | H36: CANTIDAD | I36: PRECIO | J36: GASTOS DE FABRICACION | K36: VALOR | L36: =SUM(K37:K39) -> 18467.666
C37: DEPRECIACIONES | H37: =$E$33 -> 3.9 | I37: =32609.69/9 -> 3623.2989 | J37: ARRIENDO x HORA | K37: =I37*H37 -> 14130.866
C38: TOTAL | D38: =SUM(D34:D37) -> 21017.666 | H38: =$E$33 -> 3.9 | I38: 967 | J38: AGUA x HORA | K38: =I38*H38 -> 3771.3
H39: =$E$33 -> 3.9 | I39: 145 | J39: LUZ x HORA | K39: =I39*H39 -> 565.5
B40: PROVISIONAR | C40: IVA | D40: =E11-E21 -> 133080.13
H41: ESTADO DE RESULTADOS
B42: TOTAL HRS TRABAJADAS | D42: =E33 -> 3.9 | H42: INGRESOS | I42: + TOTAL VENTA | M42: =D11 -> 740964
H43: COSTOS | I43: - MATERIA PRIMA DIRECTA | M43: =D21 -> 40542.264
...
