Workbook

Sheet 2229
G2: MUEBLES SANTA FE SPA
G3: VENTAS POR MENOR DE MUEBLES
G4: RUT: 77.054.606-0
G5: SEPTIMA AVENIDA 1631, SAN MIGUEL
G6: FONO 22521 6502 | O6: 10077 SF PORTLAND MAPLE
G7: E-MAIL: ventas@topmobili.cl
B8: P R E S U P U E S T O | D8: N° 11213
B10: CLIENTE: | C10: IMPORTADORA Y EXPORTADORA CLEVER LTDA | G10: FECHA: | H10: 45642
B11: RUT: | C11: 77.327.630-7 | G11: PLAZO ENTREGA: | H11: 15 DIAS HABILES | R11: MT2 PUERTAS
B12: CONTACTO | C12: DOUGLAS GUAJARDO | G12: OBRA:
B13: CORREO: | G13: CORTADA A LA MEDIDA | H13: SI | R13: ML CUBIERTAS
B14: FONO: | C14: + 569 4207 3701 | G14: PEDIDO:
B15: DIRECCION: | G15: FORMA DE PAGO: | H15: CONTADO
B16: CIUDAD: | C16: RANCAGUA | G16: DURACION COTIZACION: 5 DIAS
B18: D E T A L L E | M18: 0.05 | P18: TOTAL | Q18: VALOR X MT2 | R18: ENCHAPE | S18: MT/L
B19: UNIDAD | C19: TIPO | D19: LARGO | E19: ANCHO | F19: ENCHAPE | G19: COLOR | H19: VALOR | I19: TOTAL | L19: =B19 -> UNIDAD | M19: ALTO | N19: =E19 -> ANCHO | O19: MT | P19: MT2 | Q19: =O36 -> 41370.201 | R19: 5000 | T19: m/l
B20: 70 | C20: CUB C/R R8 | D20: 3 | E20: 0.5 | F20: X DEFINIR | G20: SLATE 22099 SF | H20: 67273 | I20: =H20*B20 -> 4709110 | K20: LAMINAS | L20: =B20 -> 70 | M20: =D20+M$18 -> 3.05 | N20: =E20 -> 0.5 | O20: =M20*N20 -> 1.525 | P20: =O20*L20 -> 106.75 | Q20: =Q$19*O20 -> 63089.557 | R20: =Q20+R$19 -> 68089.557 | S20: =L20*M20 -> 213.5 | T20: =M20*L20 -> 213.5
B21: =SUM(B20:B20) -> 70
H23: NETO | I23: =SUM(I20:I22) -> 4709110 | P23: =SUM(P20:P20) -> 106.75 | S23: =SUM(S20:S22) -> 213.5 | T23: =SUM(T20:T22) -> 213.5
H24: I.V.A. | I24: =I23*19% -> 894730.9 | M24: =SUM(M20:M23) -> 3.05 | P24: =P23 -> 106.75
H25: TOTAL | I25: =I23+I24 -> 5603840.9 | P25: =P24*20% -> 21.35 | Q25: 20% PERDIDA | S25: =S23+S24 -> 213.5
P26: =P24+P25 -> 128.1 | S26: 40
M28: =P26*1 -> 128.1 | N28: 2500 | O28: =M28*N28 -> 320250 | P28: ADHESIVO | Q28: TRASCARA ENCHAPADA, ES POR 2
M29: 70 | N29: 9000 | O29: =M29*N29 -> 630000 | P29: MDF 18MM
N30: 43689 | O30: =M30*N30 -> 0 | P30: LAMINA 153 X 366
B31: CUENTA VISTA DEL BANCO ESTADO N° 355-7138907-8 A NOMBRE DE MUEBLES SANTA FE SPA | M31: 35 | N31: 27147 | O31: =M31*N31 -> 950145 | P31: LAMINA 122X244
B32: RUT : 77.054.606-0 VENTAS@TOPMOBILI.CL | N32: 600 | O32: =M32*N32 -> 0 | P32: RESPALDO | R32: 1.22
B33: VISITANOS Y DESCUBRE NUESTROS PRODUCTOS EN | G33: WWW.TOPMOBILICHILE.CL | K33: 49480 | M33: 214 | N33: 500 | O33: =M33*N33 -> 107000 | P33: MEDIA CAÑA | R33: 2.44
K34: =K33/1.19 -> 41579.832 | O34: =SUM(O28:O33) -> 2007395 | P34: COSTO | R34: =R32*R33 -> 2.9768
M35: PRECIO VENTA | O35: =O34*2.2 -> 4416269 | P35: FACTOR 2,3 PARA 90° | R35: =P26/R34 -> 43.032787
O36: =O35/P24 -> 41370.201 | P36: VALOR M2
O37: =O35/O34 -> 2.2

Sheet COSTOS
B2: CENTRO DE COSTOS POSTFORMADOS
B5: FECHA: | C5: ='2229'!H10 -> 45642
B6: CLIENTE: | C6: ='2229'!C10 -> IMPORTADORA Y EXPORTADORA CLEVER LTDA | N6: Ventas Equilibrio = | P6: Costos Fijos Totales
B7: DIRECCION: | C7: ='2229'!#REF! -> #REF! | H7: COSTOS INDIRECTOS DE FABRICA VARIABLES | O7: 1 - | P7: Costos Variables Totales
B8: PRESUPUESTO: | C8: ='2229'!D8 -> N° 11213 | H8: Q/HRS | I8: $ | J8: DETALLE | K8: TOTAL | L8: TOTAL | P8: Total Venta | X8: =SUM(Q11:Q16) -> 6
H9: CANTIDAD | I9: PRECIO | J9: MATERIA PRIMA INDIRECTA | L9: =SUM(K10:K23) -> 2550 | S9: DETALLE | X9: =(E15-D11)/X8 -> -515328.54
D10: NETO | E10: IVA | F10: TOTAL | H10: 3 | I10: 350 | J10: RESPALDO | K10: =I10*H10 -> 1050 | Q10: UNIDAD | R10: TIPO | S10: LARGO | T10: ANCHO | U10: COLOR | V10: VALOR | W10: TOTAL
C11: MONTO A COBRAR | D11: ='2229'!I23 -> 4709110 | E11: =D11*0.19 -> 894730.9 | F11: =E11+D11 -> 5603840.9 | H11: 3 | I11: 500 | J11: MEDIA CAÑA | K11: =I11*H11 -> 1500 | Q11: 1 | R11: CUB C/R R8 | S11: 2.8 | T11: 0.62 | U11: MADERA X DEFINIR | V11: 105990 | W11: =V11*Q11 -> 105990 | X11: =V11+$X$9 -> -409338.54 | Y11: 108990
C12: COSTO TOTAL | D12: =SUM(M43:M45) -> 980084.09 | H12: 0 | I12: 7500 | J12: DUROLAC | K12: =I12*H12 -> 0 | Q12: 1 | R12: CUB C/R R8 | S12: 2.3 | T12: 0.62 | U12: MADERA X DEFINIR | V12: 87990 | W12: =V12*Q12 -> 87990 | X12: =V12+$X$9 -> -427338.54 | Y12: 89990
C13: % UTILIDAD | D13: =D11-D12 -> 3729025.9 | E13: =(D11/D12)-1 -> 3.804802 | H13: 0 | I13: 50 | J13: TAPACANTO PVC | K13: =I13*H13 -> 0 | Q13: 1 | R13: CUB C/R R8 | S13: 2.03 | T13: 0.62 | U13: MADERA X DEFINIR | V13: 78990 | W13: =V13*Q13 -> 78990 | X13: =V13+$X$9 -> -436338.54 | Y13: 81990
D14: % utilidad | E14: NETO | F14: UTILIDAD | H14: 0 | I14: 50 | J14: SOBERBIOS | K14: =I14*H14 -> 0 | Q14: 1 | R14: CUB C/R R8 | S14: 1.08 | T14: 0.62 | U14: MADERA X DEFINIR | V14: 39990 | W14: =V14*Q14 -> 39990 | X14: =V14+$X$9 -> -475338.54 | Y14: 39990
C15: PROYECCION | D15: 0.65 | E15: =(100%+D15)*D12 -> 1617138.7 | F15: =E15-D12 -> 637054.66 | H15: 0 | I15: 10 | J15: SOPORTE REPISA | K15: =I15*H15 -> 0 | Q15: 1 | R15: CUB C/R R8 | S15: 1.08 | T15: 0.62 | U15: MADERA X DEFINIR | V15: 39990 | W15: =V15*Q15 -> 39990 | X15: =V15+$X$9 -> -475338.54 | Y15: 39990
H16: 1 | J16: PUNTAS | K16: =I16*H16 -> 0 | Q16: 1 | R16: CUB C/R R8 | S16: 2.06 | T16: 0.62 | U16: MADERA X DEFINIR | V16: 79990 | W16: =V16*Q16 -> 79990 | X16: =V16+$X$9 -> -435338.54 | Y16: 83990
B17: M. PRIMA | C17: MATERIAL | D17: NETO | E17: IVA | F17: TOTAL | H17: 1 | J17: TORNILLOS | K17: =I17*H17 -> 0 | Q17: 6 | R17: CORTES 45° | V17: 5000 | W17: =V17*Q17 -> 30000
C18: LAMINA | D18: ='2229'!O30 -> 0 | E18: =D18*0.19 -> 0 | F18: =SUM(D18:E18) -> 0 | H18: 1 | J18: COLAFRIA | K18: =I18*H18 -> 0 | Q18: 1 | R18: PERFORACION LAVAPLATOS | V18: 10000 | W18: =V18*Q18 -> 10000
C19: MDF 18MM | D19: ='2229'!O29 -> 630000 | E19: =D19*0.19 -> 119700 | F19: =SUM(D19:E19) -> 749700 | H19: 1 | J19: LIJAS | K19: =I19*H19 -> 0 | V19: NETO | W19: =SUM(W11:W18) -> 472940 | Y19: =SUM(Y11:Y16)+SUM(W17:W18) -> 484940
C20: ADHESIVO | D20: ='2229'!O28 -> 320250 | E20: =D20*0.19 -> 60847.5 | F20: =SUM(D20:E20) -> 381097.5 | H20: 1 | J20: CARTON | K20: =I20*H20 -> 0 | V20: I.V.A. | W20: =W19*19% -> 89858.6 | Y20: =Y19*0.19 -> 92138.6
A21: =450000*1.2 -> 540000 | C21: TOTAL | D21: =SUM(D18:D20) -> 950250 | E21: =SUM(E18:E20) -> 180547.5 | F21: =SUM(F18:F20) -> 1130797.5 | H21: 1 | J21: GUAIPE | K21: =I21*H21 -> 0 | M21: =B32/9 -> 2318.8406 | Q21: PLAZO DE ENTREGA : 8 DIAS HABILES | V21: TOTAL | W21: =W19+W20 -> 562798.6 | Y21: =SUM(Y19:Y20) -> 577078.6
A22: =450000*1.2 -> 540000 | B22: M. DE OBRA | C22: PROCESO | D22: COSTO x Hr. | E22: Q Hrs. | F22: TOTAL | H22: 1 | J22: DILUYENTE | K22: =I22*H22 -> 0 | Q22: FORMA DE PAGO: 50% CONTADO, SALDO C/E
A23: =800000*1.2 -> 960000 | B23: =A21/23 -> 23478.261 | C23: CORTE | D23: =B23/9 -> 2608.6957 | E23: 0.5 | F23: =D23*E23 -> 1304.3478 | H23: 1 | J23: CINTA EMBALAJE | K23: =I23*H23 -> 0 | Q23: VALIDEZ COTIZACIÓN: 5 DIAS
A24: 450000 | B24: =A22/23 -> 23478.261 | C24: CORTE LAMINA | D24: =B24/9 -> 2608.6957 | E24: 0.5 | F24: =D24*E24 -> 1304.3478 | H24: Q/HRS | I24: PRECIO | J24: MANO DE OBRA INDIRECTA | K24: VALOR | L24: =SUM(K25:K35) -> 0
A25: 450000 | B25: =A23/23 -> 41739.13 | C25: REBAJE LAMINA | D25: =B25/9 -> 4637.6812 | F25: =D25*E25 -> 0 | H25: 0 | I25: =((480000/23)/9) -> 2318.8406 | J25: FLETERO (HRS) | K25: =H25*I25 -> 0
B26: =A24/23 -> 19565.217 | C26: TUPIZADO | D26: =B26/9 -> 2173.913 | E26: 0.5 | F26: =D26*E26 -> 1086.9565 | H26: 0 | J26: BENCINA | K26: =H26*I26 -> 0
A27: 350000 | B27: =A25/23 -> 19565.217 | C27: ARMADO | D27: =B27/9 -> 2173.913 | E27: 0.5 | F27: =D27*E27 -> 1086.9565 | H27: 0 | J27: TAG | K27: =H27*I27 -> 0
A28: 500000 | B28: =A27/23 -> 15217.391 | C28: PEGADO | D28: =B28/9 -> 1690.8213 | E28: 0.7 | F28: =D28*E28 -> 1183.5749 | H28: 0 | J28: RECTIFICACION | K28: =H28*I28 -> 0
B29: =A28/23 -> 21739.13 | C29: POSTFORMADO | D29: =B29/9 -> 2415.4589 | E29: 0.7 | F29: =D29*E29 -> 1690.8213 | H29: 0 | I29: =((550000*1.2)/23)/9 -> 3188.4058 | J29: HR. TRAB. JUAN | K29: =H29*I29 -> 0
A30: 450000 | C30: MEDIA CAÑA | D30: 2415 | F30: =D30*E30 -> 0 | H30: 0 | I30: =((450000*1.2)/23)/9 -> 2608.6957 | J30: HR. TRAB. JULIO | K30: =H30*I30 -> 0
A31: 350000 | B31: =A30/23 -> 19565.217 | C31: CORTE-ENCHAPE | D31: =B31/9 -> 2173.913 | E31: 0 | F31: =D31*E31 -> 0 | H31: 0 | I31: =((450000*1.2)/23)/9 -> 2608.6957 | J31: HR. TRAB. EUGE | K31: =H31*I31 -> 0
A32: =A21+A24+A27+A28+A30 -> 2290000 | B32: =480000/23 -> 20869.565 | C32: CONTROL CALIDAD | D32: =B32/9 -> 2318.8406 | E32: 0.5 | F32: =D32*E32 -> 1159.4203 | H32: 0 | J32: COLACION | K32: =H32*I32 -> 0
C33: TOTAL | D33: =SUM(D23:D32) -> 25216.932 | E33: =SUM(E23:E32) -> 3.9 | F33: =SUM(F23:F32) -> 8816.4251 | H33: 0 | J33: BONO | K33: =H33*I33 -> 0
B34: CIF | C34: M. PRIMA INDIREC. | D34: =L9 -> 2550 | H34: 1 | J34: PERFORACION | K34: =H34*I34 -> 0
C35: M. OBRA INDIRECTA | D35: =L24 -> 0 | H35: 6 | J35: CORTE 45 | K35: =H35*I35 -> 0
C36: GASTOS DE FABRICA | D36: =L36 -> 18467.666 | H36: CANTIDAD | I36: PRECIO | J36: GASTOS DE FABRICACION | K36: VALOR | L36: =SUM(K37:K39) -> 18467.666
C37: DEPRECIACIONES | H37: =$E$33 -> 3.9 | I37: =32609.69/9 -> 3623.2989 | J37: ARRIENDO x HORA | K37: =I37*H37 -> 14130.866
C38: TOTAL | D38: =SUM(D34:D37) -> 21017.666 | H38: =$E$33 -> 3.9 | I38: 967 | J38: AGUA x HORA | K38: =I38*H38 -> 3771.3
H39: =$E$33 -> 3.9 | I39: 145 | J39: LUZ x HORA | K39: =I39*H39 -> 565.5
B40: PROVISIONAR | C40: IVA | D40: =E11-E21 -> 714183.4
H41: ESTADO DE RESULTADOS
B42: TOTAL HRS TRABAJADAS | D42: =E33 -> 3.9 | H42: INGRESOS | I42: + TOTAL VENTA | M42: =D11 -> 4709110
H43: COSTOS | I43: - MATERIA PRIMA DIRECTA | M43: =D21 -> 950250
...
