Workbook

Sheet 5770
H2: MUEBLES SANTA FE SPA
H3: VENTAS POR MENOR DE MUEBLES
H4: RUT: 77.054.606-0
H5: SEPTIMA AVENIDA 1631, SAN MIGUEL
H6: FONO 22521 6502
H7: E-MAIL: ventas@mueblesantafe.cl
B8: P R E S U P U E S T O | D8: N°4601 | H8: NOTA DE VENTA : | I8: 7027
B10: CLIENTE: | C10: RIOCA LIMITADA | H10: FECHA : | I10: 45313
B11: RUT: | C11: 76.744.503-2 | H11: FECHA ENTREGA : | I11: 45316
B12: CONTACTO: | C12: JOSE MIGUEL RIOCA | H12: ORDEN DE COMPRA
B13: FONO: | C13: +5 525969 7449 | H13: DESPACHO: | I13: NO
B14: DIRECCION: | C14: BAJADOZ 100 LAS CONDES | H14: FORMA DE PAGO : CONTADO
B15: CIUDAD: | C15: SANTIAGO | H15: VALIDEZ COTIZACIÓN: 5 DÍAS
B18: D E T A L L E
B19: UNIDAD | C19: TIPO | D19: LARGO | E19: ANCHO | F19: FRENTE | G19: FONDO | H19: COLOR | I19: VALOR | J19: TOTAL
B20: 1 | C20: CUBIERTA MESON ATENCION | D20: 1810 | E20: 400 | F20: 200 | G20: 150 | H20: AUTUMN LEAF 22119 GL | I20: 150334 | J20: =I20*B20 -> 150334
B21: 1 | C21: CUBIERTA MESON ATENCION | D21: 1770 | E21: 400 | F21: 200 | G21: 150 | H21: AUTUMN LEAF 22119 GL | I21: 147208 | J21: =I21*B21 -> 147208
B22: 1 | C22: CUBIERTA MESON ATENCION | D22: 835 | E22: 400 | F22: 200 | G22: 150 | H22: AUTUMN LEAF 22119 GL | I22: 74151 | J22: =I22*B22 -> 74151
B23: 2 | C23: CUBIERTA MESON ATENCION | D23: 1570 | E23: 400 | F23: 200 | G23: 150 | H23: AUTUMN LEAF 22119 GL | I23: 131581 | J23: =I23*B23 -> 263162
B24: 1 | C24: CUBIERTA MESON ATENCION | D24: 1000 | E24: 400 | F24: 200 | G24: 150 | H24: AUTUMN LEAF 22119 GL | I24: 87043 | J24: =I24*B24 -> 87043
B25: 2 | C25: CUBIERTA MESON ATENCION | D25: 1570 | E25: 400 | F25: 200 | G25: 150 | H25: AUTUMN LEAF 22119 GL | I25: 131581 | J25: =I25*B25 -> 263162
B26: 2 | C26: CUBIERTA MESON ATENCION | D26: 1570 | E26: 400 | F26: 200 | G26: 150 | H26: AUTUMN LEAF 22119 GL | I26: 131581 | J26: =I26*B26 -> 263162
B27: 2 | C27: CUBIERTA MESON ATENCION | D27: 1570 | E27: 400 | F27: 200 | G27: 150 | H27: AUTUMN LEAF 22119 GL | I27: 131581 | J27: =I27*B27 -> 263162
B28: 12 | C28: SERVICIO DE CORTE A LA MEDIDA | I28: 10000 | J28: =I28*B28 -> 120000
I29: SERVICIO EXPRESS | J29: 75569
I31: NETO | J31: =SUM(J20:J30) -> 1706953
I32: I.V.A. | J32: =J31*19% -> 324321.07
I33: TOTAL | J33: =J31+J32 -> 2031274.1
B35: CUENTA VISTA DEL BANCO ESTADO N° 35571043040 A NOMBRE DE
B36: "TOPMOBILI LTDA." - RUT : 76.685.535-0, VENTAS@TOPMOBILI.CL
B37: VISITANOS Y DESCUBRE NUESTROS PRODUCTOS EN | E37: WWW.TOPMOBILICHILE.CL

Sheet CUBIERTA
C4: NOTA DE VENTA : | E4: ='5770'!I8 -> 7027
C5: CLIENTE : | D5: ='5770'!C10 -> RIOCA LIMITADA
C7: ='[1]4637'!F11 -> FECHA ENTREGA : | E7: ='5770'!I11 -> 45316
A10: SUSTRATO
D12: ALTO | E12: ANCHO
A13: MATERIAL | B13: CANTIDAD | C13: CORTE | D13: 50 | H13: DESCRIPCIÓN | L13: ALTO | M13: ANCHO
A14: MDF18MM | B14: =K14 -> 1 | D14: =L14+D$13 -> 1860 | E14: =M14+E$13 -> 400 | F14: 182 | G14: 132 | H14: =C41 -> CUBIERTA MESON ATENCION | K14: =K27 -> 1 | L14: =L27 -> 1810 | M14: =M27 -> 400 | O14: 1.35 | P14: 0.4 | Q14: 0.02 | R14: =O14*P14*Q14 -> 0.0108 | S14: =R14*K14 -> 0.0108
B15: =K15 -> 1 | D15: =L15+D$13 -> 1820 | E15: =M15+E$13 -> 400 | F15: 182 | G15: 132 | H15: =C42 -> CUBIERTA MESON ATENCION | K15: =K28 -> 1 | L15: =L28 -> 1770 | M15: =M28 -> 400
B16: =K16 -> 1 | D16: =L16+D$13 -> 885 | E16: =M16+E$13 -> 400 | F16: 182 | G16: 132 | H16: =C43 -> CUBIERTA MESON ATENCION | K16: =K29 -> 1 | L16: =L29 -> 835 | M16: =M29 -> 400
B17: =K17 -> 2 | D17: =L17+D$13 -> 1620 | E17: =M17+E$13 -> 400 | F17: 182 | G17: 132 | H17: =C44 -> CUBIERTA MESON ATENCION | K17: =K30 -> 2 | L17: =L30 -> 1570 | M17: =M30 -> 400
B18: =K18 -> 1 | D18: =L18+D$13 -> 1050 | E18: =M18+E$13 -> 400 | F18: 182 | G18: 132 | H18: =C45 -> CUBIERTA MESON ATENCION | K18: =K31 -> 1 | L18: =L31 -> 1000 | M18: =M31 -> 400
B19: =K19 -> 2 | D19: =L19+D$13 -> 1620 | E19: =M19+E$13 -> 400 | F19: 182 | G19: 132 | H19: =C46 -> CUBIERTA MESON ATENCION | K19: =K32 -> 2 | L19: =L32 -> 1570 | M19: =M32 -> 400
B20: =K20 -> 2 | D20: =L20+D$13 -> 1620 | E20: =M20+E$13 -> 400 | F20: 182 | G20: 132 | H20: =C47 -> CUBIERTA MESON ATENCION | K20: =K33 -> 2 | L20: =L33 -> 1570 | M20: =M33 -> 400
S21: =SUM(S14:S14) -> 0.0108
A23: LAMINADO
D25: ALTO | E25: ANCHO
A26: MATERIAL | B26: CANTIDAD | C26: CORTE | D26: 40 | E26: 180 | F26: FRENTE | G26: FONDO | H26: DESCRIPCIÓN | L26: ALTO | M26: ANCHO
A27: MDF 18MM | B27: =B41 -> 1 | D27: =L27+D$26 -> 1850 | E27: =M27+E26 -> 580 | F27: 200 | G27: 150 | H27: =C41 -> CUBIERTA MESON ATENCION | K27: =B41 -> 1 | L27: =D41 -> 1810 | M27: =E41 -> 400
B28: =B42 -> 1 | D28: =L28+D$26 -> 1810 | E28: =M28+E27 -> 980 | F28: 200 | G28: 150 | H28: =C42 -> CUBIERTA MESON ATENCION | K28: =B42 -> 1 | L28: =D42 -> 1770 | M28: =E42 -> 400
B29: =B43 -> 1 | D29: =L29+D$26 -> 875 | E29: =M29+E28 -> 1380 | F29: 200 | G29: 150 | H29: =C43 -> CUBIERTA MESON ATENCION | K29: =B43 -> 1 | L29: =D43 -> 835 | M29: =E43 -> 400
B30: =B44 -> 2 | D30: =L30+D$26 -> 1610 | E30: =M30+E29 -> 1780 | F30: 200 | G30: 150 | H30: =C44 -> CUBIERTA MESON ATENCION | K30: =B44 -> 2 | L30: =D44 -> 1570 | M30: =E44 -> 400
B31: =B45 -> 1 | D31: =L31+D$26 -> 1040 | E31: =M31+E30 -> 2180 | F31: 200 | G31: 150 | H31: =C45 -> CUBIERTA MESON ATENCION | K31: =B45 -> 1 | L31: =D45 -> 1000 | M31: =E45 -> 400
B32: =B46 -> 2 | D32: =L32+D$26 -> 1610 | E32: =M32+E31 -> 2580 | F32: 200 | G32: 150 | H32: =C46 -> CUBIERTA MESON ATENCION | K32: =B46 -> 2 | L32: =D46 -> 1570 | M32: =E46 -> 400
B33: =B47 -> 2 | D33: =L33+D$26 -> 1610 | E33: =M33+E32 -> 2980 | F33: 200 | G33: 150 | H33: =C47 -> CUBIERTA MESON ATENCION | K33: =B47 -> 2 | L33: =D47 -> 1570 | M33: =E47 -> 400
B34: =B48 -> 2 | D34: =L34+D$26 -> 1610 | E34: =M34+E33 -> 3380 | F34: 200 | G34: 150 | H34: =C48 -> CUBIERTA MESON ATENCION | K34: =B48 -> 2 | L34: =D48 -> 1570 | M34: =E48 -> 400
B35: =B49 -> 12 | D35: =L35+D$26 -> 40 | E35: =M35+E34 -> 3380 | F35: 200 | G35: 150 | H35: =C49 -> SERVICIO DE CORTE A LA MEDIDA | K35: =B49 -> 12 | L35: =D49 -> 0 | M35: =E49 -> 0
B38: MEDIDAS ORIGINALES
A40: MATERIAL | B40: CANTIDAD | C40: DESCRIPCIÓN | D40: ALTO | E40: ANCHO | F40: FRENTE | G40: FONDO | H40: COLOR
A41: MDF 18MM | B41: ='5770'!B20 -> 1 | C41: ='5770'!C20 -> CUBIERTA MESON ATENCION | D41: ='5770'!D20 -> 1810 | E41: ='5770'!E20 -> 400 | F41: 200 | G41: 150 | H41: =H68 -> AUTUMN LEAF 22119 GL
B42: ='5770'!B21 -> 1 | C42: ='5770'!C21 -> CUBIERTA MESON ATENCION | D42: ='5770'!D21 -> 1770 | E42: ='5770'!E21 -> 400 | F42: 200 | G42: 150 | H42: =H69 -> AUTUMN LEAF 22119 GL
B43: ='5770'!B22 -> 1 | C43: ='5770'!C22 -> CUBIERTA MESON ATENCION | D43: ='5770'!D22 -> 835 | E43: ='5770'!E22 -> 400 | F43: 200 | G43: 150 | H43: =H70 -> AUTUMN LEAF 22119 GL
B44: ='5770'!B23 -> 2 | C44: ='5770'!C23 -> CUBIERTA MESON ATENCION | D44: ='5770'!D23 -> 1570 | E44: ='5770'!E23 -> 400 | F44: 200 | G44: 150 | H44: =H71 -> AUTUMN LEAF 22119 GL
B45: ='5770'!B24 -> 1 | C45: ='5770'!C24 -> CUBIERTA MESON ATENCION | D45: ='5770'!D24 -> 1000 | E45: ='5770'!E24 -> 400 | F45: 200 | G45: 150 | H45: =H72 -> AUTUMN LEAF 22119 GL
B46: ='5770'!B25 -> 2 | C46: ='5770'!C25 -> CUBIERTA MESON ATENCION | D46: ='5770'!D25 -> 1570 | E46: ='5770'!E25 -> 400 | F46: 200 | G46: 150 | H46: =H73 -> AUTUMN LEAF 22119 GL
B47: ='5770'!B26 -> 2 | C47: ='5770'!C26 -> CUBIERTA MESON ATENCION | D47: ='5770'!D26 -> 1570 | E47: ='5770'!E26 -> 400 | F47: 200 | G47: 150 | H47: =H74 -> AUTUMN LEAF 22119 GL
B48: ='5770'!B27 -> 2 | C48: ='5770'!C27 -> CUBIERTA MESON ATENCION | D48: ='5770'!D27 -> 1570 | E48: ='5770'!E27 -> 400 | F48: 200 | G48: 150 | H48: =H75 -> AUTUMN LEAF 22119 GL
B49: ='5770'!B28 -> 12 | C49: ='5770'!C28 -> SERVICIO DE CORTE A LA MEDIDA | D49: ='5770'!D28 -> 0 | E49: ='5770'!E28 -> 0 | H49: =H76 -> 0
C58: NOTA DE VENTA : | E58: ='5770'!I8 -> 7027
C59: CLIENTE : | D59: ='5770'!C10 -> RIOCA LIMITADA
C61: ='[1]4637'!F11 -> FECHA ENTREGA : | E61: ='5770'!I11 -> 45316
...
